Workbook

Sheet RESUMEN
C1: MAIL: elmiradorconsorcios@gmail.com
C2: CUIT ADMINISTRACION: 27231256879
C3: CBU: 0720039720000002171436 | E3: TELEFONO: 11 5320-2676
C4: ADMINISTRADORA: CAROLINA CANCIANI MP:1148
C5: PERÍODO: DICIEMBRE | E5: HORARIOS DE ATENCION: LUNES A VIERNES - 10 A 16HS - EMERGENCIAS 24HS
C6: LIQUIDACION DE EXPENSAS
A14: Importante para dueños o inquilinos de departamentos o coheras: Queremos recordarles una cuestión importante respecto a los pagos de expensas que ayuda a evitar errores en la imputación de los mismos. El sistema que utilizamos asigna centavos únicos a cada Unidad Funcional (UF), lo cual nos permite identificar automáticamente a qué unidad corresponde cada transferencia. Es decir, cada UF tiene un número específico de centavos que actúa como "identificador". Por ejemplo, si tu UF es la 45, el importe a abonar debería terminar en $...,45. Si tenés más de una unidad (por ejemplo, un departamento y una cochera), cada una tiene su propio código de centavos. En esos casos, te pedimos por favor que realices una transferencia por cada UF, respetando el importe con sus centavos correspondientes. Sabemos que a veces por comodidad se suele enviar todo junto en una sola transferencia, pero esto puede generar confusión o errores en la imputación automática. Realizar los pagos por separado nos permite asegurar que cada importe se asigne correctamente. Agradecemos muchísimo la colaboración para seguir manteniendo todo ordenado. Saludos cordiales.
A20: VTO 15/01
A24: GASTOS ORDINARIOS UNIDADES FUNCIONALES: | E24: UF 93,20% | F24: LOCAL 1 (1,08%) | G24: LOCAL 2 (1,28%) | H24: LOCAL 3 (1,21%) | I24: LOCAL 4 (1,49%) | J24: LOCAL 5 (1,74%)
A25: Sueldo encargada Sonia Arzamendia Galeano
A26: Haberes | D26: 1042462
A27: Plus pileta | D27: 36382.7
A28: Plus retiro de basura | D28: =1584.8*80 -> 126784
A29: Plus cochera | D29: 21627.4
A30: Adicional Viaticos | D30: 60810.3
A31: Adicional remuneracion | D31: 50000
A32: SUBTOTAL | D32: =SUM(D26:D31) -> 1338066.4
A33: Sueldo encargada Miriam
A34: Haberes | D34: 521231
A35: Horas extras | D35: 100235
A36: Plus pileta | D36: =D27 -> 36382.7
A37: Plus retiro de basura | D37: =D28 -> 126784
A38: Plus cochera | D38: =D29 -> 21627.4
A39: Adicional Viaticos | D39: =D30 -> 60810.3
A40: Adicional remuneracion | D40: 50000
A41: SUBTOTAL | D41: =SUM(D34:D40) -> 917070.4
A42: TOTAL SUELDO | D42: =D32+D41 -> 2255136.8 | E42: =D42*93.2% -> 2101787.5 | F42: =$D42*1.08% -> 24355.477 | G42: =$D42*1.28% -> 28865.751 | H42: =$D42*1.21% -> 27287.155 | I42: =$D42*1.49% -> 33601.538 | J42: =D42*1.74% -> 39239.38 | K42: =E42+J42+F42+G42+H42+I42 -> 2255136.8 | L42: =K42-600000 -> 1655136.8
A43: SAC | D43: 0 | E43: =D43*91.91% -> 0 | J43: =D43*8.09% -> 0
D44: 0 | E44: =D44*91.91% -> 0 | J44: =D44*8.09% -> 0
A47: TOTAL | D47: =SUM(D43:D45) -> 0 | E47: =SUM(E43:E45) -> 0 | J47: =SUM(J43:J45) -> 0 | K47: =E47+J47 -> 0 | L47: =IF(D47=K47, "", "Error")
A48: COMBUSTIBLE PARA GRUPO ELECTROGENO | E48: =D48*91.91% -> 0 | J48: =D48*8.09% -> 0
E49: =D49 -> 0
E50: =D50 -> 0
E51: =D51*91.91% -> 0 | J51: =D51*8.09% -> 0
A52: TOTAL SAC | D52: =SUM(D44:D51) -> 0 | E52: =SUM(E44:E51) -> 0 | K52: =E52+J52+F52+G52+H52+I52 -> 0 | L52: =IF(D52=K52, "", "Error")
A53: IMPUESTOS
A54: ARBA - Impuesto inmobiliario partida 025024270-0 | C54: Cuota adicional | D54: 278973.9
A55: ARBA - Impuesto inmobiliario partida 025024270-0 | C55: Cuota 5 | D55: 14032.9
A56: TSG - Partida 197229000 | B56: Mes de DICIEMBRE | D56: 763852
A57: TSG - Partida 197229000 | B57: Mes de DICIEMBRE | D57: 763852
...

Sheet PRORRATEO
F1: Banco Santander Rio. | K1: SE GASTO: | L1: =RESUMEN!D109-RESUMEN!D107 -> 12944196
F2: CBU: 0720039720000002171436 | K2: SE PRORRATEA EN LAS UF: | M2: 14500000
A3: =RESUMEN!C5 -> PERÍODO: DICIEMBRE | F3: CTA CTE $ 0039 - 21714/3 FIDEICOMISO 25 DE MAYO 837 LAN 30716676737
C5: IMPORTANTE: Las personas marcadas en color naranja abonaron de forma incorrecta mediante Mercado Pago. A partir de ahora (incluso desde hace meses), ya se encuentra habilitada la cuenta bancaria correspondiente, por lo que todos los pagos deben realizarse exclusivamente a través de dicha cuenta. Los datos de la misma se encuentran justo arriba de este aviso. Quienes abonen por Mercado Pago corren el riesgo de que su pago no sea imputado correctamente.
P8: =L1-K133 -> -1368465.8
C9: IMPORTANTE: Quienes estan en violeta NO ha respetado los centavos al abonar. Para la proxima oportunidad, solicitamos que los respeten.
A11: Piso | B11: Dpto. | C11: UF | D11: Propietario | E11: Inquilinos | F11: (%) | G11: Saldo | H11: Ingreso | I11: SALDO | J11: Expensas extraor. | K11: Expensas ord | L11: SUM/ GASTOS PART | M11: TOTAL A ABONAR HASTA | N11: TOTAL A ABONAR 2DO VTO - DESDE EL
M13: =RESUMEN!A20 -> VTO 15/01 | N13: =RESUMEN!A20 -> VTO 15/01
A14: conf sup | C14: LOC 1 | D14: Fernandez, Cristian | E14: Gladys ojeda Britez - Exequiel alexis giuliani | F14: 0.0108 | G14: 124701 | H14: 124701 | I14: =G14-H14 -> 0 | J14: 0 | K14: 131452.15 | L14: 0 | M14: =K14+J14+I14+L14 -> 131452.15 | N14: =M14*6% + M14 -> 139339.28 | Q14: para copias y pegar las expensas ord del local
C15: LOC 2 | D15: Sr propietario | F15: 0.013 | G15: 147794 | H15: =G15+RESUMEN!D55 -> 161826.9 | I15: =G15-H15 -> -14032.9 | J15: 0 | K15: 155795.14 | L15: 0 | M15: =K15+J15+I15+L15 -> 141762.24 | N15: =M15*6% + M15 -> 150267.98
A16: conf sup | C16: LOC 3 | D16: Schiaffino, Edgardo Angel | F16: 0.0121 | G16: 139712 | H16: =G16 -> 139712 | I16: =G16-H16 -> 0 | J16: 0 | K16: 147275.1 | L16: 0 | M16: =K16+J16+I16+L16 -> 147275.1 | N16: =M16*6% + M16 -> 156111.6 | Q16: LOCAL 1 | R16: =RESUMEN!F109 -> 149485.13
A17: conf sup | C17: LOC 4 | D17: Cordero, Leandro Emanuel - Orona, Victoria | F17: 0.0149 | G17: 172042 | I17: =G17-H17 -> 172042 | J17: 0 | K17: 181355.28 | L17: 0 | M17: =K17+J17+I17+L17 -> 353397.28 | N17: =M17*6% + M17 -> 374601.12 | Q17: LOCAL 2 | R17: =RESUMEN!G109 -> 177167.57
A18: conf sup | C18: LOC 5 | D18: Orsi, Jose Luis - Fernandez, Cristian Gabriel | F18: 0.0174 | G18: 200908 | H18: =G18 -> 200908 | I18: =G18-H18 -> 0 | J18: 0 | K18: 211784.02 | L18: 0 | M18: =K18+J18+I18+L18 -> 211784.02 | N18: =M18*6% + M18 -> 224491.06 | Q18: LOCAL 3 | R18: =RESUMEN!H109 -> 167478.72
A19: 3 amb | C19: 2ºA | D19: Franco, Lucas Fabián | F19: 0.0188 | G19: 225600.01 | H19: =G19 -> 225600.01 | I19: =G19-H19 -> 0 | J19: =M$8*F19 -> 0 | K19: =M$2*F19 -> 272600 | L19: 0 | M19: =ROUND((K19+J19+I19+L19),0) + O19 -> 272600.01 | N19: =ROUND((M19*6% + M19 ),0) + O19 -> 288956.01 | O19: 0.01 | Q19: LOCAL 4 | R19: =RESUMEN!I109 -> 206234.12
A20: 1 amb | C20: 2ºB | D20: Martinez, Diego | F20: 0.0084 | G20: 100800.02 | H20: =G20 -> 100800.02 | I20: =G20-H20 -> 0 | J20: =M$8*F20 -> 0 | K20: =M$2*F20 -> 121800 | L20: 0 | M20: =ROUND((K20+J20+I20+L20),0) + O20 -> 121800.02 | N20: =ROUND((M20*6% + M20 ),0) + O20 -> 129108.02 | O20: =O19+0.01 -> 0.02 | Q20: LOCAL 5 | R20: =RESUMEN!J109 -> 240837.16
A21: 3 amb | C21: 2ºC | D21: Rodriguez, Carlos Alberto Miguel | F21: 0.0201 | G21: 227101.03 | H21: =G21 -> 227101.03 | I21: =G21-H21 -> 0 | J21: =M$8*F21 -> 0 | K21: =M$2*F21 -> 291450 | L21: 0 | M21: =ROUND((K21+J21+I21+L21),0) + O21 -> 291450.03 | N21: =ROUND((M21*6% + M21 ),0) + O21 -> 308937.03 | O21: =O20+0.01 -> 0.03
A22: 2 amb | C22: 2ºD | D22: Ferraro, José | E22: Matias Cuevas | F22: 0.0094 | G22: 277972.04 | H22: 112800 | I22: =G22-H22 -> 165172.04 | J22: =M$8*F22 -> 0 | K22: =M$2*F22 -> 136300 | L22: 0 | M22: =ROUND((K22+J22+I22+L22),0) + O22 -> 301472.04 | N22: =ROUND((M22*6% + M22 ),0) + O22 -> 319560.04 | O22: =O21+0.01 -> 0.04 | P22: Matias alejandro ezequiel
A23: 2 amb | C23: 2ºE | D23: Dieci, Matias Orlando | E23: Julieta Damiano/Damiani | F23: 0.0087 | G23: 191400.05 | H23: =104400.05 -> 104400.05 | I23: =G23-H23 -> 87000 | J23: =M$8*F23 -> 0 | K23: =M$2*F23 -> 126150 | L23: 0 | M23: =ROUND((K23+J23+I23+L23),0) + O23 -> 213150.05 | N23: =ROUND((M23*6% + M23 ),0) + O23 -> 225939.05 | O23: =O22+0.01 -> 0.05
A24: 2 amb | C24: 2ºF | D24: Ferraro, Jose | E24: Carolina Massa | F24: 0.0095 | G24: 114000.06 | H24: =G24 -> 114000.06 | I24: =G24-H24 -> 0 | J24: =M$8*F24 -> 0 | K24: =M$2*F24 -> 137750 | L24: 0 | M24: =ROUND((K24+J24+I24+L24),0) + O24 -> 137750.06 | N24: =ROUND((M24*6% + M24 ),0) + O24 -> 146015.06 | O24: =O23+0.01 -> 0.06
A25: 3 amb | C25: 3ºA | D25: Ferraro, Jose | E25: Walter Gabriel Ledesma | F25: 0.0165 | G25: 325977.07 | H25: 198000 | I25: =G25-H25 -> 127977.07 | J25: =M$8*F25 -> 0 | K25: =M$2*F25 -> 239250 | L25: 0 | M25: =ROUND((K25+J25+I25+L25),0) + O25 -> 367227.07 | N25: =ROUND((M25*6% + M25 ),0) + O25 -> 389261.07 | O25: =O24+0.01 -> 0.07
A26: 1 amb | C26: 3ºB | D26: Balduzzi, Stella Maris | F26: 0.0073 | G26: 87600.08 | H26: =G26 -> 87600.08 | I26: =G26-H26 -> 0 | J26: =M$8*F26 -> 0 | K26: =M$2*F26 -> 105850 | L26: =24000+20000 -> 44000 | M26: =ROUND((K26+J26+I26+L26),0) + O26 -> 149850.08 | N26: =ROUND((M26*6% + M26 ),0) + O26 -> 158841.08 | O26: =O25+0.01 -> 0.08
A27: 3 amb | C27: 3ºC | D27: Ferraro, Jose | F27: 0.0178 | G27: 728372.09 | I27: =G27-H27 -> 728372.09 | J27: =M$8*F27 -> 0 | K27: =M$2*F27 -> 258100 | L27: 0 | M27: =ROUND((K27+J27+I27+L27),0) + O27 -> 986472.09 | N27: =ROUND((M27*6% + M27 ),0) + O27 -> 1045660.1 | O27: =O26+0.01 -> 0.09
A28: 2 amb | C28: 3ºD | D28: Heredia, Christian | F28: 0.0094 | G28: 112800.1 | I28: =G28-H28 -> 112800.1 | J28: =M$8*F28 -> 0 | K28: =M$2*F28 -> 136300 | L28: 0 | M28: =ROUND((K28+J28+I28+L28),0) + O28 -> 249100.1 | N28: =ROUND((M28*6% + M28 ),0) + O28 -> 264046.1 | O28: =O27+0.01 -> 0.1
A29: 2 amb | C29: 3ºE | D29: Dallorso, Maria Ines - Dallorso, Ana Paula | F29: 0.0087 | G29: 99744.11 | H29: =G29 -> 99744.11 | I29: =G29-H29 -> 0 | J29: =M$8*F29 -> 0 | K29: =M$2*F29 -> 126150 | L29: 0 | M29: =ROUND((K29+J29+I29+L29),0) + O29 -> 126150.11 | N29: =ROUND((M29*6% + M29 ),0) + O29 -> 133719.11 | O29: =O28+0.01 -> 0.11
A30: 2 amb | C30: 3ºF | D30: Ayala, Roberto Adrian | F30: 0.0095 | G30: 380000.12 | I30: =G30-H30 -> 380000.12 | J30: =M$8*F30 -> 0 | K30: =M$2*F30 -> 137750 | L30: 0 | M30: =ROUND((K30+J30+I30+L30),0) + O30 -> 517750.12 | N30: =ROUND((M30*6% + M30 ),0) + O30 -> 548815.12 | O30: =O29+0.01 -> 0.12
A31: 3 amb | C31: 4ºA | D31: Barral, Carlos Daniel | F31: 0.0164 | G31: 196800.13 | H31: =G31 -> 196800.13 | I31: =G31-H31 -> 0 | J31: =M$8*F31 -> 0 | K31: =M$2*F31 -> 237800 | L31: 0 | M31: =ROUND((K31+J31+I31+L31),0) + O31 -> 237800.13 | N31: =ROUND((M31*6% + M31 ),0) + O31 -> 252068.13 | O31: =O30+0.01 -> 0.13
A32: 1 amb | C32: 4ºB | D32: Sr. Propietario | E32: Liria | F32: 0.0072 | G32: 86400.14 | H32: =G32 -> 86400.14 | I32: =G32-H32 -> 0 | J32: =M$8*F32 -> 0 | K32: =M$2*F32 -> 104400 | L32: 0 | M32: =ROUND((K32+J32+I32+L32),0) + O32 -> 104400.14 | N32: =ROUND((M32*6% + M32 ),0) + O32 -> 110664.14 | O32: =O31+0.01 -> 0.14
A33: 3 amb | C33: 4ºC | D33: Osipowicz, Ariel Marcelo | F33: 0.0173 | G33: 207600.15 | H33: =G33 -> 207600.15 | I33: =G33-H33 -> 0 | J33: =M$8*F33 -> 0 | K33: =M$2*F33 -> 250850 | L33: 0 | M33: =ROUND((K33+J33+I33+L33),0) + O33 -> 250850.15 | N33: =ROUND((M33*6% + M33 ),0) + O33 -> 265901.15 | O33: =O32+0.01 -> 0.15
A34: 2 amb | C34: 4ºD | D34: Ruiz, Juana Del Valle | F34: 0.0094 | G34: 124800.16 | H34: 132288.16 | I34: =G34-H34 -> -7488 | J34: =M$8*F34 -> 0 | K34: =M$2*F34 -> 136300 | L34: 0 | M34: =ROUND((K34+J34+I34+L34),0) + O34 -> 128812.16 | N34: =ROUND((M34*6% + M34 ),0) + O34 -> 136541.16 | O34: =O33+0.01 -> 0.16
A35: 2 amb | C35: 4ºE | D35: Ayala, Roberto Adrian | E35: Iara | F35: 0.0087 | G35: 121800.17 | H35: 113100.17 | I35: =G35-H35 -> 8700 | J35: =M$8*F35 -> 0 | K35: =M$2*F35 -> 126150 | L35: 0 | M35: =ROUND((K35+J35+I35+L35),0) + O35 -> 134850.17 | N35: =ROUND((M35*6% + M35 ),0) + O35 -> 142941.17 | O35: =O34+0.01 -> 0.17
A36: 2 amb | C36: 4ºF | D36: Ayala, Roberto Adrian | F36: 0.0095 | G36: 209000.18 | I36: =G36-H36 -> 209000.18 | J36: =M$8*F36 -> 0 | K36: =M$2*F36 -> 137750 | L36: 0 | M36: =ROUND((K36+J36+I36+L36),0) + O36 -> 346750.18 | N36: =ROUND((M36*6% + M36 ),0) + O36 -> 367555.18 | O36: =O35+0.01 -> 0.18
A37: 3 amb | C37: 5ºA | D37: Chehab, Gabriel Adrian | E37: Santiago Rodriguez | F37: 0.0164 | G37: 233800.19 | H37: =G37 -> 233800.19 | I37: =G37-H37 -> 0 | J37: =M$8*F37 -> 0 | K37: =M$2*F37 -> 237800 | L37: 20000 | M37: =ROUND((K37+J37+I37+L37),0) + O37 -> 257800.19 | N37: =ROUND((M37*6% + M37 ),0) + O37 -> 273268.19 | O37: =O36+0.01 -> 0.19
A38: 1 amb | C38: 5ºB | D38: Mesa, Mariano | F38: 0.0072 | G38: 86400.2 | H38: =G38 -> 86400.2 | I38: =G38-H38 -> 0 | J38: =M$8*F38 -> 0 | K38: =M$2*F38 -> 104400 | L38: 0 | M38: =ROUND((K38+J38+I38+L38),0) + O38 -> 104400.2 | N38: =ROUND((M38*6% + M38 ),0) + O38 -> 110664.2 | O38: =O37+0.01 -> 0.2
A39: 3 amb | C39: 5ºC | D39: Di Mito, Vicente Argentino - Serantes, Mabel | F39: 0.0173 | G39: 207600.21 | H39: =G39 -> 207600.21 | I39: =G39-H39 -> 0 | J39: =M$8*F39 -> 0 | K39: =M$2*F39 -> 250850 | L39: 0 | M39: =ROUND((K39+J39+I39+L39),0) + O39 -> 250850.21 | N39: =ROUND((M39*6% + M39 ),0) + O39 -> 265901.21 | O39: =O38+0.01 -> 0.21
A40: 2 amb | C40: 5ºD | D40: Ayala, Agustin | F40: 0.0094 | G40: 206800.22 | I40: =G40-H40 -> 206800.22 | J40: =M$8*F40 -> 0 | K40: =M$2*F40 -> 136300 | L40: 0 | M40: =ROUND((K40+J40+I40+L40),0) + O40 -> 343100.22 | N40: =ROUND((M40*6% + M40 ),0) + O40 -> 363686.22 | O40: =O39+0.01 -> 0.22
A41: 2 amb | C41: 5ºE | D41: Ayala, Roberto Adrian | F41: 0.0087 | G41: 104400.23 | H41: =G41 -> 104400.23 | I41: =G41-H41 -> 0 | J41: =M$8*F41 -> 0 | K41: =M$2*F41 -> 126150 | L41: 0 | M41: =ROUND((K41+J41+I41+L41),0) + O41 -> 126150.23 | N41: =ROUND((M41*6% + M41 ),0) + O41 -> 133719.23 | O41: =O40+0.01 -> 0.23 | P41: COCHERA 31
A42: 2 amb | C42: 5ºF | D42: Ayala, Agustin | F42: 0.0095 | G42: 209000.24 | I42: =G42-H42 -> 209000.24 | J42: =M$8*F42 -> 0 | K42: =M$2*F42 -> 137750 | L42: 0 | M42: =ROUND((K42+J42+I42+L42),0) + O42 -> 346750.24 | N42: =ROUND((M42*6% + M42 ),0) + O42 -> 367555.24 | O42: =O41+0.01 -> 0.24
A43: 3 amb | C43: 6ºA | D43: Morandi, Victoria Ayelen | Calvo, Luciano Ezequiel | F43: 0.0164 | G43: 196800.25 | H43: =G43 -> 196800.25 | I43: =G43-H43 -> 0 | J43: =M$8*F43 -> 0 | K43: =M$2*F43 -> 237800 | L43: 0 | M43: =ROUND((K43+J43+I43+L43),0) + O43 -> 237800.25 | N43: =ROUND((M43*6% + M43 ),0) + O43 -> 252068.25 | O43: =O42+0.01 -> 0.25
A44: 1 amb | C44: 6ºB | D44: Grizak Ruben | E44: Christian | F44: 0.0072 | G44: 86400.26 | H44: =G44 -> 86400.26 | I44: =G44-H44 -> 0 | J44: =M$8*F44 -> 0 | K44: =M$2*F44 -> 104400 | L44: 0 | M44: =ROUND((K44+J44+I44+L44),0) + O44 -> 104400.26 | N44: =ROUND((M44*6% + M44 ),0) + O44 -> 110664.26 | O44: =O43+0.01 -> 0.26
A45: 3 amb | C45: 6ºC | D45: Nuñez Leonel - Corrieri Giuliana | F45: 0.0173 | G45: 207600.27 | H45: =G45 -> 207600.27 | I45: =G45-H45 -> 0 | J45: =M$8*F45 -> 0 | K45: =M$2*F45 -> 250850 | L45: 0 | M45: =ROUND((K45+J45+I45+L45),0) + O45 -> 250850.27 | N45: =ROUND((M45*6% + M45 ),0) + O45 -> 265901.27 | O45: =O44+0.01 -> 0.27 | P45: COCHERA 33 | Q45: COCHERA 33
...

Sheet ANOTACIONES
B4: Jose ferraro pago con un monton de depositos el 10/12
B6: El comprobante de $ 90.000.- corresponde a setiembre cochera 37 y 38 $. 20.700 cada una
B7: Octubre cochera 29 $ 25.626 y cochera 34 $ 20.700 y el comprobante de $ 71.500 es de la cochera 30 saldo al 30/11
B8: El pago de $166.000, es del Dto 2 D
B9: El pago de $103.000. Es del Dto 3A
B10: Y el pago de $ 730.000 es del Dto 3C
B13: Julieta damiano en septiembre pago $87,000 a la cuenta de carolina en MP - debe estar sin deuda ya que es un pago que se nos traspapelo. Hablamos con rocio soria x mail quien es la dueña del dpto

Sheet SUELDOS
C3: =RESUMEN!C5 -> PERÍODO: DICIEMBRE | F3: =[1]RESUMEN!A22 -> Sueldo encargada Sonia Arzamendia Galeano
C5: =RESUMEN!A26 -> Haberes | G5: =RESUMEN!D26 -> 1042462 | H5: Firma
C6: =RESUMEN!A27 -> Plus pileta | G6: =RESUMEN!D27 -> 36382.7 | H6: __________________________________
C7: =RESUMEN!A28 -> Plus retiro de basura | G7: =RESUMEN!D28 -> 126784
C8: =RESUMEN!A29 -> Plus cochera | G8: =RESUMEN!D29 -> 21627.4
C9: =RESUMEN!A30 -> Adicional Viaticos | G9: =RESUMEN!D30 -> 60810.3 | H9: Aclaracion
C10: =RESUMEN!A31 -> Adicional remuneracion | G10: =RESUMEN!D31 -> 50000 | H10: __________________________________
C12: TOTAL | G12: =SUM(G5:G11) -> 1338066.4
C16: =C3 -> PERÍODO: DICIEMBRE | F16: =[1]RESUMEN!A30 -> Sueldo encargada Miriam
H18: Firma
C19: =RESUMEN!A34 -> Haberes | G19: =RESUMEN!D34 -> 521231 | H19: __________________________________
C20: =RESUMEN!A35 -> Horas extras | G20: =RESUMEN!D35 -> 100235
C21: =RESUMEN!A36 -> Plus pileta | G21: =RESUMEN!D36 -> 36382.7
C22: =RESUMEN!A37 -> Plus retiro de basura | G22: =RESUMEN!D37 -> 126784 | H22: Aclaracion
C23: =RESUMEN!A38 -> Plus cochera | G23: =RESUMEN!D38 -> 21627.4 | H23: __________________________________
C24: =RESUMEN!A39 -> Adicional Viaticos | G24: =RESUMEN!D39 -> 60810.3
C25: =RESUMEN!A40 -> Adicional remuneracion | G25: =RESUMEN!D40 -> 50000
C26: TOTAL | G26: =SUM(G18:G25) -> 917070.4

Sheet Hoja1
C4: AYALA
C5: 52141.08 | D5: 3B
C6: 67140.1 | D6: 3D
C7: 52121.11 | D7: 3E
C8: 67885.12 | D8: 3F
C9: 67140.16 | D9: 4D
C10: 62141.17 | D10: 4E
C11: 67855.18 | D11: 4F
C12: 62141.23 | D12: 5E
C13: 67855.24 | D13: 5F
C14: =SUM(C5:C13) -> 566420.39
