Workbook

Sheet RESUMEN
B1: MAIL: consorciovergara1670@gmail.com
B2: CUIT ADMINISTRACION: 27231256879
B3: CBU: 2990024602400258030006 | D3: TELEFONO: 11 5320-2676
A4: LIQUIDACION DE EXPENSAS | B4: ALIAS: VERGARA.1670
A5: CUIT DEL EDIFICIO: 30-71802922-4 | B5: PERÍODO: JUNIO - ADMINISTRADORA: CAROLINA CANCIANI MP:1148
A6: CONSORCIO DE PROPIETARIOS DEL EDIFICIO CALLE VERGARA 1670 | D6: HORARIOS DE ATENCION: LUNES A VIERNES
B8: VTO 14/07
A13: ESTIMADOS PROPIETARIOS E INQUILINOS: POR FAVOR LOS QUE ABONAN EN PRIMER VENCIMIENTO ABONEN EL MONTO DE PRIMER VENCIMIENTO, ASI AGILIZAN LA LIQUIDACION, LES PEDIMOS ENCARECIDAMENTE QUE RESPETEN LOS CENTAVOS CORRESPONDIENTES A LA UNIDAD FUNCIONAL. ES DE CARÁCTER OBLIGATORIO INFORMAR VIA MAIL LAS EXPENSAS.
A20: GASTOS ORDINARIOS UNIDADES FUNCIONALES:
A21: HABERES ENCARGADOS
A22: Remunerativos encargado Gonzalo Guenaga | D22: 598522.2
A23: Deducciones | D23: -139605.89
A24: Redondeo | D24: 0.69
A25: Neto | D25: =SUM(D22:D24) -> 458917
A26: TOTAL SUELDO | E26: =D25 -> 458917
A27: HONORARIOS
A28: Marcela De Biase- Sra. Contadora - Mes de JUNIO | D28: 35000 | E28: Transf 11/06
A29: Honorarios administracion - Mes de MAYO - Se debe JUNIO | D29: 470000 | E29: Transf 12/05
A30: TOTAL | E30: =SUM(D28:D29) -> 505000
A31: SEGUROS
A32: Seguro integral consorcio. Póliza 2161474 | D32: 70868
A33: Seguro de accidentes personales | D33: 719.9
A34: TOTAL IMPUESTO | E34: =SUM(D32:D33) -> 71587.9
A35: APORTES Y CONTRIBUCIONES
A36: ARCA | D36: 371183.27 | E36: PMC 06/05
A37: Sindicatos mes de JUNIO | B37: Fatheryh | D37: 26576.33 | E37: Debito 12/05
A38: =A37 -> Sindicatos mes de JUNIO | B38: Suther | D38: 50388.03 | E38: =E37 -> Debito 12/05
A39: =A38 -> Sindicatos mes de JUNIO | B39: Seracarh | D39: 2952.93 | E39: =E37 -> Debito 12/05
A40: TOTAL Aportes y Contribuciones - Sindicato | E40: =SUM(D36:D39) -> 451100.56
A41: ABONOS Y SERVICIOS
A42: AYSA - Nro de cliente. 318350 | D42: 84629.46
A43: Servicio de mantenimiento de ascensores | D43: 50000 | E43: Transf 19/05
A44: Cablevision - servicio | D44: 81423.93 | E44: Debito 07/05
A45: TOTAL ABONOS Y SERVICIOS | E45: =SUM(D42:D44) -> 216053.39
A46: GASTOS GENERALES / MANTENIMIENTO
A47: Matafuegos Firex compra de matafuego x5 kg | D47: 84500 | E47: Tranfs 16/05
A48: Recarga 14 matafuegos x5kg | D48: 262099.86 | E48: Tranfs 16/05
A49: Calderista - Visita tecnica - Bernardo Curcio | D49: 36300 | E49: Transf 27/05
A50: Electricista - Busqueda de fuga de corriente salto de disyuntor | D50: 25000 | E50: Transf 307/05
A51: Doartero Julio - Mano de obra y materiales reparacion de entrada de agua | D51: 165000 | E51: Tranfs 13/05
...

Sheet PRORRATEO
E1: EDESUR: | F1: 1241030.2 | K1: Gastos Ordinarios: | M1: =P1 -> 3600000 | P1: 3600000
E2: METROGAS: | F2: 561462.8 | H2: Extras: | I2: 1200000 | K2: Plan de pago metrogas: | M2: 304993.06
A3: Dpto. | C3: UF | D3: Propietario | E3: Inquilinos | F3: (%) | G3: Saldo Ord | H3: Ingreso | I3: Deuda o Saldo a favor | J3: Interes 3% | K3: =K2 -> Plan de pago metrogas: | L3: Expensas ord. | M3: EDESUR | N3: METROGAS | O3: Expensas extraord | P3: Total 1er Vto | Q3: Total 2do Vto
P4: =RESUMEN!B8 -> VTO 14/07
B5: 1°A | C5: 33 | D5: Alejandro Raul Cuezzo | F5: 0.0202 | G5: 154290.33 | H5: =158919.33 -> 158919.33 | I5: =G5-H5 -> -4629 | J5: =IF(I5>0,I5*3%,0) -> 0 | K5: =M$2*F5 -> 6160.8598 | L5: =M$1*F5 -> 72720 | M5: =F$1*F5 -> 25068.809 | N5: =F$2*F5 -> 11341.549 | O5: =I$2*F5 -> 24240 | P5: =ROUND(SUM(I5:O5),0) + R5 -> 134902.33 | Q5: =ROUND(P5*3%,0) + P5 -> 138949.33 | R5: =ROUND(0.001+C5/100,2) -> 0.33
B6: 1°B | C6: 34 | D6: Daniel Julian Guzzo | F6: 0.0139 | G6: 106170.34 | H6: =G6 -> 106170.34 | I6: =G6-H6 -> 0 | J6: =IF(I6>0,I6*3%,0) -> 0 | K6: =M$2*F6 -> 4239.4035 | L6: =M$1*F6 -> 50040 | M6: =F$1*F6 -> 17250.319 | N6: =F$2*F6 -> 7804.3329 | O6: =I$2*F6 -> 16680 | P6: =ROUND(SUM(I6:O6),0) + R6 -> 96014.34 | Q6: =ROUND(P6*3%,0) + P6 -> 98894.34 | R6: =ROUND(0.001+C6/100,2) -> 0.34
A7: 1 | B7: 1°C | C7: 35 | D7: Pablo Plebs | F7: 0.0142 | G7: 203142.35 | H7: 108461 | I7: =G7-H7 -> 94681.35 | J7: =IF(I7>0,I7*3%,0) -> 2840.4405 | K7: =M$2*F7 -> 4330.9015 | L7: =M$1*F7 -> 51120 | M7: =F$1*F7 -> 17622.628 | N7: =F$2*F7 -> 7972.7718 | O7: =I$2*F7 -> 17040 | P7: =ROUND(SUM(I7:O7),0) + R7 -> 195608.35 | Q7: =ROUND(P7*3%,0) + P7 -> 201476.35 | R7: =ROUND(0.001+C7/100,2) -> 0.35
A8: 2 | B8: 1°D | C8: 36 | D8: Adrian Alejandro Pozo | F8: 0.0202 | G8: 150347.36 | I8: =G8-H8 -> 150347.36 | J8: =IF(I8>0,I8*3%,0) -> 4510.4208 | K8: =M$2*F8 -> 6160.8598 | L8: =M$1*F8 -> 72720 | M8: =F$1*F8 -> 25068.809 | N8: =F$2*F8 -> 11341.549 | O8: =I$2*F8 -> 24240 | P8: =ROUND(SUM(I8:O8),0) + R8 -> 294389.36 | Q8: =ROUND(P8*3%,0) + P8 -> 303221.36 | R8: =ROUND(0.001+C8/100,2) -> 0.36
A9: 3 | B9: 2°A | C9: 37 | D9: Guillen Maria / Alejandro DI LEO | E9: Claudia / Laura Avido | F9: 0.0202 | G9: 93012.37 | H9: =20200+5300+72812.37-H63 -> 96784.16 | I9: =G9-H9 -> -3771.79 | J9: =IF(I9>0,I9*3%,0) -> 0 | K9: =M$2*F9 -> 6160.8598 | L9: =M$1*F9 -> 72720 | M9: =F$1*F9 -> 25068.809 | N9: =F$2*F9 -> 11341.549 | O9: =I$2*F9 -> 24240 | P9: =ROUND(SUM(I9:O9),0) + R9 -> 135759.37 | Q9: =ROUND(P9*3%,0) + P9 -> 139832.37 | R9: =ROUND(0.001+C9/100,2) -> 0.37
A10: 4 | B10: 2°B | C10: 38 | D10: Jose Luis Gurtubay | E10: Santiago Flores | F10: 0.0139 | G10: 106170.38 | H10: =106170.54 -> 106170.54 | I10: =G10-H10 -> -0.16 | J10: =IF(I10>0,I10*3%,0) -> 0 | K10: =M$2*F10 -> 4239.4035 | L10: =M$1*F10 -> 50040 | M10: =F$1*F10 -> 17250.319 | N10: =F$2*F10 -> 7804.3329 | O10: =I$2*F10 -> 16680 | P10: =ROUND(SUM(I10:O10),0) + R10 -> 96014.38 | Q10: =ROUND(P10*3%,0) + P10 -> 98894.38 | R10: =ROUND(0.001+C10/100,2) -> 0.38
A11: 5 | B11: 2°C | C11: 39 | D11: Magali Carrivale | F11: 0.0139 | G11: 106170.39 | H11: =95038.42 -> 95038.42 | I11: =G11-H11 -> 11131.97 | J11: =IF(I11>0,I11*3%,0) -> 333.9591 | K11: =M$2*F11 -> 4239.4035 | L11: =M$1*F11 -> 50040 | M11: =F$1*F11 -> 17250.319 | N11: =F$2*F11 -> 7804.3329 | O11: =I$2*F11 -> 16680 | P11: =ROUND(SUM(I11:O11),0) + R11 -> 107480.39 | Q11: =ROUND(P11*3%,0) + P11 -> 110704.39 | R11: =ROUND(0.001+C11/100,2) -> 0.39
A12: 6 | B12: 2°D | C12: 40 | D12: Juan Carlos Alonso | F12: 0.0202 | G12: 149338.4 | H12: =31194+164320.44-H78 -> 155032.4 | I12: =G12-H12 -> -5694 | J12: =IF(I12>0,I12*3%,0) -> 0 | K12: =M$2*F12 -> 6160.8598 | L12: =M$1*F12 -> 72720 | M12: =F$1*F12 -> 25068.809 | N12: =F$2*F12 -> 11341.549 | O12: =I$2*F12 -> 24240 | P12: =ROUND(SUM(I12:O12),0) + R12 -> 133837.4 | Q12: =ROUND(P12*3%,0) + P12 -> 137852.4 | R12: =ROUND(0.001+C12/100,2) -> 0.4
A13: 7 | B13: 3°A | C13: 41 | D13: Lucas Oscar Ramil | E13: Camila Benitez Nahiara | F13: 0.0202 | G13: 154290.41 | H13: =134090 -> 134090 | I13: =G13-H13 -> 20200.41 | J13: =IF(I13>0,I13*3%,0) -> 606.0123 | K13: =M$2*F13 -> 6160.8598 | L13: =M$1*F13 -> 72720 | M13: =F$1*F13 -> 25068.809 | N13: =F$2*F13 -> 11341.549 | O13: =I$2*F13 -> 24240 | P13: =ROUND(SUM(I13:O13),0) + R13 -> 160338.41 | Q13: =ROUND(P13*3%,0) + P13 -> 165148.41 | R13: =ROUND(0.001+C13/100,2) -> 0.41
A14: 8 | B14: 3°B | C14: 42 | D14: Raul Boffi | E14: Gian y Micaela Parra | F14: 0.0139 | G14: 106170.42 | H14: =G14 -> 106170.42 | I14: =G14-H14 -> 0 | J14: =IF(I14>0,I14*3%,0) -> 0 | K14: =M$2*F14 -> 4239.4035 | L14: =M$1*F14 -> 50040 | M14: =F$1*F14 -> 17250.319 | N14: =F$2*F14 -> 7804.3329 | O14: =I$2*F14 -> 16680 | P14: =ROUND(SUM(I14:O14),0) + R14 -> 96014.42 | Q14: =ROUND(P14*3%,0) + P14 -> 98894.42 | R14: =ROUND(0.001+C14/100,2) -> 0.42
A15: 1 | B15: 3°C | C15: 43 | D15: Raul Boffi | E15: Lujan / Natalia Capece | F15: 0.0139 | G15: 198850.43 | H15: =G15 -> 198850.43 | I15: =G15-H15 -> 0 | J15: =IF(I15>0,I15*3%,0) -> 0 | K15: =M$2*F15 -> 4239.4035 | L15: =M$1*F15 -> 50040 | M15: =F$1*F15 -> 17250.319 | N15: =F$2*F15 -> 7804.3329 | O15: =I$2*F15 -> 16680 | P15: =ROUND(SUM(I15:O15),0) + R15 -> 96014.43 | Q15: =ROUND(P15*3%,0) + P15 -> 98894.43 | R15: =ROUND(0.001+C15/100,2) -> 0.43
A16: 1 | B16: 3°D | C16: 44 | D16: Roxana Elena Maya | E16: Daniela Bernabe | F16: 0.0202 | G16: 149367.44 | H16: =153848.44 -> 153848.44 | I16: =G16-H16 -> -4481 | J16: =IF(I16>0,I16*3%,0) -> 0 | K16: =M$2*F16 -> 6160.8598 | L16: =M$1*F16 -> 72720 | M16: =F$1*F16 -> 25068.809 | N16: =F$2*F16 -> 11341.549 | O16: =I$2*F16 -> 24240 | P16: =ROUND(SUM(I16:O16),0) + R16 -> 135050.44 | Q16: =ROUND(P16*3%,0) + P16 -> 139102.44 | R16: =ROUND(0.001+C16/100,2) -> 0.44
A17: 2 | B17: 4°A | C17: 45 | D17: Raul Boffi | E17: Paula Murado | F17: 0.0202 | G17: 154290.45 | H17: =134090.45+20200 -> 154290.45 | I17: =G17-H17 -> 0 | J17: =IF(I17>0,I17*3%,0) -> 0 | K17: =M$2*F17 -> 6160.8598 | L17: =M$1*F17 -> 72720 | M17: =F$1*F17 -> 25068.809 | N17: =F$2*F17 -> 11341.549 | O17: =I$2*F17 -> 24240 | P17: =ROUND(SUM(I17:O17),0) + R17 -> 139531.45 | Q17: =ROUND(P17*3%,0) + P17 -> 143717.45 | R17: =ROUND(0.001+C17/100,2) -> 0.45
A18: 2 | B18: 4°B | C18: 46 | D18: Raul Boffi | E18: Maria Florencia Boffi | F18: 0.0139 | G18: 106170.46 | H18: =92270.46+13900+3185 -> 109355.46 | I18: =G18-H18 -> -3185 | J18: =IF(I18>0,I18*3%,0) -> 0 | K18: =M$2*F18 -> 4239.4035 | L18: =M$1*F18 -> 50040 | M18: =F$1*F18 -> 17250.319 | N18: =F$2*F18 -> 7804.3329 | O18: =I$2*F18 -> 16680 | P18: =ROUND(SUM(I18:O18),0) + R18 -> 92829.46 | Q18: =ROUND(P18*3%,0) + P18 -> 95614.46 | R18: =ROUND(0.001+C18/100,2) -> 0.46
A19: 3 | B19: 4°C | C19: 47 | D19: Raul Boffi | E19: Norberto omar picin | F19: 0.0139 | G19: 67614.47 | H19: 27614.47 | I19: =G19-H19 -> 40000 | J19: =IF(I19>0,I19*3%,0) -> 1200 | K19: =M$2*F19 -> 4239.4035 | L19: =M$1*F19 -> 50040 | M19: =F$1*F19 -> 17250.319 | N19: =F$2*F19 -> 7804.3329 | O19: =I$2*F19 -> 16680 | P19: =ROUND(SUM(I19:O19),0) + R19 -> 137214.47 | Q19: =ROUND(P19*3%,0) + P19 -> 141330.47 | R19: =ROUND(0.001+C19/100,2) -> 0.47 | S19: TODO LO QUE HABIA DEPOSITADO NORBERTO OMAR PICIN SE LO HABIAMOS PUESTO A EZEQUIEL GARRO ERRONEAMENTE, HAY QUE CORREGIR ESO)
A20: 3 | B20: 4°D | C20: 48 | D20: Hernán Gastón Padilla | E20: Armando Ezequiel Garro | F20: 0.0202 | G20: 154290.48 | H20: =194772.48-H89 -> 154290.33 | I20: =G20-H20 -> 0.15 | J20: =IF(I20>0,I20*3%,0) -> 0.0045 | K20: =M$2*F20 -> 6160.8598 | L20: =M$1*F20 -> 72720 | M20: =F$1*F20 -> 25068.809 | N20: =F$2*F20 -> 11341.549 | O20: =I$2*F20 -> 24240 | P20: =ROUND(SUM(I20:O20),0) + R20 -> 139531.48 | Q20: =ROUND(P20*3%,0) + P20 -> 143717.48 | R20: =ROUND(0.001+C20/100,2) -> 0.48 | S20: 40000+9980+20000+20000+48097+20000+20000+ TODO ESTO ES DE PICIN
A21: 4 | B21: 5°A | C21: 49 | D21: Raul Boffi | E21: Barbara Fucito | F21: 0.0202 | G21: 154290.49 | H21: =G21 -> 154290.49 | I21: =G21-H21 -> 0 | J21: =IF(I21>0,I21*3%,0) -> 0 | K21: =M$2*F21 -> 6160.8598 | L21: =M$1*F21 -> 72720 | M21: =F$1*F21 -> 25068.809 | N21: =F$2*F21 -> 11341.549 | O21: =I$2*F21 -> 24240 | P21: =ROUND(SUM(I21:O21),0) + R21 -> 139531.49 | Q21: =ROUND(P21*3%,0) + P21 -> 143717.49 | R21: =ROUND(0.001+C21/100,2) -> 0.49
A22: 4 | B22: 5°B | C22: 50 | D22: Raul Boffi | F22: 0.0139 | G22: 341684.5 | I22: =G22-H22 -> 341684.5 | J22: =IF(I22>0,I22*3%,0) -> 10250.535 | K22: =M$2*F22 -> 4239.4035 | L22: =M$1*F22 -> 50040 | M22: =F$1*F22 -> 17250.319 | N22: =F$2*F22 -> 7804.3329 | O22: =I$2*F22 -> 16680 | P22: =ROUND(SUM(I22:O22),0) + R22 -> 447949.5 | Q22: =ROUND(P22*3%,0) + P22 -> 461387.5 | R22: =ROUND(0.001+C22/100,2) -> 0.5
A23: 5 | B23: 5°C | C23: 51 | D23: Raul Boffi | E23: Brenda Carrasco | F23: 0.0139 | G23: 172203.51 | I23: =G23-H23 -> 172203.51 | J23: =IF(I23>0,I23*3%,0) -> 5166.1053 | K23: =M$2*F23 -> 4239.4035 | L23: =M$1*F23 -> 50040 | M23: =F$1*F23 -> 17250.319 | N23: =F$2*F23 -> 7804.3329 | O23: =I$2*F23 -> 16680 | P23: =ROUND(SUM(I23:O23),0) + R23 -> 273384.51 | Q23: =ROUND(P23*3%,0) + P23 -> 281586.51 | R23: =ROUND(0.001+C23/100,2) -> 0.51
A24: 5 | B24: 5°D | C24: 52 | D24: Fernando Andres Canepa | E24: Matias / Carla Esteves | F24: 0.0202 | G24: 154290.52 | H24: =20200+150290.52+40482.12-G86 -> 170490.52 | I24: =G24-H24 -> -16200 | J24: =IF(I24>0,I24*3%,0) -> 0 | K24: =M$2*F24 -> 6160.8598 | L24: =M$1*F24 -> 72720 | M24: =F$1*F24 -> 25068.809 | N24: =F$2*F24 -> 11341.549 | O24: =I$2*F24 -> 24240 | P24: =ROUND(SUM(I24:O24),0) + R24 -> 123331.52 | Q24: =ROUND(P24*3%,0) + P24 -> 127031.52 | R24: =ROUND(0.001+C24/100,2) -> 0.52
A25: 6 | B25: 6°A | C25: 53 | D25: Andres Gabriel Devouassoux | F25: 0.0202 | G25: 120367.53 | H25: 123198.53 | I25: =G25-H25 -> -2831 | J25: =IF(I25>0,I25*3%,0) -> 0 | K25: =M$2*F25 -> 6160.8598 | L25: =M$1*F25 -> 72720 | M25: =F$1*F25 -> 25068.809 | N25: =F$2*F25 -> 11341.549 | O25: =I$2*F25 -> 24240 | P25: =ROUND(SUM(I25:O25),0) + R25 -> 136700.53 | Q25: =ROUND(P25*3%,0) + P25 -> 140801.53 | R25: =ROUND(0.001+C25/100,2) -> 0.53
A26: 6 | B26: 6°B | C26: 54 | D26: Raul Boffi | E26: Nicolas Iudice | F26: 0.0139 | G26: 106170.54 | H26: =G26 -> 106170.54 | I26: =G26-H26 -> 0 | J26: =IF(I26>0,I26*3%,0) -> 0 | K26: =M$2*F26 -> 4239.4035 | L26: =M$1*F26 -> 50040 | M26: =F$1*F26 -> 17250.319 | N26: =F$2*F26 -> 7804.3329 | O26: =I$2*F26 -> 16680 | P26: =ROUND(SUM(I26:O26),0) + R26 -> 96014.54 | Q26: =ROUND(P26*3%,0) + P26 -> 98894.54 | R26: =ROUND(0.001+C26/100,2) -> 0.54
A27: 7 | B27: 6°C | C27: 55 | D27: Barbara Eugenia GARCIA FONTENLA | E27: Diego Coronel / Mirta Beatriz Castañeda | F27: 0.0139 | G27: 106171.55 | H27: =95039.55 -> 95039.55 | I27: =G27-H27 -> 11132 | J27: =IF(I27>0,I27*3%,0) -> 333.96 | K27: =M$2*F27 -> 4239.4035 | L27: =M$1*F27 -> 50040 | M27: =F$1*F27 -> 17250.319 | N27: =F$2*F27 -> 7804.3329 | O27: =I$2*F27 -> 16680 | P27: =ROUND(SUM(I27:O27),0) + R27 -> 107480.55 | Q27: =ROUND(P27*3%,0) + P27 -> 110704.55 | R27: =ROUND(0.001+C27/100,2) -> 0.55
A28: 7 | B28: 6°D | C28: 56 | D28: Javier Alejandro Panaccio | E28: Javier Enrique Zambrano | F28: 0.0202 | G28: 237024.56 | H28: =20200.56+200.56+220309-H65 -> 239181.89 | I28: =G28-H28 -> -2157.33 | J28: =IF(I28>0,I28*3%,0) -> 0 | K28: =M$2*F28 -> 6160.8598 | L28: =M$1*F28 -> 72720 | M28: =F$1*F28 -> 25068.809 | N28: =F$2*F28 -> 11341.549 | O28: =I$2*F28 -> 24240 | P28: =ROUND(SUM(I28:O28),0) + R28 -> 137374.56 | Q28: =ROUND(P28*3%,0) + P28 -> 141495.56 | R28: =ROUND(0.001+C28/100,2) -> 0.56
A29: 8 | B29: 7°A | C29: 57 | D29: Mirta Isabel Asturino | F29: 0.0202 | G29: 154290.57 | H29: =G29 -> 154290.57 | I29: =G29-H29 -> 0 | J29: =IF(I29>0,I29*3%,0) -> 0 | K29: =M$2*F29 -> 6160.8598 | L29: =M$1*F29 -> 72720 | M29: =F$1*F29 -> 25068.809 | N29: =F$2*F29 -> 11341.549 | O29: =I$2*F29 -> 24240 | P29: =ROUND(SUM(I29:O29),0) + R29 -> 139531.57 | Q29: =ROUND(P29*3%,0) + P29 -> 143717.57 | R29: =ROUND(0.001+C29/100,2) -> 0.57
A30: 8 | B30: 7°B | C30: 58 | D30: Jorge Antonio Mendiola | E30: Carlos Mehinger Lisa | F30: 0.0139 | G30: 106170.58 | H30: =13900.58+92270.58 -> 106171.16 | I30: =G30-H30 -> -0.58 | J30: =IF(I30>0,I30*3%,0) -> 0 | K30: =M$2*F30 -> 4239.4035 | L30: =M$1*F30 -> 50040 | M30: =F$1*F30 -> 17250.319 | N30: =F$2*F30 -> 7804.3329 | O30: =I$2*F30 -> 16680 | P30: =ROUND(SUM(I30:O30),0) + R30 -> 96013.58 | Q30: =ROUND(P30*3%,0) + P30 -> 98893.58 | R30: =ROUND(0.001+C30/100,2) -> 0.58
A31: 9 | B31: 7°C | C31: 59 | D31: Nelson Ariel FRAGA | F31: 0.0139 | G31: 205309.59 | H31: =205309.59 -> 205309.59 | I31: =G31-H31 -> 0 | J31: =IF(I31>0,I31*3%,0) -> 0 | K31: =M$2*F31 -> 4239.4035 | L31: =M$1*F31 -> 50040 | M31: =F$1*F31 -> 17250.319 | N31: =F$2*F31 -> 7804.3329 | O31: =I$2*F31 -> 16680 | P31: =ROUND(SUM(I31:O31),0) + R31 -> 96014.59 | Q31: =ROUND(P31*3%,0) + P31 -> 98894.59 | R31: =ROUND(0.001+C31/100,2) -> 0.59
A32: 9 | B32: 7°D | C32: 60 | D32: Domingo Alifraco | E32: Micaela Contreras | F32: 0.0202 | G32: 154878.6 | H32: 154879 | I32: =G32-H32 -> -0.4 | J32: =IF(I32>0,I32*3%,0) -> 0 | K32: =M$2*F32 -> 6160.8598 | L32: =M$1*F32 -> 72720 | M32: =F$1*F32 -> 25068.809 | N32: =F$2*F32 -> 11341.549 | O32: =I$2*F32 -> 24240 | P32: =ROUND(SUM(I32:O32),0) + R32 -> 139531.6 | Q32: =ROUND(P32*3%,0) + P32 -> 143717.6 | R32: =ROUND(0.001+C32/100,2) -> 0.6
A33: 10 | B33: 8°A | C33: 61 | D33: Juan Pablo Charpin | F33: 0.0202 | G33: 154290.61 | H33: =169272.74-H87 -> 128790.61 | I33: =G33-H33 -> 25500 | J33: =IF(I33>0,I33*3%,0) -> 765 | K33: =M$2*F33 -> 6160.8598 | L33: =M$1*F33 -> 72720 | M33: =F$1*F33 -> 25068.809 | N33: =F$2*F33 -> 11341.549 | O33: =I$2*F33 -> 24240 | P33: =ROUND(SUM(I33:O33),0) + R33 -> 165796.61 | Q33: =ROUND(P33*3%,0) + P33 -> 170770.61 | R33: =ROUND(0.001+C33/100,2) -> 0.61
A34: 10 | B34: 8°B | C34: 62 | D34: Adriana Del Bagno | E34: Fanta / Alejandro Gabriel Lopez | F34: 0.0139 | G34: 106170.62 | H34: =109365.52 -> 109365.52 | I34: =G34-H34 -> -3194.9 | J34: =IF(I34>0,I34*3%,0) -> 0 | K34: =M$2*F34 -> 4239.4035 | L34: =M$1*F34 -> 50040 | M34: =F$1*F34 -> 17250.319 | N34: =F$2*F34 -> 7804.3329 | O34: =I$2*F34 -> 16680 | P34: =ROUND(SUM(I34:O34),0) + R34 -> 92819.62 | Q34: =ROUND(P34*3%,0) + P34 -> 95604.62 | R34: =ROUND(0.001+C34/100,2) -> 0.62
A35: 11 | B35: 8°C | C35: 63 | D35: Claudio Moroni | E35: Macarena Barraza | F35: 0.0139 | G35: 106170.63 | H35: =G35 -> 106170.63 | I35: =G35-H35 -> 0 | J35: =IF(I35>0,I35*3%,0) -> 0 | K35: =M$2*F35 -> 4239.4035 | L35: =M$1*F35 -> 50040 | M35: =F$1*F35 -> 17250.319 | N35: =F$2*F35 -> 7804.3329 | O35: =I$2*F35 -> 16680 | P35: =ROUND(SUM(I35:O35),0) + R35 -> 96014.63 | Q35: =ROUND(P35*3%,0) + P35 -> 98894.63 | R35: =ROUND(0.001+C35/100,2) -> 0.63
A36: 11 | B36: 8°D | C36: 64 | D36: Karina Edith Mastandrea | E36: Ayelen Agustina | F36: 0.0202 | G36: 88536.64 | H36: =150000 -> 150000 | I36: =G36-H36 -> -61463.36 | J36: =IF(I36>0,I36*3%,0) -> 0 | K36: =M$2*F36 -> 6160.8598 | L36: =M$1*F36 -> 72720 | M36: =F$1*F36 -> 25068.809 | N36: =F$2*F36 -> 11341.549 | O36: =I$2*F36 -> 24240 | P36: =ROUND(SUM(I36:O36),0) + R36 -> 78068.64 | Q36: =ROUND(P36*3%,0) + P36 -> 80410.64 | R36: =ROUND(0.001+C36/100,2) -> 0.64
A37: 12 | B37: 9°A | C37: 65 | D37: Fernando Fernandez | E37: Olivera Rodrigo | F37: 0.0202 | G37: 150368.65 | H37: =G37 -> 150368.65 | I37: =G37-H37 -> 0 | J37: =IF(I37>0,I37*3%,0) -> 0 | K37: =M$2*F37 -> 6160.8598 | L37: =M$1*F37 -> 72720 | M37: =F$1*F37 -> 25068.809 | N37: =F$2*F37 -> 11341.549 | O37: =I$2*F37 -> 24240 | P37: =ROUND(SUM(I37:O37),0) + R37 -> 139531.65 | Q37: =ROUND(P37*3%,0) + P37 -> 143717.65 | R37: =ROUND(0.001+C37/100,2) -> 0.65
A38: 12 | B38: 9°B | C38: 66 | D38: Gonzalo Cadiz | E38: Micaela Dib | F38: 0.0139 | G38: 198850.66 | I38: =G38-H38 -> 198850.66 | J38: =IF(I38>0,I38*3%,0) -> 5965.5198 | K38: =M$2*F38 -> 4239.4035 | L38: =M$1*F38 -> 50040 | M38: =F$1*F38 -> 17250.319 | N38: =F$2*F38 -> 7804.3329 | O38: =I$2*F38 -> 16680 | P38: =ROUND(SUM(I38:O38),0) + R38 -> 300830.66 | Q38: =ROUND(P38*3%,0) + P38 -> 309855.66 | R38: =ROUND(0.001+C38/100,2) -> 0.66
A39: 1 | B39: 9°C | C39: 67 | D39: Hernan Miñambres | E39: Laura Quintana | F39: 0.0139 | G39: 188028.67 | H39: =168651.67 -> 168651.67 | I39: =G39-H39 -> 19377 | J39: =IF(I39>0,I39*3%,0) -> 581.31 | K39: =M$2*F39 -> 4239.4035 | L39: =M$1*F39 -> 50040 | M39: =F$1*F39 -> 17250.319 | N39: =F$2*F39 -> 7804.3329 | O39: =I$2*F39 -> 16680 | P39: =ROUND(SUM(I39:O39),0) + R39 -> 115972.67 | Q39: =ROUND(P39*3%,0) + P39 -> 119451.67 | R39: =ROUND(0.001+C39/100,2) -> 0.67
A40: 1 | B40: 9°D | C40: 68 | D40: Matías Ezequiel Tobío | E40: =D76 -> Jesica Romina Tobio | F40: 0.0202 | G40: 149124.68 | H40: =198008.7-H76 -> 149124.68 | I40: =G40-H40 -> 0 | J40: =IF(I40>0,I40*3%,0) -> 0 | K40: =M$2*F40 -> 6160.8598 | L40: =M$1*F40 -> 72720 | M40: =F$1*F40 -> 25068.809 | N40: =F$2*F40 -> 11341.549 | O40: =I$2*F40 -> 24240 | P40: =ROUND(SUM(I40:O40),0) + R40 -> 139531.68 | Q40: =ROUND(P40*3%,0) + P40 -> 143717.68 | R40: =ROUND(0.001+C40/100,2) -> 0.68
...

Sheet anotaciones 
D4: LA COCHERA S.S31 DE MICAELA CONTRERAS ESTABA ABONADA EL MES PASADO CON UN MONTO DE 91,358 , SIN EMBARGO ESE MONTO LO PUSIMOS EN LA UF 60 COMO DINERO A FAVOR, CORREGIR ESO
D8: AGUSTINA AYELEN MARTINEZ PAGA EK 8D Y LA COCHERA S.S 22, DESDE SIEMPRE LE PONEMOS PAGO EL 8D PERO COMO NO SABIAMOS QUE TAMBIEN PAGA LA COCHERA S.S 22 LA COCHERA LE QUEDABA IMPAGA, RASTREAR LOS PAGOS Y RESTAR LO NECESARIO
D12: QUE QUEDE SIN DEUDA
D15: PABLO PLEBS TIENE UNA TRANSFERENCIA DE $91.922,35 EN ABRIL QUE NO SE LA IMPUTAMOS NUNCA (NI COMO TRANSF NO IDENTIDICADA) POR ENDE NO DEBE TENER DEUDA ALGUNA - ES MAS, SEGÚN ROMI EL PAGO (ESTE MES, EN JUNIO) 119 MIL Y PICO, POR ENDE LE DEBE QUEDAR DINERO A FAVOR
D18: hay que agregar a luzalberio@gmail.com a la cadena, es nueva inquilina del 10D
D21: el mes pasado quedo debiendo 5,300$ cuando es incorrecto, debe quedar sin deuda (si es que este mes abono)
