Workbook

Sheet RESUMEN
B1: MAIL: centerlongaleria@gmail.com
B2: CUIT ADMINISTRACION: 27231256879
B3: TELEFONO: 11 5320-2676
A4: LIQUIDACION DE EXPENSAS | B4: ADMINISTRADORA: CAROLINA CANCIANI MP:1148
A5: CUIT DEL EDIFICIO: 30-66055743-8 - PERÍODO: OCTUBRE - HORARIOS DE ATENCION: LUNES A VIERNES 10 A 16HS
A6: CONSORCIO DE COPROPIETARIOS GALERIA BOEDO 266/270 LOMAS DE ZAMORA
B8: VTO 14/11
A13: ESTIMADOS PROPIETARIOS E INQUILINOS: POR FAVOR LOS QUE ABONAN EN PRIMER VENCIMIENTO ABONEN EL MONTO DE PRIMER VENCIMIENTO, ASI AGILIZAN LA LIQUIDACION, RESPETEN LOS CENTAVOS CORRESPONDIENTES A LA UNIDAD FUNCIONAL. ES DE CARÁCTER OBLIGATORIO INFORMAR VIA MAIL LAS EXPENSAS. CASO CONTRARIO SE INFORMARA VIA CARTA DOCUMENTO A LA UNIDAD FUNCIONAL QUE CREEMOS QUE CORRESPONDE, CUYO COSTO SERA IMPUTADO A LA UNIDAD FUNCIONAL SOSPECHADA.
A20: GASTOS ORDINARIOS UNIDADES FUNCIONALES:
A21: HONORARIOS
A22: Honorarios administracion rc - Se adeuda SEPTIEMBRE Y OCTUBRE | E22: Falta de fondos
A23: TOTAL | E23: =SUM(D22:D22) -> 0
A24: SEGUROS
A25: Mercantil andina seguro integral de consorcio - Poliza nro. 001166139 - OCTUBRE | D25: 111486 | E25: Debito 08/10
A26: TOTAL IMPUESTO | E26: =SUM(D25:D25) -> 111486
A27: ABONOS Y SERVICIOS
A28: AYSA - Cuenta nro. 3480025 | B28: EN JUICIO - NO SE ABONA
A29: EDESUR - Cliente Nro. 80084190 | D29: 753904.2 | E29: Debito 07/10
A32: TOTAL ABONOS Y SERVICIOS | E32: =SUM(D28:D31) -> 753904.2
A33: GASTOS GENERALES / MANTENIMIENTO
A34: Servisur - Cambio de luces en toda la galeria, mano de obra y materiales | D34: =285725+69575+300000 -> 655300 | E34: Transf 07/10 - 15/10 y 23/10
A35: Sra. Silvana mantenimiento y limpieza - 10 dias | E35: Falta de fondos | H35: Pendiente para Noviembre: | J35: Sra. Silvana mantenimiento y limpieza - 10 dias .- $159300
A36: TOTAL | E36: =SUM(D34:D35) -> 655300
A37: GASTOS BANCARIOS
A38: GASTOS BANCARIOS - MES DE OCTUBRE | D38: =30569.65-2098 -> 28471.65
A39: COMISION POR CUENTA - OCTUBRE | D39: =44400 -> 44400
A40: TOTAL | E40: =SUM(D38:D39) -> 72871.65
A42: PREVISION ORDINARIA - HONORARIOS DE ADMINISTARCION + SERVICIO DE LIMPIEZA | E42: =3000000-1595659.85+2098 -> 1406438.1
A44: TOTAL ORDINARIOS | E44: =(SUM(E21:E42)) -> 3000000
A47: GASTOS EXTRAORDINARIOS UNIDADES FUNCIONALES:
E53: =SUM(D48:D52) -> 0
A56: PREVISION EXTRAORDINARIA
A58: TOTAL EXTRAORDINARIOS | E58: =E53+E56 -> 0
A60: GASTOS ORDINARIOS + PREVISION : | B60: =E44 -> 3000000
A61: GASTOS ORDINARIOS SIN PREVISION: | B61: =E44-E42 -> 1593561.9
A62: GASTOS EXTRAORDINARIOS SIN PREVISION: | B62: =E58-E56 -> 0
A63: GASTOS EXTRAORDINARIOS CON PREVISION: | B63: =E58 -> 0
A70: RESUMEN
A71: Saldo anterior | B71: 940446.91
A72: Ingreso Ordinarias | B72: =PRORRATEO!G34 -> 1009547.6
...

Sheet PRORRATEO
C1: Titularidad: CONS DE PROP BOEDO 266 Banco: Santander Cuenta: CC$ 029-030888/3 CBU: 0720029820000003088836 Alias: ALA.CATRE.FUERTE
J3: Gastos ordinarios a prorratear: | L3: 3000000
J4: Gastos ordinarios a prorratear:
A5: Piso | B5: UF | C5: Propietario | D5: Inquilinos | E5: (%) | F5: Saldo Ord | G5: Ingresos | H5: Deuda o Saldo a favor | I5: Intereses | J5: Expensas extraor. | K5: Expensas ord. | L5: Gastos part. | M5: Total 1er Vto | N5: Total 2do Vto. | O5: Total 2do Vto
M6: =RESUMEN!B8 -> VTO 14/11
A7: PB | B7: 1 | C7: ZAFFINO, Fernando | E7: 6.8 | F7: 170000.01 | G7: =151000+19000 -> 170000 | H7: =F7-G7 -> 0.01 | I7: =IF(H7>0,H7*15%,0) -> 0.0015 | J7: =L$4*E7/100 -> 0 | K7: =L$3*E7/100 -> 204000 | L7: 0 | M7: =ROUND(SUM(H7:L7),0) + P7 -> 204000.01 | N7: =ROUND(M7*6% + M7,0) + P7 -> 216240.01 | O7: =ROUND(M7*3%,0) + M7 -> 210120.01 | P7: 0.01
A8: 3º | B8: =B7+1 -> 2 | C8: BERESTEIN, Javier | E8: 5.1 | F8: 127500.02 | G8: =F8 -> 127500.02 | H8: =F8-G8 -> 0 | I8: =IF(H8>0,H8*15%,0) -> 0 | J8: =L$4*E8/100 -> 0 | K8: =L$3*E8/100 -> 153000 | L8: 0 | M8: =ROUND(SUM(H8:L8),0) + P8 -> 153000.02 | N8: =ROUND(M8*6% + M8,0) + P8 -> 162180.02 | O8: =ROUND(M8*3%,0) + M8 -> 157590.02 | P8: =P7+0.01 -> 0.02
A9: 3º | B9: =B8+1 -> 3 | C9: VAZQUEZ PALLARES, Juan | E9: 5.6 | F9: EN JUICIO | G9: EN JUICIO | I9: =IF(H9>0,H9*15%,0) -> 0 | J9: =L$4*E9/100 -> 0 | K9: =L$3*E9/100 -> 168000 | L9: 0 | M9: =ROUND(SUM(H9:L9),0) + P9 -> 168000.03 | N9: =ROUND(M9*6% + M9,0) + P9 -> 178080.03 | O9: EN JUICIO | P9: =P8+0.01 -> 0.03
A10: 4º | B10: =B9+1 -> 4 | C10: HUINCA HUEMUL S.A. | E10: 2.8 | F10: -12823.96 | H10: =F10-G10 -> -12823.96 | I10: =IF(H10>0,H10*15%,0) -> 0 | J10: =L$4*E10/100 -> 0 | K10: =L$3*E10/100 -> 84000 | L10: 0 | M10: =ROUND(SUM(H10:L10),0) + P10 -> 71176.04 | N10: =ROUND(M10*6% + M10,0) + P10 -> 75447.04 | O10: =ROUND(M10*3%,0) + M10 -> 73311.04 | P10: =P9+0.01 -> 0.04 | R10: Maria Fernanda Garcia
A11: 4º | B11: =B10+1 -> 5 | C11: LAZARTE, Irma | E11: 2.8 | F11: 169055.05 | G11: 99055 | H11: =F11-G11 -> 70000.05 | I11: =IF(H11>0,H11*15%,0) -> 10500.007 | J11: =L$4*E11/100 -> 0 | K11: =L$3*E11/100 -> 84000 | L11: 0 | M11: =ROUND(SUM(H11:L11),0) + P11 -> 164500.05 | N11: =ROUND(M11*6% + M11,0) + P11 -> 174370.05 | O11: =ROUND(M11*3%,0) + M11 -> 169435.05 | P11: =P10+0.01 -> 0.05
A12: 5º | B12: =B11+1 -> 6 | C12: MINOCHIO, Gustavo | E12: 2.8 | F12: 69391.06 | G12: =F12 -> 69391.06 | H12: =F12-G12 -> 0 | I12: =IF(H12>0,H12*15%,0) -> 0 | J12: =L$4*E12/100 -> 0 | K12: =L$3*E12/100 -> 84000 | L12: 0 | M12: =ROUND(SUM(H12:L12),0) + P12 -> 84000.06 | N12: =ROUND(M12*6% + M12,0) + P12 -> 89040.06 | O12: =ROUND(M12*3%,0) + M12 -> 86520.06 | P12: =P11+0.01 -> 0.06 | R12: Melanie P
A13: 5º | B13: =B12+1 -> 7 | C13: QUIROGA, Karina | E13: 4 | F13: 662810.07 | G13: 0 | H13: =F13-G13 -> 662810.07 | I13: =IF(H13>0,H13*15%,0) -> 99421.51 | J13: =L$4*E13/100 -> 0 | K13: =L$3*E13/100 -> 120000 | L13: 0 | M13: =ROUND(SUM(H13:L13),0) + P13 -> 882232.07 | N13: =ROUND(M13*6% + M13,0) + P13 -> 935166.07 | O13: =ROUND(M13*3%,0) + M13 -> 908699.07 | P13: =P12+0.01 -> 0.07
A14: 6º | B14: =B13+1 -> 8 | C14: PENAS, Roberto | E14: 3.2 | F14: 752887.08 | G14: 0 | H14: =F14-G14 -> 752887.08 | I14: =IF(H14>0,H14*15%,0) -> 112933.06 | J14: =L$4*E14/100 -> 0 | K14: =L$3*E14/100 -> 96000 | L14: 0 | M14: =ROUND(SUM(H14:L14),0) + P14 -> 961820.08 | N14: =ROUND(M14*6% + M14,0) + P14 -> 1019529.1 | O14: =ROUND(M14*3%,0) + M14 -> 990675.08 | P14: =P13+0.01 -> 0.08
A15: 6º | B15: =B14+1 -> 9 | C15: MURPHY, Gabriel | E15: 2.8 | F15: 686006.09 | G15: 0 | H15: =F15-G15 -> 686006.09 | I15: =IF(H15>0,H15*15%,0) -> 102900.91 | J15: =L$4*E15/100 -> 0 | K15: =L$3*E15/100 -> 84000 | L15: 0 | M15: =ROUND(SUM(H15:L15),0) + P15 -> 872907.09 | N15: =ROUND(M15*6% + M15,0) + P15 -> 925282.09 | O15: =ROUND(M15*3%,0) + M15 -> 899094.09 | P15: =P14+0.01 -> 0.09
A16: 7º | B16: =B15+1 -> 10 | C16: JAURETCHE, Claudio | E16: 2.8 | F16: EN JUICIO | G16: EN JUICIO | I16: =IF(H16>0,H16*15%,0) -> 0 | J16: =L$4*E16/100 -> 0 | K16: =L$3*E16/100 -> 84000 | L16: 0 | M16: =ROUND(SUM(H16:L16),0) + P16 -> 84000.1 | N16: =ROUND(M16*6% + M16,0) + P16 -> 89040.1 | O16: EN JUICIO | P16: =P15+0.01 -> 0.1
A17: 7º | B17: =B16+1 -> 11 | C17: BRUZZONE, Héctor | E17: 2.8 | F17: EN JUICIO | G17: EN JUICIO | I17: =IF(H17>0,H17*15%,0) -> 0 | J17: =L$4*E17/100 -> 0 | K17: =L$3*E17/100 -> 84000 | L17: 0 | M17: =ROUND(SUM(H17:L17),0) + P17 -> 84000.11 | N17: =ROUND(M17*6% + M17,0) + P17 -> 89040.11 | O17: EN JUICIO | P17: =P16+0.01 -> 0.11
A18: 8º | B18: =B17+1 -> 12 | C18: HUINCA HUEMUL S.A. | E18: 2.8 | F18: 70000.12 | G18: =F18 -> 70000.12 | H18: =F18-G18 -> 0 | I18: =IF(H18>0,H18*15%,0) -> 0 | J18: =L$4*E18/100 -> 0 | K18: =L$3*E18/100 -> 84000 | L18: 0 | M18: =ROUND(SUM(H18:L18),0) + P18 -> 84000.12 | N18: =ROUND(M18*6% + M18,0) + P18 -> 89040.12 | O18: =ROUND(M18*3%,0) + M18 -> 86520.12 | P18: =P17+0.01 -> 0.12
A19: 8º | B19: =B18+1 -> 13 | C19: CALVI, José | E19: 5.1 | F19: 535652.13 | H19: =F19-G19 -> 535652.13 | I19: =IF(H19>0,H19*15%,0) -> 80347.819 | J19: =L$4*E19/100 -> 0 | K19: =L$3*E19/100 -> 153000 | L19: 0 | M19: =ROUND(SUM(H19:L19),0) + P19 -> 769000.13 | N19: =ROUND(M19*6% + M19,0) + P19 -> 815140.13 | O19: =ROUND(M19*3%,0) + M19 -> 792070.13 | P19: =P18+0.01 -> 0.13
A20: 9º | B20: =B19+1 -> 14 | C20: PENAS, Roberto | E20: 2.6 | F20: 497289.14 | G20: 0 | H20: =F20-G20 -> 497289.14 | I20: =IF(H20>0,H20*15%,0) -> 74593.371 | J20: =L$4*E20/100 -> 0 | K20: =L$3*E20/100 -> 78000 | L20: 0 | M20: =ROUND(SUM(H20:L20),0) + P20 -> 649883.14 | N20: =ROUND(M20*6% + M20,0) + P20 -> 688876.14 | O20: =ROUND(M20*3%,0) + M20 -> 669379.14 | P20: =P19+0.01 -> 0.14
A21: 9º | B21: =B20+1 -> 15 | C21: KOCKA, José | E21: 2.8 | F21: 66500.15 | G21: 66500 | H21: =F21-G21 -> 0.15 | I21: =IF(H21>0,H21*15%,0) -> 0.0225 | J21: =L$4*E21/100 -> 0 | K21: =L$3*E21/100 -> 84000 | L21: 0 | M21: =ROUND(SUM(H21:L21),0) + P21 -> 84000.15 | N21: =ROUND(M21*6% + M21,0) + P21 -> 89040.15 | O21: =ROUND(M21*3%,0) + M21 -> 86520.15 | P21: =P20+0.01 -> 0.15
A22: 10º | B22: =B21+1 -> 16 | C22: LASSALLE, Cristina | E22: 2.6 | F22: 61910.16 | G22: 63800 | H22: =F22-G22 -> -1889.84 | I22: =IF(H22>0,H22*15%,0) -> 0 | J22: =L$4*E22/100 -> 0 | K22: =L$3*E22/100 -> 78000 | L22: 0 | M22: =ROUND(SUM(H22:L22),0) + P22 -> 76110.16 | N22: =ROUND(M22*6% + M22,0) + P22 -> 80677.16 | O22: =ROUND(M22*3%,0) + M22 -> 78393.16 | P22: =P21+0.01 -> 0.16
A23: 10º | B23: =B22+1 -> 17 | C23: LUCERO, Olga | E23: 4.5 | F23: 479724.17 | H23: =F23-G23 -> 479724.17 | I23: =IF(H23>0,H23*15%,0) -> 71958.625 | J23: =L$4*E23/100 -> 0 | K23: =L$3*E23/100 -> 135000 | L23: 0 | M23: =ROUND(SUM(H23:L23),0) + P23 -> 686683.17 | N23: =ROUND(M23*6% + M23,0) + P23 -> 727884.17 | O23: =ROUND(M23*3%,0) + M23 -> 707283.17 | P23: =P22+0.01 -> 0.17
A24: 11º | B24: =B23+1 -> 18 | C24: MINOCHIO, Gustavo | E24: 2.8 | F24: 70000.18 | G24: =F24 -> 70000.18 | H24: =F24-G24 -> 0 | I24: =IF(H24>0,H24*15%,0) -> 0 | J24: =L$4*E24/100 -> 0 | K24: =L$3*E24/100 -> 84000 | L24: 0 | M24: =ROUND(SUM(H24:L24),0) + P24 -> 84000.18 | N24: =ROUND(M24*6% + M24,0) + P24 -> 89040.18 | O24: =ROUND(M24*3%,0) + M24 -> 86520.18 | P24: =P23+0.01 -> 0.18
A25: 11º | B25: =B24+1 -> 19 | C25: VERA, Ricardo | E25: 2.8 | F25: 399567.19 | G25: 70000 | H25: =F25-G25 -> 329567.19 | I25: =IF(H25>0,H25*15%,0) -> 49435.078 | J25: =L$4*E25/100 -> 0 | K25: =L$3*E25/100 -> 84000 | L25: 0 | M25: =ROUND(SUM(H25:L25),0) + P25 -> 463002.19 | N25: =ROUND(M25*6% + M25,0) + P25 -> 490782.19 | O25: =ROUND(M25*3%,0) + M25 -> 476892.19 | P25: =P24+0.01 -> 0.19
A26: 12º | B26: =B25+1 -> 20 | C26: HUINCA HUEMUL S.A. | E26: 2.8 | F26: 70001.2 | G26: 72101.2 | H26: =F26-G26 -> -2100 | I26: =IF(H26>0,H26*15%,0) -> 0 | J26: =L$4*E26/100 -> 0 | K26: =L$3*E26/100 -> 84000 | L26: 0 | M26: =ROUND(SUM(H26:L26),0) + P26 -> 81900.2 | N26: =ROUND(M26*6% + M26,0) + P26 -> 86814.2 | O26: =ROUND(M26*3%,0) + M26 -> 84357.2 | P26: =P25+0.01 -> 0.2
A27: 13º | B27: =B26+1 -> 21 | C27: QUIROGA, Karina | E27: 3 | F27: 497108.21 | G27: 0 | H27: =F27-G27 -> 497108.21 | I27: =IF(H27>0,H27*15%,0) -> 74566.231 | J27: =L$4*E27/100 -> 0 | K27: =L$3*E27/100 -> 90000 | L27: 0 | M27: =ROUND(SUM(H27:L27),0) + P27 -> 661674.21 | N27: =ROUND(M27*6% + M27,0) + P27 -> 701375.21 | O27: =ROUND(M27*3%,0) + M27 -> 681524.21 | P27: =P26+0.01 -> 0.21
A28: 14º | B28: =B27+1 -> 22 | C28: QUIROGA, Karina | E28: 4.1 | F28: 679381.22 | G28: 0 | H28: =F28-G28 -> 679381.22 | I28: =IF(H28>0,H28*15%,0) -> 101907.18 | J28: =L$4*E28/100 -> 0 | K28: =L$3*E28/100 -> 123000 | L28: 0 | M28: =ROUND(SUM(H28:L28),0) + P28 -> 904288.22 | N28: =ROUND(M28*6% + M28,0) + P28 -> 958546.22 | O28: =ROUND(M28*3%,0) + M28 -> 931417.22 | P28: =P27+0.01 -> 0.22
A29: 15º | B29: =B28+1 -> 23 | C29: SALAZAR, Javier | E29: 5.1 | F29: 131280.23 | G29: 131200 | H29: =F29-G29 -> 80.23 | I29: =IF(H29>0,H29*15%,0) -> 12.0345 | J29: =L$4*E29/100 -> 0 | K29: =L$3*E29/100 -> 153000 | L29: 0 | M29: =ROUND(SUM(H29:L29),0) + P29 -> 153092.23 | N29: =ROUND(M29*6% + M29,0) + P29 -> 162278.23 | O29: =ROUND(M29*3%,0) + M29 -> 157685.23 | P29: =P28+0.01 -> 0.23
A30: COC | B30: =B29+1 -> 24 | C30: QUIROGA, Karina | E30: 5.9 | F30: 977645.24 | G30: 0 | H30: =F30-G30 -> 977645.24 | I30: =IF(H30>0,H30*15%,0) -> 146646.79 | J30: =L$4*E30/100 -> 0 | K30: =L$3*E30/100 -> 177000 | L30: 0 | M30: =ROUND(SUM(H30:L30),0) + P30 -> 1301292.2 | N30: =ROUND(M30*6% + M30,0) + P30 -> 1379370.2 | O30: =ROUND(M30*3%,0) + M30 -> 1340331.2 | P30: =P29+0.01 -> 0.24
A31: COC | B31: =B30+1 -> 25 | C31: QUINTANA, Hector | E31: 5.5 | F31: EN JUICIO | G31: EN JUICIO | I31: =IF(H31>0,H31*15%,0) -> 0 | J31: =L$4*E31/100 -> 0 | K31: =L$3*E31/100 -> 165000 | L31: 0 | M31: =ROUND(SUM(H31:L31),0) + P31 -> 165000.25 | N31: =ROUND(M31*6% + M31,0) + P31 -> 174900.25 | O31: EN JUICIO | P31: =P30+0.01 -> 0.25
A32: COC | B32: =B31+1 -> 26 | C32: MURPHY, Gabriel | E32: 6.1 | F32: 1170821.3 | G32: 0 | H32: =F32-G32 -> 1170821.3 | I32: =IF(H32>0,H32*15%,0) -> 175623.19 | J32: =L$4*E32/100 -> 0 | K32: =L$3*E32/100 -> 183000 | L32: 0 | M32: =ROUND(SUM(H32:L32),0) + P32 -> 1529444.3 | N32: =ROUND(M32*6% + M32,0) + P32 -> 1621211.3 | O32: =ROUND(M32*3%,0) + M32 -> 1575327.3 | P32: =P31+0.01 -> 0.26
A33: COC
E34: =SUM(E7:E33) -> 100 | F34: =SUM(F7:F33) -> 8331706 | G34: =SUM(G7:G33) -> 1009547.6 | H34: =SUM(H7:H32) -> 7322158.4 | J34: =SUM(J7:J33) -> 0 | K34: =SUM(K7:K33) -> 3000000 | L34: =SUM(L7:L33) -> 0 | M34: =SUM(M7:M33) -> 11423007 | N34: =SUM(N7:N33) -> 12108391 | O34: =SUM(O7:O33) -> 11249665
C37: LAS FILAS COLOREADAS CON GRIS CORRESPONDEN A PLANES DE PAGO EN VIGENCIA O FINALIZADOS QUE EN EL TRANSCURSO DE LA SEMANA NOS IREMOS COMUNICANDO CON ELLOS PARA ESTAR AL TANTO DE LA SITUACION (CUOTAS CAIDAS). SI QUIEREN COMUNICARSE CON LA ADMINISTRACION PUEDEN HACERLO MEDIANTE WHATSAPP AL 11-5320-2676. A QUIENES LES FIGURA UN SALDO NEGATIVO EN LA COLUMNA LLAMADA "DEUDA O SALDO A FAVOR" SIGNIFICA QUE POSEE DINERO A FAVOR, ES DECIR PAGO POR DEMAS.

Sheet PRORRATEO (2)
D1: Formas de Pago: Cuenta corriente Nro. 740-015772/0 Santander
D2: =RESUMEN!B3 -> TELEFONO: 11 5320-2676 | L2: Gastos extraordinarios: | O2: 0
D3: Efectivo
A4: Piso | B4: Dpto. | C4: UF | D4: Propietario | E4: Inquilinos | F4: (%) | G4: Saldo Extraord | H4: Ingreso | I4: Pago por | J4: Deuda o Saldo a favor | K4: Interes | L4: Expensas extraor. | M4: Expensas extraord | N4: Gastos part. | O4: Total 1er Vto | P4: Total 2do Vto. | Q4: Total 2do Vto
O5: =RESUMEN!B8 -> VTO 14/11
A6: PB | B6: PB B | C6: 1 | D6: TULA CARLOS (2) | F6: 1.65 | G6: 0 | H6: =G6 -> 0 | J6: =G6-H6 -> 0 | K6: =IF(J6>0,J6*3%,0) -> 0 | L6: 0 | M6: =O$2*F6% -> 0 | N6: 0 | O6: =ROUND(SUM(J6:N6),0) + R6 -> 0.01 | P6: =ROUND(O6*6% + O6,0) + R6 -> 0.01 | Q6: =ROUND(O6*3%,0) + O6 -> 0.01 | R6: 0.01
A7: 3º | B7: PB C | C7: =C6+1 -> 2 | D7: COMBRE ALFREDO | F7: 1.16 | G7: 0 | H7: =G7 -> 0 | J7: =G7-H7 -> 0 | K7: =IF(J7>0,J7*3%,0) -> 0 | L7: 0 | M7: =O$2*F7% -> 0 | N7: 0 | O7: =ROUND(SUM(J7:N7),0) + R7 -> 0.02 | P7: =ROUND(O7*6% + O7,0) + R7 -> 0.02 | Q7: =ROUND(O7*3%,0) + O7 -> 0.02 | R7: =R6+0.01 -> 0.02
A8: 3º | B8: PB D | C8: =C7+1 -> 3 | D8: PRGICH FEDERICO | F8: 1.19 | G8: 0 | H8: =G8 -> 0 | J8: =G8-H8 -> 0 | K8: =IF(J8>0,J8*3%,0) -> 0 | L8: 0 | M8: =O$2*F8% -> 0 | N8: 0 | O8: =ROUND(SUM(J8:N8),0) + R8 -> 0.03 | P8: =ROUND(O8*6% + O8,0) + R8 -> 0.03 | Q8: =ROUND(O8*3%,0) + O8 -> 0.03 | R8: =R7+0.01 -> 0.03
A9: 4º | B9: PB E | C9: =C8+1 -> 4 | D9: SRUGO DAMIAN | F9: 1.22 | G9: 0 | H9: =G9 -> 0 | J9: =G9-H9 -> 0 | K9: =IF(J9>0,J9*3%,0) -> 0 | L9: 0 | M9: =O$2*F9% -> 0 | N9: 0 | O9: =ROUND(SUM(J9:N9),0) + R9 -> 0.04 | P9: =ROUND(O9*6% + O9,0) + R9 -> 0.04 | Q9: =ROUND(O9*3%,0) + O9 -> 0.04 | R9: =R8+0.01 -> 0.04
A10: 4º | B10: 1-A | C10: =C9+1 -> 5 | D10: ZELANSNY SILVIA | F10: 1.67 | J10: =G10-H10 -> 0 | K10: =IF(J10>0,J10*3%,0) -> 0 | L10: 0 | M10: =O$2*F10% -> 0 | N10: 0 | O10: =ROUND(SUM(J10:N10),0) + R10 -> 0.05 | P10: =ROUND(O10*6% + O10,0) + R10 -> 0.05 | Q10: =ROUND(O10*3%,0) + O10 -> 0.05 | R10: =R9+0.01 -> 0.05
A11: 5º | B11: 1-B | C11: =C10+1 -> 6 | D11: PICO HEBE | F11: 1.71 | G11: 0 | H11: =G11 -> 0 | J11: =G11-H11 -> 0 | K11: =IF(J11>0,J11*3%,0) -> 0 | L11: 0 | M11: =O$2*F11% -> 0 | N11: 0 | O11: =ROUND(SUM(J11:N11),0) + R11 -> 0.06 | P11: =ROUND(O11*6% + O11,0) + R11 -> 0.06 | Q11: =ROUND(O11*3%,0) + O11 -> 0.06 | R11: =R10+0.01 -> 0.06
A12: 5º | B12: 1-C | C12: =C11+1 -> 7 | D12: RAMOS ROSA | F12: 1.13 | G12: 0 | H12: =G12 -> 0 | J12: =G12-H12 -> 0 | K12: =IF(J12>0,J12*3%,0) -> 0 | L12: 0 | M12: =O$2*F12% -> 0 | N12: 0 | O12: =ROUND(SUM(J12:N12),0) + R12 -> 0.07 | P12: =ROUND(O12*6% + O12,0) + R12 -> 0.07 | Q12: =ROUND(O12*3%,0) + O12 -> 0.07 | R12: =R11+0.01 -> 0.07
A13: 6º | B13: 1-D | C13: =C12+1 -> 8 | D13: MASIMO HUGO | F13: 1.13 | G13: 0 | H13: =G13 -> 0 | J13: =G13-H13 -> 0 | K13: =IF(J13>0,J13*3%,0) -> 0 | L13: 0 | M13: =O$2*F13% -> 0 | N13: 0 | O13: =ROUND(SUM(J13:N13),0) + R13 -> 0.08 | P13: =ROUND(O13*6% + O13,0) + R13 -> 0.08 | Q13: =ROUND(O13*3%,0) + O13 -> 0.08 | R13: =R12+0.01 -> 0.08
A14: 6º | B14: 1-E | C14: =C13+1 -> 9 | D14: BARONE GERARDO | F14: 1.13 | G14: 0 | H14: =G14 -> 0 | J14: =G14-H14 -> 0 | K14: =IF(J14>0,J14*3%,0) -> 0 | L14: 0 | M14: =O$2*F14% -> 0 | N14: 0 | O14: =ROUND(SUM(J14:N14),0) + R14 -> 0.09 | P14: =ROUND(O14*6% + O14,0) + R14 -> 0.09 | Q14: =ROUND(O14*3%,0) + O14 -> 0.09 | R14: =R13+0.01 -> 0.09
A15: 7º | B15: 2-A | C15: =C14+1 -> 10 | D15: MONGIELLO CARLOS (2) | F15: 1.67 | G15: 0 | H15: =G15 -> 0 | J15: =G15-H15 -> 0 | K15: =IF(J15>0,J15*3%,0) -> 0 | L15: 0 | M15: =O$2*F15% -> 0 | N15: 0 | O15: =ROUND(SUM(J15:N15),0) + R15 -> 0.1 | P15: =ROUND(O15*6% + O15,0) + R15 -> 0.1 | Q15: =ROUND(O15*3%,0) + O15 -> 0.1 | R15: =R14+0.01 -> 0.1
A16: 7º | B16: 2-B | C16: =C15+1 -> 11 | D16: COSTA MONICA | F16: 1.71 | G16: 0 | H16: =G16 -> 0 | J16: =G16-H16 -> 0 | K16: =IF(J16>0,J16*3%,0) -> 0 | L16: 0 | M16: =O$2*F16% -> 0 | N16: 0 | O16: =ROUND(SUM(J16:N16),0) + R16 -> 0.11 | P16: =ROUND(O16*6% + O16,0) + R16 -> 0.11 | Q16: =ROUND(O16*3%,0) + O16 -> 0.11 | R16: =R15+0.01 -> 0.11
A17: 8º | B17: 2-C | C17: =C16+1 -> 12 | D17: LOPEZ GUILLERMON | F17: 1.13 | G17: 0 | H17: =G17 -> 0 | J17: =G17-H17 -> 0 | K17: =IF(J17>0,J17*3%,0) -> 0 | L17: 0 | M17: =O$2*F17% -> 0 | N17: 0 | O17: =ROUND(SUM(J17:N17),0) + R17 -> 0.12 | P17: =ROUND(O17*6% + O17,0) + R17 -> 0.12 | Q17: =ROUND(O17*3%,0) + O17 -> 0.12 | R17: =R16+0.01 -> 0.12
A18: 8º | B18: 2-D | C18: =C17+1 -> 13 | D18: MARTINEZ ADELINA | F18: 1.13 | G18: 0 | H18: =G18 -> 0 | J18: =G18-H18 -> 0 | K18: =IF(J18>0,J18*3%,0) -> 0 | L18: 0 | M18: =O$2*F18% -> 0 | N18: 0 | O18: =ROUND(SUM(J18:N18),0) + R18 -> 0.13 | P18: =ROUND(O18*6% + O18,0) + R18 -> 0.13 | Q18: =ROUND(O18*3%,0) + O18 -> 0.13 | R18: =R17+0.01 -> 0.13
A19: 9º | B19: 2-E | C19: =C18+1 -> 14 | D19: QUIROGA ALBA | F19: 1.13 | J19: =G19-H19 -> 0 | K19: =IF(J19>0,J19*3%,0) -> 0 | L19: 0 | M19: =O$2*F19% -> 0 | N19: 0 | O19: =ROUND(SUM(J19:N19),0) + R19 -> 0.14 | P19: =ROUND(O19*6% + O19,0) + R19 -> 0.14 | Q19: =ROUND(O19*3%,0) + O19 -> 0.14 | R19: =R18+0.01 -> 0.14
A20: 9º | B20: 3-A | C20: =C19+1 -> 15 | D20: MADAR MARIANA | F20: 1.67 | G20: 0 | H20: =G20 -> 0 | J20: =G20-H20 -> 0 | K20: =IF(J20>0,J20*3%,0) -> 0 | L20: 0 | M20: =O$2*F20% -> 0 | N20: 0 | O20: =ROUND(SUM(J20:N20),0) + R20 -> 0.15 | P20: =ROUND(O20*6% + O20,0) + R20 -> 0.15 | Q20: =ROUND(O20*3%,0) + O20 -> 0.15 | R20: =R19+0.01 -> 0.15
A21: 10º | B21: 3-B | C21: =C20+1 -> 16 | D21: PIRES NABAIS | F21: 1.71 | G21: 0 | H21: =G21 -> 0 | J21: =G21-H21 -> 0 | K21: =IF(J21>0,J21*3%,0) -> 0 | L21: 0 | M21: =O$2*F21% -> 0 | N21: 0 | O21: =ROUND(SUM(J21:N21),0) + R21 -> 0.16 | P21: =ROUND(O21*6% + O21,0) + R21 -> 0.16 | Q21: =ROUND(O21*3%,0) + O21 -> 0.16 | R21: =R20+0.01 -> 0.16
A22: 10º | B22: 3-C | C22: =C21+1 -> 17 | D22: SANABRIA MARIO | F22: 1.13 | G22: 0 | H22: =G22 -> 0 | J22: =G22-H22 -> 0 | K22: =IF(J22>0,J22*3%,0) -> 0 | L22: 0 | M22: =O$2*F22% -> 0 | N22: 0 | O22: =ROUND(SUM(J22:N22),0) + R22 -> 0.17 | P22: =ROUND(O22*6% + O22,0) + R22 -> 0.17 | Q22: =ROUND(O22*3%,0) + O22 -> 0.17 | R22: =R21+0.01 -> 0.17
A23: 11º | B23: 3-D | C23: =C22+1 -> 18 | D23: PEROTTI | F23: 1.13 | G23: 0 | H23: =G23 -> 0 | J23: =G23-H23 -> 0 | K23: =IF(J23>0,J23*3%,0) -> 0 | L23: 0 | M23: =O$2*F23% -> 0 | N23: 0 | O23: =ROUND(SUM(J23:N23),0) + R23 -> 0.18 | P23: =ROUND(O23*6% + O23,0) + R23 -> 0.18 | Q23: =ROUND(O23*3%,0) + O23 -> 0.18 | R23: =R22+0.01 -> 0.18
A24: 11º | B24: 3-E | C24: =C23+1 -> 19 | D24: GOITEA ANTONIO | F24: 1.13 | G24: 0 | H24: =G24 -> 0 | J24: =G24-H24 -> 0 | K24: =IF(J24>0,J24*3%,0) -> 0 | L24: 0 | M24: =O$2*F24% -> 0 | N24: 0 | O24: =ROUND(SUM(J24:N24),0) + R24 -> 0.19 | P24: =ROUND(O24*6% + O24,0) + R24 -> 0.19 | Q24: =ROUND(O24*3%,0) + O24 -> 0.19 | R24: =R23+0.01 -> 0.19
A25: 12º | B25: 4-A | C25: =C24+1 -> 20 | D25: BIDABE LOMO | F25: 1.67 | G25: 0 | H25: =G25 -> 0 | J25: =G25-H25 -> 0 | K25: =IF(J25>0,J25*3%,0) -> 0 | L25: 0 | M25: =O$2*F25% -> 0 | N25: 0 | O25: =ROUND(SUM(J25:N25),0) + R25 -> 0.2 | P25: =ROUND(O25*6% + O25,0) + R25 -> 0.2 | Q25: =ROUND(O25*3%,0) + O25 -> 0.2 | R25: =R24+0.01 -> 0.2
A26: 13º | B26: 4-B | C26: =C25+1 -> 21 | D26: SICILIANO GRACIELA (2) | F26: 1.71 | G26: 0 | H26: =G26 -> 0 | J26: =G26-H26 -> 0 | K26: =IF(J26>0,J26*3%,0) -> 0 | L26: 0 | M26: =O$2*F26% -> 0 | N26: 0 | O26: =ROUND(SUM(J26:N26),0) + R26 -> 0.21 | P26: =ROUND(O26*6% + O26,0) + R26 -> 0.21 | Q26: =ROUND(O26*3%,0) + O26 -> 0.21 | R26: =R25+0.01 -> 0.21
A27: 14º | B27: 4-C | C27: =C26+1 -> 22 | D27: SANCHEZ NELIDA | F27: 1.13 | G27: 0 | H27: =G27 -> 0 | J27: =G27-H27 -> 0 | K27: =IF(J27>0,J27*3%,0) -> 0 | L27: 0 | M27: =O$2*F27% -> 0 | N27: 0 | O27: =ROUND(SUM(J27:N27),0) + R27 -> 0.22 | P27: =ROUND(O27*6% + O27,0) + R27 -> 0.22 | Q27: =ROUND(O27*3%,0) + O27 -> 0.22 | R27: =R26+0.01 -> 0.22
A28: 15º | B28: 4-D | C28: =C27+1 -> 23 | D28: TABOADA MARIA (2) | F28: 1.13 | G28: 0 | H28: =G28 -> 0 | J28: =G28-H28 -> 0 | K28: =IF(J28>0,J28*3%,0) -> 0 | L28: 0 | M28: =O$2*F28% -> 0 | N28: 0 | O28: =ROUND(SUM(J28:N28),0) + R28 -> 0.23 | P28: =ROUND(O28*6% + O28,0) + R28 -> 0.23 | Q28: =ROUND(O28*3%,0) + O28 -> 0.23 | R28: =R27+0.01 -> 0.23
A29: COC | B29: 4-E | C29: =C28+1 -> 24 | D29: BEDOYA BEATRIZ | F29: 1.13 | H29: =G29 -> 0 | J29: =G29-H29 -> 0 | K29: =IF(J29>0,J29*3%,0) -> 0 | L29: 0 | M29: =O$2*F29% -> 0 | N29: 0 | O29: =ROUND(SUM(J29:N29),0) + R29 -> 0.24 | P29: =ROUND(O29*6% + O29,0) + R29 -> 0.24 | Q29: =ROUND(O29*3%,0) + O29 -> 0.24 | R29: =R28+0.01 -> 0.24
A30: COC | B30: 5-A | C30: =C29+1 -> 25 | D30: RIZOLI VICTOR | F30: 1.67 | G30: 0 | H30: =G30 -> 0 | J30: =G30-H30 -> 0 | K30: =IF(J30>0,J30*3%,0) -> 0 | L30: 0 | M30: =O$2*F30% -> 0 | N30: 0 | O30: =ROUND(SUM(J30:N30),0) + R30 -> 0.25 | P30: =ROUND(O30*6% + O30,0) + R30 -> 0.25 | Q30: =ROUND(O30*3%,0) + O30 -> 0.25 | R30: =R29+0.01 -> 0.25
A31: COC | B31: 5-B | C31: =C30+1 -> 26 | D31: HOREN KRASNOBRODA | F31: 1.71 | G31: 0 | H31: =G31 -> 0 | J31: =G31-H31 -> 0 | K31: =IF(J31>0,J31*3%,0) -> 0 | L31: 0 | M31: =O$2*F31% -> 0 | N31: 0 | O31: =ROUND(SUM(J31:N31),0) + R31 -> 0.26 | P31: =ROUND(O31*6% + O31,0) + R31 -> 0.26 | Q31: =ROUND(O31*3%,0) + O31 -> 0.26 | R31: =R30+0.01 -> 0.26
A32: COC | B32: 5-C | C32: =C31+1 -> 27 | D32: MUÑOZ HERNAN | F32: 1.13 | G32: 0 | H32: =G32 -> 0 | J32: =G32-H32 -> 0 | K32: =IF(J32>0,J32*3%,0) -> 0 | L32: 0 | M32: =O$2*F32% -> 0 | N32: 0 | O32: =ROUND(SUM(J32:N32),0) + R32 -> 0.27 | P32: =ROUND(O32*6% + O32,0) + R32 -> 0.27 | Q32: =ROUND(O32*3%,0) + O32 -> 0.27 | R32: =R31+0.01 -> 0.27
A33: COC | B33: 5-D | C33: =C32+1 -> 28 | D33: VASTA NANCY | F33: 1.13 | G33: 0 | H33: =G33 -> 0 | J33: =G33-H33 -> 0 | K33: =IF(J33>0,J33*3%,0) -> 0 | L33: 0 | M33: =O$2*F33% -> 0 | N33: 42488 | O33: =ROUND(SUM(J33:N33),0) + R33 -> 42488.28 | P33: =ROUND(O33*6% + O33,0) + R33 -> 45038.28 | Q33: =ROUND(O33*3%,0) + O33 -> 43763.28 | R33: =R32+0.01 -> 0.28
A34: COC | B34: 5-E | C34: =C33+1 -> 29 | D34: TRAVERSA | F34: 1.13 | G34: 0 | H34: =G34 -> 0 | J34: =G34-H34 -> 0 | K34: =IF(J34>0,J34*3%,0) -> 0 | L34: 0 | M34: =O$2*F34% -> 0 | N34: 0 | O34: =ROUND(SUM(J34:N34),0) + R34 -> 0.29 | P34: =ROUND(O34*6% + O34,0) + R34 -> 0.29 | Q34: =ROUND(O34*3%,0) + O34 -> 0.29 | R34: =R33+0.01 -> 0.29
A35: COC | B35: 6-A | C35: =C34+1 -> 30 | D35: BAFFONI FABIAN | F35: 1.67 | G35: 0 | H35: =G35 -> 0 | J35: =G35-H35 -> 0 | K35: =IF(J35>0,J35*3%,0) -> 0 | L35: 0 | M35: =O$2*F35% -> 0 | N35: 0 | O35: =ROUND(SUM(J35:N35),0) + R35 -> 0.3 | P35: =ROUND(O35*6% + O35,0) + R35 -> 0.3 | Q35: =ROUND(O35*3%,0) + O35 -> 0.3 | R35: =R34+0.01 -> 0.3
A36: COC | G36: 0 | J36: =G36-H36 -> 0 | K36: =IF(J36>0,J36*3%,0) -> 0 | L36: 0 | M36: =O$2*F36% -> 0 | N36: 0 | O36: =ROUND(SUM(J36:N36),0) + R36 -> 0 | P36: =ROUND(O36*6% + O36,0) + R36 -> 0 | Q36: =ROUND(O36*3%,0) + O36 -> 0
A37: COC | B37: 6-B | C37: 31 | D37: PAQUET DE LOPEZ | F37: 1.71 | G37: 0 | H37: =G37 -> 0 | J37: =G37-H37 -> 0 | K37: =IF(J37>0,J37*3%,0) -> 0 | L37: 0 | M37: =O$2*F37% -> 0 | N37: 0 | O37: =ROUND(SUM(J37:N37),0) + R37 -> 0.31 | P37: =ROUND(O37*6% + O37,0) + R37 -> 0.31 | Q37: =ROUND(O37*3%,0) + O37 -> 0.31 | R37: 0.31
A38: COC | B38: 6-C | C38: =C37+1 -> 32 | D38: BLANCO MABEL | F38: 1.13 | G38: 0 | H38: =G38 -> 0 | J38: =G38-H38 -> 0 | K38: =IF(J38>0,J38*3%,0) -> 0 | L38: 0 | M38: =O$2*F38% -> 0 | N38: 0 | O38: =ROUND(SUM(J38:N38),0) + R38 -> 0.32 | P38: =ROUND(O38*6% + O38,0) + R38 -> 0.32 | Q38: =ROUND(O38*3%,0) + O38 -> 0.32 | R38: =R37+0.01 -> 0.32
A39: COC | B39: 6-D | C39: =C38+1 -> 33 | D39: TESTA IRENE | F39: 1.13 | G39: 0 | H39: =G39 -> 0 | J39: =G39-H39 -> 0 | K39: =IF(J39>0,J39*3%,0) -> 0 | L39: 0 | M39: =O$2*F39% -> 0 | N39: 0 | O39: =ROUND(SUM(J39:N39),0) + R39 -> 0.33 | P39: =ROUND(O39*6% + O39,0) + R39 -> 0.33 | Q39: =ROUND(O39*3%,0) + O39 -> 0.33 | R39: =R38+0.01 -> 0.33
A40: COC | B40: 6-E | C40: =C39+1 -> 34 | D40: QUIROGA ENRIQUE | F40: 1.13 | G40: 0 | H40: =G40 -> 0 | J40: =G40-H40 -> 0 | K40: =IF(J40>0,J40*3%,0) -> 0 | L40: 0 | M40: =O$2*F40% -> 0 | N40: 0 | O40: =ROUND(SUM(J40:N40),0) + R40 -> 0.34 | P40: =ROUND(O40*6% + O40,0) + R40 -> 0.34 | Q40: =ROUND(O40*3%,0) + O40 -> 0.34 | R40: =R39+0.01 -> 0.34
...

Sheet TOTAL EXPENSAS
A2: Dpto. | B2: UF | C2: Propietario | D2: Inquilinos | E2: (%) | F2: TOTAL EXPENSAS (ESTRAORDINARIAS + ORDINARIAS)
A4: PB B | B4: 1 | C4: TULA CARLOS (2) | E4: 1.65 | F4: =PRORRATEO!M7+'PRORRATEO (2)'!O6 -> 204000.02
A5: PB C | B5: =B4+1 -> 2 | C5: COMBRE ALFREDO | E5: 1.16 | F5: =PRORRATEO!M8+'PRORRATEO (2)'!O7 -> 153000.04
A6: PB D | B6: =B5+1 -> 3 | C6: PRGICH FEDERICO | E6: 1.19 | F6: =PRORRATEO!M9+'PRORRATEO (2)'!O8 -> 168000.06
A7: PB E | B7: =B6+1 -> 4 | C7: SRUGO DAMIAN | E7: 1.22 | F7: =PRORRATEO!M10+'PRORRATEO (2)'!O9 -> 71176.08
A8: 1-A | B8: =B7+1 -> 5 | C8: ZELANSNY SILVIA | E8: 1.67 | F8: =PRORRATEO!M11+'PRORRATEO (2)'!O10 -> 164500.1
A9: 1-B | B9: =B8+1 -> 6 | C9: PICO HEBE | E9: 1.71 | F9: =PRORRATEO!M12+'PRORRATEO (2)'!O11 -> 84000.12
A10: 1-C | B10: =B9+1 -> 7 | C10: RAMOS ROSA | E10: 1.13 | F10: =PRORRATEO!M13+'PRORRATEO (2)'!O12 -> 882232.14
A11: 1-D | B11: =B10+1 -> 8 | C11: MASIMO HUGO | E11: 1.13 | F11: =PRORRATEO!M14+'PRORRATEO (2)'!O13 -> 961820.16
A12: 1-E | B12: =B11+1 -> 9 | C12: BARONE GERARDO | E12: 1.13 | F12: =PRORRATEO!M15+'PRORRATEO (2)'!O14 -> 872907.18
A13: 2-A | B13: =B12+1 -> 10 | C13: MONGIELLO CARLOS (2) | E13: 1.67 | F13: =PRORRATEO!M16+'PRORRATEO (2)'!O15 -> 84000.2
A14: 2-B | B14: =B13+1 -> 11 | C14: COSTA MONICA | E14: 1.71 | F14: =PRORRATEO!M17+'PRORRATEO (2)'!O16 -> 84000.22
A15: 2-C | B15: =B14+1 -> 12 | C15: LOPEZ GUILLERMON | E15: 1.13 | F15: =PRORRATEO!M18+'PRORRATEO (2)'!O17 -> 84000.24
A16: 2-D | B16: =B15+1 -> 13 | C16: MARTINEZ ADELINA | E16: 1.13 | F16: =PRORRATEO!M19+'PRORRATEO (2)'!O18 -> 769000.26
... A30: 5-C | B30: =B29+1 -> 27 | C30: MUÑOZ HERNAN | E30: 1.13 | F30: =PRORRATEO!M33+'PRORRATEO (2)'!O32 -> 0.27
A31: 5-D | B31: =B30+1 -> 28 | C31: VASTA NANCY | E31: 1.13 | F31: =PRORRATEO!#REF!+'PRORRATEO (2)'!O33 -> #REF!
A32: 5-E | B32: =B31+1 -> 29 | C32: TRAVERSA | E32: 1.13 | F32: =PRORRATEO!#REF!+'PRORRATEO (2)'!O34 -> #REF!
A33: 6-A | B33: =B32+1 -> 30 | C33: BAFFONI FABIAN | E33: 1.67 | F33: =PRORRATEO!#REF!+'PRORRATEO (2)'!O35 -> #REF!
F34: =PRORRATEO!#REF!+'PRORRATEO (2)'!O36 -> #REF!
A35: 6-B | B35: 31 | C35: PAQUET DE LOPEZ | E35: 1.71 | F35: =PRORRATEO!#REF!+'PRORRATEO (2)'!O37 -> #REF!
A36: 6-C | B36: =B35+1 -> 32 | C36: BLANCO MABEL | E36: 1.13 | F36: =PRORRATEO!#REF!+'PRORRATEO (2)'!O38 -> #REF!
A37: 6-D | B37: =B36+1 -> 33 | C37: TESTA IRENE | E37: 1.13 | F37: =PRORRATEO!#REF!+'PRORRATEO (2)'!O39 -> #REF!
A38: 6-E | B38: =B37+1 -> 34 | C38: QUIROGA ENRIQUE | E38: 1.13 | F38: =PRORRATEO!#REF!+'PRORRATEO (2)'!O40 -> #REF!
A39: 7-A | B39: =B38+1 -> 35 | C39: ALVAREZ VERONICA (2) | E39: 1.67 | F39: =PRORRATEO!#REF!+'PRORRATEO (2)'!O41 -> #REF!
A40: 7-B | B40: =B39+1 -> 36 | C40: ROJAS CARMEN | E40: 1.71 | F40: =PRORRATEO!#REF!+'PRORRATEO (2)'!O42 -> #REF!
A41: 7-C | B41: =B40+1 -> 37 | C41: JUCHNO IRENE | E41: 1.13 | F41: =PRORRATEO!#REF!+'PRORRATEO (2)'!O43 -> #REF!
A42: 7-D | B42: =B41+1 -> 38 | C42: URIZAR LUQUES | E42: 1.13 | F42: =PRORRATEO!#REF!+'PRORRATEO (2)'!O44 -> #REF!
A43: 7-E | B43: =B42+1 -> 39 | C43: RIPA NELLY | E43: 1.13 | F43: =PRORRATEO!#REF!+'PRORRATEO (2)'!O45 -> #REF!
A44: 8-A | B44: =B43+1 -> 40 | C44: SORIA GODOY | E44: 1.67 | F44: =PRORRATEO!#REF!+'PRORRATEO (2)'!O46 -> #REF!
A45: 8-B | B45: =B44+1 -> 41 | C45: D´ALOIA GABRIELA (2) | E45: 1.71 | F45: =PRORRATEO!#REF!+'PRORRATEO (2)'!O47 -> #REF!
A46: 8-C | B46: =B45+1 -> 42 | C46: MIÑO GRACIELA (2) | E46: 1.13 | F46: =PRORRATEO!#REF!+'PRORRATEO (2)'!O48 -> #REF!
A47: 8-D | B47: =B46+1 -> 43 | C47: CATALANO CLAUDIA | E47: 1.13 | F47: =PRORRATEO!#REF!+'PRORRATEO (2)'!O49 -> #REF!
... A78: 14-E | B78: =B77+1 -> 74 | C78: EMA ALVAREZ | E78: 1.13 | F78: =PRORRATEO!#REF!+'PRORRATEO (2)'!O80 -> #REF!
E79: =SUM(E4:E78) -> 100

Sheet Recibos 1
B3: RECIBO DE EXPENSAS
B4: CONSORCIO DE PROPIETARIOS DEL EDIFICIO CALLE LORIA 185
B5: CUIT DEL EDIFICIO: 30-57461192-8 | G5: =RESUMEN!B4 -> ADMINISTRADORA: CAROLINA CANCIANI MP:1148
B6: Adminstradora: Carolina Canciani
B8: Metodo de pago: Transferencia
B10: Nombre y apellido: | E10: =PRORRATEO!C7 -> ZAFFINO, Fernando | I10: Sello o firma autoriada:
B11: UF: | C11: =PRORRATEO!B7 -> 1 | D11: Dpto: | E11: =PRORRATEO!#REF! -> #REF!
B16: Total recibido: | G16: =PRORRATEO!M7 -> 204000.01
B20: RECIBO DE EXPENSAS
B21: CONSORCIO DE PROPIETARIOS DEL EDIFICIO CALLE LORIA 185
B22: CUIT DEL EDIFICIO: 30-57461192-8 | G22: PERÍODO: ABRIL
B23: Adminstradora: Carolina Canciani
B25: Metodo de pago: Transferencia
B27: Nombre y apellido: | E27: =PRORRATEO!C8 -> BERESTEIN, Javier | I27: Sello o firma autoriada:
B28: UF: | C28: =PRORRATEO!B8 -> 2 | D28: Dpto: | E28: =PRORRATEO!#REF! -> #REF!
B33: Total recibido: | G33: =PRORRATEO!M8 -> 153000.02
B38: RECIBO DE EXPENSAS
B39: CONSORCIO DE PROPIETARIOS DEL EDIFICIO CALLE LORIA 185
B40: CUIT DEL EDIFICIO: 30-57461192-8 | G40: PERÍODO: ABRIL
B41: Adminstradora: Carolina Canciani
B43: Metodo de pago: Transferencia
B45: Nombre y apellido: | E45: =PRORRATEO!C9 -> VAZQUEZ PALLARES, Juan | I45: Sello o firma autoriada:
B46: UF: | C46: =PRORRATEO!B9 -> 3 | D46: Dpto: | E46: =PRORRATEO!#REF! -> #REF!
B51: Total recibido: | G51: =PRORRATEO!M9 -> 168000.03
B55: RECIBO DE EXPENSAS
B56: CONSORCIO DE PROPIETARIOS DEL EDIFICIO CALLE LORIA 185
B57: CUIT DEL EDIFICIO: 30-57461192-8 | G57: PERÍODO: ABRIL
B58: Adminstradora: Carolina Canciani
B60: Metodo de pago: Transferencia
B62: Nombre y apellido: | E62: =PRORRATEO!C10 -> HUINCA HUEMUL S.A. | I62: Sello o firma autoriada:
B63: UF: | C63: =PRORRATEO!B10 -> 4 | D63: Dpto: | E63: =PRORRATEO!#REF! -> #REF!
B68: Total recibido: | G68: =PRORRATEO!M10 -> 71176.04
B73: RECIBO DE EXPENSAS
B74: CONSORCIO DE PROPIETARIOS DEL EDIFICIO CALLE LORIA 185
B75: CUIT DEL EDIFICIO: 30-57461192-8 | G75: PERÍODO: ABRIL
B76: Adminstradora: Carolina Canciani
B78: Metodo de pago: Transferencia
B80: Nombre y apellido: | E80: =PRORRATEO!C11 -> LAZARTE, Irma | I80: Sello o firma autoriada:
B81: UF: | C81: =PRORRATEO!B11 -> 5 | D81: Dpto: | E81: =PRORRATEO!#REF! -> #REF!
B86: Total recibido: | G86: =PRORRATEO!M11 -> 164500.05
...

Sheet Recibos 2
B3: RECIBO DE EXPENSAS
B4: CONSORCIO DE PROPIETARIOS DEL EDIFICIO CALLE LORIA 185
B5: CUIT DEL EDIFICIO: 14-57461192-8 | G5: PERÍODO: ABRIL
B6: Adminstradora: Carolina Canciani
B8: Metodo de pago: Transferencia
B10: Nombre y apellido: | E10: =PRORRATEO!C13 -> QUIROGA, Karina | I10: Sello o firma autoriada:
B11: UF: | C11: =PRORRATEO!B13 -> 7 | D11: Dpto: | E11: =PRORRATEO!#REF! -> #REF!
B16: Total recibido: | G16: =PRORRATEO!M13 -> 882232.07
B20: RECIBO DE EXPENSAS
B21: CONSORCIO DE PROPIETARIOS DEL EDIFICIO CALLE LORIA 185
B22: CUIT DEL EDIFICIO: 14-57461192-8 | G22: PERÍODO: ABRIL
B23: Adminstradora: Carolina Canciani
B25: Metodo de pago: Transferencia
B27: Nombre y apellido: | E27: =PRORRATEO!C14 -> PENAS, Roberto | I27: Sello o firma autoriada:
B28: UF: | C28: =PRORRATEO!B14 -> 8 | D28: Dpto: | E28: =PRORRATEO!#REF! -> #REF!
B33: Total recibido: | G33: =PRORRATEO!M14 -> 961820.08
B37: RECIBO DE EXPENSAS
B38: CONSORCIO DE PROPIETARIOS DEL EDIFICIO CALLE LORIA 185
B39: CUIT DEL EDIFICIO: 14-57461192-8 | G39: PERÍODO: ABRIL
B40: Adminstradora: Carolina Canciani
B42: Metodo de pago: Transferencia
B44: Nombre y apellido: | E44: =PRORRATEO!C15 -> MURPHY, Gabriel | I44: Sello o firma autoriada:
B45: UF: | C45: =PRORRATEO!B15 -> 9 | D45: Dpto: | E45: =PRORRATEO!#REF! -> #REF!
B50: Total recibido: | G50: =PRORRATEO!M15 -> 872907.09
B54: RECIBO DE EXPENSAS
B55: CONSORCIO DE PROPIETARIOS DEL EDIFICIO CALLE LORIA 185
B56: CUIT DEL EDIFICIO: 14-57461192-8 | G56: PERÍODO: ABRIL
B57: Adminstradora: Carolina Canciani
B59: Metodo de pago: Transferencia
B61: Nombre y apellido: | E61: =PRORRATEO!C16 -> JAURETCHE, Claudio | I61: Sello o firma autoriada:
B62: UF: | C62: =PRORRATEO!B16 -> 10 | D62: Dpto: | E62: =PRORRATEO!#REF! -> #REF!
B67: Total recibido: | G67: =PRORRATEO!M16 -> 84000.1
B72: RECIBO DE EXPENSAS
B73: CONSORCIO DE PROPIETARIOS DEL EDIFICIO CALLE LORIA 185
B74: CUIT DEL EDIFICIO: 14-57461192-8 | G74: PERÍODO: ABRIL
B75: Adminstradora: Carolina Canciani
B77: Metodo de pago: Transferencia
B79: Nombre y apellido: | E79: =PRORRATEO!C17 -> BRUZZONE, Héctor | I79: Sello o firma autoriada:
B80: UF: | C80: =PRORRATEO!B17 -> 11 | D80: Dpto: | E80: =PRORRATEO!#REF! -> #REF!
B85: Total recibido: | G85: =PRORRATEO!M17 -> 84000.11
...

Sheet Recibos 3
B3: RECIBO DE EXPENSAS
B4: CONSORCIO DE PROPIETARIOS DEL EDIFICIO CALLE LORIA 185
B5: CUIT DEL EDIFICIO: 14-57461192-8 | G5: PERÍODO: ABRIL
B6: Adminstradora: Carolina Canciani
B8: Metodo de pago: Transferencia
B10: Nombre y apellido: | E10: =PRORRATEO!C19 -> CALVI, José | I10: Sello o firma autoriada:
B11: UF: | C11: =PRORRATEO!B19 -> 13 | D11: Dpto: | E11: =PRORRATEO!#REF! -> #REF!
B16: Total recibido: | G16: =PRORRATEO!M19 -> 769000.13
B21: RECIBO DE EXPENSAS
B22: CONSORCIO DE PROPIETARIOS DEL EDIFICIO CALLE LORIA 185
B23: CUIT DEL EDIFICIO: 14-57461192-8 | G23: PERÍODO: ABRIL
B24: Adminstradora: Carolina Canciani
B26: Metodo de pago: Transferencia
B28: Nombre y apellido: | E28: =PRORRATEO!C20 -> PENAS, Roberto | I28: Sello o firma autoriada:
B29: UF: | C29: =PRORRATEO!B20 -> 14 | D29: Dpto: | E29: =PRORRATEO!#REF! -> #REF!
B34: Total recibido: | G34: =PRORRATEO!M20 -> 649883.14
B39: RECIBO DE EXPENSAS
B40: CONSORCIO DE PROPIETARIOS DEL EDIFICIO CALLE LORIA 185
B41: CUIT DEL EDIFICIO: 14-57461192-8 | G41: PERÍODO: ABRIL
B42: Adminstradora: Carolina Canciani
B44: Metodo de pago: Transferencia
B46: Nombre y apellido: | E46: =PRORRATEO!C21 -> KOCKA, José | I46: Sello o firma autoriada:
B47: UF: | C47: =PRORRATEO!B21 -> 15 | D47: Dpto: | E47: =PRORRATEO!#REF! -> #REF!
B52: Total recibido: | G52: =PRORRATEO!M21 -> 84000.15
B57: RECIBO DE EXPENSAS
B58: CONSORCIO DE PROPIETARIOS DEL EDIFICIO CALLE LORIA 185
B59: CUIT DEL EDIFICIO: 14-57461192-8 | G59: PERÍODO: ABRIL
B60: Adminstradora: Carolina Canciani
B62: Metodo de pago: Transferencia
B64: Nombre y apellido: | E64: =PRORRATEO!C22 -> LASSALLE, Cristina | I64: Sello o firma autoriada:
B65: UF: | C65: =PRORRATEO!B22 -> 16 | D65: Dpto: | E65: =PRORRATEO!#REF! -> #REF!
B70: Total recibido: | G70: =PRORRATEO!M22 -> 76110.16
B75: RECIBO DE EXPENSAS
B76: CONSORCIO DE PROPIETARIOS DEL EDIFICIO CALLE LORIA 185
B77: CUIT DEL EDIFICIO: 14-57461192-8 | G77: PERÍODO: ABRIL
B78: Adminstradora: Carolina Canciani
B80: Metodo de pago: Transferencia
B82: Nombre y apellido: | E82: =PRORRATEO!C23 -> LUCERO, Olga | I82: Sello o firma autoriada:
B83: UF: | C83: =PRORRATEO!B23 -> 17 | D83: Dpto: | E83: =PRORRATEO!#REF! -> #REF!
B88: Total recibido: | G88: =PRORRATEO!M23 -> 686683.17
...

Sheet Recibos 4
B3: RECIBO DE EXPENSAS
B4: CONSORCIO DE PROPIETARIOS DEL EDIFICIO CALLE LORIA 185
B5: CUIT DEL EDIFICIO: 14-57461192-8 | G5: PERÍODO: ABRIL
B6: Adminstradora: Carolina Canciani
B8: Metodo de pago: Transferencia
B10: Nombre y apellido: | E10: =PRORRATEO!C25 -> VERA, Ricardo | I10: Sello o firma autoriada:
B11: UF: | C11: =PRORRATEO!B25 -> 19 | D11: Dpto: | E11: =PRORRATEO!#REF! -> #REF!
B16: Total recibido: | G16: =PRORRATEO!M25 -> 463002.19
B21: RECIBO DE EXPENSAS
B22: CONSORCIO DE PROPIETARIOS DEL EDIFICIO CALLE LORIA 185
B23: CUIT DEL EDIFICIO: 14-57461192-8 | G23: PERÍODO: ABRIL
B24: Adminstradora: Carolina Canciani
B26: Metodo de pago: Transferencia
B28: Nombre y apellido: | E28: =PRORRATEO!C26 -> HUINCA HUEMUL S.A. | I28: Sello o firma autoriada:
B29: UF: | C29: =PRORRATEO!B26 -> 20 | D29: Dpto: | E29: =PRORRATEO!#REF! -> #REF!
B34: Total recibido: | G34: =PRORRATEO!M26 -> 81900.2
B38: RECIBO DE EXPENSAS
B39: CONSORCIO DE PROPIETARIOS DEL EDIFICIO CALLE LORIA 185
B40: CUIT DEL EDIFICIO: 14-57461192-8 | G40: PERÍODO: ABRIL
B41: Adminstradora: Carolina Canciani
B43: Metodo de pago: Transferencia
B45: Nombre y apellido: | E45: =PRORRATEO!C27 -> QUIROGA, Karina | I45: Sello o firma autoriada:
B46: UF: | C46: =PRORRATEO!B27 -> 21 | D46: Dpto: | E46: =PRORRATEO!#REF! -> #REF!
B51: Total recibido: | G51: =PRORRATEO!M27 -> 661674.21
B57: RECIBO DE EXPENSAS
B58: CONSORCIO DE PROPIETARIOS DEL EDIFICIO CALLE LORIA 185
B59: CUIT DEL EDIFICIO: 14-57461192-8 | G59: PERÍODO: ABRIL
B60: Adminstradora: Carolina Canciani
B62: Metodo de pago: Transferencia
B64: Nombre y apellido: | E64: =PRORRATEO!C28 -> QUIROGA, Karina | I64: Sello o firma autoriada:
B65: UF: | C65: =PRORRATEO!B28 -> 22 | D65: Dpto: | E65: =PRORRATEO!#REF! -> #REF!
B70: Total recibido: | G70: =PRORRATEO!M28 -> 904288.22
B74: RECIBO DE EXPENSAS
B75: CONSORCIO DE PROPIETARIOS DEL EDIFICIO CALLE LORIA 185
B76: CUIT DEL EDIFICIO: 14-57461192-8 | G76: PERÍODO: ABRIL
B77: Adminstradora: Carolina Canciani
B79: Metodo de pago: Transferencia
B81: Nombre y apellido: | E81: =PRORRATEO!C29 -> SALAZAR, Javier | I81: Sello o firma autoriada:
B82: UF: | C82: =PRORRATEO!B29 -> 23 | D82: Dpto: | E82: =PRORRATEO!#REF! -> #REF!
B87: Total recibido: | G87: =PRORRATEO!M29 -> 153092.23
...

Sheet Recibos 5
B4: RECIBO DE EXPENSAS
B5: CONSORCIO DE PROPIETARIOS DEL EDIFICIO CALLE LORIA 185
B6: CUIT DEL EDIFICIO: 14-57461192-8 | G6: PERÍODO: ABRIL
B7: Adminstradora: Carolina Canciani
B9: Metodo de pago: Transferencia
B11: Nombre y apellido: | E11: =PRORRATEO!C31 -> QUINTANA, Hector | I11: Sello o firma autoriada:
B12: UF: | C12: =PRORRATEO!B31 -> 25 | D12: Dpto: | E12: =PRORRATEO!#REF! -> #REF!
B17: Total recibido: | G17: =PRORRATEO!M31 -> 165000.25
B22: RECIBO DE EXPENSAS
B23: CONSORCIO DE PROPIETARIOS DEL EDIFICIO CALLE LORIA 185
B24: CUIT DEL EDIFICIO: 14-57461192-8 | G24: PERÍODO: ABRIL
B25: Adminstradora: Carolina Canciani
B27: Metodo de pago: Transferencia
B29: Nombre y apellido: | E29: =PRORRATEO!C32 -> MURPHY, Gabriel | I29: Sello o firma autoriada:
B30: UF: | C30: =PRORRATEO!B32 -> 26 | D30: Dpto: | E30: =PRORRATEO!#REF! -> #REF!
B35: Total recibido: | G35: =PRORRATEO!M32 -> 1529444.3
B40: RECIBO DE EXPENSAS
B41: CONSORCIO DE PROPIETARIOS DEL EDIFICIO CALLE LORIA 185
B42: CUIT DEL EDIFICIO: 14-57461192-8 | G42: PERÍODO: ABRIL
B43: Adminstradora: Carolina Canciani
B45: Metodo de pago: Transferencia
B47: Nombre y apellido: | E47: =PRORRATEO!C33 -> 0 | I47: Sello o firma autoriada:
B48: UF: | C48: =PRORRATEO!B33 -> 0 | D48: Dpto: | E48: =PRORRATEO!#REF! -> #REF!
B53: Total recibido: | G53: =PRORRATEO!M33 -> 0
B57: RECIBO DE EXPENSAS
B58: CONSORCIO DE PROPIETARIOS DEL EDIFICIO CALLE LORIA 185
B59: CUIT DEL EDIFICIO: 14-57461192-8 | G59: PERÍODO: ABRIL
B60: Adminstradora: Carolina Canciani
B62: Metodo de pago: Transferencia
B64: Nombre y apellido: | E64: =PRORRATEO!#REF! -> #REF! | I64: Sello o firma autoriada:
B65: UF: | C65: =PRORRATEO!#REF! -> #REF! | D65: Dpto: | E65: =PRORRATEO!#REF! -> #REF!
B70: Total recibido: | G70: =PRORRATEO!#REF! -> #REF!
B74: RECIBO DE EXPENSAS
B75: CONSORCIO DE PROPIETARIOS DEL EDIFICIO CALLE LORIA 185
B76: CUIT DEL EDIFICIO: 14-57461192-8 | G76: PERÍODO: ABRIL
B77: Adminstradora: Carolina Canciani
B79: Metodo de pago: Transferencia
B81: Nombre y apellido: | E81: =PRORRATEO!#REF! -> #REF! | I81: Sello o firma autoriada:
B82: UF: | C82: =PRORRATEO!#REF! -> #REF! | D82: Dpto: | E82: =PRORRATEO!#REF! -> #REF!
B87: Total recibido: | G87: =PRORRATEO!#REF! -> #REF!
...

Sheet Recibos 6 
B2: RECIBO DE EXPENSAS
B3: CONSORCIO DE PROPIETARIOS DEL EDIFICIO CALLE LORIA 185
B4: CUIT DEL EDIFICIO: 14-57461192-8 | G4: PERÍODO: ABRIL
B5: Adminstradora: Carolina Canciani
B7: Metodo de pago: Transferencia
B9: Nombre y apellido: | E9: =PRORRATEO!#REF! -> #REF! | I9: Sello o firma autoriada:
B10: UF: | C10: =PRORRATEO!#REF! -> #REF! | D10: Dpto: | E10: =PRORRATEO!#REF! -> #REF!
B15: Total recibido: | G15: =PRORRATEO!#REF! -> #REF!
B18: RECIBO DE EXPENSAS
B19: CONSORCIO DE PROPIETARIOS DEL EDIFICIO CALLE LORIA 185
B20: CUIT DEL EDIFICIO: 14-57461192-8 | G20: PERÍODO: ABRIL
B21: Adminstradora: Carolina Canciani
B23: Metodo de pago: Transferencia
B25: Nombre y apellido: | E25: =PRORRATEO!#REF! -> #REF! | I25: Sello o firma autoriada:
B26: UF: | C26: =PRORRATEO!#REF! -> #REF! | D26: Dpto: | E26: =PRORRATEO!#REF! -> #REF!
B31: Total recibido: | G31: =PRORRATEO!#REF! -> #REF!
B36: RECIBO DE EXPENSAS
B37: CONSORCIO DE PROPIETARIOS DEL EDIFICIO CALLE LORIA 185
B38: CUIT DEL EDIFICIO: 14-57461192-8 | G38: PERÍODO: ABRIL
B39: Adminstradora: Carolina Canciani
B41: Metodo de pago: Transferencia
B43: Nombre y apellido: | E43: =PRORRATEO!#REF! -> #REF! | I43: Sello o firma autoriada:
B44: UF: | C44: =PRORRATEO!#REF! -> #REF! | D44: Dpto: | E44: =PRORRATEO!#REF! -> #REF!
B49: Total recibido: | G49: =PRORRATEO!#REF! -> #REF!
B53: RECIBO DE EXPENSAS
B54: CONSORCIO DE PROPIETARIOS DEL EDIFICIO CALLE LORIA 185
B55: CUIT DEL EDIFICIO: 14-57461192-8 | G55: PERÍODO: ABRIL
B56: Adminstradora: Carolina Canciani
B58: Metodo de pago: Transferencia
B60: Nombre y apellido: | E60: =PRORRATEO!#REF! -> #REF! | I60: Sello o firma autoriada:
B61: UF: | C61: =PRORRATEO!#REF! -> #REF! | D61: Dpto: | E61: =PRORRATEO!#REF! -> #REF!
B66: Total recibido: | G66: =PRORRATEO!#REF! -> #REF!
B71: RECIBO DE EXPENSAS
B72: CONSORCIO DE PROPIETARIOS DEL EDIFICIO CALLE LORIA 185
B73: CUIT DEL EDIFICIO: 14-57461192-8 | G73: PERÍODO: ABRIL
B74: Adminstradora: Carolina Canciani
B76: Metodo de pago: Transferencia
B78: Nombre y apellido: | E78: =PRORRATEO!#REF! -> #REF! | I78: Sello o firma autoriada:
B79: UF: | C79: =PRORRATEO!#REF! -> #REF! | D79: Dpto: | E79: =PRORRATEO!#REF! -> #REF!
B84: Total recibido: | G84: =PRORRATEO!#REF! -> #REF!
...

Sheet Recibos 7
B4: RECIBO DE EXPENSAS
B5: CONSORCIO DE PROPIETARIOS DEL EDIFICIO CALLE LORIA 185
B6: CUIT DEL EDIFICIO: 14-57461192-8 | G6: PERÍODO: ABRIL
B7: Adminstradora: Carolina Canciani
B9: Metodo de pago: Transferencia
B11: Nombre y apellido: | E11: =PRORRATEO!#REF! -> #REF! | I11: Sello o firma autoriada:
B12: UF: | C12: =PRORRATEO!#REF! -> #REF! | D12: Dpto: | E12: =PRORRATEO!#REF! -> #REF!
B17: Total recibido: | G17: =PRORRATEO!#REF! -> #REF!
B20: RECIBO DE EXPENSAS
B21: CONSORCIO DE PROPIETARIOS DEL EDIFICIO CALLE LORIA 185
B22: CUIT DEL EDIFICIO: 14-57461192-8 | G22: PERÍODO: ABRIL
B23: Adminstradora: Carolina Canciani
B25: Metodo de pago: Transferencia
B27: Nombre y apellido: | E27: =PRORRATEO!#REF! -> #REF! | I27: Sello o firma autoriada:
B28: UF: | C28: =PRORRATEO!#REF! -> #REF! | D28: Dpto: | E28: =PRORRATEO!#REF! -> #REF!
B33: Total recibido: | G33: =PRORRATEO!#REF! -> #REF!
B37: RECIBO DE EXPENSAS
B38: CONSORCIO DE PROPIETARIOS DEL EDIFICIO CALLE LORIA 185
B39: CUIT DEL EDIFICIO: 14-57461192-8 | G39: PERÍODO: ABRIL
B40: Adminstradora: Carolina Canciani
B42: Metodo de pago: Transferencia
B44: Nombre y apellido: | E44: =PRORRATEO!#REF! -> #REF! | I44: Sello o firma autoriada:
B45: UF: | C45: =PRORRATEO!#REF! -> #REF! | D45: Dpto: | E45: =PRORRATEO!#REF! -> #REF!
B50: Total recibido: | G50: =PRORRATEO!#REF! -> #REF!
B54: RECIBO DE EXPENSAS
B55: CONSORCIO DE PROPIETARIOS DEL EDIFICIO CALLE LORIA 185
B56: CUIT DEL EDIFICIO: 14-57461192-8 | G56: PERÍODO: ABRIL
B57: Adminstradora: Carolina Canciani
B59: Metodo de pago: Transferencia
B61: Nombre y apellido: | E61: =PRORRATEO!#REF! -> #REF! | I61: Sello o firma autoriada:
B62: UF: | C62: =PRORRATEO!#REF! -> #REF! | D62: Dpto: | E62: =PRORRATEO!#REF! -> #REF!
B67: Total recibido: | G67: =PRORRATEO!#REF! -> #REF!
B71: RECIBO DE EXPENSAS
B72: CONSORCIO DE PROPIETARIOS DEL EDIFICIO CALLE LORIA 185
B73: CUIT DEL EDIFICIO: 14-57461192-8 | G73: PERÍODO: ABRIL
B74: Adminstradora: Carolina Canciani
B76: Metodo de pago: Transferencia
B78: Nombre y apellido: | E78: =PRORRATEO!#REF! -> #REF! | I78: Sello o firma autoriada:
B79: UF: | C79: =PRORRATEO!#REF! -> #REF! | D79: Dpto: | E79: =PRORRATEO!#REF! -> #REF!
B84: Total recibido: | G84: =PRORRATEO!#REF! -> #REF!
...

Sheet Recibos 8
B3: RECIBO DE EXPENSAS
B4: CONSORCIO DE PROPIETARIOS DEL EDIFICIO CALLE LORIA 185
B5: CUIT DEL EDIFICIO: 14-57466192-8 | G5: PERÍODO: ABRIL
B6: Adminstradora: Carolina Canciani
B8: Metodo de pago: Transferencia
B10: Nombre y apellido: | E10: =PRORRATEO!#REF! -> #REF! | I10: Sello o firma autoriada:
B11: UF: | C11: =PRORRATEO!#REF! -> #REF! | D11: Dpto: | E11: =PRORRATEO!#REF! -> #REF!
B16: Total recibido: | G16: =PRORRATEO!#REF! -> #REF!
B20: RECIBO DE EXPENSAS
B21: CONSORCIO DE PROPIETARIOS DEL EDIFICIO CALLE LORIA 185
B22: CUIT DEL EDIFICIO: 14-57466192-8 | G22: PERÍODO: ABRIL
B23: Adminstradora: Carolina Canciani
B25: Metodo de pago: Transferencia
B27: Nombre y apellido: | E27: =PRORRATEO!#REF! -> #REF! | I27: Sello o firma autoriada:
B28: UF: | C28: =PRORRATEO!#REF! -> #REF! | D28: Dpto: | E28: =PRORRATEO!#REF! -> #REF!
B33: Total recibido: | G33: =PRORRATEO!#REF! -> #REF!
B38: RECIBO DE EXPENSAS
B39: CONSORCIO DE PROPIETARIOS DEL EDIFICIO CALLE LORIA 185
B40: CUIT DEL EDIFICIO: 14-57466192-8 | G40: PERÍODO: ABRIL
B41: Adminstradora: Carolina Canciani
B43: Metodo de pago: Transferencia
B45: Nombre y apellido: | E45: =PRORRATEO!#REF! -> #REF! | I45: Sello o firma autoriada:
B46: UF: | C46: =PRORRATEO!#REF! -> #REF! | D46: Dpto: | E46: =PRORRATEO!#REF! -> #REF!
B51: Total recibido: | G51: =PRORRATEO!#REF! -> #REF!
B56: RECIBO DE EXPENSAS
B57: CONSORCIO DE PROPIETARIOS DEL EDIFICIO CALLE LORIA 185
B58: CUIT DEL EDIFICIO: 14-57466192-8 | G58: PERÍODO: ABRIL
B59: Adminstradora: Carolina Canciani
B61: Metodo de pago: Transferencia
B63: Nombre y apellido: | E63: =PRORRATEO!#REF! -> #REF! | I63: Sello o firma autoriada:
B64: UF: | C64: =PRORRATEO!#REF! -> #REF! | D64: Dpto: | E64: =PRORRATEO!#REF! -> #REF!
B69: Total recibido: | G69: =PRORRATEO!#REF! -> #REF!
B73: RECIBO DE EXPENSAS
B74: CONSORCIO DE PROPIETARIOS DEL EDIFICIO CALLE LORIA 185
B75: CUIT DEL EDIFICIO: 14-57466192-8 | G75: PERÍODO: ABRIL
B76: Adminstradora: Carolina Canciani
B78: Metodo de pago: Transferencia
B80: Nombre y apellido: | E80: =PRORRATEO!#REF! -> #REF! | I80: Sello o firma autoriada:
B81: UF: | C81: =PRORRATEO!#REF! -> #REF! | D81: Dpto: | E81: =PRORRATEO!#REF! -> #REF!
B86: Total recibido: | G86: =PRORRATEO!#REF! -> #REF!
...

Sheet Recibos 9
B3: RECIBO DE EXPENSAS
B4: CONSORCIO DE PROPIETARIOS DEL EDIFICIO CALLE LORIA 185
B5: CUIT DEL EDIFICIO: 14-57466192-8 | G5: PERÍODO: ABRIL
B6: Adminstradora: Carolina Canciani
B8: Metodo de pago: Transferencia
B10: Nombre y apellido: | E10: =PRORRATEO!#REF! -> #REF! | I10: Sello o firma autoriada:
B11: UF: | C11: =PRORRATEO!#REF! -> #REF! | D11: Dpto: | E11: =PRORRATEO!#REF! -> #REF!
B16: Total recibido: | G16: =PRORRATEO!#REF! -> #REF!
B21: RECIBO DE EXPENSAS
B22: CONSORCIO DE PROPIETARIOS DEL EDIFICIO CALLE LORIA 185
B23: CUIT DEL EDIFICIO: 14-57466192-8 | G23: PERÍODO: ABRIL
B24: Adminstradora: Carolina Canciani
B26: Metodo de pago: Transferencia
B28: Nombre y apellido: | E28: =PRORRATEO!#REF! -> #REF! | I28: Sello o firma autoriada:
B29: UF: | C29: =PRORRATEO!#REF! -> #REF! | D29: Dpto: | E29: =PRORRATEO!#REF! -> #REF!
B34: Total recibido: | G34: =PRORRATEO!#REF! -> #REF!
B38: RECIBO DE EXPENSAS
B39: CONSORCIO DE PROPIETARIOS DEL EDIFICIO CALLE LORIA 185
B40: CUIT DEL EDIFICIO: 14-57466192-8 | G40: PERÍODO: ABRIL
B41: Adminstradora: Carolina Canciani
B43: Metodo de pago: Transferencia
B45: Nombre y apellido: | E45: =PRORRATEO!#REF! -> #REF! | I45: Sello o firma autoriada:
B46: UF: | C46: =PRORRATEO!#REF! -> #REF! | D46: Dpto: | E46: =PRORRATEO!#REF! -> #REF!
B51: Total recibido: | G51: =PRORRATEO!#REF! -> #REF!
B54: RECIBO DE EXPENSAS
B55: CONSORCIO DE PROPIETARIOS DEL EDIFICIO CALLE LORIA 185
B56: CUIT DEL EDIFICIO: 14-57466192-8 | G56: PERÍODO: ABRIL
B57: Adminstradora: Carolina Canciani
B59: Metodo de pago: Transferencia
B61: Nombre y apellido: | E61: =PRORRATEO!#REF! -> #REF! | I61: Sello o firma autoriada:
B62: UF: | C62: =PRORRATEO!#REF! -> #REF! | D62: Dpto: | E62: =PRORRATEO!#REF! -> #REF!
B67: Total recibido: | G67: =PRORRATEO!#REF! -> #REF!
B71: RECIBO DE EXPENSAS
B72: CONSORCIO DE PROPIETARIOS DEL EDIFICIO CALLE LORIA 185
B73: CUIT DEL EDIFICIO: 14-57466192-8 | G73: PERÍODO: ABRIL
B74: Adminstradora: Carolina Canciani
B76: Metodo de pago: Transferencia
B78: Nombre y apellido: | E78: =PRORRATEO!#REF! -> #REF! | I78: Sello o firma autoriada:
B79: UF: | C79: =PRORRATEO!#REF! -> #REF! | D79: Dpto: | E79: =PRORRATEO!#REF! -> #REF!
B84: Total recibido: | G84: =PRORRATEO!#REF! -> #REF!
...

Sheet Recibos 10
B2: RECIBO DE EXPENSAS
B3: CONSORCIO DE PROPIETARIOS DEL EDIFICIO CALLE LORIA 185
B4: CUIT DEL EDIFICIO: 14-57466192-8 | G4: PERÍODO: ABRIL
B5: Adminstradora: Carolina Canciani
B7: Metodo de pago: Transferencia
B9: Nombre y apellido: | E9: =PRORRATEO!#REF! -> #REF! | I9: Sello o firma autoriada:
B10: UF: | C10: =PRORRATEO!#REF! -> #REF! | D10: Dpto: | E10: =PRORRATEO!#REF! -> #REF!
B15: Total recibido: | G15: =PRORRATEO!#REF! -> #REF!
B18: RECIBO DE EXPENSAS
B19: CONSORCIO DE PROPIETARIOS DEL EDIFICIO CALLE LORIA 185
B20: CUIT DEL EDIFICIO: 14-57466192-8 | G20: PERÍODO: ABRIL
B21: Adminstradora: Carolina Canciani
B23: Metodo de pago: Transferencia
B25: Nombre y apellido: | E25: =PRORRATEO!#REF! -> #REF! | I25: Sello o firma autoriada:
B26: UF: | C26: =PRORRATEO!#REF! -> #REF! | D26: Dpto: | E26: =PRORRATEO!#REF! -> #REF!
B31: Total recibido: | G31: =PRORRATEO!#REF! -> #REF!
B34: RECIBO DE EXPENSAS
B35: CONSORCIO DE PROPIETARIOS DEL EDIFICIO CALLE LORIA 185
B36: CUIT DEL EDIFICIO: 14-57466192-8 | G36: PERÍODO: ABRIL
B37: Adminstradora: Carolina Canciani
B39: Metodo de pago: Transferencia
B41: Nombre y apellido: | E41: =PRORRATEO!#REF! -> #REF! | I41: Sello o firma autoriada:
B42: UF: | C42: =PRORRATEO!#REF! -> #REF! | D42: Dpto: | E42: =PRORRATEO!#REF! -> #REF!
B47: Total recibido: | G47: =PRORRATEO!#REF! -> #REF!
B52: RECIBO DE EXPENSAS
B53: CONSORCIO DE PROPIETARIOS DEL EDIFICIO CALLE LORIA 185
B54: CUIT DEL EDIFICIO: 14-57466192-8 | G54: PERÍODO: ABRIL
B55: Adminstradora: Carolina Canciani
B57: Metodo de pago: Transferencia
B59: Nombre y apellido: | E59: =PRORRATEO!#REF! -> #REF! | I59: Sello o firma autoriada:
B60: UF: | C60: =PRORRATEO!#REF! -> #REF! | D60: Dpto: | E60: =PRORRATEO!#REF! -> #REF!
B65: Total recibido: | G65: =PRORRATEO!#REF! -> #REF!
B70: RECIBO DE EXPENSAS
B71: CONSORCIO DE PROPIETARIOS DEL EDIFICIO CALLE LORIA 185
B72: CUIT DEL EDIFICIO: 14-57466192-8 | G72: PERÍODO: ABRIL
B73: Adminstradora: Carolina Canciani
B75: Metodo de pago: Transferencia
B77: Nombre y apellido: | E77: =PRORRATEO!#REF! -> #REF! | I77: Sello o firma autoriada:
B78: UF: | C78: =PRORRATEO!#REF! -> #REF! | D78: Dpto: | E78: =PRORRATEO!#REF! -> #REF!
B83: Total recibido: | G83: =PRORRATEO!#REF! -> #REF!
...
