Workbook

Sheet RESUMEN
B1: MAIL: salta1167rc@gmail.com
B2: CUIT ADMINISTRACION: 27231256879
B3: CONSORCIO DE PROPIETARIOS EDIFICIO CALLE SALTA 1167/1169 C DE P SALTA 1167 1169 LANUS CTA CTE $ 039 - 22273/6 CBU: 0720039720000002227368
A4: LIQUIDACION DE EXPENSAS | B4: ADMINISTRADORA: CAROLINA CANCIANI MP:1148
A5: CUIT DEL EDIFICIO: 30-719118061-9 | B5: PERÍODO: ENERO | D5: HORARIOS DE ATENCION: LUNES A VIERNES
A6: CONSORCIO DE PROPIETARIOS DEL EDIFICIO CALLE YRIGOYEN 9730 | D6: 10 A 16HS - EMERGENCIAS 24HS
B8: VTO 16/02
A13: ESTIMADOS PROPIETARIOS E INQUILINOS: POR FAVOR LOS QUE ABONAN EN PRIMER VENCIMIENTO ABONEN EL MONTO DE PRIMER VENCIMIENTO, ASI AGILIZAN LA LIQUIDACION, RESPETEN LOS CENTAVOS CORRESPONDIENTES A LA UNIDAD FUNCIONAL. ES DE CARÁCTER OBLIGATORIO INFORMAR VIA MAIL LAS EXPENSAS. PORFAVOR RESPETAR LOS CENTAVOS AL ABONAR.
A20: GASTOS A - UNIDADES FUNCIONALES:
A21: LIMPIEZA
A22: Full Clean - Servicio de limpieza | D22: 465000.72 | E22: Transf 08/01
A24: TOTAL | E24: =SUM(D22:D23) -> 465000.72
A25: SEGUROS
A26: Federacion patronal Seguro obligatorio de consorcio - Poliza nro. 1-2249124-0 | D26: 74584 | E26: Debito 06/01
A27: TOTAL IMPUESTO | E27: =SUM(D26:D26) -> 74584
A28: ABONOS Y SERVICIOS
A29: Edesur | D29: 0
A30: Metrogas | D30: 5760.77 | E30: Transf 07/01
A31: Metrogas | D31: 275296.83 | E31: Transf 07/01
A32: AySa | D32: 358176.46 | E32: Transf 07/01
A33: Servicio de interet Claro | D33: 22064.59 | E33: Transf 07/01
A34: TOTAL ABONOS Y SERVICIOS | E34: =SUM(D29:D33) -> 661298.65
A36: Lema - Ascensores - Servicio de mantenimiento - Se abona a mes vencido | D36: 75000 | E36: Ef.
A37: Sr. Hector Piletero | D37: 103200 | E37: Transf 26/01
A38: TOTAL | E38: =SUM(D36:D37) -> 178200
A39: HONORARIOS
A40: Honorarios administracion | D40: 150000 | E40: A transferir | G40: Subidos en en3r0
A42: TOTAL | E42: =SUM(D40:D41) -> 150000
A43: GASTOS BANCARIOS
A44: Mantenimiento de cuenta
A45: Gastos bancarios | D45: 21725.2
A46: TOTAL | E46: =SUM(D44:D45) -> 21725.2
A48: PREVISION GASTOS A | E48: =2000000-1550508.57-300 -> 449191.43
A50: TOTAL GASTOS A | E50: =(SUM(E21:E48)) -> 2000000
A53: GASTOS B:
E58: =SUM(D54:D57) -> 0
A61: PREVISION GASTOS B
A63: TOTAL GASTOS B: | E63: =E58+E61 -> 0
A65: GASTOS A + PREVISION (A) : | B65: =E50 -> 2000000
A66: GASTOS A SIN PREVISION: | B66: =E50-E48 -> 1550808.6
...

Sheet PRORRATEO
E2: Gastos B | G2: 0 | K2: Gastos A | L2: 2000000
A4: Estimados convivientes: Les solicitamos, por favor, que al momento de realizar el pago respeten los centavos que figuran en el monto indicado, ya que estos nos permiten identificar correctamente los pagos y las unidades funcionales, reduciendo así el margen de error. Muchas gracias por su colaboración.
A9: REITERAMOS QUE LOS DATOS DE LA CUENTA EN DONDE DEBEN ABONAR LAS EXPENSAS SON: CONSORCIO DE PROPIETARIOS EDIFICIO CALLE SALTA 1167/1169 - C DE P SALTA 1167 1169 LANUS - CTA CTE $ 039 - 22273/6 CBU: 0720039720000002227368
A10: QUIENES ESTAN EN VIOLETA NO ESTAN RESPETANDO LOS CENTAVOS AL ABONAR.
A11: UF | C11: Propietario | D11: Inquilinos | E11: (%) | F11: Saldo Ord | G11: Ingreso | H11: Deuda o Saldo a favor | I11: Interes 3% | J11: EDESUR | K11: Gastos A | L11: Gastos B | M11: EDESUR | N11: Total 1er Vto | O11: Total 2do Vto. | P11: Total 2do Vto
N12: =RESUMEN!B8 -> VTO 16/02
A13: 1 | B13: 1 A | C13: MIRAGLIA NORBERTO JOSE | E13: 12 | F13: 240000.01 | G13: =264000-G29-G30 -> 239999.65 | H13: =F13-G13 -> 0.36 | I13: =IF(H13>0,H13*3%,0) -> 0.0108 | J13: =EDESUR!I5 -> 0 | K13: =L$2*E13/100 -> 240000 | L13: =G$2*E13/100 -> 0 | M13: =Hoja1!O4 -> 0 | N13: =ROUND(SUM(H13:M13),0) + Q13 -> 240000.01 | O13: =ROUND(N13*6% + N13,0) + Q13 -> 254400.01 | P13: =ROUND(N13*3%,0) + N13 -> 247200.01 | Q13: 0.01
A14: 2 | B14: 1 C | C14: ADAMO PABLO MARIANO | E14: 6.6 | F14: 132000.02 | G14: =130000 -> 130000 | H14: =F14-G14 -> 2000.02 | I14: =IF(H14>0,H14*3%,0) -> 60.0006 | J14: =EDESUR!I6 -> 0 | K14: =L$2*E14/100 -> 132000 | L14: =G$2*E14/100 -> 0 | M14: =Hoja1!O5 -> 9105.9823 | N14: =ROUND(SUM(H14:M14),0) + Q14 -> 143166.02 | O14: =ROUND(N14*6% + N14,0) + Q14 -> 151756.02 | P14: =ROUND(N14*3%,0) + N14 -> 147461.02 | Q14: =Q13+0.01 -> 0.02
A15: 3 | B15: 1 D | C15: REDONDO | D15: Gilmer | E15: 5.4 | F15: 108000.03 | G15: =F15 -> 108000.03 | H15: =F15-G15 -> 0 | I15: =IF(H15>0,H15*3%,0) -> 0 | J15: =EDESUR!I7 -> 0 | K15: =L$2*E15/100 -> 108000 | L15: =G$2*E15/100 -> 0 | M15: =Hoja1!O6 -> 0 | N15: =ROUND(SUM(H15:M15),0) + Q15 -> 108000.03 | O15: =ROUND(N15*6% + N15,0) + Q15 -> 114480.03 | P15: =ROUND(N15*3%,0) + N15 -> 111240.03 | Q15: =Q14+0.01 -> 0.03
A16: 4 | B16: 2 B | C16: CRUZ ADRIANA BEATRIZ | D16: Cristian | E16: 6.6 | F16: 132000.04 | G16: =144000.25-G32 -> 132000.05 | H16: =F16-G16 -> -0.01 | I16: =IF(H16>0,H16*3%,0) -> 0 | J16: =EDESUR!I8 -> 0 | K16: =L$2*E16/100 -> 132000 | L16: =G$2*E16/100 -> 0 | M16: =Hoja1!O8 -> 0 | N16: =ROUND(SUM(H16:M16),0) + Q16 -> 132000.04 | O16: =ROUND(N16*6% + N16,0) + Q16 -> 139920.04 | P16: =ROUND(N16*3%,0) + N16 -> 135960.04 | Q16: =Q15+0.01 -> 0.04
A17: 5 | B17: 2 C | C17: D AMURI JOSE LUIS | D17: Martina Belen Carbone | E17: 6.6 | F17: 132000.05 | G17: =F17 -> 132000.05 | H17: =F17-G17 -> 0 | I17: =IF(H17>0,H17*3%,0) -> 0 | J17: =EDESUR!I9 -> 0 | K17: =L$2*E17/100 -> 132000 | L17: =G$2*E17/100 -> 0 | M17: =Hoja1!O9 -> 0 | N17: =ROUND(SUM(H17:M17),0) + Q17 -> 132000.05 | O17: =ROUND(N17*6% + N17,0) + Q17 -> 139920.05 | P17: =ROUND(N17*3%,0) + N17 -> 135960.05 | Q17: =Q16+0.01 -> 0.05 | R17: Alejo Moreno
A18: 6 | B18: 2 D | C18: CAMPOLONGO LUIS | D18: Leandro Gonzalez | E18: 5.4 | F18: 108000.06 | G18: =F18 -> 108000.06 | H18: =F18-G18 -> 0 | I18: =IF(H18>0,H18*3%,0) -> 0 | J18: =EDESUR!I10 -> 0 | K18: =L$2*E18/100 -> 108000 | L18: =G$2*E18/100 -> 0 | M18: =Hoja1!O10 -> 0 | N18: =ROUND(SUM(H18:M18),0) + Q18 -> 108000.06 | O18: =ROUND(N18*6% + N18,0) + Q18 -> 114480.06 | P18: =ROUND(N18*3%,0) + N18 -> 111240.06 | Q18: =Q17+0.01 -> 0.06
A19: 7 | B19: 2 A | C19: PEREZ FERNANDO ARIEL | D19: Gaston Miranda | E19: 5.4 | F19: 108000.07 | H19: =F19-G19 -> 108000.07 | I19: =IF(H19>0,H19*3%,0) -> 3240.0021 | J19: =EDESUR!I11 -> 0 | K19: =L$2*E19/100 -> 108000 | L19: =G$2*E19/100 -> 0 | M19: =Hoja1!O7 -> 0 | N19: =ROUND(SUM(H19:M19),0) + Q19 -> 219240.07 | O19: =ROUND(N19*6% + N19,0) + Q19 -> 232394.07 | P19: =ROUND(N19*3%,0) + N19 -> 225817.07 | Q19: =Q18+0.01 -> 0.07
A20: 8 | B20: 3 B | C20: BURGOA CARINA | D20: Alan/Ailen | E20: 6.6 | F20: 135960.08 | G20: =F20 -> 135960.08 | H20: =F20-G20 -> 0 | I20: =IF(H20>0,H20*3%,0) -> 0 | J20: =EDESUR!I12 -> 0 | K20: =L$2*E20/100 -> 132000 | L20: =G$2*E20/100 -> 0 | M20: =Hoja1!O12 -> 0 | N20: =ROUND(SUM(H20:M20),0) + Q20 -> 132000.08 | O20: =ROUND(N20*6% + N20,0) + Q20 -> 139920.08 | P20: =ROUND(N20*3%,0) + N20 -> 135960.08 | Q20: =Q19+0.01 -> 0.08
A21: 9 | B21: 3 C | C21: GIL ROSANNA MABEL | D21: Gaston ibarra | E21: 6.6 | F21: 132000.09 | G21: =F21 -> 132000.09 | H21: =F21-G21 -> 0 | I21: =IF(H21>0,H21*3%,0) -> 0 | J21: =EDESUR!I13 -> 0 | K21: =L$2*E21/100 -> 132000 | L21: =G$2*E21/100 -> 0 | M21: =Hoja1!O13 -> 0 | N21: =ROUND(SUM(H21:M21),0) + Q21 -> 132000.09 | O21: =ROUND(N21*6% + N21,0) + Q21 -> 139920.09 | P21: =ROUND(N21*3%,0) + N21 -> 135960.09 | Q21: =Q20+0.01 -> 0.09
A22: 10 | B22: 3 D | C22: FELIX ALBERTO | D22: Jhonatan | E22: 5.4 | F22: 108000.1 | G22: =F22 -> 108000.1 | H22: =F22-G22 -> 0 | I22: =IF(H22>0,H22*3%,0) -> 0 | J22: =EDESUR!I14 -> 0 | K22: =L$2*E22/100 -> 108000 | L22: =G$2*E22/100 -> 0 | M22: =Hoja1!O14 -> 0 | N22: =ROUND(SUM(H22:M22),0) + Q22 -> 108000.1 | O22: =ROUND(N22*6% + N22,0) + Q22 -> 114480.1 | P22: =ROUND(N22*3%,0) + N22 -> 111240.1 | Q22: =Q21+0.01 -> 0.1
A23: 11 | B23: 3 A | C23: CAMPANA WALTER CESAR | E23: 5.4 | F23: 108000.11 | G23: =114033-G34 -> 108032.78 | H23: =F23-G23 -> -32.67 | I23: =IF(H23>0,H23*3%,0) -> 0 | J23: =EDESUR!I15 -> 0 | K23: =L$2*E23/100 -> 108000 | L23: =G$2*E23/100 -> 0 | M23: =Hoja1!O11 -> 0 | N23: =ROUND(SUM(H23:M23),0) + Q23 -> 107967.11 | O23: =ROUND(N23*6% + N23,0) + Q23 -> 114445.11 | P23: =ROUND(N23*3%,0) + N23 -> 111206.11 | Q23: =Q22+0.01 -> 0.11 | R23: Antonella
A24: 12 | B24: 4 B | C24: PALMA JOSE AGUSTIN | D24: Juan Ignacio / Mariel Cruz | E24: 6.6 | F24: 132000.12 | G24: =F24 -> 132000.12 | H24: =F24-G24 -> 0 | I24: =IF(H24>0,H24*3%,0) -> 0 | J24: =EDESUR!I16 -> 0 | K24: =L$2*E24/100 -> 132000 | L24: =G$2*E24/100 -> 0 | M24: =Hoja1!O16 -> 0 | N24: =ROUND(SUM(H24:M24),0) + Q24 -> 132000.12 | O24: =ROUND(N24*6% + N24,0) + Q24 -> 139920.12 | P24: =ROUND(N24*3%,0) + N24 -> 135960.12 | Q24: =Q23+0.01 -> 0.12
A25: 13 | B25: 4 C | C25: BENITEZ EMILIA ISABEL | D25: Daniel Leiva | E25: 6.6 | F25: 128159.13 | G25: 132004.13 | H25: =F25-G25 -> -3845 | I25: =IF(H25>0,H25*3%,0) -> 0 | J25: =EDESUR!I17 -> 0 | K25: =L$2*E25/100 -> 132000 | L25: =G$2*E25/100 -> 0 | M25: =Hoja1!O17 -> 0 | N25: =ROUND(SUM(H25:M25),0) + Q25 -> 128155.13 | O25: =ROUND(N25*6% + N25,0) + Q25 -> 135844.13 | P25: =ROUND(N25*3%,0) + N25 -> 132000.13 | Q25: =Q24+0.01 -> 0.13
A26: 14 | B26: 4 D | C26: PUCHETA SANTIAGO / CLARA | E26: 5.4 | F26: 83116.14 | G26: =F26 -> 83116.14 | H26: =F26-G26 -> 0 | I26: =IF(H26>0,H26*3%,0) -> 0 | J26: =EDESUR!I18 -> 0 | K26: =L$2*E26/100 -> 108000 | L26: =G$2*E26/100 -> 0 | M26: =Hoja1!O18 -> 0 | N26: =ROUND(SUM(H26:M26),0) + Q26 -> 108000.14 | O26: =ROUND(N26*6% + N26,0) + Q26 -> 114480.14 | P26: =ROUND(N26*3%,0) + N26 -> 111240.14 | Q26: =Q25+0.01 -> 0.14
A27: 15 | B27: 4 A | C27: CAMPANA MIRIAM NOEMI | E27: 5.4 | F27: 108000.15 | G27: =F27 -> 108000.15 | H27: =F27-G27 -> 0 | I27: =IF(H27>0,H27*3%,0) -> 0 | J27: =EDESUR!I19 -> 0 | K27: =L$2*E27/100 -> 108000 | L27: =G$2*E27/100 -> 0 | M27: =Hoja1!O15 -> 0 | N27: =ROUND(SUM(H27:M27),0) + Q27 -> 108000.15 | O27: =ROUND(N27*6% + N27,0) + Q27 -> 114480.15 | P27: =ROUND(N27*3%,0) + N27 -> 111240.15 | Q27: =Q26+0.01 -> 0.15
A28: 16 | B28: COC 1 | C28: CAMPOLONGO LUIS | D28: Leandro Gonzalez | E28: 0.7 | F28: 14000.16 | G28: =F28 -> 14000.16 | H28: =F28-G28 -> 0 | I28: =IF(H28>0,H28*3%,0) -> 0 | J28: =EDESUR!I22 -> 0 | K28: =L$2*E28/100 -> 14000 | L28: =G$2*E28/100 -> 0 | M28: =Hoja1!O22 -> 0 | N28: =ROUND(SUM(H28:M28),0) + Q28 -> 14000.16 | O28: =ROUND(N28*6% + N28,0) + Q28 -> 14840.16 | P28: =ROUND(N28*3%,0) + N28 -> 14420.16 | Q28: =Q27+0.01 -> 0.16
A29: 17 | B29: COC 2 | C29: MIRAGLIA NORBERTO JOSE | E29: 0.6 | F29: 12000.17 | G29: =F29 -> 12000.17 | H29: =F29-G29 -> 0 | I29: =IF(H29>0,H29*3%,0) -> 0 | J29: =EDESUR!I21 -> 0 | K29: =L$2*E29/100 -> 12000 | L29: =G$2*E29/100 -> 0 | M29: =Hoja1!O23 -> 0 | N29: =ROUND(SUM(H29:M29),0) + Q29 -> 12000.17 | O29: =ROUND(N29*6% + N29,0) + Q29 -> 12720.17 | P29: =ROUND(N29*3%,0) + N29 -> 12360.17 | Q29: =Q28+0.01 -> 0.17
A30: 18 | B30: COC 3 | C30: MIRAGLIA NORBERTO JOSE | E30: 0.6 | F30: 12000.18 | G30: =F30 -> 12000.18 | H30: =F30-G30 -> 0 | I30: =IF(H30>0,H30*3%,0) -> 0 | J30: =EDESUR!I22 -> 0 | K30: =L$2*E30/100 -> 12000 | L30: =G$2*E30/100 -> 0 | M30: =Hoja1!O24 -> 0 | N30: =ROUND(SUM(H30:M30),0) + Q30 -> 12000.18 | O30: =ROUND(N30*6% + N30,0) + Q30 -> 12720.18 | P30: =ROUND(N30*3%,0) + N30 -> 12360.18 | Q30: =Q29+0.01 -> 0.18
A31: 19 | B31: COC 4 | C31: PALMA JOSE AGUSTIN | E31: 0.6 | F31: 12000.19 | G31: 12360 | H31: =F31-G31 -> -359.81 | I31: =IF(H31>0,H31*3%,0) -> 0 | J31: =EDESUR!I23 -> 0 | K31: =L$2*E31/100 -> 12000 | L31: =G$2*E31/100 -> 0 | M31: =Hoja1!O25 -> 0 | N31: =ROUND(SUM(H31:M31),0) + Q31 -> 11640.19 | P31: =ROUND(N31*3%,0) + N31 -> 11989.19 | Q31: =Q30+0.01 -> 0.19
A32: 20 | B32: COC 5 | C32: CRUZ ADRIANA BEATRIZ | D32: Cristian | E32: 0.6 | F32: 12000.2 | G32: =F32 -> 12000.2 | H32: =F32-G32 -> 0 | I32: =IF(H32>0,H32*3%,0) -> 0 | J32: =EDESUR!I24 -> 0 | K32: =L$2*E32/100 -> 12000 | L32: =G$2*E32/100 -> 0 | M32: =Hoja1!O26 -> 0 | N32: =ROUND(SUM(H32:M32),0) + Q32 -> 12000.2 | P32: =ROUND(N32*3%,0) + N32 -> 12360.2 | Q32: =Q31+0.01 -> 0.2
A33: 21 | B33: COC 6 | C33: FELIX ALBERTO | D33: Jhonatan | E33: 0.3 | F33: 6000.21 | G33: =F33 -> 6000.21 | H33: =F33-G33 -> 0 | I33: =IF(H33>0,H33*3%,0) -> 0 | J33: =EDESUR!I25 -> 0 | K33: =L$2*E33/100 -> 6000 | L33: =G$2*E33/100 -> 0 | M33: =Hoja1!O27 -> 0 | N33: =ROUND(SUM(H33:M33),0) + Q33 -> 6000.21 | P33: =ROUND(N33*3%,0) + N33 -> 6180.21 | Q33: =Q32+0.01 -> 0.21
A34: 22 | B34: COC 7 | C34: CAMPANA WALTER CESAR | E34: 0.3 | F34: 6000.22 | G34: =F34 -> 6000.22 | H34: =F34-G34 -> 0 | I34: =IF(H34>0,H34*3%,0) -> 0 | J34: =EDESUR!I26 -> 0 | K34: =L$2*E34/100 -> 6000 | L34: =G$2*E34/100 -> 0 | M34: =Hoja1!O28 -> 0 | N34: =ROUND(SUM(H34:M34),0) + Q34 -> 6000.22 | P34: =ROUND(N34*3%,0) + N34 -> 6180.22 | Q34: =Q33+0.01 -> 0.22
A35: 23 | B35: COC 8 | C35: REDONDO HECTOR | D35: Gilmer | E35: 0.3 | F35: 6000.23 | G35: =F35 -> 6000.23 | H35: =F35-G35 -> 0 | I35: =IF(H35>0,H35*3%,0) -> 0 | J35: =EDESUR!I27 -> 0 | K35: =L$2*E35/100 -> 6000 | L35: =G$2*E35/100 -> 0 | M35: =Hoja1!O29 -> 0 | N35: =ROUND(SUM(H35:M35),0) + Q35 -> 6000.23 | P35: =ROUND(N35*3%,0) + N35 -> 6180.23 | Q35: =Q34+0.01 -> 0.23
E36: =SUM(E13:E35) -> 100 | F36: =SUM(F13:F35) -> 1975237.8 | G36: =SUM(G13:G35) -> 1869474.8 | H36: =SUM(H13:H35) -> 105762.96 | I36: =SUM(I13:I35) -> 3300.0135 | J36: =SUM(J13:J35) -> 0 | K36: =SUM(K13:K35) -> 2000000 | L36: =SUM(L13:L35) -> 0 | N36: =SUM(N13:N35) -> 2118170.8 | O36: =SUM(O13:O35) -> 2201120.7 | P36: =SUM(P13:P35) -> 2181715.8
C39: =RESUMEN!A13 -> ESTIMADOS PROPIETARIOS E INQUILINOS: POR FAVOR LOS QUE ABONAN EN PRIMER VENCIMIENTO ABONEN EL MONTO DE PRIMER VENCIMIENTO, ASI AGILIZAN LA LIQUIDACION, RESPETEN LOS CENTAVOS CORRESPONDIENTES A LA UNIDAD FUNCIONAL. ES DE CARÁCTER OBLIGATORIO INFORMAR VIA MAIL LAS EXPENSAS. PORFAVOR RESPETAR LOS CENTAVOS AL ABONAR.

Sheet Hoja1
D2: Consumos PARTICULARES | H2: Consumos GENERALES | K2: Total Edesur x Depto | M2: Bonificado x EDESUR | O2: SALDO a PAGAR
B3: Piso | C3: Depto | D3: Consumo Kw | E3: % Consumido | F3: Consumo x Dep | H3: Porcentaje | I3: Cons Esp Com
B4: 1 | C4: A | D4: 132.44 | E4: 0.14153202 | F4: 27650.646 | H4: 0.12 | I4: 5091.8611 | K4: =I4+F4 -> 32742.508 | M4: =K4 -> 32742.508 | O4: =K4-M4 -> 0
B5: 1 | C5: C | D5: 107.16 | E5: 0.11451654 | F5: 22372.722 | H5: 0.066 | I5: 2800.5236 | K5: =I5+F5 -> 25173.245 | M5: 16067.263 | O5: =K5-M5 -> 9105.9823
B6: 1 | C6: D | D6: 102.28 | E6: 0.10930153 | F6: 21353.882 | H6: 0.054 | I6: 2291.3375 | K6: =I6+F6 -> 23645.219 | M6: =K6 -> 23645.219 | O6: =K6-M6 -> 0
B7: 2 | C7: A | D7: 20.16 | E7: 0.021543986 | F7: 4208.9779 | H7: 0.054 | I7: 2291.3375 | K7: =I7+F7 -> 6500.3154 | M7: =K7 -> 6500.3154 | O7: =K7-M7 -> 0
B8: 2 | C8: B | D8: 0 | E8: 0 | F8: 0 | H8: 0.066 | I8: 2800.5236 | K8: =I8+F8 -> 2800.5236 | M8: =K8 -> 2800.5236 | O8: =K8-M8 -> 0
B9: 2 | C9: C | D9: 0 | E9: 0 | F9: 0 | H9: 0.066 | I9: 2800.5236 | K9: =I9+F9 -> 2800.5236 | M9: =K9 -> 2800.5236 | O9: =K9-M9 -> 0
B10: 2 | C10: D | D10: 0 | E10: 0 | F10: 0 | H10: 0.054 | I10: 2291.3375 | K10: =I10+F10 -> 2291.3375 | M10: =K10 -> 2291.3375 | O10: =K10-M10 -> 0
B11: 3 | C11: A | D11: 0 | E11: 0 | F11: 0 | H11: 0.054 | I11: 2291.3375 | K11: =I11+F11 -> 2291.3375 | M11: =K11 -> 2291.3375 | O11: =K11-M11 -> 0
B12: 3 | C12: B | D12: 253.12 | E12: 0.27049671 | F12: 52846.056 | H12: 0.066 | I12: 2800.5236 | K12: =I12+F12 -> 55646.579 | M12: =K12 -> 55646.579 | O12: =K12-M12 -> 0
B13: 3 | C13: C | D13: 0 | E13: 0 | F13: 0 | H13: 0.066 | I13: 2800.5236 | K13: =I13+F13 -> 2800.5236 | M13: =K13 -> 2800.5236 | O13: =K13-M13 -> 0
B14: 3 | C14: D | D14: 0 | E14: 0 | F14: 0 | H14: 0.054 | I14: 2291.3375 | K14: =I14+F14 -> 2291.3375 | M14: =K14 -> 2291.3375 | O14: =K14-M14 -> 0
B15: 4 | C15: A | D15: 281.24 | E15: 0.30054715 | F15: 58716.912 | H15: 0.054 | I15: 2291.3375 | K15: =I15+F15 -> 61008.249 | M15: =K15 -> 61008.249 | O15: =K15-M15 -> 0
B16: 4 | C16: B | D16: 0 | E16: 0 | F16: 0 | H16: 0.066 | I16: 2800.5236 | K16: =I16+F16 -> 2800.5236 | M16: =K16 -> 2800.5236 | O16: =K16-M16 -> 0
B17: 4 | C17: C | D17: 39.36 | E17: 0.042062067 | F17: 8217.5283 | H17: 0.066 | I17: 2800.5236 | K17: =I17+F17 -> 11018.052 | M17: =K17 -> 11018.052 | O17: =K17-M17 -> 0
B18: 4 | C18: D | D18: 0 | E18: 0 | F18: 0 | H18: 0.054 | I18: 2291.3375 | K18: =I18+F18 -> 2291.3375 | M18: =K18 -> 2291.3375 | O18: =K18-M18 -> 0
C20: Totales | D20: =SUM(D4:D19) -> 935.76 | F20: =SUM(F4:F19) -> 195366.72 | I20: =SUM(I4:I19) -> 40734.889 | K20: =SUM(K4:K19) -> 236101.61 | M20: =SUM(M4:M19) -> 226995.63 | O20: =SUM(O4:O19) -> 9105.9823
B22: Cochera | C22: 1 | H22: 0.007 | I22: 297.02523 | K22: =I22 -> 297.02523 | M22: =K22 -> 297.02523 | O22: =K22-M22 -> 0
B23: Cochera | C23: 2 | H23: 0.006 | I23: 254.59306 | K23: =I23 -> 254.59306 | M23: =K23 -> 254.59306 | O23: =K23-M23 -> 0
B24: Cochera | C24: 3 | H24: 0.006 | I24: 254.59306 | K24: =I24 -> 254.59306 | M24: =K24 -> 254.59306 | O24: =K24-M24 -> 0
B25: Cochera | C25: 4 | H25: 0.006 | I25: 254.59306 | K25: =I25 -> 254.59306 | M25: =K25 -> 254.59306 | O25: =K25-M25 -> 0
B26: Cochera | C26: 5 | H26: 0.006 | I26: 254.59306 | K26: =I26 -> 254.59306 | M26: =K26 -> 254.59306 | O26: =K26-M26 -> 0
B27: Cochera | C27: 6 | H27: 0.003 | I27: 127.29653 | K27: =I27 -> 127.29653 | M27: =K27 -> 127.29653 | O27: =K27-M27 -> 0
B28: Cochera | C28: 7 | H28: 0.003 | I28: 127.29653 | K28: =I28 -> 127.29653 | M28: =K28 -> 127.29653 | O28: =K28-M28 -> 0
B29: Cochera | C29: 8 | H29: 0.003 | I29: 127.29653 | K29: =I29 -> 127.29653 | M29: =K29 -> 127.29653 | O29: =K29-M29 -> 0
H30: Cons Coch | I30: =SUM(I22:I29) -> 1697.287 | K30: =SUM(K22:K29) -> 1697.287 | M30: =SUM(M22:M29) -> 1697.287 | O30: =SUM(O22:O29) -> 0
D32: TOTAL FACT EDESUR | F32: 237798.9 | I32: =F20+I20+I30 -> 237798.9 | K32: =K20+K30 -> 237798.9 | M32: =M20+M30 -> 228692.92 | O32: =O20+O30 -> 9105.9823

Sheet EDESUR
B3: Piso | C3: Depto | E3: Total Edesur x Depto | G3: Bonificado x EDESUR Noviembre | I3: SALDO a PAGAR
B5: 1 | C5: A | E5: 26132.02 | G5: =E5 -> 26132.02 | I5: =E5-G5 -> 0
B6: 1 | C6: C | E6: 12925.66 | G6: =E6 -> 12925.66 | I6: =E6-G6 -> 0
B7: 1 | C7: D | E7: 10709.96 | G7: =E7 -> 10709.96 | I7: =E7-G7 -> 0
B8: 2 | C8: A | E8: 5448.33 | G8: =E8 -> 5448.33 | I8: =E8-G8 -> 0
B9: 2 | C9: B | E9: 2716.04 | G9: =E9 -> 2716.04 | I9: =E9-G9 -> 0
B10: 2 | C10: C | E10: 2716.04 | G10: =E10 -> 2716.04 | I10: =E10-G10 -> 0
B11: 2 | C11: D | E11: 2222.21 | G11: =E11 -> 2222.21 | I11: =E11-G11 -> 0
B12: 3 | C12: A | E12: 2222.21 | G12: =E12 -> 2222.21 | I12: =E12-G12 -> 0
B13: 3 | C13: B | E13: 24018.62 | G13: =E13 -> 24018.62 | I13: =E13-G13 -> 0
B14: 3 | C14: C | E14: 2716.04 | G14: =E14 -> 2716.04 | I14: =E14-G14 -> 0
B15: 3 | C15: D | E15: 2222.21 | G15: =E15 -> 2222.21 | I15: =E15-G15 -> 0
B16: 4 | C16: A | E16: 36166.8 | G16: =E16 -> 36166.8 | I16: =E16-G16 -> 0
... B19: 4 | C19: D | E19: 2222.21 | G19: =E19 -> 2222.21 | I19: =E19-G19 -> 0
B21: Totales | E21: =SUM(E5:E20) -> 144169.02 | G21: =SUM(G5:G20) -> 144169.02 | I21: =E21-G21 -> 0
B22: Cochera | C22: 1 | E22: 288.06 | G22: =E22 -> 288.06 | I22: =E22-G22 -> 0
B23: Cochera | C23: 2 | E23: 246.91 | G23: =E23 -> 246.91 | I23: =E23-G23 -> 0
B24: Cochera | C24: 3 | E24: 246.91 | G24: =E24 -> 246.91 | I24: =E24-G24 -> 0
B25: Cochera | C25: 4 | E25: 246.91 | G25: =E25 -> 246.91 | I25: =E25-G25 -> 0
B26: Cochera | C26: 5 | E26: 246.91 | G26: =E26 -> 246.91 | I26: =E26-G26 -> 0
B27: Cochera | C27: 6 | E27: 123.46 | G27: =E27 -> 123.46 | I27: =E27-G27 -> 0
B28: Cochera | C28: 7 | E28: 123.46 | G28: =E28 -> 123.46 | I28: =E28-G28 -> 0
B29: Cochera | C29: 8 | E29: 123.46 | G29: =E29 -> 123.46 | I29: =E29-G29 -> 0
B30: Totales | E30: =SUM(E22:E29) -> 1646.08 | G30: =SUM(G22:G29) -> 1646.08 | I30: =E30-G30 -> 0
I31: =E31-G31 -> 0
E33: =E30+E21 -> 145815.1 | G33: =G21+G30 -> 145815.1 | I33: =E33-G33 -> 0
