Workbook

Sheet Gastos
D3: Cel. | E3: 1153202676 - Horarios de atencion: Lunes a Viernes de 10hs a 16hs
D4: e-mail: | E4: consorciobelgrano1328@gmail.com
D5: Administradora: CAROLINA CANCIANI
D6: CUIT Administradora: | E6: 27231256879 | G6: MP 1148
D7: Doctor Melo 2958 - Lanus Oeste - Piso 8 - con cita previa
A8: LIQUIDACION DE EXPENSAS | C8: PERIODO: MAYO | G8: 1ER VTO: 16/06
A9: CONSORCIO: ADMINISTRACION DE CONSORCIOS RC
A12: 1- SUELDO ENCARGADA
A13: SUELDO - REMUNERACIONES SUJETAS A RETENCION | H13: 494448
A14: REDONDEO | H14: 0.88
A15: DEDUCCIONES | H15: -122375.88
A16: TOTAL | H16: =SUM(H13:H15) -> 372073
A17: BONOS Y AJUSTES
A18: Gratificacion anual | H18: 0
A19: Deducciones | H19: 0
A20: Ajuste MAYO 2023 | H20: 0
A21: Deducciones | H21: 0
A22: Ajuste MAYO 2023 | H22: 0
A23: Deducciones | H23: 0
A24: TOTAL | H24: =SUM(H18:H23) -> 0
A25: SAC MAYO
A28: TOTAL SAC | H28: =SUM(H26:H27) -> 0
A29: 2-CARGAS SOCIALES
A30: SUTHER | B30: NO SE DEBITA | H30: 17301.4
A31: FATHERY | B31: NO SE DEBITA | H31: 49790.91
A32: SERACARH | B32: NO SE DEBITA | H32: 1922.38
A33: SUTHER | H33: 56139.12
A34: FATHERY | H34: 2472.24
A35: SERACARH | H35: 22250.16
A36: SEGURO SRA EVA | B36: FEDERACION PATRONAL - ACCIDENTE DE RIESGOS PERSONALES | H36: 5712
A37: ARCA | H37: 245128.34
A38: TOTAL | H38: =SUM(H30:H37) -> 400716.55
A39: 3- SERVICIOS
A40: AYSA - NRO. DE CUENTA 297930 - Vto. 1/04 | H40: 382405.71
A41: AYSA - NRO. DE CUENTA 297930 - Vto. 28/04 | H41: 381241.28
A42: CABLEVISION - NRO DE REFERENCIA 0477093152678 | H42: 19443.71
A43: EDESUR - CLIENTE NRO 01408557 | H43: 529266.62
A44: TOTAL | H44: =SUM(H40:H43) -> 1312357.3
A45: 4- MANTENIMIENTO DE PARTES COMUNES
A46: LEMA MANTENIMIENTO DE ASCENSORES | D46: MES DE MAYO | H46: 72800
...

Sheet Planilla
B1: =Gastos!C8 -> PERIODO: MAYO
C3: 2715751.3
B4: ORDINARIOS: | E4: EXTRAORDINARIAS:
B5: 2500000 | E5: =F3 -> 0
O7: =Gastos!G8 -> 1ER VTO: 16/06
A8: U.F. | B8: PISO - DEPTO | C8: PROPIETARIOS | D8: INQUILINOS | E8: % | F8: SALDO ANTERIOR | G8: SALDO ACTUAL | H8: DEUDA | I8: INTERES por MORA 3% | J8: SALDO A FAVOR | L8: GASTOS ORDINARIOS | M8: GASTOS EXTR. | N8: SUM | O8: 1 ER VTO. | P8: 2DO VTO. | Q8: 2DO VTO.
A9: 1 | B9: 1A | C9: Gaffuri Daniel | E9: 0.0449 | F9: 83139.524 | G9: =F9 -> 83139.524 | H9: =IF(F9>G9,F9-G9,0) -> 0 | I9: =H9*3% -> 0 | J9: =IF(G9>F9,G9-F9,0) -> 0 | L9: =B$5*E9 -> 112250 | M9: =E$5*E9 -> 0 | O9: =H9+I9-J9+K9+L9+M9+N9 -> 112250 | P9: =O9+O9*4% -> 116740 | Q9: =P9*2% + P9 -> 119074.8
A10: 2 | B10: 1B | C10: Benvenutto, Irene | E10: 0.0449 | F10: 83172.683 | G10: 83200 | H10: =IF(F10>G10,F10-G10,0) -> 0 | I10: =H10*3% -> 0 | J10: =IF(G10>F10,G10-F10,0) -> 27.316779 | L10: =B$5*E10 -> 112250 | M10: =E$5*E10 -> 0 | O10: =H10+I10-J10+K10+L10+M10+N10 -> 112222.68 | P10: =O10+O10*4% -> 116711.59 | Q10: =P10*2% + P10 -> 119045.82
A11: 3 | B11: 2A | C11: Sanchez Marcelo | E11: 0.0449 | F11: 83172.683 | G11: =86500 -> 86500 | H11: =IF(F11>G11,F11-G11,0) -> 0 | I11: =H11*3% -> 0 | J11: =IF(G11>F11,G11-F11,0) -> 3327.3168 | L11: =B$5*E11 -> 112250 | M11: =E$5*E11 -> 0 | O11: =H11+I11-J11+K11+L11+M11+N11 -> 108922.68 | P11: =O11+O11*4% -> 113279.59 | Q11: =P11*2% + P11 -> 115545.18
A12: 4 | B12: 2B | C12: Zeballos, Maria Eugenia | D12: Nicolas | E12: 0.0449 | F12: 83172.683 | G12: =77100 -> 77100 | H12: =IF(F12>G12,F12-G12,0) -> 6072.6832 | I12: =H12*3% -> 182.1805 | J12: =IF(G12>F12,G12-F12,0) -> 0 | L12: =B$5*E12 -> 112250 | M12: =E$5*E12 -> 0 | O12: =H12+I12-J12+K12+L12+M12+N12 -> 118504.86 | P12: =O12+O12*4% -> 123245.06 | Q12: =P12*2% + P12 -> 125709.96
A13: 5 | B13: 3A | C13: Vicente, Flavia E | E13: 0.0449 | F13: 83172.683 | G13: =F13 -> 83172.683 | H13: =IF(F13>G13,F13-G13,0) -> 0 | I13: =H13*3% -> 0 | J13: =IF(G13>F13,G13-F13,0) -> 0 | L13: =B$5*E13 -> 112250 | M13: =E$5*E13 -> 0 | O13: =H13+I13-J13+K13+L13+M13+N13 -> 112250 | P13: =O13+O13*4% -> 116740 | Q13: =P13*2% + P13 -> 119074.8
A14: 6 | B14: 3B | C14: Martinez Yasnikowski, Fernando | E14: 0.0449 | F14: 83172.669 | H14: =IF(F14>G14,F14-G14,0) -> 83172.669 | I14: =H14*3% -> 2495.1801 | J14: =IF(G14>F14,G14-F14,0) -> 0 | L14: =B$5*E14 -> 112250 | M14: =E$5*E14 -> 0 | O14: =H14+I14-J14+K14+L14+M14+N14 -> 197917.85 | P14: =O14+O14*4% -> 205834.56 | Q14: =P14*2% + P14 -> 209951.25
A15: 7 | B15: 4A | C15: Arias Juan Jose | E15: 0.0449 | F15: 82838.045 | G15: =89000-G35 -> 86406.642 | H15: =IF(F15>G15,F15-G15,0) -> 0 | I15: =H15*3% -> 0 | J15: =IF(G15>F15,G15-F15,0) -> 3568.5974 | L15: =B$5*E15 -> 112250 | M15: =E$5*E15 -> 0 | O15: =H15+I15-J15+K15+L15+M15+N15 -> 108681.4 | P15: =O15+O15*4% -> 113028.66 | Q15: =P15*2% + P15 -> 115289.23
A16: 8 | B16: 4B | C16: Dangelo Salvador Luis | E16: 0.0449 | F16: 83172.683 | G16: =89005-G38 -> 86596.882 | H16: =IF(F16>G16,F16-G16,0) -> 0 | I16: =H16*3% -> 0 | J16: =IF(G16>F16,G16-F16,0) -> 3424.199 | L16: =B$5*E16 -> 112250 | M16: =E$5*E16 -> 0 | O16: =H16+I16-J16+K16+L16+M16+N16 -> 108825.8 | P16: =O16+O16*4% -> 113178.83 | Q16: =P16*2% + P16 -> 115442.41
A17: 9 | B17: 5A | C17: Fabiana Sambartolomeo | D17: Gustavo Lago | E17: 0.0449 | F17: 79339.524 | G17: =82513.11 -> 82513.11 | H17: =IF(F17>G17,F17-G17,0) -> 0 | I17: =H17*3% -> 0 | J17: =IF(G17>F17,G17-F17,0) -> 3173.5857 | L17: =B$5*E17 -> 112250 | M17: =E$5*E17 -> 0 | O17: =H17+I17-J17+K17+L17+M17+N17 -> 109076.41 | P17: =O17+O17*4% -> 113439.47 | Q17: =P17*2% + P17 -> 115708.26
A18: 10 | B18: 5B | C18: Palacios, Lia | D18: Candela | E18: 0.0449 | F18: 83172.683 | G18: =F18 -> 83172.683 | H18: =IF(F18>G18,F18-G18,0) -> 0 | I18: =H18*3% -> 0 | J18: =IF(G18>F18,G18-F18,0) -> 0 | L18: =B$5*E18 -> 112250 | M18: =E$5*E18 -> 0 | O18: =H18+I18-J18+K18+L18+M18+N18 -> 112250 | P18: =O18+O18*4% -> 116740 | Q18: =P18*2% + P18 -> 119074.8
A19: 11 | B19: 6A | C19: Matta, Belén | E19: 0.0449 | F19: 83139.524 | G19: =F19 -> 83139.524 | H19: =IF(F19>G19,F19-G19,0) -> 0 | I19: =H19*3% -> 0 | J19: =IF(G19>F19,G19-F19,0) -> 0 | L19: =B$5*E19 -> 112250 | M19: =E$5*E19 -> 0 | O19: =H19+I19-J19+K19+L19+M19+N19 -> 112250 | P19: =O19+O19*4% -> 116740 | Q19: =P19*2% + P19 -> 119074.8
A20: 12 | B20: 6B | C20: Bruno, Mario | D20: Gaston Alvarez | E20: 0.0449 | F20: 83172.683 | G20: =85580.8-G39 -> 83172.682 | H20: =IF(F20>G20,F20-G20,0) -> 0.000998 | I20: =H20*3% -> 2.994e-05 | J20: =IF(G20>F20,G20-F20,0) -> 0 | L20: =B$5*E20 -> 112250 | M20: =E$5*E20 -> 0 | N20: 4000 | O20: =H20+I20-J20+K20+L20+M20+N20 -> 116250 | P20: =O20+O20*4% -> 120900 | Q20: =P20*2% + P20 -> 123318
A21: 13 | B21: 7A | C21: Gandulfo, Patricia | E21: 0.0449 | F21: 83172.205 | G21: =89196.18-G36 -> 86602.822 | H21: =IF(F21>G21,F21-G21,0) -> 0 | I21: =H21*3% -> 0 | J21: =IF(G21>F21,G21-F21,0) -> 3430.6174 | L21: =B$5*E21 -> 112250 | M21: =E$5*E21 -> 0 | O21: =H21+I21-J21+K21+L21+M21+N21 -> 108819.38 | P21: =O21+O21*4% -> 113172.16 | Q21: =P21*2% + P21 -> 115435.6
A22: 14 | B22: 7B | C22: Garófalo, Marta | E22: 0.0449 | F22: 83139.524 | G22: =F22 -> 83139.524 | H22: =IF(F22>G22,F22-G22,0) -> 0 | I22: =H22*3% -> 0 | J22: =IF(G22>F22,G22-F22,0) -> 0 | L22: =B$5*E22 -> 112250 | M22: =E$5*E22 -> 0 | O22: =H22+I22-J22+K22+L22+M22+N22 -> 112250 | P22: =O22+O22*4% -> 116740 | Q22: =P22*2% + P22 -> 119074.8
A23: 15 | B23: 8A | C23: Veiga Pablo | D23: Vanesa | E23: 0.0449 | F23: 83172.683 | G23: =F23 -> 83172.683 | H23: =IF(F23>G23,F23-G23,0) -> 0 | I23: =H23*3% -> 0 | J23: =IF(G23>F23,G23-F23,0) -> 0 | L23: =B$5*E23 -> 112250 | M23: =E$5*E23 -> 0 | O23: =H23+I23-J23+K23+L23+M23+N23 -> 112250 | P23: =O23+O23*4% -> 116740 | Q23: =P23*2% + P23 -> 119074.8
A24: 16 | B24: 8B | C24: Tarrico Nicolas | E24: 0.0449 | F24: 86499 | G24: 86500 | H24: =IF(F24>G24,F24-G24,0) -> 0 | I24: =H24*3% -> 0 | J24: =IF(G24>F24,G24-F24,0) -> 1 | L24: =B$5*E24 -> 112250 | M24: =E$5*E24 -> 0 | O24: =H24+I24-J24+K24+L24+M24+N24 -> 112249 | P24: =O24+O24*4% -> 116738.96 | Q24: =P24*2% + P24 -> 119073.74
A25: 17 | B25: 9A | C25: Reines, Juan Cruz | E25: 0.0449 | F25: 83172.683 | G25: =86500 -> 86500 | H25: =IF(F25>G25,F25-G25,0) -> 0 | I25: =H25*3% -> 0 | J25: =IF(G25>F25,G25-F25,0) -> 3327.3168 | L25: =B$5*E25 -> 112250 | M25: =E$5*E25 -> 0 | N25: 4000 | O25: =H25+I25-J25+K25+L25+M25+N25 -> 112922.68 | P25: =O25+O25*4% -> 117439.59 | Q25: =P25*2% + P25 -> 119788.38
A26: 18 | B26: 9B | C26: Cristaldo, Eduardo | E26: 0.0449 | F26: 83172.683 | H26: =IF(F26>G26,F26-G26,0) -> 83172.683 | I26: =H26*3% -> 2495.1805 | J26: =IF(G26>F26,G26-F26,0) -> 0 | L26: =B$5*E26 -> 112250 | M26: =E$5*E26 -> 0 | O26: =H26+I26-J26+K26+L26+M26+N26 -> 197917.86 | P26: =O26+O26*4% -> 205834.58 | Q26: =P26*2% + P26 -> 209951.27
A27: 19 | B27: 10A | C27: Bruno, Mario | D27: Neyen | E27: 0.0449 | F27: 83172.683 | G27: =85385.8-G40 -> 83172.682 | H27: =IF(F27>G27,F27-G27,0) -> 0.000998 | I27: =H27*3% -> 2.994e-05 | J27: =IF(G27>F27,G27-F27,0) -> 0 | L27: =B$5*E27 -> 112250 | M27: =E$5*E27 -> 0 | O27: =H27+I27-J27+K27+L27+M27+N27 -> 112250 | P27: =O27+O27*4% -> 116740 | Q27: =P27*2% + P27 -> 119074.8
A28: 20 | B28: 10B | C28: Pistone, Sergio | D28: Julieta ochoa | E28: 0.0449 | F28: 186224.53 | G28: =87172-G37 -> 81896.011 | H28: =IF(F28>G28,F28-G28,0) -> 104328.52 | I28: =H28*3% -> 3129.8555 | J28: =IF(G28>F28,G28-F28,0) -> 0 | L28: =B$5*E28 -> 112250 | M28: =E$5*E28 -> 0 | O28: =H28+I28-J28+K28+L28+M28+N28 -> 219708.37 | P28: =O28+O28*4% -> 228496.71 | Q28: =P28*2% + P28 -> 233066.64
A29: 21 | B29: 11A | C29: Alarcon Ester | E29: 0.0449 | F29: 83172.683 | G29: 86500 | H29: =IF(F29>G29,F29-G29,0) -> 0 | I29: =H29*3% -> 0 | J29: =IF(G29>F29,G29-F29,0) -> 3327.3168 | L29: =B$5*E29 -> 112250 | M29: =E$5*E29 -> 0 | O29: =H29+I29-J29+K29+L29+M29+N29 -> 108922.68 | P29: =O29+O29*4% -> 113279.59 | Q29: =P29*2% + P29 -> 115545.18
A30: 22 | B30: 11B | C30: Italiano Gabriel Cristian | E30: 0.0449 | F30: 274202.31 | H30: =IF(F30>G30,F30-G30,0) -> 274202.31 | I30: =H30*3% -> 8226.0693 | J30: =IF(G30>F30,G30-F30,0) -> 0 | L30: =B$5*E30 -> 112250 | M30: =E$5*E30 -> 0 | O30: =H30+I30-J30+K30+L30+M30+N30 -> 394678.38 | P30: =O30+O30*4% -> 410465.52 | Q30: =P30*2% + P30 -> 418674.83
F31: 0 | M31: =E$5*E31 -> 0 | O31: =H31+I31-J31+K31+L31+M31+N31 -> 0 | P31: =O31+O31*4% -> 0
A32: 23 | B32: C1 | C32: =C30 -> Italiano Gabriel Cristian | E32: 0.0014 | F32: 8549.738 | H32: =IF(F32>G32,F32-G32,0) -> 8549.738 | I32: =H32*3% -> 256.49214 | J32: =IF(G32>F32,G32-F32,0) -> 0 | L32: =B$5*E32 -> 3500 | M32: =E$5*E32 -> 0 | O32: =H32+I32-J32+K32+L32+M32+N32 -> 12306.23 | P32: =O32+O32*4% -> 12798.479 | Q32: =P32*2% + P32 -> 13054.449
A33: 24 | B33: C2 | C33: Martinez Yasnikowski, Fernando | E33: 0.0014 | F33: 2593.3576 | H33: =IF(F33>G33,F33-G33,0) -> 2593.3576 | I33: =H33*3% -> 77.800728 | J33: =IF(G33>F33,G33-F33,0) -> 0 | L33: =B$5*E33 -> 3500 | M33: =E$5*E33 -> 0 | O33: =H33+I33-J33+K33+L33+M33+N33 -> 6171.1583 | P33: =O33+O33*4% -> 6418.0047 | Q33: =P33*2% + P33 -> 6546.3648
A34: =A33+1 -> 25 | B34: C3 | C34: Cristaldo, Eduardo | E34: 0.0014 | F34: 2593.3576 | H34: =IF(F34>G34,F34-G34,0) -> 2593.3576 | I34: =H34*3% -> 77.800728 | J34: =IF(G34>F34,G34-F34,0) -> 0 | L34: =B$5*E34 -> 3500 | M34: =E$5*E34 -> 0 | O34: =H34+I34-J34+K34+L34+M34+N34 -> 6171.1583 | P34: =O34+O34*4% -> 6418.0047 | Q34: =P34*2% + P34 -> 6546.3648
A35: =A34+1 -> 26 | B35: C4 | C35: Arias, Juan Jose | E35: 0.0014 | F35: 2593.3576 | G35: =F35 -> 2593.3576 | H35: =IF(F35>G35,F35-G35,0) -> 0 | I35: =H35*3% -> 0 | J35: =IF(G35>F35,G35-F35,0) -> 0 | L35: =B$5*E35 -> 3500 | M35: =E$5*E35 -> 0 | O35: =H35+I35-J35+K35+L35+M35+N35 -> 3500 | P35: =O35+O35*4% -> 3640 | Q35: =P35*2% + P35 -> 3712.8
A36: =A35+1 -> 27 | B36: C5 | C36: Gandulfo, Patricia | E36: 0.0014 | F36: 2593.3576 | G36: =F36 -> 2593.3576 | H36: =IF(F36>G36,F36-G36,0) -> 0 | I36: =H36*3% -> 0 | J36: =IF(G36>F36,G36-F36,0) -> 0 | L36: =B$5*E36 -> 3500 | M36: =E$5*E36 -> 0 | O36: =H36+I36-J36+K36+L36+M36+N36 -> 3500 | P36: =O36+O36*4% -> 3640 | Q36: =P36*2% + P36 -> 3712.8
A37: =A36+1 -> 28 | B37: C6 | C37: Pistone, Sergio | E37: 0.0013 | F37: 5275.9886 | G37: =F37 -> 5275.9886 | H37: =IF(F37>G37,F37-G37,0) -> 0 | I37: =H37*3% -> 0 | J37: =IF(G37>F37,G37-F37,0) -> 0 | L37: =B$5*E37 -> 3250 | M37: =E$5*E37 -> 0 | O37: =H37+I37-J37+K37+L37+M37+N37 -> 3250 | P37: =O37+O37*4% -> 3380 | Q37: =P37*2% + P37 -> 3447.6
A38: =A37+1 -> 29 | B38: C7 | C38: Dangelo Salvador Luis | E38: 0.0013 | F38: 2408.1178 | G38: =F38 -> 2408.1178 | H38: =IF(F38>G38,F38-G38,0) -> 0 | I38: =H38*3% -> 0 | J38: =IF(G38>F38,G38-F38,0) -> 0 | L38: =B$5*E38 -> 3250 | M38: =E$5*E38 -> 0 | O38: =H38+I38-J38+K38+L38+M38+N38 -> 3250 | P38: =O38+O38*4% -> 3380 | Q38: =P38*2% + P38 -> 3447.6
A39: =A38+1 -> 30 | B39: C8 | C39: Bruno, Mario | D39: Gaston Alvarez | E39: 0.0013 | F39: 2408.1178 | G39: =F39 -> 2408.1178 | H39: =IF(F39>G39,F39-G39,0) -> 0 | I39: =H39*3% -> 0 | J39: =IF(G39>F39,G39-F39,0) -> 0 | L39: =B$5*E39 -> 3250 | M39: =E$5*E39 -> 0 | O39: =H39+I39-J39+K39+L39+M39+N39 -> 3250 | P39: =O39+O39*4% -> 3380 | Q39: =P39*2% + P39 -> 3447.6
A40: =A39+1 -> 31 | B40: C9 | C40: Bruno, Mario | D40: Neyen | E40: 0.0013 | F40: 2213.1178 | G40: =F40-'Planilla Extraord'!G40 -> 2213.1178 | H40: =IF(F40>G40,F40-G40,0) -> 0 | I40: =H40*3% -> 0 | J40: =IF(G40>F40,G40-F40,0) -> 0 | L40: =B$5*E40 -> 3250 | M40: =E$5*E40 -> 0 | O40: =H40+I40-J40+K40+L40+M40+N40 -> 3250 | P40: =O40+O40*4% -> 3380 | Q40: =P40*2% + P40 -> 3447.6
A41: =A40+1 -> 32 | P41: =H41+I41-J41+K41+L41+M41+N41 -> 0
A42: =A41+1 -> 33 | P42: =H42+I42-J42+K42+L42+M42+N42 -> 0
...

Sheet Planilla Extraord
B1: =Gastos!C8 -> PERIODO: MAYO
C2: 1142000
C3: 1430994.6 | F3: PLANILLA EXTRAORDINARIA
E5: 0
B6: EXTRAORDINARIOS:
A8: U.F. | B8: PISO - DEPTO | C8: PROPIETARIOS | D8: INQUILINOS | E8: % | F8: SALDO ANTERIOR | G8: SALDO ACTUAL | H8: DEUDA | I8: INTERES por MORA 3% | J8: SALDO A FAVOR | L8: GASTOS ORDINARIOS | M8: GASTOS EXTR. | N8: SUM | O8: 1 ER VTO. | P8: 2DO VTO.
A9: 1 | B9: 1A | C9: Gaffuri Daniel | E9: 0.0449 | F9: 0 | G9: =F9 -> 0 | H9: =IF(F9>G9,F9-G9,0) -> 0 | I9: =H9*3% -> 0 | J9: =IF(G9>F9,G9-F9,0) -> 0 | L9: =B$5*E9 -> 0 | M9: =B$7*E9 -> 0 | O9: =H9+I9-J9+K9+L9+M9+N9 -> 0 | P9: =O9*2% + O9 -> 0
A10: 2 | B10: 1B | C10: Benvenutto, Irene | E10: 0.0449 | F10: 0 | G10: =F10 -> 0 | H10: =IF(F10>G10,F10-G10,0) -> 0 | I10: =H10*3% -> 0 | J10: =IF(G10>F10,G10-F10,0) -> 0 | L10: =B$5*E10 -> 0 | M10: =B$7*E10 -> 0 | O10: =H10+I10-J10+K10+L10+M10+N10 -> 0 | P10: =O10*2% + O10 -> 0
A11: 3 | B11: 2A | C11: Sanchez Marcelo | E11: 0.0449 | F11: 0 | G11: =F11 -> 0 | H11: =IF(F11>G11,F11-G11,0) -> 0 | I11: =H11*3% -> 0 | J11: =IF(G11>F11,G11-F11,0) -> 0 | L11: =B$5*E11 -> 0 | M11: =B$7*E11 -> 0 | O11: =H11+I11-J11+K11+L11+M11+N11 -> 0 | P11: =O11*2% + O11 -> 0
A12: 4 | B12: 2B | C12: Zeballos, Maria Eugenia | D12: Nicolas | E12: 0.0449 | F12: 0 | G12: =F12 -> 0 | H12: =IF(F12>G12,F12-G12,0) -> 0 | I12: =H12*3% -> 0 | J12: =IF(G12>F12,G12-F12,0) -> 0 | L12: =B$5*E12 -> 0 | M12: =B$7*E12 -> 0 | O12: =H12+I12-J12+K12+L12+M12+N12 -> 0 | P12: =O12*2% + O12 -> 0
A13: 5 | B13: 3A | C13: Vicente, Flavia E | E13: 0.0449 | F13: 0 | G13: =F13 -> 0 | H13: =IF(F13>G13,F13-G13,0) -> 0 | I13: =H13*3% -> 0 | J13: =IF(G13>F13,G13-F13,0) -> 0 | L13: =B$5*E13 -> 0 | M13: =B$7*E13 -> 0 | O13: =H13+I13-J13+K13+L13+M13+N13 -> 0 | P13: =O13*2% + O13 -> 0
A14: 6 | B14: 3B | C14: Martinez Yasnikowski, Fernando | E14: 0.0449 | H14: =IF(F14>G14,F14-G14,0) -> 0 | I14: =H14*3% -> 0 | J14: =IF(G14>F14,G14-F14,0) -> 0 | L14: =B$5*E14 -> 0 | M14: =B$7*E14 -> 0 | O14: =H14+I14-J14+K14+L14+M14+N14 -> 0 | P14: =O14*2% + O14 -> 0
A15: 7 | B15: 4A | C15: Arias Juan Jose | E15: 0.0449 | F15: 0 | G15: =F15 -> 0 | H15: =IF(F15>G15,F15-G15,0) -> 0 | I15: =H15*3% -> 0 | J15: =IF(G15>F15,G15-F15,0) -> 0 | L15: =B$5*E15 -> 0 | M15: =B$7*E15 -> 0 | O15: =H15+I15-J15+K15+L15+M15+N15 -> 0 | P15: =O15*2% + O15 -> 0
A16: 8 | B16: 4B | C16: Dangelo Salvador Luis | E16: 0.0449 | F16: 0 | G16: =F16 -> 0 | H16: =IF(F16>G16,F16-G16,0) -> 0 | I16: =H16*3% -> 0 | J16: =IF(G16>F16,G16-F16,0) -> 0 | L16: =B$5*E16 -> 0 | M16: =B$7*E16 -> 0 | O16: =H16+I16-J16+K16+L16+M16+N16 -> 0 | P16: =O16*2% + O16 -> 0
A17: 9 | B17: 5A | C17: Fabiana Sambartolomeo | E17: 0.0449 | F17: 0 | G17: =F17 -> 0 | H17: =IF(F17>G17,F17-G17,0) -> 0 | I17: =H17*3% -> 0 | J17: =IF(G17>F17,G17-F17,0) -> 0 | L17: =B$5*E17 -> 0 | M17: =B$7*E17 -> 0 | O17: =H17+I17-J17+K17+L17+M17+N17 -> 0 | P17: =O17*2% + O17 -> 0
A18: 10 | B18: 5B | C18: =Planilla!C18 -> Palacios, Lia | D18: Candela | E18: 0.0449 | F18: 0 | G18: =F18 -> 0 | H18: =IF(F18>G18,F18-G18,0) -> 0 | I18: =H18*3% -> 0 | J18: =IF(G18>F18,G18-F18,0) -> 0 | L18: =B$5*E18 -> 0 | M18: =B$7*E18 -> 0 | O18: =H18+I18-J18+K18+L18+M18+N18 -> 0 | P18: =O18*2% + O18 -> 0
A19: 11 | B19: 6A | C19: Matta, Belén | E19: 0.0449 | F19: 0 | G19: =F19 -> 0 | H19: =IF(F19>G19,F19-G19,0) -> 0 | I19: =H19*3% -> 0 | J19: =IF(G19>F19,G19-F19,0) -> 0 | L19: =B$5*E19 -> 0 | M19: =B$7*E19 -> 0 | O19: =H19+I19-J19+K19+L19+M19+N19 -> 0 | P19: =O19*2% + O19 -> 0
A20: 12 | B20: 6B | C20: Bruno, Mario | D20: Gaston | E20: 0.0449 | F20: 0 | G20: =F20 -> 0 | H20: =IF(F20>G20,F20-G20,0) -> 0 | I20: =H20*3% -> 0 | J20: =IF(G20>F20,G20-F20,0) -> 0 | L20: =B$5*E20 -> 0 | M20: =B$7*E20 -> 0 | O20: =H20+I20-J20+K20+L20+M20+N20 -> 0 | P20: =O20*2% + O20 -> 0
A21: 13 | B21: 7A | C21: Gandulfo, Patricia | E21: 0.0449 | F21: 0 | G21: =F21 -> 0 | H21: =IF(F21>G21,F21-G21,0) -> 0 | I21: =H21*3% -> 0 | J21: =IF(G21>F21,G21-F21,0) -> 0 | L21: =B$5*E21 -> 0 | M21: =B$7*E21 -> 0 | O21: =H21+I21-J21+K21+L21+M21+N21 -> 0 | P21: =O21*2% + O21 -> 0
A22: 14 | B22: 7B | C22: Garófalo, Marta | E22: 0.0449 | F22: 0 | G22: =F22 -> 0 | H22: =IF(F22>G22,F22-G22,0) -> 0 | I22: =H22*3% -> 0 | J22: =IF(G22>F22,G22-F22,0) -> 0 | L22: =B$5*E22 -> 0 | M22: =B$7*E22 -> 0 | O22: =H22+I22-J22+K22+L22+M22+N22 -> 0 | P22: =O22*2% + O22 -> 0
A23: 15 | B23: 8A | C23: Veiga Pablo | D23: Vanesa | E23: 0.0449 | F23: 0 | G23: =F23 -> 0 | H23: =IF(F23>G23,F23-G23,0) -> 0 | I23: =H23*3% -> 0 | J23: =IF(G23>F23,G23-F23,0) -> 0 | L23: =B$5*E23 -> 0 | M23: =B$7*E23 -> 0 | O23: =H23+I23-J23+K23+L23+M23+N23 -> 0 | P23: =O23*2% + O23 -> 0
A24: 16 | B24: 8B | C24: Tarrico Nicolas | E24: 0.0449 | F24: 0 | G24: =F24 -> 0 | H24: =IF(F24>G24,F24-G24,0) -> 0 | I24: =H24*3% -> 0 | J24: =IF(G24>F24,G24-F24,0) -> 0 | L24: =B$5*E24 -> 0 | M24: =B$7*E24 -> 0 | O24: =H24+I24-J24+K24+L24+M24+N24 -> 0 | P24: =O24*2% + O24 -> 0
A25: 17 | B25: 9A | C25: Reines, Juan Cruz | E25: 0.0449 | F25: 0 | G25: =F25 -> 0 | H25: =IF(F25>G25,F25-G25,0) -> 0 | I25: =H25*3% -> 0 | J25: =IF(G25>F25,G25-F25,0) -> 0 | L25: =B$5*E25 -> 0 | M25: =B$7*E25 -> 0 | O25: =H25+I25-J25+K25+L25+M25+N25 -> 0 | P25: =O25*2% + O25 -> 0
A26: 18 | B26: 9B | C26: Cristaldo, Eduardo | E26: 0.0449 | F26: 0 | G26: =F26 -> 0 | H26: =IF(F26>G26,F26-G26,0) -> 0 | I26: =H26*3% -> 0 | J26: =IF(G26>F26,G26-F26,0) -> 0 | L26: =B$5*E26 -> 0 | M26: =B$7*E26 -> 0 | O26: =H26+I26-J26+K26+L26+M26+N26 -> 0 | P26: =O26*2% + O26 -> 0
A27: 19 | B27: 10A | C27: Bruno, Mario | D27: Neyen | E27: 0.0449 | F27: 0 | G27: =F27 -> 0 | H27: =IF(F27>G27,F27-G27,0) -> 0 | I27: =H27*3% -> 0 | J27: =IF(G27>F27,G27-F27,0) -> 0 | L27: =B$5*E27 -> 0 | M27: =B$7*E27 -> 0 | O27: =H27+I27-J27+K27+L27+M27+N27 -> 0 | P27: =O27*2% + O27 -> 0
A28: 20 | B28: 10B | C28: Pistone, Sergio | E28: 0.0449 | F28: 0 | G28: =F28 -> 0 | H28: =IF(F28>G28,F28-G28,0) -> 0 | I28: =H28*3% -> 0 | J28: =IF(G28>F28,G28-F28,0) -> 0 | L28: =B$5*E28 -> 0 | M28: =B$7*E28 -> 0 | O28: =H28+I28-J28+K28+L28+M28+N28 -> 0 | P28: =O28*2% + O28 -> 0
A29: 21 | B29: 11A | C29: Alarcon Ester | E29: 0.0449 | F29: 0 | G29: =F29 -> 0 | H29: =IF(F29>G29,F29-G29,0) -> 0 | I29: =H29*3% -> 0 | J29: =IF(G29>F29,G29-F29,0) -> 0 | L29: =B$5*E29 -> 0 | M29: =B$7*E29 -> 0 | O29: =H29+I29-J29+K29+L29+M29+N29 -> 0 | P29: =O29*2% + O29 -> 0
A30: 22 | B30: 11B | C30: Daniel Vidal | E30: 0.0449 | F30: 0 | G30: =F30 -> 0 | H30: =IF(F30>G30,F30-G30,0) -> 0 | I30: =H30*3% -> 0 | J30: =IF(G30>F30,G30-F30,0) -> 0 | L30: =B$5*E30 -> 0 | M30: =B$7*E30 -> 0 | O30: =H30+I30-J30+K30+L30+M30+N30 -> 0 | P30: =O30*2% + O30 -> 0
F31: 0 | O31: =H31+I31-J31+K31+L31+M31+N31 -> 0
A32: 23 | B32: C1 | C32: Daniel Vidal | E32: 0.0014 | F32: 0 | G32: =F32 -> 0 | H32: =IF(F32>G32,F32-G32,0) -> 0 | I32: =H32*3% -> 0 | J32: =IF(G32>F32,G32-F32,0) -> 0 | L32: =B$5*E32 -> 0 | M32: =B$7*E32 -> 0 | O32: =H32+I32-J32+K32+L32+M32+N32 -> 0 | P32: =O32*2% + O32 -> 0
A33: 24 | B33: C2 | C33: Martinez Yasnikowski, Fernando | E33: 0.0014 | H33: =IF(F33>G33,F33-G33,0) -> 0 | I33: =H33*3% -> 0 | J33: =IF(G33>F33,G33-F33,0) -> 0 | L33: =B$5*E33 -> 0 | M33: =B$7*E33 -> 0 | O33: =H33+I33-J33+K33+L33+M33+N33 -> 0 | P33: =O33*2% + O33 -> 0
A34: =A33+1 -> 25 | B34: C3 | C34: Cristaldo, Eduardo | E34: 0.0014 | F34: 0 | G34: =F34 -> 0 | H34: =IF(F34>G34,F34-G34,0) -> 0 | I34: =H34*3% -> 0 | J34: =IF(G34>F34,G34-F34,0) -> 0 | L34: =B$5*E34 -> 0 | M34: =B$7*E34 -> 0 | O34: =H34+I34-J34+K34+L34+M34+N34 -> 0 | P34: =O34*2% + O34 -> 0
A35: =A34+1 -> 26 | B35: C4 | C35: Arias, Juan Jose | E35: 0.0014 | F35: 0 | G35: =F35 -> 0 | H35: =IF(F35>G35,F35-G35,0) -> 0 | I35: =H35*3% -> 0 | J35: =IF(G35>F35,G35-F35,0) -> 0 | L35: =B$5*E35 -> 0 | M35: =B$7*E35 -> 0 | O35: =H35+I35-J35+K35+L35+M35+N35 -> 0 | P35: =O35*2% + O35 -> 0
A36: =A35+1 -> 27 | B36: C5 | C36: Gandulfo, Patricia | E36: 0.0014 | F36: 0 | G36: =F36 -> 0 | H36: =IF(F36>G36,F36-G36,0) -> 0 | I36: =H36*3% -> 0 | J36: =IF(G36>F36,G36-F36,0) -> 0 | L36: =B$5*E36 -> 0 | M36: =B$7*E36 -> 0 | O36: =H36+I36-J36+K36+L36+M36+N36 -> 0 | P36: =O36*2% + O36 -> 0
A37: =A36+1 -> 28 | B37: C6 | C37: Pistone, Sergio | E37: 0.0013 | F37: 0 | G37: =F37 -> 0 | H37: =IF(F37>G37,F37-G37,0) -> 0 | I37: =H37*3% -> 0 | J37: =IF(G37>F37,G37-F37,0) -> 0 | L37: =B$5*E37 -> 0 | M37: =B$7*E37 -> 0 | O37: =H37+I37-J37+K37+L37+M37+N37 -> 0 | P37: =O37*2% + O37 -> 0
A38: =A37+1 -> 29 | B38: C7 | C38: Dangelo Salvador Luis | E38: 0.0013 | F38: 0 | G38: =F38 -> 0 | H38: =IF(F38>G38,F38-G38,0) -> 0 | I38: =H38*3% -> 0 | J38: =IF(G38>F38,G38-F38,0) -> 0 | L38: =B$5*E38 -> 0 | M38: =B$7*E38 -> 0 | O38: =H38+I38-J38+K38+L38+M38+N38 -> 0 | P38: =O38*2% + O38 -> 0
A39: =A38+1 -> 30 | B39: C8 | C39: Bruno, Mario | D39: Gaston | E39: 0.0013 | F39: 0 | G39: =F39 -> 0 | H39: =IF(F39>G39,F39-G39,0) -> 0 | I39: =H39*3% -> 0 | J39: =IF(G39>F39,G39-F39,0) -> 0 | L39: =B$5*E39 -> 0 | M39: =B$7*E39 -> 0 | O39: =H39+I39-J39+K39+L39+M39+N39 -> 0 | P39: =O39*2% + O39 -> 0
A40: =A39+1 -> 31 | B40: C9 | C40: Bruno, Mario | D40: Neyen | E40: 0.0013 | F40: 0 | G40: =F40 -> 0 | H40: =IF(F40>G40,F40-G40,0) -> 0 | I40: =H40*3% -> 0 | J40: =IF(G40>F40,G40-F40,0) -> 0 | L40: =B$5*E40 -> 0 | M40: =B$7*E40 -> 0 | O40: =H40+I40-J40+K40+L40+M40+N40 -> 0 | P40: =O40*2% + O40 -> 0
A41: =A40+1 -> 32 | F41: 0 | O41: =H41+I41-J41+K41+L41+M41+N41 -> 0
A42: =A41+1 -> 33 | O42: =H42+I42-J42+K42+L42+M42+N42 -> 0
...

Sheet recibo
C5: RECIBO DE EXPENSAS
C6: =Gastos!A9 -> CONSORCIO: ADMINISTRACION DE CONSORCIOS RC
H7: PERIODO: OCTUBRE
C8: Adminstradora: Carolina Canciani | H8: VENCIMIENTO: NOVIEMBRE
C10: Metodo de pago: Efectivo
C12: Nombre y apellido: | E12: =Planilla!C29 -> Alarcon Ester | G12: Fecha: | H12: 45616 | J12: Sello o firma autoriada:
C13: UF: | D13: =Planilla!B29 -> 11A
C18: Total recibido: | H18: 78000
C20: RECIBO DE EXPENSAS
C21: CONSORCIO: ADMINISTRACION DE CONSORCIOS RC
H22: PERIODO: OCTUBRE
C23: Adminstradora: Carolina Canciani | H23: VENCIMIENTO: NOVIEMBRE
C25: Metodo de pago: Efectivo
C27: Nombre y apellido: | E27: =Planilla!C21 -> Gandulfo, Patricia | G27: Fecha: | H27: 45616 | J27: Sello o firma autoriada:
C28: UF: | D28: =Planilla!B21 -> 7A
C33: Total recibido: | H33: 73210
C35: RECIBO DE EXPENSAS
C36: CONSORCIO: ADMINISTRACION DE CONSORCIOS RC
H37: PERIODO: OCTUBRE
C38: Adminstradora: Carolina Canciani | H38: VENCIMIENTO: NOVIEMBRE
C40: Metodo de pago: Efectivo
C42: Nombre y apellido: | E42: =Planilla!C13 -> Vicente, Flavia E | G42: Fecha: | H42: 45616 | J42: Sello o firma autoriada:
C43: UF: | D43: =Planilla!B13 -> 3A
C48: Total recibido: | H48: 66370
C52: RECIBO DE EXPENSAS
C53: CONSORCIO: ADMINISTRACION DE CONSORCIOS RC
H54: PERIODO: OCTUBRE
C55: Adminstradora: Carolina Canciani | H55: VENCIMIENTO: NOVIEMBRE
C57: Metodo de pago: Efectivo
C59: Nombre y apellido: | E59: =Planilla!D20 -> Gaston Alvarez | G59: Fecha: | H59: 45616 | J59: Sello o firma autoriada:
C60: UF: | D60: =Planilla!B20 -> 6B
C65: Total recibido: | H65: 76000
E68: EXPENSAS ORDINARIAS Y EXTRAORDINARIAS (RECIBO VEIGA)
C70: RECIBO DE EXPENSAS
C71: CONSORCIO: ADMINISTRACION DE CONSORCIOS RC
H72: PERIODO: OCTUBRE
C73: Adminstradora: Carolina Canciani | H73: VENCIMIENTO: NOVIEMBRE
C75: EXPENSAS ORDINARIAS
C77: Nombre y apellido: | E77: =Planilla!C23 -> Veiga Pablo | G77: Fecha: | H77: 45624 | J77: Sello o firma autoriada:
C78: UF: | D78: =Planilla!B23 -> 8A
...
