Workbook
Name CantOper: #REF!
Name CantOper: #REF!
Name PaseMateriales: #REF!
Name PaseMateriales: #REF!
Name PaseMdeO: #REF!
Name PaseMdeO: #REF!
Name PaseSubcontratos: #REF!
Name PaseSubcontratos: #REF!
Name Plazo: #REF!
Name Plazo: #REF!

Sheet Gastos
D2: Domicilio: | E2: TUCUMAN 1061
D3: Cel. | E3: 1153202676
D4: e-mail: | E4: tucuman1061rc@gmail.com
D5: MP:1148
A7: LIQUIDACION DE EXPENSAS | E7: PERIODO: FEBRERO
A10: Domicilio: | B10: ROSALES 624
A12: 1- SERVICIO DE LIMPIEZA Y JARDINERIA
A14: SUELDO | B14: Sr. Encargado Hernan | H14: 373590.5
A16: Total: | H16: =SUM(H13:H15) -> 373590.5
A18: 2- SERVICIO PUBLICIO
A19: AYSA | H19: 164649.06
A20: Edesur | H20: 383278.85
A23: Total Servicios publicos: | H23: =SUM(H19:H22) -> 547927.91
A24: 3- IMPUESTOS MUNICIPALES Y PROVINCIALES
A25: ARBA | H25: 0
A26: TSG ENERO 2024 | H26: 0
A27: Total: | H27: =SUM(H25:H26) -> 0
A28: 3- MANTENIMIENTO DE PARTES COMUNES
A29: Arituclos de limpieza | H29: 75800
A30: Seguro OBLIGATORIO DE CONSORCIO - POLIZA Nro. 1175840 - Mercantil Andina | H30: 39308
A31: Lema mantenimiento ascensores | H31: 65000
A32: Total mantenimiento: | H32: =SUM(H29:H31) -> 180108
A33: 4- GASTO DE ADMINISTRACION
A34: Nombre y Apellido: | C34: Carolina Canciani
A35: Administraciòn FEBRERO 2025: | H35: =51243.5+5124.35 -> 56367.85 | N35: subidos en dic 2024
A37: 5- SEGURO OBLIGATORIO
A39: TOTAL DE GASTOS ORDINARIOS 1,2,3,4,5,6; | H39: =H16+H23+H27+H32+H35+H38 -> 1157994.3
A40: Prevision ordinaria | H40: 842005.74
A41: GASTOS EXTRAORDINARIOS
A46: TOTAL | H46: =SUM(H43:H45) -> 0
A49: TOTAL DE GASTOS ORDINARIOS A PRORRATEAR | H49: =+H39+H40 -> 2000000
A50: ANTE LOS DEUDORES SE PREVISIONA PARA PODER HACER FRENTE AL SELLADO DE LAS MEDIANERAS
A52: TOTAL DE GASTOS EXTRAORDINARIO | H52: =H46 -> 0
A54: ESTADO FINANCIERO
A55: SALDO ANTERIOR | H55: -12027.49
A56: Ingreso pago por expensas | H56: =Planilla!I32 -> 1356852.3
A57: Punitorios mal cobrados
A58: Egresos gastos del mes | H58: =-(H39+H46) -> -1157994.3
A59: Saldo al cierre | H59: =SUM(H55:H58) -> 186830.52

Sheet Planilla
A1: =Gastos!E7 -> PERIODO: FEBRERO
C5: 2000000
C6: Gastos Ordinarios:
C7: =C5 -> 2000000
B8: Gastos Extr. | C8: 0
C9: Gastos Extraordinarios:
A11: U.F. | B11: PISO - DEPTO | C11: PROPIETARIOS | D11: PROPIETARIOS | E11: INQUILINOS | F11: % | G11: SALDO ANTERIOR | H11: PAGO EXTRA | I11: PAGOS | J11: EDESUR | K11: DEUDA | L11: DEUDA Extra | M11: Mora | N11: Total con Mora | O11: Gasto Ordinario | P11: Gasto Extraordinario | Q11: EDESUR | R11: Total a Pagar
A12: 1a | C12: 1ro. "A" | D12: Juan Pablo Rodriguez/ Valeria Ruggiero | E12: Cristian | F12: 7.9 | G12: 248228.93 | H12: 0 | I12: 174000 | J12: =C9*F12/100 -> #VALUE! | K12: =G12-H12-I12 -> 74228.934 | M12: =(K12+L12)*3% -> 2226.868 | N12: =K12+M12+L12 -> 76455.802 | O12: =C$7*F12/100 -> 158000 | P12: =C$10*F12/100 -> 0 | Q12: ='Calculo Servicios (2)'!H9 -> 0 | R12: =O12+N12+P12+Q12 -> 234455.8 | U12: 1ro. "A"
A13: 1b | C13: 1ro. "B" | D13: Mendez Juan Carlos | F13: 7.9 | G13: 132911.43 | H13: 0 | J13: =C9*F13/100 -> #VALUE! | K13: =G13-H13-I13 -> 132911.43 | M13: =(K13+L13)*3% -> 3987.343 | N13: =K13+M13+L13 -> 136898.78 | O13: =C$7*F13/100 -> 158000 | P13: =C$10*F13/100 -> 0 | Q13: ='Calculo Servicios (2)'!H10 -> 0 | R13: =O13+N13+P13+Q13 -> 294898.78 | U13: 1ro. "B"
A14: 2a | C14: 2do. "A" | D14: Matias Ezequiel Bonfiglio | E14: Maria Elena | F14: 7.9 | G14: 261931.42 | H14: 0 | I14: 79475.21 | J14: =C9*F14/100 -> #VALUE! | K14: =G14-H14-I14 -> 182456.21 | M14: =(K14+L14)*3% -> 5473.6863 | N14: =K14+M14+L14 -> 187929.9 | O14: =C$7*F14/100 -> 158000 | P14: =C$10*F14/100 -> 0 | Q14: ='Calculo Servicios (2)'!H11 -> 0 | R14: =O14+N14+P14+Q14 -> 345929.9 | U14: 2do. "A"
A15: 2b | C15: 2do. "B" | D15: Garcia Milano Maximiliano Gaston | F15: 7.9 | G15: 132911.43 | I15: =G15+100 -> 133011.43 | J15: =C9*F15/100 -> #VALUE! | K15: =G15-H15-I15 -> -100 | M15: =(K15+L15)*3% -> -3 | N15: =K15+M15+L15 -> -103 | O15: =C$7*F15/100 -> 158000 | P15: =C$10*F15/100 -> 0 | Q15: ='Calculo Servicios (2)'!H12 -> 0 | R15: =O15+N15+P15+Q15 -> 157897 | U15: 2do. "B"
A16: 3a | C16: 3ro. "A" | D16: Cecilia Mariel Cassettari | F16: 7.9 | G16: 132911.43 | H16: 0 | I16: =G16 -> 132911.43 | J16: =C9*F16/100 -> #VALUE! | K16: =G16-H16-I16 -> 0 | M16: =(K16+L16)*3% -> 0 | N16: =K16+M16+L16 -> 0 | O16: =C$7*F16/100 -> 158000 | P16: =C$10*F16/100 -> 0 | Q16: ='Calculo Servicios (2)'!H13 -> 0 | R16: =O16+N16+P16+Q16 -> 158000 | U16: 3ro. "A"
A17: 3b | C17: 3ro. "B" | D17: Grandinetti Leonardo Alberto | E17: Marcos | F17: 7.9 | G17: 132911.43 | H17: 0 | J17: =C9*F17/100 -> #VALUE! | K17: =G17-H17-I17 -> 132911.43 | M17: =(K17+L17)*3% -> 3987.343 | N17: =K17+M17+L17 -> 136898.78 | O17: =C$7*F17/100 -> 158000 | P17: =C$10*F17/100 -> 0 | Q17: ='Calculo Servicios (2)'!H14 -> 0 | R17: =O17+N17+P17+Q17 -> 294898.78 | U17: 3ro. "B"
A18: 4a | C18: 4to. "A" | D18: Estevez Norberto Omar | E18: Sofia | F18: 7.9 | G18: 132911.43 | H18: 0 | I18: =G18 -> 132911.43 | J18: =C9*F18/100 -> #VALUE! | K18: =G18-H18-I18 -> 0 | M18: =(K18+L18)*3% -> 0 | N18: =K18+M18+L18 -> 0 | O18: =C$7*F18/100 -> 158000 | P18: =C$10*F18/100 -> 0 | Q18: ='Calculo Servicios (2)'!H15 -> 0 | R18: =O18+N18+P18+Q18 -> 158000 | U18: 4to. "A"
A19: 4b | C19: 4to. "B" | D19: Lopez Gabriela | E19: Yago | F19: 7.9 | G19: 237688.56 | H19: 0 | I19: =G19 -> 237688.56 | J19: =C9*F19/100 -> #VALUE! | K19: =G19-H19-I19 -> 0 | M19: =(K19+L19)*3% -> 0 | N19: =K19+M19+L19 -> 0 | O19: =C$7*F19/100 -> 158000 | P19: =C$10*F19/100 -> 0 | Q19: ='Calculo Servicios (2)'!H16 -> 0 | R19: =O19+N19+P19+Q19 -> 158000 | U19: 4to. "B"
A20: 5a | C20: 5to. "A" | D20: Degl´Innocenti Julieta Antonella | F20: 7.9 | G20: 355415.29 | H20: 0 | J20: =C9*F20/100 -> #VALUE! | K20: =G20-H20-I20 -> 355415.29 | L20: =G20-I20 -> 355415.29 | M20: =(K20+L20)*3% -> 21324.917 | N20: =K20+M20+L20 -> 732155.5 | O20: =C$7*F20/100 -> 158000 | P20: =C$10*F20/100 -> 0 | Q20: ='Calculo Servicios (2)'!H17 -> 0 | R20: =O20+N20+P20+Q20 -> 890155.5 | U20: 5to. "A"
A21: 5b | C21: 5to. "B" | D21: Scarlercio Jorge Omar | F21: 7.9 | G21: 132911.43 | I21: =G21 -> 132911.43 | K21: =G21-H21-I21 -> 0 | M21: =(K21+L21)*3% -> 0 | N21: =K21+M21+L21 -> 0 | O21: =C$7*F21/100 -> 158000 | P21: =C$10*F21/100 -> 0 | Q21: ='Calculo Servicios (2)'!H18 -> 0 | R21: =O21+N21+P21+Q21 -> 158000 | U21: 5to. "B"
A22: 6a | C22: 6to. "A" | D22: Moro Vanesa Yania / Juan Carlos Moro | E22: Facundo | F22: 7.9 | G22: 253499.12 | I22: =G22 -> 253499.12 | K22: =G22-H22-I22 -> 0 | M22: =(K22+L22)*3% -> 0 | N22: =K22+M22+L22 -> 0 | O22: =C$7*F22/100 -> 158000 | P22: =C$10*F22/100 -> 0 | Q22: ='Calculo Servicios (2)'!H19 -> 0 | R22: =O22+N22+P22+Q22 -> 158000 | U22: 6to. "A"
A23: 6b | C23: 6to. "B" | D23: Rodriguez Flavio// Rodriguez Mauro | F23: 7.9 | G23: 132911.43 | K23: =G23-H23-I23 -> 132911.43 | M23: =(K23+L23)*3% -> 3987.343 | N23: =K23+M23+L23 -> 136898.78 | O23: =C$7*F23/100 -> 158000 | P23: =C$10*F23/100 -> 0 | Q23: ='Calculo Servicios (2)'!H20 -> 0 | R23: =O23+N23+P23+Q23 -> 294898.78 | U23: 6to. "B"
C24: COCHERA 1 (4A) | D24: =D18 -> Estevez Norberto Omar | E24: Sofia | F24: 0.74 | G24: 12449.932 | I24: =G24 -> 12449.932 | K24: =G24-H24-I24 -> 0 | M24: =(K24+L24)*3% -> 0 | N24: =K24+M24+L24 -> 0 | O24: =C$7*F24/100 -> 14800 | P24: =C$10*F24/100 -> 0 | R24: =O24+N24+P24+Q24 -> 14800 | U24: 7mo. "A"
C25: COCHERA 2 (6A) | D25: =D22 -> Moro Vanesa Yania / Juan Carlos Moro | E25: Facundo | F25: 0.74 | G25: 21546.924 | I25: =G25 -> 21546.924 | K25: =G25-H25-I25 -> 0 | M25: =(K25+L25)*3% -> 0 | N25: =K25+M25+L25 -> 0 | O25: =C$7*F25/100 -> 14800 | P25: =C$10*F25/100 -> 0 | Q25: ='Calculo Servicios (2)'!H22 -> 0 | R25: =O25+N25+P25+Q25 -> 14800 | U25: 7mo. "B"
C26: COCHERA 3 (5B) | D26: =D21 -> Scarlercio Jorge Omar | F26: 0.74 | G26: 12449.932 | I26: =G26 -> 12449.932 | K26: =G26-H26-I26 -> 0 | M26: =(K26+L26)*3% -> 0 | N26: =K26+M26+L26 -> 0 | O26: =C$7*F26/100 -> 14800 | P26: =C$10*F26/100 -> 0 | Q26: ='Calculo Servicios (2)'!H23 -> 0 | R26: =O26+N26+P26+Q26 -> 14800 | U26: 8vo. "A"
C27: COCHERA 4 (4B) | D27: =D19 -> Lopez Gabriela | E27: Yago | F27: 0.74 | G27: 21546.924 | H27: 0 | I27: =G27 -> 21546.924 | J27: =C9*F27/100 -> #VALUE! | K27: =G27-H27-I27 -> 0 | M27: =(K27+L27)*3% -> 0 | N27: =K27+M27+L27 -> 0 | O27: =C$7*F27/100 -> 14800 | P27: =C$10*F27/100 -> 0 | Q27: ='Calculo Servicios (2)'!H24 -> 0 | R27: =O27+N27+P27+Q27 -> 14800 | U27: 8vo. "B"
C28: COCHERA 5 (3A) | D28: =D16 -> Cecilia Mariel Cassettari | F28: 0.74 | G28: 12449.932 | H28: 0 | I28: =G28 -> 12449.932 | J28: =C9*F28/100 -> #VALUE! | K28: =G28-H28-I28 -> 0 | M28: =(K28+L28)*3% -> 0 | N28: =K28+M28+L28 -> 0 | O28: =C$7*F28/100 -> 14800 | P28: =C$10*F28/100 -> 0 | Q28: ='Calculo Servicios (2)'!H25 -> 0 | R28: =O28+N28+P28+Q28 -> 14800 | U28: 9no. "A"
C29: COCHERA 6 (3B) | D29: =D17 -> Grandinetti Leonardo Alberto | E29: Marcos | F29: 0.74 | G29: 12449.932 | H29: 0 | J29: 0 | K29: =G29-H29-I29 -> 12449.932 | M29: =(K29+L29)*3% -> 373.49795 | N29: =K29+M29+L29 -> 12823.43 | O29: =C$7*F29/100 -> 14800 | P29: =C$10*F29/100 -> 0 | Q29: ='Calculo Servicios (2)'!H26 -> 0 | R29: =O29+N29+P29+Q29 -> 27623.43 | U29: COCHERA 1
C30: COCHERA 7 (6B) | D30: =D23 -> Rodriguez Flavio// Rodriguez Mauro | F30: 0.74 | G30: 12449.932 | H30: 0 | J30: =C9*F30/100 -> #VALUE! | K30: =G30-H30-I30 -> 12449.932 | M30: =(K30+L30)*3% -> 373.49795 | N30: =K30+M30+L30 -> 12823.43 | O30: =C$7*F30/100 -> 14800 | P30: =C$10*F30/100 -> 0 | Q30: ='Calculo Servicios (2)'!H27 -> 0 | R30: =O30+N30+P30+Q30 -> 27623.43 | U30: COCHERA 2
H31: 0 | P31: =C$10*F31/100 -> 0 | U31: COCHERA 7
G32: =SUM(G12:G31) -> 2392486.9 | H32: =SUM(H12:H31) -> 0 | I32: =SUM(I12:I31) -> 1356852.3 | K32: =SUM(K12:K31) -> 1035634.6 | O32: =SUM(O12:O31) -> 1999600 | P32: =SUM(P12:P31) -> 0 | R32: =O32+N32+P32+Q32 -> 1999600 | U32: COCHERA 8
B33: Señores propietarios e inquilinos: la superficie que ocupa la camara de luz y que forma del porcentaje total construido, el gasto se prorratea por cada unidad funcional. Atte. La Administracion.- | U33: COCHERA 9
U34: COCHERA 10
C35: LAS LINEAS AMARILLAS SIGNIFICAN DEUDORES, ALGUNOS INCLUSO DE VARIOS MESES, A LA FECHA DE COBRO SE LE IMPUTARAN LOS PUNITORIOS, POR LO TANTO CADA UNO QUE DEBA ABONAR Y ADEUDE, ANTES DE IR DEBE CONSULTAR CUAL ES EL MONTO TOTAL QUE DEBE AFRONTAR CON EL TOTAL DE LA DEUDA Y LOS PUNITORIOS CORRESPONDIENTES. SALUDOS CORDIALES.

Sheet Calculo Servicios  (2)
A1: Aysa
D2: Q dias Mes
A3: =13+28+19 -> 60 | B3: 10531.71 | C3: =+B3/A3 -> 175.5285 | D3: 4863.9 | E3: Tramo 2/2 | I3: 17/08 al 18/10
A7: Edesur | L7: Variable | M7: Fijo
A8: 0 | B8: Consumo Anterior | C8: Consumo Actual | D8: Consumo Mes | E8: =3935/2 -> 1967.5 | F8: Variable | G8: Fijo | H8: Total x unidad | K8: 19 | L8: 7502.93 | M8: 2365.26
A9: 1ro. "A" | B9: 1617 | C9: =B9+J25 -> 1689 | D9: =+C9-B9 -> 72 | E9: =+D9/E8 -> 0.036594663 | F9: =+A8*E9 -> 0 | G9: =+(A8*A23)/12 -> 0 | H9: =+G9+F9 -> 0 | K9: 106 | L9: =+L8*O9 -> 1575.6153 | M9: =M8*21% -> 496.7046 | N9: Iva | O9: 0.21
A10: 1ro. "B" | B10: 4104 | C10: =B10+J26 -> 4195 | D10: =+C10-B10 -> 91 | E10: =+D10/E8 -> 0.046251588 | F10: =+A8*E10 -> 0 | G10: =+G9 -> 0 | H10: =+G10+F10 -> 0 | K10: 60 | L10: =+L8*O10 -> 481.98822 | M10: =+M8*6.424% -> 151.9443 | N10: Contribucion Municipal | O10: 0.06424
A11: 2do. "A" | B11: 7644 | C11: =B11+J27 -> 7807 | D11: =+C11-B11 -> 163 | E11: =+D11/E8 -> 0.082846252 | F11: =+A8*E11 -> 0 | G11: =G10 -> 0 | H11: =+G11+F11 -> 0 | K11: 79 | L11: =+L8*0.001% -> 0.0750293 | M11: 0.03 | N11: Contribicion Provincial | O11: 0.1
A12: 2do. "B" | B12: 6554 | C12: =B12+J28 -> 6730 | D12: =+C12-B12 -> 176 | E12: =+D12/E8 -> 0.089453621 | F12: =+A8*E12 -> 0 | G12: =G9 -> 0 | H12: =SUM(F12:G12) -> 0 | K12: 89 | L12: 400 | M12: 253 | N12: Tasa Municipal | O12: 653
A13: 3ro. "A" | B13: 7564 | C13: =B13+J29 -> 7767 | D13: =+C13-B13 -> 203 | E13: =+D13/E8 -> 0.10317662 | F13: =+A8*E13 -> 0 | G13: =G9 -> 0 | H13: =SUM(F13:G13) -> 0 | K13: 140 | L13: =SUM(L8:L12)-0.45 -> 9960.1586 | M13: =SUM(M8:M12) -> 3266.9389
A14: 3ro. "B" | B14: 10119 | C14: =B14+J30 -> 10334 | D14: =+C14-B14 -> 215 | E14: =+D14/E8 -> 0.10927573 | F14: =+A8*E14 -> 0 | G14: =G9 -> 0 | H14: =SUM(F14:G14) -> 0 | K14: 143
A15: 4to. "A" | B15: 8986 | C15: =B15+J31 -> 9068 | D15: =+C15-B15 -> 82 | E15: =+D15/E8 -> 0.041677255 | F15: =+A8*E15 -> 0 | G15: =G9 -> 0 | H15: =SUM(F15:G15) -> 0 | K15: 221 | L15: =+L13+M13 -> 13227.097
A16: 4to. "B" | B16: 7032 | C16: =B16+J32 -> 7034 | D16: =+C16-B16 -> 2 | E16: =+D16/E8 -> 0.0010165184 | F16: =+A8*E16 -> 0 | G16: =G9 -> 0 | H16: =SUM(F16:G16) -> 0 | K16: 32
A17: 5to. "A" | B17: 1623 | C17: =B17+J33 -> 1668 | D17: =+C17-B17 -> 45 | E17: =+D17/E8 -> 0.022871665 | F17: =+A8*E17 -> 0 | G17: =G9 -> 0 | H17: =SUM(F17:G17) -> 0 | K17: 80
A18: 5to. "B" | B18: 3932 | C18: =B18+J34 -> 4021 | D18: =+C18-B18 -> 89 | E18: =+D18/E8 -> 0.04523507 | F18: =+A8*E18 -> 0 | G18: =G9 -> 0 | H18: =SUM(F18:G18) -> 0 | K18: 113
A19: 6to. "A" | B19: 6887 | C19: =B19+J35 -> 6994 | D19: =+C19-B19 -> 107 | E19: =+D19/E8 -> 0.054383736 | F19: =+A8*E19 -> 0 | G19: =G9 -> 0 | H19: =SUM(F19:G19) -> 0 | K19: 2
A20: 6to. "B" | B20: 1884 | C20: =B20+J36 -> 2020 | D20: =+C20-B20 -> 136 | E20: =+D20/E8 -> 0.069123253 | F20: =+A8*E20 -> 0 | G20: =G9 -> 0 | H20: =SUM(F20:G20) -> 0
A21: Total Consumo Mes Octubre | D21: =SUM(D9:D20) -> 1381 | H21: =SUM(H9:H20) -> 0 | J21: =+H21-A8 -> 0
A22: =+D21/E8 -> 0.70190597 | B22: Consumo Depto
A23: =100%-A22 -> 0.29809403 | B23: General
J25: 72
J26: 91
J27: 163
B28: Fondo de Reserva | J28: 176
B29: Mes | C29: Cobrado | D29: Utilizado | E29: Concepto | F29: Acumulado | J29: 203
B30: Abril 2021 | C30: 4000 | D30: 0 | F30: =+C30 -> 4000 | J30: 215 | M30: =+H21-A8 -> 0
B31: Mayo 2021 | C31: 4000 | D31: 0 | F31: =+F30+C31-D31 -> 8000 | J31: 82
B32: Junio 2021 | C32: 4000 | D32: 0 | F32: =+F31+C32-D32 -> 12000 | J32: 2
B33: Julio 2021 | C33: 4000 | D33: 0 | F33: =+F32+C33-D33 -> 16000 | J33: 45 | K33: =11934.02-11933.71 -> 0.31
B34: Agosto 2021 | C34: 4000 | D34: 0 | F34: =+F33+C34-D34 -> 20000 | J34: 89
B35: Septiembre 2021 | C35: 4000 | D35: 0 | F35: =+F34+C35-D35 -> 24000 | J35: 107
B36: Octubre 2021 | C36: 4000 | D36: 0 | F36: =+F35+C36-D36 -> 28000 | J36: 136
B37: Noviembre 2021 | C37: 4000 | D37: 0 | F37: =+F36+C37-D37 -> 32000
B38: Diciembre 2021 | C38: 4000 | D38: 3500 | E38: Arreglo cerradura | F38: =+F37+C38-D38 -> 32500 | M38: =88.05-100 -> -11.95
B39: Enero 2022 | C39: 4000 | F39: =+F38+C39-D39 -> 36500
B40: Febrero 2022 | C40: 4000 | F40: =+F39+C40-D40 -> 40500
B41: Marzo 2022 | C41: 4000 | F41: =+F40+C41-D41 -> 44500
B42: Abril 2022 | C42: 0 | F42: =+F41+C42-D42 -> 44500
B43: Mayo 2022 | C43: 0 | F43: =+F42+C43-D43 -> 44500
B44: Junio 2022 | C44: 0 | F44: =+F43+C44-D44 -> 44500
...
