Workbook

Sheet RESUMEN
C1: MAIL: elmiradorconsorcios@gmail.com
C2: CUIT ADMINISTRACION: 27231256879
C3: CBU: | E3: TELEFONO: 11 5320-2676
C4: ADMINISTRADORA: CAROLINA CANCIANI MP:1148
C5: PERÍODO: JULIO | E5: HORARIOS DE ATENCION: LUNES A VIERNES - 10 A 16HS - EMERGENCIAS 24HS
C6: LIQUIDACION DE EXPENSAS
A14: Importante para dueños o inquilinos de departamentos o coheras: Queremos recordarles una cuestión importante respecto a los pagos de expensas que ayuda a evitar errores en la imputación de los mismos. El sistema que utilizamos asigna centavos únicos a cada Unidad Funcional (UF), lo cual nos permite identificar automáticamente a qué unidad corresponde cada transferencia. Es decir, cada UF tiene un número específico de centavos que actúa como "identificador". Por ejemplo, si tu UF es la 45, el importe a abonar debería terminar en $...,45. Si tenés más de una unidad (por ejemplo, un departamento y una cochera), cada una tiene su propio código de centavos. En esos casos, te pedimos por favor que realices una transferencia por cada UF, respetando el importe con sus centavos correspondientes. Sabemos que a veces por comodidad se suele enviar todo junto en una sola transferencia, pero esto puede generar confusión o errores en la imputación automática. Realizar los pagos por separado nos permite asegurar que cada importe se asigne correctamente. Agradecemos muchísimo la colaboración para seguir manteniendo todo ordenado. Saludos cordiales.
A21: GASTOS ORDINARIOS UNIDADES FUNCIONALES: | E21: UF 93,20% | F21: LOCAL 1 (1,08%) | G21: LOCAL 2 (1,28%) | H21: LOCAL 3 (1,21%) | I21: LOCAL 4 (1,49%) | J21: LOCAL 5 (1,74%)
A22: Sueldo encargada Sonia Arzamendia Galeano
A23: Haberes | D23: =481500*2 -> 963000
A24: Plus pileta | D24: 33606.9
A25: Plus retiro de basura | D25: 111256.4
A26: Plus cochera | D26: 19877.4
A27: Adicional remuneracion | D27: 50000
A28: SAC | D28: 410000
A29: SUBTOTAL | D29: =SUM(D23:D28) -> 1587740.7
A30: Sueldo encargada Miriam
A31: Haberes | D31: =240732 -> 240732
A32: Plus pileta | D32: 33606.9
A33: Plus retiro de basura | D33: 111256.4
A34: Plus cochera | D34: 19877.4
A35: Adicional remuneracion | D35: 50000
A36: SUBTOTAL | D36: =SUM(D31:D35) -> 455472.7
A37: TOTAL SUELDO | D37: =D29+D36 -> 2043213.4 | E37: =D37*93.2% -> 1904274.9 | F37: =$D37*1.08% -> 22066.705 | G37: =$D37*1.28% -> 26153.132 | H37: =$D37*1.21% -> 24722.882 | I37: =$D37*1.49% -> 30443.88 | J37: =D37*1.74% -> 35551.913 | K37: =E37+J37+F37+G37+H37+I37 -> 2043213.4 | L37: =IF(D37=K37, "", "Error")
A38: SAC | D38: 0 | E38: =D38*91.91% -> 0 | J38: =D38*8.09% -> 0
D39: 0 | E39: =D39*91.91% -> 0 | J39: =D39*8.09% -> 0
A42: TOTAL | D42: =SUM(D38:D40) -> 0 | E42: =SUM(E38:E40) -> 0 | J42: =SUM(J38:J40) -> 0 | K42: =E42+J42 -> 0 | L42: =IF(D42=K42, "", "Error")
A43: COMBUSTIBLE PARA GRUPO ELECTROGENO | E43: =D43*91.91% -> 0 | J43: =D43*8.09% -> 0
A44: Gas Lanus SA - Compra infinia diesel | C44: Efect 02/07 | D44: 79500.01 | E44: =D44 -> 79500.01
E45: =D45*91.91% -> 0 | J45: =D45*8.09% -> 0
A46: TOTAL SAC | D46: =SUM(D39:D45) -> 79500.01 | E46: =SUM(E39:E45) -> 79500.01 | K46: =E46+J46+F46+G46+H46+I46 -> 79500.01 | L46: =IF(D46=K46, "", "Error")
A47: IMPUESTOS
A48: ARBA - Impuesto inmobiliario partida 025024270-0 | C48: PMC 10/06 | D48: 132512.6
A49: TSG - Partida 197229000 | C49: PMC 09/06 | D49: 669159
A50: TSG - Partida 197227000 | C50: PMC 09/06 | D50: 643422
A51: TOTAL IMPUESTOS | D51: =SUM(D48:D50) -> 1445093.6 | E51: =D51*93.2% -> 1346827.2 | F51: =$D51*1.08% -> 15607.011 | G51: =$D51*1.28% -> 18497.198 | H51: =$D51*1.21% -> 17485.633 | I51: =$D51*1.49% -> 21531.895 | J51: =D51*1.74% -> 25144.629 | K51: =E51+J51+F51+G51+H51+I51 -> 1445093.6 | L51: =IF(D51=K51, "", "Error")
A52: APORTES Y CONTRIBUCIONES
A53: Monotributo Sra. Sonia | D53: 48854
A55: TOTAL APORTES Y CONTRIBUCIONES | D55: =SUM(D52:D54) -> 48854 | E55: =D55*93.2% -> 45531.928 | F55: =$D55*1.08% -> 527.6232 | G55: =$D55*1.28% -> 625.3312 | H55: =$D55*1.21% -> 591.1334 | I55: =$D55*1.49% -> 727.9246 | J55: =D55*1.74% -> 850.0596 | K55: =E55+J55+F55+G55+H55+I55 -> 48854 | L55: =IF(D55=K55, "", "Error")
A56: SEGUROS
...

Sheet PRORRATEO
F1: ESTADO DE CUENTA Y PRORRATEO | J1: SE GASTO: | K1: =RESUMEN!D96-RESUMEN!D94 -> 6774629
J2: SE PRORRATEA EN LAS UF: | L2: 7142595.9
A3: =RESUMEN!C5 -> PERÍODO: JULIO
I4: =(I3*8.09%)/44 -> 0 | O4: =K1-J126 -> -315014.57
A5: Piso | B5: Dpto. | C5: UF | D5: Propietario | E5: (%) | F5: Saldo | G5: Ingreso | H5: SALDO | I5: Expensas extraor. | J5: Expensas ord | K5: SUM/ GASTOS PART | L5: TOTAL EXPENSAS 1er VTO | M5: TOTAL EXPENSAS 2do VTO
A7: conf sup | C7: LOC 1 | D7: Fernandez, Cristian | E7: 0.0108 | H7: =F7-G7 -> 0 | I7: 0 | J7: 70998.784 | K7: 0 | L7: =J7+I7+H7+K7 -> 70998.784 | M7: =L7*6% + L7 -> 75258.711 | P7: para copias y pegar las expensas ord del local
C8: LOC 2 | D8: Sr propietario | E8: 0.013 | H8: =F8-G8 -> 0 | I8: 0 | J8: 84146.707 | K8: =I$3*E8%+I$4 -> 0 | L8: =J8+I8+H8+K8 -> 84146.707 | M8: =L8*6% + L8 -> 89195.51
A9: conf sup | C9: LOC 3 | D9: Passeri, Hernán | E9: 0.0121 | H9: =F9-G9 -> 0 | I9: 0 | J9: 79544.934 | K9: =I$3*E9%+I$4 -> 0 | L9: =J9+I9+H9+K9 -> 79544.934 | M9: =L9*6% + L9 -> 84317.63 | P9: LOCAL 1 | Q9: =RESUMEN!F96 -> 77824.742
A10: conf sup | C10: LOC 4 | D10: Cordero, Leandro Emanuel - Orona, Victoria | E10: 0.0149 | H10: =F10-G10 -> 0 | I10: 0 | J10: 97952.027 | K10: =I$3*E10%+I$4 -> 0 | L10: =J10+I10+H10+K10 -> 97952.027 | M10: =L10*6% + L10 -> 103829.15 | P10: LOCAL 2 | Q10: =RESUMEN!G96 -> 92236.731
A11: conf sup | C11: LOC 5 | D11: Sr propietario | E11: 0.0174 | H11: =F11-G11 -> 0 | I11: 0 | J11: 114386.93 | K11: =I$3*E11%+I$4 -> 0 | L11: =J11+I11+H11+K11 -> 114386.93 | M11: =L11*6% + L11 -> 121250.15 | P11: LOCAL 3 | Q11: =RESUMEN!H96 -> 87192.535
A12: 3 amb | C12: 2ºA | D12: Franco, Lucas Fabián | E12: 0.0188 | H12: =F12-G12 -> 0 | I12: =L$4*E12 -> 0 | J12: =L$2*E12 -> 134280.8 | K12: =I$3*E12%+I$4 -> 0 | L12: =ROUND((J12+I12+H12+K12),0) + N12 -> 134281.01 | M12: =ROUND((L12*6% + L12 ),0) + N12 -> 142338.01 | N12: 0.01 | P12: LOCAL 4 | Q12: =RESUMEN!I96 -> 107369.32
A13: 1 amb | C13: 2ºB | D13: Martinez, Diego | E13: 0.0084 | H13: =F13-G13 -> 0 | I13: =L$4*E13 -> 0 | J13: =L$2*E13 -> 59997.805 | K13: =I$3*E13%+I$4 -> 0 | L13: =ROUND((J13+I13+H13+K13),0) + N13 -> 59998.02 | M13: =ROUND((L13*6% + L13 ),0) + N13 -> 63598.02 | N13: =N12+0.01 -> 0.02 | P13: LOCAL 5 | Q13: =RESUMEN!J96 -> 125384.31
A14: 3 amb | C14: 2ºC | D14: Rodriguez, Carlos Alberto Miguel | E14: 0.0201 | H14: =F14-G14 -> 0 | I14: =L$4*E14 -> 0 | J14: =L$2*E14 -> 143566.18 | K14: =I$3*E14%+I$4 -> 0 | L14: =ROUND((J14+I14+H14+K14),0) + N14 -> 143566.03 | M14: =ROUND((L14*6% + L14 ),0) + N14 -> 152180.03 | N14: =N13+0.01 -> 0.03
A15: 2 amb | C15: 2ºD | D15: Ferraro, José | E15: 0.0094 | H15: =F15-G15 -> 0 | I15: =L$4*E15 -> 0 | J15: =L$2*E15 -> 67140.401 | K15: =I$3*E15%+I$4 -> 0 | L15: =ROUND((J15+I15+H15+K15),0) + N15 -> 67140.04 | M15: =ROUND((L15*6% + L15 ),0) + N15 -> 71168.04 | N15: =N14+0.01 -> 0.04
A16: 2 amb | C16: 2ºE | D16: Dieci, Matias Orlando | E16: 0.0087 | H16: =F16-G16 -> 0 | I16: =L$4*E16 -> 0 | J16: =L$2*E16 -> 62140.584 | K16: 0 | L16: =ROUND((J16+I16+H16+K16),0) + N16 -> 62141.05 | M16: =ROUND((L16*6% + L16 ),0) + N16 -> 65870.05 | N16: =N15+0.01 -> 0.05
A17: 2 amb | C17: 2ºF | D17: Ferraro, Jose | E17: 0.0095 | H17: =F17-G17 -> 0 | I17: =L$4*E17 -> 0 | J17: =L$2*E17 -> 67854.661 | K17: =I$3*E17%+I$4 -> 0 | L17: =ROUND((J17+I17+H17+K17),0) + N17 -> 67855.06 | M17: =ROUND((L17*6% + L17 ),0) + N17 -> 71926.06 | N17: =N16+0.01 -> 0.06
A18: 3 amb | C18: 3ºA | D18: Ferraro, Jose | E18: 0.0165 | H18: =F18-G18 -> 0 | I18: =L$4*E18 -> 0 | J18: =L$2*E18 -> 117852.83 | K18: =I$3*E18%+I$4 -> 0 | L18: =ROUND((J18+I18+H18+K18),0) + N18 -> 117853.07 | M18: =ROUND((L18*6% + L18 ),0) + N18 -> 124924.07 | N18: =N17+0.01 -> 0.07
A19: 1 amb | C19: 3ºB | D19: Ayala, Roberto Adrian | E19: 0.0073 | H19: =F19-G19 -> 0 | I19: =L$4*E19 -> 0 | J19: =L$2*E19 -> 52140.95 | K19: =I$3*E19%+I$4 -> 0 | L19: =ROUND((J19+I19+H19+K19),0) + N19 -> 52141.08 | M19: =ROUND((L19*6% + L19 ),0) + N19 -> 55270.08 | N19: =N18+0.01 -> 0.08
A20: 3 amb | C20: 3ºC | D20: Ferraro, Jose | E20: 0.0178 | H20: =F20-G20 -> 0 | I20: =L$4*E20 -> 0 | J20: =L$2*E20 -> 127138.21 | K20: =I$3*E20%+I$4 -> 0 | L20: =ROUND((J20+I20+H20+K20),0) + N20 -> 127138.09 | M20: =ROUND((L20*6% + L20 ),0) + N20 -> 134766.09 | N20: =N19+0.01 -> 0.09
A21: 2 amb | C21: 3ºD | D21: Ayala, Roberto Adrian | E21: 0.0094 | H21: =F21-G21 -> 0 | I21: =L$4*E21 -> 0 | J21: =L$2*E21 -> 67140.401 | K21: =I$3*E21%+I$4 -> 0 | L21: =ROUND((J21+I21+H21+K21),0) + N21 -> 67140.1 | M21: =ROUND((L21*6% + L21 ),0) + N21 -> 71169.1 | N21: =N20+0.01 -> 0.1
A22: 2 amb | C22: 3ºE | D22: Ayala, Roberto Adrian | E22: 0.0087 | H22: =F22-G22 -> 0 | I22: =L$4*E22 -> 0 | J22: =L$2*E22 -> 62140.584 | K22: =I$3*E22%+I$4 -> 0 | L22: =ROUND((J22+I22+H22+K22),0) + N22 -> 62141.11 | M22: =ROUND((L22*6% + L22 ),0) + N22 -> 65870.11 | N22: =N21+0.01 -> 0.11
A23: 2 amb | C23: 3ºF | D23: Ayala, Roberto Adrian | E23: 0.0095 | H23: =F23-G23 -> 0 | I23: =L$4*E23 -> 0 | J23: =L$2*E23 -> 67854.661 | K23: 0 | L23: =ROUND((J23+I23+H23+K23),0) + N23 -> 67855.12 | M23: =ROUND((L23*6% + L23 ),0) + N23 -> 71926.12 | N23: =N22+0.01 -> 0.12
A24: 3 amb | C24: 4ºA | D24: Barral, Carlos Daniel | E24: 0.0164 | H24: =F24-G24 -> 0 | I24: =L$4*E24 -> 0 | J24: =L$2*E24 -> 117138.57 | K24: =2*9000 -> 18000 | L24: =ROUND((J24+I24+H24+K24),0) + N24 -> 135139.13 | M24: =ROUND((L24*6% + L24 ),0) + N24 -> 143247.13 | N24: =N23+0.01 -> 0.13
A25: 1 amb | C25: 4ºB | D25: Sr. Propietario | E25: 0.0072 | H25: =F25-G25 -> 0 | I25: =L$4*E25 -> 0 | J25: =L$2*E25 -> 51426.69 | K25: =I$3*E25%+I$4 -> 0 | L25: =ROUND((J25+I25+H25+K25),0) + N25 -> 51427.14 | M25: =ROUND((L25*6% + L25 ),0) + N25 -> 54513.14 | N25: =N24+0.01 -> 0.14
A26: 3 amb | C26: 4ºC | D26: Osipowicz, Ariel Marcelo | E26: 0.0173 | H26: =F26-G26 -> 0 | I26: =L$4*E26 -> 0 | J26: =L$2*E26 -> 123566.91 | K26: =3*9000 -> 27000 | L26: =ROUND((J26+I26+H26+K26),0) + N26 -> 150567.15 | M26: =ROUND((L26*6% + L26 ),0) + N26 -> 159601.15 | N26: =N25+0.01 -> 0.15
A27: 2 amb | C27: 4ºD | D27: Ayala, Roberto Adrian | E27: 0.0094 | H27: =F27-G27 -> 0 | I27: =L$4*E27 -> 0 | J27: =L$2*E27 -> 67140.401 | K27: =I$3*E27%+I$4 -> 0 | L27: =ROUND((J27+I27+H27+K27),0) + N27 -> 67140.16 | M27: =ROUND((L27*6% + L27 ),0) + N27 -> 71169.16 | N27: =N26+0.01 -> 0.16
A28: 2 amb | C28: 4ºE | D28: Ayala, Roberto Adrian | E28: 0.0087 | H28: =F28-G28 -> 0 | I28: =L$4*E28 -> 0 | J28: =L$2*E28 -> 62140.584 | K28: =I$3*E28%+I$4 -> 0 | L28: =ROUND((J28+I28+H28+K28),0) + N28 -> 62141.17 | M28: =ROUND((L28*6% + L28 ),0) + N28 -> 65870.17 | N28: =N27+0.01 -> 0.17
A29: 2 amb | C29: 4ºF | D29: Ayala, Roberto Adrian | E29: 0.0095 | H29: =F29-G29 -> 0 | I29: =L$4*E29 -> 0 | J29: =L$2*E29 -> 67854.661 | K29: =I$3*E29%+I$4 -> 0 | L29: =ROUND((J29+I29+H29+K29),0) + N29 -> 67855.18 | M29: =ROUND((L29*6% + L29 ),0) + N29 -> 71926.18 | N29: =N28+0.01 -> 0.18
A30: 3 amb | C30: 5ºA | D30: Chehab, Gabriel Adrian | E30: 0.0164 | H30: =F30-G30 -> 0 | I30: =L$4*E30 -> 0 | J30: =L$2*E30 -> 117138.57 | K30: =I$3*E30%+I$4 -> 0 | L30: =ROUND((J30+I30+H30+K30),0) + N30 -> 117139.19 | M30: =ROUND((L30*6% + L30 ),0) + N30 -> 124168.19 | N30: =N29+0.01 -> 0.19
A31: 1 amb | C31: 5ºB | D31: Mesa, Mariano | E31: 0.0072 | H31: =F31-G31 -> 0 | I31: =L$4*E31 -> 0 | J31: =L$2*E31 -> 51426.69 | K31: =I$3*E31%+I$4 -> 0 | L31: =ROUND((J31+I31+H31+K31),0) + N31 -> 51427.2 | M31: =ROUND((L31*6% + L31 ),0) + N31 -> 54513.2 | N31: =N30+0.01 -> 0.2
A32: 3 amb | C32: 5ºC | D32: Di Mito, Vicente Argentino - Serantes, Mabel | E32: 0.0173 | H32: =F32-G32 -> 0 | I32: =L$4*E32 -> 0 | J32: =L$2*E32 -> 123566.91 | K32: =I$3*E32%+I$4 -> 0 | L32: =ROUND((J32+I32+H32+K32),0) + N32 -> 123567.21 | M32: =ROUND((L32*6% + L32 ),0) + N32 -> 130981.21 | N32: =N31+0.01 -> 0.21
A33: 2 amb | C33: 5ºD | D33: Ayala, Roberto Adrian | E33: 0.0094 | H33: =F33-G33 -> 0 | I33: =L$4*E33 -> 0 | J33: =L$2*E33 -> 67140.401 | K33: =I$3*E33%+I$4 -> 0 | L33: =ROUND((J33+I33+H33+K33),0) + N33 -> 67140.22 | M33: =ROUND((L33*6% + L33 ),0) + N33 -> 71169.22 | N33: =N32+0.01 -> 0.22
A34: 2 amb | C34: 5ºE | D34: Ayala, Roberto Adrian | E34: 0.0087 | H34: =F34-G34 -> 0 | I34: =L$4*E34 -> 0 | J34: =L$2*E34 -> 62140.584 | K34: =I$3*E34%+I$4 -> 0 | L34: =ROUND((J34+I34+H34+K34),0) + N34 -> 62141.23 | M34: =ROUND((L34*6% + L34 ),0) + N34 -> 65870.23 | N34: =N33+0.01 -> 0.23
A35: 2 amb | C35: 5ºF | D35: Ayala, Roberto Adrian | E35: 0.0095 | H35: =F35-G35 -> 0 | I35: =L$4*E35 -> 0 | J35: =L$2*E35 -> 67854.661 | K35: =I$3*E35%+I$4 -> 0 | L35: =ROUND((J35+I35+H35+K35),0) + N35 -> 67855.24 | M35: =ROUND((L35*6% + L35 ),0) + N35 -> 71927.24 | N35: =N34+0.01 -> 0.24
A36: 3 amb | C36: 6ºA | D36: Morandi, Victoria Ayelen | Calvo, Luciano Ezequiel | E36: 0.0164 | H36: =F36-G36 -> 0 | I36: =L$4*E36 -> 0 | J36: =L$2*E36 -> 117138.57 | K36: =I$3*E36%+I$4 -> 0 | L36: =ROUND((J36+I36+H36+K36),0) + N36 -> 117139.25 | M36: =ROUND((L36*6% + L36 ),0) + N36 -> 124168.25 | N36: =N35+0.01 -> 0.25
A37: 1 amb | C37: 6ºB | D37: Grizak Ruben | E37: 0.0072 | H37: =F37-G37 -> 0 | I37: =L$4*E37 -> 0 | J37: =L$2*E37 -> 51426.69 | K37: =9000*3 -> 27000 | L37: =ROUND((J37+I37+H37+K37),0) + N37 -> 78427.26 | M37: =ROUND((L37*6% + L37 ),0) + N37 -> 83133.26 | N37: =N36+0.01 -> 0.26
A38: 3 amb | C38: 6ºC | D38: Nuñez Leonel - Corrieri Giuliana | E38: 0.0173 | H38: =F38-G38 -> 0 | I38: =L$4*E38 -> 0 | J38: =L$2*E38 -> 123566.91 | K38: =I$3*E38%+I$4 -> 0 | L38: =ROUND((J38+I38+H38+K38),0) + N38 -> 123567.27 | M38: =ROUND((L38*6% + L38 ),0) + N38 -> 130981.27 | N38: =N37+0.01 -> 0.27
A39: 2 amb | C39: 6ºD | D39: Sr propietario | E39: 0.0094 | H39: =F39-G39 -> 0 | I39: =L$4*E39 -> 0 | J39: =L$2*E39 -> 67140.401 | K39: =I$3*E39%+I$4 -> 0 | L39: =ROUND((J39+I39+H39+K39),0) + N39 -> 67140.28 | M39: =ROUND((L39*6% + L39 ),0) + N39 -> 71169.28 | N39: =N38+0.01 -> 0.28 | P39: mariano hecimovic
A40: 2 amb | C40: 6ºE | D40: Dieci, Matias Orlando | E40: 0.0087 | H40: =F40-G40 -> 0 | I40: =L$4*E40 -> 0 | J40: =L$2*E40 -> 62140.584 | K40: =I$3*E40%+I$4 -> 0 | L40: =ROUND((J40+I40+H40+K40),0) + N40 -> 62141.29 | M40: =ROUND((L40*6% + L40 ),0) + N40 -> 65870.29 | N40: =N39+0.01 -> 0.29
A41: 2 amb | C41: 6ºF | D41: Mazzia Alexia | E41: 0.0095 | H41: =F41-G41 -> 0 | I41: =L$4*E41 -> 0 | J41: =L$2*E41 -> 67854.661 | K41: =I$3*E41%+I$4 -> 0 | L41: =ROUND((J41+I41+H41+K41),0) + N41 -> 67855.3 | M41: =ROUND((L41*6% + L41 ),0) + N41 -> 71927.3 | N41: =N40+0.01 -> 0.3
...

Sheet ANOTACIONES
B4: AGREGAR MAILS DEL FOLEO

Sheet SUELDOS
C3: =RESUMEN!C5 -> PERÍODO: JULIO | F3: =RESUMEN!A22 -> Sueldo encargada Sonia Arzamendia Galeano
C5: =RESUMEN!A23 -> Haberes | G5: =RESUMEN!D23 -> 963000 | H5: Firma
C6: =RESUMEN!A24 -> Plus pileta | G6: =RESUMEN!D24 -> 33606.9 | H6: __________________________________
C7: =RESUMEN!A25 -> Plus retiro de basura | G7: =RESUMEN!D25 -> 111256.4
C8: =RESUMEN!A26 -> Plus cochera | G8: =RESUMEN!D26 -> 19877.4
C9: =RESUMEN!A27 -> Adicional remuneracion | G9: =RESUMEN!D27 -> 50000 | H9: Aclaracion
C10: =RESUMEN!A28 -> SAC | G10: =RESUMEN!D28 -> 410000 | H10: __________________________________
C12: TOTAL | G12: =SUM(G5:G11) -> 1587740.7
C16: =RESUMEN!C5 -> PERÍODO: JULIO | F16: =RESUMEN!A30 -> Sueldo encargada Miriam
C18: =RESUMEN!A30 -> Sueldo encargada Miriam | H18: Firma
C19: =RESUMEN!A31 -> Haberes | G19: =RESUMEN!D31 -> 240732 | H19: __________________________________
C20: =RESUMEN!A32 -> Plus pileta | G20: =RESUMEN!D32 -> 33606.9
C21: =RESUMEN!A33 -> Plus retiro de basura | G21: =RESUMEN!D33 -> 111256.4
C22: =RESUMEN!A34 -> Plus cochera | G22: =RESUMEN!D34 -> 19877.4 | H22: Aclaracion
C23: =RESUMEN!A35 -> Adicional remuneracion | G23: =RESUMEN!D35 -> 50000 | H23: __________________________________
C25: TOTAL | G25: =SUM(G18:G24) -> 455472.7
