Workbook

Sheet RESUMEN
C1: MAIL: elmiradorconsorcios@gmail.com
C2: CUIT ADMINISTRACION: 27231256879
C3: CBU: 0720039720000002171436 | E3: TELEFONO: 11 5320-2676
C4: ADMINISTRADORA: CAROLINA CANCIANI MP:1148
C5: PERÍODO: MAYO | E5: HORARIOS DE ATENCION: LUNES A VIERNES - 10 A 15HS - EMERGENCIAS 24HS
C6: LIQUIDACION DE EXPENSAS
A14: Importante para dueños o inquilinos de departamentos o coheras: Queremos recordarles una cuestión importante respecto a los pagos de expensas que ayuda a evitar errores en la imputación de los mismos. El sistema que utilizamos asigna centavos únicos a cada Unidad Funcional (UF), lo cual nos permite identificar automáticamente a qué unidad corresponde cada transferencia. Es decir, cada UF tiene un número específico de centavos que actúa como "identificador". Por ejemplo, si tu UF es la 45, el importe a abonar debería terminar en $...,45. Si tenés más de una unidad (por ejemplo, un departamento y una cochera), cada una tiene su propio código de centavos. En esos casos, te pedimos por favor que realices una transferencia por cada UF, respetando el importe con sus centavos correspondientes. Sabemos que a veces por comodidad se suele enviar todo junto en una sola transferencia, pero esto puede generar confusión o errores en la imputación automática. Realizar los pagos por separado nos permite asegurar que cada importe se asigne correctamente. Agradecemos muchísimo la colaboración para seguir manteniendo todo ordenado. Saludos cordiales.
A20: VTO 18/06
A24: GASTOS ORDINARIOS UNIDADES FUNCIONALES: | E24: UF 93,20% | F24: LOCAL 1 (1,08%) | G24: LOCAL 2 (1,28%) | H24: LOCAL 3 (1,21%) | I24: LOCAL 4 (1,49%) | J24: LOCAL 5 (1,74%)
A25: Salvati - Servicios de limpieza
A26: Servicio de limpieza | C26: Transf 04/05 | D26: 3000000
A27: TOTAL | D27: =SUM(D25:D26) -> 3000000 | E27: =D27*93.2% -> 2796000 | F27: =$D27*1.08% -> 32400 | G27: =$D27*1.28% -> 38400 | H27: =$D27*1.21% -> 36300 | I27: =$D27*1.49% -> 44700 | J27: =D27*1.74% -> 52200 | K27: =E27+J27+F27+G27+H27+I27 -> 3000000 | L27: =IF(D27=K27, "", "Error")
A28: COMBUSTIBLE PARA GRUPO ELECTROGENO
A29: Combustible - Compra | B29: 07/05 Compra Sr. Ariel Osipowicz | D29: 63630
A30: Combustible - Compra | B30: 08/05 Compra Sr. Mariano Campelo - Abono Efectivo | D30: 60000
A31: Combustible - Compra | B31: 07/05 Compra Sr. Carlos Rodriguez -Abono Efectivo | D31: 99726.06
A32: Combustible - Compra | B32: 07/05 Compra Sr. Carlos Rodriguez -Abono Efectivo | D32: 44990.07
A33: Combustible - Compra | B33: 07/05 Compra Sr. Carlos Rodriguez -Abono Efectivo | D33: 70000.03
A34: Combustible - Compra | B34: 08/05 Compra Sr. Mariano Campelo - Abono Efectivo | D34: 60015.95
A36: TOTAL | D36: =SUM(D29:D35) -> 398362.11 | E36: =D36 -> 398362.11 | K36: =E36+J36+F36+G36+H36+I36 -> 398362.11 | L36: =IF(D36=K36, "", "Error")
A37: IMPUESTOS
A38: ARBA - Impuesto inmobiliario partida 025024270-0 | D38: 0
A39: TSG - Partida 197227000 | B39: Mes de MAYO | C39: Transf 22/05 | D39: 1742902
A40: TSG - Partida 197229000 | B40: Mes de MAYO | C40: Transf 22/05 | D40: 1742902
A42: TOTAL IMPUESTOS | D42: =SUM(D38:D41) -> 3485804 | E42: =D42*93.2% -> 3248769.3 | F42: =$D42*1.08% -> 37646.683 | G42: =$D42*1.28% -> 44618.291 | H42: =$D42*1.21% -> 42178.228 | I42: =$D42*1.49% -> 51938.48 | J42: =D42*1.74% -> 60652.99 | K42: =E42+J42+F42+G42+H42+I42 -> 3485804 | L42: =IF(D42=K42, "", "Error")
A43: APORTES Y CONTRIBUCIONES
A47: TOTAL APORTES Y CONTRIBUCIONES | D47: =SUM(D43:D46) -> 0 | E47: =D47*93.2% -> 0 | F47: =$D47*1.08% -> 0 | G47: =$D47*1.28% -> 0 | H47: =$D47*1.21% -> 0 | I47: =$D47*1.49% -> 0 | J47: =D47*1.74% -> 0 | K47: =E47+J47+F47+G47+H47+I47 -> 0 | L47: =IF(D47=K47, "", "Error")
A48: SEGUROS
A49: Federacion patronal - Poliza integral para consorcios nro. 2152393 | C49: Debito autom. | D49: 214371 | E49: =D49*93.2% -> 199793.77 | F49: =$D49*1.08% -> 2315.2068 | G49: =$D49*1.28% -> 2743.9488 | H49: =$D49*1.21% -> 2593.8891 | I49: =$D49*1.49% -> 3194.1279 | J49: =D49*1.74% -> 3730.0554 | K49: =SUM(E49:J49) -> 214371
A51: TOTAL Aportes y Contribuciones - Sindicato | D51: =SUM(D49:D50) -> 214371 | E51: =SUM(E49:E50) -> 199793.77 | F51: =SUM(F49:F50) -> 2315.2068 | G51: =SUM(G49:G50) -> 2743.9488 | H51: =SUM(H49:H50) -> 2593.8891 | I51: =SUM(I49:I50) -> 3194.1279 | J51: =SUM(J49:J50) -> 3730.0554 | K51: =E51+J51+F51+G51+H51+I51 -> 214371 | L51: =IF(D51=K51, "", "Error")
A52: ABONOS Y SERVICIOS
A53: Aysa - Cuenta 249011 | C53: Transf 11/5 | D53: 36079.1 | E53: =D53*93.2% -> 33625.721 | F53: =$D53*1.08% -> 389.65428 | G53: =$D53*1.28% -> 461.81248 | H53: =$D53*1.21% -> 436.55711 | I53: =$D53*1.49% -> 537.57859 | J53: =D53*1.74% -> 627.77634 | K53: =D53 -> 36079.1 | L53: =SUM(E53:J53) -> 36079.1
A54: Edesur - Cliente 01291636 | C54: Transf 12/5 | D54: 3898893.1 | E54: =D54*93.2% -> 3633768.4 | F54: =$D54*1.08% -> 42108.045 | G54: =$D54*1.28% -> 49905.832 | H54: =$D54*1.21% -> 47176.607 | I54: =$D54*1.49% -> 58093.507 | J54: =D54*1.74% -> 67840.74 | K54: =D54 -> 3898893.1 | L54: =E54+J54+I54+H54+G54+F54 -> 3898893.1
A55: Telecentro - Zona coworking - Cliente 7725479 | C55: Debito 19/05 | D55: 151564.8 | E55: =D55 -> 151564.8 | K55: =D55 -> 151564.8 | L55: =E55+J55+I55+H55+G55+F55 -> 151564.8 | M55: =L55-D55 -> 0 | N55: =K55-D55 -> 0
A56: ADS - Abono de mantenimiento ascensores MAYO del 2025 | C56: Transf 08/04 | D56: 359504.14 | E56: =D56 -> 359504.14 | K56: =D56 -> 359504.14 | L56: =E56+J56+I56+H56+G56+F56 -> 359504.14
A57: Victor Martinez - Abono mantenimiento control de accesos - 2 Meses | C57: Transf 11/05 | D57: 50000 | E57: =D57 -> 50000 | K57: =D57 -> 50000 | L57: =E57+J57+I57+H57+G57+F57 -> 50000 | M57: =L57-D57 -> 0 | N57: =K57-D57 -> 0
A58: Metrogas - Cliente nro. 40000496339 | C58: Transf 13/05 | D58: 5760.01 | E58: =D58*93.2% -> 5368.3293 | F58: =$D58*1.08% -> 62.208108 | G58: =$D58*1.28% -> 73.728128 | H58: =$D58*1.21% -> 69.696121 | I58: =$D58*1.49% -> 85.824149 | J58: =D58*1.74% -> 100.22417 | K58: =D58 -> 5760.01 | L58: =E58+J58+I58+H58+G58+F58 -> 5760.01 | M58: =L58-D58 -> 0 | N58: =K58-D58 -> 0
A59: Metrogas - Cliente nro. 40000497007 | C59: Transf 13/05 | D59: 907421.13 | E59: =D59 -> 907421.13 | K59: =D59 -> 907421.13 | L59: =E59+J59+I59+H59+G59+F59 -> 907421.13 | M59: =L59-D59 -> 0 | N59: =K59-D59 -> 0
A60: Loschi Mantenimiento grupo electrogeno - Abono bimestral | C60: Transf 18/05 | D60: 120000 | E60: =D60 -> 120000 | K60: =D60 -> 120000 | L60: =E60+J60+I60+H60+G60+F60 -> 120000 | M60: =L60-D60 -> 0 | N60: =K60-D60 -> 0
A61: TOTAL ABONOS Y SERVICIOS | D61: =SUM(D53:D60) -> 5529222.3 | E61: =SUM(E53:E60) -> 5261252.5 | F61: =SUM(F53:F60) -> 42559.908 | G61: =SUM(G53:G60) -> 50441.372 | H61: =SUM(H53:H60) -> 47682.86 | I61: =SUM(I53:I60) -> 58716.91 | J61: =SUM(J53:J60) -> 68568.74 | K61: =E61+J61+F61+G61+H61+I61 -> 5529222.3 | L61: =IF(D61=K61, "", "Error") | M61: =D61-K61 -> 0
...

Sheet PRORRATEO
A1: Las casillas coloreadas en la columna Gastos Par/SUM de color rojo corresponden a multas aplicadas por el uso del SUM. En consecuencia, la unidad funcional involucrada no podrá acceder al uso del mismo por tiempo indeterminado. Por otro lado, las casillas coloreadas en amarillo, corresponden a llaves y las verdes corresponden al mal uso del coworking. | F1: Banco Santander Rio. | L1: SE GASTO: | M1: =RESUMEN!D89-N3 -> 15847088
F2: CBU: 0720039720000002171436 | L2: SE PRORRATEA EN LAS UF: | N2: 15000000
F3: CTA CTE $ 0039 - 21714/3 FIDEICOMISO 25 DE MAYO 837 LAN 30716676737 | L3: ARBA: | N3: 0
C5: IMPORTANTE: Las personas marcadas en color naranja abonaron de forma incorrecta mediante Mercado Pago. A partir de ahora (incluso desde hace meses), ya se encuentra habilitada la cuenta bancaria correspondiente, por lo que todos los pagos deben realizarse exclusivamente a través de dicha cuenta. Los datos de la misma se encuentran justo arriba de este aviso. Quienes abonen por Mercado Pago corren el riesgo de que su pago no sea imputado correctamente.
C9: IMPORTANTE: Quienes estan en violeta NO ha respetado los centavos al abonar. Para la proxima oportunidad, solicitamos que los respeten. | Q9: LOCAL 1 | R9: =RESUMEN!F89 -> 139642.25
Q10: LOCAL 2 | R10: =RESUMEN!G89 -> 165501.92
A11: Piso | B11: Dpto. | C11: UF | D11: Propietario | E11: Inquilinos | F11: (%) | G11: Saldo | H11: Ingreso | I11: SALDO | J11: Expensas extraor. | K11: Cuota ARBA | L11: Expensas ord | M11: SUM/ GASTOS PART | N11: TOTAL A ABONAR HASTA | O11: TOTAL A ABONAR 2DO VTO - DESDE EL | Q11: LOCAL 3 | R11: =RESUMEN!H89 -> 156451.04
Q12: LOCAL 4 | R12: =RESUMEN!I89 -> 192654.58
N13: =RESUMEN!A20 -> VTO 18/06 | O13: =RESUMEN!A20 -> VTO 18/06 | Q13: LOCAL 5 | R13: =RESUMEN!J89 -> 224979.18
A14: conf sup | C14: LOC 1 | D14: Fernandez, Cristian | E14: Gladys ojeda Britez - Exequiel alexis giuliani | F14: 0.0108 | G14: 267664.48 | H14: 206250 | I14: =G14-H14 -> 61414.477 | J14: 0 | K14: =N$3*F14 -> 0 | L14: 206250.12 | M14: 0 | N14: =L14+J14+I14+M14+K14 -> 267664.6 | O14: =N14*6% + N14 -> 283724.47 | P14: Bezzo Jorge
C15: LOC 2 | D15: Fridgi, Guillermo Ariel | F15: 0.013 | G15: 388046.4 | H15: =244445+178355 -> 422800 | I15: =G15-H15 -> -34753.596 | J15: 0 | K15: =N$3*F15 -> 0 | L15: 244444.58 | M15: 0 | N15: =L15+J15+I15+M15+K15 -> 209690.99 | O15: =N15*6% + N15 -> 222272.45 | P15: Lucas Rocha
A16: conf sup | C16: LOC 3 | D16: Patricia Mainieri | E16: Cristina andrea Massa | F16: 0.0121 | G16: 299883.35 | H16: =231077+68807 -> 299884 | I16: =G16-H16 -> -0.650652 | J16: 0 | K16: =N$3*F16 -> 0 | L16: 231076.52 | M16: 0 | N16: =L16+J16+I16+M16+K16 -> 231075.87 | O16: =N16*6% + N16 -> 244940.42
A17: conf sup | C17: LOC 4 | D17: Cordero, Leandro Emanuel - Orona, Victoria | F17: 0.0149 | G17: 1661074 | H17: =1932950.72-271877 -> 1661073.7 | I17: =G17-H17 -> 0.29529238 | J17: 0 | K17: =N$3*F17 -> 0 | L17: 284548.77 | M17: 0 | N17: =L17+J17+I17+M17+K17 -> 284549.07 | O17: =N17*6% + N17 -> 301622.01
A18: conf sup | C18: LOC 5 | D18: Orsi, Jose Luis - Fernandez, Cristian Gabriel | F18: 0.0174 | G18: 391506.51 | H18: 98945 | I18: =G18-H18 -> 292561.51 | J18: 0 | K18: =N$3*F18 -> 0 | L18: 332291.86 | M18: 0 | N18: =L18+J18+I18+M18+K18 -> 624853.37 | O18: =N18*6% + N18 -> 662344.57
A19: 3 amb | C19: 2ºA | D19: Franco, Lucas Fabián | F19: 0.0188 | G19: 388906.01 | H19: =G19 -> 388906.01 | I19: =G19-H19 -> 0 | J19: =N$8*F19 -> 0 | K19: =N$3*F19 -> 0 | L19: =N$2*F19 -> 282000 | M19: 0 | N19: =ROUND((L19+J19+I19+K19+M19),0) + P19 -> 282000.01 | O19: =ROUND((N19*6% + N19 ),0) + P19 -> 298920.01 | P19: 0.01
A20: 1 amb | C20: 2ºB | D20: Martinez, Diego | F20: 0.0084 | G20: 173767.02 | H20: =G20 -> 173767.02 | I20: =G20-H20 -> 0 | J20: =N$8*F20 -> 0 | K20: =N$3*F20 -> 0 | L20: =N$2*F20 -> 126000 | M20: 0 | N20: =ROUND((L20+J20+I20+K20+M20),0) + P20 -> 126000.02 | O20: =ROUND((N20*6% + N20 ),0) + P20 -> 133560.02 | P20: =P19+0.01 -> 0.02
A21: 3 amb | C21: 2ºC | D21: Rodriguez, Carlos Alberto Miguel | F21: 0.0201 | G21: 440747.03 | H21: =G21 -> 440747.03 | I21: =G21-H21 -> 0 | J21: =N$8*F21 -> 0 | K21: =N$3*F21 -> 0 | L21: =N$2*F21 -> 301500 | M21: 0 | N21: =ROUND((L21+J21+I21+K21+M21),0) + P21 -> 301500.03 | O21: =ROUND((N21*6% + N21 ),0) + P21 -> 319590.03 | P21: =P20+0.01 -> 0.03
A22: 2 amb | C22: 2ºD | D22: Ferraro, José | E22: Matias Cuevas | F22: 0.0094 | G22: 143675.04 | H22: =53453+143675.04 -> 197128.04 | I22: =G22-H22 -> -53453 | J22: =N$8*F22 -> 0 | K22: =N$3*F22 -> 0 | L22: =N$2*F22 -> 141000 | M22: 0 | N22: =ROUND((L22+J22+I22+K22+M22),0) + P22 -> 87547.04 | O22: =ROUND((N22*6% + N22 ),0) + P22 -> 92800.04 | P22: =P21+0.01 -> 0.04 | Q22: Matias alejandro ezequiel
A23: 2 amb | C23: 2ºE | D23: Dieci, Matias Orlando | E23: Julieta Damiano/Damiani | F23: 0.0087 | G23: 179973.05 | H23: =G23 -> 179973.05 | I23: =G23-H23 -> 0 | J23: =N$8*F23 -> 0 | K23: =N$3*F23 -> 0 | L23: =N$2*F23 -> 130500 | M23: 0 | N23: =ROUND((L23+J23+I23+K23+M23),0) + P23 -> 130500.05 | O23: =ROUND((N23*6% + N23 ),0) + P23 -> 138330.05 | P23: =P22+0.01 -> 0.05
A24: 2 amb | C24: 2ºF | D24: Ferraro, Jose | E24: Carolina Massa | F24: 0.0095 | G24: 145604.06 | H24: =54022+33595.06+145604.06 -> 233221.12 | I24: =G24-H24 -> -87617.06 | J24: =N$8*F24 -> 0 | K24: =N$3*F24 -> 0 | L24: =N$2*F24 -> 142500 | M24: 20000 | N24: =ROUND((L24+J24+I24+K24+M24),0) + P24 -> 74883.06 | O24: =ROUND((N24*6% + N24 ),0) + P24 -> 79376.06 | P24: =P23+0.01 -> 0.06
A25: 3 amb | C25: 3ºA | D25: Ferraro, Jose | E25: Walter Gabriel Ledesma | F25: 0.0165 | G25: 268063.07 | H25: =93827+268063.07 -> 361890.07 | I25: =G25-H25 -> -93827 | J25: =N$8*F25 -> 0 | K25: =N$3*F25 -> 0 | L25: =N$2*F25 -> 247500 | M25: 20000 | N25: =ROUND((L25+J25+I25+K25+M25),0) + P25 -> 173673.07 | O25: =ROUND((N25*6% + N25 ),0) + P25 -> 184093.07 | P25: =P24+0.01 -> 0.07
A26: 1 amb | C26: 3ºB | D26: Balduzzi, Stella Maris | F26: 0.0073 | G26: 151012.08 | H26: =G26 -> 151012.08 | I26: =G26-H26 -> 0 | J26: =N$8*F26 -> 0 | K26: =N$3*F26 -> 0 | L26: =N$2*F26 -> 109500 | M26: 0 | N26: =ROUND((L26+J26+I26+K26+M26),0) + P26 -> 109500.08 | O26: =ROUND((N26*6% + N26 ),0) + P26 -> 116070.08 | P26: =P25+0.01 -> 0.08
A27: 3 amb | C27: 3ºC | D27: Ferraro, Jose | E27: Gustavo Oscar Fernandez | F27: 0.0178 | G27: 272815.09 | H27: =101220 -> 101220 | I27: =G27-H27 -> 171595.09 | J27: =N$8*F27 -> 0 | K27: =N$3*F27 -> 0 | L27: =N$2*F27 -> 267000 | M27: 0 | N27: =ROUND((L27+J27+I27+K27+M27),0) + P27 -> 438595.09 | O27: =ROUND((N27*6% + N27 ),0) + P27 -> 464911.09 | P27: =P26+0.01 -> 0.09
A28: 2 amb | C28: 3ºD | D28: Fernandez, Christian Norberto | F28: 0.0094 | G28: 194453.1 | H28: =G28 -> 194453.1 | I28: =G28-H28 -> 0 | J28: =N$8*F28 -> 0 | K28: =N$3*F28 -> 0 | L28: =N$2*F28 -> 141000 | M28: 0 | N28: =ROUND((L28+J28+I28+K28+M28),0) + P28 -> 141000.1 | O28: =ROUND((N28*6% + N28 ),0) + P28 -> 149460.1 | P28: =P27+0.01 -> 0.1
A29: 2 amb | C29: 3ºE | D29: Dallorso, Maria Ines - Dallorso, Ana Paula | F29: 0.0087 | G29: 179973.11 | H29: =G29 -> 179973.11 | I29: =G29-H29 -> 0 | J29: =N$8*F29 -> 0 | K29: =N$3*F29 -> 0 | L29: =N$2*F29 -> 130500 | M29: 0 | N29: =ROUND((L29+J29+I29+K29+M29),0) + P29 -> 130500.11 | O29: =ROUND((N29*6% + N29 ),0) + P29 -> 138330.11 | P29: =P28+0.01 -> 0.11
A30: 2 amb | C30: 3ºF | D30: Ayala, Roberto Adrian | F30: 0.0095 | G30: 1271868.1 | I30: =G30-H30 -> 1271868.1 | J30: =N$8*F30 -> 0 | K30: =N$3*F30 -> 0 | L30: =N$2*F30 -> 142500 | M30: 0 | N30: =ROUND((L30+J30+I30+K30+M30),0) + P30 -> 1414368.1 | O30: =ROUND((N30*6% + N30 ),0) + P30 -> 1499230.1 | P30: =P29+0.01 -> 0.12
A31: 3 amb | C31: 4ºA | D31: Barral, Carlos Daniel | F31: 0.0164 | G31: 339259.13 | H31: =G31 -> 339259.13 | I31: =G31-H31 -> 0 | J31: =N$8*F31 -> 0 | K31: =N$3*F31 -> 0 | L31: =N$2*F31 -> 246000 | M31: 0 | N31: =ROUND((L31+J31+I31+K31+M31),0) + P31 -> 246000.13 | O31: =ROUND((N31*6% + N31 ),0) + P31 -> 260760.13 | P31: =P30+0.01 -> 0.13
A32: 1 amb | C32: 4ºB | D32: Sr. Propietario | E32: Liria | F32: 0.0072 | G32: 148943.14 | H32: =G32 -> 148943.14 | I32: =G32-H32 -> 0 | J32: =N$8*F32 -> 0 | K32: =N$3*F32 -> 0 | L32: =N$2*F32 -> 108000 | M32: 0 | N32: =ROUND((L32+J32+I32+K32+M32),0) + P32 -> 108000.14 | O32: =ROUND((N32*6% + N32 ),0) + P32 -> 114480.14 | P32: =P31+0.01 -> 0.14
A33: 3 amb | C33: 4ºC | D33: Osipowicz, Ariel Marcelo | F33: 0.0173 | G33: 357877.15 | H33: =G33+63630 -> 421507.15 | I33: =G33-H33 -> -63630 | J33: =N$8*F33 -> 0 | K33: =N$3*F33 -> 0 | L33: =N$2*F33 -> 259500 | M33: 0 | N33: =ROUND((L33+J33+I33+K33+M33),0) + P33 -> 195870.15 | O33: =ROUND((N33*6% + N33 ),0) + P33 -> 207622.15 | P33: =P32+0.01 -> 0.15
A34: 2 amb | C34: 4ºD | D34: Ruiz, Juana Del Valle | F34: 0.0094 | G34: 187685.16 | H34: =G34 -> 187685.16 | I34: =G34-H34 -> 0 | J34: =N$8*F34 -> 0 | K34: =N$3*F34 -> 0 | L34: =N$2*F34 -> 141000 | M34: 0 | N34: =ROUND((L34+J34+I34+K34+M34),0) + P34 -> 141000.16 | O34: =ROUND((N34*6% + N34 ),0) + P34 -> 149460.16 | P34: =P33+0.01 -> 0.16 | Q34: Pablo Amarilla
A35: 2 amb | C35: 4ºE | D35: Szkarlatiuk, Carina Sonia | E35: Iara | F35: 0.0087 | G35: 284373.17 | H35: =234900.17 -> 234900.17 | I35: =G35-H35 -> 49473 | J35: =N$8*F35 -> 0 | K35: =N$3*F35 -> 0 | L35: =N$2*F35 -> 130500 | M35: 0 | N35: =ROUND((L35+J35+I35+K35+M35),0) + P35 -> 179973.17 | O35: =ROUND((N35*6% + N35 ),0) + P35 -> 190772.17 | P35: =P34+0.01 -> 0.17
A36: 2 amb | C36: 4ºF | D36: Ayala, Roberto Adrian | F36: 0.0095 | G36: 754117.18 | I36: =G36-H36 -> 754117.18 | J36: =N$8*F36 -> 0 | K36: =N$3*F36 -> 0 | L36: =N$2*F36 -> 142500 | M36: 0 | N36: =ROUND((L36+J36+I36+K36+M36),0) + P36 -> 896617.18 | O36: =ROUND((N36*6% + N36 ),0) + P36 -> 950414.18 | P36: =P35+0.01 -> 0.18
A37: 3 amb | C37: 5ºA | D37: Chehab, Gabriel Adrian | E37: Santiago Rodriguez | F37: 0.0164 | G37: 339259.19 | H37: =G37 -> 339259.19 | I37: =G37-H37 -> 0 | J37: =N$8*F37 -> 0 | K37: =N$3*F37 -> 0 | L37: =N$2*F37 -> 246000 | M37: 0 | N37: =ROUND((L37+J37+I37+K37+M37),0) + P37 -> 246000.19 | O37: =ROUND((N37*6% + N37 ),0) + P37 -> 260760.19 | P37: =P36+0.01 -> 0.19 | Q37: Cochera 38
A38: 1 amb | C38: 5ºB | D38: Mesa, Mariano | F38: 0.0072 | G38: 148943.2 | H38: =G38 -> 148943.2 | I38: =G38-H38 -> 0 | J38: =N$8*F38 -> 0 | K38: =N$3*F38 -> 0 | L38: =N$2*F38 -> 108000 | M38: 0 | N38: =ROUND((L38+J38+I38+K38+M38),0) + P38 -> 108000.2 | O38: =ROUND((N38*6% + N38 ),0) + P38 -> 114480.2 | P38: =P37+0.01 -> 0.2
A39: 3 amb | C39: 5ºC | D39: Di Mito, Vicente Argentino - Serantes, Mabel | F39: 0.0173 | G39: 534246.21 | H39: =G39 -> 534246.21 | I39: =G39-H39 -> 0 | J39: =N$8*F39 -> 0 | K39: =N$3*F39 -> 0 | L39: =N$2*F39 -> 259500 | M39: 20000 | N39: =ROUND((L39+J39+I39+K39+M39),0) + P39 -> 279500.21 | O39: =ROUND((N39*6% + N39 ),0) + P39 -> 296270.21 | P39: =P38+0.01 -> 0.21
A40: 2 amb | C40: 5ºD | D40: Ayala, Agustin | F40: 0.0094 | G40: 819814.22 | I40: =G40-H40 -> 819814.22 | J40: =N$8*F40 -> 0 | K40: =N$3*F40 -> 0 | L40: =N$2*F40 -> 141000 | M40: 0 | N40: =ROUND((L40+J40+I40+K40+M40),0) + P40 -> 960814.22 | O40: =ROUND((N40*6% + N40 ),0) + P40 -> 1018463.2 | P40: =P39+0.01 -> 0.22 | Q40: Ayala paga 5D, 5F y 4F
A41: 2 amb | C41: 5ºE | D41: Basaez, Rogelio Luis - Savino, Cecilia | F41: 0.0087 | G41: 179973.23 | H41: =G41 -> 179973.23 | I41: =G41-H41 -> 0 | J41: =N$8*F41 -> 0 | K41: =N$3*F41 -> 0 | L41: =N$2*F41 -> 130500 | M41: 0 | N41: =ROUND((L41+J41+I41+K41+M41),0) + P41 -> 130500.23 | O41: =ROUND((N41*6% + N41 ),0) + P41 -> 138330.23 | P41: =P40+0.01 -> 0.23 | Q41: COCHERA 31
A42: 2 amb | C42: 5ºF | D42: Ayala, Agustin | F42: 0.0095 | G42: 499337.24 | H42: 0 | I42: =G42-H42 -> 499337.24 | J42: =N$8*F42 -> 0 | K42: =N$3*F42 -> 0 | L42: =N$2*F42 -> 142500 | M42: 0 | N42: =ROUND((L42+J42+I42+K42+M42),0) + P42 -> 641837.24 | O42: =ROUND((N42*6% + N42 ),0) + P42 -> 680347.24 | P42: =P41+0.01 -> 0.24
A43: 3 amb | C43: 6ºA | D43: Morandi, Victoria Ayelen | Calvo, Luciano Ezequiel | F43: 0.0164 | G43: 339259.25 | H43: =G43 -> 339259.25 | I43: =G43-H43 -> 0 | J43: =N$8*F43 -> 0 | K43: =N$3*F43 -> 0 | L43: =N$2*F43 -> 246000 | M43: 0 | N43: =ROUND((L43+J43+I43+K43+M43),0) + P43 -> 246000.25 | O43: =ROUND((N43*6% + N43 ),0) + P43 -> 260760.25 | P43: =P42+0.01 -> 0.25
A44: 1 amb | C44: 6ºB | D44: Grizak Ruben | E44: Christian | F44: 0.0072 | G44: 148943.26 | H44: =G44 -> 148943.26 | I44: =G44-H44 -> 0 | J44: =N$8*F44 -> 0 | K44: =N$3*F44 -> 0 | L44: =N$2*F44 -> 108000 | M44: 0 | N44: =ROUND((L44+J44+I44+K44+M44),0) + P44 -> 108000.26 | O44: =ROUND((N44*6% + N44 ),0) + P44 -> 114480.26 | P44: =P43+0.01 -> 0.26
...

Sheet ARBA
A1: IMPORTANTE: RESPETAR CENTAVOS AL ABONAR.
A3: Quienes adeudan ARBA deben abonar el monto coloreado en ROSADO si es que en el trancurso del mes 3 y 4 del 2026 no abonaron ninguna cuota.
A4: DPTOS | B4: COCH | C4: Propietario | D4: (%) | E4: ARBA REVALUO | F4: POSESION | G4: TOTAL A ABONAR HASTA | H4: TOTAL A ABONAR 1ERA CUOTA - VTO. 31/03 | I4: TOTAL A ABONAR 2DA CUOTA - VTO. 30/04 | J4: A PAGAR PROPIETARIO | L4: ABONADO POR PROPIETARIO | M4: AL PROPIETARIO LE RESTA ABONAR | N4: A PAGAR CONSTRUCTORA | O4: TOTAL
A7: LOC 1 | C7: Fernandez, Cristian | D7: 0.0108 | E7: 282914.38 | F7: 45856 | G7: -197064.48 | H7: =J7/2 -> 98532.35 | I7: =H7 -> 98532.35 | J7: =ROUND((-G7),0)+P7 -> 197064.7 | K7: -85849.897 | L7: 0 | M7: 98532.35 | N7: =-K7 -> 85849.897 | O7: =ROUND((J7+N7),0) + P7 -> 282915.7 | P7: 0.7
A8: LOC 2 | C8: Frigidi Guillermo Ariel | D8: 0.0128 | E8: 335305.93 | F8: 46001 | G8: -34751.379 | H8: =J8/2 -> 17375.855 | I8: =H8 -> 17375.855 | J8: =ROUND((-G8),0)+P8 -> 34751.71 | K8: -300554.55 | M8: =IF(L8=H8,I8,J8) -> 34751.71 | N8: =-K8 -> 300554.55 | O8: =ROUND((J8+N8),0) + P8 -> 335306.71 | P8: =P7+0.01 -> 0.71
A9: LOC 3 | C9: Patricia Mainieri | D9: 0.0121 | E9: 316968.89 | F9: 45856 | G9: -220785.21 | H9: =J9/2 -> 110392.86 | I9: =H9 -> 110392.86 | J9: =ROUND((-G9),0)+P9 -> 220785.72 | K9: -96183.681 | M9: =IF(L9=H9,I9,J9) -> 220785.72 | N9: =-K9 -> 96183.681 | O9: =ROUND((J9+N9),0) + P9 -> 316969.72 | P9: =P8+0.01 -> 0.72
A10: LOC 4 | C10: Cordero, Leandro Emanuel - Orona, Victoria | D10: 0.0149 | E10: 390317.06 | F10: 45856 | G10: -271876 | H10: =J10/2 -> 135938.36 | I10: =H10 -> 135938.36 | J10: =ROUND((-G10),0)+P10 -> 271876.73 | K10: -118441.06 | L10: =J10 -> 271876.73 | M10: 0 | N10: =-K10 -> 118441.06 | O10: =ROUND((J10+N10),0) + P10 -> 390318.73 | P10: =P9+0.01 -> 0.73
A11: LOC 5 | C11: Orsi, José Luis - Fernández, Cristián Gabriel | D11: 0.0175 | E11: 458426.08 | F11: 45856 | G11: -319317.45 | H11: =J11/2 -> 159658.87 | I11: =H11 -> 159658.87 | J11: =ROUND((-G11),0)+P11 -> 319317.74 | K11: -139108.63 | L11: 0 | M11: 159658.87 | N11: =-K11 -> 139108.63 | O11: =ROUND((J11+N11),0) + P11 -> 458426.74 | P11: =P10+0.01 -> 0.74
A12: 2ºA | B12: 25 | C12: Franco, Lucas Fabián | D12: 0.0212 | E12: 555350.45 | F12: 45777 | G12: -519626.97 | H12: =ROUND((J12/2),0)+P12 -> 259814.01 | I12: =H12 -> 259814.01 | J12: =ROUND((-G12),0)+P12 -> 519627.01 | K12: -35723.479 | L12: 0 | M12: 0 | N12: =-K12 -> 35723.479 | O12: =ROUND((J12+N12),0) + P12 -> 555350.01 | P12: 0.01
A13: 2ºB | C13: Martinez, Diego | D13: 0.0084 | E13: 220044.52 | F13: 45775 | G13: -206492.25 | H13: =ROUND((J13/2),0)+P13 -> 103246.02 | I13: =H13 -> 103246.02 | J13: =ROUND((-G13),0)+P13 -> 206492.02 | K13: -13552.263 | M13: 0 | N13: =-K13 -> 13552.263 | O13: =ROUND((J13+N13),0) + P13 -> 220044.02 | P13: =P12+0.01 -> 0.02
A14: 2ºC | B14: 22 | C14: Rodriguez, Carlos Alberto Miguel | D14: 0.0225 | E14: 589404.96 | F14: 45770 | G14: -557137.66 | H14: =ROUND((J14/2),0)+P14 -> 278569.03 | I14: =H14 -> 278569.03 | J14: =ROUND((-G14),0)+P14 -> 557138.03 | K14: -32267.294 | M14: 0 | N14: =-K14 -> 32267.294 | O14: =ROUND((J14+N14),0) + P14 -> 589405.03 | P14: =P13+0.01 -> 0.03
A15: 2ºD | B15: 29-30 | C15: Ferraro, José | D15: 0.014 | E15: 366740.86 | F15: 45805 | G15: -327282.74 | H15: =ROUND((J15/2),0)+P15 -> 163642.04 | I15: =H15 -> 163642.04 | J15: =ROUND((-G15),0)+P15 -> 327283.04 | K15: -39458.12 | M15: 0 | N15: =-K15 -> 39458.12 | O15: =ROUND((J15+N15),0) + P15 -> 366741.04 | P15: =P14+0.01 -> 0.04
A16: 2ºE | C16: Dieci, Matias Orlando | D16: 0.0087 | E16: 227903.25 | F16: 45800 | G16: -206069.05 | H16: =ROUND((J16/2),0)+P16 -> 103035.05 | I16: =H16 -> 103035.05 | J16: =ROUND((-G16),0)+P16 -> 206069.05 | K16: -21834.202 | M16: 0 | N16: =-K16 -> 21834.202 | O16: =ROUND((J16+N16),0) + P16 -> 227903.05 | P16: =P15+0.01 -> 0.05
A17: 2ºF | B17: 34-39 | C17: Ferraro, Jose | D17: 0.0141 | E17: 369360.44 | F17: 45805 | G17: -329620.48 | H17: =ROUND((J17/2),0)+P17 -> 164810.06 | I17: =H17 -> 164810.06 | J17: =ROUND((-G17),0)+P17 -> 329620.06 | K17: -39739.963 | M17: 0 | N17: =-K17 -> 39739.963 | O17: =ROUND((J17+N17),0) + P17 -> 369360.06 | P17: =P16+0.01 -> 0.06
A18: 3ºA | B18: 37-38 | C18: Ferraro, Jose - ------ALEJANDRO | D18: 0.0211 | E18: 552730.87 | F18: 45805 | G18: -493261.85 | H18: =ROUND((J18/2),0)+P18 -> 246631.07 | I18: =H18 -> 246631.07 | J18: =ROUND((-G18),0)+P18 -> 493262.07 | K18: -59469.023 | M18: 0 | N18: =-K18 -> 59469.023 | O18: =ROUND((J18+N18),0) + P18 -> 552731.07 | P18: =P17+0.01 -> 0.07
A19: 3ºB | C19: Ayala, Roberto Adrian/BALDUZZI | D19: 0.0074 | E19: 193848.74 | F19: 45839 | G19: -147681.21 | H19: =ROUND((J19/2),0)+P19 -> 73841.08 | I19: =H19 -> 73841.08 | J19: =ROUND((-G19),0)+P19 -> 147681.08 | K19: -46167.53 | M19: 0 | N19: =-K19 -> 46167.53 | O19: =ROUND((J19+N19),0) + P19 -> 193849.08 | P19: =P18+0.01 -> 0.08
A20: 3ºC | C20: Ferraro, Jose | D20: 0.0179 | E20: 468904.39 | F20: 45805 | G20: -418454.36 | H20: =ROUND((J20/2),0)+P20 -> 209227.09 | I20: =H20 -> 209227.09 | J20: =ROUND((-G20),0)+P20 -> 418454.09 | K20: -50450.024 | M20: 0 | N20: =-K20 -> 50450.024 | O20: =ROUND((J20+N20),0) + P20 -> 468904.09 | P20: =P19+0.01 -> 0.09
A21: 3ºD | C21: Ayala, Roberto Adrian | D21: 0.0094 | E21: 246240.29 | F21: 45839 | G21: -187595.05 | H21: =ROUND((J21/2),0)+P21 -> 93798.1 | I21: =H21 -> 93798.1 | J21: =ROUND((-G21),0)+P21 -> 187595.1 | K21: -58645.241 | M21: 0 | N21: =-K21 -> 58645.241 | O21: =ROUND((J21+N21),0) + P21 -> 246240.1 | P21: =P20+0.01 -> 0.1
A22: 3ºE | C22: Ayala, Roberto Adrian /CALZETTA | D22: 0.0087 | E22: 227903.25 | F22: 45839 | G22: -173625.21 | H22: =ROUND((J22/2),0)+P22 -> 86813.11 | I22: =H22 -> 86813.11 | J22: =ROUND((-G22),0)+P22 -> 173625.11 | K22: -54278.042 | M22: 0 | N22: =-K22 -> 54278.042 | O22: =ROUND((J22+N22),0) + P22 -> 227903.11 | P22: =P21+0.01 -> 0.11
A23: 3ºF | C23: Ayala, Roberto Adrian | D23: 0.0095 | E23: 248859.87 | F23: 45839 | G23: -189590.74 | H23: =ROUND((J23/2),0)+P23 -> 94796.12 | I23: =H23 -> 94796.12 | J23: =ROUND((-G23),0)+P23 -> 189591.12 | K23: -59269.126 | M23: =IF(L23=H23,I23,J23) -> 189591.12 | N23: =-K23 -> 59269.126 | O23: =ROUND((J23+N23),0) + P23 -> 248860.12 | P23: =P22+0.01 -> 0.12
A24: 4ºA | C24: Barral, Carlos Daniel | D24: 0.0164 | E24: 429610.72 | F24: 45775 | G24: -403151.54 | H24: =ROUND((J24/2),0)+P24 -> 201576.13 | I24: =H24 -> 201576.13 | J24: =ROUND((-G24),0)+P24 -> 403152.13 | K24: -26459.181 | M24: 0 | N24: =-K24 -> 26459.181 | O24: =ROUND((J24+N24),0) + P24 -> 429611.13 | P24: =P23+0.01 -> 0.13
A25: 4ºB | C25: Calzetta, Gabriel Andrés Felipe | D25: 0.0073 | E25: 191229.16 | F25: 45800 | G25: -172908.51 | H25: =ROUND((J25/2),0)+P25 -> 86455.14 | I25: =H25 -> 86455.14 | J25: =ROUND((-G25),0)+P25 -> 172909.14 | K25: -18320.652 | L25: =H25 -> 86455.14 | M25: 0 | N25: =-K25 -> 18320.652 | O25: =ROUND((J25+N25),0) + P25 -> 191230.14 | P25: =P24+0.01 -> 0.14
A26: 4ºC | B26: 1-11 | C26: Osipowicz, Ariel Marcelo | D26: 0.022 | E26: 576307.07 | F26: 45775 | G26: -540813.05 | H26: =ROUND((J26/2),0)+P26 -> 270407.15 | I26: =H26 -> 270407.15 | J26: =ROUND((-G26),0)+P26 -> 540813.15 | K26: -35494.023 | M26: 0 | N26: =-K26 -> 35494.023 | O26: =ROUND((J26+N26),0) + P26 -> 576307.15 | P26: =P25+0.01 -> 0.15
A27: 4ºD | C27: Ayala, Roberto Adrian | D27: 0.0094 | E27: 246240.29 | F27: 45839 | G27: -187595.05 | H27: =ROUND((J27/2),0)+P27 -> 93798.16 | I27: =H27 -> 93798.16 | J27: =ROUND((-G27),0)+P27 -> 187595.16 | K27: -58645.241 | M27: =IF(L27=H27,I27,J27) -> 187595.16 | N27: =-K27 -> 58645.241 | O27: =ROUND((J27+N27),0) + P27 -> 246240.16 | P27: =P26+0.01 -> 0.16 | Q27: Pablo Amarilla
A28: 4ºE | C28: Ayala, Roberto Adrian/SKARLATIUK | D28: 0.0087 | E28: 227903.25 | F28: 45839 | G28: -173625.21 | H28: =ROUND((J28/2),0)+P28 -> 86813.17 | I28: =H28 -> 86813.17 | J28: =ROUND((-G28),0)+P28 -> 173625.17 | K28: -54278.042 | M28: 0 | N28: =-K28 -> 54278.042 | O28: =ROUND((J28+N28),0) + P28 -> 227903.17 | P28: =P27+0.01 -> 0.17
A29: 4ºF | C29: Ayala, Roberto Adrian | D29: 0.0095 | E29: 248859.87 | F29: 45839 | G29: -189590.74 | H29: =ROUND((J29/2),0)+P29 -> 94796.18 | I29: =H29 -> 94796.18 | J29: =ROUND((-G29),0)+P29 -> 189591.18 | K29: -59269.126 | M29: =IF(L29=H29,I29,J29) -> 189591.18 | N29: =-K29 -> 59269.126 | O29: =ROUND((J29+N29),0) + P29 -> 248860.18 | P29: =P28+0.01 -> 0.18
A30: 5ºA | C30: Chehab, Gabriel Adrian | D30: 0.0164 | E30: 429610.72 | F30: 45800 | G30: -388452 | H30: =ROUND((J30/2),0)+P30 -> 194226.19 | I30: =H30 -> 194226.19 | J30: =ROUND((-G30),0)+P30 -> 388452.19 | K30: -41158.726 | M30: 0 | N30: =-K30 -> 41158.726 | O30: =ROUND((J30+N30),0) + P30 -> 429611.19 | P30: =P29+0.01 -> 0.19 | Q30: Cochera 38
A31: 5ºB | B31: 16 | C31: Mesa, Mariano | D31: 0.0096 | E31: 251479.45 | F31: 45805 | G31: -224422.45 | H31: =ROUND((J31/2),0)+P31 -> 112211.2 | I31: =H31 -> 112211.2 | J31: =ROUND((-G31),0)+P31 -> 224422.2 | K31: -27056.996 | M31: 0 | N31: =-K31 -> 27056.996 | O31: =ROUND((J31+N31),0) + P31 -> 251479.2 | P31: =P30+0.01 -> 0.2
A32: 5ºC | B32: 6 | C32: Di Mito, Vicente Argentino - Serantes, Mabel | D32: 0.0197 | E32: 516056.79 | F32: 45805 | G32: -460533.57 | H32: =ROUND((J32/2),0)+P32 -> 230267.21 | I32: =H32 -> 230267.21 | J32: =ROUND((-G32),0)+P32 -> 460534.21 | K32: -55523.211 | M32: =IF(L32=H32,I32,J32) -> 460534.21 | N32: =-K32 -> 55523.211 | O32: =ROUND((J32+N32),0) + P32 -> 516057.21 | P32: =P31+0.01 -> 0.21
A33: 5ºD | C33: Ayala, Roberto Adrian | D33: 0.0094 | E33: 246240.29 | F33: 45839 | G33: -187595.05 | H33: =ROUND((J33/2),0)+P33 -> 93798.22 | I33: =H33 -> 93798.22 | J33: =ROUND((-G33),0)+P33 -> 187595.22 | K33: -58645.241 | L33: =J33 -> 187595.22 | M33: 0 | N33: =-K33 -> 58645.241 | O33: =ROUND((J33+N33),0) + P33 -> 246240.22 | P33: =P32+0.01 -> 0.22 | Q33: Ayala paga 5D, 5F y 4F
A34: 5ºE | B34: 31 | C34: Ayala, Roberto Adrian/CALZETTA/ BASAEZ ROGELIO | D34: 0.011 | E34: 288153.53 | F34: 45839 | G34: -219526.13 | H34: =ROUND((J34/2),0)+P34 -> 109763.23 | I34: =H34 -> 109763.23 | J34: =ROUND((-G34),0)+P34 -> 219526.23 | K34: -68627.409 | M34: 0 | N34: =-K34 -> 68627.409 | O34: =ROUND((J34+N34),0) + P34 -> 288154.23 | P34: =P33+0.01 -> 0.23 | Q34: COCHERA 31
A35: 5ºF | C35: Ayala, Roberto Adrian | D35: 0.0095 | E35: 248859.87 | F35: 45839 | G35: -189590.74 | H35: =ROUND((J35/2),0)+P35 -> 94796.24 | I35: =H35 -> 94796.24 | J35: =ROUND((-G35),0)+P35 -> 189591.24 | K35: -59269.126 | M35: =IF(L35=H35,I35,J35) -> 189591.24 | N35: =-K35 -> 59269.126 | O35: =ROUND((J35+N35),0) + P35 -> 248860.24 | P35: =P34+0.01 -> 0.24
A36: 6ºA | B36: 28 | C36: Morandi, Victoria Ayelen | Calvo, Luciano Ezequiel | D36: 0.0187 | E36: 489861.01 | F36: 45786 | G36: -452316.22 | H36: =ROUND((J36/2),0)+P36 -> 226158.25 | I36: =H36 -> 226158.25 | J36: =ROUND((-G36),0)+P36 -> 452316.25 | K36: -37544.789 | M36: 0 | N36: =-K36 -> 37544.789 | O36: =ROUND((J36+N36),0) + P36 -> 489861.25 | P36: =P35+0.01 -> 0.25
A37: 6ºB | C37: GRIZEK RUBEN EDUARDO (ex Orellano) | D37: 0.0073 | E37: 191229.16 | F37: 45789 | G37: -175787.47 | H37: =ROUND((J37/2),0)+P37 -> 87894.26 | I37: =H37 -> 87894.26 | J37: =ROUND((-G37),0)+P37 -> 175787.26 | K37: -15441.693 | L37: 0 | M37: 0 | N37: =-K37 -> 15441.693 | O37: =ROUND((J37+N37),0) + P37 -> 191229.26 | P37: =P36+0.01 -> 0.26
A38: 6ºC | B38: 33 | C38: Nuñez Leonel - Corrieri Giuliana | D38: 0.0197 | E38: 516056.79 | F38: 45793 | G38: -471560.19 | H38: =ROUND((J38/2),0)+P38 -> 235780.27 | I38: =H38 -> 235780.27 | J38: =ROUND((-G38),0)+P38 -> 471560.27 | K38: -44496.598 | M38: 0 | N38: =-K38 -> 44496.598 | O38: =ROUND((J38+N38),0) + P38 -> 516057.27 | P38: =P37+0.01 -> 0.27 | Q38: COCHERA 33 | R38: COCHERA 33
A39: 6ºD | B39: 44 | C39: ANCHIPI GASTON (Cedido x Hecimovic)Hecimovic, Mariano Hernán (Cedido x Lopez Malara, Ramiro Alejandro) | D39: 0.0117 | E39: 306490.58 | F39: 45800 | G39: -277127.34 | H39: =ROUND((J39/2),0)+P39 -> 138564.28 | I39: =H39 -> 138564.28 | J39: =ROUND((-G39),0)+P39 -> 277127.28 | K39: -29363.237 | M39: 238127.28 | N39: =-K39 -> 29363.237 | O39: =ROUND((J39+N39),0) + P39 -> 306491.28 | P39: =P38+0.01 -> 0.28
A40: 6ºE | C40: Dieci, Matias Orlando | D40: 0.0087 | E40: 227903.25 | F40: 45800 | G40: -206069.05 | H40: =ROUND((J40/2),0)+P40 -> 103035.29 | I40: =H40 -> 103035.29 | J40: =ROUND((-G40),0)+P40 -> 206069.29 | K40: -21834.202 | M40: 0 | N40: =-K40 -> 21834.202 | O40: =ROUND((J40+N40),0) + P40 -> 227903.29 | P40: =P39+0.01 -> 0.29
A41: 6ºF | C41: ALEXIA JOANA MAZZIA | D41: 0.0095 | E41: 248859.87 | F41: 45800 | G41: -225017.93 | H41: =ROUND((J41/2),0)+P41 -> 112509.3 | I41: =H41 -> 112509.3 | J41: =ROUND((-G41),0)+P41 -> 225018.3 | K41: -23841.945 | M41: 0 | N41: =-K41 -> 23841.945 | O41: =ROUND((J41+N41),0) + P41 -> 248860.3 | P41: =P40+0.01 -> 0.3
A42: 7ºA | B42: 7 | C42: Campelo, Mariano | D42: 0.0187 | E42: 489861.01 | F42: 45806 | G42: -435275.01 | H42: =ROUND((J42/2),0)+P42 -> 217638.31 | I42: =H42 -> 217638.31 | J42: =ROUND((-G42),0)+P42 -> 435275.31 | K42: -54586.004 | M42: 0 | N42: =-K42 -> 54586.004 | O42: =ROUND((J42+N42),0) + P42 -> 489861.31 | P42: =P41+0.01 -> 0.31
A43: 7ºB | B43: 3 | C43: Paes, Yazmin Luciana | D43: 0.0096 | E43: 251479.45 | F43: 45775 | G43: -235991.15 | H43: =ROUND((J43/2),0)+P43 -> 117996.32 | I43: =H43 -> 117996.32 | J43: =ROUND((-G43),0)+P43 -> 235991.32 | K43: -15488.301 | M43: 0 | N43: =-K43 -> 15488.301 | O43: =ROUND((J43+N43),0) + P43 -> 251480.32 | P43: =P42+0.01 -> 0.32
...

Sheet ANOTACIONES
C2: ANOTACION | D2: 1
C3: FECHA DE LA ANOTACION: | E3: 0 | G3: NOMBRE: | H3: Ferraro jose
C4: QUEJA VIA: | D4: WHATSAPP | E4: MAIL | G4: LOTE:
C5: MOTIVO DE LA QUEJA:
C6: Adjunto el comprobante de pago de las expensas netas de la cochera 30 , $58.102,08 07/05
C11: ANOTACION | D11: =D2+1 -> 2
C12: FECHA DE LA ANOTACION: | E12: 0 | G12: NOMBRE: | H12: Ferraro jose
C13: QUEJA VIA: | D13: WHATSAPP | E13: MAIL | G13: LOTE:
C14: MOTIVO DE LA QUEJA:
C15: Deposito $382.000 el 08/05: Dto 2D. 53.453 Dto 2F. 54.022 Dto3A. 93.827 Dto3C. 101.220 ———————- 302.522.- Más 78.474.- ——————- 382.000.- Las cocheras son 29/30/34/37/38/39 6 X 13.079=78.474
C20: ANOTACION | D20: =D11+1 -> 3
C21: FECHA DE LA ANOTACION: | E21: 0 | G21: NOMBRE: | H21: Gaston Smith
C22: QUEJA VIA: | D22: WHATSAPP | E22: MAIL | G22: LOTE: | H22: 6E y Cochera 12
C23: MOTIVO DE LA QUEJA:
C24: El ultimo dia de abril el abono 102.165,29 para el 6E y 27.009,81 para la cochera 12 corregir
C29: ANOTACION | D29: =D20+1 -> 4
C30: FECHA DE LA ANOTACION: | E30: 0 | G30: NOMBRE: | H30: Local 2
C31: QUEJA VIA: | D31: WHATSAPP | E31: MAIL | G31: LOTE: | H31: Local 2
C32: MOTIVO DE LA QUEJA:
C33: Pago $244.445 el 19/05
C38: ANOTACION | D38: =D29+1 -> 5
C39: FECHA DE LA ANOTACION: | E39: 0 | G39: NOMBRE: | H39: 10B
C40: QUEJA VIA: | D40: WHATSAPP | E40: MAIL | G40: LOTE: | H40: 10B | I40: IMPORTANTE!
C41: MOTIVO DE LA QUEJA:
C42: 10B en marzo pago $81.371,5 y se lo pusimos en ARBA cuando le tenia que quedar a favor en las expensas
