Workbook

Sheet RESUMEN
B1: Domicilio: Dr. Melo Nº 2958 - 8VO PISO - Con cita previa
B2: consorciobelgrano1640@gmail.com
B3: Santander cuenta 039-010552/1
B4: CBU: 0720039720000001055218
A5: LIQUIDACION DE EXPENSAS | B5: PERÍODO: JULIO | C5: VTO: 14/08
A6: CUIT: 33-71826987-9
A7: CONSORCIO DE PROPIETARIOS DEL EDIFICIO CALLE BELGRANO NUMERO 1640/1646 BANFIELD PARTIDO DE LOMAS DE ZAMORA
B14: Los gastos que se encuentras subrayados son los que corresponden tanto a las unidades funcionales como tambien al local
A21: GASTOS ORDINARIOS UNIDADES FUNCIONALES: | E21: UF 91,91% | F21: LOCAL 8,09%
A22: Sr. Diego Britez | B22: Honorarios JULIO
A23: Haberes | D23: 1869737.2 | E23: =D23*91.91% -> 1718475.5 | F23: =D23*8.09% -> 151261.74
A24: Deducciones | D24: -406667.86 | E24: =D24*91.91% -> -373768.43 | F24: =D24*8.09% -> -32899.43
A25: Redondeo | D25: 0.61 | E25: =D25*91.91% -> 0.560651 | F25: =D25*8.09% -> 0.049349
A27: TOTAL SUELDO | D27: =SUM(D23:D26) -> 1463070 | E27: =SUM(E23:E26) -> 1344707.6 | F27: =SUM(F23:F26) -> 118362.36 | G27: =E27+F27 -> 1463070 | H27: =IF(D27=G27, "", "Error")
A28: SAC | D28: 0 | E28: =D28*91.91% -> 0 | F28: =D28*8.09% -> 0
D29: 0 | E29: =D29*91.91% -> 0 | F29: =D29*8.09% -> 0
A32: TOTAL | D32: =SUM(D28:D30) -> 0 | E32: =SUM(E28:E30) -> 0 | F32: =SUM(F28:F30) -> 0 | G32: =E32+F32 -> 0 | H32: =IF(D32=G32, "", "Error")
A33: SAC | E33: =D33*91.91% -> 0 | F33: =D33*8.09% -> 0
A34: Redondeo | E34: =D34*91.91% -> 0 | F34: =D34*8.09% -> 0
A35: Deducciones | E35: =D35*91.91% -> 0 | F35: =D35*8.09% -> 0
A36: TOTAL SAC | D36: =SUM(D29:D35) -> 0 | E36: =SUM(E29:E35) -> 0 | F36: =E36*8.09% -> 0
A40: TOTAL | E40: =SUM(D37:D39) -> 0 | F40: =(D37)*8.09% -> 0
A41: Seguro de vida Sra. Monica | D41: 3567.21 | E41: =D41*91.91% -> 3278.6227 | F41: =D41*8.09% -> 288.58729
A42: Reemplazo Sr. Diego - Monica Gorosito | D42: 37000 | E42: =D42*91.91% -> 34006.7 | F42: =D42*8.09% -> 2993.3
E43: =D43*91.91% -> 0 | F43: =D43*8.09% -> 0
A44: TOTAL REEMPLAZO | D44: =SUM(D41:D43) -> 40567.21 | E44: =SUM(E41:E43) -> 37285.323 | F44: =SUM(F41:F43) -> 3281.8873 | G44: =E44+F44 -> 40567.21
A45: APORTES Y CONTRIBUCIONES
A46: SEGURO OBLIGATORIO SR DIEGO BRITEZ FEDERACION PATRONAL DEBITO AUTOMATICO 04/06 | D46: 5020 | E46: =D46*91.91% -> 4613.882 | F46: =D46*8.09% -> 406.118
A47: SUTERH - FATERYH - SARACAH | B47: Debito 12/06 | D47: =157828.92+9348.69+84138.18 -> 251315.79 | E47: =D47*91.91% -> 230984.34 | F47: =D47*8.09% -> 20331.447
A48: ARCA | B48: Pago mis cuentas 12/06 | D48: 828107.55 | E48: =D48*91.91% -> 761113.65 | F48: =D48*8.09% -> 66993.901
A49: TOTAL Aportes y Contribuciones - Sindicato | D49: =SUM(D46:D48) -> 1084443.3 | E49: =SUM(E46:E48) -> 996711.87 | F49: =SUM(F46:F48) -> 87731.466 | G49: =E49+F49 -> 1084443.3 | H49: =IF(D49=G49, "", "Error")
A50: ABONOS Y SERVICIOS
A51: Contessi - Cuota 2 de arreglo montavehiculos | D51: 960000 | E51: =D51 -> 960000 | G51: =D51 -> 960000 | H51: =E51+F51 -> 960000 | I51: =H51-D51 -> 0 | J51: =G51-D51 -> 0
A52: Contessi - Mantenimiento de ascensores | D52: 372000 | E52: =D52 -> 372000 | G52: =D52 -> 372000 | H52: =E52+F52 -> 372000 | I52: =H52-D52 -> 0
A53: Riesgo Uno - Reemplazo de detector, verificacion de cableado, pulsadores y panel - Mano de obra y materiales | D53: 165500 | E53: =D53*91.91% -> 152111.05 | F53: =D53*8.09% -> 13388.95 | G53: =D53 -> 165500 | H53: =E53+F53 -> 165500 | I53: =H53-D53 -> 0 | J53: =G53-D53 -> 0
A54: Riesgo Uno | D54: 148124.67 | E54: =D54*91.91% -> 136141.38 | F54: =D54*8.09% -> 11983.286 | G54: =D54 -> 148124.67 | H54: =E54+F54 -> 148124.67
A55: Energoup MES DE JULIO | D55: 148200 | E55: =D55*91.91% -> 136210.62 | F55: =D55*8.09% -> 11989.38 | G55: =D55 -> 148200 | H55: =E55+F55 -> 148200 | I55: =H55-D55 -> 0 | J55: =G55-D55 -> 0
A56: Seguro Poliza | B56: Numero 1859135 Debito automatico 02/06 | D56: 74623.7 | E56: =D56*91.91% -> 68586.643 | F56: =D56*8.09% -> 6037.0573 | G56: =D56 -> 74623.7 | H56: =E56+F56 -> 74623.7 | I56: =H56-D56 -> 0 | J56: =G56-D56 -> 0
A57: AYSA | D57: 614674.98 | E57: =D57*91.91% -> 564947.77 | F57: =D57*8.09% -> 49727.206 | G57: =D57 -> 614674.98 | H57: =E57+F57 -> 614674.98 | I57: =H57-D57 -> 0 | J57: =G57-D57 -> 0
A58: EDESUR | B58: Debito 27/07 | D58: 1101493.9 | E58: =D58*91.91% -> 1012383.1 | F58: =D58*8.09% -> 89110.86 | G58: =D58 -> 1101493.9 | H58: =E58+F58 -> 1101493.9 | I58: =H58-D58 -> 0 | J58: =G58-D58 -> 0
...

Sheet PRORRATEO
F1: ESTADO DE CUENTA Y PRORRATEO | K1: SE GASTO: | L1: =RESUMEN!D92 -> 8307924.1 | O1: =L1*8.09% -> 672111.06
K2: SE PRORRATEA EN LAS UF: | M2: =(5500000-150000-3015-250-12+1997000+170000+5497+450+30) -> 7519700 | O2: =O1-K7-553-50-86-8 -> 259256.38
A3: =RESUMEN!C5 -> VTO: 14/08 | K3: EXPENSAS EXTRA: | M3: =RESUMEN!D105 -> 0
J4: =(J3*8.09%)/44 -> 0 | K4: SE PRORRATEA EN LAS UF: | M4: 0
A5: Piso | B5: Dpto. | C5: UF | D5: Propietario | E5: (%) | F5: Saldo | G5: Ingreso | H5: SALDO | I5: Fecha | J5: Expensas extraor. | K5: Expensas ord | L5: SUM/ GASTOS PART | M5: TOTAL EXPENSAS 1er VTO | N5: TOTAL EXPENSAS 2do VTO
A7: PB | C7: 1 | D7: LOCAL 1 - DANIEL VIDAL | E7: 8.09 | F7: 423542.39 | G7: =F7 -> 423542.39 | H7: =F7-G7 -> 0 | I7: 13 | K7: 412157.68 | L7: 0 | M7: =K7+J7+H7+L7 -> 412157.68 | N7: =M7*6% + M7 -> 436887.14
A8: 3º | C8: 24 | D8: RODRIGUEZ, MARIA ROSA | E8: 2.21 | F8: 151158.85 | G8: 144100 | H8: =F8-G8 -> 7058.845 | I8: 10 | J8: =M$4*E8% -> 0 | K8: =M$2*E8 /100 -> 166185.37 | L8: =J$3*E8%+J$4 -> 0 | M8: =K8+J8+H8+L8 -> 173244.22 | N8: =M8*6% + M8 -> 183638.87
A9: 3º | C9: 25 | D9: RUSSO, JUAN ANTONIO | E9: 4.21 | F9: 177670.97 | G9: =214701-G34 -> 177670.98 | H9: =F9-G9 -> -0.0017157367 | I9: 5 | J9: =M$4*E9% -> 0 | K9: =M$2*E9 /100 -> 316579.37 | L9: 10000 | M9: =K9+J9+H9+L9 -> 326579.37 | N9: =M9*6% + M9 -> 346174.13
A10: 4º | C10: 26 | D10: SALLABER, MARIA | E10: 2.84 | F10: 229352.21 | G10: 185159 | H10: =F10-G10 -> 44193.206 | I10: 6 | J10: =M$4*E10% -> 0 | K10: =M$2*E10 /100 -> 213559.48 | L10: =J$3*E10%+J$4 -> 0 | M10: =K10+J10+H10+L10 -> 257752.69 | N10: =M10*6% + M10 -> 273217.85
A11: 4º | C11: 27 | D11: COLATRELLA, CAROLINA | E11: 3.43 | F11: 235209.23 | G11: =223626 -> 223626 | H11: =F11-G11 -> 11583.232 | I11: 9 | J11: =M$4*E11% -> 0 | K11: =M$2*E11 /100 -> 257925.71 | L11: =J$3*E11%+J$4 -> 0 | M11: =K11+J11+H11+L11 -> 269508.94 | N11: =M11*6% + M11 -> 285679.48
A12: 5º | C12: 28 | D12: LUSENSKY, CARLOS | E12: 2.84 | F12: 194750.5 | G12: =F12 -> 194750.5 | H12: =F12-G12 -> 0 | I12: 3 | J12: =M$4*E12% -> 0 | K12: =M$2*E12 /100 -> 213559.48 | L12: 10000 | M12: =K12+J12+H12+L12 -> 223559.48 | N12: =M12*6% + M12 -> 236973.05
A13: 5º | C13: 29 | D13: DI TORO, ALEJANDRO | E13: 3.43 | F13: 235208.87 | G13: =235209-G50 -> 194750.27 | H13: =F13-G13 -> 40458.603 | I13: 3 | J13: =M$4*E13% -> 0 | K13: =M$2*E13 /100 -> 257925.71 | L13: 10000 | M13: =K13+J13+H13+L13 -> 308384.31 | N13: =M13*6% + M13 -> 326887.37
A14: 6º | C14: 30 | D14: PERAZA, MARTHA | E14: 2.84 | F14: 194750.5 | G14: =185159 -> 185159 | H14: =F14-G14 -> 9591.5008 | I14: 14 | J14: =M$4*E14% -> 0 | K14: =M$2*E14 /100 -> 213559.48 | L14: =J$3*E14%+J$4 -> 0 | M14: =K14+J14+H14+L14 -> 223150.98 | N14: =M14*6% + M14 -> 236540.04
A15: 6º | C15: 31 | D15: BALBOA, ARIEL | E15: 3.43 | F15: 235208.62 | G15: =235209+34287-G35 -> 235208.94 | H15: =F15-G15 -> -0.32395347 | I15: 3 | J15: =M$4*E15% -> 0 | K15: =M$2*E15 /100 -> 257925.71 | L15: =J$3*E15%+J$4 -> 0 | M15: =K15+J15+H15+L15 -> 257925.39 | N15: =M15*6% + M15 -> 273400.91
A16: 7º | C16: 32 | D16: FEUILLANT, GASTON | E16: 2.84 | F16: 220949.43 | G16: =220949+33601-G49 -> 220948.68 | H16: =F16-G16 -> 0.74460066 | I16: 6 | J16: =M$4*E16% -> 0 | K16: =M$2*E16 /100 -> 213559.48 | L16: 0 | M16: =K16+J16+H16+L16 -> 213560.22 | N16: =M16*6% + M16 -> 226373.84
A17: 7º | C17: 33 | D17: CAMPANA, NESTOR | E17: 3.43 | F17: 250529.74 | G17: =318418-G47-G48 -> 250529.62 | H17: =F17-G17 -> 0.12371111 | I17: 11 | J17: =M$4*E17% -> 0 | K17: =M$2*E17 /100 -> 257925.71 | L17: =J$3*E17%+J$4 -> 0 | M17: =K17+J17+H17+L17 -> 257925.83 | N17: =M17*6% + M17 -> 273401.38
A18: 8º | C18: 34 | D18: JARA, CLAUDIO | E18: 2.84 | F18: 194180.5 | G18: =223000-G51 -> 183912.75 | H18: =F18-G18 -> 10267.744 | I18: 12 | J18: =M$4*E18% -> 0 | K18: =M$2*E18 /100 -> 213559.48 | L18: =J$3*E18%+J$4 -> 0 | M18: =K18+J18+H18+L18 -> 223827.22 | N18: =M18*6% + M18 -> 237256.86
A19: 8º | C19: 35 | D19: MIRAMONTES, HORACIO | E19: 3.43 | F19: 235209.46 | G19: =272239-G41 -> 235208.98 | H19: =F19-G19 -> 0.48276517 | I19: 3 | J19: =M$4*E19% -> 0 | K19: =M$2*E19 /100 -> 257925.71 | L19: =J$3*E19%+J$4 -> 0 | M19: =K19+J19+H19+L19 -> 257926.19 | N19: =M19*6% + M19 -> 273401.76
A20: 9º | C20: 36 | D20: MELINA, ANDRES | E20: 2.84 | F20: 194750.27 | G20: =217106-G38 -> 183504.68 | H20: =F20-G20 -> 11245.59 | I20: 3 | J20: =M$4*E20% -> 0 | K20: =M$2*E20 /100 -> 213559.48 | L20: =J$3*E20%+J$4 -> 0 | M20: =K20+J20+H20+L20 -> 224805.07 | N20: =M20*6% + M20 -> 238293.37
A21: 9º | C21: 37 | D21: GARCIA, MARIA SOL | E21: 3.43 | F21: 235209.86 | G21: =272240-G45 -> 235209.98 | H21: =F21-G21 -> -0.1149082 | I21: 4 | J21: =M$4*E21% -> 0 | K21: =M$2*E21 /100 -> 257925.71 | L21: =J$3*E21%+J$4 -> 0 | M21: =K21+J21+H21+L21 -> 257925.6 | N21: =M21*6% + M21 -> 273401.13
A22: 10º | C22: 38 | D22: RATON, MARIELA | E22: 2.84 | F22: 194750.5 | G22: 185159 | H22: =F22-G22 -> 9591.5008 | I22: 3 | J22: =M$4*E22% -> 0 | K22: =M$2*E22 /100 -> 213559.48 | L22: =J$3*E22%+J$4 -> 0 | M22: =K22+J22+H22+L22 -> 223150.98 | N22: =M22*6% + M22 -> 236540.04
A23: 10º | C23: 39 | D23: DAVIN, ALEJANDRO | E23: 3.43 | F23: 57370.666 | G23: =118871-G46 -> 84583.94 | H23: =F23-G23 -> -27213.274 | I23: 4 | J23: =M$4*E23% -> 0 | K23: =M$2*E23 /100 -> 257925.71 | L23: 10000 | M23: =K23+J23+H23+L23 -> 240712.44 | N23: =M23*6% + M23 -> 255155.18
A24: 11º | C24: 40 | D24: VROONLAND, DANIEL | E24: 2.84 | F24: 191483.99 | G24: =232000-G37 -> 198398.68 | H24: =F24-G24 -> -6914.6925 | I24: 5 | J24: =M$4*E24% -> 0 | K24: =M$2*E24 /100 -> 213559.48 | L24: =J$3*E24%+J$4 -> 0 | M24: =K24+J24+H24+L24 -> 206644.79 | N24: =M24*6% + M24 -> 219043.47
A25: 11º | C25: 41 | D25: SIMONASSI, ALEJO | E25: 3.43 | F25: 235209.23 | G25: =F25 -> 235209.23 | H25: =F25-G25 -> 0 | I25: 6 | J25: =M$4*E25% -> 0 | K25: =M$2*E25 /100 -> 257925.71 | L25: 10000 | M25: =K25+J25+H25+L25 -> 267925.71 | N25: =M25*6% + M25 -> 284001.25
A26: 12º | C26: 42 | D26: VELAZ, ATILIO | E26: 6 | F26: -556256.31 | G26: =-G30-G31-G36 -> -109032.85 | H26: =F26-G26 -> -447223.46 | I26: 5 | J26: =M$4*E26% -> 0 | K26: =M$2*E26 /100 -> 451182 | L26: =J$3*E26%+J$4 -> 0 | M26: =K26+J26+H26+L26 -> 3958.5408 | N26: =M26*6% + M26 -> 4196.0533
A27: 13º | C27: 43 | D27: AGÜERO, MIRIAM S | E27: 5.89 | F27: 403845.13 | G27: =483391-G39-G40 -> 403845.02 | H27: =F27-G27 -> 0.10553527 | I27: 11 | J27: =M$4*E27% -> 0 | K27: =M$2*E27 /100 -> 442910.33 | L27: =J$3*E27%+J$4 -> 0 | M27: =K27+J27+H27+L27 -> 442910.44 | N27: =M27*6% + M27 -> 469485.06
A28: 14º | C28: 44 | D28: VILLA, JUAN MANUEL | E28: 5.89 | F28: 304604.2 | G28: =353860-G32-G33 -> 281171.43 | H28: =F28-G28 -> 23432.764 | I28: 9 | J28: =M$4*E28% -> 0 | K28: =M$2*E28 /100 -> 442910.33 | L28: =J$3*E28%+J$4 -> 0 | M28: =K28+J28+H28+L28 -> 466343.09 | N28: =M28*6% + M28 -> 494323.68
A29: 15º | C29: 45 | D29: TOLOSA, FABIO | E29: 5.89 | F29: 316080.22 | G29: =-G42-G43-G44+RESUMEN!#REF! -> #REF! | H29: =F29-G29 -> #REF! | I29: 5 | J29: =M$4*E29% -> 0 | K29: =M$2*E29 /100 -> 442910.33 | L29: =J$3*E29%+J$4 -> 0 | M29: =K29+J29+H29+L29 -> #REF! | N29: =M29*6% + M29 -> #REF!
A30: COC | C30: 1 | D30: VELAZ, ATILIO | E30: 0.54 | F30: 37030.025 | G30: =F30 -> 37030.025 | H30: =F30-G30 -> 0 | J30: =M$4*E30% -> 0 | K30: =M$2*E30 /100 -> 40606.38 | L30: =J$3*E30%+J$4 -> 0 | M30: =K30+J30+H30+L30 -> 40606.38 | N30: =M30*6% + M30 -> 43042.763
A31: COC | C31: 2 | D31: VELAZ, ATILIO | E31: 0.55 | F31: 37715.766 | G31: =F31 -> 37715.766 | H31: =F31-G31 -> 0 | J31: =M$4*E31% -> 0 | K31: =M$2*E31 /100 -> 41358.35 | L31: =J$3*E31%+J$4 -> 0 | M31: =K31+J31+H31+L31 -> 41358.35 | N31: =M31*6% + M31 -> 43839.851
A32: COC | C32: 3 | D32: VILLA, JUAN MANUEL | E32: 0.45 | F32: 30858.354 | G32: =F32 -> 30858.354 | H32: =F32-G32 -> 0 | J32: =M$4*E32% -> 0 | K32: =M$2*E32 /100 -> 33838.65 | L32: =J$3*E32%+J$4 -> 0 | M32: =K32+J32+H32+L32 -> 33838.65 | N32: =M32*6% + M32 -> 35868.969
A33: COC | C33: 4 | D33: VILLA, JUAN MANUEL | E33: 0.61 | F33: 41830.213 | G33: =F33 -> 41830.213 | H33: =F33-G33 -> 0 | J33: =M$4*E33% -> 0 | K33: =M$2*E33 /100 -> 45870.17 | L33: =J$3*E33%+J$4 -> 0 | M33: =K33+J33+H33+L33 -> 45870.17 | N33: =M33*6% + M33 -> 48622.38
A34: COC | C34: 5 | D34: RUSSO, JUAN ANTONIO | E34: 0.54 | F34: 37030.025 | G34: =F34 -> 37030.025 | H34: =F34-G34 -> 0 | J34: =M$4*E34% -> 0 | K34: =M$2*E34 /100 -> 40606.38 | L34: =J$3*E34%+J$4 -> 0 | M34: =K34+J34+H34+L34 -> 40606.38 | N34: =M34*6% + M34 -> 43042.763
A35: COC | C35: 6 | D35: BALBOA, ARIEL | E35: 0.5 | F35: 34287.06 | G35: =F35 -> 34287.06 | H35: =F35-G35 -> 0 | J35: =M$4*E35% -> 0 | K35: =M$2*E35 /100 -> 37598.5 | L35: =J$3*E35%+J$4 -> 0 | M35: =K35+J35+H35+L35 -> 37598.5 | N35: =M35*6% + M35 -> 39854.41
A36: COC | C36: 7 | D36: VELAZ, ATILIO | E36: 0.5 | F36: 34287.06 | G36: =F36 -> 34287.06 | H36: =F36-G36 -> 0 | J36: =M$4*E36% -> 0 | K36: =M$2*E36 /100 -> 37598.5 | L36: =J$3*E36%+J$4 -> 0 | M36: =K36+J36+H36+L36 -> 37598.5 | N36: =M36*6% + M36 -> 39854.41
A37: COC | C37: 8 | D37: VROONLAND, DANIEL | E37: 0.49 | F37: 33601.319 | G37: =F37 -> 33601.319 | H37: =F37-G37 -> 0 | J37: =M$4*E37% -> 0 | K37: =M$2*E37 /100 -> 36846.53 | L37: =J$3*E37%+J$4 -> 0 | M37: =K37+J37+H37+L37 -> 36846.53 | N37: =M37*6% + M37 -> 39057.322
A38: COC | C38: 9 | D38: MELINA, ANDRES | E38: 0.49 | F38: 33601.319 | G38: =F38 -> 33601.319 | H38: =F38-G38 -> 0 | J38: =M$4*E38% -> 0 | K38: =M$2*E38 /100 -> 36846.53 | L38: =J$3*E38%+J$4 -> 0 | M38: =K38+J38+H38+L38 -> 36846.53 | N38: =M38*6% + M38 -> 39057.322
A39: COC | C39: 10 | D39: AGÜERO, MIRIAM S | E39: 0.59 | F39: 40458.731 | G39: =F39 -> 40458.731 | H39: =F39-G39 -> 0 | J39: =M$4*E39% -> 0 | K39: =M$2*E39 /100 -> 44366.23 | L39: =J$3*E39%+J$4 -> 0 | M39: =K39+J39+H39+L39 -> 44366.23 | N39: =M39*6% + M39 -> 47028.204
A40: COC | C40: 11 | D40: AGÜERO, MIRIAM S | E40: 0.57 | F40: 39087.248 | G40: =F40 -> 39087.248 | H40: =F40-G40 -> 0 | J40: =M$4*E40% -> 0 | K40: =M$2*E40 /100 -> 42862.29 | L40: =J$3*E40%+J$4 -> 0 | M40: =K40+J40+H40+L40 -> 42862.29 | N40: =M40*6% + M40 -> 45434.027
A41: COC | C41: 12 | D41: MIRAMONTES, HORACIO | E41: 0.54 | F41: 37030.025 | G41: =F41 -> 37030.025 | H41: =F41-G41 -> 0 | J41: =M$4*E41% -> 0 | K41: =M$2*E41 /100 -> 40606.38 | L41: =J$3*E41%+J$4 -> 0 | M41: =K41+J41+H41+L41 -> 40606.38 | N41: =M41*6% + M41 -> 43042.763
...

Sheet COCHERA
D1: ESTADO DE CUENTA Y PRORRATEO | L1: Vencimiento | N1: =RESUMEN!C5 -> VTO: 14/08
D2: BELGRANO Nº 1640
J3: Gastos Ordinario: | L3: 249991.3 | N3: -1891.33
J4: Gastos Extr.: | L4: 0
A5: Cochera | B5: Propietario | C5: Porcentaje | D5: Saldo | E5: Ingreso | F5: DEUDAS | G5: Deuda exp | H5: Intereses | I5: porcentaje | J5: Expensas | K5: Expensas | L5: TOTAL | N5: 1ER Vto. | O5: 2DO Vto.
C6: (%) | D6: Anterior | E6: Exp. Ord. | G6: Extraord | H6: 0.06 | I6: % | J6: Ord. | K6: Extr. | L6: EXPENSAS
A7: 1 | B7: VELAZ, ATILIO | C7: 5.4 | D7: 13967.239 | E7: =D7 -> 13967.239 | F7: 0 | G7: 0 | H7: 0 | I7: 0.54 | J7: 11608.2 | K7: 0 | L7: 11608.2 | N7: 11608.2 | O7: 12304.692
A8: 2 | B8: VELAZ, ATILIO | C8: 5.5 | D8: 14267.901 | E8: =D8 -> 14267.901 | F8: 0 | G8: 0 | H8: 0 | I8: 0.55 | J8: 11858.191 | K8: 0 | L8: 11858.191 | N8: 11858.191 | O8: 12569.683
A9: 3 | B9: VILLA, JUAN MANUEL | C9: 4.5 | D9: 11261.283 | E9: =D9 -> 11261.283 | F9: 0 | G9: 0 | H9: 0 | I9: 0.45 | J9: 9358.2784 | K9: 0 | L9: 9358.2784 | N9: 9358.2784 | O9: 9919.7751
A10: 4 | B10: VILLA, JUAN MANUEL | C10: 6.1 | D10: 16071.872 | E10: =D10 -> 16071.872 | F10: 0 | G10: 0 | H10: 0 | I10: 0.61 | J10: 13358.139 | K10: 0 | L10: 13358.139 | N10: 13358.139 | O10: 14159.628
A11: 5 | B11: RUSSO, JUAN ANTONIO | C11: 5.4 | D11: 13967.239 | E11: =D11 -> 13967.239 | F11: 0 | G11: 0 | H11: 0 | I11: 0.54 | J11: 11608.2 | K11: 0 | L11: 11608.2 | N11: 11608.2 | O11: 12304.692
A12: 6 | B12: MARANTE, MAURO | C12: 5 | D12: 12764.592 | E12: =D12 -> 12764.592 | F12: 0 | G12: 0 | H12: 0 | I12: 0.5 | J12: 10608.235 | K12: 0 | L12: 10608.235 | N12: 10608.235 | O12: 11244.729
A13: 7 | B13: VELAZ, ATILIO | C13: 5 | D13: 12764.592 | E13: =D13 -> 12764.592 | F13: 0 | G13: 0 | H13: 0 | I13: 0.5 | J13: 10608.235 | K13: 0 | L13: 10608.235 | N13: 10608.235 | O13: 11244.729
A14: 8 | B14: VROONLAND, DANIEL | C14: 4.9 | D14: 12463.93 | E14: =D14 -> 12463.93 | F14: 0 | G14: 0 | H14: 0 | I14: 0.49 | J14: 10358.244 | K14: 0 | L14: 10358.244 | N14: 10358.244 | O14: 10979.738
A15: 9 | B15: MELINA, ANDRES | C15: 4.9 | D15: 12463.93 | E15: =D15 -> 12463.93 | F15: 0 | G15: 0 | H15: 0 | I15: 0.49 | J15: 10358.244 | K15: 0 | L15: 10358.244 | N15: 10358.244 | O15: 10979.738
A16: 10 | B16: AGÜERO, MIRIAM S | C16: 5.9 | D16: 15470.549 | E16: =D16 -> 15470.549 | F16: 0 | G16: 0 | H16: 0 | I16: 0.59 | J16: 12858.157 | K16: 0 | L16: 12858.157 | N16: 12858.157 | O16: 13629.646
A17: 11 | B17: AGÜERO, MIRIAM S | C17: 5.7 | D17: 14869.225 | E17: =D17 -> 14869.225 | F17: 0 | G17: 0 | H17: 0 | I17: 0.57 | J17: 12358.174 | K17: 0 | L17: 12358.174 | N17: 12358.174 | O17: 13099.664
A18: 12 | B18: MIRAMONTES, HORACIO | C18: 5.4 | D18: 13967.239 | E18: =D18 -> 13967.239 | F18: 0 | G18: 0 | H18: 0 | I18: 0.54 | J18: 11608.2 | K18: 0 | L18: 11608.2 | N18: 11608.2 | O18: 12304.692
... A28: 22 | B28: JARA, CLAUDIO | C28: 5.7 | D28: 14869.225 | E28: =D28 -> 14869.225 | F28: 0 | G28: 0 | H28: 0 | I28: 0.57 | J28: 12358.174 | K28: 0 | L28: 12358.174 | N28: 12358.174 | O28: 13099.664
C30: 116.6 | D30: 161487.47 | E30: 161487.47 | F30: 0 | G30: 0 | H30: 0 | I30: 11.66 | J30: 249880.59 | K30: 0 | L30: 249880.59 | N30: 249880.59 | O30: 264873.43
