Workbook

Sheet RESUMEN
B1: MAIL: consorciovergara1670@gmail.com
B2: CUIT ADMINISTRACION: 27231256879
B3: CBU: 2990024602400258030006 | D3: TELEFONO: 11 5320-2676
A4: LIQUIDACION DE EXPENSAS | B4: ALIAS: VERGARA.1670
A5: CUIT DEL EDIFICIO: 30-71802922-4 | B5: PERÍODO: MARZO - ADMINISTRADORA: CAROLINA CANCIANI MP:1148
A6: CONSORCIO DE PROPIETARIOS DEL EDIFICIO CALLE VERGARA 1670 | D6: HORARIOS DE ATENCION: LUNES A VIERNES
B8: VTO 14/04
A13: ESTIMADOS PROPIETARIOS E INQUILINOS: POR FAVOR LOS QUE ABONAN EN PRIMER VENCIMIENTO ABONEN EL MONTO DE PRIMER VENCIMIENTO, ASI AGILIZAN LA LIQUIDACION, LES PEDIMOS ENCARECIDAMENTE QUE RESPETEN LOS CENTAVOS CORRESPONDIENTES A LA UNIDAD FUNCIONAL. ES DE CARÁCTER OBLIGATORIO INFORMAR VIA MAIL LAS EXPENSAS.
A20: GASTOS ORDINARIOS UNIDADES FUNCIONALES:
A21: HABERES ENCARGADOS
A22: Remunerativos encargado Gonzalo Guenaga | D22: 590585.1
A23: Deducciones | D23: -138117.69
A24: Redondeo | D24: 0.59
A25: Neto | D25: =SUM(D22:D24) -> 452468
A26: Sueldo a pagar por la administracion saliente ya abonado | D26: 445381
A27: TOTAL SUELDO | E27: =D25+D26 -> 897849
A28: HONORARIOS
A29: Marcela De Biase- Sra. Contadora - Mes de Marzo | D29: 28000 | E29: Transf 19/03
A30: Honorarios administracion - Mes de Marzo - No se abonan por falta de caja
A31: TOTAL | E31: =SUM(D29:D30) -> 28000
A32: SEGUROS
A33: Seguro integral consorcio. Póliza 346504 Mapfre (4116-6397/6652 4458-5065) | D33: 226692
A34: Seguro de accidentes personales. Póliza 2151088 Mapfre | D34: 719.9
A35: TOTAL IMPUESTO | E35: =SUM(D33:D34) -> 227411.9
A36: APORTES Y CONTRIBUCIONES
A37: ARCA | D37: 299291.16 | E37: Debito 19/03
A38: Sindicatos mes de MARZO | B38: Fatheryh | D38: 26307.3 | E38: Debito 13/03
A39: =A38 -> Sindicatos mes de MARZO | B39: Suther | D39: 54080.16 | E39: =E38 -> Debito 13/03
A40: =A39 -> Sindicatos mes de MARZO | B40: Seracarh | D40: 2923 | E40: =E38 -> Debito 13/03
A41: TOTAL Aportes y Contribuciones - Sindicato | E41: =SUM(D37:D40) -> 382601.62
A42: ABONOS Y SERVICIOS
A43: AYSA - Nro de cliente. 318350 | D43: 38133.98 | E43: Transf 19/03
A44: Servicio de mantenimiento de ascensores - ADS | D44: 35000 | E44: Transf 25/03
A47: TOTAL ABONOS Y SERVICIOS | E47: =SUM(D43:D46) -> 73133.98
A48: GASTOS GENERALES / MANTENIMIENTO
A49: Extintores triclase ABC x 5kg - recarga anual | D49: 181500 | E49: Transf 19/03
A50: Mano de obra emergencias plomeria - Doartero Julio | D50: 185000 | E50: Transf 19/03
A51: Reparacion rampa de cocheras | D51: 110000 | E51: Transf 19/03
A52: JPL articulos de limpieza - NO SE ABONAN POR FALTA DE CAJA
A53: Ajuste de medidores | D53: 110000 | E53: Transf 31/03
...

Sheet PRORRATEO
D1: EDESUR | E1: EDESUR: | F1: 2306985.9 | J1: EXPENSAS ORD | K1: Gastos Ordinarios: | M1: =P1 -> 3600000 | P1: 3600000
D2: METROGAS | E2: METROGAS: | F2: 566376.62 | J2: EXPENSAS EXTRAORD | K2: Gastos extraordinarios:
A3: Dpto. | C3: UF | D3: Propietario | E3: Inquilinos | F3: (%) | G3: Saldo Ord | H3: Ingreso | I3: Deuda o Saldo a favor | J3: Interes 3% | K3: Expensas extraor. | L3: Expensas ord. | M3: EDESUR | N3: METROGAS | O3: Total 1er Vto | P3: Total 2do Vto
O4: =RESUMEN!B8 -> VTO 14/04
B5: 1°A | C5: 33 | D5: Alejandro Raul Cuezzo | F5: 0.0202 | G5: 113493.34 | H5: =G5 -> 113493.34 | I5: =G5-H5 -> 0 | J5: =IF(I5>0,I5*3%,0) -> 0 | K5: =M$2*F5 -> 0 | L5: =M$1*F5 -> 72720 | M5: =F$1*F5 -> 46601.115 | N5: =F$2*F5 -> 11440.808 | O5: =ROUND(SUM(I5:N5),0) + Q5 -> 130762.33 | P5: =ROUND(O5*3%,0) + O5 -> 134685.33 | Q5: =ROUND(0.001+C5/100,2) -> 0.33
B6: 1°B | C6: 34 | D6: Daniel Julian Guzzo | F6: 0.0139 | G6: 134635.46 | H6: 54364 | I6: =G6-H6 -> 80271.464 | J6: =IF(I6>0,I6*3%,0) -> 2408.1439 | K6: =M$2*F6 -> 0 | L6: =M$1*F6 -> 50040 | M6: =F$1*F6 -> 32067.104 | N6: =F$2*F6 -> 7872.635 | O6: =ROUND(SUM(I6:N6),0) + Q6 -> 172659.34 | P6: =ROUND(O6*3%,0) + O6 -> 177839.34 | Q6: =ROUND(0.001+C6/100,2) -> 0.34
A7: 1 | B7: 1°C | C7: 35 | D7: Pablo Plebs | F7: 0.0142 | G7: 79782.449 | H7: =G7 -> 79782.449 | I7: =G7-H7 -> 0 | J7: =IF(I7>0,I7*3%,0) -> 0 | K7: =M$2*F7 -> 0 | L7: =M$1*F7 -> 51120 | M7: =F$1*F7 -> 32759.2 | N7: =F$2*F7 -> 8042.548 | O7: =ROUND(SUM(I7:N7),0) + Q7 -> 91922.35 | P7: =ROUND(O7*3%,0) + O7 -> 94680.35 | Q7: =ROUND(0.001+C7/100,2) -> 0.35
A8: 2 | B8: 1°D | C8: 36 | D8: Adrian Alejandro Pozo | F8: 0.0202 | G8: 195164.54 | H8: =196966-H64 -> 195165 | I8: =G8-H8 -> -0.45268608 | J8: =IF(I8>0,I8*3%,0) -> 0 | K8: =M$2*F8 -> 0 | L8: =M$1*F8 -> 72720 | M8: =F$1*F8 -> 46601.115 | N8: =F$2*F8 -> 11440.808 | O8: =ROUND(SUM(I8:N8),0) + Q8 -> 130761.36 | P8: =ROUND(O8*3%,0) + O8 -> 134684.36 | Q8: =ROUND(0.001+C8/100,2) -> 0.36
A9: 3 | B9: 2°A | C9: 37 | D9: Guillen Maria / Alejandro DI LEO | E9: Claudia | F9: 0.0202 | G9: 113493.34 | I9: =G9-H9 -> 113493.34 | J9: =IF(I9>0,I9*3%,0) -> 3404.8003 | K9: =M$2*F9 -> 0 | L9: =M$1*F9 -> 72720 | M9: =F$1*F9 -> 46601.115 | N9: =F$2*F9 -> 11440.808 | O9: =ROUND(SUM(I9:N9),0) + Q9 -> 247660.37 | P9: =ROUND(O9*3%,0) + O9 -> 255090.37 | Q9: =ROUND(0.001+C9/100,2) -> 0.37
A10: 4 | B10: 2°B | C10: 38 | D10: Jose Luis Gurtubay | E10: Santiago Flores | F10: 0.0139 | G10: 78096.904 | H10: =106311 -> 106311 | I10: =G10-H10 -> -28214.096 | J10: =IF(I10>0,I10*3%,0) -> 0 | K10: =M$2*F10 -> 0 | L10: =M$1*F10 -> 50040 | M10: =F$1*F10 -> 32067.104 | N10: =F$2*F10 -> 7872.635 | O10: =ROUND(SUM(I10:N10),0) + Q10 -> 61766.38 | P10: =ROUND(O10*3%,0) + O10 -> 63619.38 | Q10: =ROUND(0.001+C10/100,2) -> 0.38
A11: 5 | B11: 2°C | C11: 39 | D11: Magali Carrivale | F11: 0.0139 | G11: 78096.904 | H11: =G11 -> 78096.904 | I11: =G11-H11 -> 0 | J11: =IF(I11>0,I11*3%,0) -> 0 | K11: =M$2*F11 -> 0 | L11: =M$1*F11 -> 50040 | M11: =F$1*F11 -> 32067.104 | N11: =F$2*F11 -> 7872.635 | O11: =ROUND(SUM(I11:N11),0) + Q11 -> 89980.39 | P11: =ROUND(O11*3%,0) + O11 -> 92679.39 | Q11: =ROUND(0.001+C11/100,2) -> 0.39
A12: 6 | B12: 2°D | C12: 40 | D12: Juan Carlos Alonso | F12: 0.0202 | G12: 113493.34 | H12: =141707-H78 -> 113492.86 | I12: =G12-H12 -> 0.47951392 | J12: =IF(I12>0,I12*3%,0) -> 0.014385418 | K12: =M$2*F12 -> 0 | L12: =M$1*F12 -> 72720 | M12: =F$1*F12 -> 46601.115 | N12: =F$2*F12 -> 11440.808 | O12: =ROUND(SUM(I12:N12),0) + Q12 -> 130762.4 | P12: =ROUND(O12*3%,0) + O12 -> 134685.4 | Q12: =ROUND(0.001+C12/100,2) -> 0.4
A13: 7 | B13: 3°A | C13: 41 | D13: Lucas Oscar Ramil | E13: Camila Benitez | F13: 0.0202 | G13: 113493.34 | H13: =G13 -> 113493.34 | I13: =G13-H13 -> 0 | J13: =IF(I13>0,I13*3%,0) -> 0 | K13: =M$2*F13 -> 0 | L13: =M$1*F13 -> 72720 | M13: =F$1*F13 -> 46601.115 | N13: =F$2*F13 -> 11440.808 | O13: =ROUND(SUM(I13:N13),0) + Q13 -> 130762.41 | P13: =ROUND(O13*3%,0) + O13 -> 134685.41 | Q13: =ROUND(0.001+C13/100,2) -> 0.41
A14: 8 | B14: 3°B | C14: 42 | D14: Raul Boffi | E14: Gian y Micaela Parra | F14: 0.0139 | G14: 78096.904 | H14: =G14 -> 78096.904 | I14: =G14-H14 -> 0 | J14: =IF(I14>0,I14*3%,0) -> 0 | K14: =M$2*F14 -> 0 | L14: =M$1*F14 -> 50040 | M14: =F$1*F14 -> 32067.104 | N14: =F$2*F14 -> 7872.635 | O14: =ROUND(SUM(I14:N14),0) + Q14 -> 89980.42 | P14: =ROUND(O14*3%,0) + O14 -> 92679.42 | Q14: =ROUND(0.001+C14/100,2) -> 0.42
A15: 1 | B15: 3°C | C15: 43 | D15: Raul Boffi | E15: Lujan / Natalia Capece | F15: 0.0139 | G15: 78096.904 | H15: 78097 | I15: =G15-H15 -> -0.095717646 | J15: =IF(I15>0,I15*3%,0) -> 0 | K15: =M$2*F15 -> 0 | L15: =M$1*F15 -> 50040 | M15: =F$1*F15 -> 32067.104 | N15: =F$2*F15 -> 7872.635 | O15: =ROUND(SUM(I15:N15),0) + Q15 -> 89980.43 | P15: =ROUND(O15*3%,0) + O15 -> 92679.43 | Q15: =ROUND(0.001+C15/100,2) -> 0.43
A16: 1 | B16: 3°D | C16: 44 | D16: Roxana Elena Maya | E16: Daniela Bernabe | F16: 0.0202 | G16: 113493.34 | H16: =G16 -> 113493.34 | I16: =G16-H16 -> 0 | J16: =IF(I16>0,I16*3%,0) -> 0 | K16: =M$2*F16 -> 0 | L16: =M$1*F16 -> 72720 | M16: =F$1*F16 -> 46601.115 | N16: =F$2*F16 -> 11440.808 | O16: =ROUND(SUM(I16:N16),0) + Q16 -> 130762.44 | P16: =ROUND(O16*3%,0) + O16 -> 134685.44 | Q16: =ROUND(0.001+C16/100,2) -> 0.44
A17: 2 | B17: 4°A | C17: 45 | D17: Raul Boffi | E17: Paula Murado | F17: 0.0202 | G17: 113493.34 | H17: =G17 -> 113493.34 | I17: =G17-H17 -> 0 | J17: =IF(I17>0,I17*3%,0) -> 0 | K17: =M$2*F17 -> 0 | L17: =M$1*F17 -> 72720 | M17: =F$1*F17 -> 46601.115 | N17: =F$2*F17 -> 11440.808 | O17: =ROUND(SUM(I17:N17),0) + Q17 -> 130762.45 | P17: =ROUND(O17*3%,0) + O17 -> 134685.45 | Q17: =ROUND(0.001+C17/100,2) -> 0.45
A18: 2 | B18: 4°B | C18: 46 | D18: Raul Boffi | E18: Maria Florencia Boffi | F18: 0.0139 | G18: 78096.904 | H18: =G18 -> 78096.904 | I18: =G18-H18 -> 0 | J18: =IF(I18>0,I18*3%,0) -> 0 | K18: =M$2*F18 -> 0 | L18: =M$1*F18 -> 50040 | M18: =F$1*F18 -> 32067.104 | N18: =F$2*F18 -> 7872.635 | O18: =ROUND(SUM(I18:N18),0) + Q18 -> 89980.46 | P18: =ROUND(O18*3%,0) + O18 -> 92679.46 | Q18: =ROUND(0.001+C18/100,2) -> 0.46
A19: 3 | B19: 4°C | C19: 47 | D19: Raul Boffi | F19: 0.0139 | G19: 48096.904 | I19: =G19-H19 -> 48096.904 | J19: =IF(I19>0,I19*3%,0) -> 1442.9071 | K19: =M$2*F19 -> 0 | L19: =M$1*F19 -> 50040 | M19: =F$1*F19 -> 32067.104 | N19: =F$2*F19 -> 7872.635 | O19: =ROUND(SUM(I19:N19),0) + Q19 -> 139520.47 | P19: =ROUND(O19*3%,0) + O19 -> 143706.47 | Q19: =ROUND(0.001+C19/100,2) -> 0.47
A20: 3 | B20: 4°D | C20: 48 | D20: Hernán Gastón Padilla | E20: Armando Ezequiel Garro | F20: 0.0202 | G20: 113493.34 | H20: =141707-H89 -> 113492.86 | I20: =G20-H20 -> 0.47951392 | J20: =IF(I20>0,I20*3%,0) -> 0.014385418 | K20: =M$2*F20 -> 0 | L20: =M$1*F20 -> 72720 | M20: =F$1*F20 -> 46601.115 | N20: =F$2*F20 -> 11440.808 | O20: =ROUND(SUM(I20:N20),0) + Q20 -> 130762.48 | P20: =ROUND(O20*3%,0) + O20 -> 134685.48 | Q20: =ROUND(0.001+C20/100,2) -> 0.48
A21: 4 | B21: 5°A | C21: 49 | D21: Raul Boffi | E21: Barbara y Ezequiel | F21: 0.0202 | G21: 113493.34 | H21: =G21 -> 113493.34 | I21: =G21-H21 -> 0 | J21: =IF(I21>0,I21*3%,0) -> 0 | K21: =M$2*F21 -> 0 | L21: =M$1*F21 -> 72720 | M21: =F$1*F21 -> 46601.115 | N21: =F$2*F21 -> 11440.808 | O21: =ROUND(SUM(I21:N21),0) + Q21 -> 130762.49 | P21: =ROUND(O21*3%,0) + O21 -> 134685.49 | Q21: =ROUND(0.001+C21/100,2) -> 0.49
A22: 4 | B22: 5°B | C22: 50 | D22: Raul Boffi | F22: 0.0139 | G22: 134635.46 | I22: =G22-H22 -> 134635.46 | J22: =IF(I22>0,I22*3%,0) -> 4039.0639 | K22: =M$2*F22 -> 0 | L22: =M$1*F22 -> 50040 | M22: =F$1*F22 -> 32067.104 | N22: =F$2*F22 -> 7872.635 | O22: =ROUND(SUM(I22:N22),0) + Q22 -> 228654.5 | P22: =ROUND(O22*3%,0) + O22 -> 235514.5 | Q22: =ROUND(0.001+C22/100,2) -> 0.5
A23: 5 | B23: 5°C | C23: 51 | D23: Raul Boffi | F23: 0.0139 | G23: 78096.904 | I23: =G23-H23 -> 78096.904 | J23: =IF(I23>0,I23*3%,0) -> 2342.9071 | K23: =M$2*F23 -> 0 | L23: =M$1*F23 -> 50040 | M23: =F$1*F23 -> 32067.104 | N23: =F$2*F23 -> 7872.635 | O23: =ROUND(SUM(I23:N23),0) + Q23 -> 170420.51 | P23: =ROUND(O23*3%,0) + O23 -> 175533.51 | Q23: =ROUND(0.001+C23/100,2) -> 0.51
A24: 5 | B24: 5°D | C24: 52 | D24: Fernando Andres Canepa | E24: Matias / Carla Esteves | F24: 0.0202 | G24: 113493.34 | H24: =28214+113493-G86 -> 113492.86 | I24: =G24-H24 -> 0.47951392 | J24: =IF(I24>0,I24*3%,0) -> 0.014385418 | K24: =M$2*F24 -> 0 | L24: =M$1*F24 -> 72720 | M24: =F$1*F24 -> 46601.115 | N24: =F$2*F24 -> 11440.808 | O24: =ROUND(SUM(I24:N24),0) + Q24 -> 130762.52 | P24: =ROUND(O24*3%,0) + O24 -> 134685.52 | Q24: =ROUND(0.001+C24/100,2) -> 0.52
A25: 6 | B25: 6°A | C25: 53 | D25: Andres Gabriel Devouassoux | F25: 0.0202 | G25: 113493.34 | H25: =G25 -> 113493.34 | I25: =G25-H25 -> 0 | J25: =IF(I25>0,I25*3%,0) -> 0 | K25: =M$2*F25 -> 0 | L25: =M$1*F25 -> 72720 | M25: =F$1*F25 -> 46601.115 | N25: =F$2*F25 -> 11440.808 | O25: =ROUND(SUM(I25:N25),0) + Q25 -> 130762.53 | P25: =ROUND(O25*3%,0) + O25 -> 134685.53 | Q25: =ROUND(0.001+C25/100,2) -> 0.53
A26: 6 | B26: 6°B | C26: 54 | D26: Raul Boffi | E26: Nicolas Iudice | F26: 0.0139 | G26: 78096.904 | H26: =G26 -> 78096.904 | I26: =G26-H26 -> 0 | J26: =IF(I26>0,I26*3%,0) -> 0 | K26: =M$2*F26 -> 0 | L26: =M$1*F26 -> 50040 | M26: =F$1*F26 -> 32067.104 | N26: =F$2*F26 -> 7872.635 | O26: =ROUND(SUM(I26:N26),0) + Q26 -> 89980.54 | P26: =ROUND(O26*3%,0) + O26 -> 92679.54 | Q26: =ROUND(0.001+C26/100,2) -> 0.54
A27: 7 | B27: 6°C | C27: 55 | D27: Barbara Eugenia GARCIA FONTENLA | E27: Diego Coronel | F27: 0.0139 | G27: 134635.46 | H27: =79635 -> 79635 | I27: =G27-H27 -> 55000.464 | J27: =IF(I27>0,I27*3%,0) -> 1650.0139 | K27: =M$2*F27 -> 0 | L27: =M$1*F27 -> 50040 | M27: =F$1*F27 -> 32067.104 | N27: =F$2*F27 -> 7872.635 | O27: =ROUND(SUM(I27:N27),0) + Q27 -> 146630.55 | P27: =ROUND(O27*3%,0) + O27 -> 151029.55 | Q27: =ROUND(0.001+C27/100,2) -> 0.55
A28: 7 | B28: 6°D | C28: 56 | D28: Javier Alejandro Panaccio | F28: 0.0202 | G28: 195657.5 | H28: =79712-H65 -> 77910.996 | I28: =G28-H28 -> 117746.51 | J28: =IF(I28>0,I28*3%,0) -> 3532.3952 | K28: =M$2*F28 -> 0 | L28: =M$1*F28 -> 72720 | M28: =F$1*F28 -> 46601.115 | N28: =F$2*F28 -> 11440.808 | O28: =ROUND(SUM(I28:N28),0) + Q28 -> 252041.56 | P28: =ROUND(O28*3%,0) + O28 -> 259602.56 | Q28: =ROUND(0.001+C28/100,2) -> 0.56
A29: 8 | B29: 7°A | C29: 57 | D29: Mirta Isabel Asturino | F29: 0.0202 | G29: 113493.34 | H29: =G29 -> 113493.34 | I29: =G29-H29 -> 0 | J29: =IF(I29>0,I29*3%,0) -> 0 | K29: =M$2*F29 -> 0 | L29: =M$1*F29 -> 72720 | M29: =F$1*F29 -> 46601.115 | N29: =F$2*F29 -> 11440.808 | O29: =ROUND(SUM(I29:N29),0) + Q29 -> 130762.57 | P29: =ROUND(O29*3%,0) + O29 -> 134685.57 | Q29: =ROUND(0.001+C29/100,2) -> 0.57
A30: 8 | B30: 7°B | C30: 58 | D30: Jorge Antonio Mendiola | E30: Carlos Mehinger | F30: 0.0139 | G30: 393923.06 | H30: =78097 -> 78097 | I30: =G30-H30 -> 315826.06 | J30: =IF(I30>0,I30*3%,0) -> 9474.7819 | K30: =M$2*F30 -> 0 | L30: =M$1*F30 -> 50040 | M30: =F$1*F30 -> 32067.104 | N30: =F$2*F30 -> 7872.635 | O30: =ROUND(SUM(I30:N30),0) + Q30 -> 415281.58 | P30: =ROUND(O30*3%,0) + O30 -> 427739.58 | Q30: =ROUND(0.001+C30/100,2) -> 0.58
A31: 9 | B31: 7°C | C31: 59 | D31: Nelson Ariel FRAGA | F31: 0.0139 | G31: 135451.86 | H31: 135000 | I31: =G31-H31 -> 451.86428 | J31: =IF(I31>0,I31*3%,0) -> 13.555928 | K31: =M$2*F31 -> 0 | L31: =M$1*F31 -> 50040 | M31: =F$1*F31 -> 32067.104 | N31: =F$2*F31 -> 7872.635 | O31: =ROUND(SUM(I31:N31),0) + Q31 -> 90445.59 | P31: =ROUND(O31*3%,0) + O31 -> 93158.59 | Q31: =ROUND(0.001+C31/100,2) -> 0.59
A32: 9 | B32: 7°D | C32: 60 | D32: Domingo Alifraco | E32: Micaela Contreras | F32: 0.0202 | G32: 113493.34 | H32: =G32 -> 113493.34 | I32: =G32-H32 -> 0 | J32: =IF(I32>0,I32*3%,0) -> 0 | K32: =M$2*F32 -> 0 | L32: =M$1*F32 -> 72720 | M32: =F$1*F32 -> 46601.115 | N32: =F$2*F32 -> 11440.808 | O32: =ROUND(SUM(I32:N32),0) + Q32 -> 130762.6 | P32: =ROUND(O32*3%,0) + O32 -> 134685.6 | Q32: =ROUND(0.001+C32/100,2) -> 0.6
A33: 10 | B33: 8°A | C33: 61 | D33: Juan Pablo Charpin | F33: 0.0202 | G33: 113493.34 | H33: =141707-H87 -> 113492.86 | I33: =G33-H33 -> 0.47951392 | J33: =IF(I33>0,I33*3%,0) -> 0.014385418 | K33: =M$2*F33 -> 0 | L33: =M$1*F33 -> 72720 | M33: =F$1*F33 -> 46601.115 | N33: =F$2*F33 -> 11440.808 | O33: =ROUND(SUM(I33:N33),0) + Q33 -> 130762.61 | P33: =ROUND(O33*3%,0) + O33 -> 134685.61 | Q33: =ROUND(0.001+C33/100,2) -> 0.61
A34: 10 | B34: 8°B | C34: 62 | D34: Adriana Del Bagno | E34: Fanta / Alejandro Gabriel Lopez | F34: 0.0139 | G34: 78096.904 | H34: =G34 -> 78096.904 | I34: =G34-H34 -> 0 | J34: =IF(I34>0,I34*3%,0) -> 0 | K34: =M$2*F34 -> 0 | L34: =M$1*F34 -> 50040 | M34: =F$1*F34 -> 32067.104 | N34: =F$2*F34 -> 7872.635 | O34: =ROUND(SUM(I34:N34),0) + Q34 -> 89980.62 | P34: =ROUND(O34*3%,0) + O34 -> 92679.62 | Q34: =ROUND(0.001+C34/100,2) -> 0.62
A35: 11 | B35: 8°C | C35: 63 | D35: Claudio Moroni | E35: Macarena Barraza | F35: 0.0139 | G35: 78096.904 | H35: =G35 -> 78096.904 | I35: =G35-H35 -> 0 | J35: =IF(I35>0,I35*3%,0) -> 0 | K35: =M$2*F35 -> 0 | L35: =M$1*F35 -> 50040 | M35: =F$1*F35 -> 32067.104 | N35: =F$2*F35 -> 7872.635 | O35: =ROUND(SUM(I35:N35),0) + Q35 -> 89980.63 | P35: =ROUND(O35*3%,0) + O35 -> 92679.63 | Q35: =ROUND(0.001+C35/100,2) -> 0.63
A36: 11 | B36: 8°D | C36: 64 | D36: Karina Edith Mastandrea | E36: Ayelen | F36: 0.0202 | G36: 113493.34 | I36: =G36-H36 -> 113493.34 | J36: =IF(I36>0,I36*3%,0) -> 3404.8003 | K36: =M$2*F36 -> 0 | L36: =M$1*F36 -> 72720 | M36: =F$1*F36 -> 46601.115 | N36: =F$2*F36 -> 11440.808 | O36: =ROUND(SUM(I36:N36),0) + Q36 -> 247660.64 | P36: =ROUND(O36*3%,0) + O36 -> 255090.64 | Q36: =ROUND(0.001+C36/100,2) -> 0.64
A37: 12 | B37: 9°A | C37: 65 | D37: Fernando Fernandez | E37: Olivera Rodrigo | F37: 0.0202 | G37: 113493.34 | H37: =G37 -> 113493.34 | I37: =G37-H37 -> 0 | J37: =IF(I37>0,I37*3%,0) -> 0 | K37: =M$2*F37 -> 0 | L37: =M$1*F37 -> 72720 | M37: =F$1*F37 -> 46601.115 | N37: =F$2*F37 -> 11440.808 | O37: =ROUND(SUM(I37:N37),0) + Q37 -> 130762.65 | P37: =ROUND(O37*3%,0) + O37 -> 134685.65 | Q37: =ROUND(0.001+C37/100,2) -> 0.65
A38: 12 | B38: 9°B | C38: 66 | D38: Gonzalo Cadiz | E38: Micaela Dib | F38: 0.0139 | G38: 78096.904 | H38: =G38 -> 78096.904 | I38: =G38-H38 -> 0 | J38: =IF(I38>0,I38*3%,0) -> 0 | K38: =M$2*F38 -> 0 | L38: =M$1*F38 -> 50040 | M38: =F$1*F38 -> 32067.104 | N38: =F$2*F38 -> 7872.635 | O38: =ROUND(SUM(I38:N38),0) + Q38 -> 89980.66 | P38: =ROUND(O38*3%,0) + O38 -> 92679.66 | Q38: =ROUND(0.001+C38/100,2) -> 0.66
A39: 1 | B39: 9°C | C39: 67 | D39: Hernan Miñambres | E39: Laura Quintana | F39: 0.0139 | G39: 78096.904 | H39: =G39 -> 78096.904 | I39: =G39-H39 -> 0 | J39: =IF(I39>0,I39*3%,0) -> 0 | K39: =M$2*F39 -> 0 | L39: =M$1*F39 -> 50040 | M39: =F$1*F39 -> 32067.104 | N39: =F$2*F39 -> 7872.635 | O39: =ROUND(SUM(I39:N39),0) + Q39 -> 89980.67 | P39: =ROUND(O39*3%,0) + O39 -> 92679.67 | Q39: =ROUND(0.001+C39/100,2) -> 0.67
A40: 1 | B40: 9°D | C40: 68 | D40: Matías Ezequiel Tobío | E40: Jesica Romina | F40: 0.0202 | G40: 113493.34 | H40: =147563-H76 -> 113493.1 | I40: =G40-H40 -> 0.24371392 | J40: =IF(I40>0,I40*3%,0) -> 0.0073114177 | K40: =M$2*F40 -> 0 | L40: =M$1*F40 -> 72720 | M40: =F$1*F40 -> 46601.115 | N40: =F$2*F40 -> 11440.808 | O40: =ROUND(SUM(I40:N40),0) + Q40 -> 130762.68 | P40: =ROUND(O40*3%,0) + O40 -> 134685.68 | Q40: =ROUND(0.001+C40/100,2) -> 0.68
...
