Workbook

Sheet RESUMEN
C1: MAIL: elmiradorconsorcios@gmail.com
C2: CUIT ADMINISTRACION: 27231256879
C3: CBU: 0720039720000002171436 | E3: TELEFONO: 11 5320-2676
C4: ADMINISTRADORA: CAROLINA CANCIANI MP:1148
C5: PERÍODO: ENERO | E5: HORARIOS DE ATENCION: LUNES A VIERNES - 10 A 16HS - EMERGENCIAS 24HS
C6: LIQUIDACION DE EXPENSAS
A14: Importante para dueños o inquilinos de departamentos o coheras: Queremos recordarles una cuestión importante respecto a los pagos de expensas que ayuda a evitar errores en la imputación de los mismos. El sistema que utilizamos asigna centavos únicos a cada Unidad Funcional (UF), lo cual nos permite identificar automáticamente a qué unidad corresponde cada transferencia. Es decir, cada UF tiene un número específico de centavos que actúa como "identificador". Por ejemplo, si tu UF es la 45, el importe a abonar debería terminar en $...,45. Si tenés más de una unidad (por ejemplo, un departamento y una cochera), cada una tiene su propio código de centavos. En esos casos, te pedimos por favor que realices una transferencia por cada UF, respetando el importe con sus centavos correspondientes. Sabemos que a veces por comodidad se suele enviar todo junto en una sola transferencia, pero esto puede generar confusión o errores en la imputación automática. Realizar los pagos por separado nos permite asegurar que cada importe se asigne correctamente. Agradecemos muchísimo la colaboración para seguir manteniendo todo ordenado. Saludos cordiales.
A20: VTO 16/02
A24: GASTOS ORDINARIOS UNIDADES FUNCIONALES: | E24: UF 93,20% | F24: LOCAL 1 (1,08%) | G24: LOCAL 2 (1,28%) | H24: LOCAL 3 (1,21%) | I24: LOCAL 4 (1,49%) | J24: LOCAL 5 (1,74%)
A25: Sueldo encargada Sonia Arzamendia Galeano
A26: Haberes | D26: 1124512
A27: Plus pileta | D27: 39622.7
A28: Plus retiro de basura | D28: =1726*80 -> 138080
A29: Plus cochera | D29: 23553.4
A30: Adicional Viaticos | D30: 65596.5
A31: Adicional remuneracion | D31: 120000
A32: Descuento Dia Sabado 31/01 | D32: -44192.27
A33: SUBTOTAL | D33: =SUM(D26:D32) -> 1467172.3
A34: Sueldo encargada Miriam
A35: Haberes | D35: 562256
A36: Plus pileta | D36: =D27 -> 39622.7
A37: Plus retiro de basura | D37: =D28 -> 138080
A38: Plus cochera | D38: =D29 -> 23553.4
A39: Adicional Viaticos | D39: =D30 -> 65596.5
A40: Adicional remuneracion | D40: 60000
A41: Descuento 4 dias | D41: -101801.65
A42: SUBTOTAL | D42: =SUM(D35:D41) -> 787306.95
A43: TOTAL SUELDO | D43: =D33+D42 -> 2254479.3 | E43: =D43*93.2% -> 2101174.7 | F43: =$D43*1.08% -> 24348.376 | G43: =$D43*1.28% -> 28857.335 | H43: =$D43*1.21% -> 27279.199 | I43: =$D43*1.49% -> 33591.741 | J43: =D43*1.74% -> 39227.939 | K43: =E43+J43+F43+G43+H43+I43 -> 2254479.3 | L43: =IF(D43=K43, "", "Error")
A44: Reemplazo Sra. Miriam - Sr. Cristian | D44: 254504.03
A46: TOTAL | D46: =SUM(D44:D44) -> 254504.03 | E46: =D46*93.2% -> 237197.76 | F46: =$D46*1.08% -> 2748.6435 | G46: =$D46*1.28% -> 3257.6516 | H46: =$D46*1.21% -> 3079.4988 | I46: =$D46*1.49% -> 3792.11 | J46: =D46*1.74% -> 4428.3701 | K46: =E46+J46+F46+G46+H46+I46 -> 254504.03 | L46: =IF(D46=K46, "", "Error")
A47: COMBUSTIBLE PARA GRUPO ELECTROGENO | E47: =D47*91.91% -> 0
A48: Combustible | C48: 46024 | D48: 71000 | E48: =D48 -> 71000
A49: Combustible | C49: 46024 | D49: 71000 | E49: =D49 -> 71000
A50: Combustible | C50: 46024 | D50: 36025 | E50: =D50 -> 36025
A51: Combustible | C51: 46024 | D51: 78006.05 | E51: =D51 -> 78006.05
A52: Combustible | C52: 46025 | D52: 37040 | E52: =D52 -> 37040
A54: TOTAL | D54: =SUM(D48:D53) -> 293071.05 | E54: =D54 -> 293071.05 | K54: =E54+J54+F54+G54+H54+I54 -> 293071.05 | L54: =IF(D54=K54, "", "Error")
A55: IMPUESTOS
A56: ARBA - Impuesto inmobiliario partida 025024270-0
A57: TSG - Partida 197229000 | B57: Mes de ENERO | C57: Pago Ef. Por adm. | D57: 249469
...

Sheet PRORRATEO
A1: Las casillas coloreadas en la columna Gastos Par/SUM de color rojo corresponden a multas aplicadas por el uso del SUM. En consecuencia, la unidad funcional involucrada no podrá acceder al uso del mismo por tiempo indeterminado. Por otro lado, las casillas coloreadas en amarillo, corresponden a llaves y las verdes corresponden al mal uso del coworking. | F1: Banco Santander Rio. | K1: SE GASTO: | L1: =RESUMEN!D110-RESUMEN!D108 -> 12343887
F2: CBU: 0720039720000002171436 | K2: SE PRORRATEA EN LAS UF: | M2: 15667206
F3: CTA CTE $ 0039 - 21714/3 FIDEICOMISO 25 DE MAYO 837 LAN 30716676737
C5: IMPORTANTE: Las personas marcadas en color naranja abonaron de forma incorrecta mediante Mercado Pago. A partir de ahora (incluso desde hace meses), ya se encuentra habilitada la cuenta bancaria correspondiente, por lo que todos los pagos deben realizarse exclusivamente a través de dicha cuenta. Los datos de la misma se encuentran justo arriba de este aviso. Quienes abonen por Mercado Pago corren el riesgo de que su pago no sea imputado correctamente.
C9: IMPORTANTE: Quienes estan en violeta NO ha respetado los centavos al abonar. Para la proxima oportunidad, solicitamos que los respeten. | P9: LOCAL 1 | Q9: =RESUMEN!F110 -> 141730.21
P10: LOCAL 2 | Q10: =RESUMEN!G110 -> 167976.55
A11: Piso | B11: Dpto. | C11: UF | D11: Propietario | E11: Inquilinos | F11: (%) | G11: Saldo | H11: Ingreso | I11: SALDO | J11: Expensas extraor. | K11: Expensas ord | L11: SUM/ GASTOS PART | M11: TOTAL A ABONAR HASTA | N11: TOTAL A ABONAR 2DO VTO - DESDE EL | P11: LOCAL 3 | Q11: =RESUMEN!H110 -> 158790.33
P12: LOCAL 4 | Q12: =RESUMEN!I110 -> 195535.2
M13: =RESUMEN!A20 -> VTO 16/02 | N13: =RESUMEN!A20 -> VTO 16/02 | P13: LOCAL 5 | Q13: =RESUMEN!J110 -> 228343.12
A14: conf sup | C14: LOC 1 | D14: Fernandez, Cristian | E14: Gladys ojeda Britez - Exequiel alexis giuliani | F14: 0.0108 | G14: 274719.32 | I14: =G14-H14 -> 274719.32 | J14: 0 | K14: 141730.21 | L14: 0 | M14: =K14+J14+I14+L14 -> 416449.53 | N14: =M14*6% + M14 -> 441436.51
C15: LOC 2 | D15: Fridgi, Guillermo Ariel | F15: 0.013 | G15: 183831.27 | H15: 61277 | I15: =G15-H15 -> 122554.27 | J15: 0 | K15: 167976.55 | L15: 0 | M15: =K15+J15+I15+L15 -> 290530.82 | N15: =M15*6% + M15 -> 307962.67
A16: conf sup | C16: LOC 3 | D16: Schiaffino, Edgardo Angel | E16: Cristina andrea Massa | F16: 0.0121 | G16: 160512.29 | H16: =G16 -> 160512.29 | I16: =G16-H16 -> 0 | J16: 0 | K16: 158790.33 | L16: 0 | M16: =K16+J16+I16+L16 -> 158790.33 | N16: =M16*6% + M16 -> 168317.75
A17: conf sup | C17: LOC 4 | D17: Cordero, Leandro Emanuel - Orona, Victoria | F17: 0.0149 | G17: 551052.92 | I17: =G17-H17 -> 551052.92 | J17: 0 | K17: 195535.2 | L17: 0 | M17: =K17+J17+I17+L17 -> 746588.12 | N17: =M17*6% + M17 -> 791383.4
A18: conf sup | C18: LOC 5 | D18: Orsi, Jose Luis - Fernandez, Cristian Gabriel | F18: 0.0174 | G18: 469159.56 | H18: =G18 -> 469159.56 | I18: =G18-H18 -> 0 | J18: 0 | K18: 228343.12 | L18: 0 | M18: =K18+J18+I18+L18 -> 228343.12 | N18: =M18*6% + M18 -> 242043.71
A19: 3 amb | C19: 2ºA | D19: Franco, Lucas Fabián | F19: 0.0188 | G19: 261193.01 | H19: =G19 -> 261193.01 | I19: =G19-H19 -> 0 | J19: =M$8*F19 -> 0 | K19: =M$2*F19 -> 294543.47 | L19: 0 | M19: =ROUND((K19+J19+I19+L19),0) + O19 -> 294543.01 | N19: =ROUND((M19*6% + M19 ),0) + O19 -> 312216.01 | O19: 0.01 | P19: Constructora: paga ademas del 2A la cochera 25
A20: 1 amb | C20: 2ºB | D20: Martinez, Diego | F20: 0.0084 | G20: 131605.02 | H20: =G20 -> 131605.02 | I20: =G20-H20 -> 0 | J20: =M$8*F20 -> 0 | K20: =M$2*F20 -> 131604.53 | L20: 0 | M20: =ROUND((K20+J20+I20+L20),0) + O20 -> 131605.02 | N20: =ROUND((M20*6% + M20 ),0) + O20 -> 139501.02 | O20: =O19+0.01 -> 0.02
A21: 3 amb | C21: 2ºC | D21: Rodriguez, Carlos Alberto Miguel | F21: 0.0201 | G21: 333806.03 | H21: =G21 -> 333806.03 | I21: =G21-H21 -> 0 | J21: =M$8*F21 -> 0 | K21: =M$2*F21 -> 314910.84 | L21: 20000 | M21: =ROUND((K21+J21+I21+L21),0) + O21 -> 334911.03 | N21: =ROUND((M21*6% + M21 ),0) + O21 -> 355006.03 | O21: =O20+0.01 -> 0.03
A22: 2 amb | C22: 2ºD | D22: Ferraro, José | E22: Matias Cuevas | F22: 0.0094 | G22: 146444.04 | H22: 147222 | I22: =G22-H22 -> -777.96 | J22: =M$8*F22 -> 0 | K22: =M$2*F22 -> 147271.74 | L22: 0 | M22: =ROUND((K22+J22+I22+L22),0) + O22 -> 146494.04 | N22: =ROUND((M22*6% + M22 ),0) + O22 -> 155284.04 | O22: =O21+0.01 -> 0.04 | P22: Matias alejandro ezequiel
A23: 2 amb | C23: 2ºE | D23: Dieci, Matias Orlando | E23: Julieta Damiano/Damiani | F23: 0.0087 | G23: 156305.05 | H23: =19700+136605.05 -> 156305.05 | I23: =G23-H23 -> 0 | J23: =M$8*F23 -> 0 | K23: =M$2*F23 -> 136304.69 | M23: =ROUND((K23+J23+I23+L23),0) + O23 -> 136305.05 | N23: =ROUND((M23*6% + M23 ),0) + O23 -> 144483.05 | O23: =O22+0.01 -> 0.05
A24: 2 amb | C24: 2ºF | D24: Ferraro, Jose | E24: Carolina Massa | F24: 0.0095 | G24: 148838.06 | H24: =G24 -> 148838.06 | I24: =G24-H24 -> 0 | J24: =M$8*F24 -> 0 | K24: =M$2*F24 -> 148838.46 | L24: 0 | M24: =ROUND((K24+J24+I24+L24),0) + O24 -> 148838.06 | N24: =ROUND((M24*6% + M24 ),0) + O24 -> 157768.06 | O24: =O23+0.01 -> 0.06
A25: 3 amb | C25: 3ºA | D25: Ferraro, Jose | E25: Walter Gabriel Ledesma | F25: 0.0165 | G25: 300495.07 | H25: =G25 -> 300495.07 | I25: =G25-H25 -> 0 | J25: =M$8*F25 -> 0 | K25: =M$2*F25 -> 258508.9 | L25: 0 | M25: =ROUND((K25+J25+I25+L25),0) + O25 -> 258509.07 | N25: =ROUND((M25*6% + M25 ),0) + O25 -> 274020.07 | O25: =O24+0.01 -> 0.07
A26: 1 amb | C26: 3ºB | D26: Balduzzi, Stella Maris | F26: 0.0073 | G26: 114371.08 | H26: =G26 -> 114371.08 | I26: =G26-H26 -> 0 | J26: =M$8*F26 -> 0 | K26: =M$2*F26 -> 114370.6 | L26: 20000 | M26: =ROUND((K26+J26+I26+L26),0) + O26 -> 134371.08 | N26: =ROUND((M26*6% + M26 ),0) + O26 -> 142433.08 | O26: =O25+0.01 -> 0.08
A27: 3 amb | C27: 3ºC | D27: Ferraro, Jose | E27: Gustavo Oscar Fernandez | F27: 0.0178 | G27: 535348.09 | H27: =278876+258100 -> 536976 | I27: =G27-H27 -> -1627.91 | J27: =M$8*F27 -> 0 | K27: =M$2*F27 -> 278876.27 | L27: =13000*3 -> 39000 | M27: =ROUND((K27+J27+I27+L27),0) + O27 -> 316248.09 | N27: =ROUND((M27*6% + M27 ),0) + O27 -> 335223.09 | O27: =O26+0.01 -> 0.09
A28: 2 amb | C28: 3ºD | D28: Heredia, Christian | F28: 0.0094 | G28: 133172.1 | H28: =G28 -> 133172.1 | I28: =G28-H28 -> 0 | J28: =M$8*F28 -> 0 | K28: =M$2*F28 -> 147271.74 | L28: 0 | M28: =ROUND((K28+J28+I28+L28),0) + O28 -> 147272.1 | N28: =ROUND((M28*6% + M28 ),0) + O28 -> 156108.1 | O28: =O27+0.01 -> 0.1
A29: 2 amb | C29: 3ºE | D29: Dallorso, Maria Ines - Dallorso, Ana Paula | F29: 0.0087 | G29: 136305.11 | H29: =G29 -> 136305.11 | I29: =G29-H29 -> 0 | J29: =M$8*F29 -> 0 | K29: =M$2*F29 -> 136304.69 | L29: 20000 | M29: =ROUND((K29+J29+I29+L29),0) + O29 -> 156305.11 | N29: =ROUND((M29*6% + M29 ),0) + O29 -> 165683.11 | O29: =O28+0.01 -> 0.11
A30: 2 amb | C30: 3ºF | D30: Ayala, Roberto Adrian | F30: 0.0095 | G30: 666589.12 | I30: =G30-H30 -> 666589.12 | J30: =M$8*F30 -> 0 | K30: =M$2*F30 -> 148838.46 | L30: 0 | M30: =ROUND((K30+J30+I30+L30),0) + O30 -> 815428.12 | N30: =ROUND((M30*6% + M30 ),0) + O30 -> 864354.12 | O30: =O29+0.01 -> 0.12
A31: 3 amb | C31: 4ºA | D31: Barral, Carlos Daniel | F31: 0.0164 | G31: 276942.13 | H31: =G31 -> 276942.13 | I31: =G31-H31 -> 0 | J31: =M$8*F31 -> 0 | K31: =M$2*F31 -> 256942.18 | L31: 0 | M31: =ROUND((K31+J31+I31+L31),0) + O31 -> 256942.13 | N31: =ROUND((M31*6% + M31 ),0) + O31 -> 272359.13 | O31: =O30+0.01 -> 0.13
A32: 1 amb | C32: 4ºB | D32: Sr. Propietario | E32: Liria | F32: 0.0072 | G32: 112804.14 | H32: =G32 -> 112804.14 | I32: =G32-H32 -> 0 | J32: =M$8*F32 -> 0 | K32: =M$2*F32 -> 112803.88 | L32: 0 | M32: =ROUND((K32+J32+I32+L32),0) + O32 -> 112804.14 | N32: =ROUND((M32*6% + M32 ),0) + O32 -> 119572.14 | O32: =O31+0.01 -> 0.14
A33: 3 amb | C33: 4ºC | D33: Osipowicz, Ariel Marcelo | F33: 0.0173 | G33: 271043.15 | H33: =G33 -> 271043.15 | I33: =G33-H33 -> 0 | J33: =M$8*F33 -> 0 | K33: =M$2*F33 -> 271042.67 | L33: 25000 | M33: =ROUND((K33+J33+I33+L33),0) + O33 -> 296043.15 | N33: =ROUND((M33*6% + M33 ),0) + O33 -> 313806.15 | O33: =O32+0.01 -> 0.15
A34: 2 amb | C34: 4ºD | D34: Ruiz, Juana Del Valle | F34: 0.0094 | G34: 139543.16 | H34: =G34 -> 139543.16 | I34: =G34-H34 -> 0 | J34: =M$8*F34 -> 0 | K34: =M$2*F34 -> 147271.74 | L34: 0 | M34: =ROUND((K34+J34+I34+L34),0) + O34 -> 147272.16 | N34: =ROUND((M34*6% + M34 ),0) + O34 -> 156108.16 | O34: =O33+0.01 -> 0.16 | P34: Pablo Amarilla
A35: 2 amb | C35: 4ºE | D35: Ayala, Roberto Adrian | E35: Iara | F35: 0.0087 | G35: 136305.17 | H35: =G35 -> 136305.17 | I35: =G35-H35 -> 0 | J35: =M$8*F35 -> 0 | K35: =M$2*F35 -> 136304.69 | L35: 0 | M35: =ROUND((K35+J35+I35+L35),0) + O35 -> 136305.17 | N35: =ROUND((M35*6% + M35 ),0) + O35 -> 144483.17 | O35: =O34+0.01 -> 0.17
A36: 2 amb | C36: 4ºF | D36: Ayala, Roberto Adrian | F36: 0.0095 | G36: 148838.18 | I36: =G36-H36 -> 148838.18 | J36: =M$8*F36 -> 0 | K36: =M$2*F36 -> 148838.46 | L36: 0 | M36: =ROUND((K36+J36+I36+L36),0) + O36 -> 297677.18 | N36: =ROUND((M36*6% + M36 ),0) + O36 -> 315538.18 | O36: =O35+0.01 -> 0.18
A37: 3 amb | C37: 5ºA | D37: Chehab, Gabriel Adrian | E37: Santiago Rodriguez | F37: 0.0164 | G37: 256942.19 | H37: =G37 -> 256942.19 | I37: =G37-H37 -> 0 | J37: =M$8*F37 -> 0 | K37: =M$2*F37 -> 256942.18 | M37: =ROUND((K37+J37+I37+L37),0) + O37 -> 256942.19 | N37: =ROUND((M37*6% + M37 ),0) + O37 -> 272359.19 | O37: =O36+0.01 -> 0.19 | P37: Cochera 38
A38: 1 amb | C38: 5ºB | D38: Mesa, Mariano | F38: 0.0072 | G38: 112804.2 | H38: =G38 -> 112804.2 | I38: =G38-H38 -> 0 | J38: =M$8*F38 -> 0 | K38: =M$2*F38 -> 112803.88 | L38: 20000 | M38: =ROUND((K38+J38+I38+L38),0) + O38 -> 132804.2 | N38: =ROUND((M38*6% + M38 ),0) + O38 -> 140772.2 | O38: =O37+0.01 -> 0.2
A39: 3 amb | C39: 5ºC | D39: Di Mito, Vicente Argentino - Serantes, Mabel | F39: 0.0173 | G39: 271043.21 | H39: 287306.21 | I39: =G39-H39 -> -16263 | J39: =M$8*F39 -> 0 | K39: =M$2*F39 -> 271042.67 | L39: 0 | M39: =ROUND((K39+J39+I39+L39),0) + O39 -> 254780.21 | N39: =ROUND((M39*6% + M39 ),0) + O39 -> 270067.21 | O39: =O38+0.01 -> 0.21
A40: 2 amb | C40: 5ºD | D40: Ayala, Agustin | F40: 0.0094 | G40: 220907.22 | I40: =G40-H40 -> 220907.22 | J40: =M$8*F40 -> 0 | K40: =M$2*F40 -> 147271.74 | M40: =ROUND((K40+J40+I40+L40),0) + O40 -> 368179.22 | N40: =ROUND((M40*6% + M40 ),0) + O40 -> 390270.22 | O40: =O39+0.01 -> 0.22 | P40: Ayala paga 5D, 5F y 4F
A41: 2 amb | C41: 5ºE | D41: Ayala, Roberto Adrian | F41: 0.0087 | G41: 136305.23 | H41: =G41 -> 136305.23 | I41: =G41-H41 -> 0 | J41: =M$8*F41 -> 0 | K41: =M$2*F41 -> 136304.69 | L41: 0 | M41: =ROUND((K41+J41+I41+L41),0) + O41 -> 136305.23 | N41: =ROUND((M41*6% + M41 ),0) + O41 -> 144484.23 | O41: =O40+0.01 -> 0.23 | P41: COCHERA 31
A42: 2 amb | C42: 5ºF | D42: Ayala, Agustin | F42: 0.0095 | G42: 148838.24 | I42: =G42-H42 -> 148838.24 | J42: =M$8*F42 -> 0 | K42: =M$2*F42 -> 148838.46 | L42: 0 | M42: =ROUND((K42+J42+I42+L42),0) + O42 -> 297677.24 | N42: =ROUND((M42*6% + M42 ),0) + O42 -> 315538.24 | O42: =O41+0.01 -> 0.24
A43: 3 amb | C43: 6ºA | D43: Morandi, Victoria Ayelen | Calvo, Luciano Ezequiel | F43: 0.0164 | G43: 256942.25 | H43: =G43 -> 256942.25 | I43: =G43-H43 -> 0 | J43: =M$8*F43 -> 0 | K43: =M$2*F43 -> 256942.18 | L43: 0 | M43: =ROUND((K43+J43+I43+L43),0) + O43 -> 256942.25 | N43: =ROUND((M43*6% + M43 ),0) + O43 -> 272359.25 | O43: =O42+0.01 -> 0.25
A44: 1 amb | C44: 6ºB | D44: Grizak Ruben | E44: Christian | F44: 0.0072 | G44: 112804.26 | H44: =G44 -> 112804.26 | I44: =G44-H44 -> 0 | J44: =M$8*F44 -> 0 | K44: =M$2*F44 -> 112803.88 | L44: 0 | M44: =ROUND((K44+J44+I44+L44),0) + O44 -> 112804.26 | N44: =ROUND((M44*6% + M44 ),0) + O44 -> 119573.26 | O44: =O43+0.01 -> 0.26
...

Sheet ANOTACIONES
