Workbook

Sheet RESUMEN
B1: MAIL: salta1167rc@gmail.com
B2: CUIT ADMINISTRACION: 27231256879
B3: CONSORCIO DE PROPIETARIOS EDIFICIO CALLE SALTA 1167/1169 C DE P SALTA 1167 1169 LANUS CTA CTE $ 039 - 22273/6 CBU: 0720039720000002227368
A4: LIQUIDACION DE EXPENSAS | B4: ADMINISTRADORA: CAROLINA CANCIANI MP:1148
A5: CUIT DEL EDIFICIO: 30-719118061-9 | B5: PERÍODO: SEPTIEMBRE | D5: HORARIOS DE ATENCION: LUNES A VIERNES
A6: CONSORCIO DE PROPIETARIOS DEL EDIFICIO CALLE SALTA 1167 | D6: 10 A 15HS - EMERGENCIAS 24HS
B8: VTO 16/10
A13: ESTIMADOS PROPIETARIOS E INQUILINOS: POR FAVOR LOS QUE ABONAN EN PRIMER VENCIMIENTO ABONEN EL MONTO DE PRIMER VENCIMIENTO, ASI AGILIZAN LA LIQUIDACION, RESPETEN LOS CENTAVOS CORRESPONDIENTES A LA UNIDAD FUNCIONAL. ES DE CARÁCTER OBLIGATORIO INFORMAR VIA MAIL LAS EXPENSAS. PORFAVOR RESPETAR LOS CENTAVOS AL ABONAR.
A20: GASTOS A - UNIDADES FUNCIONALES:
A21: LIMPIEZA
A22: Full Clean - Servicio de limpieza | D22: 510846.85 | E22: Transf 13/09
A24: TOTAL | E24: =SUM(D22:D23) -> 510846.85
A25: SEGUROS
A26: Federacion patronal Seguro obligatorio de consorcio - Poliza nro. 1-2249124-0 | D26: 74244 | E26: Transf 07/09
A27: TOTAL IMPUESTO | E27: =SUM(D26:D26) -> 74244
A28: ABONOS Y SERVICIOS
A29: Edesur | D29: 233485 | E29: Transf 28/09
A30: Metrogas | D30: 8972.48 | E30: =E31 -> Transf 07/09
A31: Metrogas | D31: 550258.94 | E31: Transf 07/09
A32: AySa | D32: 872785.72 | E32: Transf 07/09
A33: Servicio de interet Claro | D33: 30111.39 | E33: Transf 07/09
A34: TOTAL ABONOS Y SERVICIOS | E34: =SUM(D29:D33) -> 1695613.5
A36: Lema - Ascensores - Servicio de mantenimiento - Se abona a mes vencido | D36: 82000 | E36: Transf 01/09
A37: Gonzalez Matias - Compra de paneles de luz fria y lamparas | D37: 52253.44 | E37: Transf 18/09
A38: Arreglo Cielorraso - Dpto. 1C | D38: 200000 | E38: Transferido 1C
A39: TOTAL | E39: =SUM(D36:D38) -> 334253.44
A40: HONORARIOS
A41: Honorario administracion - Mes de SEPTIEMBRE | D41: 190000 | E41: Transf 30/09
A42: TOTAL | E42: =SUM(D41:D41) -> 190000
A43: GASTOS BANCARIOS
A44: Mantenimiento de cuenta | B44: Bonificado
A45: Gastos bancarios | D45: 35494.27
A46: TOTAL | E46: =SUM(D44:D45) -> 35494.27
A48: PREVISION GASTOS A | E48: =3000000-2840452.09 -> 159547.91
A50: TOTAL GASTOS A | E50: =(SUM(E21:E48)) -> 3000000
A53: GASTOS B:
E58: =SUM(D54:D57) -> 0
A61: PREVISION GASTOS B
A63: TOTAL GASTOS B: | E63: =E58+E61 -> 0
A65: GASTOS A + PREVISION (A) : | B65: =E50 -> 3000000
...

Sheet PRORRATEO
E2: Gastos B | G2: 0 | J2: Gastos A | K2: 3000000
A4: Estimados convivientes: Les solicitamos, por favor, que al momento de realizar el pago respeten los centavos que figuran en el monto indicado, ya que estos nos permiten identificar correctamente los pagos y las unidades funcionales, reduciendo así el margen de error. Muchas gracias por su colaboración.
A9: REITERAMOS QUE LOS DATOS DE LA CUENTA EN DONDE DEBEN ABONAR LAS EXPENSAS SON: CONSORCIO DE PROPIETARIOS EDIFICIO CALLE SALTA 1167/1169 - C DE P SALTA 1167 1169 LANUS - CTA CTE $ 039 - 22273/6 CBU: 0720039720000002227368
A10: QUIENES ESTAN EN VIOLETA NO ESTAN RESPETANDO LOS CENTAVOS AL ABONAR.
A11: UF | C11: Propietario | D11: Inquilinos | E11: (%) | F11: Saldo Ord | G11: Ingreso | H11: Deuda o Saldo a favor | I11: Interes 3% | J11: Gastos A | K11: Gastos B | L11: EDESUR | M11: SUM | N11: Total 1er Vto | O11: Total 2do Vto. | P11: Total 2do Vto
N12: =RESUMEN!B8 -> VTO 16/10
A13: 1 | B13: 1 A | C13: MIRAGLIA NORBERTO JOSE | E13: 12 | F13: 360000.01 | G13: =396280-G29-G31 -> 359999.64 | H13: =F13-G13 -> 0.37 | I13: =IF(H13>0,H13*3%,0) -> 0.0111 | J13: =K$2*E13/100 -> 360000 | K13: =G$2*E13/100 -> 0 | L13: =EDESUR!O4 -> 0 | N13: =ROUND(SUM(H13:M13),0) + Q13 -> 360000.01 | O13: =ROUND(N13*6% + N13,0) + Q13 -> 381600.01 | P13: =ROUND(N13*3%,0) + N13 -> 370800.01 | Q13: 0.01
A14: 2 | B14: 1 C | C14: ADAMO PABLO MARIANO | E14: 6.6 | F14: 339673.02 | G14: =200000+140000 -> 340000 | H14: =F14-G14 -> -326.98 | I14: =IF(H14>0,H14*3%,0) -> 0 | J14: =K$2*E14/100 -> 198000 | K14: =G$2*E14/100 -> 0 | L14: =EDESUR!O5 -> 125263.17 | M14: 0 | N14: =ROUND(SUM(H14:M14),0) + Q14 -> 322936.02 | O14: =ROUND(N14*6% + N14,0) + Q14 -> 342312.02 | P14: =ROUND(N14*3%,0) + N14 -> 332624.02 | Q14: =Q13+0.01 -> 0.02
A15: 3 | B15: 1 D | C15: REDONDO | D15: Gilmer | E15: 5.4 | F15: 162000.03 | G15: =F15 -> 162000.03 | H15: =F15-G15 -> 0 | I15: =IF(H15>0,H15*3%,0) -> 0 | J15: =K$2*E15/100 -> 162000 | K15: =G$2*E15/100 -> 0 | L15: =EDESUR!O6 -> 0 | N15: =ROUND(SUM(H15:M15),0) + Q15 -> 162000.03 | O15: =ROUND(N15*6% + N15,0) + Q15 -> 171720.03 | P15: =ROUND(N15*3%,0) + N15 -> 166860.03 | Q15: =Q14+0.01 -> 0.03
A16: 4 | B16: 2 B | C16: CRUZ ADRIANA BEATRIZ | D16: Cristian Rodrigo Centurion | E16: 6.6 | F16: 191638.04 | G16: =209778-G32 -> 191637.8 | H16: =F16-G16 -> 0.24 | I16: =IF(H16>0,H16*3%,0) -> 0.0072 | J16: =K$2*E16/100 -> 198000 | K16: =G$2*E16/100 -> 0 | L16: =EDESUR!O7 -> 0 | N16: =ROUND(SUM(H16:M16),0) + Q16 -> 198000.04 | O16: =ROUND(N16*6% + N16,0) + Q16 -> 209880.04 | P16: =ROUND(N16*3%,0) + N16 -> 203940.04 | Q16: =Q15+0.01 -> 0.04 | R16: Cristian oscar Rifici
A17: 5 | B17: 2 C | C17: D AMURI JOSE LUIS | D17: Martina Belen Carbone | E17: 6.6 | F17: 198000.05 | G17: =F17 -> 198000.05 | H17: =F17-G17 -> 0 | I17: =IF(H17>0,H17*3%,0) -> 0 | J17: =K$2*E17/100 -> 198000 | K17: =G$2*E17/100 -> 0 | L17: =EDESUR!O8 -> 0 | M17: 0 | N17: =ROUND(SUM(H17:M17),0) + Q17 -> 198000.05 | O17: =ROUND(N17*6% + N17,0) + Q17 -> 209880.05 | P17: =ROUND(N17*3%,0) + N17 -> 203940.05 | Q17: =Q16+0.01 -> 0.05 | R17: Alejo Moreno
A18: 6 | B18: 2 D | C18: CAMPOLONGO LUIS | D18: Leandro Gonzalez | E18: 5.4 | F18: 162000.06 | G18: =F18 -> 162000.06 | H18: =F18-G18 -> 0 | I18: =IF(H18>0,H18*3%,0) -> 0 | J18: =K$2*E18/100 -> 162000 | K18: =G$2*E18/100 -> 0 | L18: =EDESUR!O9 -> 0 | N18: =ROUND(SUM(H18:M18),0) + Q18 -> 162000.06 | O18: =ROUND(N18*6% + N18,0) + Q18 -> 171720.06 | P18: =ROUND(N18*3%,0) + N18 -> 166860.06 | Q18: =Q17+0.01 -> 0.06
A19: 7 | B19: 2 A | C19: PEREZ FERNANDO ARIEL | D19: Gaston Miranda | E19: 5.4 | F19: 166860.07 | G19: =F19 -> 166860.07 | H19: =F19-G19 -> 0 | I19: =IF(H19>0,H19*3%,0) -> 0 | J19: =K$2*E19/100 -> 162000 | K19: =G$2*E19/100 -> 0 | L19: =EDESUR!O10 -> 0 | N19: =ROUND(SUM(H19:M19),0) + Q19 -> 162000.07 | O19: =ROUND(N19*6% + N19,0) + Q19 -> 171720.07 | P19: =ROUND(N19*3%,0) + N19 -> 166860.07 | Q19: =Q18+0.01 -> 0.07
A20: 8 | B20: 3 B | C20: BURGOA CARINA | D20: Alan/Ailen | E20: 6.6 | F20: 275013.08 | G20: =F20 -> 275013.08 | H20: =F20-G20 -> 0 | I20: =IF(H20>0,H20*3%,0) -> 0 | J20: =K$2*E20/100 -> 198000 | K20: =G$2*E20/100 -> 0 | L20: =EDESUR!O12 -> 98658.34 | N20: =ROUND(SUM(H20:M20),0) + Q20 -> 296658.08 | O20: =ROUND(N20*6% + N20,0) + Q20 -> 314458.08 | P20: =ROUND(N20*3%,0) + N20 -> 305558.08 | Q20: =Q19+0.01 -> 0.08
A21: 9 | B21: 3 C | C21: GIL ROSANNA MABEL | D21: Gaston ibarra | E21: 6.6 | F21: 198000.09 | G21: =F21 -> 198000.09 | H21: =F21-G21 -> 0 | I21: =IF(H21>0,H21*3%,0) -> 0 | J21: =K$2*E21/100 -> 198000 | K21: =G$2*E21/100 -> 0 | L21: 0 | M21: 50000 | N21: =ROUND(SUM(H21:M21),0) + Q21 -> 248000.09 | O21: =ROUND(N21*6% + N21,0) + Q21 -> 262880.09 | P21: =ROUND(N21*3%,0) + N21 -> 255440.09 | Q21: =Q20+0.01 -> 0.09
A22: 10 | B22: 3 D | C22: FELIX ALBERTO | D22: Jhonatan | E22: 5.4 | F22: 4012.1 | G22: =F22 -> 4012.1 | H22: =F22-G22 -> 0 | I22: =IF(H22>0,H22*3%,0) -> 0 | J22: =K$2*E22/100 -> 162000 | K22: =G$2*E22/100 -> 0 | L22: =EDESUR!O13 -> 0 | N22: =ROUND(SUM(H22:M22),0) + Q22 -> 162000.1 | O22: =ROUND(N22*6% + N22,0) + Q22 -> 171720.1 | P22: =ROUND(N22*3%,0) + N22 -> 166860.1 | Q22: =Q21+0.01 -> 0.1
A23: 11 | B23: 3 A | C23: CAMPANA WALTER CESAR | E23: 5.4 | F23: 162000.11 | G23: =171070.33-G34 -> 162000.11 | H23: =F23-G23 -> 0 | I23: =IF(H23>0,H23*3%,0) -> 0 | J23: =K$2*E23/100 -> 162000 | K23: =G$2*E23/100 -> 0 | L23: =EDESUR!O14 -> 0 | N23: =ROUND(SUM(H23:M23),0) + Q23 -> 162000.11 | O23: =ROUND(N23*6% + N23,0) + Q23 -> 171720.11 | P23: =ROUND(N23*3%,0) + N23 -> 166860.11 | Q23: =Q22+0.01 -> 0.11 | R23: Antonella
A24: 12 | B24: 4 B | C24: PALMA JOSE AGUSTIN | D24: Juan Ignacio / Mariel Cruz | E24: 6.6 | F24: 198000.12 | G24: =F24 -> 198000.12 | H24: =F24-G24 -> 0 | I24: =IF(H24>0,H24*3%,0) -> 0 | J24: =K$2*E24/100 -> 198000 | K24: =G$2*E24/100 -> 0 | L24: =EDESUR!O15 -> 0 | N24: =ROUND(SUM(H24:M24),0) + Q24 -> 198000.12 | O24: =ROUND(N24*6% + N24,0) + Q24 -> 209880.12 | P24: =ROUND(N24*3%,0) + N24 -> 203940.12 | Q24: =Q23+0.01 -> 0.12
A25: 13 | B25: 4 C | C25: BENITEZ EMILIA ISABEL | D25: Daniel Leiva | E25: 6.6 | F25: 192168.13 | G25: 197933.13 | H25: =F25-G25 -> -5765 | I25: =IF(H25>0,H25*3%,0) -> 0 | J25: =K$2*E25/100 -> 198000 | K25: =G$2*E25/100 -> 0 | L25: =EDESUR!O16 -> 0 | N25: =ROUND(SUM(H25:M25),0) + Q25 -> 192235.13 | O25: =ROUND(N25*6% + N25,0) + Q25 -> 203769.13 | P25: =ROUND(N25*3%,0) + N25 -> 198002.13 | Q25: =Q24+0.01 -> 0.13
A26: 14 | B26: 4 D | C26: PUCHETA SANTIAGO / CLARA | E26: 5.4 | F26: 162000.14 | G26: =F26 -> 162000.14 | H26: =F26-G26 -> 0 | I26: =IF(H26>0,H26*3%,0) -> 0 | J26: =K$2*E26/100 -> 162000 | K26: =G$2*E26/100 -> 0 | L26: =EDESUR!O17 -> 0 | N26: =ROUND(SUM(H26:M26),0) + Q26 -> 162000.14 | O26: =ROUND(N26*6% + N26,0) + Q26 -> 171720.14 | P26: =ROUND(N26*3%,0) + N26 -> 166860.14 | Q26: =Q25+0.01 -> 0.14
A27: 15 | B27: 4 A | C27: CAMPANA MIRIAM NOEMI | E27: 5.4 | F27: 162000.15 | G27: =F27 -> 162000.15 | H27: =F27-G27 -> 0 | I27: =IF(H27>0,H27*3%,0) -> 0 | J27: =K$2*E27/100 -> 162000 | K27: =G$2*E27/100 -> 0 | L27: =EDESUR!O18 -> 0 | N27: =ROUND(SUM(H27:M27),0) + Q27 -> 162000.15 | O27: =ROUND(N27*6% + N27,0) + Q27 -> 171720.15 | P27: =ROUND(N27*3%,0) + N27 -> 166860.15 | Q27: =Q26+0.01 -> 0.15
A28: 16 | B28: COC 1 | C28: CAMPOLONGO LUIS | D28: Leandro Gonzalez | E28: 0.7 | F28: 21163.16 | G28: =F28 -> 21163.16 | H28: =F28-G28 -> 0 | I28: =IF(H28>0,H28*3%,0) -> 0 | J28: =K$2*E28/100 -> 21000 | K28: =G$2*E28/100 -> 0 | L28: =EDESUR!O19 -> 0 | N28: =ROUND(SUM(H28:M28),0) + Q28 -> 21000.16 | O28: =ROUND(N28*6% + N28,0) + Q28 -> 22260.16 | P28: =ROUND(N28*3%,0) + N28 -> 21630.16 | Q28: =Q27+0.01 -> 0.16
A29: 17 | B29: COC 2 | C29: MIRAGLIA NORBERTO JOSE | E29: 0.6 | F29: 18140.17 | G29: =F29 -> 18140.17 | H29: =F29-G29 -> 0 | I29: =IF(H29>0,H29*3%,0) -> 0 | J29: =K$2*E29/100 -> 18000 | K29: =G$2*E29/100 -> 0 | L29: 0 | N29: =ROUND(SUM(H29:M29),0) + Q29 -> 18000.17 | O29: =ROUND(N29*6% + N29,0) + Q29 -> 19080.17 | P29: =ROUND(N29*3%,0) + N29 -> 18540.17 | Q29: =Q28+0.01 -> 0.17
A30: 18 | B30: COC 3 | C30: MIRAGLIA NORBERTO JOSE | E30: 0.6 | F30: 18140.18 | G30: =F30 -> 18140.18 | H30: =F30-G30 -> 0 | I30: =IF(H30>0,H30*3%,0) -> 0 | J30: =K$2*E30/100 -> 18000 | K30: =G$2*E30/100 -> 0 | L30: =EDESUR!O21 -> 0 | N30: =ROUND(SUM(H30:M30),0) + Q30 -> 18000.18 | O30: =ROUND(N30*6% + N30,0) + Q30 -> 19080.18 | P30: =ROUND(N30*3%,0) + N30 -> 18540.18 | Q30: =Q29+0.01 -> 0.18
A31: 19 | B31: COC 4 | C31: PALMA JOSE AGUSTIN | E31: 0.6 | F31: 18140.19 | G31: =F31 -> 18140.19 | H31: =F31-G31 -> 0 | I31: =IF(H31>0,H31*3%,0) -> 0 | J31: =K$2*E31/100 -> 18000 | K31: =G$2*E31/100 -> 0 | L31: =EDESUR!O22 -> 0 | N31: =ROUND(SUM(H31:M31),0) + Q31 -> 18000.19 | P31: =ROUND(N31*3%,0) + N31 -> 18540.19 | Q31: =Q30+0.01 -> 0.19
A32: 20 | B32: COC 5 | C32: CRUZ ADRIANA BEATRIZ | D32: Cristian Rodrigo Centurion | E32: 0.6 | F32: 18140.2 | G32: =F32 -> 18140.2 | H32: =F32-G32 -> 0 | I32: =IF(H32>0,H32*3%,0) -> 0 | J32: =K$2*E32/100 -> 18000 | K32: =G$2*E32/100 -> 0 | L32: =EDESUR!O23 -> 0 | N32: =ROUND(SUM(H32:M32),0) + Q32 -> 18000.2 | P32: =ROUND(N32*3%,0) + N32 -> 18540.2 | Q32: =Q31+0.01 -> 0.2
A33: 21 | B33: COC 6 | C33: FELIX ALBERTO | D33: Jhonatan | E33: 0.3 | F33: 9070.21 | G33: =F33 -> 9070.21 | H33: =F33-G33 -> 0 | I33: =IF(H33>0,H33*3%,0) -> 0 | J33: =K$2*E33/100 -> 9000 | K33: =G$2*E33/100 -> 0 | L33: =EDESUR!O24 -> 0 | N33: =ROUND(SUM(H33:M33),0) + Q33 -> 9000.21 | P33: =ROUND(N33*3%,0) + N33 -> 9270.21 | Q33: =Q32+0.01 -> 0.21
A34: 22 | B34: COC 7 | C34: CAMPANA WALTER CESAR | E34: 0.3 | F34: 9070.22 | G34: =F34 -> 9070.22 | H34: =F34-G34 -> 0 | I34: =IF(H34>0,H34*3%,0) -> 0 | J34: =K$2*E34/100 -> 9000 | K34: =G$2*E34/100 -> 0 | L34: =EDESUR!O25 -> 0 | N34: =ROUND(SUM(H34:M34),0) + Q34 -> 9000.22 | P34: =ROUND(N34*3%,0) + N34 -> 9270.22 | Q34: =Q33+0.01 -> 0.22
A35: 23 | B35: COC 8 | C35: REDONDO HECTOR | D35: Gilmer | E35: 0.3 | F35: 9070.23 | G35: =F35 -> 9070.23 | H35: =F35-G35 -> 0 | I35: =IF(H35>0,H35*3%,0) -> 0 | J35: =K$2*E35/100 -> 9000 | K35: =G$2*E35/100 -> 0 | L35: =EDESUR!O26 -> 0 | N35: =ROUND(SUM(H35:M35),0) + Q35 -> 9000.23 | P35: =ROUND(N35*3%,0) + N35 -> 9270.23 | Q35: =Q34+0.01 -> 0.23
E36: =SUM(E13:E35) -> 100 | F36: =SUM(F13:F35) -> 3054299.8 | G36: =SUM(G13:G35) -> 3060391.1 | H36: =SUM(H13:H35) -> -6091.37 | I36: =SUM(I13:I35) -> 0.0183 | J36: =SUM(J13:J35) -> 3000000 | K36: =SUM(K13:K35) -> 0 | L36: =SUM(L13:L35) -> 223921.51 | N36: =SUM(N13:N35) -> 3267831.8 | O36: =SUM(O13:O35) -> 3397120.7 | P36: =SUM(P13:P35) -> 3365866.8
C39: =RESUMEN!A13 -> ESTIMADOS PROPIETARIOS E INQUILINOS: POR FAVOR LOS QUE ABONAN EN PRIMER VENCIMIENTO ABONEN EL MONTO DE PRIMER VENCIMIENTO, ASI AGILIZAN LA LIQUIDACION, RESPETEN LOS CENTAVOS CORRESPONDIENTES A LA UNIDAD FUNCIONAL. ES DE CARÁCTER OBLIGATORIO INFORMAR VIA MAIL LAS EXPENSAS. PORFAVOR RESPETAR LOS CENTAVOS AL ABONAR.

Sheet EDESUR
D2: Consumos PARTICULARES | H2: Consumos GENERALES | K2: Total Edesur x Depto | M2: Bonificado x EDESUR | O2: SALDO a PAGAR
B3: Piso | C3: Depto | D3: Consumo Kw | E3: % Consumido | F3: Consumo x Dep | H3: Porcentaje | I3: Cons Esp Com
B4: 1 | C4: A | D4: 0 | E4: 0 | F4: 0 | H4: 0.12 | I4: 5711.4946 | K4: =I4+F4 -> 5711.4946 | M4: =K4 -> 5711.4946 | O4: =K4-M4 -> 0
B5: 1 | C5: C | D5: 300.2 | E5: 0.5611215 | F5: 122121.84 | H5: 0.066 | I5: 3141.322 | K5: =I5+F5 -> 125263.17 | M5: 0 | O5: =K5-M5 -> 125263.17
B6: 1 | C6: D | D6: 0 | E6: 0 | F6: 0 | H6: 0.054 | I6: 2570.1726 | K6: =I6+F6 -> 2570.1726 | M6: =K6 -> 2570.1726 | O6: =K6-M6 -> 0
B7: 2 | C7: A | D7: 0 | E7: 0 | F7: 0 | H7: 0.054 | I7: 2570.1726 | K7: =I7+F7 -> 2570.1726 | M7: =K7 -> 2570.1726 | O7: =K7-M7 -> 0
B8: 2 | C8: B | D8: 0 | E8: 0 | F8: 0 | H8: 0.066 | I8: 3141.322 | K8: =I8+F8 -> 3141.322 | M8: =K8 -> 3141.322 | O8: =K8-M8 -> 0
B9: 2 | C9: C | D9: 0 | E9: 0 | F9: 0 | H9: 0.066 | I9: 3141.322 | K9: =I9+F9 -> 3141.322 | M9: =K9 -> 3141.322 | O9: =K9-M9 -> 0
B10: 2 | C10: D | D10: 0 | E10: 0 | F10: 0 | H10: 0.054 | I10: 2570.1726 | K10: =I10+F10 -> 2570.1726 | M10: =K10 -> 2570.1726 | O10: =K10-M10 -> 0
B11: 3 | C11: A | D11: 0 | E11: 0 | F11: 0 | H11: 0.054 | I11: 2570.1726 | K11: =I11+F11 -> 2570.1726 | M11: =K11 -> 2570.1726 | O11: =K11-M11 -> 0
B12: 3 | C12: B | D12: 234.8 | E12: 0.4388785 | F12: 95517.018 | H12: 0.066 | I12: 3141.322 | K12: =I12+F12 -> 98658.34 | M12: 0 | O12: =K12-M12 -> 98658.34
B13: 3 | C13: C | D13: 0 | E13: 0 | F13: 0 | H13: 0.066 | I13: 3141.322 | K13: =I13+F13 -> 3141.322 | M13: =K13 -> 3141.322 | O13: =K13-M13 -> 0
B14: 3 | C14: D | D14: 0 | E14: 0 | F14: 0 | H14: 0.054 | I14: 2570.1726 | K14: =I14+F14 -> 2570.1726 | M14: =K14 -> 2570.1726 | O14: =K14-M14 -> 0
B15: 4 | C15: A | D15: 0 | E15: 0 | F15: 0 | H15: 0.054 | I15: 2570.1726 | K15: =I15+F15 -> 2570.1726 | M15: =K15 -> 2570.1726 | O15: =K15-M15 -> 0
B16: 4 | C16: B | D16: 0 | E16: 0 | F16: 0 | H16: 0.066 | I16: 3141.322 | K16: =I16+F16 -> 3141.322 | M16: =K16 -> 3141.322 | O16: =K16-M16 -> 0
B17: 4 | C17: C | D17: 0 | E17: 0 | F17: 0 | H17: 0.066 | I17: 3141.322 | K17: =I17+F17 -> 3141.322 | M17: =K17 -> 3141.322 | O17: =K17-M17 -> 0
B18: 4 | C18: D | D18: 0 | E18: 0 | F18: 0 | H18: 0.054 | I18: 2570.1726 | K18: =I18+F18 -> 2570.1726 | M18: =K18 -> 2570.1726 | O18: =K18-M18 -> 0
C20: Totales | D20: =SUM(D4:D19) -> 535 | F20: =SUM(F4:F19) -> 217638.86 | I20: =SUM(I4:I19) -> 45691.957 | K20: =SUM(K4:K19) -> 263330.82 | M20: =SUM(M4:M19) -> 39409.313 | O20: =SUM(O4:O19) -> 223921.51
E21: Mes ANTERIOR
B22: Cochera | C22: 1 | H22: 0.007 | I22: 333.17052 | K22: =I22 -> 333.17052 | M22: 333.17052 | O22: =K22-M22 -> 0
B23: Cochera | C23: 2 | H23: 0.006 | I23: 285.57473 | K23: =I23 -> 285.57473 | M23: 285.57473 | O23: =K23-M23 -> 0
B24: Cochera | C24: 3 | H24: 0.006 | I24: 285.57473 | K24: =I24 -> 285.57473 | M24: 285.57473 | O24: =K24-M24 -> 0
B25: Cochera | C25: 4 | H25: 0.006 | I25: 285.57473 | K25: =I25 -> 285.57473 | M25: 285.57473 | O25: =K25-M25 -> 0
B26: Cochera | C26: 5 | H26: 0.006 | I26: 285.57473 | K26: =I26 -> 285.57473 | M26: 285.57473 | O26: =K26-M26 -> 0
B27: Cochera | C27: 6 | H27: 0.003 | I27: 142.78737 | K27: =I27 -> 142.78737 | M27: 142.78737 | O27: =K27-M27 -> 0
B28: Cochera | C28: 7 | H28: 0.003 | I28: 142.78737 | K28: =I28 -> 142.78737 | M28: 142.78737 | O28: =K28-M28 -> 0
B29: Cochera | C29: 8 | H29: 0.003 | I29: 142.78737 | K29: =I29 -> 142.78737 | M29: 142.78737 | O29: =K29-M29 -> 0
H30: Cons Coch | I30: =SUM(I22:I29) -> 1903.8315 | K30: =SUM(K22:K29) -> 1903.8315 | M30: =SUM(M22:M29) -> 1903.8315 | O30: =SUM(O22:O29) -> 0
D32: TOTAL FACT EDESUR | F32: 265234.65 | I32: =F20+I20+I30 -> 265234.65 | K32: =K20+K30 -> 265234.65 | M32: =M20+M30 -> 41313.144 | O32: =O20+O30 -> 223921.51

Sheet Anotaciones
C3: A gaston le doble cobramos un sum erroneamente el mes pasado, corregir en agosto - Debe abonar 132.216,09 , pago 182.216,09
