Workbook

Sheet RESUMEN
B1: MAIL: salta1167rc@gmail.com
B2: CUIT ADMINISTRACION: 27231256879
B3: CONSORCIO DE PROPIETARIOS EDIFICIO CALLE SALTA 1167/1169 C DE P SALTA 1167 1169 LANUS CTA CTE $ 039 - 22273/6 CBU: 0720039720000002227368
A4: LIQUIDACION DE EXPENSAS | B4: ADMINISTRADORA: CAROLINA CANCIANI MP:1148
A5: CUIT DEL EDIFICIO: 30-719118061-9 | B5: PERÍODO: DICIEMBRE | D5: HORARIOS DE ATENCION: LUNES A VIERNES
A6: CONSORCIO DE PROPIETARIOS DEL EDIFICIO CALLE YRIGOYEN 9730 | D6: 10 A 16HS - EMERGENCIAS 24HS
B8: VTO 15/01
A13: ESTIMADOS PROPIETARIOS E INQUILINOS: POR FAVOR LOS QUE ABONAN EN PRIMER VENCIMIENTO ABONEN EL MONTO DE PRIMER VENCIMIENTO, ASI AGILIZAN LA LIQUIDACION, RESPETEN LOS CENTAVOS CORRESPONDIENTES A LA UNIDAD FUNCIONAL. ES DE CARÁCTER OBLIGATORIO INFORMAR VIA MAIL LAS EXPENSAS. PORFAVOR RESPETAR LOS CENTAVOS AL ABONAR.
A20: GASTOS A - UNIDADES FUNCIONALES:
A21: LIMPIEZA
A22: Full Clean - Servicio de limpieza | D22: 464897.27 | E22: Transf 02/12
A24: TOTAL | E24: =SUM(D22:D23) -> 464897.27
A25: SEGUROS
A26: Federacion patronal Seguro obligatorio de consorcio - Poliza nro. 1-2249124-0 | D26: 74591 | E26: Debito 09/12
A27: TOTAL IMPUESTO | E27: =SUM(D26:D26) -> 74591
A28: ABONOS Y SERVICIOS
A29: Edesur | D29: 0
A30: Metrogas | D30: 5494.37 | E30: Transf 02/12
A31: Metrogas | D31: 323182.89 | E31: Transf 02/12
A32: AySa | D32: 358176.46 | E32: Transf 02/12
A33: Servicio de interet Claro | D33: 21236.33 | E33: Transf 02/12
A34: TOTAL ABONOS Y SERVICIOS | E34: =SUM(D29:D33) -> 708090.05
A36: Lema - Ascensores - Servicio de mantenimiento - Se abona a mes vencido
A37: Sr. Hector Piletero | D37: 82600 | E37: Transf 30/12
A38: Chavez Pablo - Impermeabilizacion de medianera | D38: 1537000 | E38: Transf 22/12
A39: Chavez Pablo - Impermeabilizacion de medianera | D39: 90000 | E39: Transf 29/12
A40: Indugar SRL - Compra de pinturas trabajo en medianera | D40: 42370 | E40: Transf 16/12
A41: Pintureria Gianonni - Bricol para ceramicos | D41: 24884.21 | E41: Sr. Pucheta
A42: TOTAL | E42: =SUM(D36:D41) -> 1776854.2
A43: HONORARIOS
A44: Honorarios administracion | D44: 140000
A46: TOTAL | E46: =SUM(D44:D45) -> 140000
A47: GASTOS BANCARIOS
A48: Mantenimiento de cuenta
A49: Gastos bancarios | D49: =40662.21-311.85-1485-4686.04-151.2-720-450+720+151.2+540 -> 34269.32
A50: TOTAL | E50: =SUM(D48:D49) -> 34269.32
A52: PREVISION GASTOS A
A54: TOTAL GASTOS A | E54: =(SUM(E21:E52)) -> 3198701.8
A57: GASTOS B:
E62: =SUM(D58:D61) -> 0
...

Sheet PRORRATEO
E2: Gastos B | G2: 0 | K2: Gastos A | L2: 2000000
A4: ¡IMPORTANTE! Estimados convivientes: Les solicitamos, por favor, que al momento de realizar el pago respeten los centavos que figuran en el monto indicado, ya que estos nos permiten identificar correctamente los pagos y las unidades funcionales, reduciendo así el margen de error. Muchas gracias por su colaboración.
A9: QUIENES ESTAN MARCADOS DE COLOR VERDE NO HAN ABONADO A LA CUENTA BANCARIA CORRESPONDIENTE. REITERAMOS QUE LOS DATOS DE LA CUENTA EN DONDE DEBEN ABONAR LAS EXPENSAS SON: CONSORCIO DE PROPIETARIOS EDIFICIO CALLE SALTA 1167/1169 - C DE P SALTA 1167 1169 LANUS - CTA CTE $ 039 - 22273/6 CBU: 0720039720000002227368
A10: QUIENES ESTAN EN VIOLETA NO ESTAN RESPETANDO LOS CENTAVOS AL ABONAR.
A11: UF | C11: Propietario | D11: Inquilinos | E11: (%) | F11: Saldo Ord | G11: Ingreso | H11: Deuda o Saldo a favor | I11: Interes 3% | J11: EDESUR | K11: Gastos A | L11: Gastos B | M11: Total 1er Vto | N11: Total 2do Vto. | O11: Total 2do Vto
M12: =RESUMEN!B8 -> VTO 15/01
A13: 1 | B13: 1 A | C13: MIRAGLIA NORBERTO JOSE | E13: 12 | F13: 232082.01 | G13: =256082.01-G29-G30 -> 232081.66 | H13: =F13-G13 -> 0.35 | I13: =IF(H13>0,H13*3%,0) -> 0.0105 | J13: =EDESUR!I5 -> 0 | K13: =L$2*E13/100 -> 240000 | L13: =G$2*E13/100 -> 0 | M13: =ROUND(SUM(H13:L13),0) + P13 -> 240000.01 | N13: =ROUND(M13*6% + M13,0) + P13 -> 254400.01 | O13: =ROUND(M13*3%,0) + M13 -> 247200.01 | P13: 0.01
A14: 2 | B14: 1 C | C14: ADAMO PABLO MARIANO | E14: 6.6 | F14: 132000.02 | G14: =F14 -> 132000.02 | H14: =F14-G14 -> 0 | I14: =IF(H14>0,H14*3%,0) -> 0 | J14: =EDESUR!I6 -> 0 | K14: =L$2*E14/100 -> 132000 | L14: =G$2*E14/100 -> 0 | M14: =ROUND(SUM(H14:L14),0) + P14 -> 132000.02 | N14: =ROUND(M14*6% + M14,0) + P14 -> 139920.02 | O14: =ROUND(M14*3%,0) + M14 -> 135960.02 | P14: =P13+0.01 -> 0.02
A15: 3 | B15: 1 D | C15: REDONDO | D15: Gilmer | E15: 5.4 | F15: 108000.03 | G15: =F15 -> 108000.03 | H15: =F15-G15 -> 0 | I15: =IF(H15>0,H15*3%,0) -> 0 | J15: =EDESUR!I7 -> 0 | K15: =L$2*E15/100 -> 108000 | L15: =G$2*E15/100 -> 0 | M15: =ROUND(SUM(H15:L15),0) + P15 -> 108000.03 | N15: =ROUND(M15*6% + M15,0) + P15 -> 114480.03 | O15: =ROUND(M15*3%,0) + M15 -> 111240.03 | P15: =P14+0.01 -> 0.03
A16: 4 | B16: 2 B | C16: CRUZ ADRIANA BEATRIZ | D16: Cristian | E16: 6.6 | F16: 129700.04 | G16: =154060-G32 -> 129700 | H16: =F16-G16 -> 0.04 | I16: =IF(H16>0,H16*3%,0) -> 0.0012 | J16: =EDESUR!I8 -> 0 | K16: =L$2*E16/100 -> 132000 | L16: =G$2*E16/100 -> 0 | M16: =ROUND(SUM(H16:L16),0) + P16 -> 132000.04 | N16: =ROUND(M16*6% + M16,0) + P16 -> 139920.04 | O16: =ROUND(M16*3%,0) + M16 -> 135960.04 | P16: =P15+0.01 -> 0.04
A17: 5 | B17: 2 C | C17: D AMURI JOSE LUIS | D17: Martina Belen Carbone | E17: 6.6 | F17: 132000.05 | G17: =F17 -> 132000.05 | H17: =F17-G17 -> 0 | I17: =IF(H17>0,H17*3%,0) -> 0 | J17: =EDESUR!I9 -> 0 | K17: =L$2*E17/100 -> 132000 | L17: =G$2*E17/100 -> 0 | M17: =ROUND(SUM(H17:L17),0) + P17 -> 132000.05 | N17: =ROUND(M17*6% + M17,0) + P17 -> 139920.05 | O17: =ROUND(M17*3%,0) + M17 -> 135960.05 | P17: =P16+0.01 -> 0.05 | Q17: Alejo Moreno
A18: 6 | B18: 2 D | C18: CAMPOLONGO LUIS | D18: Leandro Gonzalez | E18: 5.4 | F18: 108000.06 | G18: =F18 -> 108000.06 | H18: =F18-G18 -> 0 | I18: =IF(H18>0,H18*3%,0) -> 0 | J18: =EDESUR!I10 -> 0 | K18: =L$2*E18/100 -> 108000 | L18: =G$2*E18/100 -> 0 | M18: =ROUND(SUM(H18:L18),0) + P18 -> 108000.06 | N18: =ROUND(M18*6% + M18,0) + P18 -> 114480.06 | O18: =ROUND(M18*3%,0) + M18 -> 111240.06 | P18: =P17+0.01 -> 0.06
A19: 7 | B19: 2 A | C19: PEREZ FERNANDO ARIEL | D19: Gaston Miranda | E19: 5.4 | F19: 108000.07 | G19: =F19 -> 108000.07 | H19: =F19-G19 -> 0 | I19: =IF(H19>0,H19*3%,0) -> 0 | J19: =EDESUR!I11 -> 0 | K19: =L$2*E19/100 -> 108000 | L19: =G$2*E19/100 -> 0 | M19: =ROUND(SUM(H19:L19),0) + P19 -> 108000.07 | N19: =ROUND(M19*6% + M19,0) + P19 -> 114480.07 | O19: =ROUND(M19*3%,0) + M19 -> 111240.07 | P19: =P18+0.01 -> 0.07
A20: 8 | B20: 3 B | C20: BURGOA CARINA | D20: Alan/Ailen | E20: 6.6 | F20: 132000.08 | G20: =F20 -> 132000.08 | H20: =F20-G20 -> 0 | I20: =IF(H20>0,H20*3%,0) -> 0 | J20: =EDESUR!I12 -> 0 | K20: =L$2*E20/100 -> 132000 | L20: =G$2*E20/100 -> 0 | M20: =ROUND(SUM(H20:L20),0) + P20 -> 132000.08 | N20: =ROUND(M20*6% + M20,0) + P20 -> 139920.08 | O20: =ROUND(M20*3%,0) + M20 -> 135960.08 | P20: =P19+0.01 -> 0.08
A21: 9 | B21: 3 C | C21: GIL ROSANNA MABEL | D21: Gaston ibarra | E21: 6.6 | F21: 132000.09 | G21: =F21 -> 132000.09 | H21: =F21-G21 -> 0 | I21: =IF(H21>0,H21*3%,0) -> 0 | J21: =EDESUR!I13 -> 0 | K21: =L$2*E21/100 -> 132000 | L21: =G$2*E21/100 -> 0 | M21: =ROUND(SUM(H21:L21),0) + P21 -> 132000.09 | N21: =ROUND(M21*6% + M21,0) + P21 -> 139920.09 | O21: =ROUND(M21*3%,0) + M21 -> 135960.09 | P21: =P20+0.01 -> 0.09
A22: 10 | B22: 3 D | C22: FELIX ALBERTO | D22: Jhonatan | E22: 5.4 | F22: 68000.1 | G22: =F22 -> 68000.1 | H22: =F22-G22 -> 0 | I22: =IF(H22>0,H22*3%,0) -> 0 | J22: =EDESUR!I14 -> 0 | K22: =L$2*E22/100 -> 108000 | L22: =G$2*E22/100 -> 0 | M22: =ROUND(SUM(H22:L22),0) + P22 -> 108000.1 | N22: =ROUND(M22*6% + M22,0) + P22 -> 114480.1 | O22: =ROUND(M22*3%,0) + M22 -> 111240.1 | P22: =P21+0.01 -> 0.1
A23: 11 | B23: 3 A | C23: CAMPANA WALTER CESAR | E23: 5.4 | F23: 108000.11 | G23: =114000.11-G34 -> 108000.11 | H23: =F23-G23 -> 0 | I23: =IF(H23>0,H23*3%,0) -> 0 | J23: =EDESUR!I15 -> 0 | K23: =L$2*E23/100 -> 108000 | L23: =G$2*E23/100 -> 0 | M23: =ROUND(SUM(H23:L23),0) + P23 -> 108000.11 | N23: =ROUND(M23*6% + M23,0) + P23 -> 114480.11 | O23: =ROUND(M23*3%,0) + M23 -> 111240.11 | P23: =P22+0.01 -> 0.11 | Q23: Antonella
A24: 12 | B24: 4 B | C24: PALMA JOSE AGUSTIN | D24: Juan Ignacio / Mariel Cruz | E24: 6.6 | F24: 132000.12 | G24: =F24 -> 132000.12 | H24: =F24-G24 -> 0 | I24: =IF(H24>0,H24*3%,0) -> 0 | J24: =EDESUR!I16 -> 0 | K24: =L$2*E24/100 -> 132000 | L24: =G$2*E24/100 -> 0 | M24: =ROUND(SUM(H24:L24),0) + P24 -> 132000.12 | N24: =ROUND(M24*6% + M24,0) + P24 -> 139920.12 | O24: =ROUND(M24*3%,0) + M24 -> 135960.12 | P24: =P23+0.01 -> 0.12
A25: 13 | B25: 4 C | C25: BENITEZ EMILIA ISABEL | D25: Daniel Leiva | E25: 6.6 | F25: 128040.13 | G25: 131881.13 | H25: =F25-G25 -> -3841 | I25: =IF(H25>0,H25*3%,0) -> 0 | J25: =EDESUR!I17 -> 0 | K25: =L$2*E25/100 -> 132000 | L25: =G$2*E25/100 -> 0 | M25: =ROUND(SUM(H25:L25),0) + P25 -> 128159.13 | N25: =ROUND(M25*6% + M25,0) + P25 -> 135849.13 | O25: =ROUND(M25*3%,0) + M25 -> 132004.13 | P25: =P24+0.01 -> 0.13
A26: 14 | B26: 4 D | C26: PUCHETA SANTIAGO / CLARA | E26: 5.4 | F26: 108000.14 | G26: =F26+RESUMEN!D41 -> 132884.35 | H26: =F26-G26 -> -24884.21 | I26: =IF(H26>0,H26*3%,0) -> 0 | J26: =EDESUR!I18 -> 0 | K26: =L$2*E26/100 -> 108000 | L26: =G$2*E26/100 -> 0 | M26: =ROUND(SUM(H26:L26),0) + P26 -> 83116.14 | N26: =ROUND(M26*6% + M26,0) + P26 -> 88103.14 | O26: =ROUND(M26*3%,0) + M26 -> 85609.14 | P26: =P25+0.01 -> 0.14
A27: 15 | B27: 4 A | C27: CAMPANA MIRIAM NOEMI | E27: 5.4 | F27: 108000.15 | G27: =F27 -> 108000.15 | H27: =F27-G27 -> 0 | I27: =IF(H27>0,H27*3%,0) -> 0 | J27: =EDESUR!I19 -> 0 | K27: =L$2*E27/100 -> 108000 | L27: =G$2*E27/100 -> 0 | M27: =ROUND(SUM(H27:L27),0) + P27 -> 108000.15 | N27: =ROUND(M27*6% + M27,0) + P27 -> 114480.15 | O27: =ROUND(M27*3%,0) + M27 -> 111240.15 | P27: =P26+0.01 -> 0.15
A28: 16 | B28: COC 1 | C28: CAMPOLONGO LUIS | D28: Leandro Gonzalez | E28: 0.7 | F28: 14000.16 | G28: =F28 -> 14000.16 | H28: =F28-G28 -> 0 | I28: =IF(H28>0,H28*3%,0) -> 0 | J28: =EDESUR!I22 -> 0 | K28: =L$2*E28/100 -> 14000 | L28: =G$2*E28/100 -> 0 | M28: =ROUND(SUM(H28:L28),0) + P28 -> 14000.16 | N28: =ROUND(M28*6% + M28,0) + P28 -> 14840.16 | O28: =ROUND(M28*3%,0) + M28 -> 14420.16 | P28: =P27+0.01 -> 0.16
A29: 17 | B29: COC 2 | C29: MIRAGLIA NORBERTO JOSE | E29: 0.6 | F29: 12000.17 | G29: =F29 -> 12000.17 | H29: =F29-G29 -> 0 | I29: =IF(H29>0,H29*3%,0) -> 0 | J29: =EDESUR!I21 -> 0 | K29: =L$2*E29/100 -> 12000 | L29: =G$2*E29/100 -> 0 | M29: =ROUND(SUM(H29:L29),0) + P29 -> 12000.17 | N29: =ROUND(M29*6% + M29,0) + P29 -> 12720.17 | O29: =ROUND(M29*3%,0) + M29 -> 12360.17 | P29: =P28+0.01 -> 0.17
A30: 18 | B30: COC 3 | C30: MIRAGLIA NORBERTO JOSE | E30: 0.6 | F30: 12000.18 | G30: =F30 -> 12000.18 | H30: =F30-G30 -> 0 | I30: =IF(H30>0,H30*3%,0) -> 0 | J30: =EDESUR!I22 -> 0 | K30: =L$2*E30/100 -> 12000 | L30: =G$2*E30/100 -> 0 | M30: =ROUND(SUM(H30:L30),0) + P30 -> 12000.18 | N30: =ROUND(M30*6% + M30,0) + P30 -> 12720.18 | O30: =ROUND(M30*3%,0) + M30 -> 12360.18 | P30: =P29+0.01 -> 0.18
A31: 19 | B31: COC 4 | C31: PALMA JOSE AGUSTIN | E31: 0.6 | F31: 12000.19 | G31: =F31 -> 12000.19 | H31: =F31-G31 -> 0 | I31: =IF(H31>0,H31*3%,0) -> 0 | J31: =EDESUR!I23 -> 0 | K31: =L$2*E31/100 -> 12000 | L31: =G$2*E31/100 -> 0 | M31: =ROUND(SUM(H31:L31),0) + P31 -> 12000.19 | O31: =ROUND(M31*3%,0) + M31 -> 12360.19 | P31: =P30+0.01 -> 0.19
A32: 20 | B32: COC 5 | C32: CRUZ ADRIANA BEATRIZ | D32: Cristian | E32: 0.6 | F32: 24360 | G32: =F32 -> 24360 | H32: =F32-G32 -> 0 | I32: =IF(H32>0,H32*3%,0) -> 0 | J32: =EDESUR!I24 -> 0 | K32: =L$2*E32/100 -> 12000 | L32: =G$2*E32/100 -> 0 | M32: =ROUND(SUM(H32:L32),0) + P32 -> 12000.2 | O32: =ROUND(M32*3%,0) + M32 -> 12360.2 | P32: =P31+0.01 -> 0.2
A33: 21 | B33: COC 6 | C33: FELIX ALBERTO | D33: Jhonatan | E33: 0.3 | F33: 6000 | G33: =F33 -> 6000 | H33: =F33-G33 -> 0 | I33: =IF(H33>0,H33*3%,0) -> 0 | J33: =EDESUR!I25 -> 0 | K33: =L$2*E33/100 -> 6000 | L33: =G$2*E33/100 -> 0 | M33: =ROUND(SUM(H33:L33),0) + P33 -> 6000.21 | O33: =ROUND(M33*3%,0) + M33 -> 6180.21 | P33: =P32+0.01 -> 0.21
A34: 22 | B34: COC 7 | C34: CAMPANA WALTER CESAR | E34: 0.3 | F34: 6000 | G34: =F34 -> 6000 | H34: =F34-G34 -> 0 | I34: =IF(H34>0,H34*3%,0) -> 0 | J34: =EDESUR!I26 -> 0 | K34: =L$2*E34/100 -> 6000 | L34: =G$2*E34/100 -> 0 | M34: =ROUND(SUM(H34:L34),0) + P34 -> 6000.22 | O34: =ROUND(M34*3%,0) + M34 -> 6180.22 | P34: =P33+0.01 -> 0.22
A35: 23 | B35: COC 8 | C35: REDONDO HECTOR | D35: Gilmer | E35: 0.3 | F35: 6000 | G35: =F35 -> 6000 | H35: =F35-G35 -> 0 | I35: =IF(H35>0,H35*3%,0) -> 0 | J35: =EDESUR!I27 -> 0 | K35: =L$2*E35/100 -> 6000 | L35: =G$2*E35/100 -> 0 | M35: =ROUND(SUM(H35:L35),0) + P35 -> 6000.23 | O35: =ROUND(M35*3%,0) + M35 -> 6180.23 | P35: =P34+0.01 -> 0.23
E36: =SUM(E13:E35) -> 100 | F36: =SUM(F13:F35) -> 1958183.9 | G36: =SUM(G13:G35) -> 1986908.7 | H36: =SUM(H13:H35) -> -28724.82 | I36: =SUM(I13:I35) -> 0.0117 | J36: =SUM(J13:J35) -> 0 | K36: =SUM(K13:K35) -> 2000000 | L36: =SUM(L13:L35) -> 0 | ... O36: =SUM(O13:O35) -> 2030415.8
C39: =RESUMEN!A13 -> ESTIMADOS PROPIETARIOS E INQUILINOS: POR FAVOR LOS QUE ABONAN EN PRIMER VENCIMIENTO ABONEN EL MONTO DE PRIMER VENCIMIENTO, ASI AGILIZAN LA LIQUIDACION, RESPETEN LOS CENTAVOS CORRESPONDIENTES A LA UNIDAD FUNCIONAL. ES DE CARÁCTER OBLIGATORIO INFORMAR VIA MAIL LAS EXPENSAS. PORFAVOR RESPETAR LOS CENTAVOS AL ABONAR.

Sheet EDESUR
B3: Piso | C3: Depto | E3: Total Edesur x Depto | G3: Bonificado x EDESUR Noviembre | I3: SALDO a PAGAR
B5: 1 | C5: A | E5: 26132.02 | G5: =E5 -> 26132.02 | I5: =E5-G5 -> 0
B6: 1 | C6: C | E6: 12925.66 | G6: =E6 -> 12925.66 | I6: =E6-G6 -> 0
B7: 1 | C7: D | E7: 10709.96 | G7: =E7 -> 10709.96 | I7: =E7-G7 -> 0
B8: 2 | C8: A | E8: 5448.33 | G8: =E8 -> 5448.33 | I8: =E8-G8 -> 0
B9: 2 | C9: B | E9: 2716.04 | G9: =E9 -> 2716.04 | I9: =E9-G9 -> 0
B10: 2 | C10: C | E10: 2716.04 | G10: =E10 -> 2716.04 | I10: =E10-G10 -> 0
B11: 2 | C11: D | E11: 2222.21 | G11: =E11 -> 2222.21 | I11: =E11-G11 -> 0
B12: 3 | C12: A | E12: 2222.21 | G12: =E12 -> 2222.21 | I12: =E12-G12 -> 0
B13: 3 | C13: B | E13: 24018.62 | G13: =E13 -> 24018.62 | I13: =E13-G13 -> 0
B14: 3 | C14: C | E14: 2716.04 | G14: =E14 -> 2716.04 | I14: =E14-G14 -> 0
B15: 3 | C15: D | E15: 2222.21 | G15: =E15 -> 2222.21 | I15: =E15-G15 -> 0
B16: 4 | C16: A | E16: 36166.8 | G16: =E16 -> 36166.8 | I16: =E16-G16 -> 0
... B19: 4 | C19: D | E19: 2222.21 | G19: =E19 -> 2222.21 | I19: =E19-G19 -> 0
B21: Totales | E21: =SUM(E5:E20) -> 144169.02 | G21: =SUM(G5:G20) -> 144169.02 | I21: =E21-G21 -> 0
B22: Cochera | C22: 1 | E22: 288.06 | G22: =E22 -> 288.06 | I22: =E22-G22 -> 0
B23: Cochera | C23: 2 | E23: 246.91 | G23: =E23 -> 246.91 | I23: =E23-G23 -> 0
B24: Cochera | C24: 3 | E24: 246.91 | G24: =E24 -> 246.91 | I24: =E24-G24 -> 0
B25: Cochera | C25: 4 | E25: 246.91 | G25: =E25 -> 246.91 | I25: =E25-G25 -> 0
B26: Cochera | C26: 5 | E26: 246.91 | G26: =E26 -> 246.91 | I26: =E26-G26 -> 0
B27: Cochera | C27: 6 | E27: 123.46 | G27: =E27 -> 123.46 | I27: =E27-G27 -> 0
B28: Cochera | C28: 7 | E28: 123.46 | G28: =E28 -> 123.46 | I28: =E28-G28 -> 0
B29: Cochera | C29: 8 | E29: 123.46 | G29: =E29 -> 123.46 | I29: =E29-G29 -> 0
B30: Totales | E30: =SUM(E22:E29) -> 1646.08 | G30: =SUM(G22:G29) -> 1646.08 | I30: =E30-G30 -> 0
I31: =E31-G31 -> 0
E33: =E30+E21 -> 145815.1 | G33: =G21+G30 -> 145815.1 | I33: =E33-G33 -> 0
