Workbook

Sheet RESUMEN
B1: MAIL: brisasdeadroguerc@gmail.com
B2: CELULAR: +54 9 11 2640-1829
B3: Titular: CONSORCIO DE PROPIETARIOS LAS BRISAS - ADROGUE - Santander Río - Cuenta Corriente Nº 221-007370/9
B4: CBU.: 0720221820000000737090 * ALIAS: MARTES.POLO.IDEAL
B5: PERÍODO: Agosto - ADMINISTRADORA: CAROLINA CANCIANI MP:1148
B6: CUIT.: 30-71618269-6
B7: CONSORCIO DE PROPIETARIOS LAS BRISAS - ADROGUE
A9: VTO 30/09
A14: ESTIMADOS: LES RECORDAMOS QUE ES OBLIGATORIO INFORMAR POR CORREO ELECTRÓNICO EL PAGO DE LAS EXPENSAS. APROVECHAMOS LA OCASIÓN PARA REITERAR UN PUNTO CLAVE QUE AYUDA A EVITAR ERRORES EN LA IMPUTACIÓN DE LOS PAGOS. EL SISTEMA QUE UTILIZAMOS ASIGNA CENTAVOS ÚNICOS A CADA UNIDAD FUNCIONAL (UF) O LOTE, LO QUE NOS PERMITE IDENTIFICAR AUTOMÁTICAMENTE A CUÁL CORRESPONDE CADA TRANSFERENCIA. ES DECIR, CADA UF/LOTE TIENE UN NÚMERO ESPECÍFICO DE CENTAVOS QUE FUNCIONA COMO IDENTIFICADOR. POR EJEMPLO, SI SU LOTE ES EL 45, EL IMPORTE A ABONAR DEBERÁ TERMINAR EN $...,45. EN CASO DE TENER MÁS DE UN LOTE (POR EJEMPLO, EL 3 Y EL 78), CADA UNO TENDRÁ SU PROPIO CÓDIGO DE CENTAVOS. EN ESTOS CASOS, LES PEDIMOS QUE REALICEN UNA TRANSFERENCIA INDIVIDUAL POR CADA LOTE, RESPETANDO LOS IMPORTES CON SUS CENTAVOS CORRESPONDIENTES. SABEMOS QUE, POR COMODIDAD, A VECES SE OPTA POR ENVIAR TODO EN UNA ÚNICA TRANSFERENCIA, PERO ESTO PUEDE GENERAR CONFUSIÓN O ERRORES EN LA ASIGNACIÓN AUTOMÁTICA. SEPARAR LOS PAGOS NOS PERMITE ASEGURAR QUE CADA UNO SE IMPUTE CORRECTAMENTE. AGRADECEMOS MUCHÍSIMO SU COLABORACIÓN PARA SEGUIR MANTENIENDO EL ORDEN. MUCHAS GRACIAS.
A21: GASTOS ORDINARIOS UNIDADES FUNCIONALES:
A22: HABERES ENCARGADOS
A23: Sueldo intendencia - Maximiliano Abbruzzese - Agosto | D23: 1311455.5
A24: Deducciones mes de Agosto | D24: -285241.6
A25: Redondeo mes de Agosto | D25: 0.1
A26: Neto | D26: =SUM(D23:D25) -> 1026214 | E26: Aun no se transf
A27: Honorarios arquitectura - Srta. Burgos Oros Johanna Melanie - Fc. 00000085 | D27: 630000 | E27: Transf 06/08
A28: Neto | D28: =SUM(D27:D27) -> 630000
A29: TOTAL SUELDOS | E29: =D26+D28 -> 1656214
A30: CARGAS SOCIALES - APORTES Y CONTRIBUCIONES
A31: ARCA - Mes de Julio | D31: 601216.04 | E31: Debito 07/08
A32: Sindicatos mes de Julio | B32: Fatheryh | D32: 59015.5 | E32: Debito 12/08
A33: =A32 -> Sindicatos mes de Julio | B33: Suther | D33: 109872.62 | E33: =E32 -> Debito 12/08
A34: =A33 -> Sindicatos mes de Julio | B34: Seracarh | D34: 6557.28 | E34: =E33 -> Debito 12/08
A35: TOTAL SEGUROS | E35: =SUM(D31:D34) -> 776661.44
A36: SEGUROS
A37: Federacion patronal - Poliza nro. 1-2195343-0 - Riesgo integral de barrios privados | D37: 148964 | E37: Debito 04/08
A38: Federacion patronal - Poliza nro. 1-77459-6 - Seguro de vida obligatorio Sr. Maximiliano Abbruzzese | D38: 5619 | E38: Debito 04/08
A39: Allianz (Cuit.: 30--50003721-7) - Seguro Técnico - Póliza N° 240210705270; Vto.01/09/2025 | D39: 14585.38 | E39: Debito 14/08
A40: Allianz (Cuit.: 30--50003721-7) - Seguro Técnico - Póliza N° 240210705270; Vto.01/09/2025 | D40: 18195 | E40: Debito 06/08
A41: TOTAL APORTES Y CONTRIBUCIONES | E41: =SUM(D37:D40) -> 187363.38
A42: SEGURIDAD
A43: GOLD (Cuit.: 33-71225773-9) - Fc.0000402 (Servicio de Seguridad Julio 2025) | D43: 40494443 | E43: Transf 04/08
A44: Servicio Polad - Mes de Julio - Valor de la hora $6.110,08 (742hs en total) | D44: 4533679.4 | E44: Transf 14/08
A45: TOTAL GASTOS SEGURIDAD | E45: =SUM(D43:D44) -> 45028122
A46: LIMPIEZA - MANTENIMIENTO DE ALUMBRADO | C46: SEGURIDAD
A47: OMS (Cuit.: 30-71568933-9) - Fc.00002637 (Abono mantenimiento planta de tratamiento) | D47: 984870 | E47: Transf 27/08
A48: Induser - Muestreo analisis e informe de pozo 1 y 2 - CUIT: 30707887008 - Fc. 3054 | D48: 902866 | E48: Transf 01/08
A49: Armella Cristian - CUIT: 20371419234 - Fc. 0004 - Mantenimiento espacios verdes | D49: 5500000 | E49: Transf 04/08
A50: Armella Cristian - CUIT: 20371419234 - Fc. 00010 - Recoleccion de basura mes de julio | D50: 250000 | E50: Transf 26/08
A51: Armella Cristian - CUIT: 20371419234 - Fc. 00014 - Extraccion de arboles | D51: 1500000 | E51: Transf 26/08
...

Sheet PRORRATEO
N1: Fondo de reserva: | P1: 30000000 | U1: 71243590
C2: Compensacion expensas lote 140 - 141: | G2: =W2 -> 23535900 | I2: Ordinarios: | K2: 69000000 | N2: Extraordinarios: | P2: 0 | T2: COMPENSACION EXP. LOTE 140/141 | W2: =((K2+P2)*D144)+((K2+P2)*D145) -> 23535900
A3: Dpto. | B3: UF | C3: Propietario | D3: (%) | E3: Saldo | F3: Ingreso | G3: Deuda o Saldo a favor | H3: Interes | I3: Expensas ord. | K3: Compensacion expensas lote 140/141 | L3: Fondo de reserva | M3: Gastos exclusivos de lotes (honorarios arquitecturas, intimaciones, etc) | N3: Canon de obra | O3: Gastos particulares / Multas / SUM | P3: Total | S3: LOTE
B5: 1 | C5: Lettieri, Miguel Angel | D5: 0.0046 | E5: 665352.01 | F5: =E5 -> 665352.01 | G5: =E5-F5 -> 0 | H5: =IF(G5>0,G5*3.087%,0) -> 0 | I5: =K$2*D5 -> 317400 | J5: =P$2*D5 -> 0 | K5: =G$2*0.675675676% -> 159026.35 | L5: =P$1*0.675675676% -> 202702.7 | M5: =G$1*D5 -> 0 | N5: 0 | P5: =ROUND(SUM(G5:O5),0) + R5 -> 679129.01 | R5: =ROUND(0.001+B5/100,2) -> 0.01 | S5: =B5 -> 1 | T5: Patricia Sobol <patriciasobol@hotmail.com> - - tambien tiene lote 127
B6: =B5+1 -> 2 | C6: Basile, Santiago | D6: 0.0046 | E6: 1712716 | G6: =E6-F6 -> 1712716 | H6: =IF(G6>0,G6*3.087%,0) -> 52871.544 | I6: =K$2*D6 -> 317400 | J6: =P$2*D6 -> 0 | K6: =G$2*0.675675676% -> 159026.35 | L6: =P$1*0.675675676% -> 202702.7 | M6: =G$1*D6 -> 0 | N6: 0 | P6: =ROUND(SUM(G6:O6),0) + R6 -> 2444717 | R6: =ROUND(0.001+B6/100,2) -> 0.02 | S6: =B6 -> 2
B7: =B6+1 -> 3 | C7: Garcia, Stella Maris | D7: 0.0046 | E7: 665352.03 | F7: =E7 -> 665352.03 | G7: =E7-F7 -> 0 | H7: =IF(G7>0,G7*3.087%,0) -> 0 | I7: =K$2*D7 -> 317400 | J7: =P$2*D7 -> 0 | K7: =G$2*0.675675676% -> 159026.35 | L7: =P$1*0.675675676% -> 202702.7 | M7: =G$1*D7 -> 0 | N7: 0 | P7: =ROUND(SUM(G7:O7),0) + R7 -> 679129.03 | R7: =ROUND(0.001+B7/100,2) -> 0.03 | S7: =B7 -> 3 | U7: avicola lanus a nombre de tamara en el mail
B8: =B7+1 -> 4 | C8: Reyes, Damian | D8: 0.0047 | E8: 687953.04 | F8: =E8 -> 687953.04 | G8: =E8-F8 -> 0 | H8: =IF(G8>0,G8*3.087%,0) -> 0 | I8: =K$2*D8 -> 324300 | J8: =P$2*D8 -> 0 | K8: =G$2*0.675675676% -> 159026.35 | L8: =P$1*0.675675676% -> 202702.7 | M8: =G$1*D8 -> 0 | N8: 0 | P8: =ROUND(SUM(G8:O8),0) + R8 -> 686029.04 | R8: =ROUND(0.001+B8/100,2) -> 0.04 | S8: =B8 -> 4 | T8: Ad Premed SRL
B9: =B8+1 -> 5 | C9: Tamburrino, Javier | D9: 0.0047 | E9: 672052.05 | F9: =E9 -> 672052.05 | G9: =E9-F9 -> 0 | H9: =IF(G9>0,G9*3.087%,0) -> 0 | I9: =K$2*D9 -> 324300 | J9: =P$2*D9 -> 0 | K9: =G$2*0.675675676% -> 159026.35 | L9: =P$1*0.675675676% -> 202702.7 | M9: =G$1*D9 -> 0 | N9: 0 | P9: =ROUND(SUM(G9:O9),0) + R9 -> 686029.05 | R9: =ROUND(0.001+B9/100,2) -> 0.05 | S9: =B9 -> 5
B10: =B9+1 -> 6 | C10: Marquez, Florencia | D10: 0.0045 | E10: 658651.06 | F10: =E10 -> 658651.06 | G10: =E10-F10 -> 0 | H10: =IF(G10>0,G10*3.087%,0) -> 0 | I10: =K$2*D10 -> 310500 | J10: =P$2*D10 -> 0 | K10: =G$2*0.675675676% -> 159026.35 | L10: =P$1*0.675675676% -> 202702.7 | M10: =G$1*D10 -> 0 | N10: 0 | P10: =ROUND(SUM(G10:O10),0) + R10 -> 672229.06 | R10: =ROUND(0.001+B10/100,2) -> 0.06 | S10: =B10 -> 6 | U10: Fattorini sergio
B11: =B10+1 -> 7 | C11: Olmedo, Alberto | D11: 0.0043 | E11: 1337245.1 | F11: =670000+680000 -> 1350000 | G11: =E11-F11 -> -12754.93 | H11: =IF(G11>0,G11*3.087%,0) -> 0 | I11: =K$2*D11 -> 296700 | J11: =P$2*D11 -> 0 | K11: =G$2*0.675675676% -> 159026.35 | L11: =P$1*0.675675676% -> 202702.7 | M11: =G$1*D11 -> 0 | N11: 0 | P11: =ROUND(SUM(G11:O11),0) + R11 -> 645674.07 | R11: =ROUND(0.001+B11/100,2) -> 0.07 | S11: =B11 -> 7 | T11: Cristian Colson
B12: =B11+1 -> 8 | C12: Troppelli, R. / Segura, J. | D12: 0.0047 | E12: 671974.08 | F12: =E12 -> 671974.08 | G12: =E12-F12 -> 0 | H12: =IF(G12>0,G12*3.087%,0) -> 0 | I12: =K$2*D12 -> 324300 | J12: =P$2*D12 -> 0 | K12: =G$2*0.675675676% -> 159026.35 | L12: =P$1*0.675675676% -> 202702.7 | M12: =G$1*D12 -> 0 | N12: 0 | P12: =ROUND(SUM(G12:O12),0) + R12 -> 686029.08 | R12: =ROUND(0.001+B12/100,2) -> 0.08 | S12: =B12 -> 8 | T12: Romina Troppelli - Deposita
B13: =B12+1 -> 9 | C13: Ferraris, Sergio | D13: 0.0047 | E13: 4421406.1 | F13: =1000000+1000000+1500000 -> 3500000 | G13: =E13-F13 -> 921406.09 | H13: =IF(G13>0,G13*3.087%,0) -> 28443.806 | I13: =K$2*D13 -> 324300 | J13: =P$2*D13 -> 0 | K13: =G$2*0.675675676% -> 159026.35 | L13: =P$1*0.675675676% -> 202702.7 | M13: 59274 | N13: =(I13+K13)/2 -> 241663.18 | P13: =ROUND(SUM(G13:O13),0) + R13 -> 1936816.1 | R13: =ROUND(0.001+B13/100,2) -> 0.09 | S13: =B13 -> 9
B14: =B13+1 -> 10 | C14: Schunk, Andrea | D14: 0.0047 | E14: 672052.1 | F14: =E14 -> 672052.1 | G14: =E14-F14 -> 0 | H14: =IF(G14>0,G14*3.087%,0) -> 0 | I14: =K$2*D14 -> 324300 | J14: =P$2*D14 -> 0 | K14: =G$2*0.675675676% -> 159026.35 | L14: =P$1*0.675675676% -> 202702.7 | M14: =G$1*D14 -> 0 | N14: 0 | P14: =ROUND(SUM(G14:O14),0) + R14 -> 686029.1 | R14: =ROUND(0.001+B14/100,2) -> 0.1 | S14: =B14 -> 10 | T14: Ariel Sposito
B15: =B14+1 -> 11 | C15: Arrom, Tamara | D15: 0.0047 | E15: -27946.89 | F15: =-700000+672053.11 -> -27946.89 | G15: =E15-F15 -> 0 | H15: =IF(G15>0,G15*3.087%,0) -> 0 | I15: =K$2*D15 -> 324300 | J15: =P$2*D15 -> 0 | K15: =G$2*0.675675676% -> 159026.35 | L15: =P$1*0.675675676% -> 202702.7 | M15: =G$1*D15 -> 0 | N15: 0 | P15: =ROUND(SUM(G15:O15),0) + R15 -> 686029.11 | R15: =ROUND(0.001+B15/100,2) -> 0.11 | S15: =B15 -> 11 | T15: maranata perfumeria
B16: =B15+1 -> 12 | C16: ADVC SRL. | D16: 0.0043 | E16: 1926403.1 | F16: =700000+21608 -> 721608 | G16: =E16-F16 -> 1204795.1 | H16: =IF(G16>0,G16*3.087%,0) -> 37192.025 | I16: =K$2*D16 -> 296700 | J16: =P$2*D16 -> 0 | K16: =G$2*0.675675676% -> 159026.35 | L16: =P$1*0.675675676% -> 202702.7 | M16: =G$1*D16 -> 0 | N16: 0 | P16: =ROUND(SUM(G16:O16),0) + R16 -> 1900416.1 | R16: =ROUND(0.001+B16/100,2) -> 0.12 | S16: =B16 -> 12 | T16: Gustavo Kearney <gkearney@batt.com.ar> - maranata perfumeria
B17: =B16+1 -> 13 | C17: Huenchupan, Alejandro | D17: 0.0046 | E17: 954689.13 | F17: =E17 -> 954689.13 | G17: =E17-F17 -> 0 | H17: =IF(G17>0,G17*3.087%,0) -> 0 | I17: =K$2*D17 -> 317400 | J17: =P$2*D17 -> 0 | K17: =G$2*0.675675676% -> 159026.35 | L17: =P$1*0.675675676% -> 202702.7 | M17: 58013 | N17: =(I17+K17)/2 -> 238213.18 | P17: =ROUND(SUM(G17:O17),0) + R17 -> 975355.13 | R17: =ROUND(0.001+B17/100,2) -> 0.13 | S17: =B17 -> 13
B18: =B17+1 -> 14 | C18: De Lucas, S. | D18: 0.0047 | E18: 695292.14 | F18: =E18 -> 695292.14 | G18: =E18-F18 -> 0 | H18: =IF(G18>0,G18*3.087%,0) -> 0 | I18: =K$2*D18 -> 324300 | J18: =P$2*D18 -> 0 | K18: =G$2*0.675675676% -> 159026.35 | L18: =P$1*0.675675676% -> 202702.7 | M18: =G$1*D18 -> 0 | N18: 0 | P18: =ROUND(SUM(G18:O18),0) + R18 -> 686029.14 | R18: =ROUND(0.001+B18/100,2) -> 0.14 | S18: =B18 -> 14 | T18: PAGOS UNIVERSALES SA/ GLOBAL TT S.A. / GLOBAT
B19: =B18+1 -> 15 | C19: Berlotti, Maria Laura | D19: 0.0044 | E19: 1439200.1 | F19: =763674.15+675526.15+23575 -> 1462775.3 | G19: =E19-F19 -> -23575.15 | H19: =IF(G19>0,G19*3.087%,0) -> 0 | I19: =K$2*D19 -> 303600 | J19: =P$2*D19 -> 0 | K19: =G$2*0.675675676% -> 159026.35 | L19: =P$1*0.675675676% -> 202702.7 | M19: =G$1*D19 -> 0 | N19: 0 | P19: =ROUND(SUM(G19:O19),0) + R19 -> 641754.15 | R19: =ROUND(0.001+B19/100,2) -> 0.15 | S19: =B19 -> 15 | T19: Adminar SA y Lobison
B20: =B19+1 -> 16 | C20: Giordano, Juan Pablo | D20: 0.0046 | E20: 954689.16 | F20: =E20 -> 954689.16 | G20: =E20-F20 -> 0 | H20: =IF(G20>0,G20*3.087%,0) -> 0 | I20: =K$2*D20 -> 317400 | J20: =P$2*D20 -> 0 | K20: =G$2*0.675675676% -> 159026.35 | L20: =P$1*0.675675676% -> 202702.7 | M20: 58013 | N20: =(I20+K20)/2 -> 238213.18 | P20: =ROUND(SUM(G20:O20),0) + R20 -> 975355.16 | R20: =ROUND(0.001+B20/100,2) -> 0.16 | S20: =B20 -> 16
B21: =B20+1 -> 17 | C21: Zacharias, Valeria | D21: 0.0046 | E21: 1365134.2 | F21: 765860.17 | G21: =E21-F21 -> 599274 | H21: =IF(G21>0,G21*3.087%,0) -> 18499.588 | I21: =K$2*D21 -> 317400 | J21: =P$2*D21 -> 0 | K21: =G$2*0.675675676% -> 159026.35 | L21: =P$1*0.675675676% -> 202702.7 | M21: =G$1*D21 -> 0 | N21: 0 | P21: =ROUND(SUM(G21:O21),0) + R21 -> 1296903.2 | R21: =ROUND(0.001+B21/100,2) -> 0.17 | S21: =B21 -> 17 | T21: Deposita MECANICA VANDEN BOSCH <mecanicavandenbosch@gmail.com>
B22: =B21+1 -> 18 | C22: De Nardi, Mario | D22: 0.0046 | E22: 665352.18 | F22: =E22 -> 665352.18 | G22: =E22-F22 -> 0 | H22: =IF(G22>0,G22*3.087%,0) -> 0 | I22: =K$2*D22 -> 317400 | J22: =P$2*D22 -> 0 | K22: =G$2*0.675675676% -> 159026.35 | L22: =P$1*0.675675676% -> 202702.7 | M22: =G$1*D22 -> 0 | N22: 0 | P22: =ROUND(SUM(G22:O22),0) + R22 -> 679129.18 | R22: =ROUND(0.001+B22/100,2) -> 0.18 | S22: =B22 -> 18 | T22: Deposita, tambien paga el 132
B23: =B22+1 -> 19 | C23: Oniszczuk, Sebastian | D23: 0.0047 | E23: 672011.19 | F23: =E23 -> 672011.19 | G23: =E23-F23 -> 0 | H23: =IF(G23>0,G23*3.087%,0) -> 0 | I23: =K$2*D23 -> 324300 | J23: =P$2*D23 -> 0 | K23: =G$2*0.675675676% -> 159026.35 | L23: =P$1*0.675675676% -> 202702.7 | M23: =G$1*D23 -> 0 | N23: 0 | P23: =ROUND(SUM(G23:O23),0) + R23 -> 686029.19 | R23: =ROUND(0.001+B23/100,2) -> 0.19 | S23: =B23 -> 19
B24: =B23+1 -> 20 | C24: Gomez, Jose Luis | D24: 0.0047 | E24: 672052.2 | F24: =E24 -> 672052.2 | G24: =E24-F24 -> 0 | H24: =IF(G24>0,G24*3.087%,0) -> 0 | I24: =K$2*D24 -> 324300 | J24: =P$2*D24 -> 0 | K24: =G$2*0.675675676% -> 159026.35 | L24: =P$1*0.675675676% -> 202702.7 | M24: =G$1*D24 -> 0 | N24: 0 | P24: =ROUND(SUM(G24:O24),0) + R24 -> 686029.2 | R24: =ROUND(0.001+B24/100,2) -> 0.2 | S24: =B24 -> 20
B25: =B24+1 -> 21 | C25: Carcioni, Jose | D25: 0.0047 | E25: 672052.21 | G25: =E25-F25 -> 672052.21 | H25: =IF(G25>0,G25*3.087%,0) -> 20746.252 | I25: =K$2*D25 -> 324300 | J25: =P$2*D25 -> 0 | K25: =G$2*0.675675676% -> 159026.35 | L25: =P$1*0.675675676% -> 202702.7 | M25: =G$1*D25 -> 0 | N25: 0 | P25: =ROUND(SUM(G25:O25),0) + R25 -> 1378828.2 | R25: =ROUND(0.001+B25/100,2) -> 0.21 | S25: =B25 -> 21 | U25: Suavenol
B26: =B25+1 -> 22 | C26: Oniszczuk, Esteban | D26: 0.0047 | E26: 672052.22 | F26: =E26 -> 672052.22 | G26: =E26-F26 -> 0 | H26: =IF(G26>0,G26*3.087%,0) -> 0 | I26: =K$2*D26 -> 324300 | J26: =P$2*D26 -> 0 | K26: =G$2*0.675675676% -> 159026.35 | L26: =P$1*0.675675676% -> 202702.7 | M26: =G$1*D26 -> 0 | N26: 0 | P26: =ROUND(SUM(G26:O26),0) + R26 -> 686029.22 | R26: =ROUND(0.001+B26/100,2) -> 0.22 | S26: =B26 -> 22 | T26: Nicolas Cecilia Andrea
B27: =B26+1 -> 23 | C27: Dominguez, Javier | D27: 0.0047 | E27: 2241707.2 | F27: =E27 -> 2241707.2 | G27: =E27-F27 -> 0 | H27: =IF(G27>0,G27*3.087%,0) -> 0 | I27: =K$2*D27 -> 324300 | J27: =P$2*D27 -> 0 | K27: =G$2*0.675675676% -> 159026.35 | L27: =P$1*0.675675676% -> 202702.7 | M27: =G$1*D27 -> 0 | N27: 0 | P27: =ROUND(SUM(G27:O27),0) + R27 -> 686029.23 | R27: =ROUND(0.001+B27/100,2) -> 0.23 | S27: =B27 -> 23
B28: =B27+1 -> 24 | C28: Calviño, Eduardo | D28: 0.0047 | E28: 2326863.2 | F28: =703707+49554+1533990.24 -> 2287251.2 | G28: =E28-F28 -> 39612 | H28: =IF(G28>0,G28*3.087%,0) -> 1222.8224 | I28: =K$2*D28 -> 324300 | J28: =P$2*D28 -> 0 | K28: =G$2*0.675675676% -> 159026.35 | L28: =P$1*0.675675676% -> 202702.7 | M28: =G$1*D28 -> 0 | N28: 0 | P28: =ROUND(SUM(G28:O28),0) + R28 -> 726864.24 | R28: =ROUND(0.001+B28/100,2) -> 0.24 | S28: =B28 -> 24
B29: =B28+1 -> 25 | C29: Cejas, Nicolas | D29: 0.0048 | E29: 1436837.2 | F29: =636837.25+800000 -> 1436837.2 | G29: =E29-F29 -> 0 | H29: =IF(G29>0,G29*3.087%,0) -> 0 | I29: =K$2*D29 -> 331200 | J29: =P$2*D29 -> 0 | K29: =G$2*0.675675676% -> 159026.35 | L29: =P$1*0.675675676% -> 202702.7 | M29: =G$1*D29 -> 0 | N29: 0 | P29: =ROUND(SUM(G29:O29),0) + R29 -> 692929.25 | R29: =ROUND(0.001+B29/100,2) -> 0.25 | S29: =B29 -> 25 | U29: Agustina Palermo
B30: =B29+1 -> 26 | C30: De Nardi, Karina | D30: 0.0048 | E30: 672746.26 | F30: 675000 | G30: =E30-F30 -> -2253.74 | H30: =IF(G30>0,G30*3.087%,0) -> 0 | I30: =K$2*D30 -> 331200 | J30: =P$2*D30 -> 0 | K30: =G$2*0.675675676% -> 159026.35 | L30: =P$1*0.675675676% -> 202702.7 | M30: =G$1*D30 -> 0 | N30: 0 | P30: =ROUND(SUM(G30:O30),0) + R30 -> 690675.26 | R30: =ROUND(0.001+B30/100,2) -> 0.26 | S30: =B30 -> 26 | U30: Luis Grecco Y Karina
B31: =B30+1 -> 27 | C31: Montero, Pablo | D31: 0.0048 | E31: 678753.27 | F31: =E31 -> 678753.27 | G31: =E31-F31 -> 0 | H31: =IF(G31>0,G31*3.087%,0) -> 0 | I31: =K$2*D31 -> 331200 | J31: =P$2*D31 -> 0 | K31: =G$2*0.675675676% -> 159026.35 | L31: =P$1*0.675675676% -> 202702.7 | M31: =G$1*D31 -> 0 | N31: 0 | P31: =ROUND(SUM(G31:O31),0) + R31 -> 692929.27 | R31: =ROUND(0.001+B31/100,2) -> 0.27 | S31: =B31 -> 27
B32: =B31+1 -> 28 | C32: Gariotto, Salvador | D32: 0.0045 | E32: 2668040.3 | F32: =670000+20000 -> 690000 | G32: =E32-F32 -> 1978040.3 | H32: =IF(G32>0,G32*3.087%,0) -> 61062.103 | I32: =K$2*D32 -> 310500 | J32: =P$2*D32 -> 0 | K32: =G$2*0.675675676% -> 159026.35 | L32: =P$1*0.675675676% -> 202702.7 | M32: =G$1*D32 -> 0 | N32: 0 | P32: =ROUND(SUM(G32:O32),0) + R32 -> 2711331.3 | R32: =ROUND(0.001+B32/100,2) -> 0.28 | S32: =B32 -> 28 | T32: Deposita - pamela
B33: =B32+1 -> 29 | C33: Aducci, Marcelo | D33: 0.0048 | E33: 678753.29 | F33: =E33 -> 678753.29 | G33: =E33-F33 -> 0 | H33: =IF(G33>0,G33*3.087%,0) -> 0 | I33: =K$2*D33 -> 331200 | J33: =P$2*D33 -> 0 | K33: =G$2*0.675675676% -> 159026.35 | L33: =P$1*0.675675676% -> 202702.7 | M33: =G$1*D33 -> 0 | N33: 0 | P33: =ROUND(SUM(G33:O33),0) + R33 -> 692929.29 | R33: =ROUND(0.001+B33/100,2) -> 0.29 | S33: =B33 -> 29 | T33: IGLE SA
B34: =B33+1 -> 30 | C34: Petrucchi, Hernan | D34: 0.0045 | E34: 658651.3 | F34: =E34 -> 658651.3 | G34: =E34-F34 -> 0 | H34: =IF(G34>0,G34*3.087%,0) -> 0 | I34: =K$2*D34 -> 310500 | J34: =P$2*D34 -> 0 | K34: =G$2*0.675675676% -> 159026.35 | L34: =P$1*0.675675676% -> 202702.7 | M34: =G$1*D34 -> 0 | N34: 0 | P34: =ROUND(SUM(G34:O34),0) + R34 -> 672229.3 | R34: =ROUND(0.001+B34/100,2) -> 0.3 | S34: =B34 -> 30 | T34: ConstruHap - Veronica Laura Maggiot
B35: =B34+1 -> 31 | C35: Rosi, Martin | D35: 0.0045 | E35: 1351585.3 | F35: =672184 -> 672184 | G35: =E35-F35 -> 679401.31 | H35: =IF(G35>0,G35*3.087%,0) -> 20973.118 | I35: =K$2*D35 -> 310500 | J35: =P$2*D35 -> 0 | K35: =G$2*0.675675676% -> 159026.35 | L35: =P$1*0.675675676% -> 202702.7 | M35: =G$1*D35 -> 0 | N35: 0 | P35: =ROUND(SUM(G35:O35),0) + R35 -> 1372603.3 | R35: =ROUND(0.001+B35/100,2) -> 0.31 | S35: =B35 -> 31 | T35: ventas@quimicaros.com.ar
B36: =B35+1 -> 32 | C36: Bernardez, M. / Giordano, J. | D36: 0.0045 | E36: 658651.32 | F36: =5888095-F17-F20-F37-F90-F149-F150-F152 -> 658651.67 | G36: =E36-F36 -> -0.35 | H36: =IF(G36>0,G36*3.087%,0) -> 0 | I36: =K$2*D36 -> 310500 | J36: =P$2*D36 -> 0 | K36: =G$2*0.675675676% -> 159026.35 | L36: =P$1*0.675675676% -> 202702.7 | M36: =G$1*D36 -> 0 | N36: 0 | O36: 150760 | P36: =ROUND(SUM(G36:O36),0) + R36 -> 822989.32 | R36: =ROUND(0.001+B36/100,2) -> 0.32 | S36: =B36 -> 32
B37: 33 | C37: Giordano, Juan Pablo | D37: 0.0045 | E37: 658651.33 | F37: =E37 -> 658651.33 | G37: =E37-F37 -> 0 | H37: =IF(G37>0,G37*3.087%,0) -> 0 | I37: =K$2*D37 -> 310500 | J37: =P$2*D37 -> 0 | K37: =G$2*0.675675676% -> 159026.35 | L37: =P$1*0.675675676% -> 202702.7 | M37: =G$1*D37 -> 0 | N37: 0 | P37: =ROUND(SUM(G37:O37),0) + R37 -> 672229.33 | R37: =ROUND(0.001+B37/100,2) -> 0.33 | S37: =B37 -> 33
B38: 34 | C38: Rosi, Martin | D38: 0.0045 | E38: 1351585.3 | F38: =672184 -> 672184 | G38: =E38-F38 -> 679401.34 | H38: =IF(G38>0,G38*3.087%,0) -> 20973.119 | I38: =K$2*D38 -> 310500 | J38: =P$2*D38 -> 0 | K38: =G$2*0.675675676% -> 159026.35 | L38: =P$1*0.675675676% -> 202702.7 | M38: =G$1*D38 -> 0 | N38: 0 | P38: =ROUND(SUM(G38:O38),0) + R38 -> 1372604.3 | R38: =ROUND(0.001+B38/100,2) -> 0.34 | S38: =B38 -> 34
A39: 1 | B39: 35 | C39: Di Biase, Diego | D39: 0.0046 | E39: 665352.35 | F39: =E39 -> 665352.35 | G39: =E39-F39 -> 0 | H39: =IF(G39>0,G39*3.087%,0) -> 0 | I39: =K$2*D39 -> 317400 | J39: =P$2*D39 -> 0 | K39: =G$2*0.675675676% -> 159026.35 | L39: =P$1*0.675675676% -> 202702.7 | M39: =G$1*D39 -> 0 | N39: 0 | P39: =ROUND(SUM(G39:O39),0) + R39 -> 679129.35 | R39: =ROUND(0.001+B39/100,2) -> 0.35 | S39: =B39 -> 35 | T39: Velazco Velasco Gisela
A40: 2 | B40: 36 | C40: Acosta, Claudio | D40: 0.0046 | E40: 2057458.4 | G40: =E40-F40 -> 2057458.4 | H40: =IF(G40>0,G40*3.087%,0) -> 63513.74 | I40: =K$2*D40 -> 317400 | J40: =P$2*D40 -> 0 | K40: =G$2*0.675675676% -> 159026.35 | L40: =P$1*0.675675676% -> 202702.7 | M40: =G$1*D40 -> 0 | N40: 0 | P40: =ROUND(SUM(G40:O40),0) + R40 -> 2800101.4 | R40: =ROUND(0.001+B40/100,2) -> 0.36 | S40: =B40 -> 36
A41: 3 | B41: 37 | C41: Caiz, Ariel | D41: 0.0045 | E41: 658651.37 | F41: 718953.37 | G41: =E41-F41 -> -60302 | H41: =IF(G41>0,G41*3.087%,0) -> 0 | I41: =K$2*D41 -> 310500 | J41: =P$2*D41 -> 0 | K41: =G$2*0.675675676% -> 159026.35 | L41: =P$1*0.675675676% -> 202702.7 | M41: =G$1*D41 -> 0 | N41: 0 | P41: =ROUND(SUM(G41:O41),0) + R41 -> 611927.37 | R41: =ROUND(0.001+B41/100,2) -> 0.37 | S41: =B41 -> 37
...

Sheet anotaciones
C1: ANOTACION | D1: 1
C2: FECHA DE LA ANOTACION: | E2: 45874 | G2: NOMBRE: | H2: Daiana Casas
C3: QUEJA VIA: | D3: WHATSAPP | E3: MAIL | G3: LOTE: | H3: 109
C4: FECHA DE LA QUEJA: | E4: 45874
C5: MOTIVO DE LA QUEJA:
C6: Deposito el 05/08 $722.000 y 2000
C11: ANOTACION | D11: =D1+1 -> 2
C12: FECHA DE LA ANOTACION: | E12: 45875 | G12: NOMBRE: | H12: Marcos Strianese
C13: QUEJA VIA: | D13: WHATSAPP | E13: MAIL | G13: LOTE: | H13: 72
C14: FECHA DE LA QUEJA: | E14: 45874
C15: MOTIVO DE LA QUEJA:
C16: Deposito 650 mil el 5/8 y Deposito 650 mil el 25/8
C21: ANOTACION | D21: =D11+1 -> 3
C22: FECHA DE LA ANOTACION: | E22: 45883 | G22: NOMBRE: | H22: ALEJANDRA CASTRO
C23: QUEJA VIA: | D23: WHATSAPP | E23: MAIL | G23: LOTE: | H23: 82
C24: FECHA DE LA QUEJA: | E24: 45871
C25: MOTIVO DE LA QUEJA:
C26: Deposito el 01/08 $1.915.000 - tiene pdf con desglose a abonar
C31: ANOTACION | D31: =D21+1 -> 4
C32: FECHA DE LA ANOTACION: | E32: 45887 | G32: NOMBRE: | H32: ventas@quimicaros.com.ar
C33: QUEJA VIA: | D33: WHATSAPP | E33: MAIL | G33: LOTE: | H33: 31
C34: FECHA DE LA QUEJA: | E34: 45871
C35: MOTIVO DE LA QUEJA:
C36: 672184 el 12/08
C41: ANOTACION | D41: =D31+1 -> 5
C42: FECHA DE LA ANOTACION: | E42: 45887 | G42: NOMBRE: | H42: Juan ignacio santangelo
C43: QUEJA VIA: | D43: WHATSAPP | E43: MAIL | G43: LOTE: | H43: 105
C44: FECHA DE LA QUEJA:
C45: MOTIVO DE LA QUEJA:
C46: El mes pasado le pusimos dinero de mas que no correspondia. Ademas, no le pusimossu deposito de 651498 y le estabamos cobrando intereses mal cobrados de 37738 - debe abonar $638.551,05. y quedar en 0
C51: ANOTACION | D51: =D41+1 -> 6
C52: FECHA DE LA ANOTACION: | E52: 45887 | G52: NOMBRE: | H52: Gustavo kearney
C53: QUEJA VIA: | D53: WHATSAPP | E53: MAIL | G53: LOTE: | H53: 12 y 11
C54: FECHA DE LA QUEJA: | E54: 45887
C55: MOTIVO DE LA QUEJA:
C56: El 31/07 deposito $700.000 pesos y se lo pusimos al lote 11 cuando era al lote 12
C61: ANOTACION | D61: =D51+1 -> 7
C62: FECHA DE LA ANOTACION: | E62: 45888 | G62: NOMBRE: | H62: Sergio Ferraris
C63: QUEJA VIA: | D63: WHATSAPP | E63: MAIL | G63: LOTE: | H63: 9
C64: FECHA DE LA QUEJA: | E64: 45887
...

Sheet suzel
D5: CIERRE EXPENSAS JULIO
D6: LOTE | E6: MONTO A ABONAR
D7: =PRORRATEO!S122 -> 118 | E7: =PRORRATEO!P122 -> 1077853.2
D8: =PRORRATEO!S124 -> 120 | E8: =PRORRATEO!P124 -> 679130.2
D9: =PRORRATEO!S125 -> 121 | E9: =PRORRATEO!P125 -> 679130.21
D10: TOTAL | E10: =SUM(E7:E9) -> 2436113.6
D12: 25/8 DEPOSITO | E12: 1770000
D13: RESTA ABONAR | E13: =E10-E12 -> 666113.59

Sheet SUMS A CORREGIR
B9: al lote 38 le cobramos una deuda (bien cobrada) y un sum por 150.760 MAL COBRADO, este sum que le cobramos mal al 38 era para el 32
