Workbook

Sheet RESUMEN
C1: MAIL: elmiradorconsorcios@gmail.com
C2: CUIT ADMINISTRACION: 27231256879
C3: CBU: | E3: TELEFONO: 11 5320-2676
C4: ADMINISTRADORA: CAROLINA CANCIANI MP:1148
C5: PERÍODO: JULIO | E5: HORARIOS DE ATENCION: LUNES A VIERNES - 10 A 16HS - EMERGENCIAS 24HS
C6: LIQUIDACION DE EXPENSAS
A14: Importante para dueños o inquilinos de departamentos o coheras: Queremos recordarles una cuestión importante respecto a los pagos de expensas que ayuda a evitar errores en la imputación de los mismos. El sistema que utilizamos asigna centavos únicos a cada Unidad Funcional (UF), lo cual nos permite identificar automáticamente a qué unidad corresponde cada transferencia. Es decir, cada UF tiene un número específico de centavos que actúa como "identificador". Por ejemplo, si tu UF es la 45, el importe a abonar debería terminar en $...,45. Si tenés más de una unidad (por ejemplo, un departamento y una cochera), cada una tiene su propio código de centavos. En esos casos, te pedimos por favor que realices una transferencia por cada UF, respetando el importe con sus centavos correspondientes. Sabemos que a veces por comodidad se suele enviar todo junto en una sola transferencia, pero esto puede generar confusión o errores en la imputación automática. Realizar los pagos por separado nos permite asegurar que cada importe se asigne correctamente. Agradecemos muchísimo la colaboración para seguir manteniendo todo ordenado. Saludos cordiales.
A20: VTO 14/08
A24: GASTOS ORDINARIOS UNIDADES FUNCIONALES: | E24: UF 93,20% | F24: LOCAL 1 (1,08%) | G24: LOCAL 2 (1,28%) | H24: LOCAL 3 (1,21%) | I24: LOCAL 4 (1,49%) | J24: LOCAL 5 (1,74%)
A25: Sueldo encargada Sonia Arzamendia Galeano
A26: Haberes | D26: 977372
A27: Plus pileta | D27: 34111
A28: Plus retiro de basura | D28: 111256.4
A29: Plus cochera | D29: 20777
A30: Adicional remuneracion | D30: 50000
A31: SUBTOTAL | D31: =SUM(D26:D30) -> 1193516.4
A32: Sueldo encargada Miriam
A33: Haberes | D33: 488686
A34: Plus pileta | D34: 34111
A35: Plus retiro de basura | D35: 111256.4
A36: Plus cochera | D36: 20777
A37: Adicional remuneracion | D37: 50000
A38: SUBTOTAL | D38: =SUM(D33:D37) -> 704830.4
A39: TOTAL SUELDO | D39: =D31+D38 -> 1898346.8 | E39: =D39*93.2% -> 1769259.2 | F39: =$D39*1.08% -> 20502.145 | G39: =$D39*1.28% -> 24298.839 | H39: =$D39*1.21% -> 22969.996 | I39: =$D39*1.49% -> 28285.367 | J39: =D39*1.74% -> 33031.234 | K39: =E39+J39+F39+G39+H39+I39 -> 1898346.8 | L39: =IF(D39=K39, "", "Error")
A40: SAC | D40: 0 | E40: =D40*91.91% -> 0 | J40: =D40*8.09% -> 0
D41: 0 | E41: =D41*91.91% -> 0 | J41: =D41*8.09% -> 0
A44: TOTAL | D44: =SUM(D40:D42) -> 0 | E44: =SUM(E40:E42) -> 0 | J44: =SUM(J40:J42) -> 0 | K44: =E44+J44 -> 0 | L44: =IF(D44=K44, "", "Error")
A45: COMBUSTIBLE PARA GRUPO ELECTROGENO | E45: =D45*91.91% -> 0 | J45: =D45*8.09% -> 0
A46: Gas Lanus SA - Compra infinia diesel | C46: Efect 24/07 | D46: 37011.99 | E46: =D46 -> 37011.99
A47: Gas Lanus SA - Compra infinia diesel | C47: Efect 24/07 | D47: 65006.06 | E47: =D47 -> 65006.06
A48: Gas Lanus SA - Compra infinia diesel | C48: Efect 26/07 | D48: 26019.04 | E48: =D48 -> 26019.04
A49: Gas Lanus SA - Compra infinia diesel | C49: Efect 28/07 | D49: 23000 | E49: =D49 -> 23000
A50: Gas Lanus SA - Compra infinia diesel | C50: Efect 31/07 | D50: 27002.95 | E50: =D50 -> 27002.95
E51: =D51*91.91% -> 0 | J51: =D51*8.09% -> 0
A52: TOTAL SAC | D52: =SUM(D41:D51) -> 178040.04 | E52: =SUM(E41:E51) -> 178040.04 | K52: =E52+J52+F52+G52+H52+I52 -> 178040.04 | L52: =IF(D52=K52, "", "Error")
A53: IMPUESTOS
A54: ARBA - Impuesto inmobiliario partida 025024270-0
A55: TSG - Partida 197229000 | C55: PMC 10/07 | D55: 643422
A56: TSG - Partida 197227000 | C56: PMC 10/07 | D56: 643422
A57: TOTAL IMPUESTOS | D57: =SUM(D54:D56) -> 1286844 | E57: =D57*93.2% -> 1199338.6 | F57: =$D57*1.08% -> 13897.915 | G57: =$D57*1.28% -> 16471.603 | H57: =$D57*1.21% -> 15570.812 | I57: =$D57*1.49% -> 19173.976 | J57: =D57*1.74% -> 22391.086 | K57: =E57+J57+F57+G57+H57+I57 -> 1286844 | L57: =IF(D57=K57, "", "Error")
...

Sheet PRORRATEO
G1: ESTADO DE CUENTA Y PRORRATEO | K1: SE GASTO: | L1: =RESUMEN!D103-RESUMEN!D101 -> 7642586
K2: SE PRORRATEA EN LAS UF: | M2: 9000000
A3: =RESUMEN!C5 -> PERÍODO: JULIO
J4: =(J3*8.09%)/44 -> 0 | P4: =L1-K127 -> -1240893.8
A5: Piso | B5: Dpto. | C5: UF | D5: Propietario | E5: Inquilinos | F5: (%) | G5: Saldo | H5: Ingreso | I5: SALDO | J5: Expensas extraor. | K5: Expensas ord | L5: SUM/ GASTOS PART | M5: TOTAL A ABONAR HASTA | N5: TOTAL A ABONAR 2DO VTO - DESDE EL
M7: =RESUMEN!A20 -> VTO 14/08 | N7: =RESUMEN!A20 -> VTO 14/08
A8: conf sup | C8: LOC 1 | D8: Fernandez, Cristian | F8: 0.0108 | G8: 70998.784 | H8: =G8 -> 70998.784 | I8: =G8-H8 -> 0 | J8: 0 | K8: 81552.687 | L8: =J$3*F8%+J$4 -> 0 | M8: =K8+J8+I8+L8 -> 81552.687 | N8: =M8*6% + M8 -> 86445.848 | Q8: para copias y pegar las expensas ord del local
C9: LOC 2 | D9: Sr propietario | F9: 0.013 | G9: 84146.707 | H9: =G9 -> 84146.707 | I9: =G9-H9 -> 0 | J9: 0 | K9: 96655.037 | L9: =J$3*F9%+J$4 -> 0 | M9: =K9+J9+I9+L9 -> 96655.037 | N9: =M9*6% + M9 -> 102454.34
A10: conf sup | C10: LOC 3 | D10: Schiaffino, Edgardo Angel | F10: 0.0121 | G10: 79544.934 | H10: =G10 -> 79544.934 | I10: =G10-H10 -> 0 | J10: 0 | K10: 91369.214 | L10: =J$3*F10%+J$4 -> 0 | M10: =K10+J10+I10+L10 -> 91369.214 | N10: =M10*6% + M10 -> 96851.367 | Q10: LOCAL 1 | R10: =RESUMEN!F103 -> 82162.051
A11: conf sup | C11: LOC 4 | D11: Cordero, Leandro Emanuel - Orona, Victoria | F11: 0.0149 | G11: 97952.027 | H11: =G11 -> 97952.027 | I11: =G11-H11 -> 0 | J11: 0 | K11: 112512.5 | L11: =J$3*F11%+J$4 -> 0 | M11: =K11+J11+I11+L11 -> 112512.5 | N11: =M11*6% + M11 -> 119263.25 | Q11: LOCAL 2 | R11: =RESUMEN!G103 -> 97377.246
A12: conf sup | C12: LOC 5 | D12: Orsi, Jose Luis - Fernandez, Cristian Gabriel | F12: 0.0174 | G12: 114386.93 | H12: =G12 -> 114386.93 | I12: =G12-H12 -> 0 | J12: 0 | K12: 131390.44 | L12: =J$3*F12%+J$4 -> 0 | M12: =K12+J12+I12+L12 -> 131390.44 | N12: =M12*6% + M12 -> 139273.87 | Q12: LOCAL 3 | R12: =RESUMEN!H103 -> 92051.928
A13: 3 amb | C13: 2ºA | D13: Franco, Lucas Fabián | F13: 0.0188 | G13: 134281.01 | H13: =G13 -> 134281.01 | I13: =G13-H13 -> 0 | J13: =M$4*F13 -> 0 | K13: =M$2*F13 -> 169200 | L13: =J$3*F13%+J$4 -> 0 | M13: =ROUND((K13+J13+I13+L13),0) + O13 -> 169200.01 | N13: =ROUND((M13*6% + M13 ),0) + O13 -> 179352.01 | O13: 0.01 | Q13: LOCAL 4 | R13: =RESUMEN!I103 -> 113353.2
A14: 1 amb | C14: 2ºB | D14: Martinez, Diego | F14: 0.0084 | G14: 59998.02 | H14: 63598.02 | I14: =G14-H14 -> -3600 | J14: =M$4*F14 -> 0 | K14: =M$2*F14 -> 75600 | L14: =J$3*F14%+J$4 -> 0 | M14: =ROUND((K14+J14+I14+L14),0) + O14 -> 72000.02 | N14: =ROUND((M14*6% + M14 ),0) + O14 -> 76320.02 | O14: =O13+0.01 -> 0.02 | Q14: LOCAL 5 | R14: =RESUMEN!J103 -> 132372.19
A15: 3 amb | C15: 2ºC | D15: Rodriguez, Carlos Alberto Miguel | F15: 0.0201 | G15: 143566.03 | H15: =G15 -> 143566.03 | I15: =G15-H15 -> 0 | J15: =M$4*F15 -> 0 | K15: =M$2*F15 -> 180900 | L15: =J$3*F15%+J$4 -> 0 | M15: =ROUND((K15+J15+I15+L15),0) + O15 -> 180900.03 | N15: =ROUND((M15*6% + M15 ),0) + O15 -> 191754.03 | O15: =O14+0.01 -> 0.03
A16: 2 amb | C16: 2ºD | D16: Ferraro, José | F16: 0.0094 | G16: 67140.04 | I16: =G16-H16 -> 67140.04 | J16: =M$4*F16 -> 0 | K16: =M$2*F16 -> 84600 | L16: =J$3*F16%+J$4 -> 0 | M16: =ROUND((K16+J16+I16+L16),0) + O16 -> 151740.04 | N16: =ROUND((M16*6% + M16 ),0) + O16 -> 160844.04 | O16: =O15+0.01 -> 0.04
A17: 2 amb | C17: 2ºE | D17: Dieci, Matias Orlando | F17: 0.0087 | G17: 62141.05 | H17: =G17 -> 62141.05 | I17: =G17-H17 -> 0 | J17: =M$4*F17 -> 0 | K17: =M$2*F17 -> 78300 | L17: 9000 | M17: =ROUND((K17+J17+I17+L17),0) + O17 -> 87300.05 | N17: =ROUND((M17*6% + M17 ),0) + O17 -> 92538.05 | O17: =O16+0.01 -> 0.05
A18: 2 amb | C18: 2ºF | D18: Ferraro, Jose | E18: Carolina | F18: 0.0095 | G18: 67855.06 | I18: =G18-H18 -> 67855.06 | J18: =M$4*F18 -> 0 | K18: =M$2*F18 -> 85500 | L18: 9000 | M18: =ROUND((K18+J18+I18+L18),0) + O18 -> 162355.06 | N18: =ROUND((M18*6% + M18 ),0) + O18 -> 172096.06 | O18: =O17+0.01 -> 0.06
A19: 3 amb | C19: 3ºA | D19: Ferraro, Jose | F19: 0.0165 | G19: 117853.07 | I19: =G19-H19 -> 117853.07 | J19: =M$4*F19 -> 0 | K19: =M$2*F19 -> 148500 | L19: =J$3*F19%+J$4 -> 0 | M19: =ROUND((K19+J19+I19+L19),0) + O19 -> 266353.07 | N19: =ROUND((M19*6% + M19 ),0) + O19 -> 282334.07 | O19: =O18+0.01 -> 0.07
A20: 1 amb | C20: 3ºB | D20: Balduzzi, Stella Maris | F20: 0.0073 | G20: 52141.08 | H20: =G20 -> 52141.08 | I20: =G20-H20 -> 0 | J20: =M$4*F20 -> 0 | K20: =M$2*F20 -> 65700 | L20: =J$3*F20%+J$4 -> 0 | M20: =ROUND((K20+J20+I20+L20),0) + O20 -> 65700.08 | N20: =ROUND((M20*6% + M20 ),0) + O20 -> 69642.08 | O20: =O19+0.01 -> 0.08
A21: 3 amb | C21: 3ºC | D21: Ferraro, Jose | F21: 0.0178 | G21: 127138.09 | I21: =G21-H21 -> 127138.09 | J21: =M$4*F21 -> 0 | K21: =M$2*F21 -> 160200 | L21: =J$3*F21%+J$4 -> 0 | M21: =ROUND((K21+J21+I21+L21),0) + O21 -> 287338.09 | N21: =ROUND((M21*6% + M21 ),0) + O21 -> 304578.09 | O21: =O20+0.01 -> 0.09
A22: 2 amb | C22: 3ºD | D22: Ayala, Roberto Adrian | F22: 0.0094 | G22: 67140.1 | H22: =G22 -> 67140.1 | I22: =G22-H22 -> 0 | J22: =M$4*F22 -> 0 | K22: =M$2*F22 -> 84600 | L22: =J$3*F22%+J$4 -> 0 | M22: =ROUND((K22+J22+I22+L22),0) + O22 -> 84600.1 | N22: =ROUND((M22*6% + M22 ),0) + O22 -> 89676.1 | O22: =O21+0.01 -> 0.1
A23: 2 amb | C23: 3ºE | D23: Ayala, Roberto Adrian | F23: 0.0087 | G23: 62141.11 | H23: =G23 -> 62141.11 | I23: =G23-H23 -> 0 | J23: =M$4*F23 -> 0 | K23: =M$2*F23 -> 78300 | L23: =J$3*F23%+J$4 -> 0 | M23: =ROUND((K23+J23+I23+L23),0) + O23 -> 78300.11 | N23: =ROUND((M23*6% + M23 ),0) + O23 -> 82998.11 | O23: =O22+0.01 -> 0.11
A24: 2 amb | C24: 3ºF | D24: Ayala, Roberto Adrian | F24: 0.0095 | G24: 67855.12 | H24: =G24 -> 67855.12 | I24: =G24-H24 -> 0 | J24: =M$4*F24 -> 0 | K24: =M$2*F24 -> 85500 | L24: =J$3*F24%+J$4 -> 0 | M24: =ROUND((K24+J24+I24+L24),0) + O24 -> 85500.12 | N24: =ROUND((M24*6% + M24 ),0) + O24 -> 90630.12 | O24: =O23+0.01 -> 0.12
A25: 3 amb | C25: 4ºA | D25: Barral, Carlos Daniel | F25: 0.0164 | G25: 135139.13 | H25: =G25 -> 135139.13 | I25: =G25-H25 -> 0 | J25: =M$4*F25 -> 0 | K25: =M$2*F25 -> 147600 | L25: =J$3*F25%+J$4 -> 0 | M25: =ROUND((K25+J25+I25+L25),0) + O25 -> 147600.13 | N25: =ROUND((M25*6% + M25 ),0) + O25 -> 156456.13 | O25: =O24+0.01 -> 0.13
A26: 1 amb | C26: 4ºB | D26: Sr. Propietario | E26: Liria | F26: 0.0072 | G26: 51427.14 | I26: =G26-H26 -> 51427.14 | J26: =M$4*F26 -> 0 | K26: =M$2*F26 -> 64800 | L26: =J$3*F26%+J$4 -> 0 | M26: =ROUND((K26+J26+I26+L26),0) + O26 -> 116227.14 | N26: =ROUND((M26*6% + M26 ),0) + O26 -> 123201.14 | O26: =O25+0.01 -> 0.14
A27: 3 amb | C27: 4ºC | D27: Osipowicz, Ariel Marcelo | F27: 0.0173 | G27: 150567.15 | H27: =G27 -> 150567.15 | I27: =G27-H27 -> 0 | J27: =M$4*F27 -> 0 | K27: =M$2*F27 -> 155700 | L27: =J$3*F27%+J$4 -> 0 | M27: =ROUND((K27+J27+I27+L27),0) + O27 -> 155700.15 | N27: =ROUND((M27*6% + M27 ),0) + O27 -> 165042.15 | O27: =O26+0.01 -> 0.15
A28: 2 amb | C28: 4ºD | D28: Ayala, Roberto Adrian | F28: 0.0094 | G28: 67140.16 | H28: =G28 -> 67140.16 | I28: =G28-H28 -> 0 | J28: =M$4*F28 -> 0 | K28: =M$2*F28 -> 84600 | L28: =J$3*F28%+J$4 -> 0 | M28: =ROUND((K28+J28+I28+L28),0) + O28 -> 84600.16 | N28: =ROUND((M28*6% + M28 ),0) + O28 -> 89676.16 | O28: =O27+0.01 -> 0.16
A29: 2 amb | C29: 4ºE | D29: Ayala, Roberto Adrian | F29: 0.0087 | G29: 62141.17 | H29: =G29 -> 62141.17 | I29: =G29-H29 -> 0 | J29: =M$4*F29 -> 0 | K29: =M$2*F29 -> 78300 | L29: =J$3*F29%+J$4 -> 0 | M29: =ROUND((K29+J29+I29+L29),0) + O29 -> 78300.17 | N29: =ROUND((M29*6% + M29 ),0) + O29 -> 82998.17 | O29: =O28+0.01 -> 0.17
A30: 2 amb | C30: 4ºF | D30: Ayala, Roberto Adrian | F30: 0.0095 | G30: 67855.18 | H30: =G30 -> 67855.18 | I30: =G30-H30 -> 0 | J30: =M$4*F30 -> 0 | K30: =M$2*F30 -> 85500 | L30: =J$3*F30%+J$4 -> 0 | M30: =ROUND((K30+J30+I30+L30),0) + O30 -> 85500.18 | N30: =ROUND((M30*6% + M30 ),0) + O30 -> 90630.18 | O30: =O29+0.01 -> 0.18
A31: 3 amb | C31: 5ºA | D31: Chehab, Gabriel Adrian | F31: 0.0164 | G31: 117139.19 | H31: =G31 -> 117139.19 | I31: =G31-H31 -> 0 | J31: =M$4*F31 -> 0 | K31: =M$2*F31 -> 147600 | L31: =J$3*F31%+J$4 -> 0 | M31: =ROUND((K31+J31+I31+L31),0) + O31 -> 147600.19 | N31: =ROUND((M31*6% + M31 ),0) + O31 -> 156456.19 | O31: =O30+0.01 -> 0.19
A32: 1 amb | C32: 5ºB | D32: Mesa, Mariano | F32: 0.0072 | G32: 51427.2 | H32: =G32 -> 51427.2 | I32: =G32-H32 -> 0 | J32: =M$4*F32 -> 0 | K32: =M$2*F32 -> 64800 | L32: =J$3*F32%+J$4 -> 0 | M32: =ROUND((K32+J32+I32+L32),0) + O32 -> 64800.2 | N32: =ROUND((M32*6% + M32 ),0) + O32 -> 68688.2 | O32: =O31+0.01 -> 0.2
A33: 3 amb | C33: 5ºC | D33: Di Mito, Vicente Argentino - Serantes, Mabel | F33: 0.0173 | G33: 123567.21 | I33: =G33-H33 -> 123567.21 | J33: =M$4*F33 -> 0 | K33: =M$2*F33 -> 155700 | L33: =J$3*F33%+J$4 -> 0 | M33: =ROUND((K33+J33+I33+L33),0) + O33 -> 279267.21 | N33: =ROUND((M33*6% + M33 ),0) + O33 -> 296023.21 | O33: =O32+0.01 -> 0.21
A34: 2 amb | C34: 5ºD | D34: Ayala, Agustin | F34: 0.0094 | G34: 67140.22 | H34: =G34 -> 67140.22 | I34: =G34-H34 -> 0 | J34: =M$4*F34 -> 0 | K34: =M$2*F34 -> 84600 | L34: =J$3*F34%+J$4 -> 0 | M34: =ROUND((K34+J34+I34+L34),0) + O34 -> 84600.22 | N34: =ROUND((M34*6% + M34 ),0) + O34 -> 89676.22 | O34: =O33+0.01 -> 0.22
A35: 2 amb | C35: 5ºE | D35: Ayala, Roberto Adrian | F35: 0.0087 | G35: 62141.23 | H35: =G35 -> 62141.23 | I35: =G35-H35 -> 0 | J35: =M$4*F35 -> 0 | K35: =M$2*F35 -> 78300 | L35: =J$3*F35%+J$4 -> 0 | M35: =ROUND((K35+J35+I35+L35),0) + O35 -> 78300.23 | N35: =ROUND((M35*6% + M35 ),0) + O35 -> 82998.23 | O35: =O34+0.01 -> 0.23
A36: 2 amb | C36: 5ºF | D36: Ayala, Agustin | F36: 0.0095 | G36: 67855.24 | H36: =G36 -> 67855.24 | I36: =G36-H36 -> 0 | J36: =M$4*F36 -> 0 | K36: =M$2*F36 -> 85500 | L36: =J$3*F36%+J$4 -> 0 | M36: =ROUND((K36+J36+I36+L36),0) + O36 -> 85500.24 | N36: =ROUND((M36*6% + M36 ),0) + O36 -> 90630.24 | O36: =O35+0.01 -> 0.24
A37: 3 amb | C37: 6ºA | D37: Morandi, Victoria Ayelen | Calvo, Luciano Ezequiel | F37: 0.0164 | G37: 117139.25 | H37: =G37 -> 117139.25 | I37: =G37-H37 -> 0 | J37: =M$4*F37 -> 0 | K37: =M$2*F37 -> 147600 | L37: =J$3*F37%+J$4 -> 0 | M37: =ROUND((K37+J37+I37+L37),0) + O37 -> 147600.25 | N37: =ROUND((M37*6% + M37 ),0) + O37 -> 156456.25 | O37: =O36+0.01 -> 0.25
A38: 1 amb | C38: 6ºB | D38: Grizak Ruben | E38: Christian | F38: 0.0072 | G38: 78427.26 | H38: 78430 | I38: =G38-H38 -> -2.74 | J38: =M$4*F38 -> 0 | K38: =M$2*F38 -> 64800 | L38: =J$3*F38%+J$4 -> 0 | M38: =ROUND((K38+J38+I38+L38),0) + O38 -> 64797.26 | N38: =ROUND((M38*6% + M38 ),0) + O38 -> 68685.26 | O38: =O37+0.01 -> 0.26
A39: 3 amb | C39: 6ºC | D39: Nuñez Leonel - Corrieri Giuliana | F39: 0.0173 | G39: 123567.27 | H39: =G39 -> 123567.27 | I39: =G39-H39 -> 0 | J39: =M$4*F39 -> 0 | K39: =M$2*F39 -> 155700 | L39: 18000 | M39: =ROUND((K39+J39+I39+L39),0) + O39 -> 173700.27 | N39: =ROUND((M39*6% + M39 ),0) + O39 -> 184122.27 | O39: =O38+0.01 -> 0.27 | P39: COCHERA 33 | Q39: COCHERA 33
A40: 2 amb | C40: 6ºD | D40: Sr propietario | F40: 0.0094 | G40: 67140.28 | H40: =G40 -> 67140.28 | I40: =G40-H40 -> 0 | J40: =M$4*F40 -> 0 | K40: =M$2*F40 -> 84600 | L40: =J$3*F40%+J$4 -> 0 | M40: =ROUND((K40+J40+I40+L40),0) + O40 -> 84600.28 | N40: =ROUND((M40*6% + M40 ),0) + O40 -> 89676.28 | O40: =O39+0.01 -> 0.28 | Q40: mariano hecimovic
A41: 2 amb | C41: 6ºE | D41: Dieci, Matias Orlando | F41: 0.0087 | G41: 62141.29 | H41: =G41 -> 62141.29 | I41: =G41-H41 -> 0 | J41: =M$4*F41 -> 0 | K41: =M$2*F41 -> 78300 | L41: =J$3*F41%+J$4 -> 0 | M41: =ROUND((K41+J41+I41+L41),0) + O41 -> 78300.29 | N41: =ROUND((M41*6% + M41 ),0) + O41 -> 82998.29 | O41: =O40+0.01 -> 0.29
...

Sheet Hoja1
C4: AYALA
C5: 52141.08 | D5: 3B
C6: 67140.1 | D6: 3D
C7: 52121.11 | D7: 3E
C8: 67885.12 | D8: 3F
C9: 67140.16 | D9: 4D
C10: 62141.17 | D10: 4E
C11: 67855.18 | D11: 4F
C12: 62141.23 | D12: 5E
C13: 67855.24 | D13: 5F
C14: =SUM(C5:C13) -> 566420.39

Sheet ANOTACIONES
B4: AGREGAR MAILS DEL FOLEO
