Workbook

Sheet RESUMEN
B2: MAIL: consorciogorriti368@gmail.com
B3: CUIT ADMINISTRACION: 27231256879
B4: CBU: 0290034600000502294350 | D4: TELEFONO: 11 5320-2676
A5: LIQUIDACION DE EXPENSAS | B5: ADMINISTRADORA: CAROLINA CANCIANI MP:1148
A6: CUIT DEL EDIFICIO: 30583957819 | B6: PERÍODO: MARZO | D6: HORARIOS DE ATENCION: LUNES A VIERNES
A7: CONSORCIO DE PROPIETARIOS DEL EDIFICIO CALLE GORRITI 368 | D7: 10 A 16HS - EMERGENCIAS 24HS
B9: VTO 14/04
A14: ESTIMADOS PROPIETARIOS E INQUILINOS: POR FAVOR LOS QUE ABONAN EN PRIMER VENCIMIENTO ABONEN EL MONTO DE PRIMER VENCIMIENTO, ASI AGILIZAN LA LIQUIDACION, RESPETEN LOS CENTAVOS CORRESPONDIENTES A LA UNIDAD FUNCIONAL. ES DE CARÁCTER OBLIGATORIO INFORMAR VIA MAIL LAS EXPENSAS. CASO CONTRARIO SE INFORMARA VIA CARTA DOCUMENTO A LA UNIDAD FUNCIONAL QUE CREEMOS QUE CORRESPONDE, CUYO COSTO SERA IMPUTADO A LA UNIDAD FUNCIONAL SOSPECHADA.
A21: GASTOS ORDINARIOS UNIDADES FUNCIONALES:
A22: HABERES ENCARGADOS
A23: Sueldo encargado Colmiero Oscar | D23: 1227647
A26: Retenciones | D26: 0
A28: Neto | D28: =SUM(D23:D27) -> 1227647 | G28: =D28+D37 -> 2231706
A29: Sueldo encargado Balcazza Leonardo | D29: 1004059
A33: SAC
A34: Retenciones SAC
A35: Retenciones | D35: 0
A37: Neto | D37: =SUM(D29:D36) -> 1004059
A38: TOTAL SUELDO | E38: =D28+D37 -> 2231706
A39: HONORARIOS
A40: GUSTAVO PADRON - SE ABONA MES 12/2024 - MES 1 Y 2 DEL 2025 - SE DEBE MES DE MARZO 2025 | D40: 150000 | E40: Transf 13/02
A41: HONORARIOS ADMINISTRACION RC - SE ABONA EL MES 1 Y 2 DEL 2025 - SE ADEUDA MES 3 | D41: 460000 | E41: =E40 -> Transf 13/02
A42: TOTAL | E42: =SUM(D40:D41) -> 610000
A43: SEGUROS
A44: Seguro Integral consorcio San Cristobal - Poliza 01-05-07-30183461 | D44: 120974 | E44: Debito 10/03
A46: TOTAL IMPUESTO | E46: =SUM(D44:D45) -> 120974
A47: APORTES Y CONTRIBUCIONES
A48: ARCA | D48: 1425903 | E48: PMC 13/03
A49: Sindicatos mes de MARZO | B49: Fatheryh | D49: 130033.66 | E49: Debito 12/03
A50: =A49 -> Sindicatos mes de MARZO | B50: Suther | D50: 263175.12 | E50: =E49 -> Debito 12/03
A51: =A50 -> Sindicatos mes de MARZO | B51: Seracarh | D51: 14448.18 | E51: =E50 -> Debito 12/03
A52: TOTAL Aportes y Contribuciones - Sindicato | E52: =SUM(D48:D51) -> 1833560
A53: ABONOS Y SERVICIOS
A54: EDESUR - Cliente nro. 828563 | D54: 684571.44 | E54: PMC 10/03
A55: EDESUR - Cliente nro. 01672309 | D55: 22935.54 | E55: =E54 -> PMC 10/03
A56: EDESUR - Cliente nro. 01672321 | D56: 16991 | E56: =E55 -> PMC 10/03
A57: EDESUR - Cliente nro. 01672319 | D57: 11712.22 | E57: =E56 -> PMC 10/03
A58: Metrogas - Cliente nro. 20463936100 | D58: =8218.47 -> 8218.47 | E58: PMC 19/03
A59: Metrogas Plan de pagos cuota 1 de 4 - Cliente nro. 020495697900 | D59: 571923.58 | E59: Efect 31/03
A60: EL EFECTIVO FUE ABONADO POR LA ADMINISTRACION Y SE RECUPERARA MEDIANTE TRANSFERENCIA YA QUE LOS PLANES DE PAGO SE ABONAN CON TARJETA DE CREDITO, DEBITO O EFECTIVO.
...

Sheet PRORRATEO
E2: =RESUMEN!B4 -> CBU: 0290034600000502294350 | L2: Gastos ordinarios: | P2: 11376831
A4: Piso | B4: Dpto. | D4: UF | E4: Propietario | F4: Inquilinos | G4: (%) | H4: Saldo Ord | I4: Ingreso | J4: Pago por | K4: Deuda o Saldo a favor | L4: Interes 3% | M4: Expensas extraor. | N4: Expensas ord. | O4: Gastos part. | P4: Total 1er Vto | Q4: Total 2do Vto. | R4: Total 2do Vto
P5: =RESUMEN!B9 -> VTO 14/04
A6: PB | C6: LOC | D6: 1 | E6: GEFFNER SILVIA E. | G6: 0.5131 | H6: 53269.01 | I6: =659558-I13-I7-I47-I48-I59-I69-I73 -> 53269.19 | K6: =H6-I6 -> -0.18 | L6: =IF(K6>0,K6*3%,0) -> 0 | M6: 0 | N6: =P$2*G6% -> 58374.522 | O6: 0 | P6: =ROUND(SUM(K6:O6),0) + S6 -> 58374.01 | Q6: =ROUND(P6*6% + P6,0) + S6 -> 61876.01 | R6: =ROUND(P6*3%,0) + P6 -> 60125.01 | S6: 0.01 | U6: este es el candel que tiene a todas sus demas ufs relacionadas
A7: 3º | C7: LOC | D7: =D6+1 -> 2 | E7: COVILOZA S. A. | G7: 0.6119 | H7: 63526.02 | I7: =H7 -> 63526.02 | K7: =H7-I7 -> 0 | L7: =IF(K7>0,K7*3%,0) -> 0 | M7: 0 | N7: =P$2*G7% -> 69614.832 | O7: 0 | P7: =ROUND(SUM(K7:O7),0) + S7 -> 69615.02 | Q7: =ROUND(P7*6% + P7,0) + S7 -> 73792.02 | R7: =ROUND(P7*3%,0) + P7 -> 71703.02 | S7: =S6+0.01 -> 0.02
A8: 3º | B8: 1 | D8: =D7+1 -> 3 | E8: ASIST Y TRAB. | G8: 0.6115 | H8: 63485.03 | K8: =H8-I8 -> 63485.03 | L8: =IF(K8>0,K8*3%,0) -> 1904.5509 | M8: 0 | N8: =P$2*G8% -> 69569.324 | O8: 0 | P8: =ROUND(SUM(K8:O8),0) + S8 -> 134959.03 | Q8: =ROUND(P8*6% + P8,0) + S8 -> 143057.03 | R8: =ROUND(P8*3%,0) + P8 -> 139008.03 | S8: =S7+0.01 -> 0.03
A9: 4º | B9: 2 | D9: =D8+1 -> 4 | E9: ASIST Y TRAB. | G9: 0.5033 | H9: 52252.04 | K9: =H9-I9 -> 52252.04 | L9: =IF(K9>0,K9*3%,0) -> 1567.5612 | M9: 0 | N9: =P$2*G9% -> 57259.593 | O9: 0 | P9: =ROUND(SUM(K9:O9),0) + S9 -> 111079.04 | Q9: =ROUND(P9*6% + P9,0) + S9 -> 117744.04 | R9: =ROUND(P9*3%,0) + P9 -> 114411.04 | S9: =S8+0.01 -> 0.04
A10: 4º | B10: 3 | D10: =D9+1 -> 5 | E10: ASIST Y TRAB. | G10: 0.5033 | H10: 46711.05 | K10: =H10-I10 -> 46711.05 | L10: =IF(K10>0,K10*3%,0) -> 1401.3315 | M10: 0 | N10: =P$2*G10% -> 57259.593 | O10: 0 | P10: =ROUND(SUM(K10:O10),0) + S10 -> 105372.05 | Q10: =ROUND(P10*6% + P10,0) + S10 -> 111694.05 | R10: =ROUND(P10*3%,0) + P10 -> 108533.05 | S10: =S9+0.01 -> 0.05
A11: 5º | B11: 4 | D11: =D10+1 -> 6 | E11: BENMAOR D. | F11: Cristian Requelme | G11: 0.7499 | H11: 77853.06 | I11: =H11 -> 77853.06 | K11: =H11-I11 -> 0 | L11: =IF(K11>0,K11*3%,0) -> 0 | M11: 0 | N11: =P$2*G11% -> 85314.859 | O11: 0 | P11: =ROUND(SUM(K11:O11),0) + S11 -> 85315.06 | Q11: =ROUND(P11*6% + P11,0) + S11 -> 90434.06 | R11: =ROUND(P11*3%,0) + P11 -> 87874.06 | S11: =S10+0.01 -> 0.06
A12: 5º | B12: 5 | D12: =D11+1 -> 7 | E12: GALANTERNIK A | F12: Miriam Larken | G12: 0.5425 | H12: 56321.07 | I12: =H12 -> 56321.07 | K12: =H12-I12 -> 0 | L12: =IF(K12>0,K12*3%,0) -> 0 | M12: 0 | N12: =P$2*G12% -> 61719.311 | O12: 0 | P12: =ROUND(SUM(K12:O12),0) + S12 -> 61719.07 | Q12: =ROUND(P12*6% + P12,0) + S12 -> 65422.07 | R12: =ROUND(P12*3%,0) + P12 -> 63571.07 | S12: =S11+0.01 -> 0.07
A13: 6º | B13: 6 | D13: =D12+1 -> 8 | E13: CANDEL JORGE ISAAC | G13: 0.4537 | H13: 47102.08 | I13: =H13 -> 47102.08 | K13: =H13-I13 -> 0 | L13: =IF(K13>0,K13*3%,0) -> 0 | M13: 0 | N13: =P$2*G13% -> 51616.684 | O13: 0 | P13: =ROUND(SUM(K13:O13),0) + S13 -> 51617.08 | Q13: =ROUND(P13*6% + P13,0) + S13 -> 54714.08 | R13: =ROUND(P13*3%,0) + P13 -> 53166.08 | S13: =S12+0.01 -> 0.08
A14: 6º | B14: 7 | D14: =D13+1 -> 9 | E14: BORTZ SERGIO | G14: 0.5244 | H14: 54442.09 | K14: =H14-I14 -> 54442.09 | L14: =IF(K14>0,K14*3%,0) -> 1633.2627 | M14: 0 | N14: =P$2*G14% -> 59660.104 | O14: 0 | P14: =ROUND(SUM(K14:O14),0) + S14 -> 115735.09 | Q14: =ROUND(P14*6% + P14,0) + S14 -> 122679.09 | R14: =ROUND(P14*3%,0) + P14 -> 119207.09 | S14: =S13+0.01 -> 0.09 | U14: ESTA ES LA FUNDACION DE MEDICOS
A15: 7º | B15: 8 | D15: =D14+1 -> 10 | E15: BORTZ SERGIO | G15: 0.424 | H15: 44019.1 | K15: =H15-I15 -> 44019.1 | L15: =IF(K15>0,K15*3%,0) -> 1320.573 | M15: 0 | N15: =P$2*G15% -> 48237.765 | O15: 0 | P15: =ROUND(SUM(K15:O15),0) + S15 -> 93577.1 | Q15: =ROUND(P15*6% + P15,0) + S15 -> 99192.1 | R15: =ROUND(P15*3%,0) + P15 -> 96384.1 | S15: =S14+0.01 -> 0.1 | U15: ESTA ES LA FUNDACION DE MEDICOS
A16: 7º | B16: 1 | C16: A | D16: =D15+1 -> 11 | E16: KIM SOON LEO | G16: 2.3033 | H16: 2218018.1 | K16: =H16-I16 -> 2218018.1 | L16: =IF(K16>0,K16*3%,0) -> 66540.543 | M16: 0 | N16: =P$2*G16% -> 262042.56 | O16: 0 | P16: =ROUND(SUM(K16:O16),0) + S16 -> 2546601.1 | Q16: =ROUND(P16*6% + P16,0) + S16 -> 2699397.1 | R16: =ROUND(P16*3%,0) + P16 -> 2622999.1 | S16: =S15+0.01 -> 0.11
A17: 8º | B17: 1 | C17: B | D17: =D16+1 -> 12 | E17: CANDEL MARCELO | F17: Florencia Fucci | G17: 2.7493 | H17: 293990.12 | I17: =H17 -> 293990.12 | K17: =H17-I17 -> 0 | L17: =IF(K17>0,K17*3%,0) -> 0 | M17: 0 | N17: =P$2*G17% -> 312783.23 | O17: 0 | P17: =ROUND(SUM(K17:O17),0) + S17 -> 312783.12 | Q17: =ROUND(P17*6% + P17,0) + S17 -> 331550.12 | R17: =ROUND(P17*3%,0) + P17 -> 322166.12 | S17: =S16+0.01 -> 0.12
A18: 8º | B18: 2 | C18: A | D18: =D17+1 -> 13 | E18: TRIPODI | F18: Mariela Pricolo | G18: 2.3033 | H18: 239124.13 | I18: =H18 -> 239124.13 | K18: =H18-I18 -> 0 | L18: =IF(K18>0,K18*3%,0) -> 0 | M18: 0 | N18: =P$2*G18% -> 262042.56 | O18: 0 | P18: =ROUND(SUM(K18:O18),0) + S18 -> 262043.13 | Q18: =ROUND(P18*6% + P18,0) + S18 -> 277766.13 | R18: =ROUND(P18*3%,0) + P18 -> 269904.13 | S18: =S17+0.01 -> 0.13
A19: 9º | B19: 2 | C19: B | D19: =D18+1 -> 14 | E19: MIRANDA DE GIL | F19: Susana | G19: 2.6368 | H19: 314618.14 | I19: =234000+80618 -> 314618 | K19: =H19-I19 -> 0.14 | L19: =IF(K19>0,K19*3%,0) -> 0.0042 | M19: 0 | N19: =P$2*G19% -> 299984.29 | O19: 0 | P19: =ROUND(SUM(K19:O19),0) + S19 -> 299984.14 | Q19: =ROUND(P19*6% + P19,0) + S19 -> 317983.14 | R19: =ROUND(P19*3%,0) + P19 -> 308984.14 | S19: =S18+0.01 -> 0.14 | U19: MAXIMO
A20: 9º | B20: 3 | C20: A | D20: =D19+1 -> 15 | E20: FRAGA DORA | G20: 2.3537 | H20: 236299.15 | I20: 243388.15 | K20: =H20-I20 -> -7089 | L20: =IF(K20>0,K20*3%,0) -> 0 | M20: 0 | N20: =P$2*G20% -> 267776.48 | O20: 0 | P20: =ROUND(SUM(K20:O20),0) + S20 -> 260687.15 | Q20: =ROUND(P20*6% + P20,0) + S20 -> 276328.15 | R20: =ROUND(P20*3%,0) + P20 -> 268508.15 | S20: =S19+0.01 -> 0.15
A21: 10º | B21: 3 | C21: B | D21: =D20+1 -> 16 | E21: SARUBBI MARTIN | F21: Sarubbi Adriana | G21: 2.6477 | H21: 274879.16 | I21: =H21 -> 274879.16 | K21: =H21-I21 -> 0 | L21: =IF(K21>0,K21*3%,0) -> 0 | M21: 0 | N21: =P$2*G21% -> 301224.37 | O21: 0 | P21: =ROUND(SUM(K21:O21),0) + S21 -> 301224.16 | Q21: =ROUND(P21*6% + P21,0) + S21 -> 319298.16 | R21: =ROUND(P21*3%,0) + P21 -> 310261.16 | S21: =S20+0.01 -> 0.16
A22: 10º | B22: 4 | C22: A | D22: =D21+1 -> 17 | E22: LACENTRE | F22: Gabriela Tamara | G22: 2.3235 | H22: 241222.17 | I22: =H22 -> 241222.17 | K22: =H22-I22 -> 0 | L22: =IF(K22>0,K22*3%,0) -> 0 | M22: 0 | N22: =P$2*G22% -> 264340.68 | O22: 0 | P22: =ROUND(SUM(K22:O22),0) + S22 -> 264341.17 | Q22: =ROUND(P22*6% + P22,0) + S22 -> 280202.17 | R22: =ROUND(P22*3%,0) + P22 -> 272271.17 | S22: =S21+0.01 -> 0.17
A23: 11º | B23: 4 | C23: B | D23: =D22+1 -> 18 | E23: FERNANDEZ BERTA | F23: KRAVETZ | G23: 2.688 | H23: 599159.18 | I23: =200000*2+217134 -> 617134 | K23: =H23-I23 -> -17974.82 | L23: =IF(K23>0,K23*3%,0) -> 0 | M23: 0 | N23: =P$2*G23% -> 305809.23 | O23: 0 | P23: =ROUND(SUM(K23:O23),0) + S23 -> 287834.18 | Q23: =ROUND(P23*6% + P23,0) + S23 -> 305104.18 | R23: =ROUND(P23*3%,0) + P23 -> 296469.18 | S23: =S22+0.01 -> 0.18 | U23: KRAVETZ
A24: 11º | B24: 5 | C24: A | D24: =D23+1 -> 19 | E24: VERONES JOSE MARIA | G24: 2.36 | H24: 245011.19 | I24: =345011.19 -> 345011.19 | K24: =H24-I24 -> -100000 | L24: =IF(K24>0,K24*3%,0) -> 0 | M24: 0 | N24: =P$2*G24% -> 268493.22 | O24: 0 | P24: =ROUND(SUM(K24:O24),0) + S24 -> 168493.19 | Q24: =ROUND(P24*6% + P24,0) + S24 -> 178603.19 | R24: =ROUND(P24*3%,0) + P24 -> 173548.19 | S24: =S23+0.01 -> 0.19
A25: 12º | B25: 5 | C25: B | D25: =D24+1 -> 20 | E25: SRUGO CARLOS | G25: 2.7183 | H25: 365245.2 | I25: 365300 | K25: =H25-I25 -> -54.8 | L25: =IF(K25>0,K25*3%,0) -> 0 | M25: 0 | N25: =P$2*G25% -> 309256.41 | O25: 0 | P25: =ROUND(SUM(K25:O25),0) + S25 -> 309202.2 | Q25: =ROUND(P25*6% + P25,0) + S25 -> 327754.2 | R25: =ROUND(P25*3%,0) + P25 -> 318478.2 | S25: =S24+0.01 -> 0.2
A26: 13º | B26: 6 | C26: A | D26: =D25+1 -> 21 | E26: DINOTO | G26: 2.3033 | H26: -6461.79 | K26: =H26-I26 -> -6461.79 | L26: =IF(K26>0,K26*3%,0) -> 0 | M26: 0 | N26: =P$2*G26% -> 262042.56 | O26: 0 | P26: =ROUND(SUM(K26:O26),0) + S26 -> 255581.21 | Q26: =ROUND(P26*6% + P26,0) + S26 -> 270916.21 | R26: =ROUND(P26*3%,0) + P26 -> 263248.21 | S26: =S25+0.01 -> 0.21
A27: 14º | B27: 6 | C27: B | D27: =D26+1 -> 22 | E27: BORTZ ESTHER | F27: Daniel | G27: 2.636 | H27: 273665.22 | K27: =H27-I27 -> 273665.22 | L27: =IF(K27>0,K27*3%,0) -> 8209.9566 | M27: 0 | N27: =P$2*G27% -> 299893.28 | O27: 0 | P27: =ROUND(SUM(K27:O27),0) + S27 -> 581768.22 | Q27: =ROUND(P27*6% + P27,0) + S27 -> 616674.22 | R27: =ROUND(P27*3%,0) + P27 -> 599221.22 | S27: =S26+0.01 -> 0.22 | U27: ESTA ES LA FUNDACION DE MEDICOS
A28: 15º | B28: 7 | C28: A | D28: =D27+1 -> 23 | E28: COUSO MARIA CRISTINA | G28: 2.3033 | H28: 239124.23 | I28: =H28 -> 239124.23 | K28: =H28-I28 -> 0 | L28: =IF(K28>0,K28*3%,0) -> 0 | M28: 0 | N28: =P$2*G28% -> 262042.56 | O28: 0 | P28: =ROUND(SUM(K28:O28),0) + S28 -> 262043.23 | Q28: =ROUND(P28*6% + P28,0) + S28 -> 277766.23 | R28: =ROUND(P28*3%,0) + P28 -> 269904.23 | S28: =S27+0.01 -> 0.23
A29: COC | B29: 7 | C29: B | D29: =D28+1 -> 24 | E29: POSSENTI JUAN JOSE | G29: 2.6159 | H29: 271578.24 | I29: =H29 -> 271578.24 | K29: =H29-I29 -> 0 | L29: =IF(K29>0,K29*3%,0) -> 0 | M29: 0 | N29: =P$2*G29% -> 297606.53 | O29: 0 | P29: =ROUND(SUM(K29:O29),0) + S29 -> 297607.24 | Q29: =ROUND(P29*6% + P29,0) + S29 -> 315464.24 | R29: =ROUND(P29*3%,0) + P29 -> 306535.24 | S29: =S28+0.01 -> 0.24
A30: COC | B30: 8 | C30: A | D30: =D29+1 -> 25 | E30: VANNI KARINA | G30: 2.3537 | H30: 244357.25 | I30: =H30 -> 244357.25 | K30: =H30-I30 -> 0 | L30: =IF(K30>0,K30*3%,0) -> 0 | M30: 0 | N30: =P$2*G30% -> 267776.48 | O30: 0 | P30: =ROUND(SUM(K30:O30),0) + S30 -> 267776.25 | Q30: =ROUND(P30*6% + P30,0) + S30 -> 283843.25 | R30: =ROUND(P30*3%,0) + P30 -> 275809.25 | S30: =S29+0.01 -> 0.25
A31: COC | B31: 8 | C31: B | D31: =D30+1 -> 26 | E31: CARRIZO RAÚL | F31: Noelia Villarino | G31: 2.6469 | H31: 274796.26 | I31: =H31 -> 274796.26 | K31: =H31-I31 -> 0 | L31: =IF(K31>0,K31*3%,0) -> 0 | M31: 0 | N31: =P$2*G31% -> 301133.35 | O31: 0 | P31: =ROUND(SUM(K31:O31),0) + S31 -> 301133.26 | Q31: =ROUND(P31*6% + P31,0) + S31 -> 319201.26 | R31: =ROUND(P31*3%,0) + P31 -> 310167.26 | S31: =S30+0.01 -> 0.26
A32: COC | B32: 9 | C32: A | D32: =D31+1 -> 27 | E32: BLANCO | G32: 2.3537 | H32: 244357.27 | I32: =H32 -> 244357.27 | K32: =H32-I32 -> 0 | L32: =IF(K32>0,K32*3%,0) -> 0 | M32: 0 | N32: =P$2*G32% -> 267776.48 | O32: 0 | P32: =ROUND(SUM(K32:O32),0) + S32 -> 267776.27 | Q32: =ROUND(P32*6% + P32,0) + S32 -> 283843.27 | R32: =ROUND(P32*3%,0) + P32 -> 275809.27 | S32: =S31+0.01 -> 0.27
A33: COC | B33: 9 | C33: B | D33: =D32+1 -> 28 | E33: GALANTE CELIA | G33: 2.6663 | H33: 267682.28 | I33: 275712.28 | K33: =H33-I33 -> -8030 | L33: =IF(K33>0,K33*3%,0) -> 0 | M33: 0 | N33: =P$2*G33% -> 303340.46 | O33: 0 | P33: =ROUND(SUM(K33:O33),0) + S33 -> 295310.28 | Q33: =ROUND(P33*6% + P33,0) + S33 -> 313029.28 | R33: =ROUND(P33*3%,0) + P33 -> 304169.28 | S33: =S32+0.01 -> 0.28
A34: COC | B34: 10 | C34: A | D34: =D33+1 -> 29 | E34: LEGUIZAMON PABLO | F34: Carla | G34: 2.4476 | H34: 254105.29 | I34: =H34 -> 254105.29 | K34: =H34-I34 -> 0 | L34: =IF(K34>0,K34*3%,0) -> 0 | M34: 0 | N34: =P$2*G34% -> 278459.33 | O34: 0 | P34: =ROUND(SUM(K34:O34),0) + S34 -> 278459.29 | Q34: =ROUND(P34*6% + P34,0) + S34 -> 295167.29 | R34: =ROUND(P34*3%,0) + P34 -> 286813.29 | S34: =S33+0.01 -> 0.29
A35: COC | B35: 10 | C35: B | D35: =D34+1 -> 30 | E35: CANDEL E. MARCELO | G35: 2.7183 | H35: 601724.3 | I35: 619776.3 | K35: =H35-I35 -> -18052 | L35: =IF(K35>0,K35*3%,0) -> 0 | M35: 0 | N35: =P$2*G35% -> 309256.41 | O35: 0 | P35: =ROUND(SUM(K35:O35),0) + S35 -> 291204.3 | Q35: =ROUND(P35*6% + P35,0) + S35 -> 308677.3 | R35: =ROUND(P35*3%,0) + P35 -> 299940.3 | S35: =S34+0.01 -> 0.3
A36: COC | B36: 11 | C36: A | D36: =D35+1 -> 31 | E36: DAVICCA MIGUEL | F36: Romina Navarro | G36: 2.3026 | H36: 231323.31 | I36: =H36 -> 231323.31 | K36: =H36-I36 -> 0 | L36: =IF(K36>0,K36*3%,0) -> 0 | M36: 0 | N36: =P$2*G36% -> 261962.92 | O36: 0 | P36: =ROUND(SUM(K36:O36),0) + S36 -> 261963.31 | Q36: =ROUND(P36*6% + P36,0) + S36 -> 277681.31 | R36: =ROUND(P36*3%,0) + P36 -> 269822.31 | S36: =S35+0.01 -> 0.31
A37: COC | B37: 11 | C37: B | D37: =D36+1 -> 32 | E37: GUTMAN MARIO | G37: 2.6562 | H37: 376989.32 | I37: 275762.32 | K37: =H37-I37 -> 101227 | L37: =IF(K37>0,K37*3%,0) -> 3036.81 | M37: 0 | N37: =P$2*G37% -> 302191.4 | O37: 0 | P37: =ROUND(SUM(K37:O37),0) + S37 -> 406455.32 | Q37: =ROUND(P37*6% + P37,0) + S37 -> 430843.32 | R37: =ROUND(P37*3%,0) + P37 -> 418649.32 | S37: =S36+0.01 -> 0.32
A38: COC | B38: 12 | C38: A | D38: =D37+1 -> 33 | E38: PRATOLONGO EDUARDO | G38: 2.3343 | H38: 242343.33 | I38: =H38 -> 242343.33 | K38: =H38-I38 -> 0 | L38: =IF(K38>0,K38*3%,0) -> 0 | M38: 0 | N38: =P$2*G38% -> 265569.38 | O38: 0 | P38: =ROUND(SUM(K38:O38),0) + S38 -> 265569.33 | Q38: =ROUND(P38*6% + P38,0) + S38 -> 281503.33 | R38: =ROUND(P38*3%,0) + P38 -> 273536.33 | S38: =S37+0.01 -> 0.33
A39: COC | B39: 12 | C39: B | D39: =D38+1 -> 34 | E39: CARTABBIA MARIO | G39: 2.6259 | H39: 272616.34 | I39: =H39 -> 272616.34 | K39: =H39-I39 -> 0 | L39: =IF(K39>0,K39*3%,0) -> 0 | M39: 0 | N39: =P$2*G39% -> 298744.22 | O39: 0 | P39: =ROUND(SUM(K39:O39),0) + S39 -> 298744.34 | Q39: =ROUND(P39*6% + P39,0) + S39 -> 316669.34 | R39: =ROUND(P39*3%,0) + P39 -> 307706.34 | S39: =S38+0.01 -> 0.34
A40: COC | B40: 1 | C40: C | D40: =D39+1 -> 35 | E40: NAVA HECTOR | F40: Marcos | G40: 1.007 | H40: 107681.35 | I40: =104545.35 -> 104545.35 | K40: =H40-I40 -> 3136 | L40: =IF(K40>0,K40*3%,0) -> 94.08 | M40: 0 | N40: =P$2*G40% -> 114564.69 | O40: 0 | P40: =ROUND(SUM(K40:O40),0) + S40 -> 117795.35 | Q40: =ROUND(P40*6% + P40,0) + S40 -> 124863.35 | R40: =ROUND(P40*3%,0) + P40 -> 121329.35 | S40: =S39+0.01 -> 0.35
A41: COC | B41: 1 | C41: D | D41: =D40+1 -> 36 | E41: BRATTOLI | F41: Palermo Hernan | G41: 0.7812 | H41: 81103.36 | I41: =H41 -> 81103.36 | K41: =H41-I41 -> 0 | L41: =IF(K41>0,K41*3%,0) -> 0 | M41: 0 | N41: =P$2*G41% -> 88875.807 | O41: 0 | P41: =ROUND(SUM(K41:O41),0) + S41 -> 88876.36 | Q41: =ROUND(P41*6% + P41,0) + S41 -> 94209.36 | R41: =ROUND(P41*3%,0) + P41 -> 91542.36 | S41: =S40+0.01 -> 0.36 | U41: PALERMO
B42: 1 | C42: E | D42: =D41+1 -> 37 | E42: BRATTOLI | F42: Palermo Hernan | G42: 1.2153 | H42: 126170.37 | I42: =H42 -> 126170.37 | K42: =H42-I42 -> 0 | L42: =IF(K42>0,K42*3%,0) -> 0 | M42: 0 | N42: =P$2*G42% -> 138262.63 | O42: 0 | P42: =ROUND(SUM(K42:O42),0) + S42 -> 138263.37 | Q42: =ROUND(P42*6% + P42,0) + S42 -> 146559.37 | R42: =ROUND(P42*3%,0) + P42 -> 142411.37 | S42: =S41+0.01 -> 0.37 | U42: PALERMO
...
