Workbook

Sheet RESUMEN
B1: MAIL: yrigoyen7630@gmail.com
B2: CUIT ADMINISTRACION: 27231256879
B3: CBU: 0440060830000011423569 / ALIAS: OMBU.TECLEO.AMOROSAS / TELEFONO: 11 5320-2676
A4: LIQUIDACION DE EXPENSAS | B4: ADMINISTRADORA: CAROLINA CANCIANI MP:1148
A5: CUIT DEL EDIFICIO: 30-55421584-6 | B5: PERÍODO: MARZO | D5: HORARIOS DE ATENCION: LUNES A VIERNES
A6: CONSORCIO DE PROPIETARIOS DEL EDIFICIO CALLE YRIGOYEN 7630 | D6: 10 A 15HS - EMERGENCIAS 24HS
B8: VTO 17/04
A13: ESTIMADOS PROPIETARIOS E INQUILINOS: POR FAVOR LOS QUE ABONAN EN PRIMER VENCIMIENTO ABONEN EL MONTO DE PRIMER VENCIMIENTO, ASI AGILIZAN LA LIQUIDACION, RESPETEN LOS CENTAVOS CORRESPONDIENTES A LA UNIDAD FUNCIONAL. ES DE CARÁCTER OBLIGATORIO INFORMAR VIA MAIL LAS EXPENSAS. CASO CONTRARIO SE INFORMARA VIA CARTA DOCUMENTO A LA UNIDAD FUNCIONAL QUE CREEMOS QUE CORRESPONDE, CUYO COSTO SERA IMPUTADO A LA UNIDAD FUNCIONAL SOSPECHADA.
A20: GASTOS ORDINARIOS UNIDADES FUNCIONALES:
A21: HABERES ENCARGADOS
A22: Sueldo encargado Walter Fernandez | D22: 1010153
A24: Neto | D24: =SUM(D22:D23) -> 1010153
A25: Sueldo encargado Balcazza Leonardo
A29: SAC
A30: Neto | D30: =SUM(D25:D29) -> 0
A31: TOTAL SUELDO | E31: =D24+D30 -> 1010153
A32: HONORARIOS
A33: Gustavo padron - Sr contador honorarios MARZO | D33: 45000
A34: Honorarios administracion - MARZO | D34: 147300 | H34: Subidos en En3r0
A35: TOTAL | E35: =SUM(D33:D34) -> 192300
A36: SEGUROS
A37: Federacion patronal - Seguro de vida Poliza nro. 211840604 | D37: =26570+6696 -> 33266 | E37: Debito 03/02
A38: Federacion patronal Seguro obligatorio de consorcio | D38: 54278 | E38: =E37 -> Debito 03/02
A39: TOTAL IMPUESTO | E39: =SUM(D37:D38) -> 87544
A40: APORTES Y CONTRIBUCIONES
A41: ARCA | D41: 735161.05 | E41: Debito 10/02
A42: Plan de pagos ARCA | D42: 10602.27 | E42: Debito 18/02
A43: Plan de pagos ARCA | D43: 75532.29 | E43: =E42 -> Debito 18/02 | F43: =D43+D42 -> 86134.56
A44: Sindicatos mes de MARZO | D44: 107615.71 | E44: Debito 12/02
A45: =A44 -> Sindicatos mes de MARZO | D45: 6711.98 | E45: =E44 -> Debito 12/02
A46: =A45 -> Sindicatos mes de MARZO | D46: 60407.79 | E46: =E45 -> Debito 12/02
A47: TOTAL Aportes y Contribuciones - Sindicato | E47: =SUM(D41:D46) -> 996031.09
A48: ABONOS Y SERVICIOS
A49: EDESUR - Cliente nro. 1481147 | D49: 66712.05 | E49: Debito 04/02
A50: EDESUR Porteria | D50: 38354.13 | E50: Debito 04/02
A51: Metrogas Porteria | D51: 26185.98 | E51: Debito 04/02
A52: AYSA - Nro de cliente 3477073 | D52: 629889.97 | E52: Debito 10/02
A53: TOTAL ABONOS Y SERVICIOS | E53: =SUM(D49:D52) -> 761142.13
A55: Ascensores lema - Mantenimiento | D55: 85000 | E55: Transf 04/03
A56: Fumigacion | D56: 50000 | E56: Transf 08/03
...

Sheet PRORRATEO
D2: Arca plan de pagos: | F2: 86134.56 | J2: Ordinarios | L2: 3774269.2
A4: UF | B4: Propietario | C4: Inquilinos | D4: (%) | E4: Saldo Ord | F4: Ingreso | G4: Deuda o Saldo a favor | H4: Interes 3% | I4: Expensas extraor. | J4: Expensas ord. | K4: Arca plan de pagos | L4: Total 1er Vto | M4: Total 2do Vto. | N4: Total 2do Vto | Q4: 3774269.2
L5: =RESUMEN!B8 -> VTO 17/04
A6: 1 | B6: Diaz Joaquin Andres | D6: 6.69 | E6: 258261.01 | F6: =E6 -> 258261.01 | G6: =E6-F6 -> 0 | H6: =IF(G6>0,G6*3%,0) -> 0 | I6: 0 | J6: =L$2*D6/100 -> 252498.61 | K6: =F$2*D6/100 -> 5762.4021 | L6: =ROUND(SUM(G6:K6),0) + O6 -> 258261.01 | M6: =ROUND(L6*6% + L6,0) + O6 -> 273757.01 | N6: =ROUND(L6*3%,0) + L6 -> 266009.01 | O6: 0.01
A7: =A6+1 -> 2 | B7: Marquez, Miguel | D7: 5.88 | E7: 944334.02 | G7: =E7-F7 -> 944334.02 | H7: =IF(G7>0,G7*3%,0) -> 28330.021 | I7: 0 | J7: =L$2*D7% -> 221927.03 | K7: =F$2*D7/100 -> 5064.7121 | L7: =ROUND(SUM(G7:K7),0) + O7 -> 1199656 | M7: =ROUND(L7*6% + L7,0) + O7 -> 1271635 | N7: =ROUND(L7*3%,0) + L7 -> 1235646 | O7: =O6+0.01 -> 0.02
A8: =A7+1 -> 3 | B8: Matheu, Martha F. | D8: 6.65 | E8: 655089.03 | F8: =264419.03+380000.03+10670 -> 655089.06 | G8: =E8-F8 -> -0.03 | H8: =IF(G8>0,G8*3%,0) -> 0 | I8: 0 | J8: =L$2*D8% -> 250988.9 | K8: =F$2*D8/100 -> 5727.9482 | L8: =ROUND(SUM(G8:K8),0) + O8 -> 256717.03 | M8: =ROUND(L8*6% + L8,0) + O8 -> 272120.03 | N8: =ROUND(L8*3%,0) + L8 -> 264419.03 | O8: =O7+0.01 -> 0.03
A9: =A8+1 -> 4 | B9: Hernandez, Susana | D9: 6.73 | E9: 259805.04 | F9: =E9 -> 259805.04 | G9: =E9-F9 -> 0 | H9: =IF(G9>0,G9*3%,0) -> 0 | I9: 0 | J9: =L$2*D9% -> 254008.32 | K9: =F$2*D9/100 -> 5796.8559 | L9: =ROUND(SUM(G9:K9),0) + O9 -> 259805.04 | M9: =ROUND(L9*6% + L9,0) + O9 -> 275393.04 | N9: =ROUND(L9*3%,0) + L9 -> 267599.04 | O9: =O8+0.01 -> 0.04
A10: =A9+1 -> 5 | B10: Rossi, Raul Alfredo | D10: 8.04 | E10: 630064.05 | G10: =E10-F10 -> 630064.05 | H10: =IF(G10>0,G10*3%,0) -> 18901.922 | I10: 0 | J10: =L$2*D10% -> 303451.24 | K10: =F$2*D10/100 -> 6925.2186 | L10: =ROUND(SUM(G10:K10),0) + O10 -> 959342.05 | M10: =ROUND(L10*6% + L10,0) + O10 -> 1016903.1 | N10: =ROUND(L10*3%,0) + L10 -> 988122.05 | O10: =O9+0.01 -> 0.05
A11: =A10+1 -> 6 | B11: Medaglia, Amadeo Juan | D11: 4.73 | E11: 182597.06 | F11: =E11 -> 182597.06 | G11: =E11-F11 -> 0 | H11: =IF(G11>0,G11*3%,0) -> 0 | I11: 0 | J11: =L$2*D11% -> 178522.93 | K11: =F$2*D11/100 -> 4074.1647 | L11: =ROUND(SUM(G11:K11),0) + O11 -> 182597.06 | M11: =ROUND(L11*6% + L11,0) + O11 -> 193553.06 | N11: =ROUND(L11*3%,0) + L11 -> 188075.06 | O11: =O10+0.01 -> 0.06
A12: =A11+1 -> 7 | B12: Solerno, Raul Anibal | D12: 5.67 | E12: 676552.07 | G12: =E12-F12 -> 676552.07 | H12: =IF(G12>0,G12*3%,0) -> 20296.562 | I12: 0 | J12: =L$2*D12% -> 214001.06 | K12: =F$2*D12/100 -> 4883.8296 | L12: =ROUND(SUM(G12:K12),0) + O12 -> 915734.07 | M12: =ROUND(L12*6% + L12,0) + O12 -> 970678.07 | N12: =ROUND(L12*3%,0) + L12 -> 943206.07 | O12: =O11+0.01 -> 0.07
A13: =A12+1 -> 8 | B13: Cavalli, Maria | D13: 5.67 | E13: 225452.08 | F13: =E13 -> 225452.08 | G13: =E13-F13 -> 0 | H13: =IF(G13>0,G13*3%,0) -> 0 | I13: 0 | J13: =L$2*D13% -> 214001.06 | K13: =F$2*D13/100 -> 4883.8296 | L13: =ROUND(SUM(G13:K13),0) + O13 -> 218885.08 | M13: =ROUND(L13*6% + L13,0) + O13 -> 232018.08 | N13: =ROUND(L13*3%,0) + L13 -> 225452.08 | O13: =O12+0.01 -> 0.08 | Q13: CONSTANZA
A14: =A13+1 -> 9 | B14: Lencina, Suzana | D14: 7.67 | E14: 296093.09 | F14: =E14 -> 296093.09 | G14: =E14-F14 -> 0 | H14: =IF(G14>0,G14*3%,0) -> 0 | I14: 0 | J14: =L$2*D14% -> 289486.45 | K14: =F$2*D14/100 -> 6606.5208 | L14: =ROUND(SUM(G14:K14),0) + O14 -> 296093.09 | M14: =ROUND(L14*6% + L14,0) + O14 -> 313859.09 | N14: =ROUND(L14*3%,0) + L14 -> 304976.09 | O14: =O13+0.01 -> 0.09
A15: =A14+1 -> 10 | B15: Castro, Ana Maria | D15: 4.9 | E15: -181679.9 | F15: =RESUMEN!D57 -> 340000 | G15: =E15-F15 -> -521679.9 | H15: =IF(G15>0,G15*3%,0) -> 0 | I15: 0 | J15: =L$2*D15% -> 184939.19 | K15: =F$2*D15/100 -> 4220.5934 | L15: =ROUND(SUM(G15:K15),0) + O15 -> -332519.9 | M15: =ROUND(L15*6% + L15,0) + O15 -> -352470.9 | N15: =ROUND(L15*3%,0) + L15 -> -342495.9 | O15: =O14+0.01 -> 0.1
A16: =A15+1 -> 11 | B16: Penerbosa, Miguel Angel | D16: 5.63 | E16: 217341.11 | F16: =E16 -> 217341.11 | G16: =E16-F16 -> 0 | H16: =IF(G16>0,G16*3%,0) -> 0 | I16: 0 | J16: =L$2*D16% -> 212491.35 | K16: =F$2*D16/100 -> 4849.3757 | L16: =ROUND(SUM(G16:K16),0) + O16 -> 217341.11 | M16: =ROUND(L16*6% + L16,0) + O16 -> 230382.11 | N16: =ROUND(L16*3%,0) + L16 -> 223861.11 | O16: =O15+0.01 -> 0.11
A17: =A16+1 -> 12 | B17: Smietniansky, Laura | D17: 5.55 | E17: 214252.12 | F17: =E17 -> 214252.12 | G17: =E17-F17 -> 0 | H17: =IF(G17>0,G17*3%,0) -> 0 | I17: 0 | J17: =L$2*D17% -> 209471.94 | K17: =F$2*D17/100 -> 4780.4681 | L17: =ROUND(SUM(G17:K17),0) + O17 -> 214252.12 | M17: =ROUND(L17*6% + L17,0) + O17 -> 227107.12 | N17: =ROUND(L17*3%,0) + L17 -> 220680.12 | O17: =O16+0.01 -> 0.12
A18: =A17+1 -> 13 | B18: Llobera, Fernando | D18: 11.06 | E18: 426961.13 | F18: =E18 -> 426961.13 | G18: =E18-F18 -> 0 | H18: =IF(G18>0,G18*3%,0) -> 0 | I18: 0 | J18: =L$2*D18% -> 417434.17 | K18: =F$2*D18/100 -> 9526.4823 | L18: =ROUND(SUM(G18:K18),0) + O18 -> 426961.13 | M18: =ROUND(L18*6% + L18,0) + O18 -> 452579.13 | N18: =ROUND(L18*3%,0) + L18 -> 439770.13 | O18: =O17+0.01 -> 0.13
A19: =A18+1 -> 14 | B19: Stancati, Victor Dario | D19: 3.3 | E19: 871372.14 | G19: =E19-F19 -> 871372.14 | H19: =IF(G19>0,G19*3%,0) -> 26141.164 | I19: 0 | J19: =L$2*D19% -> 124550.88 | K19: =F$2*D19/100 -> 2842.4405 | L19: =ROUND(SUM(G19:K19),0) + O19 -> 1024907.1 | M19: =ROUND(L19*6% + L19,0) + O19 -> 1086402.1 | N19: =ROUND(L19*3%,0) + L19 -> 1055654.1 | O19: =O18+0.01 -> 0.14
A20: =A19+1 -> 15 | B20: Russo, Mabel | D20: 1.8 | E20: =4170+65317.15 -> 69487.15 | F20: =59233+10253.82 -> 69486.82 | G20: =E20-F20 -> 0.33 | H20: =IF(G20>0,G20*3%,0) -> 0.0099 | I20: 0 | J20: =L$2*D20% -> 67936.845 | K20: =F$2*D20/100 -> 1550.4221 | L20: =ROUND(SUM(G20:K20),0) + O20 -> 69488.15 | M20: =ROUND(L20*6% + L20,0) + O20 -> 73657.15 | N20: =ROUND(L20*3%,0) + L20 -> 71573.15 | O20: =O19+0.01 -> 0.15 | P20: cristina - su inquilino es gustavo almeyda
A21: =A20+1 -> 16 | B21: Gamboa, Ana Cecilia | D21: 3.22 | E21: 124305.16 | F21: =E21 -> 124305.16 | G21: =E21-F21 -> 0 | H21: =IF(G21>0,G21*3%,0) -> 0 | I21: 0 | J21: =L$2*D21% -> 121531.47 | K21: =F$2*D21/100 -> 2773.5328 | L21: =ROUND(SUM(G21:K21),0) + O21 -> 124305.16 | M21: =ROUND(L21*6% + L21,0) + O21 -> 131763.16 | N21: =ROUND(L21*3%,0) + L21 -> 128034.16 | O21: =O20+0.01 -> 0.16 | P21: EL EX INQUILINO DE CRISTINA (UF 15) PAGO EN FEBRERO CUANDO YA NO ESTABA MAS, SEGURO SE CONFUNDIO DE CUENTA A LA QUE DEBIA TRANSFERIR. ABONO $124.551. ESE PAGO NO LO COMPUTAMOS, SOLO LO DEJAMOS ASENTADO ACA
A22: =A21+1 -> 17 | B22: Rodriguez, Stella Maris | D22: 2.61 | E22: 421529.17 | F22: 0 | G22: =E22-F22 -> 421529.17 | H22: =IF(G22>0,G22*3%,0) -> 12645.875 | I22: 0 | J22: =L$2*D22% -> 98508.425 | K22: =F$2*D22/100 -> 2248.112 | L22: =ROUND(SUM(G22:K22),0) + O22 -> 534932.17 | M22: =ROUND(L22*6% + L22,0) + O22 -> 567028.17 | N22: =ROUND(L22*3%,0) + L22 -> 550980.17 | O22: =O21+0.01 -> 0.17
A23: =A22+1 -> 18 | B23: Sieira, Leonardo | D23: 4.28 | E23: 165225.18 | F23: =E23 -> 165225.18 | G23: =E23-F23 -> 0 | H23: =IF(G23>0,G23*3%,0) -> 0 | I23: 0 | J23: =L$2*D23% -> 161538.72 | K23: =F$2*D23/100 -> 3686.5592 | L23: =ROUND(SUM(G23:K23),0) + O23 -> 165225.18 | M23: =ROUND(L23*6% + L23,0) + O23 -> 175139.18 | N23: =ROUND(L23*3%,0) + L23 -> 170182.18 | O23: =O22+0.01 -> 0.18
O24: =O23+0.01 -> 0.19
D29: =SUM(D6:D28) -> 100.08 | E29: =SUM(E6:E28) -> 6457040.7 | F29: =SUM(F6:F28) -> 3434868.9 | G29: =SUM(G6:G28) -> 3022171.9 | H29: =SUM(H6:H28) -> 106315.55 | I29: =SUM(I6:I28) -> 0 | J29: =SUM(J6:J28) -> 3777288.6 | K29: =SUM(K6:K28) -> 86203.468 | L29: =SUM(L6:L23) -> 6991982.7 | M29: =SUM(M6:M28) -> 7411503.7 | N29: =SUM(N6:N28) -> 7201743.7
B32: =RESUMEN!A13 -> ESTIMADOS PROPIETARIOS E INQUILINOS: POR FAVOR LOS QUE ABONAN EN PRIMER VENCIMIENTO ABONEN EL MONTO DE PRIMER VENCIMIENTO, ASI AGILIZAN LA LIQUIDACION, RESPETEN LOS CENTAVOS CORRESPONDIENTES A LA UNIDAD FUNCIONAL. ES DE CARÁCTER OBLIGATORIO INFORMAR VIA MAIL LAS EXPENSAS. CASO CONTRARIO SE INFORMARA VIA CARTA DOCUMENTO A LA UNIDAD FUNCIONAL QUE CREEMOS QUE CORRESPONDE, CUYO COSTO SERA IMPUTADO A LA UNIDAD FUNCIONAL SOSPECHADA.

Sheet ANOTACIONES
C8: El departamento 7 adjunta un monton de comprobantes desde el mail de (mer_paisa@hotmail.com) antiguos para que reveamos su deuda. Chequear y revisar.
