Workbook

Sheet RESUMEN
B1: MAIL: salta1167rc@gmail.com
B2: CUIT ADMINISTRACION: 27231256879
B3: CONSORCIO DE PROPIETARIOS EDIFICIO CALLE SALTA 1167/1169 C DE P SALTA 1167 1169 LANUS CTA CTE $ 039 - 22273/6 CBU: 0720039720000002227368
A4: LIQUIDACION DE EXPENSAS | B4: ADMINISTRADORA: CAROLINA CANCIANI MP:1148
A5: CUIT DEL EDIFICIO: 30-719118061-9 | B5: PERÍODO: JULIO | D5: HORARIOS DE ATENCION: LUNES A VIERNES
A6: CONSORCIO DE PROPIETARIOS DEL EDIFICIO CALLE SALTA 1167 | D6: 10 A 15HS - EMERGENCIAS 24HS
B8: VTO 17/08
A13: ESTIMADOS PROPIETARIOS E INQUILINOS: POR FAVOR LOS QUE ABONAN EN PRIMER VENCIMIENTO ABONEN EL MONTO DE PRIMER VENCIMIENTO, ASI AGILIZAN LA LIQUIDACION, RESPETEN LOS CENTAVOS CORRESPONDIENTES A LA UNIDAD FUNCIONAL. ES DE CARÁCTER OBLIGATORIO INFORMAR VIA MAIL LAS EXPENSAS. PORFAVOR RESPETAR LOS CENTAVOS AL ABONAR.
A20: GASTOS A - UNIDADES FUNCIONALES:
A21: LIMPIEZA
A22: Full Clean - Servicio de limpieza | D22: 510846.85 | E22: Transf 07/07
A24: TOTAL | E24: =SUM(D22:D23) -> 510846.85
A25: SEGUROS
A26: Federacion patronal Seguro obligatorio de consorcio - Poliza nro. 1-2249124-0 | D26: 79864 | E26: Transf 06/07
A27: TOTAL IMPUESTO | E27: =SUM(D26:D26) -> 79864
A28: ABONOS Y SERVICIOS
A29: Edesur | D29: 162387.66 | E29: Transf 23/07
A30: Metrogas | D30: 7090.36 | E30: =E31 -> Transf 06/07
A31: Metrogas | D31: 482288.43 | E31: Transf 06/07
A32: AySa | D32: 632390 | E32: Transf 06/07
A33: Servicio de interet Claro | D33: 27338.01 | E33: Transf 06/07
A34: TOTAL ABONOS Y SERVICIOS | E34: =SUM(D29:D33) -> 1311494.5
A36: Lema - Ascensores - Servicio de mantenimiento - Se abona a mes vencido | D36: 82000 | E36: Transf 10/07
A37: Megasec - Compra de matafuegos - Cuota 1/2 | D37: =199530 -> 199530 | E37: Transf 13/07
A38: GrupoProtect - Compra de matafuego | D38: 72635 | E38: Transf 27/07
A39: Easy Barracas - Compra de termotanque - Cuota 5 - Resta 1 cuotas de $157.988,29 | D39: 157988.29
A40: Compra de pilas - Puerta SUM | D40: 8000 | E40: Efectivo
A41: TOTAL | E41: =SUM(D36:D40) -> 520153.29
A42: HONORARIOS
A43: Honorario administracion - Mes de JULIO | D43: 190000 | E43: Transf 30/07
A44: TOTAL | E44: =SUM(D43:D43) -> 190000
A45: GASTOS BANCARIOS
A46: Mantenimiento de cuenta - Bonificacion bancaria | D46: 0
A47: Gastos bancarios | D47: 44926.11
A48: TOTAL | E48: =SUM(D46:D47) -> 44926.11
A50: PREVISION GASTOS A
A52: TOTAL GASTOS A | E52: =(SUM(E21:E50)) -> 2657284.7
A55: GASTOS B:
E60: =SUM(D56:D59) -> 0
A63: PREVISION GASTOS B
...

Sheet PRORRATEO
E2: Gastos B | G2: 0 | J2: Gastos A | K2: 2700000
A4: Estimados convivientes: Les solicitamos, por favor, que al momento de realizar el pago respeten los centavos que figuran en el monto indicado, ya que estos nos permiten identificar correctamente los pagos y las unidades funcionales, reduciendo así el margen de error. Muchas gracias por su colaboración.
A9: REITERAMOS QUE LOS DATOS DE LA CUENTA EN DONDE DEBEN ABONAR LAS EXPENSAS SON: CONSORCIO DE PROPIETARIOS EDIFICIO CALLE SALTA 1167/1169 - C DE P SALTA 1167 1169 LANUS - CTA CTE $ 039 - 22273/6 CBU: 0720039720000002227368
A10: QUIENES ESTAN EN VIOLETA NO ESTAN RESPETANDO LOS CENTAVOS AL ABONAR.
A11: UF | C11: Propietario | D11: Inquilinos | E11: (%) | F11: Saldo Ord | G11: Ingreso | H11: Deuda o Saldo a favor | I11: Interes 3% | J11: Gastos A | K11: Gastos B | L11: EDESUR | M11: SUM | N11: Total 1er Vto | O11: Total 2do Vto. | P11: Total 2do Vto
N12: =RESUMEN!B8 -> VTO 17/08
A13: 1 | B13: 1 A | C13: MIRAGLIA NORBERTO JOSE | E13: 12 | F13: 324000.01 | G13: =356868.01-G29-G30 -> 324009.66 | H13: =F13-G13 -> -9.65 | I13: =IF(H13>0,H13*3%,0) -> 0 | J13: =K$2*E13/100 -> 324000 | K13: =G$2*E13/100 -> 0 | L13: =EDESUR!K3 -> 29460.827 | N13: =ROUND(SUM(H13:M13),0) + Q13 -> 353451.01 | O13: =ROUND(N13*6% + N13,0) + Q13 -> 374658.01 | P13: =ROUND(N13*3%,0) + N13 -> 364055.01 | Q13: 0.01
A14: 2 | B14: 1 C | C14: ADAMO PABLO MARIANO | E14: 6.6 | F14: 280517.02 | G14: 281000 | H14: =F14-G14 -> -482.98 | I14: =IF(H14>0,H14*3%,0) -> 0 | J14: =K$2*E14/100 -> 178200 | K14: =G$2*E14/100 -> 0 | L14: =EDESUR!K4 -> 149105.46 | N14: =ROUND(SUM(H14:M14),0) + Q14 -> 326822.02 | O14: =ROUND(N14*6% + N14,0) + Q14 -> 346431.02 | P14: =ROUND(N14*3%,0) + N14 -> 336627.02 | Q14: =Q13+0.01 -> 0.02
A15: 3 | B15: 1 D | C15: REDONDO | D15: Gilmer | E15: 5.4 | F15: 149456.03 | G15: =F15 -> 149456.03 | H15: =F15-G15 -> 0 | I15: =IF(H15>0,H15*3%,0) -> 0 | J15: =K$2*E15/100 -> 145800 | K15: =G$2*E15/100 -> 0 | L15: =EDESUR!K5 -> 13257.372 | N15: =ROUND(SUM(H15:M15),0) + Q15 -> 159057.03 | O15: =ROUND(N15*6% + N15,0) + Q15 -> 168600.03 | P15: =ROUND(N15*3%,0) + N15 -> 163829.03 | Q15: =Q14+0.01 -> 0.03
A16: 4 | B16: 2 B | C16: CRUZ ADRIANA BEATRIZ | D16: Cristian Rodrigo Centurion | E16: 6.6 | F16: 172600.04 | G16: =189033-G32 -> 172603.8 | H16: =F16-G16 -> -3.76 | I16: =IF(H16>0,H16*3%,0) -> 0 | J16: =K$2*E16/100 -> 178200 | K16: =G$2*E16/100 -> 0 | L16: =EDESUR!K7 -> 16203.455 | N16: =ROUND(SUM(H16:M16),0) + Q16 -> 194400.04 | O16: =ROUND(N16*6% + N16,0) + Q16 -> 206064.04 | P16: =ROUND(N16*3%,0) + N16 -> 200232.04 | Q16: =Q15+0.01 -> 0.04
A17: 5 | B17: 2 C | C17: D AMURI JOSE LUIS | D17: Martina Belen Carbone | E17: 6.6 | F17: 178200.05 | G17: =F17 -> 178200.05 | H17: =F17-G17 -> 0 | I17: =IF(H17>0,H17*3%,0) -> 0 | J17: =K$2*E17/100 -> 178200 | K17: =G$2*E17/100 -> 0 | L17: =EDESUR!K8 -> 16203.455 | M17: 0 | N17: =ROUND(SUM(H17:M17),0) + Q17 -> 194403.05 | O17: =ROUND(N17*6% + N17,0) + Q17 -> 206067.05 | P17: =ROUND(N17*3%,0) + N17 -> 200235.05 | Q17: =Q16+0.01 -> 0.05 | R17: Alejo Moreno
A18: 6 | B18: 2 D | C18: CAMPOLONGO LUIS | D18: Leandro Gonzalez | E18: 5.4 | F18: 156924.06 | G18: 129600.06 | H18: =F18-G18 -> 27324 | I18: =IF(H18>0,H18*3%,0) -> 819.72 | J18: =K$2*E18/100 -> 145800 | K18: =G$2*E18/100 -> 0 | L18: =EDESUR!K9 -> 13257.372 | N18: =ROUND(SUM(H18:M18),0) + Q18 -> 187201.06 | O18: =ROUND(N18*6% + N18,0) + Q18 -> 198433.06 | P18: =ROUND(N18*3%,0) + N18 -> 192817.06 | Q18: =Q17+0.01 -> 0.06
A19: 7 | B19: 2 A | C19: PEREZ FERNANDO ARIEL | D19: Gaston Miranda | E19: 5.4 | F19: 279288.07 | G19: =F19 -> 279288.07 | H19: =F19-G19 -> 0 | I19: =IF(H19>0,H19*3%,0) -> 0 | J19: =K$2*E19/100 -> 145800 | K19: =G$2*E19/100 -> 0 | L19: =EDESUR!K6 -> 13257.372 | N19: =ROUND(SUM(H19:M19),0) + Q19 -> 159057.07 | O19: =ROUND(N19*6% + N19,0) + Q19 -> 168600.07 | P19: =ROUND(N19*3%,0) + N19 -> 163829.07 | Q19: =Q18+0.01 -> 0.07
A20: 8 | B20: 3 B | C20: BURGOA CARINA | D20: Alan/Ailen | E20: 6.6 | F20: 248675.08 | G20: =F20 -> 248675.08 | H20: =F20-G20 -> 0 | I20: =IF(H20>0,H20*3%,0) -> 0 | J20: =K$2*E20/100 -> 178200 | K20: =G$2*E20/100 -> 0 | L20: =EDESUR!K11 -> 80448.249 | N20: =ROUND(SUM(H20:M20),0) + Q20 -> 258648.08 | O20: =ROUND(N20*6% + N20,0) + Q20 -> 274167.08 | P20: =ROUND(N20*3%,0) + N20 -> 266407.08 | Q20: =Q19+0.01 -> 0.08
A21: 9 | B21: 3 C | C21: GIL ROSANNA MABEL | D21: Gaston ibarra | E21: 6.6 | F21: 199813.09 | G21: =F21+12187.9 -> 212000.99 | H21: =F21-G21 -> -12187.9 | I21: =IF(H21>0,H21*3%,0) -> 0 | J21: =K$2*E21/100 -> 178200 | K21: =G$2*E21/100 -> 0 | L21: =EDESUR!K12 -> 16203.455 | M21: 0 | N21: =ROUND(SUM(H21:M21),0) + Q21 -> 182216.09 | O21: =ROUND(N21*6% + N21,0) + Q21 -> 193149.09 | P21: =ROUND(N21*3%,0) + N21 -> 187682.09 | Q21: =Q20+0.01 -> 0.09
A22: 10 | B22: 3 D | C22: FELIX ALBERTO | D22: Jhonatan | E22: 5.4 | F22: 16198.1 | G22: =RESUMEN!D39+16198.1-12187.9 -> 161998.49 | H22: =F22-G22 -> -145800.39 | I22: =IF(H22>0,H22*3%,0) -> 0 | J22: =K$2*E22/100 -> 145800 | K22: =G$2*E22/100 -> 0 | L22: =EDESUR!K13 -> 13257.372 | N22: =ROUND(SUM(H22:M22),0) + Q22 -> 13257.1 | O22: =ROUND(N22*6% + N22,0) + Q22 -> 14053.1 | P22: =ROUND(N22*3%,0) + N22 -> 13655.1 | Q22: =Q21+0.01 -> 0.1
A23: 11 | B23: 3 A | C23: CAMPANA WALTER CESAR | E23: 5.4 | F23: 145800.11 | G23: =154014.33-G34 -> 145800.11 | H23: =F23-G23 -> 0 | I23: =IF(H23>0,H23*3%,0) -> 0 | J23: =K$2*E23/100 -> 145800 | K23: =G$2*E23/100 -> 0 | L23: =EDESUR!K10 -> 13257.372 | N23: =ROUND(SUM(H23:M23),0) + Q23 -> 159057.11 | O23: =ROUND(N23*6% + N23,0) + Q23 -> 168601.11 | P23: =ROUND(N23*3%,0) + N23 -> 163829.11 | Q23: =Q22+0.01 -> 0.11 | R23: Antonella
A24: 12 | B24: 4 B | C24: PALMA JOSE AGUSTIN | D24: Juan Ignacio / Mariel Cruz | E24: 6.6 | F24: 178200.12 | G24: =F24 -> 178200.12 | H24: =F24-G24 -> 0 | I24: =IF(H24>0,H24*3%,0) -> 0 | J24: =K$2*E24/100 -> 178200 | K24: =G$2*E24/100 -> 0 | L24: =EDESUR!K15 -> 16203.455 | N24: =ROUND(SUM(H24:M24),0) + Q24 -> 194403.12 | O24: =ROUND(N24*6% + N24,0) + Q24 -> 206067.12 | P24: =ROUND(N24*3%,0) + N24 -> 200235.12 | Q24: =Q23+0.01 -> 0.12
A25: 13 | B25: 4 C | C25: BENITEZ EMILIA ISABEL | D25: Daniel Leiva | E25: 6.6 | F25: 173579.13 | G25: =F25 -> 173579.13 | H25: =F25-G25 -> 0 | I25: =IF(H25>0,H25*3%,0) -> 0 | J25: =K$2*E25/100 -> 178200 | K25: =G$2*E25/100 -> 0 | L25: =EDESUR!K16 -> 16203.455 | N25: =ROUND(SUM(H25:M25),0) + Q25 -> 194403.13 | O25: =ROUND(N25*6% + N25,0) + Q25 -> 206067.13 | P25: =ROUND(N25*3%,0) + N25 -> 200235.13 | Q25: =Q24+0.01 -> 0.13
A26: 14 | B26: 4 D | C26: PUCHETA SANTIAGO / CLARA | E26: 5.4 | F26: 150174.14 | G26: 150174.14 | H26: =F26-G26 -> 0 | I26: =IF(H26>0,H26*3%,0) -> 0 | J26: =K$2*E26/100 -> 145800 | K26: =G$2*E26/100 -> 0 | L26: =EDESUR!K17 -> 13257.372 | N26: =ROUND(SUM(H26:M26),0) + Q26 -> 159057.14 | O26: =ROUND(N26*6% + N26,0) + Q26 -> 168601.14 | P26: =ROUND(N26*3%,0) + N26 -> 163829.14 | Q26: =Q25+0.01 -> 0.14
A27: 15 | B27: 4 A | C27: CAMPANA MIRIAM NOEMI | E27: 5.4 | F27: 145800.15 | G27: =F27 -> 145800.15 | H27: =F27-G27 -> 0 | I27: =IF(H27>0,H27*3%,0) -> 0 | J27: =K$2*E27/100 -> 145800 | K27: =G$2*E27/100 -> 0 | L27: =EDESUR!K14 -> 13257.372 | N27: =ROUND(SUM(H27:M27),0) + Q27 -> 159057.15 | O27: =ROUND(N27*6% + N27,0) + Q27 -> 168601.15 | P27: =ROUND(N27*3%,0) + N27 -> 163829.15 | Q27: =Q26+0.01 -> 0.15
A28: 16 | B28: COC 1 | C28: CAMPOLONGO LUIS | D28: Leandro Gonzalez | E28: 0.7 | F28: 20609.16 | G28: 16800.16 | H28: =F28-G28 -> 3809 | I28: =IF(H28>0,H28*3%,0) -> 114.27 | J28: =K$2*E28/100 -> 18900 | K28: =G$2*E28/100 -> 0 | L28: =EDESUR!K20 -> 1718.5482 | N28: =ROUND(SUM(H28:M28),0) + Q28 -> 24542.16 | O28: =ROUND(N28*6% + N28,0) + Q28 -> 26015.16 | P28: =ROUND(N28*3%,0) + N28 -> 25278.16 | Q28: =Q27+0.01 -> 0.16
A29: 17 | B29: COC 2 | C29: MIRAGLIA NORBERTO JOSE | E29: 0.6 | F29: 16429.17 | G29: =F29 -> 16429.17 | H29: =F29-G29 -> 0 | I29: =IF(H29>0,H29*3%,0) -> 0 | J29: =K$2*E29/100 -> 16200 | K29: =G$2*E29/100 -> 0 | L29: =EDESUR!K21 -> 1473.0413 | N29: =ROUND(SUM(H29:M29),0) + Q29 -> 17673.17 | O29: =ROUND(N29*6% + N29,0) + Q29 -> 18734.17 | P29: =ROUND(N29*3%,0) + N29 -> 18203.17 | Q29: =Q28+0.01 -> 0.17
A30: 18 | B30: COC 3 | C30: MIRAGLIA NORBERTO JOSE | E30: 0.6 | F30: 16429.18 | G30: =F30 -> 16429.18 | H30: =F30-G30 -> 0 | I30: =IF(H30>0,H30*3%,0) -> 0 | J30: =K$2*E30/100 -> 16200 | K30: =G$2*E30/100 -> 0 | L30: =EDESUR!K22 -> 1473.0413 | N30: =ROUND(SUM(H30:M30),0) + Q30 -> 17673.18 | O30: =ROUND(N30*6% + N30,0) + Q30 -> 18734.18 | P30: =ROUND(N30*3%,0) + N30 -> 18203.18 | Q30: =Q29+0.01 -> 0.18
A31: 19 | B31: COC 4 | C31: PALMA JOSE AGUSTIN | E31: 0.6 | F31: 16429.19 | G31: =F31 -> 16429.19 | H31: =F31-G31 -> 0 | I31: =IF(H31>0,H31*3%,0) -> 0 | J31: =K$2*E31/100 -> 16200 | K31: =G$2*E31/100 -> 0 | L31: =EDESUR!K23 -> 1473.0413 | N31: =ROUND(SUM(H31:M31),0) + Q31 -> 17673.19 | P31: =ROUND(N31*3%,0) + N31 -> 18203.19 | Q31: =Q30+0.01 -> 0.19
A32: 20 | B32: COC 5 | C32: CRUZ ADRIANA BEATRIZ | D32: Cristian Rodrigo Centurion | E32: 0.6 | F32: 16429.2 | G32: =F32 -> 16429.2 | H32: =F32-G32 -> 0 | I32: =IF(H32>0,H32*3%,0) -> 0 | J32: =K$2*E32/100 -> 16200 | K32: =G$2*E32/100 -> 0 | L32: =EDESUR!K24 -> 1473.0413 | N32: =ROUND(SUM(H32:M32),0) + Q32 -> 17673.2 | P32: =ROUND(N32*3%,0) + N32 -> 18203.2 | Q32: =Q31+0.01 -> 0.2
A33: 21 | B33: COC 6 | C33: FELIX ALBERTO | D33: Jhonatan | E33: 0.3 | F33: 8214.21 | G33: =F33 -> 8214.21 | H33: =F33-G33 -> 0 | I33: =IF(H33>0,H33*3%,0) -> 0 | J33: =K$2*E33/100 -> 8100 | K33: =G$2*E33/100 -> 0 | L33: =EDESUR!K25 -> 736.52067 | N33: =ROUND(SUM(H33:M33),0) + Q33 -> 8837.21 | P33: =ROUND(N33*3%,0) + N33 -> 9102.21 | Q33: =Q32+0.01 -> 0.21
A34: 22 | B34: COC 7 | C34: CAMPANA WALTER CESAR | E34: 0.3 | F34: 8214.22 | G34: =F34 -> 8214.22 | H34: =F34-G34 -> 0 | I34: =IF(H34>0,H34*3%,0) -> 0 | J34: =K$2*E34/100 -> 8100 | K34: =G$2*E34/100 -> 0 | L34: =EDESUR!K26 -> 736.52067 | N34: =ROUND(SUM(H34:M34),0) + Q34 -> 8837.22 | P34: =ROUND(N34*3%,0) + N34 -> 9102.22 | Q34: =Q33+0.01 -> 0.22
A35: 23 | B35: COC 8 | C35: REDONDO HECTOR | D35: Gilmer | E35: 0.3 | F35: 8214.23 | G35: =F35 -> 8214.23 | H35: =F35-G35 -> 0 | I35: =IF(H35>0,H35*3%,0) -> 0 | J35: =K$2*E35/100 -> 8100 | K35: =G$2*E35/100 -> 0 | L35: =EDESUR!K27 -> 736.52067 | N35: =ROUND(SUM(H35:M35),0) + Q35 -> 8837.23 | P35: =ROUND(N35*3%,0) + N35 -> 9102.23 | Q35: =Q34+0.01 -> 0.23
E36: =SUM(E13:E35) -> 100 | F36: =SUM(F13:F35) -> 2910193.8 | G36: =SUM(G13:G35) -> 3037545.4 | H36: =SUM(H13:H35) -> -127351.68 | I36: =SUM(I13:I35) -> 933.99 | J36: =SUM(J13:J35) -> 2700000 | K36: =SUM(K13:K35) -> 0 | L36: =SUM(L13:L35) -> 442653.69 | N36: =SUM(N13:N35) -> 3016236.8 | O36: =SUM(O13:O35) -> 3131643.7 | P36: =SUM(P13:P35) -> 3106723.8
C39: =RESUMEN!A13 -> ESTIMADOS PROPIETARIOS E INQUILINOS: POR FAVOR LOS QUE ABONAN EN PRIMER VENCIMIENTO ABONEN EL MONTO DE PRIMER VENCIMIENTO, ASI AGILIZAN LA LIQUIDACION, RESPETEN LOS CENTAVOS CORRESPONDIENTES A LA UNIDAD FUNCIONAL. ES DE CARÁCTER OBLIGATORIO INFORMAR VIA MAIL LAS EXPENSAS. PORFAVOR RESPETAR LOS CENTAVOS AL ABONAR.

Sheet Anotaciones
C3: A gaston le doble cobramos un sum erroneamente el mes pasado, corregir en agosto - Debe abonar 132.216,09 , pago 182.216,09

Sheet EDESUR
B2: Piso | C2: Depto | D2: 26/052026 | E2: 25/062026 | F2: Consumo Kw | G2: % Consumido | H2: Consumo x Dep | J2: Cons Esp Com | K2: Total x Depto
B3: 1 | C3: A | D3: 8687.5 | E3: 8687.5 | F3: =(E3-D3) -> 0 | G3: =F3/F32 -> 0 | H3: =(F3/F32)*H32 -> 0 | I3: 0.12 | J3: =H34*I3 -> 29460.827 | K3: =H3+J3 -> 29460.827
B4: 1 | C4: C | D4: 4488.6 | E4: 4865.1 | F4: =(E4-D4) -> 376.5 | G4: =F4/F32 -> 0.67412713 | H4: =(F4/F32)*H32 -> 132902.01 | I4: 0.066 | J4: =H34*I4 -> 16203.455 | K4: =H4+J4 -> 149105.46
B5: 1 | C5: D | D5: 2366.38 | E5: 2366.38 | F5: =(E5-D5) -> 0 | G5: =F5/F32 -> 0 | H5: =(F5/F32)*H32 -> 0 | I5: 0.054 | J5: =H34*I5 -> 13257.372 | K5: =H5+J5 -> 13257.372
B6: 2 | C6: A | D6: 3731.1 | E6: 3731.1 | F6: =(E6-D6) -> 0 | G6: =F6/F32 -> 0 | H6: =(F6/F32)*H32 -> 0 | I6: 0.054 | J6: =H34*I6 -> 13257.372 | K6: =H6+J6 -> 13257.372
B7: 2 | C7: B | D7: 3897.7 | E7: 3897.7 | F7: =(E7-D7) -> 0 | G7: =F7/F32 -> 0 | H7: =(F7/F32)*H32 -> 0 | I7: 0.066 | J7: =H34*I7 -> 16203.455 | K7: =H7+J7 -> 16203.455
B8: 2 | C8: C | D8: 2956.2 | E8: 2956.2 | F8: =(E8-D8) -> 0 | G8: =F8/F32 -> 0 | H8: =(F8/F32)*H32 -> 0 | I8: 0.066 | J8: =H34*I8 -> 16203.455 | K8: =H8+J8 -> 16203.455
B9: 2 | C9: D | D9: 3923.7 | E9: 3923.7 | F9: =(E9-D9) -> 0 | G9: =F9/F32 -> 0 | H9: =(F9/F32)*H32 -> 0 | I9: 0.054 | J9: =H34*I9 -> 13257.372 | K9: =H9+J9 -> 13257.372
B10: 3 | C10: A | D10: 2881.8 | E10: 2881.8 | F10: =(E10-D10) -> 0 | G10: =F10/F32 -> 0 | H10: =(F10/F32)*H32 -> 0 | I10: 0.054 | J10: =H34*I10 -> 13257.372 | K10: =H10+J10 -> 13257.372
B11: 3 | C11: B | D11: 4646 | E11: 4828 | F11: =(E11-D11) -> 182 | G11: =F11/F32 -> 0.32587287 | H11: =(F11/F32)*H32 -> 64244.794 | I11: 0.066 | J11: =H34*I11 -> 16203.455 | K11: =H11+J11 -> 80448.249
B12: 3 | C12: C | D12: 4554.6 | E12: 4554.6 | F12: =(E12-D12) -> 0 | G12: =F12/F32 -> 0 | H12: =(F12/F32)*H32 -> 0 | I12: 0.066 | J12: =H34*I12 -> 16203.455 | K12: =H12+J12 -> 16203.455
B13: 3 | C13: D | D13: 4138.6 | E13: 4138.6 | F13: =(E13-D13) -> 0 | G13: =F13/F32 -> 0 | H13: =(F13/F32)*H32 -> 0 | I13: 0.054 | J13: =H34*I13 -> 13257.372 | K13: =H13+J13 -> 13257.372
B14: 4 | C14: A | D14: 8190.4 | E14: 8190.4 | F14: =(E14-D14) -> 0 | G14: =F14/F32 -> 0 | H14: =(F14/F32)*H32 -> 0 | I14: 0.054 | J14: =H34*I14 -> 13257.372 | K14: =H14+J14 -> 13257.372
B15: 4 | C15: B | D15: 3475.3 | E15: 3475.3 | F15: =(E15-D15) -> 0 | G15: =F15/F32 -> 0 | H15: =(F15/F32)*H32 -> 0 | I15: 0.066 | J15: =H34*I15 -> 16203.455 | K15: =H15+J15 -> 16203.455
B16: 4 | C16: C | D16: 4363.3 | E16: 4363.3 | F16: =(E16-D16) -> 0 | G16: =F16/F32 -> 0 | H16: =(F16/F32)*H32 -> 0 | I16: 0.066 | J16: =H34*I16 -> 16203.455 | K16: =H16+J16 -> 16203.455
B17: 4 | C17: D | D17: 6036.6 | E17: 6036.6 | F17: =(E17-D17) -> 0 | G17: =F17/F32 -> 0 | H17: =(F17/F32)*H32 -> 0 | I17: 0.054 | J17: =H34*I17 -> 13257.372 | K17: =H17+J17 -> 13257.372
F18: =SUM(F3:F17) -> 558.5 | G18: Cons Deptos | H18: =SUM(H3:H17) -> 197146.8 | J18: =SUM(J3:J17) -> 235686.62 | K18: =H18+J18 -> 432833.41
K19: =H19+J19 -> 0
B20: Cochera | C20: 1 | I20: 0.007 | J20: =H34*I20 -> 1718.5482 | K20: =H20+J20 -> 1718.5482
B21: Cochera | C21: 2 | I21: 0.006 | J21: =H34*I21 -> 1473.0413 | K21: =H21+J21 -> 1473.0413
B22: Cochera | C22: 3 | I22: 0.006 | J22: =H34*I22 -> 1473.0413 | K22: =H22+J22 -> 1473.0413
B23: Cochera | C23: 4 | I23: 0.006 | J23: =H34*I23 -> 1473.0413 | K23: =H23+J23 -> 1473.0413
B24: Cochera | C24: 5 | I24: 0.006 | J24: =H34*I24 -> 1473.0413 | K24: =H24+J24 -> 1473.0413
B25: Cochera | C25: 6 | I25: 0.003 | J25: =H34*I25 -> 736.52067 | K25: =H25+J25 -> 736.52067
B26: Cochera | C26: 7 | I26: 0.003 | J26: =H34*I26 -> 736.52067 | K26: =H26+J26 -> 736.52067
B27: Cochera | C27: 8 | I27: 0.003 | J27: =H34*I27 -> 736.52067 | K27: =H27+J27 -> 736.52067
I28: Cons Coch | J28: =SUM(J20:J27) -> 9820.2756 | K28: =H28+J28 -> 9820.2756
D30: Total Consumo s/Edesur | F30: 1254 | G30: Total x cons Edesur | H30: 442653.69 | K30: =K18+K28 -> 442653.69
D32: Total Consumo Medidores | F32: =SUM(F3:F17) -> 558.5 | G32: Cons Deptos | H32: =H30-H34 -> 197146.8
D34: Consumo Esp Comunes | F34: =F30-F32 -> 695.5 | G34: Cons Esp Com $ | H34: =(H30*F34)/F30 -> 245506.89
F36: TOTAL FACT EDESUR | H36: =H32+H33+H34 -> 442653.69
D38: Lecturas EDESUR s/facturas | F38: 46164 | G38: 46197 | H38: Cons s/EDESUR
D39: Lect Med Edesur 01 | F39: 274268 | G39: 275522 | H39: =G39-F39 -> 1254
