Workbook

Sheet RESUMEN
B1: Domicilio: Dr. Melo Nº 2958 - 8VO PISO - Con cita previa
B2: consorciobelgrano1640@gmail.com
B3: Santander cuenta 039-010552/1
B4: CBU: 0720039720000001055218
A5: LIQUIDACION DE EXPENSAS | B5: PERÍODO: SEPTIEMBRE | C5: VTO: 15/10
A6: CUIT: 33-71826987-9
A7: CONSORCIO DE PROPIETARIOS DEL EDIFICIO CALLE BELGRANO NUMERO 1640/1646 BANFIELD PARTIDO DE LOMAS DE ZAMORA
B14: Los gastos que se encuentras subrayados son los que corresponden tanto a las unidades funcionales como tambien al local
A21: GASTOS ORDINARIOS UNIDADES FUNCIONALES: | E21: UF 91,91% | F21: LOCAL 8,09%
A22: Sr. Diego Britez | B22: Honorarios SEPTIEMBRE
A23: Haberes | D23: 1277708.7 | E23: =D23*91.91% -> 1174342.1 | F23: =D23*8.09% -> 103366.63
A24: Deducciones | D24: -277901.65 | E24: =D24*91.91% -> -255419.41 | F24: =D24*8.09% -> -22482.243
A25: Redondeo | D25: 0.95 | E25: =D25*91.91% -> 0.873145 | F25: =D25*8.09% -> 0.076855
A27: TOTAL SUELDO | D27: =SUM(D23:D26) -> 999808 | E27: =SUM(E23:E26) -> 918923.53 | F27: =SUM(F23:F26) -> 80884.467 | G27: =E27+F27 -> 999808 | H27: =IF(D27=G27, "", "Error")
A28: SAC | D28: 0 | E28: =D28*91.91% -> 0 | F28: =D28*8.09% -> 0
D29: 0 | E29: =D29*91.91% -> 0 | F29: =D29*8.09% -> 0
A32: TOTAL | D32: =SUM(D28:D30) -> 0 | E32: =SUM(E28:E30) -> 0 | F32: =SUM(F28:F30) -> 0 | G32: =E32+F32 -> 0 | H32: =IF(D32=G32, "", "Error")
A33: SAC | E33: =D33*91.91% -> 0 | F33: =D33*8.09% -> 0
A34: Redondeo | E34: =D34*91.91% -> 0 | F34: =D34*8.09% -> 0
A35: Deducciones | E35: =D35*91.91% -> 0 | F35: =D35*8.09% -> 0
A36: TOTAL SAC | D36: =SUM(D29:D35) -> 0 | E36: =SUM(E29:E35) -> 0 | F36: =E36*8.09% -> 0
A40: TOTAL | E40: =SUM(D37:D39) -> 0 | F40: =(D37)*8.09% -> 0
E41: =D41*91.91% -> 0 | F41: =D41*8.09% -> 0
E42: =D42*91.91% -> 0 | F42: =D42*8.09% -> 0
E43: =D43*91.91% -> 0 | F43: =D43*8.09% -> 0
A44: TOTAL REEMPLAZO | D44: =SUM(D41:D43) -> 0 | E44: =SUM(E41:E43) -> 0 | F44: =SUM(F41:F43) -> 0 | G44: =E44+F44 -> 0
A45: APORTES Y CONTRIBUCIONES
A46: SEGURO OBLIGATORIO SR DIEGO BRITEZ FEDERACION PATRONAL DEBITO AUTOMATICO 01/08 | D46: 5020 | E46: =D46*91.91% -> 4613.882 | F46: =D46*8.09% -> 406.118
A47: SUTERH - FATERYH - SARACAH | B47: Debito 12/08 | D47: =6338.54+57496.89+108023.08 -> 171858.51 | E47: =D47*91.91% -> 157955.16 | F47: =D47*8.09% -> 13903.353
A48: ARCA | B48: Pago mis cuentas 07/08 | D48: 565971.8 | E48: =D48*91.91% -> 520184.68 | F48: =D48*8.09% -> 45787.119
A49: TOTAL Aportes y Contribuciones - Sindicato | D49: =SUM(D46:D48) -> 742850.31 | E49: =SUM(E46:E48) -> 682753.72 | F49: =SUM(F46:F48) -> 60096.59 | G49: =E49+F49 -> 742850.31 | H49: =IF(D49=G49, "", "Error")
A50: ABONOS Y SERVICIOS
A51: Contessi - Provision y cambio de lapices de nivelacion en el montaauto | D51: 160000 | E51: =D51 -> 160000 | G51: =D51 -> 160000 | H51: =E51+F51 -> 160000
A52: Contessi - Mantenimiento de ascensores | D52: 372000 | E52: =D52 -> 372000 | G52: =D52 -> 372000 | H52: =E52+F52 -> 372000 | I52: =H52-D52 -> 0
A53: Riesgo Uno | D53: 127113.12 | E53: =D53*91.91% -> 116829.67 | F53: =D53*8.09% -> 10283.451 | G53: =D53 -> 127113.12 | H53: =E53+F53 -> 127113.12
A54: Energoup MES DE SEPTIEMBRE | D54: 148200 | E54: =D54*91.91% -> 136210.62 | F54: =D54*8.09% -> 11989.38 | G54: =D54 -> 148200 | H54: =E54+F54 -> 148200 | I54: =H54-D54 -> 0 | J54: =G54-D54 -> 0
A55: Seguro Poliza | B55: Numero 1859135 Debito automatico 01/08 | D55: 129320 | E55: =D55*91.91% -> 118858.01 | F55: =D55*8.09% -> 10461.988 | G55: =D55 -> 129320 | H55: =E55+F55 -> 129320 | I55: =H55-D55 -> 0 | J55: =G55-D55 -> 0
A56: AYSA | B56: No hubo boleta | D56: 641235.7 | E56: =D56*91.91% -> 589359.73 | F56: =D56*8.09% -> 51875.968 | G56: =D56 -> 641235.7 | H56: =E56+F56 -> 641235.7 | I56: =H56-D56 -> 0 | J56: =G56-D56 -> 0
A57: EDESUR | B57: Debito 29/08 | D57: 2276949.4 | E57: =D57*91.91% -> 2092744.2 | F57: =D57*8.09% -> 184205.21 | G57: =D57 -> 2276949.4 | H57: =E57+F57 -> 2276949.4 | I57: =H57-D57 -> 0 | J57: =G57-D57 -> 0
A58: Fumigacion 19/08 | D58: 67000 | E58: =D58 -> 67000 | G58: =D58 -> 67000 | H58: =E58+F58 -> 67000 | I58: =H58-D58 -> 0 | J58: =G58-D58 -> 0
...

Sheet PRORRATEO
F1: ESTADO DE CUENTA Y PRORRATEO | K1: SE GASTO: | L1: =RESUMEN!D92 -> 11708794 | O1: =L1*8.09% -> 947241.44
K2: SE PRORRATEA EN LAS UF: | M2: =8271670+8271670*15%+49000+4000-276 -> 9565144.5 | O2: =O1-K7-553-50-86-8 -> 225448.76
A3: =RESUMEN!C5 -> VTO: 15/10 | K3: EXPENSAS EXTRA: | M3: =RESUMEN!D105 -> 2916310.6
J4: =(J3*8.09%)/44 -> 0 | K4: SE PRORRATEA EN LAS UF: | M4: =3175000-2000+7 -> 3173007
A5: Piso | B5: Dpto. | C5: UF | D5: Propietario | E5: (%) | F5: Saldo | G5: Ingreso | H5: SALDO | I5: Fecha | J5: Expensas extraor. | K5: Expensas ord | L5: SUM/ GASTOS PART | M5: TOTAL EXPENSAS 1er VTO | N5: TOTAL EXPENSAS 2do VTO
A7: PB | C7: 1 | D7: LOCAL 1 - DANIEL VIDAL | E7: 8.09 | F7: 614669.66 | G7: =F7 -> 614669.66 | H7: =F7-G7 -> 0 | I7: 12 | J7: 235929.53 | K7: 721095.68 | L7: 0 | M7: =K7+J7+H7+L7 -> 957025.21 | N7: =M7*6% + M7 -> 1014446.7
A8: 3º | C8: 24 | D8: RODRIGUEZ, MARIA ROSA | E8: 2.21 | F8: 181048.12 | G8: 180000 | H8: =F8-G8 -> 1048.122 | I8: 11 | J8: =M$4*E8% -> 70123.455 | K8: =M$2*E8 /100 -> 211389.69 | L8: =J$3*E8%+J$4 -> 0 | M8: =K8+J8+H8+L8 -> 282561.27 | N8: =M8*6% + M8 -> 299514.95
A9: 3º | C9: 25 | D9: RUSSO, JUAN ANTONIO | E9: 4.21 | F9: 348817.06 | G9: =392904-G34 -> 348236.98 | H9: =F9-G9 -> 580.07328 | I9: 4 | J9: =M$4*E9% -> 133583.59 | K9: =M$2*E9 /100 -> 402692.58 | L9: =J$3*E9%+J$4 -> 0 | M9: =K9+J9+H9+L9 -> 536856.25 | N9: =M9*6% + M9 -> 569067.63
A10: 4º | C10: 26 | D10: SALLABER, MARIA | E10: 2.84 | F10: 279110.11 | G10: 213555 | H10: =F10-G10 -> 65555.114 | I10: 4 | J10: =M$4*E10% -> 90113.399 | K10: =M$2*E10 /100 -> 271650.1 | L10: =J$3*E10%+J$4 -> 0 | M10: =K10+J10+H10+L10 -> 427318.62 | N10: =M10*6% + M10 -> 452957.73
A11: 4º | C11: 27 | D11: COLATRELLA, CAROLINA | E11: 3.43 | F11: 283718.28 | G11: =F11 -> 283718.28 | H11: =F11-G11 -> 0 | I11: 13 | J11: =M$4*E11% -> 108834.14 | K11: =M$2*E11 /100 -> 328084.46 | L11: =J$3*E11%+J$4 -> 0 | M11: =K11+J11+H11+L11 -> 436918.6 | N11: =M11*6% + M11 -> 463133.71
A12: 5º | C12: 28 | D12: LUSENSKY, CARLOS | E12: 2.84 | F12: 234915.43 | G12: =F12 -> 234915.43 | H12: =F12-G12 -> 0 | I12: 14 | J12: =M$4*E12% -> 90113.399 | K12: =M$2*E12 /100 -> 271650.1 | L12: =J$3*E12%+J$4 -> 0 | M12: =K12+J12+H12+L12 -> 361763.5 | N12: =M12*6% + M12 -> 383469.31
A13: 5º | C13: 29 | D13: DI TORO, ALEJANDRO | E13: 3.43 | F13: 283718.82 | G13: =332521-G50 -> 283718.15 | H13: =F13-G13 -> 0.67711924 | I13: 1 | J13: =M$4*E13% -> 108834.14 | K13: =M$2*E13 /100 -> 328084.46 | L13: 10000 | M13: =K13+J13+H13+L13 -> 446919.27 | N13: =M13*6% + M13 -> 473734.43
A14: 6º | C14: 30 | D14: PERAZA, MARTHA | E14: 2.84 | F14: 258710.39 | G14: 234915 | H14: =F14-G14 -> 23795.393 | I14: 18 | J14: =M$4*E14% -> 90113.399 | K14: =M$2*E14 /100 -> 271650.1 | L14: =J$3*E14%+J$4 -> 0 | M14: =K14+J14+H14+L14 -> 385558.9 | N14: =M14*6% + M14 -> 408692.43
A15: 6º | C15: 31 | D15: BALBOA, ARIEL | E15: 3.43 | F15: 283718.17 | G15: =325076-G35 -> 283717.65 | H15: =F15-G15 -> 0.51704653 | I15: 1 | J15: =M$4*E15% -> 108834.14 | K15: =M$2*E15 /100 -> 328084.46 | L15: =J$3*E15%+J$4 -> 0 | M15: =K15+J15+H15+L15 -> 436919.11 | N15: =M15*6% + M15 -> 463134.26
A16: 7º | C16: 32 | D16: FEUILLANT, GASTON | E16: 2.84 | F16: 280282 | G16: =275546+45267-G49 -> 280281.82 | H16: =F16-G16 -> 0.183 | I16: 4 | J16: =M$4*E16% -> 90113.399 | K16: =M$2*E16 /100 -> 271650.1 | L16: =J$3*E16%+J$4 -> 0 | M16: =K16+J16+H16+L16 -> 361763.69 | N16: =M16*6% + M16 -> 383469.51
A17: 7º | C17: 33 | D17: CAMPANA, NESTOR | E17: 3.43 | F17: 293717.14 | G17: =375606+1-G47-G48 -> 293717.47 | H17: =F17-G17 -> -0.32228889 | I17: 12 | J17: =M$4*E17% -> 108834.14 | K17: =M$2*E17 /100 -> 328084.46 | L17: 10000 | M17: =K17+J17+H17+L17 -> 446918.27 | N17: =M17*6% + M17 -> 473733.37
A18: 8º | C18: 34 | D18: JARA, CLAUDIO | E18: 2.84 | F18: 231604.94 | G18: =112000+160000+8000-G51 -> 232851.48 | H18: =F18-G18 -> -1246.539 | I18: 12 | J18: =M$4*E18% -> 90113.399 | K18: =M$2*E18 /100 -> 271650.1 | L18: =J$3*E18%+J$4 -> 0 | M18: =K18+J18+H18+L18 -> 360516.96 | N18: =M18*6% + M18 -> 382147.98
A19: 8º | C19: 35 | D19: MIRAMONTES, HORACIO | E19: 3.43 | F19: 283718.85 | G19: =328385-G41 -> 283717.98 | H19: =F19-G19 -> 0.87176517 | I19: 1 | J19: =M$4*E19% -> 108834.14 | K19: =M$2*E19 /100 -> 328084.46 | L19: =J$3*E19%+J$4 -> 0 | M19: =K19+J19+H19+L19 -> 436919.47 | N19: =M19*6% + M19 -> 463134.64
A20: 9º | C20: 36 | D20: MELINA, ANDRES | E20: 2.84 | F20: 246161.03 | G20: =275446-G38 -> 234914.82 | H20: =F20-G20 -> 11246.211 | I20: 1 | J20: =M$4*E20% -> 90113.399 | K20: =M$2*E20 /100 -> 271650.1 | L20: =J$3*E20%+J$4 -> 0 | M20: =K20+J20+H20+L20 -> 373009.71 | N20: =M20*6% + M20 -> 395390.3
A21: 9º | C21: 37 | D21: GARCIA, MARIA SOL | E21: 3.43 | F21: 283718.26 | G21: =328385-G45 -> 283717.98 | H21: =F21-G21 -> 0.2740918 | I21: 1 | J21: =M$4*E21% -> 108834.14 | K21: =M$2*E21 /100 -> 328084.46 | L21: =J$3*E21%+J$4 -> 0 | M21: =K21+J21+H21+L21 -> 436918.87 | N21: =M21*6% + M21 -> 463134
A22: 10º | C22: 38 | D22: RATON, MARIELA | E22: 2.84 | F22: 254915.43 | G22: =F22 -> 254915.43 | H22: =F22-G22 -> 0 | I22: 2 | J22: =M$4*E22% -> 90113.399 | K22: =M$2*E22 /100 -> 271650.1 | L22: =J$3*E22%+J$4 -> 0 | M22: =K22+J22+H22+L22 -> 361763.5 | N22: =M22*6% + M22 -> 383469.31
A23: 10º | C23: 39 | D23: DAVIN, ALEJANDRO | E23: 3.43 | F23: 309550.97 | G23: =334000-G46 -> 290160.15 | H23: =F23-G23 -> 19390.822 | I23: 26 | J23: =M$4*E23% -> 108834.14 | K23: =M$2*E23 /100 -> 328084.46 | L23: 10000 | M23: =K23+J23+H23+L23 -> 466309.42 | N23: =M23*6% + M23 -> 494287.98
A24: 11º | C24: 40 | D24: VROONLAND, DANIEL | E24: 2.84 | F24: 233406.75 | G24: =266000+14000-G37 -> 239468.82 | H24: =F24-G24 -> -6062.0715 | I24: 6 | J24: =M$4*E24% -> 90113.399 | K24: =M$2*E24 /100 -> 271650.1 | L24: 10000 | M24: =K24+J24+H24+L24 -> 365701.43 | N24: =M24*6% + M24 -> 387643.52
A25: 11º | C25: 41 | D25: SIMONASSI, ALEJO | E25: 3.43 | F25: 322090.11 | G25: =F25 -> 322090.11 | H25: =F25-G25 -> 0 | I25: 10 | J25: =M$4*E25% -> 108834.14 | K25: =M$2*E25 /100 -> 328084.46 | L25: =J$3*E25%+J$4 -> 0 | M25: =K25+J25+H25+L25 -> 436918.6 | N25: =M25*6% + M25 -> 463133.71
A26: 12º | C26: 42 | D26: VELAZ, ATILIO | E26: 6 | F26: 496299.97 | G26: =676478.23-G30-G31-G36 -> 544958.68 | H26: =F26-G26 -> -48658.706 | I26: 1 | J26: =M$4*E26% -> 190380.42 | K26: =M$2*E26 /100 -> 573908.67 | L26: =J$3*E26%+J$4 -> 0 | M26: =K26+J26+H26+L26 -> 715630.38 | N26: =M26*6% + M26 -> 758568.21
A27: 13º | C27: 43 | D27: AGÜERO, MIRIAM S | E27: 5.89 | F27: 490962.32 | G27: =586914-G39-G40 -> 490962.63 | H27: =F27-G27 -> -0.30946473 | I27: 14 | J27: =M$4*E27% -> 186890.11 | K27: =M$2*E27 /100 -> 563387.01 | L27: =J$3*E27%+J$4 -> 0 | M27: =K27+J27+H27+L27 -> 750276.81 | N27: =M27*6% + M27 -> 795293.42
A28: 14º | C28: 44 | D28: VILLA, JUAN MANUEL | E28: 5.89 | F28: 510253.28 | G28: =598000-G32-G33 -> 510320.3 | H28: =F28-G28 -> -67.021423 | I28: 6 | J28: =M$4*E28% -> 186890.11 | K28: =M$2*E28 /100 -> 563387.01 | L28: =J$3*E28%+J$4 -> 0 | M28: =K28+J28+H28+L28 -> 750210.1 | N28: =M28*6% + M28 -> 795222.71
A29: 15º | C29: 45 | D29: TOLOSA, FABIO | E29: 5.89 | F29: 815269.45 | G29: =950000-G42-G43-G44 -> 816826.11 | H29: =F29-G29 -> -1556.6585 | I29: 3 | J29: =M$4*E29% -> 186890.11 | K29: =M$2*E29 /100 -> 563387.01 | L29: =J$3*E29%+J$4 -> 0 | M29: =K29+J29+H29+L29 -> 748720.46 | N29: =M29*6% + M29 -> 793643.69
A30: COC | C30: 1 | D30: VELAZ, ATILIO | E30: 0.54 | F30: 44667.018 | G30: =F30 -> 44667.018 | H30: =F30-G30 -> 0 | J30: =M$4*E30% -> 17134.238 | K30: =M$2*E30 /100 -> 51651.78 | L30: =J$3*E30%+J$4 -> 0 | M30: =K30+J30+H30+L30 -> 68786.018 | N30: =M30*6% + M30 -> 72913.179
A31: COC | C31: 2 | D31: VELAZ, ATILIO | E31: 0.55 | F31: 45494.185 | G31: =F31 -> 45494.185 | H31: =F31-G31 -> 0 | J31: =M$4*E31% -> 17451.539 | K31: =M$2*E31 /100 -> 52608.295 | L31: =J$3*E31%+J$4 -> 0 | M31: =K31+J31+H31+L31 -> 70059.833 | N31: =M31*6% + M31 -> 74263.423
A32: COC | C32: 3 | D32: VILLA, JUAN MANUEL | E32: 0.45 | F32: 37222.515 | G32: =F32 -> 37222.515 | H32: =F32-G32 -> 0 | J32: =M$4*E32% -> 14278.532 | K32: =M$2*E32 /100 -> 43043.15 | L32: =J$3*E32%+J$4 -> 0 | M32: =K32+J32+H32+L32 -> 57321.682 | N32: =M32*6% + M32 -> 60760.983
A33: COC | C33: 4 | D33: VILLA, JUAN MANUEL | E33: 0.61 | F33: 50457.187 | G33: =F33 -> 50457.187 | H33: =F33-G33 -> 0 | J33: =M$4*E33% -> 19355.343 | K33: =M$2*E33 /100 -> 58347.381 | L33: =J$3*E33%+J$4 -> 0 | M33: =K33+J33+H33+L33 -> 77702.724 | N33: =M33*6% + M33 -> 82364.888
A34: COC | C34: 5 | D34: RUSSO, JUAN ANTONIO | E34: 0.54 | F34: 44667.018 | G34: =F34 -> 44667.018 | H34: =F34-G34 -> 0 | J34: =M$4*E34% -> 17134.238 | K34: =M$2*E34 /100 -> 51651.78 | L34: =J$3*E34%+J$4 -> 0 | M34: =K34+J34+H34+L34 -> 68786.018 | N34: =M34*6% + M34 -> 72913.179
A35: COC | C35: 6 | D35: BALBOA, ARIEL | E35: 0.5 | F35: 41358.35 | G35: =F35 -> 41358.35 | H35: =F35-G35 -> 0 | J35: =M$4*E35% -> 15865.035 | K35: =M$2*E35 /100 -> 47825.723 | L35: =J$3*E35%+J$4 -> 0 | M35: =K35+J35+H35+L35 -> 63690.758 | N35: =M35*6% + M35 -> 67512.203
A36: COC | C36: 7 | D36: VELAZ, ATILIO | E36: 0.5 | F36: 41358.35 | G36: =F36 -> 41358.35 | H36: =F36-G36 -> 0 | J36: =M$4*E36% -> 15865.035 | K36: =M$2*E36 /100 -> 47825.723 | L36: =J$3*E36%+J$4 -> 0 | M36: =K36+J36+H36+L36 -> 63690.758 | N36: =M36*6% + M36 -> 67512.203
A37: COC | C37: 8 | D37: VROONLAND, DANIEL | E37: 0.49 | F37: 40531.183 | G37: =F37 -> 40531.183 | H37: =F37-G37 -> 0 | J37: =M$4*E37% -> 15547.734 | K37: =M$2*E37 /100 -> 46869.208 | L37: =J$3*E37%+J$4 -> 0 | M37: =K37+J37+H37+L37 -> 62416.942 | N37: =M37*6% + M37 -> 66161.959
A38: COC | C38: 9 | D38: MELINA, ANDRES | E38: 0.49 | F38: 40531.183 | G38: =F38 -> 40531.183 | H38: =F38-G38 -> 0 | J38: =M$4*E38% -> 15547.734 | K38: =M$2*E38 /100 -> 46869.208 | L38: =J$3*E38%+J$4 -> 0 | M38: =K38+J38+H38+L38 -> 62416.942 | N38: =M38*6% + M38 -> 66161.959
A39: COC | C39: 10 | D39: AGÜERO, MIRIAM S | E39: 0.59 | F39: 48802.853 | G39: =F39 -> 48802.853 | H39: =F39-G39 -> 0 | J39: =M$4*E39% -> 18720.741 | K39: =M$2*E39 /100 -> 56434.353 | L39: =J$3*E39%+J$4 -> 0 | M39: =K39+J39+H39+L39 -> 75155.094 | N39: =M39*6% + M39 -> 79664.399
A40: COC | C40: 11 | D40: AGÜERO, MIRIAM S | E40: 0.57 | F40: 47148.519 | G40: =F40 -> 47148.519 | H40: =F40-G40 -> 0 | J40: =M$4*E40% -> 18086.14 | K40: =M$2*E40 /100 -> 54521.324 | L40: =J$3*E40%+J$4 -> 0 | M40: =K40+J40+H40+L40 -> 72607.464 | N40: =M40*6% + M40 -> 76963.911
A41: COC | C41: 12 | D41: MIRAMONTES, HORACIO | E41: 0.54 | F41: 44667.018 | G41: =F41 -> 44667.018 | H41: =F41-G41 -> 0 | J41: =M$4*E41% -> 17134.238 | K41: =M$2*E41 /100 -> 51651.78 | L41: =J$3*E41%+J$4 -> 0 | M41: =K41+J41+H41+L41 -> 68786.018 | N41: =M41*6% + M41 -> 72913.179
...

Sheet Hoja1
C4: EL MES ANTERIOR ATILIO QUEDO CON UN SALDO A FAVOR DE:
C5: UF 42 | D5: -447223.46
C6: COCHERA 1 | D6: 0
C7: COCHERA 2 | D7: 0
C8: COCHERA 7 | D8: 0
C10: LAS EXPENSAS DEL MES PASADO FUERON (AL 01/07):
C11: UF 42 | D11: 451182
C12: COCHERA 1 | D12: 40606.38
C13: COCHERA 2 | D13: 41358.35
C14: COCHERA 7 | D14: 37598.5
C16: SI A LAS EXPENSAS DEL MES PASADO LES CONTEMPLAMOS EL DINERO A FAVOR:
C17: UF 42 | D17: =D11+D5 -> 3958.5408
C18: COCHERA 1 | D18: 40606.38
C19: COCHERA 2 | D19: 41358.35
C20: COCHERA 7 | D20: 37598.5
C21: YA ABONO: | D21: -25000
C22: DINERO TOTAL A ABONAR: | D22: =SUM(D17:D21) -> 98521.771

Sheet COCHERA
D1: ESTADO DE CUENTA Y PRORRATEO | L1: Vencimiento | N1: =RESUMEN!C5 -> VTO: 15/10
D2: BELGRANO Nº 1640
J3: Gastos Ordinario: | L3: 249991.3 | N3: -1891.33
J4: Gastos Extr.: | L4: 0
A5: Cochera | B5: Propietario | C5: Porcentaje | D5: Saldo | E5: Ingreso | F5: DEUDAS | G5: Deuda exp | H5: Intereses | I5: porcentaje | J5: Expensas | K5: Expensas | L5: TOTAL | N5: 1ER Vto. | O5: 2DO Vto.
C6: (%) | D6: Anterior | E6: Exp. Ord. | G6: Extraord | H6: 0.06 | I6: % | J6: Ord. | K6: Extr. | L6: EXPENSAS
A7: 1 | B7: VELAZ, ATILIO | C7: 5.4 | D7: 13967.239 | E7: =D7 -> 13967.239 | F7: 0 | G7: 0 | H7: 0 | I7: 0.54 | J7: 11608.2 | K7: 0 | L7: 11608.2 | N7: 11608.2 | O7: 12304.692
A8: 2 | B8: VELAZ, ATILIO | C8: 5.5 | D8: 14267.901 | E8: =D8 -> 14267.901 | F8: 0 | G8: 0 | H8: 0 | I8: 0.55 | J8: 11858.191 | K8: 0 | L8: 11858.191 | N8: 11858.191 | O8: 12569.683
A9: 3 | B9: VILLA, JUAN MANUEL | C9: 4.5 | D9: 11261.283 | E9: =D9 -> 11261.283 | F9: 0 | G9: 0 | H9: 0 | I9: 0.45 | J9: 9358.2784 | K9: 0 | L9: 9358.2784 | N9: 9358.2784 | O9: 9919.7751
A10: 4 | B10: VILLA, JUAN MANUEL | C10: 6.1 | D10: 16071.872 | E10: =D10 -> 16071.872 | F10: 0 | G10: 0 | H10: 0 | I10: 0.61 | J10: 13358.139 | K10: 0 | L10: 13358.139 | N10: 13358.139 | O10: 14159.628
A11: 5 | B11: RUSSO, JUAN ANTONIO | C11: 5.4 | D11: 13967.239 | E11: =D11 -> 13967.239 | F11: 0 | G11: 0 | H11: 0 | I11: 0.54 | J11: 11608.2 | K11: 0 | L11: 11608.2 | N11: 11608.2 | O11: 12304.692
A12: 6 | B12: MARANTE, MAURO | C12: 5 | D12: 12764.592 | E12: =D12 -> 12764.592 | F12: 0 | G12: 0 | H12: 0 | I12: 0.5 | J12: 10608.235 | K12: 0 | L12: 10608.235 | N12: 10608.235 | O12: 11244.729
A13: 7 | B13: VELAZ, ATILIO | C13: 5 | D13: 12764.592 | E13: =D13 -> 12764.592 | F13: 0 | G13: 0 | H13: 0 | I13: 0.5 | J13: 10608.235 | K13: 0 | L13: 10608.235 | N13: 10608.235 | O13: 11244.729
A14: 8 | B14: VROONLAND, DANIEL | C14: 4.9 | D14: 12463.93 | E14: =D14 -> 12463.93 | F14: 0 | G14: 0 | H14: 0 | I14: 0.49 | J14: 10358.244 | K14: 0 | L14: 10358.244 | N14: 10358.244 | O14: 10979.738
A15: 9 | B15: MELINA, ANDRES | C15: 4.9 | D15: 12463.93 | E15: =D15 -> 12463.93 | F15: 0 | G15: 0 | H15: 0 | I15: 0.49 | J15: 10358.244 | K15: 0 | L15: 10358.244 | N15: 10358.244 | O15: 10979.738
A16: 10 | B16: AGÜERO, MIRIAM S | C16: 5.9 | D16: 15470.549 | E16: =D16 -> 15470.549 | F16: 0 | G16: 0 | H16: 0 | I16: 0.59 | J16: 12858.157 | K16: 0 | L16: 12858.157 | N16: 12858.157 | O16: 13629.646
A17: 11 | B17: AGÜERO, MIRIAM S | C17: 5.7 | D17: 14869.225 | E17: =D17 -> 14869.225 | F17: 0 | G17: 0 | H17: 0 | I17: 0.57 | J17: 12358.174 | K17: 0 | L17: 12358.174 | N17: 12358.174 | O17: 13099.664
A18: 12 | B18: MIRAMONTES, HORACIO | C18: 5.4 | D18: 13967.239 | E18: =D18 -> 13967.239 | F18: 0 | G18: 0 | H18: 0 | I18: 0.54 | J18: 11608.2 | K18: 0 | L18: 11608.2 | N18: 11608.2 | O18: 12304.692
... A28: 22 | B28: JARA, CLAUDIO | C28: 5.7 | D28: 14869.225 | E28: =D28 -> 14869.225 | F28: 0 | G28: 0 | H28: 0 | I28: 0.57 | J28: 12358.174 | K28: 0 | L28: 12358.174 | N28: 12358.174 | O28: 13099.664
C30: 116.6 | D30: 161487.47 | E30: 161487.47 | F30: 0 | G30: 0 | H30: 0 | I30: 11.66 | J30: 249880.59 | K30: 0 | L30: 249880.59 | N30: 249880.59 | O30: 264873.43
