Workbook

Sheet detalle y gastos
B2: CANCIANI, Carolina | C2: MP 1148
B3: Tel. 11 5320-2676
B4: consorciosrc13@gmail.com
A7: ='prorrateo '!E2 -> EDIFICIO PATXOT 521 | B7: LIQUIDACIÓN EXPENSAS ENERO 2025 | C7: Vtp 13/02
A10: Teléfonos útiles
A11: EDESUR 0800-333-3787
A12: AySA 0800-321-2482
A13: Metrogas 0800-333-6427
A15: GASTOS ORDINARIOS
A16: ABONOS y SERVICIOS
A17: Seguro Integral - a contratar
A20: AYSA | B20: Pago efectivo | C20: 71602.35
C23: =SUM(C17:C22) -> 71602.35
A24: LIMPIEZA / MANTENIMIENTO / GASTOS GENERALES
A25: Sra Limpieza | B25: Período ENERO 2024
A26: 7 de ENERO copia de llave | C26: 22000
A29: Prevision
C30: =SUM(C24:C29) -> 22000
A31: TOTAL GASTOS ORDINARIOS (A) - SIN CONTAR EDESUR | C31: =+C30+C23 -> 93602.35
A33: GASTOS EXTRAORDINARIOS
A38: TOTAL GASTOS EXTRAORDINARIOS (B) | C38: =+C34+C35+C36+C37 -> 0
A40: TOTAL GENERAL DE GASTOS (A) + (B) | C40: =+C38+C31 -> 93602.35
A42: ESTADO FINACIERO
A43: Saldo anterior | C43: -269246.23
A44: Ingreso por pago de expensas en término | C44: ='prorrateo '!F15 -> 49029.911
A45: Edesur | C45: =-edesur!H1 -> -84383.63
A46: Egresos por gastos del mes ordinarios | C46: =-(C31-C29) -> -93602.35
A47: Saldo al cierre $ (pesos) | C47: =SUM(C43:C46) -> -398202.3
A51: CAJA EXTRAORDINARIA | C51: 0
A52: Egreso extraordinario | C52: =-C38 -> 0
A55: TOTAL | C55: =SUM(C51:C54) -> 0

Sheet prorrateo 
A1: EXPENSAS ORDINARIAS | E1: 93602.35
A2: ='detalle y gastos'!B7 -> LIQUIDACIÓN EXPENSAS ENERO 2025 | E2: EDIFICIO PATXOT 521
A3: Dpto. | C3: Propietario | D3: Inquilinos | E3: Saldo | F3: Pagos | G3: DEUDA | H3: Intereses | I3: % | J3: Expensas ord. | K3: EDESUR | L3: TOTAL
E4: Anterior | F4: Exp. Ord. | H4: 0.04 | L4: EXPENSAS
A5: 1 | C5: Gomez Elizabeth | E5: 29650.223 | G5: =E5-F5 -> 29650.223 | H5: =IF(G5>0,G5*4%,0) -> 1186.0089 | I5: 13.8 | J5: =E$1*I5/100 -> 12917.124 | K5: =edesur!H5 -> 7945.2119 | L5: =G5+H5+J5+K5 -> 51698.568
A6: 2 | C6: Maceyle Gabriela | D6: Caro Manay | E6: 8969.1015 | F6: =E6 -> 8969.1015 | G6: =E6-F6 -> 0 | H6: =IF(G6>0,G6*4%,0) -> 0 | I6: 11.86 | J6: =E$1*I6/100 -> 11101.239 | K6: =edesur!H6 -> 11917.818 | L6: =G6+H6+J6+K6 -> 23019.057
A7: 3 | C7: Maceyle Gabriela | D7: Pereyra Amanda | E7: 47532.635 | G7: =E7-F7 -> 47532.635 | H7: =IF(G7>0,G7*4%,0) -> 1901.3054 | I7: 12.46 | J7: =E$1*I7/100 -> 11662.853 | K7: =edesur!H7 -> 16027.41 | L7: =G7+H7+J7+K7 -> 77124.203
A8: 4 | C8: Castelao Lorena | D8: Maitena E. | E8: 40060.81 | F8: =E8 -> 40060.81 | G8: =E8-F8 -> 0 | H8: =IF(G8>0,G8*4%,0) -> 0 | I8: 14.75 | J8: =E$1*I8/100 -> 13806.347 | K8: =edesur!H8 -> 9726.0353 | L8: =G8+H8+J8+K8 -> 23532.382
A9: 5 | C9: Grand Jorge | D9: Enciso Marisa | E9: 52706.72 | G9: =E9-F9 -> 52706.72 | H9: =IF(G9>0,G9*4%,0) -> 2108.2688 | I9: 12.41 | J9: =E$1*I9/100 -> 11616.052 | K9: =edesur!H9 -> 13150.696 | L9: =G9+H9+J9+K9 -> 79581.736
A10: 6 | C10: Valdez Norberto | E10: 47546.626 | G10: =E10-F10 -> 47546.626 | H10: =IF(G10>0,G10*4%,0) -> 1901.8651 | I10: 12.48 | J10: =E$1*I10/100 -> 11681.573 | K10: =edesur!H10 -> 14794.533 | L10: =G10+H10+J10+K10 -> 75924.597
A11: 7 | C11: Lean Cosenza | E11: 39995.805 | G11: =E11-F11 -> 39995.805 | H11: =IF(G11>0,G11*4%,0) -> 1599.8322 | I11: 18.26 | J11: =E$1*I11/100 -> 17091.789 | K11: =edesur!H11 -> 10821.927 | L11: =G11+H11+J11+K11 -> 69509.353
A12: COCH A | C12: =C9 -> Grand Jorge | E12: 937.43104 | G12: =E12-F12 -> 937.43104 | H12: =IF(G12>0,G12*4%,0) -> 37.497241 | I12: 1.34 | J12: =E$1*I12/100 -> 1254.2715 | K12: 0 | L12: =G12+H12+J12+K12 -> 2229.1998
A13: COCH B | C13: =C6 -> Maceyle Gabriela | E13: 923.43953 | G13: =E13-F13 -> 923.43953 | H13: =IF(G13>0,G13*4%,0) -> 36.937581 | I13: 1.32 | J13: =E$1*I13/100 -> 1235.551 | K13: 0 | L13: =G13+H13+J13+K13 -> 2195.9281
A14: COCH C | C14: =C6 -> Maceyle Gabriela | E14: 923.43953 | G14: =E14-F14 -> 923.43953 | H14: =IF(G14>0,G14*4%,0) -> 36.937581 | I14: 1.32 | J14: =E$1*I14/100 -> 1235.551 | K14: 0 | L14: =G14+H14+J14+K14 -> 2195.9281
A15: TOTALES | E15: =SUM(E5:E14) -> 269246.23 | F15: =SUM(F5:F14) -> 49029.911 | H15: =SUM(H5:H14) -> 8808.6527 | I15: =SUM(I5:I14) -> 100 | J15: =SUM(J5:J14) -> 93602.35 | K15: =SUM(K5:K11) -> 84383.63 | L15: =SUM(L5:L14) -> 407010.95
A18: EXPENSAS EXTRAORDINARIAS | E18: 7454
A19: Liquidación de mes: JULIO 2022 | E19: 14805
A20: UF | B20: Dpto. | C20: Propietario | E20: 3297 | F20: Pagos | H20: Intereses | I20: porcentaje | J20: Expensas | L20: TOTAL
E21: 3177 | F21: Exp. Extraord. | H21: 0.02 | I21: % | J21: Ordinarias | L21: EXPENSAS
A22: 1 | B22: PB 2 | C22: POC SERGIO | E22: 3056 | F22: 37971 | H22: 0 | I22: 0.121 | J22: =0*I22 -> 0 | L22: =+#REF!+H22+J22 -> #REF!
A23: 2 | B23: PB 1 | C23: GODOY DARIO | E23: 3056 | F23: 66612 | H23: 0 | I23: 0.122 | J23: =0*I23 -> 0 | L23: =+#REF!+H23+J23 -> #REF!
A24: 3 | B24: PB 3 | C24: BARBARESI CAROLINA | E24: =SUM(E16:E23) -> 34845 | F24: 0 | H24: 0 | I24: 0.117 | J24: =0*I24 -> 0 | L24: =+#REF!+H24+J24 -> #REF!
A25: 4 | B25: PB 4 | C25: ECHEVERRIA CHRISTIAN | F25: 0 | H25: 0 | I25: 0.117 | J25: =0*I25 -> 0 | L25: =+#REF!+H25+J25 -> #REF!
A26: 5 | B26: PA 2 | C26: POC SERGIO | F26: 80517 | H26: 0 | I26: 0.137 | J26: =0*I26 -> 0 | L26: =+#REF!+H26+J26 -> #REF!
A27: 6 | B27: PA 1 | C27: POC SERGIO | F27: 0 | H27: 0 | I27: 0.132 | J27: =0*I27 -> 0 | L27: =+#REF!+H27+J27 -> #REF!
A28: 7 | B28: PA 3 | C28: BARBARESI CAROLINA | E28: EDIFICIO DRAGO 1770 | F28: 18542 | H28: 0 | I28: 0.127 | J28: =0*I28 -> 0 | L28: =+#REF!+H28+J28 -> #REF!
A29: 8 | B29: PA 4 | C29: MANTEIGA LUCAS | E29: Saldo | F29: 0 | H29: 0 | I29: 0.127 | J29: =0*I29 -> 0 | L29: =+#REF!+H29+J29 -> #REF!
A30: TOTALES | E30: Anterior | F30: =SUM(F22:F29) -> 203642 | H30: =SUM(H22:H29) -> 0 | I30: =SUM(I22:I29) -> 1 | J30: =SUM(J22:J29) -> 0 | L30: =SUM(L22:L29) -> #REF!
E32: RECIBO DE EXPENSAS
E33: CONSORCIO: ADMINISTRACION DE CONSORCIOS RC
J34: ='detalle y gastos'!B7 -> LIQUIDACIÓN EXPENSAS ENERO 2025
E35: Adminstradora: Carolina Canciani
E37: EXPENSAS EXTRAORDINARIAS
E39: Nombre y apellido: | G39: =C7 -> Maceyle Gabriela | I39: Fecha: | J39: 45674 | L39: Sello o firma autoriada:
E40: UF: | F40: 3
E42: EXPENSAS ORDINARIAS | J42: =J7 -> 11662.853
E43: EDESUR | J43: =K7 -> 16027.41
E44: DEUDA + INTERESES | J44: =G7+H7 -> 49433.94
E50: ABONA DE MAS | J50: =77200-77124.2 -> 75.8
E52: Total recibido: | J52: =SUM(J42:J51) -> 77200.003
...

Sheet edesur
B1: PATXOT | C1: NOVIEMBRE 2024 | F1: EDESUR | G1: BOLETA | H1: 84383.63
B3: UNIDAD | C3: MEDIDOR | D3: MEDIDOR | E3: CONSUMO | F3: PORCENTAJE | G3: BOLETA TOTAL | H3: TOTAL A ABONAR
C4: ANTERIOR | D4: ACTUAL | H4: =H1 -> 84383.63
A5: GOMEZ | B5: 1 | C5: 7595 | D5: 7653 | E5: =D5-C5 -> 58 | F5: =E5*100/D14 -> 9.4155844 | H5: =H4*(F5/100) -> 7945.2119
A6: CARA | B6: 2 | C6: 6891 | D6: =C6+87 -> 6978 | E6: =D6-C6 -> 87 | F6: =E6*100/D14 -> 14.123377 | H6: =H4*(F6/100) -> 11917.818
A7: PEREYRA | B7: 3 | C7: 7480 | D7: 7597 | E7: =D7-C7 -> 117 | F7: =E7*100/D14 -> 18.993506 | H7: =H4*(F7/100) -> 16027.41
A8: MARTINEZ | B8: 4 | C8: 9084 | D8: 9155 | E8: =D8-C8 -> 71 | F8: =E8*100/D14 -> 11.525974 | H8: =H4*(F8/100) -> 9726.0353
A9: ENCISO ROTELA | B9: 5 | C9: 10479 | D9: 10575 | E9: =D9-C9 -> 96 | F9: =E9*100/D14 -> 15.584416 | H9: =H4*(F9/100) -> 13150.696
A10: VALDEZ | B10: 6 | C10: 10537 | D10: 10645 | E10: =D10-C10 -> 108 | F10: =E10*100/D14 -> 17.532468 | H10: =H4*(F10/100) -> 14794.533
A11: COSENZA | B11: 7 | C11: 12975 | D11: 13054 | E11: =D11-C11 -> 79 | F11: =E11*100/D14 -> 12.824675 | H11: =H4*(F11/100) -> 10821.927
C12: =SUM(C5:C11) -> 65041 | D12: =SUM(D5:D11) -> 65657 | E12: =SUM(E5:E11) -> 616 | F12: =SUM(F5:F11) -> 100 | H12: =SUM(H5:H11) -> 84383.63
B14: CONSUMO TOTAL KW | D14: =D12-C12 -> 616
B15: EDIFICIO
E20: EN TOTAL LOS DEPARTAMENTOS USARON | H20: =D14 -> 616 | K20: KW
D21: DEPARTAMENTO | E21: 7 | F21: CONSUMIO | G21: 197 | H21: KW | K21: EL 14,96% DE TOTAL CONSUMIDO
K25: NOVIEMBRE 2024
I27: ELECTRICIDAD | J27: EXPENSAS | K27: TOTAL
H28: VALDEZ | I28: 29829 | J28: 16000 | K28: =I28+J28 -> 45829
J31: saldo OCTUBRE 24 | K31: 117067
J32: ABONASTE OCTUBRE 24 | K32: -55000
J33: NOVIEMBRE 24 | K33: 43965
K34: =SUM(K31:K33) -> 106032

Sheet eXTR
D1: 50000 | H1: 250000
A2: EXPENSAS EXTRAORDINARIAS
A3: Liquidación de mes: DICIEMBRE 2023 | D3: EDIFICIO DRAGO 1770 | F3: EXPENSAS EXTRAORDINARIAS
A4: UF | B4: Dpto. | C4: Propietario | D4: Saldo | E4: Pago | F4: DEUDAS | G4: Intereses | H4: porcentaje | I4: Expensas | J4: DEUDA | L4: PUNITORIOS DE 5 MESES | M4: EXPENSAS | N4: TOTAL A PAGAR
D5: Anterior | E5: Exp. Extraord. | G5: 0.02 | H5: % | I5: Ordinarias | J5: ENERO | M5: EXTRAORD
A6: 1 | B6: PB 2 | C6: POC SERGIO | D6: 0 | E6: 0 | F6: =+D6-E6 -> 0 | G6: 0 | H6: 0.121 | I6: =H$1*H6 -> 30250 | J6: 9706.62 | L6: =(J6+K6)*5%+(J6+K6)*5%+(J6+K6)*5%+(J6+K6)*5%+(J6+K6)*5% -> 2426.655 | M6: =H$1*H6 -> 30250 | N6: =J6+K6+L6+M6 -> 42383.275
A7: 2 | B7: PB 1 | C7: GODOY DARIO | D7: 0 | E7: 0 | F7: =+D7-E7 -> 0 | G7: 0 | H7: 0.122 | I7: =H$1*H7 -> 30500 | J7: 19573.68 | L7: =(J7+K7)*5%+(J7+K7)*5%+(J7+K7)*5%+(J7+K7)*5%+(J7+K7)*5% -> 4893.42 | M7: =H$1*H7 -> 30500 | N7: =J7+K7+L7+M7 -> 54967.1
A8: 3 | B8: PB 3 | C8: BARBARESI CAROLINA | D8: 0 | E8: 0 | F8: =+D8-E8 -> 0 | G8: 0 | H8: 0.117 | I8: =H$1*H8 -> 29250 | J8: 0 | L8: =(J8+K8)*5%+(J8+K8)*5%+(J8+K8)*5%+(J8+K8)*5%+(J8+K8)*5% -> 0 | M8: =H$1*H8 -> 29250 | N8: =J8+K8+L8+M8 -> 29250
A9: 4 | B9: PB 4 | C9: ECHEVERRIA CHRISTIAN | D9: 0 | E9: 0 | F9: =+D9-E9 -> 0 | G9: 0 | H9: 0.117 | I9: =H$1*H9 -> 29250 | J9: 18771.48 | L9: =(J9+K9)*5%+(J9+K9)*5%+(J9+K9)*5%+(J9+K9)*5%+(J9+K9)*5% -> 4692.87 | M9: =H$1*H9 -> 29250 | N9: =J9+K9+L9+M9 -> 52714.35
A10: 5 | B10: PA 2 | C10: POC SERGIO | D10: 0 | E10: 0 | F10: =+D10-E10 -> 0 | G10: 0 | H10: 0.137 | I10: =H$1*H10 -> 34250 | J10: 10990.14 | L10: =(J10+K10)*5%+(J10+K10)*5%+(J10+K10)*5%+(J10+K10)*5%+(J10+K10)*5% -> 2747.535 | M10: =H$1*H10 -> 34250 | N10: =J10+K10+L10+M10 -> 47987.675
A11: 6 | B11: PA 1 | C11: POC SERGIO | D11: 0 | E11: 0 | F11: =+D11-E11 -> 0 | G11: 0 | H11: 0.132 | I11: =H$1*H11 -> 33000 | J11: 10589.04 | L11: =(J11+K11)*5%+(J11+K11)*5%+(J11+K11)*5%+(J11+K11)*5%+(J11+K11)*5% -> 2647.26 | M11: =H$1*H11 -> 33000 | N11: =J11+K11+L11+M11 -> 46236.3
A12: 7 | B12: PA 3 | C12: BARBARESI CAROLINA | D12: 0 | E12: 0 | F12: =+D12-E12 -> 0 | G12: 0 | H12: 0.127 | I12: =H$1*H12 -> 31750 | J12: 0 | L12: =(J12+K12)*5%+(J12+K12)*5%+(J12+K12)*5%+(J12+K12)*5%+(J12+K12)*5% -> 0 | M12: =H$1*H12 -> 31750 | N12: =J12+K12+L12+M12 -> 31750
A13: 8 | B13: PA 4 | C13: MANTEIGA LUCAS | D13: 0 | E13: 0 | F13: =+D13-E13 -> 0 | G13: 0 | H13: 0.127 | I13: =H$1*H13 -> 31750 | J13: 0 | L13: =(J13+K13)*5%+(J13+K13)*5%+(J13+K13)*5%+(J13+K13)*5%+(J13+K13)*5% -> 0 | M13: =H$1*H13 -> 31750 | N13: =J13+K13+L13+M13 -> 31750
A14: TOTALES | D14: =SUM(D6:D13) -> 0 | E14: =SUM(E6:E13) -> 0 | F14: =SUM(F6:F13) -> 0 | G14: =SUM(G6:G13) -> 0 | H14: =SUM(H6:H13) -> 1 | I14: =SUM(I6:I13) -> 250000 | J14: =SUM(J6:J13) -> 69630.96 | K14: =SUM(K6:K13) -> 0 | M14: =SUM(M6:M13) -> 250000 | N14: =SUM(N6:N13) -> 337038.7
