Workbook

Sheet RESUMEN
C1: MAIL: elmiradorconsorcios@gmail.com
C2: CUIT ADMINISTRACION: 27231256879
C3: CBU: 0720039720000002171436 | E3: TELEFONO: 11 5320-2676
C4: ADMINISTRADORA: CAROLINA CANCIANI MP:1148
C5: PERÍODO: SEPTIEMBRE | E5: HORARIOS DE ATENCION: LUNES A VIERNES - 10 A 15HS - EMERGENCIAS 24HS
C6: LIQUIDACION DE EXPENSAS
A14: Importante para dueños o inquilinos de departamentos o coheras: Queremos recordarles una cuestión importante respecto a los pagos de expensas que ayuda a evitar errores en la imputación de los mismos. El sistema que utilizamos asigna centavos únicos a cada Unidad Funcional (UF), lo cual nos permite identificar automáticamente a qué unidad corresponde cada transferencia. Es decir, cada UF tiene un número específico de centavos que actúa como "identificador". Por ejemplo, si tu UF es la 45, el importe a abonar debería terminar en $...,45. Si tenés más de una unidad (por ejemplo, un departamento y una cochera), cada una tiene su propio código de centavos. En esos casos, te pedimos por favor que realices una transferencia por cada UF, respetando el importe con sus centavos correspondientes. Sabemos que a veces por comodidad se suele enviar todo junto en una sola transferencia, pero esto puede generar confusión o errores en la imputación automática. Realizar los pagos por separado nos permite asegurar que cada importe se asigne correctamente. Agradecemos muchísimo la colaboración para seguir manteniendo todo ordenado. Saludos cordiales.
A20: VTO 16/10
A24: GASTOS ORDINARIOS UNIDADES FUNCIONALES: | E24: UF 93,20% | F24: LOCAL 1 (1,08%) | G24: LOCAL 2 (1,28%) | H24: LOCAL 3 (1,21%) | I24: LOCAL 4 (1,49%) | J24: LOCAL 5 (1,74%)
A25: Salvati - Servicios de limpieza
A26: Servicio de limpieza | B26: SE ADEUDA SEPTIEMBRE | C26: Transf 09/09 | D26: 2966292
A27: Sr. Piletero 12/09 | C27: Transf 25/09 | D27: 120000
A28: TOTAL | D28: =SUM(D25:D27) -> 3086292 | E28: =D28*93.2% -> 2876424.1 | F28: =$D28*1.08% -> 33331.954 | G28: =$D28*1.28% -> 39504.538 | H28: =$D28*1.21% -> 37344.133 | I28: =$D28*1.49% -> 45985.751 | J28: =D28*1.74% -> 53701.481 | K28: =E28+J28+F28+G28+H28+I28 -> 3086292 | L28: =IF(D28=K28, "", "Error")
A29: COMBUSTIBLE PARA GRUPO ELECTROGENO
A31: TOTAL | D31: =SUM(D30:D30) -> 0 | E31: =D31 -> 0 | K31: =E31+J31+F31+G31+H31+I31 -> 0 | L31: =IF(D31=K31, "", "Error")
A32: IMPUESTOS
A33: TSG - Partida 197227000 | B33: Mes 9 | C33: Transf 07/09 | D33: 1916441
A34: TSG - Partida 197229000 | B34: Mes 9 | C34: Transf 07/09 | D34: 1916441
A35: TSG - Partida 197227000 | B35: Mes 8 | C35: Transf 11/09 | D35: =3791724/2 -> 1895862
A36: TSG - Partida 197229000 | B36: Mes 8 | C36: Transf 11/09 | D36: =3791724/2 -> 1895862
A38: TOTAL IMPUESTOS | D38: =SUM(D33:D37) -> 7624606 | E38: =D38*93.2% -> 7106132.8 | F38: =$D38*1.08% -> 82345.745 | G38: =$D38*1.28% -> 97594.957 | H38: =$D38*1.21% -> 92257.733 | I38: =$D38*1.49% -> 113606.63 | J38: =D38*1.74% -> 132668.14 | K38: =E38+J38+F38+G38+H38+I38 -> 7624606 | L38: =IF(D38=K38, "", "Error")
A39: APORTES Y CONTRIBUCIONES
A41: TOTAL APORTES Y CONTRIBUCIONES | D41: =SUM(D39:D40) -> 0 | E41: =D41*93.2% -> 0 | F41: =$D41*1.08% -> 0 | G41: =$D41*1.28% -> 0 | H41: =$D41*1.21% -> 0 | I41: =$D41*1.49% -> 0 | J41: =D41*1.74% -> 0 | K41: =E41+J41+F41+G41+H41+I41 -> 0 | L41: =IF(D41=K41, "", "Error")
A42: SEGUROS
A43: Federacion patronal - Poliza integral para consorcios nro. 2152393 | C43: Debito autom. | D43: 214371 | E43: =D43*93.2% -> 199793.77 | F43: =$D43*1.08% -> 2315.2068 | G43: =$D43*1.28% -> 2743.9488 | H43: =$D43*1.21% -> 2593.8891 | I43: =$D43*1.49% -> 3194.1279 | J43: =D43*1.74% -> 3730.0554 | K43: =SUM(E43:J43) -> 214371
A45: TOTAL Aportes y Contribuciones - Sindicato | D45: =SUM(D43:D44) -> 214371 | E45: =SUM(E43:E44) -> 199793.77 | F45: =SUM(F43:F44) -> 2315.2068 | G45: =SUM(G43:G44) -> 2743.9488 | H45: =SUM(H43:H44) -> 2593.8891 | I45: =SUM(I43:I44) -> 3194.1279 | J45: =SUM(J43:J44) -> 3730.0554 | K45: =E45+J45+F45+G45+H45+I45 -> 214371 | L45: =IF(D45=K45, "", "Error")
A46: ABONOS Y SERVICIOS
A47: Aysa - Cuenta 2490112 | C47: Transf 16/09 | D47: 2645102.9 | E47: =D47*93.2% -> 2465235.9 | F47: =$D47*1.08% -> 28567.111 | G47: =$D47*1.28% -> 33857.317 | H47: =$D47*1.21% -> 32005.745 | I47: =$D47*1.49% -> 39412.033 | J47: =D47*1.74% -> 46024.79 | K47: =D47 -> 2645102.9 | L47: =SUM(E47:J47) -> 2645102.9
A48: Edesur - Cliente 01291636 | C48: Transf 15/09 | D48: 7010415.1 | E48: =D48*93.2% -> 6533706.9 | F48: =$D48*1.08% -> 75712.483 | G48: =$D48*1.28% -> 89733.313 | H48: =$D48*1.21% -> 84826.023 | I48: =$D48*1.49% -> 104455.18 | J48: =D48*1.74% -> 121981.22 | K48: =D48 -> 7010415.1 | L48: =E48+J48+I48+H48+G48+F48 -> 7010415.1
A49: Telecentro - Zona coworking - Cliente 7725479 | C49: Debito 17/09 | D49: 176275.21 | E49: =D49 -> 176275.21 | K49: =D49 -> 176275.21 | L49: =E49+J49+I49+H49+G49+F49 -> 176275.21 | M49: =L49-D49 -> 0 | N49: =K49-D49 -> 0
A50: ADS - Abono de mantenimiento ascensores SEPTIEMBRE | C50: Transf 16/09 | D50: 427893 | E50: =D50 -> 427893 | K50: =D50 -> 427893 | L50: =E50+J50+I50+H50+G50+F50 -> 427893
A51: Victor Martinez - Abono mantenimiento control de accesos - AGOSTO | C51: Transf 11/09 | D51: 55000 | E51: =D51 -> 55000 | K51: =D51 -> 55000 | L51: =E51+J51+I51+H51+G51+F51 -> 55000 | M51: =L51-D51 -> 0 | N51: =K51-D51 -> 0
A52: Metrogas - Cliente nro. 40000496339 | C52: Transf 09/09 | D52: 8144.29 | E52: =D52 -> 8144.29 | K52: =D52 -> 8144.29 | L52: =E52+J52+I52+H52+G52+F52 -> 8144.29
A53: Metrogas - Cliente nro. 40000497007 | C53: Transf 09/09 | D53: 1751133.8 | E53: =D53*93.2% -> 1632056.7 | F53: =$D53*1.08% -> 18912.245 | G53: =$D53*1.28% -> 22414.513 | H53: =$D53*1.21% -> 21188.719 | I53: =$D53*1.49% -> 26091.894 | J53: =D53*1.74% -> 30469.729 | K53: =D53 -> 1751133.8 | L53: =E53+J53+I53+H53+G53+F53 -> 1751133.8 | M53: =L53-D53 -> 0 | N53: =K53-D53 -> 0
A54: Loschi Mantenimiento grupo electrogeno - Abono bimestral | C54: Transf 30/09 | D54: 120000 | E54: =D54 -> 120000 | K54: =D54 -> 120000 | L54: =E54+J54+I54+H54+G54+F54 -> 120000 | M54: =L54-D54 -> 0 | N54: =K54-D54 -> 0
A55: TOTAL ABONOS Y SERVICIOS | D55: =SUM(D47:D54) -> 12193964 | E55: =SUM(E47:E54) -> 11418312 | F55: =SUM(F47:F54) -> 123191.84 | G55: =SUM(G47:G54) -> 146005.14 | H55: =SUM(H47:H54) -> 138020.49 | I55: =SUM(I47:I54) -> 169959.11 | J55: =SUM(J47:J54) -> 198475.74 | K55: =E55+J55+F55+G55+H55+I55 -> 12193964 | L55: =IF(D55=K55, "", "Error") | M55: =D55-K55 -> 0
A58: GASTOS VARIOS
A59: Fumigacion - Silva Nicolas | C59: Transf 28/09 | D59: 230000 | E59: =D59 -> 230000 | K59: =D59 -> 230000 | L59: =SUM(E59:J59) -> 230000
A60: Fidiax Argentina - Redaccion, gestion y envio carta documento Aysa | C60: Transf 07/09 | D60: 130000 | E60: =D60*93.2% -> 121160 | F60: =$D60*1.08% -> 1404 | G60: =$D60*1.28% -> 1664 | H60: =$D60*1.21% -> 1573 | I60: =$D60*1.49% -> 1937 | J60: =D60*1.74% -> 2262 | K60: =D60 -> 130000 | L60: =SUM(E60:J60) -> 130000
A61: Rosales Dario - Herrero : Fc. 00000325 - Realizacion de tapas nodo gas | C61: Transf 18/09 - 30/09 | D61: 1379400 | E61: =D61*93.2% -> 1285600.8 | F61: =$D61*1.08% -> 14897.52 | G61: =$D61*1.28% -> 17656.32 | H61: =$D61*1.21% -> 16690.74 | I61: =$D61*1.49% -> 20553.06 | J61: =D61*1.74% -> 24001.56 | K61: =D61 -> 1379400 | L61: =SUM(E61:J61) -> 1379400
...

Sheet PRORRATEO
A1: Las casillas coloreadas en la columna Gastos Par/SUM de color rojo corresponden a multas aplicadas por el uso del SUM. En consecuencia, la unidad funcional involucrada no podrá acceder al uso del mismo por tiempo indeterminado. Por otro lado, las casillas coloreadas en amarillo, corresponden a llaves y las verdes corresponden al mal uso del coworking. | F1: Banco Santander Rio. | L1: SE GASTO: | M1: =RESUMEN!D76-N4 -> 18487964
F2: CBU: 0720039720000002171436 | L2: SE PRORRATEA EN LAS UF: | N2: =M1 -> 18487964
L3: SE PRORRATEA EN LOCALES: | N3: =L15+L16+L17+L18+L19 -> 1706477.5
F4: CTA CTE $ 0039 - 21714/3 FIDEICOMISO 25 DE MAYO 837 LAN 30716676737 | L4: TSG: | N4: 7624606
C6: IMPORTANTE: Si en la columna SALDO a su unidad funcional le figura un monto en negativo, significa que usted abono mas dinero del que debia abonar. Si figura un monto en positivo significa que usted abono menos de lo que realmente debia abonar. Sea positivo o negativo el numero, es contemplado en las columnas de total a abonar para al siguiente mes.
C10: IMPORTANTE: Quienes estan en violeta NO ha respetado los centavos al abonar. Para la proxima oportunidad, solicitamos que los respeten. | Q10: LOCAL 1 | R10: =RESUMEN!F76 -> 271028.78
Q11: LOCAL 2 | R11: =RESUMEN!G76 -> 321219.29
A12: Piso | B12: Dpto. | C12: UF | D12: Propietario | E12: Inquilinos | F12: (%) | G12: Saldo | H12: Ingreso | I12: SALDO | J12: Expensas extraor. | K12: Cuota TSG | L12: Expensas ord | M12: SUM/ GASTOS PART | N12: TOTAL A ABONAR HASTA | O12: TOTAL A ABONAR 2DO VTO - DESDE EL | Q12: LOCAL 3 | R12: =RESUMEN!H76 -> 303652.61
Q13: LOCAL 4 | R13: =RESUMEN!I76 -> 373919.33
N14: =RESUMEN!A20 -> VTO 16/10 | O14: =RESUMEN!A20 -> VTO 16/10 | Q14: LOCAL 5 | R14: =RESUMEN!J76 -> 436657.48
A15: conf sup | C15: LOC 1 | D15: Fernandez, Cristian | E15: Gladys ojeda Britez - Exequiel alexis giuliani | F15: 0.0108 | G15: 332345.89 | H15: 267678 | I15: =G15-H15 -> 64667.889 | J15: 0 | K15: 82345.745 | L15: 271028.78 | M15: 0 | N15: =L15+J15+I15+M15+K15 -> 418042.41 | O15: =N15*6% + N15 -> 443124.96 | P15: Bezzo Jorge
C16: LOC 2 | D16: Fridgi, Guillermo Ariel | F16: 0.013 | G16: 770503.97 | H16: =G16 -> 770503.97 | I16: =G16-H16 -> 0 | J16: 0 | L16: 321219.29 | M16: 0 | N16: =L16+J16+I16+M16+K16 -> 321219.29 | O16: =N16*6% + N16 -> 340492.45 | P16: Lucas Rocha
A17: conf sup | C17: LOC 3 | D17: Grispino, Eduardo Claudio | E17: Cristina andrea Massa | F17: 0.0121 | G17: 299898.61 | H17: =G17 -> 299898.61 | I17: =G17-H17 -> 0 | J17: 0 | L17: 303652.61 | M17: 0 | N17: =L17+J17+I17+M17+K17 -> 303652.61 | O17: =N17*6% + N17 -> 321871.77
A18: conf sup | C18: LOC 4 | D18: Cordero, Leandro Emanuel - Orona, Victoria | F18: 0.0149 | G18: 1318197.1 | I18: =G18-H18 -> 1318197.1 | J18: 0 | K18: 113606.63 | L18: 373919.33 | M18: 0 | N18: =L18+J18+I18+M18+K18 -> 1805723.1 | O18: =N18*6% + N18 -> 1914066.5
A19: conf sup | C19: LOC 5 | D19: Orsi, Jose Luis - Fernandez, Cristian Gabriel | F19: 0.0174 | G19: 727422.31 | H19: 374000 | I19: =G19-H19 -> 353422.31 | J19: 0 | K19: 132668.14 | L19: 436657.48 | M19: 0 | N19: =L19+J19+I19+M19+K19 -> 922747.93 | O19: =N19*6% + N19 -> 978112.81
A20: 3 amb | C20: 2ºA | D20: Franco, Lucas Fabián | F20: 0.0188 | G20: 508048.01 | H20: =G20 -> 508048.01 | I20: =G20-H20 -> 0 | J20: =N$9*F20 -> 0 | L20: =N$2*F20 -> 347573.72 | M20: 0 | N20: =ROUND((L20+J20+I20+K20+M20),0) + P20 -> 347574.01 | O20: =ROUND((N20*6% + N20 ),0) + P20 -> 368428.01 | P20: 0.01
A21: 1 amb | C21: 2ºB | D21: Martinez, Diego | F21: 0.0084 | G21: 220298.02 | H21: =G21 -> 220298.02 | I21: =G21-H21 -> 0 | J21: =N$9*F21 -> 0 | K21: =N$4*F21 -> 64046.69 | L21: =N$2*F21 -> 155298.9 | M21: 0 | N21: =ROUND((L21+J21+I21+K21+M21),0) + P21 -> 219346.02 | O21: =ROUND((N21*6% + N21 ),0) + P21 -> 232507.02 | P21: =P20+0.01 -> 0.02
A22: 3 amb | C22: 2ºC | D22: Rodriguez, Carlos Alberto Miguel | F22: 0.0201 | G22: 558771.03 | H22: =G22 -> 558771.03 | I22: =G22-H22 -> 0 | J22: =N$9*F22 -> 0 | L22: =N$2*F22 -> 371608.07 | M22: 0 | N22: =ROUND((L22+J22+I22+K22+M22),0) + P22 -> 371608.03 | O22: =ROUND((N22*6% + N22 ),0) + P22 -> 393905.03 | P22: =P21+0.01 -> 0.03
A23: 2 amb | C23: 2ºD | D23: Gomez, Adriana | E23: Matias Cuevas | F23: 0.0094 | G23: 246524.04 | H23: =G23 -> 246524.04 | I23: =G23-H23 -> 0 | J23: =N$9*F23 -> 0 | L23: =N$2*F23 -> 173786.86 | M23: 0 | N23: =ROUND((L23+J23+I23+K23+M23),0) + P23 -> 173787.04 | O23: =ROUND((N23*6% + N23 ),0) + P23 -> 184214.04 | P23: =P22+0.01 -> 0.04 | Q23: Matias alejandro ezequiel
A24: 2 amb | C24: 2ºE | D24: Dieci, Matias Orlando | E24: Julieta Damiano/Damiani | F24: 0.0087 | G24: 228166.05 | H24: 146784.05 | I24: =G24-H24 -> 81382 | J24: =N$9*F24 -> 0 | K24: =N$4*F24 -> 66334.072 | L24: =N$2*F24 -> 160845.29 | M24: 0 | N24: =ROUND((L24+J24+I24+K24+M24),0) + P24 -> 308561.05 | O24: =ROUND((N24*6% + N24 ),0) + P24 -> 327075.05 | P24: =P23+0.01 -> 0.05
A25: 2 amb | C25: 2ºF | D25: Gomez, Adriana | E25: Carolina Massa | F25: 0.0095 | G25: 339801.06 | H25: =G25 -> 339801.06 | I25: =G25-H25 -> 0 | J25: =N$9*F25 -> 0 | L25: =N$2*F25 -> 175635.66 | M25: 0 | N25: =ROUND((L25+J25+I25+K25+M25),0) + P25 -> 175636.06 | O25: =ROUND((N25*6% + N25 ),0) + P25 -> 186174.06 | P25: =P24+0.01 -> 0.06
A26: 3 amb | C26: 3ºA | D26: Gomez, Adriana | E26: Walter Gabriel Ledesma | F26: 0.0165 | G26: 717781.07 | H26: 302156.07 | I26: =G26-H26 -> 415625 | J26: =N$9*F26 -> 0 | L26: =N$2*F26 -> 305051.4 | M26: 0 | N26: =ROUND((L26+J26+I26+K26+M26),0) + P26 -> 720676.07 | O26: =ROUND((N26*6% + N26 ),0) + P26 -> 763917.07 | P26: =P25+0.01 -> 0.07
A27: 1 amb | C27: 3ºB | D27: Balduzzi, Stella Maris | F27: 0.0073 | G27: 224136.08 | H27: =G27 -> 224136.08 | I27: =G27-H27 -> 0 | J27: =N$9*F27 -> 0 | K27: =N$4*F27 -> 55659.624 | L27: =N$2*F27 -> 134962.14 | M27: 0 | N27: =ROUND((L27+J27+I27+K27+M27),0) + P27 -> 190622.08 | O27: =ROUND((N27*6% + N27 ),0) + P27 -> 202059.08 | P27: =P26+0.01 -> 0.08
A28: 3 amb | C28: 3ºC | D28: Gomez, Adriana | E28: Gustavo Oscar Fernandez | F28: 0.0178 | G28: 1109042.1 | H28: =728003.08+(526500-G118) -> 1108399.1 | I28: =G28-H28 -> 643 | J28: =N$9*F28 -> 0 | L28: =N$2*F28 -> 329085.76 | M28: 0 | N28: =ROUND((L28+J28+I28+K28+M28),0) + P28 -> 329729.09 | O28: =ROUND((N28*6% + N28 ),0) + P28 -> 349513.09 | P28: =P27+0.01 -> 0.09
A29: 2 amb | C29: 3ºD | D29: Fernandez, Christian Norberto | F29: 0.0094 | G29: 246524.1 | H29: =G29 -> 246524.1 | I29: =G29-H29 -> 0 | J29: =N$9*F29 -> 0 | K29: =N$4*F29 -> 71671.296 | L29: =N$2*F29 -> 173786.86 | M29: 0 | N29: =ROUND((L29+J29+I29+K29+M29),0) + P29 -> 245458.1 | O29: =ROUND((N29*6% + N29 ),0) + P29 -> 260186.1 | P29: =P28+0.01 -> 0.1
A30: 2 amb | C30: 3ºE | D30: Dallorso, Maria Ines - Dallorso, Ana Paula | F30: 0.0087 | G30: 243166.11 | H30: =G30 -> 243166.11 | I30: =G30-H30 -> 0 | J30: =N$9*F30 -> 0 | K30: =N$4*F30 -> 66334.072 | L30: =N$2*F30 -> 160845.29 | M30: 0 | N30: =ROUND((L30+J30+I30+K30+M30),0) + P30 -> 227179.11 | O30: =ROUND((N30*6% + N30 ),0) + P30 -> 240810.11 | P30: =P29+0.01 -> 0.11
A31: 2 amb | C31: 3ºF | D31: Campelo, Mariano | F31: 0.0095 | G31: 2272449.1 | H31: =G31+182709 -> 2455158.1 | I31: =G31-H31 -> -182709 | J31: =N$9*F31 -> 0 | L31: =N$2*F31 -> 175635.66 | M31: 0 | N31: =ROUND((L31+J31+I31+K31+M31),0) + P31 -> -7072.88 | O31: =ROUND((N31*6% + N31 ),0) + P31 -> -7496.88 | P31: =P30+0.01 -> 0.12
A32: 3 amb | C32: 4ºA | D32: Barral, Carlos Daniel | F32: 0.0164 | G32: 430106.13 | H32: =G32 -> 430106.13 | I32: =G32-H32 -> 0 | J32: =N$9*F32 -> 0 | L32: =N$2*F32 -> 303202.61 | M32: 0 | N32: =ROUND((L32+J32+I32+K32+M32),0) + P32 -> 303203.13 | O32: =ROUND((N32*6% + N32 ),0) + P32 -> 321395.13 | P32: =P31+0.01 -> 0.13
A33: 1 amb | C33: 4ºB | D33: Viegas, Nancy Noemi | E33: Liria | F33: 0.0072 | G33: 189183.14 | H33: 188471.14 | I33: =G33-H33 -> 712 | J33: =N$9*F33 -> 0 | L33: =N$2*F33 -> 133113.34 | M33: 0 | N33: =ROUND((L33+J33+I33+K33+M33),0) + P33 -> 133825.14 | O33: =ROUND((N33*6% + N33 ),0) + P33 -> 141855.14 | P33: =P32+0.01 -> 0.14
A34: 3 amb | C34: 4ºC | D34: Osipowicz, Ariel Marcelo | F34: 0.0173 | G34: 483709.15 | H34: =G34 -> 483709.15 | I34: =G34-H34 -> 0 | J34: =N$9*F34 -> 0 | L34: =N$2*F34 -> 319841.77 | M34: 0 | N34: =ROUND((L34+J34+I34+K34+M34),0) + P34 -> 319842.15 | O34: =ROUND((N34*6% + N34 ),0) + P34 -> 339033.15 | P34: =P33+0.01 -> 0.15
A35: 2 amb | C35: 4ºD | D35: Ruiz, Juana Del Valle | F35: 0.0094 | G35: 246524.16 | H35: =G35 -> 246524.16 | I35: =G35-H35 -> 0 | J35: =N$9*F35 -> 0 | L35: =N$2*F35 -> 173786.86 | M35: 0 | N35: =ROUND((L35+J35+I35+K35+M35),0) + P35 -> 173787.16 | O35: =ROUND((N35*6% + N35 ),0) + P35 -> 184214.16 | P35: =P34+0.01 -> 0.16 | Q35: Pablo Amarilla
A36: 2 amb | C36: 4ºE | D36: Szkarlatiuk, Carina Sonia | E36: Iara | F36: 0.0087 | G36: 228166.17 | H36: =G36 -> 228166.17 | I36: =G36-H36 -> 0 | J36: =N$9*F36 -> 0 | K36: =N$4*F36 -> 66334.072 | L36: =N$2*F36 -> 160845.29 | M36: 0 | N36: =ROUND((L36+J36+I36+K36+M36),0) + P36 -> 227179.17 | O36: =ROUND((N36*6% + N36 ),0) + P36 -> 240810.17 | P36: =P35+0.01 -> 0.17
A37: 2 amb | C37: 4ºF | D37: Campelo, Mariano | F37: 0.0095 | G37: 1723633.2 | H37: =G37+182708 -> 1906341.2 | I37: =G37-H37 -> -182708 | J37: =N$9*F37 -> 0 | L37: =N$2*F37 -> 175635.66 | M37: 0 | N37: =ROUND((L37+J37+I37+K37+M37),0) + P37 -> -7071.82 | O37: =ROUND((N37*6% + N37 ),0) + P37 -> -7495.82 | P37: =P36+0.01 -> 0.18
A38: 3 amb | C38: 5ºA | D38: Chehab, Gabriel Adrian | E38: Santiago Rodriguez | F38: 0.0164 | G38: 430106.19 | H38: =G38 -> 430106.19 | I38: =G38-H38 -> 0 | J38: =N$9*F38 -> 0 | L38: =N$2*F38 -> 303202.61 | M38: 0 | N38: =ROUND((L38+J38+I38+K38+M38),0) + P38 -> 303203.19 | O38: =ROUND((N38*6% + N38 ),0) + P38 -> 321395.19 | P38: =P37+0.01 -> 0.19 | Q38: Cochera 38
A39: 1 amb | C39: 5ºB | D39: Mesa, Mariano | F39: 0.0072 | G39: 200157.2 | H39: 188827.2 | I39: =G39-H39 -> 11330 | J39: =N$9*F39 -> 0 | K39: =N$4*F39 -> 54897.163 | L39: =N$2*F39 -> 133113.34 | M39: 0 | N39: =ROUND((L39+J39+I39+K39+M39),0) + P39 -> 199341.2 | O39: =ROUND((N39*6% + N39 ),0) + P39 -> 211302.2 | P39: =P38+0.01 -> 0.2
A40: 3 amb | C40: 5ºC | D40: Lasarte, Leda Isabel y Grossa, Raul Ariel | F40: 0.0173 | G40: 468710.21 | H40: =529029.96-H94 -> 468709.21 | I40: =G40-H40 -> 1 | J40: =N$9*F40 -> 0 | L40: =N$2*F40 -> 319841.77 | M40: 0 | N40: =ROUND((L40+J40+I40+K40+M40),0) + P40 -> 319843.21 | O40: =ROUND((N40*6% + N40 ),0) + P40 -> 339034.21 | P40: =P39+0.01 -> 0.21 | Q40: Gossa Raul Ariel
A41: 2 amb | C41: 5ºD | D41: Ayala, Roberto Adrian | F41: 0.0094 | G41: 246524.22 | H41: =G41 -> 246524.22 | I41: =G41-H41 -> 0 | J41: =N$9*F41 -> 0 | K41: =N$4*F41 -> 71671.296 | L41: =N$2*F41 -> 173786.86 | M41: 0 | N41: =ROUND((L41+J41+I41+K41+M41),0) + P41 -> 245458.22 | O41: =ROUND((N41*6% + N41 ),0) + P41 -> 260186.22 | P41: =P40+0.01 -> 0.22 | Q41: Ayala paga 5D, 5F y 4F
A42: 2 amb | C42: 5ºE | D42: Basaez, Rogelio Luis - Savino, Cecilia | F42: 0.0087 | G42: 228166.23 | H42: =G42 -> 228166.23 | I42: =G42-H42 -> 0 | J42: =N$9*F42 -> 0 | K42: =N$4*F42 -> 66334.072 | L42: =N$2*F42 -> 160845.29 | M42: 0 | N42: =ROUND((L42+J42+I42+K42+M42),0) + P42 -> 227179.23 | O42: =ROUND((N42*6% + N42 ),0) + P42 -> 240810.23 | P42: =P41+0.01 -> 0.23 | Q42: COCHERA 31
A43: 2 amb | C43: 5ºF | D43: Ayala, Roberto Adrian | F43: 0.0095 | G43: 1453566.2 | H43: =182708.22+1453566.24 -> 1636274.5 | I43: =G43-H43 -> -182708.22 | J43: =N$9*F43 -> 0 | L43: =N$2*F43 -> 175635.66 | M43: 0 | N43: =ROUND((L43+J43+I43+K43+M43),0) + P43 -> -7072.76 | O43: =ROUND((N43*6% + N43 ),0) + P43 -> -7496.76 | P43: =P42+0.01 -> 0.24
A44: 3 amb | C44: 6ºA | D44: Morandi, Victoria Ayelen | Calvo, Luciano Ezequiel | F44: 0.0164 | G44: 430106.25 | H44: =G44 -> 430106.25 | I44: =G44-H44 -> 0 | J44: =N$9*F44 -> 0 | K44: =N$4*F44 -> 125043.54 | L44: =N$2*F44 -> 303202.61 | M44: 0 | N44: =ROUND((L44+J44+I44+K44+M44),0) + P44 -> 428246.25 | O44: =ROUND((N44*6% + N44 ),0) + P44 -> 453941.25 | P44: =P43+0.01 -> 0.25
...

Sheet ANOTACIONES
C2: ANOTACION | D2: 1
C3: FECHA DE LA ANOTACION: | E3: 0 | G3: NOMBRE:
C4: QUEJA VIA: | D4: WHATSAPP | E4: MAIL | G4: LOTE: | H4: Cochera 32
C5: MOTIVO DE LA QUEJA:
C6: A la cochera 32 no le debemos cobrar el TSG, debe abonar: $42.523,01
C11: ANOTACION | D11: 1
C12: FECHA DE LA ANOTACION: | E12: 0 | G12: NOMBRE: | H12: Javier Argentino
C13: QUEJA VIA: | D13: WHATSAPP | E13: MAIL | G13: LOTE: | H13: 13C
C14: MOTIVO DE LA QUEJA:
C15: 13C transfirio $319.842 el 09/10
C19: ANOTACION | D19: 1
C20: FECHA DE LA ANOTACION: | E20: 0 | G20: NOMBRE: | H20: Javier Argentino
C21: QUEJA VIA: | D21: WHATSAPP | E21: MAIL | G21: LOTE: | H21: Cocher 35
C22: MOTIVO DE LA QUEJA:
C23: Cochera 35 transfirio el 09/10 $42.523

Sheet ARBA
A1: IMPORTANTE: RESPETAR CENTAVOS AL ABONAR.
A3: Quienes adeudan ARBA deben abonar el monto coloreado en ROSADO si es que en el trancurso del mes 3 y 4 del 2026 no abonaron ninguna cuota.
A4: DPTOS | B4: COCH | C4: Propietario | D4: (%) | E4: ARBA REVALUO | F4: POSESION | G4: TOTAL A ABONAR HASTA | H4: TOTAL A ABONAR 1ERA CUOTA - VTO. 31/03 | I4: TOTAL A ABONAR 2DA CUOTA - VTO. 30/04 | J4: A PAGAR PROPIETARIO | L4: ABONADO POR PROPIETARIO | M4: AL PROPIETARIO LE RESTA ABONAR | N4: A PAGAR CONSTRUCTORA | O4: TOTAL
A7: LOC 1 | C7: Fernandez, Cristian | D7: 0.0108 | E7: 282914.38 | F7: 45856 | G7: -197064.48 | H7: =J7/2 -> 98532.35 | I7: =H7 -> 98532.35 | J7: =ROUND((-G7),0)+P7 -> 197064.7 | K7: -85849.897 | L7: 0 | M7: 98532.35 | N7: =-K7 -> 85849.897 | O7: =ROUND((J7+N7),0) + P7 -> 282915.7 | P7: 0.7
A8: LOC 2 | C8: Frigidi Guillermo Ariel | D8: 0.0128 | E8: 335305.93 | F8: 46001 | G8: -34751.379 | H8: =J8/2 -> 17375.855 | I8: =H8 -> 17375.855 | J8: =ROUND((-G8),0)+P8 -> 34751.71 | K8: -300554.55 | L8: 34752 | M8: 0 | N8: =-K8 -> 300554.55 | O8: =ROUND((J8+N8),0) + P8 -> 335306.71 | P8: =P7+0.01 -> 0.71
A9: LOC 3 | C9: Patricia Mainieri | D9: 0.0121 | E9: 316968.89 | F9: 45856 | G9: -220785.21 | H9: =J9/2 -> 110392.86 | I9: =H9 -> 110392.86 | J9: =ROUND((-G9),0)+P9 -> 220785.72 | K9: -96183.681 | L9: 0 | M9: =IF(L9=H9,I9,J9) -> 220785.72 | N9: =-K9 -> 96183.681 | O9: =ROUND((J9+N9),0) + P9 -> 316969.72 | P9: =P8+0.01 -> 0.72
A10: LOC 4 | C10: Cordero, Leandro Emanuel - Orona, Victoria | D10: 0.0149 | E10: 390317.06 | F10: 45856 | G10: -271876 | H10: =J10/2 -> 135938.36 | I10: =H10 -> 135938.36 | J10: =ROUND((-G10),0)+P10 -> 271876.73 | K10: -118441.06 | L10: 0 | M10: 0 | N10: =-K10 -> 118441.06 | O10: =ROUND((J10+N10),0) + P10 -> 390318.73 | P10: =P9+0.01 -> 0.73
A11: LOC 5 | C11: Orsi, José Luis - Fernández, Cristián Gabriel | D11: 0.0175 | E11: 458426.08 | F11: 45856 | G11: -319317.45 | H11: =J11/2 -> 159658.87 | I11: =H11 -> 159658.87 | J11: =ROUND((-G11),0)+P11 -> 319317.74 | K11: -139108.63 | L11: 0 | M11: 159658.87 | N11: =-K11 -> 139108.63 | O11: =ROUND((J11+N11),0) + P11 -> 458426.74 | P11: =P10+0.01 -> 0.74
A12: 2ºA | B12: 25 | C12: Franco, Lucas Fabián | D12: 0.0212 | E12: 555350.45 | F12: 45777 | G12: -519626.97 | H12: =ROUND((J12/2),0)+P12 -> 259814.01 | I12: =H12 -> 259814.01 | J12: =ROUND((-G12),0)+P12 -> 519627.01 | K12: -35723.479 | L12: 0 | M12: 0 | N12: =-K12 -> 35723.479 | O12: =ROUND((J12+N12),0) + P12 -> 555350.01 | P12: 0.01
A13: 2ºB | C13: Martinez, Diego | D13: 0.0084 | E13: 220044.52 | F13: 45775 | G13: -206492.25 | H13: =ROUND((J13/2),0)+P13 -> 103246.02 | I13: =H13 -> 103246.02 | J13: =ROUND((-G13),0)+P13 -> 206492.02 | K13: -13552.263 | L13: 0 | M13: 0 | N13: =-K13 -> 13552.263 | O13: =ROUND((J13+N13),0) + P13 -> 220044.02 | P13: =P12+0.01 -> 0.02
A14: 2ºC | B14: 22 | C14: Rodriguez, Carlos Alberto Miguel | D14: 0.0225 | E14: 589404.96 | F14: 45770 | G14: -557137.66 | H14: =ROUND((J14/2),0)+P14 -> 278569.03 | I14: =H14 -> 278569.03 | J14: =ROUND((-G14),0)+P14 -> 557138.03 | K14: -32267.294 | L14: 0 | M14: 0 | N14: =-K14 -> 32267.294 | O14: =ROUND((J14+N14),0) + P14 -> 589405.03 | P14: =P13+0.01 -> 0.03
A15: 2ºD | B15: 29-30 | C15: Ferraro, José | D15: 0.014 | E15: 366740.86 | F15: 45805 | G15: -327282.74 | H15: =ROUND((J15/2),0)+P15 -> 163642.04 | I15: =H15 -> 163642.04 | J15: =ROUND((-G15),0)+P15 -> 327283.04 | K15: -39458.12 | L15: 0 | M15: 0 | N15: =-K15 -> 39458.12 | O15: =ROUND((J15+N15),0) + P15 -> 366741.04 | P15: =P14+0.01 -> 0.04
A16: 2ºE | C16: Dieci, Matias Orlando | D16: 0.0087 | E16: 227903.25 | F16: 45800 | G16: -206069.05 | H16: =ROUND((J16/2),0)+P16 -> 103035.05 | I16: =H16 -> 103035.05 | J16: =ROUND((-G16),0)+P16 -> 206069.05 | K16: -21834.202 | L16: 0 | M16: 0 | N16: =-K16 -> 21834.202 | O16: =ROUND((J16+N16),0) + P16 -> 227903.05 | P16: =P15+0.01 -> 0.05
A17: 2ºF | B17: 34-39 | C17: Ferraro, Jose | D17: 0.0141 | E17: 369360.44 | F17: 45805 | G17: -329620.48 | H17: =ROUND((J17/2),0)+P17 -> 164810.06 | I17: =H17 -> 164810.06 | J17: =ROUND((-G17),0)+P17 -> 329620.06 | K17: -39739.963 | L17: 0 | M17: 0 | N17: =-K17 -> 39739.963 | O17: =ROUND((J17+N17),0) + P17 -> 369360.06 | P17: =P16+0.01 -> 0.06
A18: 3ºA | B18: 37-38 | C18: Ferraro, Jose - ------ALEJANDRO | D18: 0.0211 | E18: 552730.87 | F18: 45805 | G18: -493261.85 | H18: =ROUND((J18/2),0)+P18 -> 246631.07 | I18: =H18 -> 246631.07 | J18: =ROUND((-G18),0)+P18 -> 493262.07 | K18: -59469.023 | L18: 0 | M18: 0 | N18: =-K18 -> 59469.023 | O18: =ROUND((J18+N18),0) + P18 -> 552731.07 | P18: =P17+0.01 -> 0.07
A19: 3ºB | C19: Ayala, Roberto Adrian/BALDUZZI | D19: 0.0074 | E19: 193848.74 | F19: 45839 | G19: -147681.21 | H19: =ROUND((J19/2),0)+P19 -> 73841.08 | I19: =H19 -> 73841.08 | J19: =ROUND((-G19),0)+P19 -> 147681.08 | K19: -46167.53 | L19: 0 | M19: 0 | N19: =-K19 -> 46167.53 | O19: =ROUND((J19+N19),0) + P19 -> 193849.08 | P19: =P18+0.01 -> 0.08
A20: 3ºC | C20: Ferraro, Jose | D20: 0.0179 | E20: 468904.39 | F20: 45805 | G20: -418454.36 | H20: =ROUND((J20/2),0)+P20 -> 209227.09 | I20: =H20 -> 209227.09 | J20: =ROUND((-G20),0)+P20 -> 418454.09 | K20: -50450.024 | L20: 0 | M20: 0 | N20: =-K20 -> 50450.024 | O20: =ROUND((J20+N20),0) + P20 -> 468904.09 | P20: =P19+0.01 -> 0.09
A21: 3ºD | C21: Ayala, Roberto Adrian | D21: 0.0094 | E21: 246240.29 | F21: 45839 | G21: -187595.05 | H21: =ROUND((J21/2),0)+P21 -> 93798.1 | I21: =H21 -> 93798.1 | J21: =ROUND((-G21),0)+P21 -> 187595.1 | K21: -58645.241 | L21: 0 | M21: 0 | N21: =-K21 -> 58645.241 | O21: =ROUND((J21+N21),0) + P21 -> 246240.1 | P21: =P20+0.01 -> 0.1
A22: 3ºE | C22: Ayala, Roberto Adrian /CALZETTA | D22: 0.0087 | E22: 227903.25 | F22: 45839 | G22: -173625.21 | H22: =ROUND((J22/2),0)+P22 -> 86813.11 | I22: =H22 -> 86813.11 | J22: =ROUND((-G22),0)+P22 -> 173625.11 | K22: -54278.042 | L22: 0 | M22: 0 | N22: =-K22 -> 54278.042 | O22: =ROUND((J22+N22),0) + P22 -> 227903.11 | P22: =P21+0.01 -> 0.11
A23: 3ºF | C23: Ayala, Roberto Adrian | D23: 0.0095 | E23: 248859.87 | F23: 45839 | G23: -189590.74 | H23: =ROUND((J23/2),0)+P23 -> 94796.12 | I23: =H23 -> 94796.12 | J23: =ROUND((-G23),0)+P23 -> 189591.12 | K23: -59269.126 | L23: 0 | M23: 0 | N23: =-K23 -> 59269.126 | O23: =ROUND((J23+N23),0) + P23 -> 248860.12 | P23: =P22+0.01 -> 0.12
A24: 4ºA | C24: Barral, Carlos Daniel | D24: 0.0164 | E24: 429610.72 | F24: 45775 | G24: -403151.54 | H24: =ROUND((J24/2),0)+P24 -> 201576.13 | I24: =H24 -> 201576.13 | J24: =ROUND((-G24),0)+P24 -> 403152.13 | K24: -26459.181 | L24: 0 | M24: 0 | N24: =-K24 -> 26459.181 | O24: =ROUND((J24+N24),0) + P24 -> 429611.13 | P24: =P23+0.01 -> 0.13
A25: 4ºB | C25: Calzetta, Gabriel Andrés Felipe | D25: 0.0073 | E25: 191229.16 | F25: 45800 | G25: -172908.51 | H25: =ROUND((J25/2),0)+P25 -> 86455.14 | I25: =H25 -> 86455.14 | J25: =ROUND((-G25),0)+P25 -> 172909.14 | K25: -18320.652 | L25: 0 | M25: 0 | N25: =-K25 -> 18320.652 | O25: =ROUND((J25+N25),0) + P25 -> 191230.14 | P25: =P24+0.01 -> 0.14
A26: 4ºC | B26: 1-11 | C26: Osipowicz, Ariel Marcelo | D26: 0.022 | E26: 576307.07 | F26: 45775 | G26: -540813.05 | H26: =ROUND((J26/2),0)+P26 -> 270407.15 | I26: =H26 -> 270407.15 | J26: =ROUND((-G26),0)+P26 -> 540813.15 | K26: -35494.023 | L26: 0 | M26: 0 | N26: =-K26 -> 35494.023 | O26: =ROUND((J26+N26),0) + P26 -> 576307.15 | P26: =P25+0.01 -> 0.15
A27: 4ºD | C27: Ayala, Roberto Adrian | D27: 0.0094 | E27: 246240.29 | F27: 45839 | G27: -187595.05 | H27: =ROUND((J27/2),0)+P27 -> 93798.16 | I27: =H27 -> 93798.16 | J27: =ROUND((-G27),0)+P27 -> 187595.16 | K27: -58645.241 | L27: 0 | M27: 0 | N27: =-K27 -> 58645.241 | O27: =ROUND((J27+N27),0) + P27 -> 246240.16 | P27: =P26+0.01 -> 0.16 | Q27: Pablo Amarilla
A28: 4ºE | C28: Ayala, Roberto Adrian/SKARLATIUK | D28: 0.0087 | E28: 227903.25 | F28: 45839 | G28: -173625.21 | H28: =ROUND((J28/2),0)+P28 -> 86813.17 | I28: =H28 -> 86813.17 | J28: =ROUND((-G28),0)+P28 -> 173625.17 | K28: -54278.042 | L28: 0 | M28: 0 | N28: =-K28 -> 54278.042 | O28: =ROUND((J28+N28),0) + P28 -> 227903.17 | P28: =P27+0.01 -> 0.17
A29: 4ºF | C29: Ayala, Roberto Adrian | D29: 0.0095 | E29: 248859.87 | F29: 45839 | G29: -189590.74 | H29: =ROUND((J29/2),0)+P29 -> 94796.18 | I29: =H29 -> 94796.18 | J29: =ROUND((-G29),0)+P29 -> 189591.18 | K29: -59269.126 | L29: 0 | N29: =-K29 -> 59269.126 | O29: =ROUND((J29+N29),0) + P29 -> 248860.18 | P29: =P28+0.01 -> 0.18
A30: 5ºA | C30: Chehab, Gabriel Adrian | D30: 0.0164 | E30: 429610.72 | F30: 45800 | G30: -388452 | H30: =ROUND((J30/2),0)+P30 -> 194226.19 | I30: =H30 -> 194226.19 | J30: =ROUND((-G30),0)+P30 -> 388452.19 | K30: -41158.726 | L30: 0 | M30: 0 | N30: =-K30 -> 41158.726 | O30: =ROUND((J30+N30),0) + P30 -> 429611.19 | P30: =P29+0.01 -> 0.19 | Q30: Cochera 38
A31: 5ºB | B31: 16 | C31: Mesa, Mariano | D31: 0.0096 | E31: 251479.45 | F31: 45805 | G31: -224422.45 | H31: =ROUND((J31/2),0)+P31 -> 112211.2 | I31: =H31 -> 112211.2 | J31: =ROUND((-G31),0)+P31 -> 224422.2 | K31: -27056.996 | L31: 0 | M31: 0 | N31: =-K31 -> 27056.996 | O31: =ROUND((J31+N31),0) + P31 -> 251479.2 | P31: =P30+0.01 -> 0.2
A32: 5ºC | B32: 6 | C32: Di Mito, Vicente Argentino - Serantes, Mabel | D32: 0.0197 | E32: 516056.79 | F32: 45805 | G32: -460533.57 | H32: =ROUND((J32/2),0)+P32 -> 230267.21 | I32: =H32 -> 230267.21 | J32: =ROUND((-G32),0)+P32 -> 460534.21 | K32: -55523.211 | L32: 0 | M32: =IF(L32=H32,I32,J32) -> 460534.21 | N32: =-K32 -> 55523.211 | O32: =ROUND((J32+N32),0) + P32 -> 516057.21 | P32: =P31+0.01 -> 0.21
A33: 5ºD | C33: Ayala, Roberto Adrian | D33: 0.0094 | E33: 246240.29 | F33: 45839 | G33: -187595.05 | H33: =ROUND((J33/2),0)+P33 -> 93798.22 | I33: =H33 -> 93798.22 | J33: =ROUND((-G33),0)+P33 -> 187595.22 | K33: -58645.241 | L33: 0 | M33: 0 | N33: =-K33 -> 58645.241 | O33: =ROUND((J33+N33),0) + P33 -> 246240.22 | P33: =P32+0.01 -> 0.22 | Q33: Ayala paga 5D, 5F y 4F
A34: 5ºE | B34: 31 | C34: Ayala, Roberto Adrian/CALZETTA/ BASAEZ ROGELIO | D34: 0.011 | E34: 288153.53 | F34: 45839 | G34: -219526.13 | H34: =ROUND((J34/2),0)+P34 -> 109763.23 | I34: =H34 -> 109763.23 | J34: =ROUND((-G34),0)+P34 -> 219526.23 | K34: -68627.409 | L34: 0 | M34: 0 | N34: =-K34 -> 68627.409 | O34: =ROUND((J34+N34),0) + P34 -> 288154.23 | P34: =P33+0.01 -> 0.23 | Q34: COCHERA 31
A35: 5ºF | C35: Ayala, Roberto Adrian | D35: 0.0095 | E35: 248859.87 | F35: 45839 | G35: -189590.74 | H35: =ROUND((J35/2),0)+P35 -> 94796.24 | I35: =H35 -> 94796.24 | J35: =ROUND((-G35),0)+P35 -> 189591.24 | K35: -59269.126 | L35: 0 | N35: =-K35 -> 59269.126 | O35: =ROUND((J35+N35),0) + P35 -> 248860.24 | P35: =P34+0.01 -> 0.24
A36: 6ºA | B36: 28 | C36: Morandi, Victoria Ayelen | Calvo, Luciano Ezequiel | D36: 0.0187 | E36: 489861.01 | F36: 45786 | G36: -452316.22 | H36: =ROUND((J36/2),0)+P36 -> 226158.25 | I36: =H36 -> 226158.25 | J36: =ROUND((-G36),0)+P36 -> 452316.25 | K36: -37544.789 | L36: 0 | M36: 0 | N36: =-K36 -> 37544.789 | O36: =ROUND((J36+N36),0) + P36 -> 489861.25 | P36: =P35+0.01 -> 0.25
A37: 6ºB | C37: GRIZEK RUBEN EDUARDO (ex Orellano) | D37: 0.0073 | E37: 191229.16 | F37: 45789 | G37: -175787.47 | H37: =ROUND((J37/2),0)+P37 -> 87894.26 | I37: =H37 -> 87894.26 | J37: =ROUND((-G37),0)+P37 -> 175787.26 | K37: -15441.693 | L37: 0 | M37: 0 | N37: =-K37 -> 15441.693 | O37: =ROUND((J37+N37),0) + P37 -> 191229.26 | P37: =P36+0.01 -> 0.26
A38: 6ºC | B38: 33 | C38: Nuñez Leonel - Corrieri Giuliana | D38: 0.0197 | E38: 516056.79 | F38: 45793 | G38: -471560.19 | H38: =ROUND((J38/2),0)+P38 -> 235780.27 | I38: =H38 -> 235780.27 | J38: =ROUND((-G38),0)+P38 -> 471560.27 | K38: -44496.598 | L38: 0 | M38: 0 | N38: =-K38 -> 44496.598 | O38: =ROUND((J38+N38),0) + P38 -> 516057.27 | P38: =P37+0.01 -> 0.27 | Q38: COCHERA 33 | R38: COCHERA 33
A39: 6ºD | B39: 44 | C39: ANCHIPI GASTON (Cedido x Hecimovic)Hecimovic, Mariano Hernán (Cedido x Lopez Malara, Ramiro Alejandro) | D39: 0.0117 | E39: 306490.58 | F39: 45800 | G39: -277127.34 | H39: =ROUND((J39/2),0)+P39 -> 138564.28 | I39: =H39 -> 138564.28 | J39: =ROUND((-G39),0)+P39 -> 277127.28 | K39: -29363.237 | L39: 0 | M39: 238127.28 | N39: =-K39 -> 29363.237 | O39: =ROUND((J39+N39),0) + P39 -> 306491.28 | P39: =P38+0.01 -> 0.28
A40: 6ºE | C40: Dieci, Matias Orlando | D40: 0.0087 | E40: 227903.25 | F40: 45800 | G40: -206069.05 | H40: =ROUND((J40/2),0)+P40 -> 103035.29 | I40: =H40 -> 103035.29 | J40: =ROUND((-G40),0)+P40 -> 206069.29 | K40: -21834.202 | L40: 0 | M40: 0 | N40: =-K40 -> 21834.202 | O40: =ROUND((J40+N40),0) + P40 -> 227903.29 | P40: =P39+0.01 -> 0.29
A41: 6ºF | C41: ALEXIA JOANA MAZZIA | D41: 0.0095 | E41: 248859.87 | F41: 45800 | G41: -225017.93 | H41: =ROUND((J41/2),0)+P41 -> 112509.3 | I41: =H41 -> 112509.3 | J41: =ROUND((-G41),0)+P41 -> 225018.3 | K41: -23841.945 | L41: 0 | M41: 0 | N41: =-K41 -> 23841.945 | O41: =ROUND((J41+N41),0) + P41 -> 248860.3 | P41: =P40+0.01 -> 0.3
A42: 7ºA | B42: 7 | C42: Campelo, Mariano | D42: 0.0187 | E42: 489861.01 | F42: 45806 | G42: -435275.01 | H42: =ROUND((J42/2),0)+P42 -> 217638.31 | I42: =H42 -> 217638.31 | J42: =ROUND((-G42),0)+P42 -> 435275.31 | K42: -54586.004 | L42: 0 | M42: 0 | N42: =-K42 -> 54586.004 | O42: =ROUND((J42+N42),0) + P42 -> 489861.31 | P42: =P41+0.01 -> 0.31
A43: 7ºB | B43: 3 | C43: Paes, Yazmin Luciana | D43: 0.0096 | E43: 251479.45 | F43: 45775 | G43: -235991.15 | H43: =ROUND((J43/2),0)+P43 -> 117996.32 | I43: =H43 -> 117996.32 | J43: =ROUND((-G43),0)+P43 -> 235991.32 | K43: -15488.301 | L43: 0 | M43: 0 | N43: =-K43 -> 15488.301 | O43: =ROUND((J43+N43),0) + P43 -> 251480.32 | P43: =P42+0.01 -> 0.32
...

Sheet DEUDA AYALA
C3: DEUDA SR. AYALA AL 04/09/2026
C4: UF: | D4: Propietario: | G4: Deuda a abonar antes del 17/09
C5: =PRORRATEO!C31 -> 3ºF | D5: =PRORRATEO!D31 -> Campelo, Mariano | G5: =PRORRATEO!N31 -> -7072.88
G7: Deuda ARBA 3F
G8: 0
C9: UF: | D9: Propietario: | G9: Deuda a abonar antes del 17/09
C10: =PRORRATEO!C37 -> 4ºF | D10: =PRORRATEO!D37 -> Campelo, Mariano | G10: =PRORRATEO!N37 -> -7071.82
G12: Deuda ARBA 4F
G13: 0
C14: UF: | D14: Propietario: | G14: Deuda a abonar antes del 17/09
C15: =PRORRATEO!C43 -> 5ºF | D15: =PRORRATEO!D43 -> Ayala, Roberto Adrian | G15: =PRORRATEO!N43 -> -7072.76
G17: Deuda ARBA 5F
G18: 0
C20: TOTAL DEUDA | G20: =G15+G10+G5 -> -21217.46
