Workbook

Sheet RESUMEN
B1: TELEFONO: 11-5320-2676
B2: CUIT ADMINISTRACION: 27231256879
B3: ADMINISTRADORA: CAROLINA CANCIANI MP:1148
B4: TRANSFERIR A : carolina.rc.adm - CVU: 0000003100054616492658
A5: CONSORCIO DE PROPIETARIOS DEL EDIFICIO GAEBELER 1949 | D5: LUNES A VIERNES 10 A 15HS
B7: VTO 06/04
A12: ESTIMADOS PROPIETARIOS E INQUILINOS: POR FAVOR LOS QUE ABONAN EN PRIMER VENCIMIENTO ABONEN EL MONTO DE PRIMER VENCIMIENTO, ASI AGILIZAN LA LIQUIDACION, RESPETEN LOS CENTAVOS CORRESPONDIENTES A LA UNIDAD FUNCIONAL. ES DE CARÁCTER OBLIGATORIO INFORMAR VIA MAIL LAS EXPENSAS. CASO CONTRARIO SE INFORMARA VIA CARTA DOCUMENTO A LA UNIDAD FUNCIONAL QUE CREEMOS QUE CORRESPONDE, CUYO COSTO SERA IMPUTADO A LA UNIDAD FUNCIONAL SOSPECHADA.
A19: GASTOS ORDINARIOS UNIDADES FUNCIONALES:
A20: GASTOS A RECUPERAR ABONADOS POR CONSTRUTORA Y ADMINISTRACION DESDE QUE TOMARON POSESION
A21: Seguro integral de cosorcio - Federacion patronal - Poliza 2217080 | D21: 52745
A22: Plan de pago Anticipo edesur | D22: 496816.96
A23: SUBTOTAL | E23: =SUM(D21:D22) -> 549561.96
A24: TOTAL | E24: =E23 -> 549561.96
A26: PREVISION ORDINARIA DE CAJA
A28: TOTAL ORDINARIOS | E28: =E24+E26 -> 549561.96
A31: GASTOS EXTRAORDINARIOS:
E36: =SUM(D32:D35) -> 0
A39: PREVISION EXTRAORDINARIA
A41: TOTAL EXTRAORDINARIOS | E41: =E36+E39 -> 0
A43: GASTOS ORDINARIOS + PREVISION : | B43: =E28 -> 549561.96
A44: GASTOS ORDINARIOS SIN PREVISION: | B44: =E28-E26 -> 549561.96
A45: GASTOS EXTRAORDINARIOS SIN PREVISION: | B45: =E41-E39 -> 0
A46: GASTOS EXTRAORDINARIOS CON PREVISION: | B46: =E41 -> 0
A53: RESUMEN
B54: 0
A55: Ingreso | B55: =PRORRATEO!F25 -> 986668.29
B56: 0
A57: Deposito sin identificar | B57: =B78 -> 165459
A59: Punitorios mal cobrados
A60: Egresos Ordinarios | B60: =-B44 -> -549561.96
A61: Egresos Extraordinarios | B61: =-(B45) -> 0
A62: TOTAL | B62: =SUM(B54:B61) -> 602565.33
A66: SALDO INICIAL | B66: -2735184
A67: Egresos del mes ordinarios | B67: =-B44 -> -549561.96
A68: Egresos del mes extrordinarios | B68: =-B45 -> 0
A69: Pagos sin identificar | B69: =B78 -> 165459 | D69: =B69+B70 -> 1152127.3
A70: Ingresos | B70: =PRORRATEO!F25 -> 986668.29
A71: Punitorios mal cobrados
A72: CAJA REAL | B72: =SUM(B66:C71) -> -2132618.6
A75: DEPOSITOS NO IDENTIFICADOS
...

Sheet PRORRATEO
B1: =RESUMEN!B4 -> TRANSFERIR A : carolina.rc.adm - CVU: 0000003100054616492658
B2: ¡POR FAVOR RESPETAR LOS CENTAVOS AL ABONAR! | K2: Ordinarios | L2: 1105490
A4: UF | B4: Propietario | C4: Inquilinos | D4: (%) | E4: Saldo Ord | F4: Ingreso | G4: Pago por | H4: Deuda o Saldo a favor | I4: Interes 3% | J4: Expensas extraor. | K4: Expensas ord. | L4: Total 1er Vto | M4: Total 2do Vto. | N4: Total 2do Vto
L5: =RESUMEN!B7 -> VTO 06/04
A6: 1A | B6: Chida Gustavo Daniel | D6: =8+1.02777778 -> 9.0277778 | E6: 260082.01 | H6: =E6-F6 -> 260082.01 | I6: =IF(H6>0,H6*3%,0) -> 7802.4603 | J6: 0 | K6: =L$2*D6/100 -> 99801.181 | L6: =ROUND(SUM(H6:K6),0) + O6 -> 367686.01 | M6: =ROUND(L6*6% + L6,0) + O6 -> 389747.01 | N6: =ROUND(L6*3%,0) + L6 -> 378717.01 | O6: 0.01
A7: 1B | B7: D' Andrea Patricia Daniela | D7: =1.02777778+4.9 -> 5.9277778 | E7: 241298.02 | F7: =E7 -> 241298.02 | H7: =E7-F7 -> 0 | I7: =IF(H7>0,H7*3%,0) -> 0 | J7: 0 | K7: =L$2*D7% -> 65530.991 | L7: =ROUND(SUM(H7:K7),0) + O7 -> 65531.02 | M7: =ROUND(L7*6% + L7,0) + O7 -> 69463.02 | N7: =ROUND(L7*3%,0) + L7 -> 67497.02 | O7: =O6+0.01 -> 0.02 | P7: Luz catan
A8: 1C | B8: Arroyo Aldana | D8: =1.02777778+3.2 -> 4.2277778 | E8: 200808.03 | F8: 200808.03 | H8: =E8-F8 -> 0 | I8: =IF(H8>0,H8*3%,0) -> 0 | J8: 0 | K8: =L$2*D8% -> 46737.661 | L8: =ROUND(SUM(H8:K8),0) + O8 -> 46738.03 | M8: =ROUND(L8*6% + L8,0) + O8 -> 49542.03 | N8: =ROUND(L8*3%,0) + L8 -> 48140.03 | O8: =O7+0.01 -> 0.03
A9: 2A | B9: Stagno Jorge Adrian | D9: =8+1.02777778 -> 9.0277778 | E9: 216502.04 | H9: =E9-F9 -> 216502.04 | I9: =IF(H9>0,H9*3%,0) -> 6495.0612 | J9: 0 | K9: =L$2*D9% -> 99801.181 | L9: =ROUND(SUM(H9:K9),0) + O9 -> 322798.04 | M9: =ROUND(L9*6% + L9,0) + O9 -> 342166.04 | N9: =ROUND(L9*3%,0) + L9 -> 332482.04 | O9: =O8+0.01 -> 0.04
A10: 2B | B10: Stagno Jorge Adrian | D10: =1.02777778+4.9 -> 5.9277778 | E10: 165458.05 | H10: =E10-F10 -> 165458.05 | I10: =IF(H10>0,H10*3%,0) -> 4963.7415 | J10: 0 | K10: =L$2*D10% -> 65530.991 | L10: =ROUND(SUM(H10:K10),0) + O10 -> 235953.05 | M10: =ROUND(L10*6% + L10,0) + O10 -> 250110.05 | N10: =ROUND(L10*3%,0) + L10 -> 243032.05 | O10: =O9+0.01 -> 0.05
A11: 2C | B11: Beneyte Lenorado Damian | D11: =1.02777778+3.2 -> 4.2277778 | E11: 252613.06 | F11: =E11 -> 252613.06 | H11: =E11-F11 -> 0 | I11: =IF(H11>0,H11*3%,0) -> 0 | J11: 0 | K11: =L$2*D11% -> 46737.661 | L11: =ROUND(SUM(H11:K11),0) + O11 -> 46738.06 | M11: =ROUND(L11*6% + L11,0) + O11 -> 49542.06 | N11: =ROUND(L11*3%,0) + L11 -> 48140.06 | O11: =O10+0.01 -> 0.06 | P11: Hugo Britez Ramon Irala
A12: 3A | B12: Sr Propietario | D12: =8+1.02777778 -> 9.0277778 | E12: 211871.07 | H12: =E12-F12 -> 211871.07 | I12: =IF(H12>0,H12*3%,0) -> 6356.1321 | J12: 0 | K12: =L$2*D12% -> 99801.181 | L12: =ROUND(SUM(H12:K12),0) + O12 -> 318028.07 | M12: =ROUND(L12*6% + L12,0) + O12 -> 337110.07 | N12: =ROUND(L12*3%,0) + L12 -> 327569.07 | O12: =O11+0.01 -> 0.07
A13: 3B | B13: Torres Lilliana Beatriz | D13: =1.02777778+4.9 -> 5.9277778 | E13: 286943.08 | H13: =E13-F13 -> 286943.08 | I13: =IF(H13>0,H13*3%,0) -> 8608.2924 | J13: 0 | K13: =L$2*D13% -> 65530.991 | L13: =ROUND(SUM(H13:K13),0) + O13 -> 361082.08 | M13: =ROUND(L13*6% + L13,0) + O13 -> 382747.08 | N13: =ROUND(L13*3%,0) + L13 -> 371914.08 | O13: =O12+0.01 -> 0.08
A14: 3C | B14: Arostegui Hector/Herrera Monica | D14: =1.02777778+3.2 -> 4.2277778 | E14: 156615.09 | H14: =E14-F14 -> 156615.09 | I14: =IF(H14>0,H14*3%,0) -> 4698.4527 | J14: 0 | K14: =L$2*D14% -> 46737.661 | L14: =ROUND(SUM(H14:K14),0) + O14 -> 208051.09 | M14: =ROUND(L14*6% + L14,0) + O14 -> 220534.09 | N14: =ROUND(L14*3%,0) + L14 -> 214293.09 | O14: =O13+0.01 -> 0.09 | P14: Maria Celeste Moreyra
A15: 4A | B15: Frosio Diego Martin | D15: =8+1.02777778 -> 9.0277778 | E15: 471282.1 | H15: =E15-F15 -> 471282.1 | I15: =IF(H15>0,H15*3%,0) -> 14138.463 | J15: 0 | K15: =L$2*D15% -> 99801.181 | L15: =ROUND(SUM(H15:K15),0) + O15 -> 585222.1 | M15: =ROUND(L15*6% + L15,0) + O15 -> 620335.1 | N15: =ROUND(L15*3%,0) + L15 -> 602779.1 | O15: =O14+0.01 -> 0.1
A16: 4B | B16: Actis Sofia Magali | D16: =1.02777778+4.9 -> 5.9277778 | E16: 184126.11 | F16: =E16 -> 184126.11 | H16: =E16-F16 -> 0 | I16: =IF(H16>0,H16*3%,0) -> 0 | J16: 0 | K16: =L$2*D16% -> 65530.991 | L16: =ROUND(SUM(H16:K16),0) + O16 -> 65531.11 | M16: =ROUND(L16*6% + L16,0) + O16 -> 69463.11 | N16: =ROUND(L16*3%,0) + L16 -> 67497.11 | O16: =O15+0.01 -> 0.11
A17: 4C | B17: Alanis Hebert | D17: =1.02777778+3.2 -> 4.2277778 | E17: 99546.12 | H17: =E17-F17 -> 99546.12 | I17: =IF(H17>0,H17*3%,0) -> 2986.3836 | J17: 0 | K17: =L$2*D17% -> 46737.661 | L17: =ROUND(SUM(H17:K17),0) + O17 -> 149270.12 | M17: =ROUND(L17*6% + L17,0) + O17 -> 158226.12 | N17: =ROUND(L17*3%,0) + L17 -> 153748.12 | O17: =O16+0.01 -> 0.12
A18: 5A | B18: Sr Propietario | D18: =1.02777778+5.4+5.7 -> 12.127778 | E18: 782007.13 | F18: =2879.57+4943.5+100000 -> 107823.07 | H18: =E18-F18 -> 674184.06 | I18: =IF(H18>0,H18*3%,0) -> 20225.522 | K18: =L$2*D18% -> 134071.37 | L18: =ROUND(SUM(H18:K18),0) + O18 -> 828481.13 | N18: =ROUND(L18*3%,0) + L18 -> 853335.13 | O18: =O17+0.01 -> 0.13 | P18: Graciela Vigamonti
O19: =O18+0.01 -> 0.14
A20: C1 | B20: Frosio Diego Martin | D20: =1.02777778+1.2 -> 2.2277778 | E20: 43759.15 | H20: =E20-F20 -> 43759.15 | I20: =IF(H20>0,H20*3%,0) -> 1312.7745 | K20: =L$2*D20% -> 24627.861 | L20: =ROUND(SUM(H20:K20),0) + O20 -> 69700.15 | N20: =ROUND(L20*3%,0) + L20 -> 71791.15 | O20: =O19+0.01 -> 0.15
A21: C2 | B21: Sr Propietario | D21: =1.02777778+1.2 -> 2.2277778 | E21: 43759.16 | H21: =E21-F21 -> 43759.16 | I21: =IF(H21>0,H21*3%,0) -> 1312.7748 | K21: =L$2*D21% -> 24627.861 | L21: =ROUND(SUM(H21:K21),0) + O21 -> 69700.16 | N21: =ROUND(L21*3%,0) + L21 -> 71791.16 | O21: =O20+0.01 -> 0.16 | P21: Graciela Vigamonti
A22: C3 | B22: Torres Lilliana Beatriz | D22: =1.02777778+1.2 -> 2.2277778 | E22: 51678.17 | H22: =E22-F22 -> 51678.17 | I22: =IF(H22>0,H22*3%,0) -> 1550.3451 | K22: =L$2*D22% -> 24627.861 | L22: =ROUND(SUM(H22:K22),0) + O22 -> 77856.17 | N22: =ROUND(L22*3%,0) + L22 -> 80192.17 | O22: =O21+0.01 -> 0.17
A23: C4 | B23: Frosio Diego Martin | D23: =1.02777778+1.2 -> 2.2277778 | E23: 43759.18 | H23: =E23-F23 -> 43759.18 | I23: =IF(H23>0,H23*3%,0) -> 1312.7754 | K23: =L$2*D23% -> 24627.861 | L23: =ROUND(SUM(H23:K23),0) + O23 -> 69700.18 | N23: =ROUND(L23*3%,0) + L23 -> 71791.18 | O23: =O22+0.01 -> 0.18
A24: C5 | B24: Sr Propietario | D24: =1.02777778+1.2 -> 2.2277778 | E24: 51678.19 | H24: =E24-F24 -> 51678.19 | I24: =IF(H24>0,H24*3%,0) -> 1550.3457 | J24: 0 | K24: =L$2*D24% -> 24627.861 | L24: =ROUND(SUM(H24:K24),0) + O24 -> 77856.19 | M24: =ROUND(L24*6% + L24,0) + O24 -> 82528.19 | N24: =ROUND(L24*3%,0) + L24 -> 80192.19 | O24: =O23+0.01 -> 0.19
D25: =SUM(D6:D24) -> 100 | E25: =SUM(E6:E24) -> 3763785.8 | F25: =SUM(F6:F24) -> 986668.29 | G25: =SUM(G6:G24) -> 0 | H25: =SUM(H6:H24) -> 2777117.5 | I25: =SUM(I6:I24) -> 83313.524 | J25: =SUM(J6:J24) -> 0 | K25: =SUM(K6:K24) -> 1105490 | ... N25: =SUM(N6:N24) -> 4084901.8
B27: ESTIMADOS PROPIETARIOS E INQUILINOS: EN LAS PROXIMAS SEMANAS RECIBIRAN UN PRORRATEO DEL EDESUR CONSUMIDO EN CADA DEPARTAMENTO PARA IR ABONANDO - LA SEMANA DEL 12 DE ENERO COMIENZA LA EMPRESA DE LIMPIEZA, SE INFORMARA DIAS Y HORAS DE LOS OPERARIOS

Sheet Edesur
A1: EDESUR
B2: EDESUR | D2: 2521214
B3: EDESUR | C3: 0 | K3: =D2-I24 -> 858773.02
A4: U.F. | B4: U.F. | C4: PISO - DEPTO | D4: PROPIETARIOS | E4: % | F4: CONSUMO ANT. | G4: CONSUMO ACTUAL | H4: KWH | I4: EDESUR | J4: PARTES COMUNES | K4: PARTES COMUNES | L4: KWH | M4: EDESUR FINAL
A5: 1 | B5: 1 | C5: =PRORRATEO!A6 -> 1A | D5: =PRORRATEO!B6 -> Chida Gustavo Daniel | E5: 9.0277778 | F5: 0 | G5: 752.3 | H5: =G5-F5 -> 752.3 | I5: =L5*110 -> 82753 | J5: =J3*E5% -> 0 | K5: =K$3*E5/Q$7 -> 77528.12 | L5: =G5-F5 -> 752.3 | M5: =I5+K5 -> 160281.12
A6: 2 | B6: 2 | C6: =PRORRATEO!A7 -> 1B | D6: =PRORRATEO!B7 -> D' Andrea Patricia Daniela | E6: 5.9277778 | F6: 0 | G6: 1135.1 | H6: =G6-F6 -> 1135.1 | I6: =L6*110 -> 124861 | J6: =J3*E6% -> 0 | K6: =K$3*E6/Q$7 -> 50906.156 | L6: =G6-F6 -> 1135.1 | M6: =I6+K6 -> 175767.16
A7: 3 | B7: 3 | C7: =PRORRATEO!A8 -> 1C | D7: =PRORRATEO!B8 -> Arroyo Aldana | E7: 4.2277778 | F7: 0 | G7: 1017.4 | H7: =G7-F7 -> 1017.4 | I7: =L7*110 -> 111914 | J7: =J3*E7% -> 0 | K7: =K$3*E7/Q$7 -> 36307.015 | L7: =G7-F7 -> 1017.4 | M7: =I7+K7 -> 148221.01 | Q7: 100
A8: 4 | B8: 4 Y 5 | C8: =PRORRATEO!A9 -> 2A | D8: =PRORRATEO!B9 -> Stagno Jorge Adrian | E8: 9.0277778 | F8: 0 | G8: 64.4 | H8: =G8-F8 -> 64.4 | I8: =L8*110 -> 7084 | J8: =J3*E8% -> 0 | K8: =K$3*E8/Q$7 -> 77528.12 | L8: =G8-F8 -> 64.4 | M8: =I8+K8 -> 84612.12
A9: 6 | B9: 6 | C9: =PRORRATEO!A10 -> 2B | D9: =PRORRATEO!B10 -> Stagno Jorge Adrian | E9: 5.9277778 | F9: 0 | G9: 254.1 | H9: =G9-F9 -> 254.1 | I9: =L9*110 -> 27951 | J9: =J3*E9% -> 0 | K9: =K$3*E9/Q$7 -> 50906.156 | L9: =G9-F9 -> 254.1 | M9: =I9+K9 -> 78857.156
A10: 7 | B10: 7 | C10: =PRORRATEO!A11 -> 2C | D10: =PRORRATEO!B11 -> Beneyte Lenorado Damian | E10: 4.2277778 | F10: 0 | G10: 1454.6 | H10: =G10-F10 -> 1454.6 | I10: =L10*110 -> 160006 | J10: =J3*E10% -> 0 | K10: =K$3*E10/Q$7 -> 36307.015 | L10: =G10-F10 -> 1454.6 | M10: =I10+K10 -> 196313.01
A11: 8 | B11: 8 | C11: =PRORRATEO!A12 -> 3A | D11: =PRORRATEO!B12 -> Sr Propietario | E11: 9.0277778 | F11: 0 | G11: 22.3 | H11: =G11-F11 -> 22.3 | I11: =L11*110 -> 2453 | J11: =J3*E11% -> 0 | K11: =K$3*E11/Q$7 -> 77528.12 | L11: =G11-F11 -> 22.3 | M11: =I11+K11 -> 79981.12
A12: 9 | B12: 9 | C12: =PRORRATEO!A13 -> 3B | D12: =PRORRATEO!B13 -> Torres Lilliana Beatriz | E12: 5.9277778 | F12: 0 | G12: 1544.3 | H12: =G12-F12 -> 1544.3 | I12: =L12*110 -> 169873 | J12: =J3*E12% -> 0 | K12: =K$3*E12/Q$7 -> 50906.156 | L12: =G12-F12 -> 1544.3 | M12: =I12+K12 -> 220779.16
A13: 10 | B13: 10 | C13: =PRORRATEO!A14 -> 3C | D13: =PRORRATEO!B14 -> Arostegui Hector/Herrera Monica | E13: 4.2277778 | F13: 0 | G13: 672.8 | H13: =G13-F13 -> 672.8 | I13: =L13*110 -> 74008 | J13: =J3*E13% -> 0 | K13: =K$3*E13/Q$7 -> 36307.015 | L13: =G13-F13 -> 672.8 | M13: =I13+K13 -> 110315.01
A14: 11 | B14: 11 | C14: =PRORRATEO!A15 -> 4A | D14: =PRORRATEO!B15 -> Frosio Diego Martin | E14: 9.0277778 | F14: 0 | G14: 2672.3 | H14: =G14-F14 -> 2672.3 | I14: =L14*110 -> 293953 | J14: =J3*E14% -> 0 | K14: =K$3*E14/Q$7 -> 77528.12 | L14: =G14-F14 -> 2672.3 | M14: =I14+K14 -> 371481.12
A15: 12 | B15: 12 | C15: =PRORRATEO!A16 -> 4B | D15: =PRORRATEO!B16 -> Actis Sofia Magali | E15: 5.9277778 | F15: 0 | G15: 566.6 | H15: =G15-F15 -> 566.6 | I15: =L15*110 -> 62326 | J15: =J3*E15% -> 0 | K15: =K$3*E15/Q$7 -> 50906.156 | L15: =G15-F15 -> 566.6 | M15: =I15+K15 -> 113232.16
A16: 13 | B16: 13 | C16: =PRORRATEO!A17 -> 4C | D16: =PRORRATEO!B17 -> Alanis Hebert | E16: 4.2277778 | F16: 0 | G16: 13.4 | H16: =G16-F16 -> 13.4 | I16: =L16*110 -> 1474 | J16: =J3*E16% -> 0 | K16: =K$3*E16/Q$7 -> 36307.015 | L16: =G16-F16 -> 13.4 | M16: =I16+K16 -> 37781.015
A17: 14 | B17: 14 | C17: =PRORRATEO!A18 -> 5A | D17: =PRORRATEO!B18 -> Sr Propietario | E17: 12.127778 | F17: 0 | G17: 4943.5 | H17: =G17-F17 -> 4943.5 | I17: =L17*110 -> 543785 | J17: =J3*E17% -> 0 | K17: =K$3*E17/Q$7 -> 104150.08 | L17: =G17-F17 -> 4943.5 | M17: =I17+K17 -> 647935.08
A18: 15 | B18: 15
A19: 16 | B19: 16 | C19: =PRORRATEO!A20 -> C1 | D19: =PRORRATEO!B20 -> Frosio Diego Martin | E19: 2.2277778 | F19: 0 | G19: 0 | H19: =G19-F19 -> 0 | I19: =L19*93.787 -> 0 | J19: =J3*E19% -> 0 | K19: =K$3*E19/Q$7 -> 19131.555 | L19: =G19-F19 -> 0 | M19: =I19+K19 -> 19131.555
A20: 17 | B20: 17 | C20: =PRORRATEO!A21 -> C2 | D20: =PRORRATEO!B21 -> Sr Propietario | E20: 2.2277778 | F20: 0 | G20: 0 | H20: =G20-F20 -> 0 | I20: =L20*93.787 -> 0 | J20: =J3*E20% -> 0 | K20: =K$3*E20/Q$7 -> 19131.555 | L20: =G20-F20 -> 0 | M20: =I20+K20 -> 19131.555
A21: 18 | B21: 18 | C21: =PRORRATEO!A22 -> C3 | D21: =PRORRATEO!B22 -> Torres Lilliana Beatriz | E21: 2.2277778 | F21: 0 | G21: 0 | H21: =G21-F21 -> 0 | I21: =L21*93.787 -> 0 | J21: =J3*E21% -> 0 | K21: =K$3*E21/Q$7 -> 19131.555 | L21: =G21-F21 -> 0 | M21: =I21+K21 -> 19131.555
A22: 19 | B22: 19 | C22: =PRORRATEO!A23 -> C4 | D22: =PRORRATEO!B23 -> Frosio Diego Martin | E22: 2.2277778 | F22: 0 | G22: 0 | H22: =G22-F22 -> 0 | K22: =K$3*E22/Q$7 -> 19131.555 | L22: 0 | M22: =I22+K22 -> 19131.555
A23: 20 | C23: =PRORRATEO!A24 -> C5 | D23: =PRORRATEO!B24 -> Sr Propietario | E23: 2.2277778 | F23: 0 | G23: 0 | H23: 0 | K23: =K$3*E23/Q$7 -> 19131.555 | L23: 0 | M23: =I23+K23 -> 19131.555
A24: 24 | E24: =SUM(E5:E23) -> 100 | I24: =SUM(I5:I23) -> 1662441 | K24: =SUM(K5:K23) -> 858773.02 | M24: =SUM(M5:M23) -> 2521214
E25: =SUM(E5:E24) -> 200 | K25: =K24+I24 -> 2521214
A26: NOTA:
