Workbook
Name CantOper: #REF!
Name CantOper: #REF!
Name PaseMateriales: #REF!
Name PaseMateriales: #REF!
Name PaseMdeO: #REF!
Name PaseMdeO: #REF!
Name PaseSubcontratos: #REF!
Name PaseSubcontratos: #REF!
Name Plazo: #REF!
Name Plazo: #REF!

Sheet Gastos
D2: Domicilio: | E2: TUCUMAN 1061
D3: Cel. | E3: 1153202676
D4: e-mail: | E4: tucuman1061rc@gmail.com
D5: MP:1148
D6: Banco santander - C DE P TUCUMAN 1061 1063 - Nro. De cuenta : 39-022068/6 CBU: 0720039720000002206868
A9: LIQUIDACION DE EXPENSAS | E9: PERIODO: DICIEMBRE | H9: VTO: 15/01
A12: Domicilio: | B12: ROSALES 624
A14: 1- SERVICIO DE LIMPIEZA Y JARDINERIA
A16: SUELDO | B16: Sr. Encargado Hernan | H16: =392270+392270*2% -> 400115.4
A17: Poliza Sr. De Luca Carlos Hernan - La holando DICIEMBRE | H17: 4030.28
A18: Total: | H18: =SUM(H15:H17) -> 404145.68
A20: 2- SERVICIO PUBLICIO
A21: AYSA | H21: 17684.56
A22: Edesur | H22: 1051844.8
A23: Total Servicios publicos: | H23: =SUM(H21:H22) -> 1069529.3
A24: 3- MANTENIMIENTO DE PARTES COMUNES
A25: Seguro OBLIGATORIO DE CONSORCIO - POLIZA Nro. 191195427 - Mercantil Andina | H25: 48079.52
A26: Articulios de limpieza | H26: 0
A27: Casa Ruan - Compra de materiales electricos | H27: 200000
A28: Servisur - Fotocelula con cableado | H28: 30000
A29: Lema mantenimiento ascensores | H29: 80000
A30: Total mantenimiento: | H30: =SUM(H25:H29) -> 358079.52
A31: 4- GASTO DE ADMINISTRACION
A32: Nombre y Apellido: | C32: Carolina Canciani | H32: 97600
A33: Gustavo padron - Contador - Honorarios | H33: 0
A34: Administraciòn DICIEMBRE 2025: | H34: =SUM(H32:H33) -> 97600 | N34: subidos en n0v 2025
A36: 5 - GASTOS BANCARIOS
A37: Gastos bancarios | H37: 19863.26
A38: TOTAL DE GASTOS ORDINARIOS 1,2,3,4,5,6; | H38: =H18+H23+H30+H34+H37 -> 1949217.8
A39: Prevision ordinaria - Edesur | H39: 500000
A40: GASTOS EXTRAORDINARIOS
A42: Sr. Leonardo Balcazza trabajo en medianera (Altura) - Diferencia | H42: =520000-350000 -> 170000
A44: TOTAL | H44: =SUM(H42:H43) -> 170000
A47: TOTAL DE GASTOS ORDINARIOS A PRORRATEAR | H47: =+H38+H39 -> 2449217.8
A49: TOTAL DE GASTOS EXTRAORDINARIOS | H49: =H44 -> 170000
A51: ESTADO FINANCIERO
A52: SALDO ANTERIOR | H52: 1627667.8
A53: Ingreso pago por expensas | H53: =Planilla!I31 -> 2458640.5
A54: Punitorios mal cobrados | H54: -4586
A55: Egresos gastos del mes | H55: =-(H38+H44) -> -2119217.8
...

Sheet Planilla
A1: =Gastos!E9 -> PERIODO: DICIEMBRE
C2: =687024.57+500000 -> 1187024.6 | F2: QUIENES ESTAN MARCADOS EN ROJO NO ESTAN RESPETANDO LOS CENTAVOS AL ABONAR - LEER PORFAVOR EL CARTEL AMARILLO | M2: IMPORTANTE ⚠️ Al abonar, respetar los centavos que figuran en la columna “Total a pagar”. Respetar los centavos facilita la correcta identificación de los pagos y las unidades funcionales. Si poseen departamento y cochera, les pedimos —en la medida de lo posible— que realicen dos pagos separados, respetando los centavos correspondientes a cada uno. ¡Muchas gracias por la colaboración! 🙌
D3: 500000
C4: EDESUR:
C5: =D3 -> 500000
C6: Gastos Ordinarios sin edesur: | F6: SOLICITAMOS POR FAVOR QUE, SI REALIZAN EL PAGO ANTES DE LA FECHA DEL PRIMER VENCIMIENTO (EN ESTE CASO, EL 15/12), ABONEN ÚNICAMENTE EL MONTO CORRESPONDIENTE A DICHO VENCIMIENTO Y NO EL DEL SEGUNDO.
C7: =C2-D3 -> 687024.57
C8: Gastos Extraordinarios:
C9: 170000
A10: U.F. | B10: PISO - DEPTO | C10: PROPIETARIOS | D10: PROPIETARIOS | E10: INQUILINOS | F10: % | G10: SALDO ANTERIOR | H10: PAGO EXTRA | I10: PAGOS | J10: EDESUR | K10: DEUDA | L10: DEUDA Extra | M10: Mora | N10: Total con Mora | O10: Gasto Ordinario - Sin Edesur | P10: Gasto Extraordinario | Q10: EDESUR | R10: ="1ER vto - " & Gastos!H9 & "'" -> 1ER vto - VTO: 15/01' | S10: 2do vto
A11: 1a | C11: 1ro. "A" | D11: Juan Pablo Rodriguez/ Valeria Ruggiero | F11: 7.9 | G11: 150476.01 | H11: 0 | I11: 154990.01 | J11: =C8*F11/100 -> #VALUE! | K11: =G11-H11-I11 -> -4514 | M11: =(K11+L11)*3% -> -135.42 | N11: =K11+M11+L11 -> -4649.42 | O11: =C$7*F11/100 -> 54274.941 | P11: =C$9*F11/100 -> 13430 | Q11: =C$5*F11/100 -> 39500 | R11: =ROUND(O11+N11+P11+Q11,0) + T11 -> 102556.01 | S11: =ROUND(R11+R11*3%,0) + T11 -> 105633.01 | T11: 0.01
A12: 1b | C12: 1ro. "B" | D12: Mendez Juan Carlos | F12: 7.9 | G12: 150476.02 | H12: 0 | I12: =G12 -> 150476.02 | J12: =C8*F12/100 -> #VALUE! | K12: =G12-H12-I12 -> 0 | M12: =(K12+L12)*3% -> 0 | N12: =K12+M12+L12 -> 0 | O12: =C$7*F12/100 -> 54274.941 | P12: =C$9*F12/100 -> 13430 | Q12: =C$5*F12/100 -> 39500 | R12: =ROUND(O12+N12+P12+Q12,0) + T12 -> 107205.02 | S12: =ROUND(R12+R12*3%,0) + T12 -> 110421.02 | T12: =T11+0.01 -> 0.02
A13: 2a | C13: 2do. "A" | D13: Matias Ezequiel Bonfiglio | E13: Maria Elena | F13: 7.9 | G13: 150476.03 | H13: 0 | J13: =C8*F13/100 -> #VALUE! | K13: =G13-H13-I13 -> 150476.03 | M13: =(K13+L13)*3% -> 4514.2809 | N13: =K13+M13+L13 -> 154990.31 | O13: =C$7*F13/100 -> 54274.941 | P13: =C$9*F13/100 -> 13430 | Q13: =C$5*F13/100 -> 39500 | R13: =ROUND(O13+N13+P13+Q13,0) + T13 -> 262195.03 | S13: =ROUND(R13+R13*3%,0) + T13 -> 270061.03 | T13: =T12+0.01 -> 0.03
A14: 2b | C14: 2do. "B" | D14: Garcia Milano Maximiliano Gaston | F14: 7.9 | G14: 150476.04 | I14: 154990.04 | J14: =C8*F14/100 -> #VALUE! | K14: =G14-H14-I14 -> -4514 | M14: =(K14+L14)*3% -> -135.42 | N14: =K14+M14+L14 -> -4649.42 | O14: =C$7*F14/100 -> 54274.941 | P14: =C$9*F14/100 -> 13430 | Q14: =C$5*F14/100 -> 39500 | R14: =ROUND(O14+N14+P14+Q14,0) + T14 -> 102556.04 | S14: =ROUND(R14+R14*3%,0) + T14 -> 105633.04 | T14: =T13+0.01 -> 0.04
A15: 3a | C15: 3ro. "A" | D15: Cecilia Mariel Cassettari | F15: 7.9 | G15: 150476.05 | H15: 0 | I15: =154990.05 -> 154990.05 | J15: =C8*F15/100 -> #VALUE! | K15: =G15-H15-I15 -> -4514 | M15: =(K15+L15)*3% -> -135.42 | N15: =K15+M15+L15 -> -4649.42 | O15: =C$7*F15/100 -> 54274.941 | P15: =C$9*F15/100 -> 13430 | Q15: =C$5*F15/100 -> 39500 | R15: =ROUND(O15+N15+P15+Q15,0) + T15 -> 102556.05 | S15: =ROUND(R15+R15*3%,0) + T15 -> 105633.05 | T15: =T14+0.01 -> 0.05
A16: 3b | C16: 3ro. "B" | D16: Perez Sebastian | E16: Luz / Martin | F16: 7.9 | G16: 150476.06 | H16: 0 | I16: =163345-I28 -> 152748.82 | J16: =C8*F16/100 -> #VALUE! | K16: =G16-H16-I16 -> -2272.76 | M16: =(K16+L16)*3% -> -68.1828 | N16: =K16+M16+L16 -> -2340.9428 | O16: =C$7*F16/100 -> 54274.941 | P16: =C$9*F16/100 -> 13430 | Q16: =C$5*F16/100 -> 39500 | R16: =ROUND(O16+N16+P16+Q16,0) + T16 -> 104864.06 | S16: =ROUND(R16+R16*3%,0) + T16 -> 108010.06 | T16: =T15+0.01 -> 0.06
A17: 4a | C17: 4to. "A" | D17: Estevez Norberto Omar | E17: Sofia | F17: 7.9 | G17: 161167.07 | H17: 0 | I17: =176916.2-I23 -> 166320.07 | J17: =C8*F17/100 -> #VALUE! | K17: =G17-H17-I17 -> -5153 | M17: =(K17+L17)*3% -> -154.59 | N17: =K17+M17+L17 -> -5307.59 | O17: =C$7*F17/100 -> 54274.941 | P17: =C$9*F17/100 -> 13430 | Q17: =C$5*F17/100 -> 39500 | R17: =ROUND(O17+N17+P17+Q17,0) + T17 -> 101897.07 | S17: =ROUND(R17+R17*3%,0) + T17 -> 104954.07 | T17: =T16+0.01 -> 0.07
A18: 4b | C18: 4to. "B" | D18: Lopez Gabriela | E18: Yago | F18: 7.9 | G18: 308030.08 | H18: 0 | I18: =G18 -> 308030.08 | J18: =C8*F18/100 -> #VALUE! | K18: =G18-H18-I18 -> 0 | M18: =(K18+L18)*3% -> 0 | N18: =K18+M18+L18 -> 0 | O18: =C$7*F18/100 -> 54274.941 | P18: =C$9*F18/100 -> 13430 | Q18: =C$5*F18/100 -> 39500 | R18: =ROUND(O18+N18+P18+Q18,0) + T18 -> 107205.08 | S18: =ROUND(R18+R18*3%,0) + T18 -> 110421.08 | T18: =T17+0.01 -> 0.08
A19: 5a | C19: 5to. "A" | D19: Degl´Innocenti Julieta Antonella | F19: 7.9 | G19: 150476.09 | H19: 0 | I19: 154990.09 | J19: =C8*F19/100 -> #VALUE! | K19: =G19-H19-I19 -> -4514 | L19: =G19-I19 -> -4514 | M19: =(K19+L19)*3% -> -270.84 | N19: =K19+M19+L19 -> -9298.84 | O19: =C$7*F19/100 -> 54274.941 | P19: =C$9*F19/100 -> 13430 | Q19: =C$5*F19/100 -> 39500 | R19: =ROUND(O19+N19+P19+Q19,0) + T19 -> 97906.09 | S19: =ROUND(R19+R19*3%,0) + T19 -> 100843.09 | T19: =T18+0.01 -> 0.09
A20: 5b | C20: 5to. "B" | D20: Scarlercio Jorge Omar | F20: 7.9 | G20: 308030.1 | I20: =142126+165904.25 -> 308030.25 | K20: =G20-H20-I20 -> -0.15 | M20: =(K20+L20)*3% -> -0.0045 | N20: =K20+M20+L20 -> -0.1545 | O20: =C$7*F20/100 -> 54274.941 | P20: =C$9*F20/100 -> 13430 | Q20: =C$5*F20/100 -> 39500 | R20: =ROUND(O20+N20+P20+Q20,0) + T20 -> 107205.1 | S20: =ROUND(R20+R20*3%,0) + T20 -> 110421.1 | T20: =T19+0.01 -> 0.1
A21: 6a | C21: 6to. "A" | D21: Moro Vanesa Yania / Juan Carlos Moro | E21: Facundo | F21: 7.9 | G21: 308030.11 | I21: =339197-I24 -> 317909.86 | K21: =G21-H21-I21 -> -9879.75 | M21: =(K21+L21)*3% -> -296.3925 | N21: =K21+M21+L21 -> -10176.142 | O21: =C$7*F21/100 -> 54274.941 | P21: =C$9*F21/100 -> 13430 | Q21: =C$5*F21/100 -> 39500 | R21: =ROUND(O21+N21+P21+Q21,0) + T21 -> 97029.11 | S21: =ROUND(R21+R21*3%,0) + T21 -> 99940.11 | T21: =T20+0.01 -> 0.11
A22: 6b | C22: 6to. "B" | D22: Rodriguez Flavio/Rodriguez Mauro | E22: Javier | F22: 7.9 | G22: 308030.12 | I22: =339197.31-I29 -> 317910.12 | K22: =G22-H22-I22 -> -9880 | M22: =(K22+L22)*3% -> -296.4 | N22: =K22+M22+L22 -> -10176.4 | O22: =C$7*F22/100 -> 54274.941 | P22: =C$9*F22/100 -> 13430 | Q22: =C$5*F22/100 -> 39500 | R22: =ROUND(O22+N22+P22+Q22,0) + T22 -> 97029.12 | S22: =ROUND(R22+R22*3%,0) + T22 -> 99940.12 | T22: =T21+0.01 -> 0.12
C23: COCHERA 1 (4A) | D23: =D17 -> Estevez Norberto Omar | E23: Sofia | F23: 0.74 | G23: 10596.13 | I23: =G23 -> 10596.13 | K23: =G23-H23-I23 -> 0 | M23: =(K23+L23)*3% -> 0 | N23: =K23+M23+L23 -> 0 | O23: =C$7*F23/100 -> 5083.9818 | P23: =C$9*F23/100 -> 1258 | R23: =ROUND(O23+N23+P23+Q23,0) + T23 -> 6342.13 | S23: =ROUND(R23+R23*3%,0) + T23 -> 6532.13 | T23: =T22+0.01 -> 0.13
C24: COCHERA 2 (6A) | D24: =D21 -> Moro Vanesa Yania / Juan Carlos Moro | E24: Facundo | F24: 0.74 | G24: 21287.14 | I24: =G24 -> 21287.14 | K24: =G24-H24-I24 -> 0 | M24: =(K24+L24)*3% -> 0 | N24: =K24+M24+L24 -> 0 | O24: =C$7*F24/100 -> 5083.9818 | P24: =C$9*F24/100 -> 1258 | Q24: ='Calculo Servicios (2)'!H22 -> 0 | R24: =ROUND(O24+N24+P24+Q24,0) + T24 -> 6342.14 | S24: =ROUND(R24+R24*3%,0) + T24 -> 6532.14 | T24: =T23+0.01 -> 0.14
C25: COCHERA 3 (5B) | D25: =D20 -> Scarlercio Jorge Omar | F25: 0.74 | G25: 21287.15 | I25: =G25 -> 21287.15 | K25: =G25-H25-I25 -> 0 | M25: =(K25+L25)*3% -> 0 | N25: =K25+M25+L25 -> 0 | O25: =C$7*F25/100 -> 5083.9818 | P25: =C$9*F25/100 -> 1258 | Q25: ='Calculo Servicios (2)'!H23 -> 0 | R25: =ROUND(O25+N25+P25+Q25,0) + T25 -> 6342.15 | S25: =ROUND(R25+R25*3%,0) + T25 -> 6532.15 | T25: =T24+0.01 -> 0.15 | U25: la habiamos puesto impaga
C26: COCHERA 4 (4B) | D26: =D18 -> Lopez Gabriela | E26: Yago | F26: 0.74 | G26: 21287.16 | H26: 0 | I26: =G26 -> 21287.16 | J26: =C8*F26/100 -> #VALUE! | K26: =G26-H26-I26 -> 0 | M26: =(K26+L26)*3% -> 0 | N26: =K26+M26+L26 -> 0 | O26: =C$7*F26/100 -> 5083.9818 | P26: =C$9*F26/100 -> 1258 | Q26: ='Calculo Servicios (2)'!H24 -> 0 | R26: =ROUND(O26+N26+P26+Q26,0) + T26 -> 6342.16 | S26: =ROUND(R26+R26*3%,0) + T26 -> 6532.16 | T26: =T25+0.01 -> 0.16
C27: COCHERA 5 (3A) | D27: =D15 -> Cecilia Mariel Cassettari | F27: 0.74 | G27: 10596.17 | H27: 0 | I27: 10914.17 | J27: =C8*F27/100 -> #VALUE! | K27: =G27-H27-I27 -> -318 | M27: =(K27+L27)*3% -> -9.54 | N27: =K27+M27+L27 -> -327.54 | O27: =C$7*F27/100 -> 5083.9818 | P27: =C$9*F27/100 -> 1258 | Q27: ='Calculo Servicios (2)'!H25 -> 0 | R27: =ROUND(O27+N27+P27+Q27,0) + T27 -> 6014.17 | S27: =ROUND(R27+R27*3%,0) + T27 -> 6195.17 | T27: =T26+0.01 -> 0.17
C28: COCHERA 6 (3B) | D28: =D16 -> Perez Sebastian | E28: Luz / Martin | F28: 0.74 | G28: 10596.18 | H28: 0 | I28: =G28 -> 10596.18 | J28: 0 | K28: =G28-H28-I28 -> 0 | M28: =(K28+L28)*3% -> 0 | N28: =K28+M28+L28 -> 0 | O28: =C$7*F28/100 -> 5083.9818 | P28: =C$9*F28/100 -> 1258 | Q28: ='Calculo Servicios (2)'!H26 -> 0 | R28: =ROUND(O28+N28+P28+Q28,0) + T28 -> 6342.18 | S28: =ROUND(R28+R28*3%,0) + T28 -> 6532.18 | T28: =T27+0.01 -> 0.18
C29: COCHERA 7 (6B) | D29: =D22 -> Rodriguez Flavio/Rodriguez Mauro | E29: Javier | F29: 0.74 | G29: 21287.19 | H29: 0 | I29: =G29 -> 21287.19 | J29: =C8*F29/100 -> #VALUE! | K29: =G29-H29-I29 -> 0 | M29: =(K29+L29)*3% -> 0 | N29: =K29+M29+L29 -> 0 | O29: =C$7*F29/100 -> 5083.9818 | P29: =C$9*F29/100 -> 1258 | Q29: ='Calculo Servicios (2)'!H27 -> 0 | R29: =ROUND(O29+N29+P29+Q29,0) + T29 -> 6342.19 | S29: =ROUND(R29+R29*3%,0) + T29 -> 6532.19 | T29: =T28+0.01 -> 0.19
H30: 0 | P30: =#REF!*F30/100 -> #REF!
G31: =SUM(G11:G30) -> 2563556.9 | H31: =SUM(H11:H30) -> 0 | I31: =SUM(I11:I30) -> 2458640.5 | K31: =SUM(K11:K30) -> 104916.37 | O31: =SUM(O11:O30) -> 686887.17 | P31: =SUM(P11:P29) -> 169966 | Q31: =SUM(Q11:Q29) -> 474000 | R31: =SUM(R11:R29) -> 1434270.9 | S31: =SUM(S11:S29) -> 1477298.9
B32: Señores propietarios e inquilinos: la superficie que ocupa la camara de luz y que forma del porcentaje total construido, el gasto se prorratea por cada unidad funcional. Atte. La Administracion.-

Sheet Calculo Servicios  (2)
A1: Aysa
D2: Q dias Mes
A3: =13+28+19 -> 60 | B3: 10531.71 | C3: =+B3/A3 -> 175.5285 | D3: 4863.9 | E3: Tramo 2/2 | I3: 17/08 al 18/10
A7: Edesur | L7: Variable | M7: Fijo
A8: 400523.88 | B8: Consumo Anterior | C8: Consumo Actual | D8: Consumo Mes | E8: =3935/2 -> 1967.5 | F8: Variable | G8: Fijo | H8: Total x unidad | K8: 19 | L8: 7502.93 | M8: 2365.26
A9: 1ro. "A" | B9: 1617 | C9: =B9+J25 -> 1689 | D9: =+C9-B9 -> 72 | E9: =+D9/E8 -> 0.036594663 | F9: =+A8*E9 -> 14657.037 | G9: =+(A8*A23)/12 -> 9949.4814 | H9: =+G9+F9 -> 24606.518 | K9: 106 | L9: =+L8*O9 -> 1575.6153 | M9: =M8*21% -> 496.7046 | N9: Iva | O9: 0.21
A10: 1ro. "B" | B10: 4104 | C10: =B10+J26 -> 4195 | D10: =+C10-B10 -> 91 | E10: =+D10/E8 -> 0.046251588 | F10: =+A8*E10 -> 18524.866 | G10: =+G9 -> 9949.4814 | H10: =+G10+F10 -> 28474.347 | K10: 60 | L10: =+L8*O10 -> 481.98822 | M10: =+M8*6.424% -> 151.9443 | N10: Contribucion Municipal | O10: 0.06424
A11: 2do. "A" | B11: 7644 | C11: =B11+J27 -> 7807 | D11: =+C11-B11 -> 163 | E11: =+D11/E8 -> 0.082846252 | F11: =+A8*E11 -> 33181.902 | G11: =G10 -> 9949.4814 | H11: =+G11+F11 -> 43131.384 | K11: 79 | L11: =+L8*0.001% -> 0.0750293 | M11: 0.03 | N11: Contribicion Provincial | O11: 0.1
A12: 2do. "B" | B12: 6554 | C12: =B12+J28 -> 6730 | D12: =+C12-B12 -> 176 | E12: =+D12/E8 -> 0.089453621 | F12: =+A8*E12 -> 35828.312 | G12: =G9 -> 9949.4814 | H12: =SUM(F12:G12) -> 45777.793 | K12: 89 | L12: 400 | M12: 253 | N12: Tasa Municipal | O12: 653
A13: 3ro. "A" | B13: 7564 | C13: =B13+J29 -> 7767 | D13: =+C13-B13 -> 203 | E13: =+D13/E8 -> 0.10317662 | F13: =+A8*E13 -> 41324.7 | G13: =G9 -> 9949.4814 | H13: =SUM(F13:G13) -> 51274.182 | K13: 140 | L13: =SUM(L8:L12)-0.45 -> 9960.1586 | M13: =SUM(M8:M12) -> 3266.9389
A14: 3ro. "B" | B14: 10119 | C14: =B14+J30 -> 10334 | D14: =+C14-B14 -> 215 | E14: =+D14/E8 -> 0.10927573 | F14: =+A8*E14 -> 43767.54 | G14: =G9 -> 9949.4814 | H14: =SUM(F14:G14) -> 53717.021 | K14: 143
A15: 4to. "A" | B15: 8986 | C15: =B15+J31 -> 9068 | D15: =+C15-B15 -> 82 | E15: =+D15/E8 -> 0.041677255 | F15: =+A8*E15 -> 16692.736 | G15: =G9 -> 9949.4814 | H15: =SUM(F15:G15) -> 26642.217 | K15: 221 | L15: =+L13+M13 -> 13227.097
A16: 4to. "B" | B16: 7032 | C16: =B16+J32 -> 7034 | D16: =+C16-B16 -> 2 | E16: =+D16/E8 -> 0.0010165184 | F16: =+A8*E16 -> 407.1399 | G16: =G9 -> 9949.4814 | H16: =SUM(F16:G16) -> 10356.621 | K16: 32
A17: 5to. "A" | B17: 1623 | C17: =B17+J33 -> 1668 | D17: =+C17-B17 -> 45 | E17: =+D17/E8 -> 0.022871665 | F17: =+A8*E17 -> 9160.6478 | G17: =G9 -> 9949.4814 | H17: =SUM(F17:G17) -> 19110.129 | K17: 80
A18: 5to. "B" | B18: 3932 | C18: =B18+J34 -> 4021 | D18: =+C18-B18 -> 89 | E18: =+D18/E8 -> 0.04523507 | F18: =+A8*E18 -> 18117.726 | G18: =G9 -> 9949.4814 | H18: =SUM(F18:G18) -> 28067.207 | K18: 113
A19: 6to. "A" | B19: 6887 | C19: =B19+J35 -> 6994 | D19: =+C19-B19 -> 107 | E19: =+D19/E8 -> 0.054383736 | F19: =+A8*E19 -> 21781.985 | G19: =G9 -> 9949.4814 | H19: =SUM(F19:G19) -> 31731.466 | K19: 2
A20: 6to. "B" | B20: 1884 | C20: =B20+J36 -> 2020 | D20: =+C20-B20 -> 136 | E20: =+D20/E8 -> 0.069123253 | F20: =+A8*E20 -> 27685.513 | G20: =G9 -> 9949.4814 | H20: =SUM(F20:G20) -> 37634.995
A21: Total Consumo Mes Octubre | D21: =SUM(D9:D20) -> 1381 | H21: =SUM(H9:H20) -> 400523.88 | J21: =+H21-A8 -> 0
A22: =+D21/E8 -> 0.70190597 | B22: Consumo Depto
A23: =100%-A22 -> 0.29809403 | B23: General
J25: 72
J26: 91
J27: 163
B28: Fondo de Reserva | J28: 176
B29: Mes | C29: Cobrado | D29: Utilizado | E29: Concepto | F29: Acumulado | J29: 203
B30: Abril 2021 | C30: 4000 | D30: 0 | F30: =+C30 -> 4000 | J30: 215 | M30: =+H21-A8 -> 0
B31: Mayo 2021 | C31: 4000 | D31: 0 | F31: =+F30+C31-D31 -> 8000 | J31: 82
B32: Junio 2021 | C32: 4000 | D32: 0 | F32: =+F31+C32-D32 -> 12000 | J32: 2
B33: Julio 2021 | C33: 4000 | D33: 0 | F33: =+F32+C33-D33 -> 16000 | J33: 45 | K33: =11934.02-11933.71 -> 0.31
B34: Agosto 2021 | C34: 4000 | D34: 0 | F34: =+F33+C34-D34 -> 20000 | J34: 89
B35: Septiembre 2021 | C35: 4000 | D35: 0 | F35: =+F34+C35-D35 -> 24000 | J35: 107
B36: Octubre 2021 | C36: 4000 | D36: 0 | F36: =+F35+C36-D36 -> 28000 | J36: 136
B37: Noviembre 2021 | C37: 4000 | D37: 0 | F37: =+F36+C37-D37 -> 32000
B38: Diciembre 2021 | C38: 4000 | D38: 3500 | E38: Arreglo cerradura | F38: =+F37+C38-D38 -> 32500 | M38: =88.05-100 -> -11.95
B39: Enero 2022 | C39: 4000 | F39: =+F38+C39-D39 -> 36500
B40: Febrero 2022 | C40: 4000 | F40: =+F39+C40-D40 -> 40500
B41: Marzo 2022 | C41: 4000 | F41: =+F40+C41-D41 -> 44500
B42: Abril 2022 | C42: 0 | F42: =+F41+C42-D42 -> 44500
B43: Mayo 2022 | C43: 0 | F43: =+F42+C43-D43 -> 44500
B44: Junio 2022 | C44: 0 | F44: =+F43+C44-D44 -> 44500
...
