Workbook
Name CantOper: #REF!
Name CantOper: #REF!
Name PaseMateriales: #REF!
Name PaseMateriales: #REF!
Name PaseMdeO: #REF!
Name PaseMdeO: #REF!
Name PaseSubcontratos: #REF!
Name PaseSubcontratos: #REF!
Name Plazo: #REF!
Name Plazo: #REF!

Sheet Gastos
D2: Domicilio: | E2: TUCUMAN 1061
D3: Cel. | E3: 1153202676
D4: e-mail: | E4: tucuman1061rc@gmail.com
D5: MP:1148
D6: Banco santander - C DE P TUCUMAN 1061 1063 - Nro. De cuenta : 39-022068/6 CBU: 0720039720000002206868
A9: LIQUIDACION DE EXPENSAS | E9: PERIODO: MARZO | H9: VTO: 17/04
A12: Domicilio: | B12: ROSALES 624
A14: 1- SERVICIO DE LIMPIEZA Y JARDINERIA
A16: SUELDO | B16: Sr. Encargado Hernan | H16: =392270+392270*2% -> 400115.4
A17: Poliza Sr. De Luca Carlos Hernan - La holando MARZO | H17: 4030.28
A18: Total: | H18: =SUM(H15:H17) -> 404145.68
A20: 2- SERVICIO PUBLICIO
A21: AYSA | H21: 18355.59
A22: Edesur | H22: 974869.58
A23: Total Servicios publicos: | H23: =SUM(H21:H22) -> 993225.17
A24: 3- MANTENIMIENTO DE PARTES COMUNES
A25: Seguro OBLIGATORIO DE CONSORCIO - POLIZA Nro. 191195427 - Mercantil Andina | H25: 48099.52
A26: Articulos de limpieza | H26: 32650
A27: Articulos de limpieza | H27: 65450
A28: Lema mantenimiento ascensores | H28: 80000
A29: Total mantenimiento: | H29: =SUM(H25:H28) -> 226199.52
A30: 4- GASTO DE ADMINISTRACION
A31: Nombre y Apellido: | C31: Carolina Canciani | H31: 97600
H32: 0
A33: Administraciòn MARZO 2025: | H33: =SUM(H31:H32) -> 97600 | N33: subidos en n0v 2025
A35: 5 - GASTOS BANCARIOS
A36: Gastos bancarios | H36: 14622.12
A37: TOTAL DE GASTOS ORDINARIOS 1,2,3,4,5,6; | H37: =H18+H23+H29+H33+H36 -> 1735792.5
A38: Prevision ordinaria
A39: GASTOS EXTRAORDINARIOS
A42: TOTAL | H42: =SUM(H41:H41) -> 0
A45: TOTAL DE GASTOS ORDINARIOS A PRORRATEAR | H45: =+H37+H38 -> 1735792.5
A47: TOTAL DE GASTOS EXTRAORDINARIOS | H47: =H42 -> 0
A49: ESTADO FINANCIERO
A50: SALDO ANTERIOR | H50: 1842211.6
A51: Ingreso pago por expensas | H51: =Planilla!H31 -> 1360767.9
A52: Punitorios mal cobrados
A53: Egresos gastos del mes | H53: =-(H37+H42) -> -1735792.5
A54: Saldo al cierre | H54: =SUM(H50:H53) -> 1467186.9

Sheet Planilla
A1: =Gastos!E9 -> PERIODO: MARZO
C2: 1667498.5 | F2: QUIENES ESTAN MARCADOS EN ROJO NO ESTAN RESPETANDO LOS CENTAVOS AL ABONAR - LEER PORFAVOR EL CARTEL AMARILLO | J2: IMPORTANTE ⚠️ Al abonar, respetar los centavos que figuran en la columna “Total a pagar”. Respetar los centavos facilita la correcta identificación de los pagos y las unidades funcionales. Si poseen departamento y cochera, les pedimos —en la medida de lo posible— que realicen dos pagos separados, respetando los centavos correspondientes a cada uno. ¡Muchas gracias por la colaboración! 🙌
D3: 974869.58
C4: EDESUR:
C5: =D3 -> 974869.58
C6: Gastos Ordinarios sin edesur: | F6: SOLICITAMOS POR FAVOR QUE, SI REALIZAN EL PAGO ANTES DE LA FECHA DEL PRIMER VENCIMIENTO , ABONEN ÚNICAMENTE EL MONTO CORRESPONDIENTE A DICHO VENCIMIENTO Y NO EL DEL SEGUNDO.
C7: =C2-D3 -> 692628.89
C8: Gastos Extraordinarios:
C9: 0
A10: U.F. | B10: PISO - DEPTO | C10: PROPIETARIOS | D10: PROPIETARIOS | E10: INQUILINOS | F10: % | G10: SALDO ANTERIOR | H10: PAGOS | I10: DEUDA | J10: Mora | K10: Total con Mora | L10: Gasto Ordinario - Sin Edesur | M10: Gasto Extraordinario | N10: EDESUR | O10: ="1ER vto - " & Gastos!H9 & "'" -> 1ER vto - VTO: 17/04' | P10: 2do vto
A11: 1a | C11: 1ro. "A" | D11: Juan Pablo Rodriguez/ Valeria Ruggiero | F11: 7.9 | G11: 186804.01 | H11: =G11 -> 186804.01 | I11: =G11-H11 -> 0 | J11: =(I11)*3% -> 0 | K11: =I11+J11 -> 0 | L11: =C$7*F11/100 -> 54717.682 | M11: =C$9*F11/100 -> 0 | N11: =C$5*F11/100 -> 77014.697 | O11: =ROUND(L11+K11+M11+N11,0) + Q11 -> 131732.01 | P11: =ROUND(O11+O11*3%,0) + Q11 -> 135684.01 | Q11: 0.01
A12: 1b | C12: 1ro. "B" | D12: Mendez Juan Carlos | F12: 7.9 | G12: 190951.02 | H12: =G12 -> 190951.02 | I12: =G12-H12 -> 0 | J12: =(I12)*3% -> 0 | K12: =I12+J12 -> 0 | L12: =C$7*F12/100 -> 54717.682 | M12: =C$9*F12/100 -> 0 | N12: =C$5*F12/100 -> 77014.697 | O12: =ROUND(L12+K12+M12+N12,0) + Q12 -> 131732.02 | P12: =ROUND(O12+O12*3%,0) + Q12 -> 135684.02 | Q12: =Q11+0.01 -> 0.02
A13: 2a | C13: 2do. "A" | D13: Matias Ezequiel Bonfiglio | E13: Maria Elena | F13: 7.9 | G13: 190951.03 | I13: =G13-H13 -> 190951.03 | J13: =(I13)*3% -> 5728.5309 | K13: =I13+J13 -> 196679.56 | L13: =C$7*F13/100 -> 54717.682 | M13: =C$9*F13/100 -> 0 | N13: =C$5*F13/100 -> 77014.697 | O13: =ROUND(L13+K13+M13+N13,0) + Q13 -> 328412.03 | P13: =ROUND(O13+O13*3%,0) + Q13 -> 338264.03 | Q13: =Q12+0.01 -> 0.03
A14: 2b | C14: 2do. "B" | D14: Garcia Milano Maximiliano Gaston | F14: 7.9 | G14: 190951.04 | H14: =G14 -> 190951.04 | I14: =G14-H14 -> 0 | J14: =(I14)*3% -> 0 | K14: =I14+J14 -> 0 | L14: =C$7*F14/100 -> 54717.682 | M14: =C$9*F14/100 -> 0 | N14: =C$5*F14/100 -> 77014.697 | O14: =ROUND(L14+K14+M14+N14,0) + Q14 -> 131732.04 | P14: =ROUND(O14+O14*3%,0) + Q14 -> 135684.04 | Q14: =Q13+0.01 -> 0.04
A15: 3a | C15: 3ro. "A" | D15: Cecilia Mariel Cassettari | F15: 7.9 | G15: 186706.05 | I15: =G15-H15 -> 186706.05 | J15: =(I15)*3% -> 5601.1815 | K15: =I15+J15 -> 192307.23 | L15: =C$7*F15/100 -> 54717.682 | M15: =C$9*F15/100 -> 0 | N15: =C$5*F15/100 -> 77014.697 | O15: =ROUND(L15+K15+M15+N15,0) + Q15 -> 324040.05 | P15: =ROUND(O15+O15*3%,0) + Q15 -> 333761.05 | Q15: =Q14+0.01 -> 0.05
A16: 3b | C16: 3ro. "B" | D16: Perez Sebastian | E16: Luz / Martin | F16: 7.9 | G16: 190951.06 | H16: =G16 -> 190951.06 | I16: =G16-H16 -> 0 | J16: =(I16)*3% -> 0 | K16: =I16+J16 -> 0 | L16: =C$7*F16/100 -> 54717.682 | M16: =C$9*F16/100 -> 0 | N16: =C$5*F16/100 -> 77014.697 | O16: =ROUND(L16+K16+M16+N16,0) + Q16 -> 131732.06 | P16: =ROUND(O16+O16*3%,0) + Q16 -> 135684.06 | Q16: =Q15+0.01 -> 0.06
A17: 4a | C17: 4to. "A" | D17: Estevez Norberto Omar | E17: Sofia | F17: 7.9 | G17: 190951.07 | H17: =G17 -> 190951.07 | I17: =G17-H17 -> 0 | J17: =(I17)*3% -> 0 | K17: =I17+J17 -> 0 | L17: =C$7*F17/100 -> 54717.682 | M17: =C$9*F17/100 -> 0 | N17: =C$5*F17/100 -> 77014.697 | O17: =ROUND(L17+K17+M17+N17,0) + Q17 -> 131732.07 | P17: =ROUND(O17+O17*3%,0) + Q17 -> 135684.07 | Q17: =Q16+0.01 -> 0.07
A18: 4b | C18: 4to. "B" | D18: Lopez Gabriela | E18: Yago | F18: 7.9 | G18: 190951.08 | I18: =G18-H18 -> 190951.08 | J18: =(I18)*3% -> 5728.5324 | K18: =I18+J18 -> 196679.61 | L18: =C$7*F18/100 -> 54717.682 | M18: =C$9*F18/100 -> 0 | N18: =C$5*F18/100 -> 77014.697 | O18: =ROUND(L18+K18+M18+N18,0) + Q18 -> 328412.08 | P18: =ROUND(O18+O18*3%,0) + Q18 -> 338264.08 | Q18: =Q17+0.01 -> 0.08
A19: 5a | C19: 5to. "A" | D19: Degl´Innocenti Julieta Antonella | F19: 7.9 | G19: 186706.09 | H19: =G19 -> 186706.09 | I19: =G19-H19 -> 0 | J19: =(I19)*3% -> 0 | K19: =I19+J19 -> 0 | L19: =C$7*F19/100 -> 54717.682 | M19: =C$9*F19/100 -> 0 | N19: =C$5*F19/100 -> 77014.697 | O19: =ROUND(L19+K19+M19+N19,0) + Q19 -> 131732.09 | P19: =ROUND(O19+O19*3%,0) + Q19 -> 135684.09 | Q19: =Q18+0.01 -> 0.09
A20: 5b | C20: 5to. "B" | D20: Scarlercio Jorge Omar | F20: 7.9 | G20: 190951.1 | H20: =G20 -> 190951.1 | I20: =G20-H20 -> 0 | J20: =(I20)*3% -> 0 | K20: =I20+J20 -> 0 | L20: =C$7*F20/100 -> 54717.682 | M20: =C$9*F20/100 -> 0 | N20: =C$5*F20/100 -> 77014.697 | O20: =ROUND(L20+K20+M20+N20,0) + Q20 -> 131732.1 | P20: =ROUND(O20+O20*3%,0) + Q20 -> 135684.1 | Q20: =Q19+0.01 -> 0.1
A21: 6a | C21: 6to. "A" | D21: Moro Vanesa Yania / Juan Carlos Moro | E21: Facundo | F21: 7.9 | G21: 183618.11 | I21: =G21-H21 -> 183618.11 | J21: =(I21)*3% -> 5508.5433 | K21: =I21+J21 -> 189126.65 | L21: =C$7*F21/100 -> 54717.682 | M21: =C$9*F21/100 -> 0 | N21: =C$5*F21/100 -> 77014.697 | O21: =ROUND(L21+K21+M21+N21,0) + Q21 -> 320859.11 | P21: =ROUND(O21+O21*3%,0) + Q21 -> 330485.11 | Q21: =Q20+0.01 -> 0.11
A22: 6b | C22: 6to. "B" | D22: Rodriguez Flavio/Rodriguez Mauro | E22: Javier | F22: 7.9 | G22: 190951.12 | I22: =G22-H22 -> 190951.12 | J22: =(I22)*3% -> 5728.5336 | K22: =I22+J22 -> 196679.65 | L22: =C$7*F22/100 -> 54717.682 | M22: =C$9*F22/100 -> 0 | N22: =C$5*F22/100 -> 77014.697 | O22: =ROUND(L22+K22+M22+N22,0) + Q22 -> 328412.12 | P22: =ROUND(O22+O22*3%,0) + Q22 -> 338264.12 | Q22: =Q21+0.01 -> 0.12 | S22: Celeste
C23: COCHERA 1 (4A) | D23: =D17 -> Estevez Norberto Omar | E23: Sofia | F23: 0.74 | G23: 10834.13 | H23: =G23 -> 10834.13 | I23: =G23-H23 -> 0 | J23: =(I23)*3% -> 0 | K23: =I23+J23 -> 0 | L23: =C$7*F23/100 -> 5125.4538 | M23: =C$9*F23/100 -> 0 | O23: =ROUND(L23+K23+M23+N23,0) + Q23 -> 5125.13 | P23: =ROUND(O23+O23*3%,0) + Q23 -> 5279.13 | Q23: =Q22+0.01 -> 0.13
C24: COCHERA 2 (6A) | D24: =D21 -> Moro Vanesa Yania / Juan Carlos Moro | E24: Facundo | F24: 0.74 | G24: 10475.14 | I24: =G24-H24 -> 10475.14 | J24: =(I24)*3% -> 314.2542 | K24: =I24+J24 -> 10789.394 | L24: =C$7*F24/100 -> 5125.4538 | M24: =C$9*F24/100 -> 0 | N24: ='Calculo Servicios (2)'!H22 -> 0 | O24: =ROUND(L24+K24+M24+N24,0) + Q24 -> 15915.14 | P24: =ROUND(O24+O24*3%,0) + Q24 -> 16393.14 | Q24: =Q23+0.01 -> 0.14
C25: COCHERA 3 (5B) | D25: =D20 -> Scarlercio Jorge Omar | F25: 0.74 | G25: 10834.15 | H25: =G25 -> 10834.15 | I25: =G25-H25 -> 0 | J25: =(I25)*3% -> 0 | K25: =I25+J25 -> 0 | L25: =C$7*F25/100 -> 5125.4538 | M25: =C$9*F25/100 -> 0 | N25: ='Calculo Servicios (2)'!H23 -> 0 | O25: =ROUND(L25+K25+M25+N25,0) + Q25 -> 5125.15 | P25: =ROUND(O25+O25*3%,0) + Q25 -> 5279.15 | Q25: =Q24+0.01 -> 0.15
C26: COCHERA 4 (4B) | D26: =D18 -> Lopez Gabriela | E26: Yago | F26: 0.74 | G26: 10834.16 | I26: =G26-H26 -> 10834.16 | J26: =(I26)*3% -> 325.0248 | K26: =I26+J26 -> 11159.185 | L26: =C$7*F26/100 -> 5125.4538 | M26: =C$9*F26/100 -> 0 | N26: ='Calculo Servicios (2)'!H24 -> 0 | O26: =ROUND(L26+K26+M26+N26,0) + Q26 -> 16285.16 | P26: =ROUND(O26+O26*3%,0) + Q26 -> 16774.16 | Q26: =Q25+0.01 -> 0.16
C27: COCHERA 5 (3A) | D27: =D15 -> Cecilia Mariel Cassettari | F27: 0.74 | G27: 10676.17 | I27: =G27-H27 -> 10676.17 | J27: =(I27)*3% -> 320.2851 | K27: =I27+J27 -> 10996.455 | L27: =C$7*F27/100 -> 5125.4538 | M27: =C$9*F27/100 -> 0 | N27: ='Calculo Servicios (2)'!H25 -> 0 | O27: =ROUND(L27+K27+M27+N27,0) + Q27 -> 16122.17 | P27: =ROUND(O27+O27*3%,0) + Q27 -> 16606.17 | Q27: =Q26+0.01 -> 0.17
C28: COCHERA 6 (3B) | D28: =D16 -> Perez Sebastian | E28: Luz / Martin | F28: 0.74 | G28: 10834.18 | H28: =G28 -> 10834.18 | I28: =G28-H28 -> 0 | J28: =(I28)*3% -> 0 | K28: =I28+J28 -> 0 | L28: =C$7*F28/100 -> 5125.4538 | M28: =C$9*F28/100 -> 0 | N28: ='Calculo Servicios (2)'!H26 -> 0 | O28: =ROUND(L28+K28+M28+N28,0) + Q28 -> 5125.18 | P28: =ROUND(O28+O28*3%,0) + Q28 -> 5279.18 | Q28: =Q27+0.01 -> 0.18
C29: COCHERA 7 (6B) | D29: =D22 -> Rodriguez Flavio/Rodriguez Mauro | E29: Javier | F29: 0.74 | G29: 10834.19 | I29: =G29-H29 -> 10834.19 | J29: =(I29)*3% -> 325.0257 | K29: =I29+J29 -> 11159.216 | L29: =C$7*F29/100 -> 5125.4538 | M29: =C$9*F29/100 -> 0 | N29: ='Calculo Servicios (2)'!H27 -> 0 | O29: =ROUND(L29+K29+M29+N29,0) + Q29 -> 16285.19 | P29: =ROUND(O29+O29*3%,0) + Q29 -> 16774.19 | Q29: =Q28+0.01 -> 0.19
M30: =#REF!*F30/100 -> #REF!
G31: =SUM(G11:G30) -> 2346764.9 | H31: =SUM(H11:H30) -> 1360767.9 | I31: =SUM(I11:I30) -> 985997.05 | L31: =SUM(L11:L30) -> 692490.36 | M31: =SUM(M11:M29) -> 0 | N31: =SUM(N11:N29) -> 924176.36 | O31: =SUM(O11:O29) -> 2632242.9 | P31: =SUM(P11:P29) -> 2711211.9
B32: Señores propietarios e inquilinos: la superficie que ocupa la camara de luz y que forma del porcentaje total construido, el gasto se prorratea por cada unidad funcional. Atte. La Administracion.-

Sheet Calculo Servicios  (2)
A1: Aysa
D2: Q dias Mes
A3: =13+28+19 -> 60 | B3: 10531.71 | C3: =+B3/A3 -> 175.5285 | D3: 4863.9 | E3: Tramo 2/2 | I3: 17/08 al 18/10
A7: Edesur | L7: Variable | M7: Fijo
A8: 953033.85 | B8: Consumo Anterior | C8: Consumo Actual | D8: Consumo Mes | E8: =3935/2 -> 1967.5 | F8: Variable | G8: Fijo | H8: Total x unidad | K8: 19 | L8: 7502.93 | M8: 2365.26
A9: 1ro. "A" | B9: 1617 | C9: =B9+J25 -> 1689 | D9: =+C9-B9 -> 72 | E9: =+D9/E8 -> 0.036594663 | F9: =+A8*E9 -> 34875.953 | G9: =+(A8*A23)/12 -> 23674.475 | H9: =+G9+F9 -> 58550.428 | K9: 106 | L9: =+L8*O9 -> 1575.6153 | M9: =M8*21% -> 496.7046 | N9: Iva | O9: 0.21
A10: 1ro. "B" | B10: 4104 | C10: =B10+J26 -> 4195 | D10: =+C10-B10 -> 91 | E10: =+D10/E8 -> 0.046251588 | F10: =+A8*E10 -> 44079.329 | G10: =+G9 -> 23674.475 | H10: =+G10+F10 -> 67753.804 | K10: 60 | L10: =+L8*O10 -> 481.98822 | M10: =+M8*6.424% -> 151.9443 | N10: Contribucion Municipal | O10: 0.06424
A11: 2do. "A" | B11: 7644 | C11: =B11+J27 -> 7807 | D11: =+C11-B11 -> 163 | E11: =+D11/E8 -> 0.082846252 | F11: =+A8*E11 -> 78955.282 | G11: =G10 -> 23674.475 | H11: =+G11+F11 -> 102629.76 | K11: 79 | L11: =+L8*0.001% -> 0.0750293 | M11: 0.03 | N11: Contribicion Provincial | O11: 0.1
A12: 2do. "B" | B12: 6554 | C12: =B12+J28 -> 6730 | D12: =+C12-B12 -> 176 | E12: =+D12/E8 -> 0.089453621 | F12: =+A8*E12 -> 85252.329 | G12: =G9 -> 23674.475 | H12: =SUM(F12:G12) -> 108926.8 | K12: 89 | L12: 400 | M12: 253 | N12: Tasa Municipal | O12: 653
A13: 3ro. "A" | B13: 7564 | C13: =B13+J29 -> 7767 | D13: =+C13-B13 -> 203 | E13: =+D13/E8 -> 0.10317662 | F13: =+A8*E13 -> 98330.811 | G13: =G9 -> 23674.475 | H13: =SUM(F13:G13) -> 122005.29 | K13: 140 | L13: =SUM(L8:L12)-0.45 -> 9960.1586 | M13: =SUM(M8:M12) -> 3266.9389
A14: 3ro. "B" | B14: 10119 | C14: =B14+J30 -> 10334 | D14: =+C14-B14 -> 215 | E14: =+D14/E8 -> 0.10927573 | F14: =+A8*E14 -> 104143.47 | G14: =G9 -> 23674.475 | H14: =SUM(F14:G14) -> 127817.95 | K14: 143
A15: 4to. "A" | B15: 8986 | C15: =B15+J31 -> 9068 | D15: =+C15-B15 -> 82 | E15: =+D15/E8 -> 0.041677255 | F15: =+A8*E15 -> 39719.835 | G15: =G9 -> 23674.475 | H15: =SUM(F15:G15) -> 63394.31 | K15: 221 | L15: =+L13+M13 -> 13227.097
A16: 4to. "B" | B16: 7032 | C16: =B16+J32 -> 7034 | D16: =+C16-B16 -> 2 | E16: =+D16/E8 -> 0.0010165184 | F16: =+A8*E16 -> 968.77647 | G16: =G9 -> 23674.475 | H16: =SUM(F16:G16) -> 24643.251 | K16: 32
A17: 5to. "A" | B17: 1623 | C17: =B17+J33 -> 1668 | D17: =+C17-B17 -> 45 | E17: =+D17/E8 -> 0.022871665 | F17: =+A8*E17 -> 21797.471 | G17: =G9 -> 23674.475 | H17: =SUM(F17:G17) -> 45471.945 | K17: 80
A18: 5to. "B" | B18: 3932 | C18: =B18+J34 -> 4021 | D18: =+C18-B18 -> 89 | E18: =+D18/E8 -> 0.04523507 | F18: =+A8*E18 -> 43110.553 | G18: =G9 -> 23674.475 | H18: =SUM(F18:G18) -> 66785.028 | K18: 113
A19: 6to. "A" | B19: 6887 | C19: =B19+J35 -> 6994 | D19: =+C19-B19 -> 107 | E19: =+D19/E8 -> 0.054383736 | F19: =+A8*E19 -> 51829.541 | G19: =G9 -> 23674.475 | H19: =SUM(F19:G19) -> 75504.016 | K19: 2
A20: 6to. "B" | B20: 1884 | C20: =B20+J36 -> 2020 | D20: =+C20-B20 -> 136 | E20: =+D20/E8 -> 0.069123253 | F20: =+A8*E20 -> 65876.8 | G20: =G9 -> 23674.475 | H20: =SUM(F20:G20) -> 89551.275
A21: Total Consumo Mes Octubre | D21: =SUM(D9:D20) -> 1381 | H21: =SUM(H9:H20) -> 953033.85 | J21: =+H21-A8 -> 0
A22: =+D21/E8 -> 0.70190597 | B22: Consumo Depto
A23: =100%-A22 -> 0.29809403 | B23: General
J25: 72
J26: 91
J27: 163
B28: Fondo de Reserva | J28: 176
B29: Mes | C29: Cobrado | D29: Utilizado | E29: Concepto | F29: Acumulado | J29: 203
B30: Abril 2021 | C30: 4000 | D30: 0 | F30: =+C30 -> 4000 | J30: 215 | M30: =+H21-A8 -> 0
B31: Mayo 2021 | C31: 4000 | D31: 0 | F31: =+F30+C31-D31 -> 8000 | J31: 82
B32: Junio 2021 | C32: 4000 | D32: 0 | F32: =+F31+C32-D32 -> 12000 | J32: 2
B33: Julio 2021 | C33: 4000 | D33: 0 | F33: =+F32+C33-D33 -> 16000 | J33: 45 | K33: =11934.02-11933.71 -> 0.31
B34: Agosto 2021 | C34: 4000 | D34: 0 | F34: =+F33+C34-D34 -> 20000 | J34: 89
B35: Septiembre 2021 | C35: 4000 | D35: 0 | F35: =+F34+C35-D35 -> 24000 | J35: 107
B36: Octubre 2021 | C36: 4000 | D36: 0 | F36: =+F35+C36-D36 -> 28000 | J36: 136
B37: Noviembre 2021 | C37: 4000 | D37: 0 | F37: =+F36+C37-D37 -> 32000
B38: Diciembre 2021 | C38: 4000 | D38: 3500 | E38: Arreglo cerradura | F38: =+F37+C38-D38 -> 32500 | M38: =88.05-100 -> -11.95
B39: Enero 2022 | C39: 4000 | F39: =+F38+C39-D39 -> 36500
B40: Febrero 2022 | C40: 4000 | F40: =+F39+C40-D40 -> 40500
B41: Marzo 2022 | C41: 4000 | F41: =+F40+C41-D41 -> 44500
B42: Abril 2022 | C42: 0 | F42: =+F41+C42-D42 -> 44500
B43: Mayo 2022 | C43: 0 | F43: =+F42+C43-D43 -> 44500
B44: Junio 2022 | C44: 0 | F44: =+F43+C44-D44 -> 44500
...
