Workbook

Sheet RESUMEN
B1: MAIL: salta1167rc@gmail.com
B2: CUIT ADMINISTRACION: 27231256879
B3: CONSORCIO DE PROPIETARIOS EDIFICIO CALLE SALTA 1167/1169 C DE P SALTA 1167 1169 LANUS CTA CTE $ 039 - 22273/6 CBU: 0720039720000002227368
A4: LIQUIDACION DE EXPENSAS | B4: ADMINISTRADORA: CAROLINA CANCIANI MP:1148
A5: CUIT DEL EDIFICIO: 30-719118061-9 | B5: PERÍODO: OCTUBRE | D5: HORARIOS DE ATENCION: LUNES A VIERNES
A6: CONSORCIO DE PROPIETARIOS DEL EDIFICIO CALLE YRIGOYEN 9730 | D6: 10 A 16HS - EMERGENCIAS 24HS
B8: VTO 14/11
A13: ESTIMADOS PROPIETARIOS E INQUILINOS: POR FAVOR LOS QUE ABONAN EN PRIMER VENCIMIENTO ABONEN EL MONTO DE PRIMER VENCIMIENTO, ASI AGILIZAN LA LIQUIDACION, RESPETEN LOS CENTAVOS CORRESPONDIENTES A LA UNIDAD FUNCIONAL. ES DE CARÁCTER OBLIGATORIO INFORMAR VIA MAIL LAS EXPENSAS. PORFAVOR RESPETAR LOS CENTAVOS AL ABONAR.
A20: GASTOS ORDINARIOS UNIDADES FUNCIONALES:
A21: LIMPIEZA
A22: Full Clean - Servicio de limpieza - Esperando definicion de traspaso
A23: TOTAL | E23: =SUM(D22:D22) -> 0
A24: SEGUROS
A25: Federacion patronal Seguro obligatorio de consorcio - Poliza nro. 2223190 | D25: 65518 | E25: Mp 06/10
A26: TOTAL IMPUESTO | E26: =SUM(D25:D25) -> 65518
A27: ABONOS Y SERVICIOS
A28: Edesur | D28: 0
A29: Metrogas | D29: 8128.13 | E29: Mp 03/10
A30: Metrogas | D30: 374755.03 | E30: Mp 03/10
A31: AySa | D31: 242436.29 | E31: Mp 03/10
A32: Servicio de interet Claro | D32: 20332.08 | E32: Mp 06/10
A33: TOTAL ABONOS Y SERVICIOS | E33: =SUM(D28:D32) -> 645651.53
A35: Pila energizer AAA - Madero Bytes SA | D35: 3320
A36: Ascensores Guillemi - Mantenimiento de ascesores - No se abona aguardando traspaso
A37: Fotocopias septiembre (Gestion de administracion saliente) | D37: 3960
A38: Si.Pro.Da | D38: 35000
A39: TOTAL | E39: =SUM(D35:D38) -> 42280
A40: HONORARIOS
A41: Honorarios administracion | D41: 140000
A42: Sr cossentino - Traspaso administracion | D42: 202000
A43: TOTAL | E43: =SUM(D41:D42) -> 342000
A44: GASTOS BANCARIOS
A45: Mantenimiento de cuenta
A46: Gastos bancarios - Mes de septiembre Administracion anterior | D46: 84679.61
A47: TOTAL | E47: =SUM(D45:D46) -> 84679.61
A49: PREVISION GASTOS A | E49: =2000000-1180129.14 -> 819870.86
A51: TOTAL GASTOS A | E51: =(SUM(E21:E49)) -> 2000000
A54: GASTOS B:
A55: Digitalizacion acta de desingnacion y rubrica del libro - Escribania Romanatti | D55: 37000
A56: Padron Gustavo - Contador - Gestion en ARCA - Inscripcion en ARCA | D56: 120000 | E56: Mp 28/10
...

Sheet PRORRATEO
E2: Gastos B | G2: 0 | K2: Gastos A | L2: 2000000
A4: ¡IMPORTANTE! Estimados convivientes: Les solicitamos, por favor, que al momento de realizar el pago respeten los centavos que figuran en el monto indicado, ya que estos nos permiten identificar correctamente los pagos y las unidades funcionales, reduciendo así el margen de error. Muchas gracias por su colaboración.
A9: UF | C9: Propietario | D9: Inquilinos | E9: (%) | F9: Saldo Ord | G9: Ingreso | H9: Deuda o Saldo a favor | I9: Interes 3% | J9: EDESUR | K9: Gastos A | L9: Gastos B | M9: Total 1er Vto | N9: Total 2do Vto. | O9: Total 2do Vto
M10: =RESUMEN!B8 -> VTO 14/11
A11: 1 | B11: 1 A | C11: MIRAGLIA NORBERTO JOSE | E11: 12 | F11: 495807 | G11: =530667-G27-G28 -> 495867 | H11: =F11-G11 -> -60 | I11: =IF(H11>0,H11*3%,0) -> 0 | J11: =EDESUR!I5 -> 0 | K11: =L$2*E11/100 -> 240000 | L11: =G$2*E11/100 -> 0 | M11: =ROUND(SUM(H11:L11),0) + P11 -> 239940.01 | N11: =ROUND(M11*6% + M11,0) + P11 -> 254336.01 | O11: =ROUND(M11*3%,0) + M11 -> 247138.01 | P11: 0.01
A12: 2 | B12: 1 C | C12: ADAMO PABLO MARIANO | E12: 6.6 | F12: 230445 | G12: =F12 -> 230445 | H12: =F12-G12 -> 0 | I12: =IF(H12>0,H12*3%,0) -> 0 | J12: =EDESUR!I6 -> 0 | K12: =L$2*E12/100 -> 132000 | L12: =G$2*E12/100 -> 0 | M12: =ROUND(SUM(H12:L12),0) + P12 -> 132000.02 | N12: =ROUND(M12*6% + M12,0) + P12 -> 139920.02 | O12: =ROUND(M12*3%,0) + M12 -> 135960.02 | P12: =P11+0.01 -> 0.02
A13: 3 | B13: 1 D | C13: REDONDO | D13: Gilmer | E13: 5.4 | F13: 183797 | G13: =F13 -> 183797 | H13: =F13-G13 -> 0 | I13: =IF(H13>0,H13*3%,0) -> 0 | J13: =EDESUR!I7 -> 0 | K13: =L$2*E13/100 -> 108000 | L13: =G$2*E13/100 -> 0 | M13: =ROUND(SUM(H13:L13),0) + P13 -> 108000.03 | N13: =ROUND(M13*6% + M13,0) + P13 -> 114480.03 | O13: =ROUND(M13*3%,0) + M13 -> 111240.03 | P13: =P12+0.01 -> 0.03
A14: 4 | B14: 2 B | C14: CRUZ ADRIANA BEATRIZ | D14: Cristian | E14: 6.6 | F14: 206119 | G14: =322065.64-115947 -> 206118.64 | H14: =F14-G14 -> 0.36 | I14: =IF(H14>0,H14*3%,0) -> 0.0108 | J14: =EDESUR!I8 -> 0 | K14: =L$2*E14/100 -> 132000 | L14: =G$2*E14/100 -> 0 | M14: =ROUND(SUM(H14:L14),0) + P14 -> 132000.04 | N14: =ROUND(M14*6% + M14,0) + P14 -> 139920.04 | O14: =ROUND(M14*3%,0) + M14 -> 135960.04 | P14: =P13+0.01 -> 0.04
A15: 5 | B15: 2 C | C15: D AMURI JOSE LUIS | D15: Martina Belen Carbone | E15: 6.6 | F15: 301901 | G15: =F15 -> 301901 | H15: =F15-G15 -> 0 | I15: =IF(H15>0,H15*3%,0) -> 0 | J15: =EDESUR!I9 -> 0 | K15: =L$2*E15/100 -> 132000 | L15: =G$2*E15/100 -> 0 | M15: =ROUND(SUM(H15:L15),0) + P15 -> 132000.05 | N15: =ROUND(M15*6% + M15,0) + P15 -> 139920.05 | O15: =ROUND(M15*3%,0) + M15 -> 135960.05 | P15: =P14+0.01 -> 0.05
A16: 6 | B16: 2 D | C16: CAMPOLONGO LUIS | D16: Leandro Gonzalez | E16: 5.4 | F16: 193307 | G16: =F16 -> 193307 | H16: =F16-G16 -> 0 | I16: =IF(H16>0,H16*3%,0) -> 0 | J16: =EDESUR!I10 -> 0 | K16: =L$2*E16/100 -> 108000 | L16: =G$2*E16/100 -> 0 | M16: =ROUND(SUM(H16:L16),0) + P16 -> 108000.06 | N16: =ROUND(M16*6% + M16,0) + P16 -> 114480.06 | O16: =ROUND(M16*3%,0) + M16 -> 111240.06 | P16: =P15+0.01 -> 0.06
A17: 7 | B17: 2 A | C17: PEREZ FERNANDO ARIEL | D17: Gaston Miranda | E17: 5.4 | F17: 287266 | G17: =171318+115948 -> 287266 | H17: =F17-G17 -> 0 | I17: =IF(H17>0,H17*3%,0) -> 0 | J17: =EDESUR!I11 -> 0 | K17: =L$2*E17/100 -> 108000 | L17: =G$2*E17/100 -> 0 | M17: =ROUND(SUM(H17:L17),0) + P17 -> 108000.07 | N17: =ROUND(M17*6% + M17,0) + P17 -> 114480.07 | O17: =ROUND(M17*3%,0) + M17 -> 111240.07 | P17: =P16+0.01 -> 0.07
A18: 8 | B18: 3 B | C18: BURGOA CARINA | D18: Alan/Ailen | E18: 6.6 | F18: 274735 | G18: =F18 -> 274735 | H18: =F18-G18 -> 0 | I18: =IF(H18>0,H18*3%,0) -> 0 | J18: =EDESUR!I12 -> 0 | K18: =L$2*E18/100 -> 132000 | L18: =G$2*E18/100 -> 0 | M18: =ROUND(SUM(H18:L18),0) + P18 -> 132000.08 | N18: =ROUND(M18*6% + M18,0) + P18 -> 139920.08 | O18: =ROUND(M18*3%,0) + M18 -> 135960.08 | P18: =P17+0.01 -> 0.08
A19: 9 | B19: 3 C | C19: GIL ROSANNA MABEL | D19: Gaston ibarra | E19: 6.6 | F19: 228179 | G19: =219377+8802 -> 228179 | H19: =F19-G19 -> 0 | I19: =IF(H19>0,H19*3%,0) -> 0 | J19: =EDESUR!I13 -> 0 | K19: =L$2*E19/100 -> 132000 | L19: =G$2*E19/100 -> 0 | M19: =ROUND(SUM(H19:L19),0) + P19 -> 132000.09 | N19: =ROUND(M19*6% + M19,0) + P19 -> 139920.09 | O19: =ROUND(M19*3%,0) + M19 -> 135960.09 | P19: =P18+0.01 -> 0.09
A20: 10 | B20: 3 D | C20: FELIX ALBERTO | D20: Jhonatan | E20: 5.4 | F20: 269046 | G20: =286548-G31-8802+3320 -> 272366 | H20: =F20-G20 -> -3320 | I20: =IF(H20>0,H20*3%,0) -> 0 | J20: =EDESUR!I14 -> 0 | K20: =L$2*E20/100 -> 108000 | L20: =G$2*E20/100 -> 0 | M20: =ROUND(SUM(H20:L20),0) + P20 -> 104680.1 | N20: =ROUND(M20*6% + M20,0) + P20 -> 110961.1 | O20: =ROUND(M20*3%,0) + M20 -> 107820.1 | P20: =P19+0.01 -> 0.1
A21: 11 | B21: 3 A | C21: CAMPANA WALTER CESAR | E21: 5.4 | F21: 169635 | G21: =178335-G32 -> 169635 | H21: =F21-G21 -> 0 | I21: =IF(H21>0,H21*3%,0) -> 0 | J21: =EDESUR!I15 -> 0 | K21: =L$2*E21/100 -> 108000 | L21: =G$2*E21/100 -> 0 | M21: =ROUND(SUM(H21:L21),0) + P21 -> 108000.11 | N21: =ROUND(M21*6% + M21,0) + P21 -> 114480.11 | O21: =ROUND(M21*3%,0) + M21 -> 111240.11 | P21: =P20+0.01 -> 0.11 | Q21: Antonella
A22: 12 | B22: 4 B | C22: PALMA JOSE AGUSTIN | D22: Juan Ignacio / Mariel Cruz | E22: 6.6 | F22: 226859 | G22: =F22 -> 226859 | H22: =F22-G22 -> 0 | I22: =IF(H22>0,H22*3%,0) -> 0 | J22: =EDESUR!I16 -> 0 | K22: =L$2*E22/100 -> 132000 | L22: =G$2*E22/100 -> 0 | M22: =ROUND(SUM(H22:L22),0) + P22 -> 132000.12 | N22: =ROUND(M22*6% + M22,0) + P22 -> 139920.12 | O22: =ROUND(M22*3%,0) + M22 -> 135960.12 | P22: =P21+0.01 -> 0.12
A23: 13 | B23: 4 C | C23: BENITEZ EMILIA ISABEL | D23: Daniel Leiva | E23: 6.6 | F23: 236320 | G23: =F23 -> 236320 | H23: =F23-G23 -> 0 | I23: =IF(H23>0,H23*3%,0) -> 0 | J23: =EDESUR!I17 -> 0 | K23: =L$2*E23/100 -> 132000 | L23: =G$2*E23/100 -> 0 | M23: =ROUND(SUM(H23:L23),0) + P23 -> 132000.13 | N23: =ROUND(M23*6% + M23,0) + P23 -> 139920.13 | O23: =ROUND(M23*3%,0) + M23 -> 135960.13 | P23: =P22+0.01 -> 0.13
A24: 14 | B24: 4 D | C24: PUCHETA SANTIAGO / CLARA | E24: 5.4 | F24: 337128 | G24: =F24 -> 337128 | H24: =F24-G24 -> 0 | I24: =IF(H24>0,H24*3%,0) -> 0 | J24: =EDESUR!I18 -> 0 | K24: =L$2*E24/100 -> 108000 | L24: =G$2*E24/100 -> 0 | M24: =ROUND(SUM(H24:L24),0) + P24 -> 108000.14 | N24: =ROUND(M24*6% + M24,0) + P24 -> 114480.14 | O24: =ROUND(M24*3%,0) + M24 -> 111240.14 | P24: =P23+0.01 -> 0.14
A25: 15 | B25: 4 A | C25: CAMPANA MIRIAM NOEMI | E25: 5.4 | F25: 308054 | G25: =F25 -> 308054 | H25: =F25-G25 -> 0 | I25: =IF(H25>0,H25*3%,0) -> 0 | J25: =EDESUR!I19 -> 0 | K25: =L$2*E25/100 -> 108000 | L25: =G$2*E25/100 -> 0 | M25: =ROUND(SUM(H25:L25),0) + P25 -> 108000.15 | N25: =ROUND(M25*6% + M25,0) + P25 -> 114480.15 | O25: =ROUND(M25*3%,0) + M25 -> 111240.15 | P25: =P24+0.01 -> 0.15
A26: 16 | B26: COC 1 | C26: CAMPOLONGO LUIS | D26: Leandro Gonzalez | E26: 0.7 | F26: 20300 | G26: =F26 -> 20300 | H26: =F26-G26 -> 0 | I26: =IF(H26>0,H26*3%,0) -> 0 | J26: =EDESUR!I22 -> 0 | K26: =L$2*E26/100 -> 14000 | L26: =G$2*E26/100 -> 0 | M26: =ROUND(SUM(H26:L26),0) + P26 -> 14000.16 | N26: =ROUND(M26*6% + M26,0) + P26 -> 14840.16 | O26: =ROUND(M26*3%,0) + M26 -> 14420.16 | P26: =P25+0.01 -> 0.16
A27: 17 | B27: COC 2 | C27: MIRAGLIA NORBERTO JOSE | E27: 0.6 | F27: 17400 | G27: =F27 -> 17400 | H27: =F27-G27 -> 0 | I27: =IF(H27>0,H27*3%,0) -> 0 | J27: =EDESUR!I21 -> 0 | K27: =L$2*E27/100 -> 12000 | L27: =G$2*E27/100 -> 0 | M27: =ROUND(SUM(H27:L27),0) + P27 -> 12000.17 | N27: =ROUND(M27*6% + M27,0) + P27 -> 12720.17 | O27: =ROUND(M27*3%,0) + M27 -> 12360.17 | P27: =P26+0.01 -> 0.17
A28: 18 | B28: COC 3 | C28: MIRAGLIA NORBERTO JOSE | E28: 0.6 | F28: 17400 | G28: =F28 -> 17400 | H28: =F28-G28 -> 0 | I28: =IF(H28>0,H28*3%,0) -> 0 | J28: =EDESUR!I22 -> 0 | K28: =L$2*E28/100 -> 12000 | L28: =G$2*E28/100 -> 0 | M28: =ROUND(SUM(H28:L28),0) + P28 -> 12000.18 | N28: =ROUND(M28*6% + M28,0) + P28 -> 12720.18 | O28: =ROUND(M28*3%,0) + M28 -> 12360.18 | P28: =P27+0.01 -> 0.18
A29: 19 | B29: COC 4 | C29: PALMA JOSE AGUSTIN | E29: 0.6 | F29: 17400 | G29: =F29 -> 17400 | H29: =F29-G29 -> 0 | I29: =IF(H29>0,H29*3%,0) -> 0 | J29: =EDESUR!I23 -> 0 | K29: =L$2*E29/100 -> 12000 | L29: =G$2*E29/100 -> 0 | M29: =ROUND(SUM(H29:L29),0) + P29 -> 12000.19 | O29: =ROUND(M29*3%,0) + M29 -> 12360.19 | P29: =P28+0.01 -> 0.19
A30: 20 | B30: COC 5 | C30: CRUZ ADRIANA BEATRIZ | D30: Cristian | E30: 0.6 | F30: 17400 | G30: =F30 -> 17400 | H30: =F30-G30 -> 0 | I30: =IF(H30>0,H30*3%,0) -> 0 | J30: =EDESUR!I24 -> 0 | K30: =L$2*E30/100 -> 12000 | L30: =G$2*E30/100 -> 0 | M30: =ROUND(SUM(H30:L30),0) + P30 -> 12000 | O30: =ROUND(M30*3%,0) + M30 -> 12360
A31: 21 | B31: COC 6 | C31: FELIX ALBERTO | D31: Jhonatan | E31: 0.3 | F31: 8700 | G31: =F31 -> 8700 | H31: =F31-G31 -> 0 | I31: =IF(H31>0,H31*3%,0) -> 0 | J31: =EDESUR!I25 -> 0 | K31: =L$2*E31/100 -> 6000 | L31: =G$2*E31/100 -> 0 | M31: =ROUND(SUM(H31:L31),0) + P31 -> 6000 | O31: =ROUND(M31*3%,0) + M31 -> 6180
A32: 22 | B32: COC 7 | C32: CAMPANA WALTER CESAR | E32: 0.3 | F32: 8700 | G32: =F32 -> 8700 | H32: =F32-G32 -> 0 | I32: =IF(H32>0,H32*3%,0) -> 0 | J32: =EDESUR!I26 -> 0 | K32: =L$2*E32/100 -> 6000 | L32: =G$2*E32/100 -> 0 | M32: =ROUND(SUM(H32:L32),0) + P32 -> 6000 | O32: =ROUND(M32*3%,0) + M32 -> 6180
A33: 23 | B33: COC 8 | C33: REDONDO HECTOR | D33: Gilmer | E33: 0.3 | F33: 8700 | G33: =F33 -> 8700 | H33: =F33-G33 -> 0 | I33: =IF(H33>0,H33*3%,0) -> 0 | J33: =EDESUR!I27 -> 0 | K33: =L$2*E33/100 -> 6000 | L33: =G$2*E33/100 -> 0 | M33: =ROUND(SUM(H33:L33),0) + P33 -> 6000 | O33: =ROUND(M33*3%,0) + M33 -> 6180
E34: =SUM(E11:E33) -> 100 | F34: =SUM(F11:F33) -> 4064598 | G34: =SUM(G11:G33) -> 4067977.6 | H34: =SUM(H11:H33) -> -3379.64 | I34: =SUM(I11:I33) -> 0.0108 | J34: =SUM(J11:J33) -> 0 | K34: =SUM(K11:K33) -> 2000000 | L34: =SUM(L11:L33) -> 0 | M34: =SUM(M11:M28) -> 1954621.7 | N34: =SUM(N11:N33) -> 2071898.7 | O34: =SUM(O11:O33) -> 2056519.9
C37: =RESUMEN!A13 -> ESTIMADOS PROPIETARIOS E INQUILINOS: POR FAVOR LOS QUE ABONAN EN PRIMER VENCIMIENTO ABONEN EL MONTO DE PRIMER VENCIMIENTO, ASI AGILIZAN LA LIQUIDACION, RESPETEN LOS CENTAVOS CORRESPONDIENTES A LA UNIDAD FUNCIONAL. ES DE CARÁCTER OBLIGATORIO INFORMAR VIA MAIL LAS EXPENSAS. PORFAVOR RESPETAR LOS CENTAVOS AL ABONAR.

Sheet EDESUR
B3: Piso | C3: Depto | E3: Total Edesur x Depto | G3: Bonificado x EDESUR | I3: SALDO a PAGAR
B4: 1 | C4: A
B5: 1 | C5: C | E5: 61353.384 | G5: 61353.384 | I5: =E5-G5 -> 0
B6: 1 | C6: D | E6: 34428.701 | G6: 34428.701 | I6: =E6-G6 -> 0
B7: 2 | C7: A | E7: 14356.011 | G7: 14356.011 | I7: =E7-G7 -> 0
B8: 2 | C8: B | E8: 12061.218 | G8: 12061.218 | I8: =E8-G8 -> 0
B9: 2 | C9: C | E9: 53068.035 | G9: 53068.035 | I9: =E9-G9 -> 0
B10: 2 | C10: D | E10: 9841.6389 | G10: 9841.6389 | I10: =E10-G10 -> 0
B11: 3 | C11: A | E11: 9327.3712 | G11: 9327.3712 | I11: =E11-G11 -> 0
B12: 3 | C12: B | E12: 9216.144 | G12: 9216.144 | I12: =E12-G12 -> 0
B13: 3 | C13: C | E13: 23200.609 | G13: 23200.609 | I13: =E13-G13 -> 0
B14: 3 | C14: D | E14: 7781.0089 | G14: 7781.0089 | I14: =E14-G14 -> 0
B15: 4 | C15: A | E15: 10351.832 | G15: 10351.832 | I15: =E15-G15 -> 0
B16: 4 | C16: B | E16: 49509.655 | G16: 49509.655 | I16: =E16-G16 -> 0
... B18: 4 | C18: D | E18: 24968.536 | G18: 24968.536 | I18: =E18-G18 -> 0
E19: 10779.179 | G19: 10779.179 | I19: =E19-G19 -> 0
C20: Totales
E21: 347109.84 | G21: =SUM(G5:G20) -> 347109.84 | I21: =E21-G21 -> 0
B22: Cochera | C22: 1 | E22: 723.43332 | G22: 723.43332 | I22: =E22-G22 -> 0
B23: Cochera | C23: 2 | E23: 620.0857 | G23: 620.0857 | I23: =E23-G23 -> 0
B24: Cochera | C24: 3 | E24: 620.0857 | G24: 620.0857 | I24: =E24-G24 -> 0
B25: Cochera | C25: 4 | E25: 620.0857 | G25: 620.0857 | I25: =E25-G25 -> 0
B26: Cochera | C26: 5 | E26: 620.0857 | G26: 620.0857 | I26: =E26-G26 -> 0
B27: Cochera | C27: 6 | E27: 310.04285 | G27: 310.04285 | I27: =E27-G27 -> 0
B28: Cochera | C28: 7 | E28: 310.04285 | G28: 310.04285 | I28: =E28-G28 -> 0
B29: Cochera | C29: 8 | E29: 310.04285 | G29: 310.04285 | I29: =E29-G29 -> 0
E30: 4133.9047 | G30: =SUM(G22:G29) -> 4133.9047 | I30: =E30-G30 -> 0
I31: =E31-G31 -> 0
E33: 351243.74 | G33: =G21+G30 -> 351243.74 | I33: =E33-G33 -> 0
