Workbook

Sheet RESUMEN
B1: Domicilio: Dr. Melo Nº 2958 - 8VO PISO - Con cita previa
B2: consorciobelgrano1640@gmail.com
B3: Santander cuenta 039-010552/1
B4: CBU: 0720039720000001055218
A5: LIQUIDACION DE EXPENSAS | B5: PERÍODO: JUNIO | C5: VTO: 14/07
A6: CUIT: 33-71826987-9
A7: CONSORCIO DE PROPIETARIOS DEL EDIFICIO CALLE BELGRANO NUMERO 1640/1646 BANFIELD PARTIDO DE LOMAS DE ZAMORA
B14: Los gastos que se encuentras subrayados son los que corresponden tanto a las unidades funcionales como tambien al local
A21: GASTOS ORDINARIOS UNIDADES FUNCIONALES: | E21: UF 91,91% | F21: LOCAL 8,09%
A22: Sr. Diego Britez (1) | B22: Honorarios JUNIO
A23: Haberes | D23: 1234864.1 | E23: =D23*91.91% -> 1134963.6 | F23: =D23*8.09% -> 99900.506
A24: Deducciones | D24: -268582.93 | E24: =D24*91.91% -> -246854.57 | F24: =D24*8.09% -> -21728.359
A25: Redondeo | D25: 0.83 | E25: =D25*91.91% -> 0.762853 | F25: =D25*8.09% -> 0.067147
A26: Remis Sr. Diego - Dias de paro | D26: 13000 | E26: =D26*91.91% -> 11948.3 | F26: =D26*8.09% -> 1051.7
A30: TOTAL SUELDO | D30: =SUM(D23:D29) -> 979282 | E30: =SUM(E23:E29) -> 900058.09 | F30: =SUM(F23:F29) -> 79223.914 | G30: =E30+F30 -> 979282 | H30: =IF(D30=G30, "", "Error")
A31: SAC | D31: 0 | E31: =D31*91.91% -> 0 | F31: =D31*8.09% -> 0
D32: 0 | E32: =D32*91.91% -> 0 | F32: =D32*8.09% -> 0
A35: TOTAL | D35: =SUM(D31:D33) -> 0 | E35: =SUM(E31:E33) -> 0 | F35: =SUM(F31:F33) -> 0 | G35: =E35+F35 -> 0 | H35: =IF(D35=G35, "", "Error")
A36: SAC | E36: =D36*91.91% -> 0 | F36: =D36*8.09% -> 0
A37: Redondeo | E37: =D37*91.91% -> 0 | F37: =D37*8.09% -> 0
A38: Deducciones | E38: =D38*91.91% -> 0 | F38: =D38*8.09% -> 0
A39: TOTAL SAC | D39: =SUM(D32:D38) -> 0 | E39: =SUM(E32:E38) -> 0 | F39: =E39*8.09% -> 0
A43: TOTAL | E43: =SUM(D40:D42) -> 0 | F43: =(D40)*8.09% -> 0
E45: =D45 -> 0
E46: =D46*91.91% -> 0 | F46: =D46*8.09% -> 0
E47: =D47*91.91% -> 0 | F47: =D47*8.09% -> 0
A48: TOTAL REEMPLAZO | D48: =SUM(D45:D47) -> 0 | E48: =SUM(E45:E47) -> 0 | F48: =SUM(F45:F47) -> 0 | G48: =E48+F48 -> 0
A51: APORTES Y CONTRIBUCIONES
A52: SEGURO OBLIGATORIO SR DIEGO BRITEZ FEDERACION PATRONAL DEBITO AUTOMATICO 05/05 | D52: 5020 | E52: =D52*91.91% -> 4613.882 | F52: =D52*8.09% -> 406.118
A53: SUTERH - FATERYH - SARACAH | B53: Debito 12/05 | D53: =55568.88+6174.32+104266.16 -> 166009.36 | E53: =D53*91.91% -> 152579.2 | F53: =D53*8.09% -> 13430.157
A54: ARCA | B54: Pago mis cuentas 12/05 | D54: 546846.94 | E54: =D54*91.91% -> 502607.02 | F54: =D54*8.09% -> 44239.917
A55: TOTAL Aportes y Contribuciones - Sindicato | D55: =SUM(D52:D54) -> 717876.3 | E55: =SUM(E52:E54) -> 659800.11 | F55: =SUM(F52:F54) -> 58076.193 | G55: =E55+F55 -> 717876.3 | H55: =IF(D55=G55, "", "Error")
A56: ABONOS Y SERVICIOS
A57: Contessi provision y colocacion de 60 lts de aceite hidraulico en la sede del monta auto | D57: 700000 | E57: =D57 -> 700000 | G57: =D57 -> 700000 | H57: =E57+F57 -> 700000 | I57: =H57-D57 -> 0 | J57: =G57-D57 -> 0
A58: Contessi - Mantenimiento de ascensores | D58: 1350000 | E58: =D58 -> 1350000 | G58: =D58 -> 1350000 | H58: =E58+F58 -> 1350000 | I58: =H58-D58 -> 0 | J58: =G58-D58 -> 0
A59: Contessi | D59: 5000 | E59: =D59 -> 5000 | G59: =D59 -> 5000 | H59: =E59+F59 -> 5000 | I59: =H59-D59 -> 0
A60: Riesgo Uno | D60: 143638 | E60: =D60*91.91% -> 132017.69 | F60: =D60*8.09% -> 11620.314 | G60: =D60 -> 143638 | H60: =E60+F60 -> 143638 | I60: =H60-D60 -> 0 | J60: =G60-D60 -> 0
A61: Energoup MES DE JUNIO | D61: 129675 | E61: =D61*91.91% -> 119184.29 | F61: =D61*8.09% -> 10490.708 | G61: =D61 -> 129675 | H61: =E61+F61 -> 129675 | I61: =H61-D61 -> 0 | J61: =G61-D61 -> 0
A62: Seguro Poliza | B62: Numero 1859135 Debito automatico 5/05 | D62: 74622 | E62: =D62*91.91% -> 68585.08 | F62: =D62*8.09% -> 6036.9198 | G62: =D62 -> 74622 | H62: =E62+F62 -> 74622 | I62: =H62-D62 -> 0 | J62: =G62-D62 -> 0
A63: AYSA | D63: 614674.98 | E63: =D63*91.91% -> 564947.77 | F63: =D63*8.09% -> 49727.206 | G63: =D63 -> 614674.98 | H63: =E63+F63 -> 614674.98 | I63: =H63-D63 -> 0 | J63: =G63-D63 -> 0
...

Sheet PRORRATEO
F1: ESTADO DE CUENTA Y PRORRATEO | K1: SE GASTO: | L1: =RESUMEN!D116 -> 10659185 | O1: =L1*8.09% -> 862328.06
K2: SE PRORRATEA EN LAS UF: | M2: =5500000-150000-3015-250-12+1997000+170000+5497+450+30-1000000 -> 6519700 | O2: =O1-K7-553-50-86-8 -> 463199.32
A3: =RESUMEN!C5 -> VTO: 14/07 | K3: EXPENSAS EXTRA: | M3: =RESUMEN!D129 -> 310391.24
J4: =(J3*8.09%)/44 -> 0 | K4: SE PRORRATEA EN LAS UF: | M4: =25000+310391+3500-500-800+110+11 -> 337712
A5: Piso | B5: Dpto. | C5: UF | D5: Propietario | E5: (%) | F5: Saldo | G5: Ingreso | H5: SALDO | I5: Fecha | J5: Expensas extraor. | K5: Expensas ord | L5: SUM/ GASTOS PART | M5: TOTAL EXPENSAS 1er VTO | N5: TOTAL EXPENSAS 2do VTO
A7: PB | C7: 1 | D7: LOCAL 1 - DANIEL VIDAL | E7: 8.09 | F7: 330930.3 | G7: =F7 -> 330930.3 | H7: =F7-G7 -> 0 | I7: 14 | J7: 25110.651 | K7: 398431.74 | L7: 0 | M7: =K7+J7+H7+L7 -> 423542.39 | N7: =M7*6% + M7 -> 448954.93
A8: 3º | C8: 24 | D8: RODRIGUEZ, MARIA ROSA | E8: 2.21 | F8: 118110.04 | G8: 118500 | H8: =F8-G8 -> -389.96019 | I8: 8 | J8: =M$4*E8% -> 7463.4352 | K8: =M$2*E8 /100 -> 144085.37 | L8: =J$3*E8%+J$4 -> 0 | M8: =K8+J8+H8+L8 -> 151158.85 | N8: =M8*6% + M8 -> 160228.38
A9: 3º | C9: 25 | D9: RUSSO, JUAN ANTONIO | E9: 4.21 | F9: 222096.62 | G9: =250969-G34+RESUMEN!D66 -> 333122.7 | H9: =F9-G9 -> -111026.07 | I9: 7 | J9: =M$4*E9% -> 14217.675 | K9: =M$2*E9 /100 -> 274479.37 | L9: =J$3*E9%+J$4 -> 0 | M9: =K9+J9+H9+L9 -> 177670.97 | N9: =M9*6% + M9 -> 188331.23
A10: 4º | C10: 26 | D10: SALLABER, MARIA | E10: 2.84 | F10: 186446.71 | G10: 151845 | H10: =F10-G10 -> 34601.705 | I10: 9 | J10: =M$4*E10% -> 9591.0208 | K10: =M$2*E10 /100 -> 185159.48 | L10: =J$3*E10%+J$4 -> 0 | M10: =K10+J10+H10+L10 -> 229352.21 | N10: =M10*6% + M10 -> 243113.34
A11: 4º | C11: 27 | D11: COLATRELLA, CAROLINA | E11: 3.43 | F11: 183392.6 | G11: =F11 -> 183392.6 | H11: =F11-G11 -> 0 | I11: 9 | J11: =M$4*E11% -> 11583.522 | K11: =M$2*E11 /100 -> 223625.71 | L11: =J$3*E11%+J$4 -> 0 | M11: =K11+J11+H11+L11 -> 235209.23 | N11: =M11*6% + M11 -> 249321.79
A12: 5º | C12: 28 | D12: LUSENSKY, CARLOS | E12: 2.84 | F12: 151846.93 | G12: =F12 -> 151846.93 | H12: =F12-G12 -> 0 | I12: 6 | J12: =M$4*E12% -> 9591.0208 | K12: =M$2*E12 /100 -> 185159.48 | L12: =J$3*E12%+J$4 -> 0 | M12: =K12+J12+H12+L12 -> 194750.5 | N12: =M12*6% + M12 -> 206435.53
A13: 5º | C13: 29 | D13: DI TORO, ALEJANDRO | E13: 3.43 | F13: 167108.98 | G13: =198655-G50 -> 167109.33 | H13: =F13-G13 -> -0.35928076 | I13: 5 | J13: =M$4*E13% -> 11583.522 | K13: =M$2*E13 /100 -> 223625.71 | L13: =J$3*E13%+J$4 -> 0 | M13: =K13+J13+H13+L13 -> 235208.87 | N13: =M13*6% + M13 -> 249321.4
A14: 6º | C14: 30 | D14: PERAZA, MARTHA | E14: 2.84 | F14: 151846.93 | G14: =F14 -> 151846.93 | H14: =F14-G14 -> 0 | I14: 14 | J14: =M$4*E14% -> 9591.0208 | K14: =M$2*E14 /100 -> 185159.48 | L14: =J$3*E14%+J$4 -> 0 | M14: =K14+J14+H14+L14 -> 194750.5 | N14: =M14*6% + M14 -> 206435.53
A15: 6º | C15: 31 | D15: MARANTE, MAURO | E15: 3.43 | F15: 199779.77 | G15: =226514-G35 -> 199780.39 | H15: =F15-G15 -> -0.61555347 | I15: 8 | J15: =M$4*E15% -> 11583.522 | K15: =M$2*E15 /100 -> 223625.71 | L15: =J$3*E15%+J$4 -> 0 | M15: =K15+J15+H15+L15 -> 235208.62 | N15: =M15*6% + M15 -> 249321.13
A16: 7º | C16: 32 | D16: FEUILLANT, GASTON | E16: 2.84 | F16: 201082.98 | G16: =201083-G49 -> 174884.06 | H16: =F16-G16 -> 26198.925 | I16: 6 | J16: =M$4*E16% -> 9591.0208 | K16: =M$2*E16 /100 -> 185159.48 | L16: 0 | M16: =K16+J16+H16+L16 -> 220949.43 | N16: =M16*6% + M16 -> 234206.39
A17: 7º | C17: 33 | D17: CAMPANA, NESTOR | E17: 3.43 | F17: 214568 | G17: =255356-G47-G48 -> 199247.49 | H17: =F17-G17 -> 15320.513 | I17: 15 | J17: =M$4*E17% -> 11583.522 | K17: =M$2*E17 /100 -> 223625.71 | L17: =J$3*E17%+J$4 -> 0 | M17: =K17+J17+H17+L17 -> 250529.74 | N17: =M17*6% + M17 -> 265561.53
A18: 8º | C18: 34 | D18: JARA, CLAUDIO | E18: 2.84 | F18: 148953.67 | G18: =58000+76000+28000+16000+2000-G51 -> 149523.68 | H18: =F18-G18 -> -570.00522 | I18: 14 | J18: =M$4*E18% -> 9591.0208 | K18: =M$2*E18 /100 -> 185159.48 | L18: =J$3*E18%+J$4 -> 0 | M18: =K18+J18+H18+L18 -> 194180.5 | N18: =M18*6% + M18 -> 205831.33
A19: 8º | C19: 35 | D19: MIRAMONTES, HORACIO | E19: 3.43 | F19: 183392.92 | G19: =212265-G41 -> 183392.7 | H19: =F19-G19 -> 0.22636517 | I19: 5 | J19: =M$4*E19% -> 11583.522 | K19: =M$2*E19 /100 -> 223625.71 | L19: =J$3*E19%+J$4 -> 0 | M19: =K19+J19+H19+L19 -> 235209.46 | N19: =M19*6% + M19 -> 249322.03
A20: 9º | C20: 36 | D20: MELINA, ANDRES | E20: 2.84 | F20: 151847.83 | G20: =178047-G38 -> 151848.06 | H20: =F20-G20 -> -0.22969293 | I20: 5 | J20: =M$4*E20% -> 9591.0208 | K20: =M$2*E20 /100 -> 185159.48 | L20: =J$3*E20%+J$4 -> 0 | M20: =K20+J20+H20+L20 -> 194750.27 | N20: =M20*6% + M20 -> 206435.29
A21: 9º | C21: 37 | D21: GARCIA, MARIA SOL | E21: 3.43 | F21: 183392.32 | G21: =212264-G45 -> 183391.7 | H21: =F21-G21 -> 0.6286918 | I21: 5 | J21: =M$4*E21% -> 11583.522 | K21: =M$2*E21 /100 -> 223625.71 | L21: =J$3*E21%+J$4 -> 0 | M21: =K21+J21+H21+L21 -> 235209.86 | N21: =M21*6% + M21 -> 249322.45
A22: 10º | C22: 38 | D22: RATON, MARIELA | E22: 2.84 | F22: 151846.93 | G22: =F22 -> 151846.93 | H22: =F22-G22 -> 0 | I22: 7 | J22: =M$4*E22% -> 9591.0208 | K22: =M$2*E22 /100 -> 185159.48 | L22: =J$3*E22%+J$4 -> 0 | M22: =K22+J22+H22+L22 -> 194750.5 | N22: =M22*6% + M22 -> 206435.53
A23: 10º | C23: 39 | D23: DAVIN, ALEJANDRO | E23: 3.43 | F23: 385103.52 | G23: =447000-G46+RESUMEN!D71+RESUMEN!D72 -> 582942.09 | H23: =F23-G23 -> -197838.57 | I23: 5 | J23: =M$4*E23% -> 11583.522 | K23: =M$2*E23 /100 -> 223625.71 | L23: 20000 | M23: =K23+J23+H23+L23 -> 57370.666 | N23: =M23*6% + M23 -> 60812.906
A24: 11º | C24: 40 | D24: VROONLAND, DANIEL | E24: 2.84 | F24: 150534.55 | G24: =180000-G37 -> 153801.06 | H24: =F24-G24 -> -3266.5121 | I24: 5 | J24: =M$4*E24% -> 9591.0208 | K24: =M$2*E24 /100 -> 185159.48 | L24: =J$3*E24%+J$4 -> 0 | M24: =K24+J24+H24+L24 -> 191483.99 | N24: =M24*6% + M24 -> 202973.03
A25: 11º | C25: 41 | D25: SIMONASSI, ALEJO | E25: 3.43 | F25: 183392.6 | G25: =F25 -> 183392.6 | H25: =F25-G25 -> 0 | I25: 9 | J25: =M$4*E25% -> 11583.522 | K25: =M$2*E25 /100 -> 223625.71 | L25: =J$3*E25%+J$4 -> 0 | M25: =K25+J25+H25+L25 -> 235209.23 | N25: =M25*6% + M25 -> 249321.79
A26: 12º | C26: 42 | D26: VELAZ, ATILIO | E26: 6 | F26: -352713.93 | G26: =700000-G30-G31-G36 -> 614987.1 | H26: =F26-G26 -> -967701.03 | I26: 5 | J26: =M$4*E26% -> 20262.72 | K26: =M$2*E26 /100 -> 391182 | L26: =J$3*E26%+J$4 -> 0 | M26: =K26+J26+H26+L26 -> -556256.31 | N26: =M26*6% + M26 -> -589631.69
A27: 13º | C27: 43 | D27: AGÜERO, MIRIAM S | E27: 5.89 | F27: 314921.57 | G27: =377000-G39-G40 -> 314978.01 | H27: =F27-G27 -> -56.440465 | I27: 8 | J27: =M$4*E27% -> 19891.237 | K27: =M$2*E27 /100 -> 384010.33 | L27: =J$3*E27%+J$4 -> 0 | M27: =K27+J27+H27+L27 -> 403845.13 | N27: =M27*6% + M27 -> 428075.83
A28: 14º | C28: 44 | D28: VILLA, JUAN MANUEL | E28: 5.89 | F28: 314286.42 | G28: =371000-G32-G33+RESUMEN!D74 -> 413583.79 | H28: =F28-G28 -> -99297.37 | I28: 5 | J28: =M$4*E28% -> 19891.237 | K28: =M$2*E28 /100 -> 384010.33 | L28: =J$3*E28%+J$4 -> 0 | M28: =K28+J28+H28+L28 -> 304604.2 | N28: =M28*6% + M28 -> 322880.45
A29: 15º | C29: 45 | D29: TOLOSA, FABIO | E29: 5.89 | F29: 325490.37 | G29: =401000-G42-G43-G44+RESUMEN!D73 -> 413311.72 | H29: =F29-G29 -> -87821.349 | I29: 5 | J29: =M$4*E29% -> 19891.237 | K29: =M$2*E29 /100 -> 384010.33 | L29: =J$3*E29%+J$4 -> 0 | M29: =K29+J29+H29+L29 -> 316080.22 | N29: =M29*6% + M29 -> 335045.03
A30: COC | C30: 1 | D30: VELAZ, ATILIO | E30: 0.54 | F30: 28872.304 | G30: =F30 -> 28872.304 | H30: =F30-G30 -> 0 | J30: =M$4*E30% -> 1823.6448 | K30: =M$2*E30 /100 -> 35206.38 | L30: =J$3*E30%+J$4 -> 0 | M30: =K30+J30+H30+L30 -> 37030.025 | N30: =M30*6% + M30 -> 39251.826
A31: COC | C31: 2 | D31: VELAZ, ATILIO | E31: 0.55 | F31: 29406.977 | G31: =F31 -> 29406.977 | H31: =F31-G31 -> 0 | J31: =M$4*E31% -> 1857.416 | K31: =M$2*E31 /100 -> 35858.35 | L31: =J$3*E31%+J$4 -> 0 | M31: =K31+J31+H31+L31 -> 37715.766 | N31: =M31*6% + M31 -> 39978.712
A32: COC | C32: 3 | D32: VILLA, JUAN MANUEL | E32: 0.45 | F32: 24060.254 | G32: =F32 -> 24060.254 | H32: =F32-G32 -> 0 | J32: =M$4*E32% -> 1519.704 | K32: =M$2*E32 /100 -> 29338.65 | L32: =J$3*E32%+J$4 -> 0 | M32: =K32+J32+H32+L32 -> 30858.354 | N32: =M32*6% + M32 -> 32709.855
A33: COC | C33: 4 | D33: VILLA, JUAN MANUEL | E33: 0.61 | F33: 32615.01 | G33: =F33 -> 32615.01 | H33: =F33-G33 -> 0 | J33: =M$4*E33% -> 2060.0432 | K33: =M$2*E33 /100 -> 39770.17 | L33: =J$3*E33%+J$4 -> 0 | M33: =K33+J33+H33+L33 -> 41830.213 | N33: =M33*6% + M33 -> 44340.026
A34: COC | C34: 5 | D34: RUSSO, JUAN ANTONIO | E34: 0.54 | F34: 28872.304 | G34: =F34 -> 28872.304 | H34: =F34-G34 -> 0 | J34: =M$4*E34% -> 1823.6448 | K34: =M$2*E34 /100 -> 35206.38 | L34: =J$3*E34%+J$4 -> 0 | M34: =K34+J34+H34+L34 -> 37030.025 | N34: =M34*6% + M34 -> 39251.826
A35: COC | C35: 6 | D35: MARANTE, MAURO | E35: 0.5 | F35: 26733.615 | G35: =F35 -> 26733.615 | H35: =F35-G35 -> 0 | J35: =M$4*E35% -> 1688.56 | K35: =M$2*E35 /100 -> 32598.5 | L35: =J$3*E35%+J$4 -> 0 | M35: =K35+J35+H35+L35 -> 34287.06 | N35: =M35*6% + M35 -> 36344.284
A36: COC | C36: 7 | D36: VELAZ, ATILIO | E36: 0.5 | F36: 26733.615 | G36: =F36 -> 26733.615 | H36: =F36-G36 -> 0 | J36: =M$4*E36% -> 1688.56 | K36: =M$2*E36 /100 -> 32598.5 | L36: =J$3*E36%+J$4 -> 0 | M36: =K36+J36+H36+L36 -> 34287.06 | N36: =M36*6% + M36 -> 36344.284
A37: COC | C37: 8 | D37: VROONLAND, DANIEL | E37: 0.49 | F37: 26198.943 | G37: =F37 -> 26198.943 | H37: =F37-G37 -> 0 | J37: =M$4*E37% -> 1654.7888 | K37: =M$2*E37 /100 -> 31946.53 | L37: =J$3*E37%+J$4 -> 0 | M37: =K37+J37+H37+L37 -> 33601.319 | N37: =M37*6% + M37 -> 35617.398
A38: COC | C38: 9 | D38: MELINA, ANDRES | E38: 0.49 | F38: 26198.943 | G38: =F38 -> 26198.943 | H38: =F38-G38 -> 0 | J38: =M$4*E38% -> 1654.7888 | K38: =M$2*E38 /100 -> 31946.53 | L38: =J$3*E38%+J$4 -> 0 | M38: =K38+J38+H38+L38 -> 33601.319 | N38: =M38*6% + M38 -> 35617.398
A39: COC | C39: 10 | D39: AGÜERO, MIRIAM S | E39: 0.59 | F39: 31545.666 | G39: =F39 -> 31545.666 | H39: =F39-G39 -> 0 | J39: =M$4*E39% -> 1992.5008 | K39: =M$2*E39 /100 -> 38466.23 | L39: =J$3*E39%+J$4 -> 0 | M39: =K39+J39+H39+L39 -> 40458.731 | N39: =M39*6% + M39 -> 42886.255
A40: COC | C40: 11 | D40: AGÜERO, MIRIAM S | E40: 0.57 | F40: 30476.321 | G40: =F40 -> 30476.321 | H40: =F40-G40 -> 0 | J40: =M$4*E40% -> 1924.9584 | K40: =M$2*E40 /100 -> 37162.29 | L40: =J$3*E40%+J$4 -> 0 | M40: =K40+J40+H40+L40 -> 39087.248 | N40: =M40*6% + M40 -> 41432.483
A41: COC | C41: 12 | D41: MIRAMONTES, HORACIO | E41: 0.54 | F41: 28872.304 | G41: =F41 -> 28872.304 | H41: =F41-G41 -> 0 | J41: =M$4*E41% -> 1823.6448 | K41: =M$2*E41 /100 -> 35206.38 | L41: =J$3*E41%+J$4 -> 0 | M41: =K41+J41+H41+L41 -> 37030.025 | N41: =M41*6% + M41 -> 39251.826
...

Sheet COCHERA
D1: ESTADO DE CUENTA Y PRORRATEO | L1: Vencimiento | N1: =RESUMEN!C5 -> VTO: 14/07
D2: BELGRANO Nº 1640
J3: Gastos Ordinario: | L3: 249991.3 | N3: -1891.33
J4: Gastos Extr.: | L4: 0
A5: Cochera | B5: Propietario | C5: Porcentaje | D5: Saldo | E5: Ingreso | F5: DEUDAS | G5: Deuda exp | H5: Intereses | I5: porcentaje | J5: Expensas | K5: Expensas | L5: TOTAL | N5: 1ER Vto. | O5: 2DO Vto.
C6: (%) | D6: Anterior | E6: Exp. Ord. | G6: Extraord | H6: 0.06 | I6: % | J6: Ord. | K6: Extr. | L6: EXPENSAS
A7: 1 | B7: VELAZ, ATILIO | C7: 5.4 | D7: 13967.239 | E7: =D7 -> 13967.239 | F7: 0 | G7: 0 | H7: 0 | I7: 0.54 | J7: 11608.2 | K7: 0 | L7: 11608.2 | N7: 11608.2 | O7: 12304.692
A8: 2 | B8: VELAZ, ATILIO | C8: 5.5 | D8: 14267.901 | E8: =D8 -> 14267.901 | F8: 0 | G8: 0 | H8: 0 | I8: 0.55 | J8: 11858.191 | K8: 0 | L8: 11858.191 | N8: 11858.191 | O8: 12569.683
A9: 3 | B9: VILLA, JUAN MANUEL | C9: 4.5 | D9: 11261.283 | E9: =D9 -> 11261.283 | F9: 0 | G9: 0 | H9: 0 | I9: 0.45 | J9: 9358.2784 | K9: 0 | L9: 9358.2784 | N9: 9358.2784 | O9: 9919.7751
A10: 4 | B10: VILLA, JUAN MANUEL | C10: 6.1 | D10: 16071.872 | E10: =D10 -> 16071.872 | F10: 0 | G10: 0 | H10: 0 | I10: 0.61 | J10: 13358.139 | K10: 0 | L10: 13358.139 | N10: 13358.139 | O10: 14159.628
A11: 5 | B11: RUSSO, JUAN ANTONIO | C11: 5.4 | D11: 13967.239 | E11: =D11 -> 13967.239 | F11: 0 | G11: 0 | H11: 0 | I11: 0.54 | J11: 11608.2 | K11: 0 | L11: 11608.2 | N11: 11608.2 | O11: 12304.692
A12: 6 | B12: MARANTE, MAURO | C12: 5 | D12: 12764.592 | E12: =D12 -> 12764.592 | F12: 0 | G12: 0 | H12: 0 | I12: 0.5 | J12: 10608.235 | K12: 0 | L12: 10608.235 | N12: 10608.235 | O12: 11244.729
A13: 7 | B13: VELAZ, ATILIO | C13: 5 | D13: 12764.592 | E13: =D13 -> 12764.592 | F13: 0 | G13: 0 | H13: 0 | I13: 0.5 | J13: 10608.235 | K13: 0 | L13: 10608.235 | N13: 10608.235 | O13: 11244.729
A14: 8 | B14: VROONLAND, DANIEL | C14: 4.9 | D14: 12463.93 | E14: =D14 -> 12463.93 | F14: 0 | G14: 0 | H14: 0 | I14: 0.49 | J14: 10358.244 | K14: 0 | L14: 10358.244 | N14: 10358.244 | O14: 10979.738
A15: 9 | B15: MELINA, ANDRES | C15: 4.9 | D15: 12463.93 | E15: =D15 -> 12463.93 | F15: 0 | G15: 0 | H15: 0 | I15: 0.49 | J15: 10358.244 | K15: 0 | L15: 10358.244 | N15: 10358.244 | O15: 10979.738
A16: 10 | B16: AGÜERO, MIRIAM S | C16: 5.9 | D16: 15470.549 | E16: =D16 -> 15470.549 | F16: 0 | G16: 0 | H16: 0 | I16: 0.59 | J16: 12858.157 | K16: 0 | L16: 12858.157 | N16: 12858.157 | O16: 13629.646
A17: 11 | B17: AGÜERO, MIRIAM S | C17: 5.7 | D17: 14869.225 | E17: =D17 -> 14869.225 | F17: 0 | G17: 0 | H17: 0 | I17: 0.57 | J17: 12358.174 | K17: 0 | L17: 12358.174 | N17: 12358.174 | O17: 13099.664
A18: 12 | B18: MIRAMONTES, HORACIO | C18: 5.4 | D18: 13967.239 | E18: =D18 -> 13967.239 | F18: 0 | G18: 0 | H18: 0 | I18: 0.54 | J18: 11608.2 | K18: 0 | L18: 11608.2 | N18: 11608.2 | O18: 12304.692
... A28: 22 | B28: JARA, CLAUDIO | C28: 5.7 | D28: 14869.225 | E28: =D28 -> 14869.225 | F28: 0 | G28: 0 | H28: 0 | I28: 0.57 | J28: 12358.174 | K28: 0 | L28: 12358.174 | N28: 12358.174 | O28: 13099.664
C30: 116.6 | D30: 161487.47 | E30: 161487.47 | F30: 0 | G30: 0 | H30: 0 | I30: 11.66 | J30: 249880.59 | K30: 0 | L30: 249880.59 | N30: 249880.59 | O30: 264873.43
