Workbook

Sheet detalle y gastos
B2: CANCIANI, Carolina | C2: MP 1148
B3: Tel. 11 5320-2676
B4: consorciosrc13@gmail.com
A7: LIQUIDACIÓN EXPENSAS FEBRERO 2025
A10: Teléfonos útiles
A11: EDESUR 0800-333-3787
A12: AySA 0800-321-2482
A13: Metrogas 0800-333-6427
A15: GASTOS ORDINARIOS
A16: ABONOS y SERVICIOS
A17: AYSA | B17: Pago efectivo | C17: 74825.29
C20: =SUM(C17:C19) -> 74825.29
A21: LIMPIEZA / MANTENIMIENTO / GASTOS GENERALES
A22: Honorarios FEBRERO 2025 | C22: 30000
A23: Poliza de Seguro Obligatoria Mercantil andina N. 1181593 | C23: 36534.6
A26: Prevision ordinaria | C26: 150000
C27: =SUM(C21:C26) -> 216534.6
A28: TOTAL GASTOS ORDINARIOS (A) - SIN CONTAR EDESUR | C28: =+C27+C20 -> 291359.89
A30: GASTOS EXTRAORDINARIOS
A35: TOTAL GASTOS EXTRAORDINARIOS (B) | C35: =+C31+C32+C33+C34 -> 0
A37: TOTAL GENERAL DE GASTOS (A) + (B) | C37: =+C35+C28 -> 291359.89
A39: ESTADO FINACIERO
A40: Saldo anterior | C40: -225247.17
A41: Ingreso por pago de expensas en término | C41: ='prorrateo '!F15 -> 234321.67
A42: Edesur | C42: =-edesur!H1 -> 0
A43: Egresos por gastos del mes ordinarios | C43: =-(C28-C26) -> -141359.89
A44: Saldo al cierre $ (pesos) | C44: =SUM(C40:C43) -> -132285.4
A48: CAJA EXTRAORDINARIA | C48: 0
A49: Egreso extraordinario | C49: =-C35 -> 0
A52: TOTAL | C52: =SUM(C48:C51) -> 0

Sheet prorrateo 
A1: EXPENSAS ORDINARIAS | E1: 291359.89
A2: ='detalle y gastos'!B7 -> 0
A3: Dpto. | C3: Propietario | D3: Inquilinos | E3: Saldo | F3: Pagos | G3: DEUDA | H3: Intereses | I3: % | J3: Expensas ord. | K3: EDESUR | L3: TOTAL
E4: Anterior | F4: Exp. Ord. | H4: 0.04 | L4: EXPENSAS
A5: 1 | C5: Gomez Elizabeth | E5: 31310.713 | F5: =E5 -> 31310.713 | G5: =E5-F5 -> 0 | H5: =IF(G5>0,G5*4%,0) -> 0 | I5: 13.8 | J5: =E$1*I5/100 -> 40207.665 | K5: =edesur!H5 -> 0 | L5: =G5+H5+J5+K5 -> 40207.665
A6: 2 | C6: Maceyle Gabriela | D6: Caro Manay | E6: 30871.318 | F6: =E6 -> 30871.318 | G6: =E6-F6 -> 0 | H6: =IF(G6>0,G6*4%,0) -> 0 | I6: 11.86 | J6: =E$1*I6/100 -> 34555.283 | K6: =edesur!H6 -> 0 | L6: =G6+H6+J6+K6 -> 34555.283
A7: 3 | C7: Maceyle Gabriela | D7: Pereyra Amanda | E7: 31575.546 | F7: =E7 -> 31575.546 | G7: =E7-F7 -> 0 | H7: =IF(G7>0,G7*4%,0) -> 0 | I7: 12.46 | J7: =E$1*I7/100 -> 36303.442 | K7: =edesur!H7 -> 0 | L7: =G7+H7+J7+K7 -> 36303.442
A8: 4 | C8: Castelao Lorena | D8: Maitena E. | E8: 36252.089 | F8: =E8 -> 36252.089 | G8: =E8-F8 -> 0 | H8: =IF(G8>0,G8*4%,0) -> 0 | I8: 14.75 | J8: =E$1*I8/100 -> 42975.584 | K8: =edesur!H8 -> 0 | L8: =G8+H8+J8+K8 -> 42975.584
A9: 5 | C9: Grand Jorge | D9: Enciso Marisa | E9: 26179.162 | F9: =E9 -> 26179.162 | G9: =E9-F9 -> 0 | H9: =IF(G9>0,G9*4%,0) -> 0 | I9: 12.41 | J9: =E$1*I9/100 -> 36157.762 | K9: =edesur!H9 -> 0 | L9: =G9+H9+J9+K9 -> 36157.762
A10: 6 | C10: Valdez Norberto | E10: 26422.053 | F10: =E10 -> 26422.053 | G10: =E10-F10 -> 0 | H10: =IF(G10>0,G10*4%,0) -> 0 | I10: 12.48 | J10: =E$1*I10/100 -> 36361.714 | K10: =edesur!H10 -> 0 | L10: =G10+H10+J10+K10 -> 36361.714
A11: 7 | C11: Lean Cosenza | E11: 39198.726 | F11: =E11 -> 39198.726 | G11: =E11-F11 -> 0 | H11: =IF(G11>0,G11*4%,0) -> 0 | I11: 18.26 | J11: =E$1*I11/100 -> 53202.316 | K11: =edesur!H11 -> 0 | L11: =G11+H11+J11+K11 -> 53202.316
A12: COCH A | C12: =C9 -> Grand Jorge | E12: 4212.6037 | F12: =E12 -> 4212.6037 | G12: =E12-F12 -> 0 | H12: =IF(G12>0,G12*4%,0) -> 0 | I12: 1.34 | J12: =E$1*I12/100 -> 3904.2225 | K12: 0 | L12: =G12+H12+J12+K12 -> 3904.2225
A13: COCH B | C13: =C6 -> Maceyle Gabriela | E13: 4149.729 | F13: =E13 -> 4149.729 | G13: =E13-F13 -> 0 | H13: =IF(G13>0,G13*4%,0) -> 0 | I13: 1.32 | J13: =E$1*I13/100 -> 3845.9505 | K13: 0 | L13: =G13+H13+J13+K13 -> 3845.9505
A14: COCH C | C14: =C6 -> Maceyle Gabriela | E14: 4149.729 | F14: =E14 -> 4149.729 | G14: =E14-F14 -> 0 | H14: =IF(G14>0,G14*4%,0) -> 0 | I14: 1.32 | J14: =E$1*I14/100 -> 3845.9505 | K14: 0 | L14: =G14+H14+J14+K14 -> 3845.9505
A15: TOTALES | E15: =SUM(E5:E14) -> 234321.67 | F15: =SUM(F5:F14) -> 234321.67 | H15: =SUM(H5:H14) -> 0 | I15: =SUM(I5:I14) -> 100 | J15: =SUM(J5:J14) -> 291359.89 | K15: =SUM(K5:K11) -> 0 | L15: =SUM(L5:L14) -> 291359.89
A18: EXPENSAS EXTRAORDINARIAS | E18: 7454
A19: Liquidación de mes: JULIO 2022 | E19: 14805
A20: UF | B20: Dpto. | C20: Propietario | E20: 3297 | F20: Pagos | H20: Intereses | I20: porcentaje | J20: Expensas | L20: TOTAL
E21: 3177 | F21: Exp. Extraord. | H21: 0.02 | I21: % | J21: Ordinarias | L21: EXPENSAS
A22: 1 | B22: PB 2 | C22: POC SERGIO | E22: 3056 | F22: 37971 | H22: 0 | I22: 0.121 | J22: =0*I22 -> 0 | L22: =+#REF!+H22+J22 -> #REF!
A23: 2 | B23: PB 1 | C23: GODOY DARIO | E23: 3056 | F23: 66612 | H23: 0 | I23: 0.122 | J23: =0*I23 -> 0 | L23: =+#REF!+H23+J23 -> #REF!
A24: 3 | B24: PB 3 | C24: BARBARESI CAROLINA | E24: =SUM(E16:E23) -> 34845 | F24: 0 | H24: 0 | I24: 0.117 | J24: =0*I24 -> 0 | L24: =+#REF!+H24+J24 -> #REF!
A25: 4 | B25: PB 4 | C25: ECHEVERRIA CHRISTIAN | F25: 0 | H25: 0 | I25: 0.117 | J25: =0*I25 -> 0 | L25: =+#REF!+H25+J25 -> #REF!
A26: 5 | B26: PA 2 | C26: POC SERGIO | F26: 80517 | H26: 0 | I26: 0.137 | J26: =0*I26 -> 0 | L26: =+#REF!+H26+J26 -> #REF!
A27: 6 | B27: PA 1 | C27: POC SERGIO | F27: 0 | H27: 0 | I27: 0.132 | J27: =0*I27 -> 0 | L27: =+#REF!+H27+J27 -> #REF!
A28: 7 | B28: PA 3 | C28: BARBARESI CAROLINA | E28: EDIFICIO DRAGO 1770 | F28: 18542 | H28: 0 | I28: 0.127 | J28: =0*I28 -> 0 | L28: =+#REF!+H28+J28 -> #REF!
A29: 8 | B29: PA 4 | C29: MANTEIGA LUCAS | E29: Saldo | F29: 0 | H29: 0 | I29: 0.127 | J29: =0*I29 -> 0 | L29: =+#REF!+H29+J29 -> #REF!
A30: TOTALES | E30: Anterior | F30: =SUM(F22:F29) -> 203642 | H30: =SUM(H22:H29) -> 0 | I30: =SUM(I22:I29) -> 1 | J30: =SUM(J22:J29) -> 0 | L30: =SUM(L22:L29) -> #REF!
E32: RECIBO DE EXPENSAS
E33: CONSORCIO: ADMINISTRACION DE CONSORCIOS RC
J34: ='detalle y gastos'!B7 -> 0
E35: Adminstradora: Carolina Canciani
E37: EXPENSAS EXTRAORDINARIAS
E39: Nombre y apellido: | G39: =C7 -> Maceyle Gabriela | I39: Fecha: | J39: 45674 | L39: Sello o firma autoriada:
E40: UF: | F40: 3
E42: EXPENSAS ORDINARIAS | J42: =J7 -> 36303.442
E43: EDESUR | J43: =K7 -> 0
E44: DEUDA + INTERESES | J44: =G7+H7 -> 0
E50: ABONA DE MAS | J50: =77200-77124.2 -> 75.8
E52: Total recibido: | J52: =SUM(J42:J51) -> 36379.242
...

Sheet edesur
B1: PATXOT | C1: ENERO 2025 | F1: EDESUR | G1: BOLETA | H1: 0
B3: UNIDAD | C3: MEDIDOR | D3: MEDIDOR | E3: CONSUMO | F3: PORCENTAJE | G3: BOLETA TOTAL | H3: TOTAL A ABONAR
C4: ANTERIOR | D4: ACTUAL | H4: =H1 -> 0
A5: GOMEZ | B5: 1 | C5: 7735 | D5: =C5+82 -> 7817 | E5: =D5-C5 -> 82 | F5: =E5*100/D14 -> 13.712375 | H5: =H4*(F5/100) -> 0
A6: CARA | B6: 2 | C6: 7076 | D6: =C6+98 -> 7174 | E6: =D6-C6 -> 98 | F6: =E6*100/D14 -> 16.38796 | H6: =H4*(F6/100) -> 0
A7: PEREYRA | B7: 3 | C7: 7694 | D7: =C7+97 -> 7791 | E7: =D7-C7 -> 97 | F7: =E7*100/D14 -> 16.220736 | H7: =H4*(F7/100) -> 0
A8: MARTINEZ | B8: 4 | C8: 9262 | D8: =C8+107 -> 9369 | E8: =D8-C8 -> 107 | F8: =E8*100/D14 -> 17.892977 | H8: =H4*(F8/100) -> 0
A9: ENCISO ROTELA | B9: 5 | C9: 10635 | D9: =C9+60 -> 10695 | E9: =D9-C9 -> 60 | F9: =E9*100/D14 -> 10.033445 | H9: =H4*(F9/100) -> 0
A10: VALDEZ | B10: 6 | C10: 10706 | D10: =C10+37+12+12 -> 10767 | E10: =D10-C10 -> 61 | F10: =E10*100/D14 -> 10.200669 | H10: =H4*(F10/100) -> 0
A11: COSENZA | B11: 7 | C11: 13147 | D11: =C11+93 -> 13240 | E11: =D11-C11 -> 93 | F11: =E11*100/D14 -> 15.551839 | H11: =H4*(F11/100) -> 0
C12: =SUM(C5:C11) -> 66255 | D12: =SUM(D5:D11) -> 66853 | E12: =SUM(E5:E11) -> 598 | F12: =SUM(F5:F11) -> 100 | H12: =SUM(H5:H11) -> 0
B14: CONSUMO TOTAL KW | D14: =D12-C12 -> 598
B15: EDIFICIO
E20: EN TOTAL LOS DEPARTAMENTOS USARON | H20: =D14 -> 598 | K20: KW
D21: DEPARTAMENTO | E21: 7 | F21: CONSUMIO | G21: 197 | H21: KW | K21: EL 14,96% DE TOTAL CONSUMIDO
K25: NOVIEMBRE 2024
I27: ELECTRICIDAD | J27: EXPENSAS | K27: TOTAL
H28: VALDEZ | I28: 29829 | J28: 16000 | K28: =I28+J28 -> 45829
J31: saldo OCTUBRE 24 | K31: 117067
J32: ABONASTE OCTUBRE 24 | K32: -55000
J33: NOVIEMBRE 24 | K33: 43965
K34: =SUM(K31:K33) -> 106032

Sheet eXTR
D1: 50000 | H1: 250000
A2: EXPENSAS EXTRAORDINARIAS
A3: Liquidación de mes: DICIEMBRE 2023 | D3: EDIFICIO DRAGO 1770 | F3: EXPENSAS EXTRAORDINARIAS
A4: UF | B4: Dpto. | C4: Propietario | D4: Saldo | E4: Pago | F4: DEUDAS | G4: Intereses | H4: porcentaje | I4: Expensas | J4: DEUDA | L4: PUNITORIOS DE 5 MESES | M4: EXPENSAS | N4: TOTAL A PAGAR
D5: Anterior | E5: Exp. Extraord. | G5: 0.02 | H5: % | I5: Ordinarias | J5: ENERO | M5: EXTRAORD
A6: 1 | B6: PB 2 | C6: POC SERGIO | D6: 0 | E6: 0 | F6: =+D6-E6 -> 0 | G6: 0 | H6: 0.121 | I6: =H$1*H6 -> 30250 | J6: 9706.62 | L6: =(J6+K6)*5%+(J6+K6)*5%+(J6+K6)*5%+(J6+K6)*5%+(J6+K6)*5% -> 2426.655 | M6: =H$1*H6 -> 30250 | N6: =J6+K6+L6+M6 -> 42383.275
A7: 2 | B7: PB 1 | C7: GODOY DARIO | D7: 0 | E7: 0 | F7: =+D7-E7 -> 0 | G7: 0 | H7: 0.122 | I7: =H$1*H7 -> 30500 | J7: 19573.68 | L7: =(J7+K7)*5%+(J7+K7)*5%+(J7+K7)*5%+(J7+K7)*5%+(J7+K7)*5% -> 4893.42 | M7: =H$1*H7 -> 30500 | N7: =J7+K7+L7+M7 -> 54967.1
A8: 3 | B8: PB 3 | C8: BARBARESI CAROLINA | D8: 0 | E8: 0 | F8: =+D8-E8 -> 0 | G8: 0 | H8: 0.117 | I8: =H$1*H8 -> 29250 | J8: 0 | L8: =(J8+K8)*5%+(J8+K8)*5%+(J8+K8)*5%+(J8+K8)*5%+(J8+K8)*5% -> 0 | M8: =H$1*H8 -> 29250 | N8: =J8+K8+L8+M8 -> 29250
A9: 4 | B9: PB 4 | C9: ECHEVERRIA CHRISTIAN | D9: 0 | E9: 0 | F9: =+D9-E9 -> 0 | G9: 0 | H9: 0.117 | I9: =H$1*H9 -> 29250 | J9: 18771.48 | L9: =(J9+K9)*5%+(J9+K9)*5%+(J9+K9)*5%+(J9+K9)*5%+(J9+K9)*5% -> 4692.87 | M9: =H$1*H9 -> 29250 | N9: =J9+K9+L9+M9 -> 52714.35
A10: 5 | B10: PA 2 | C10: POC SERGIO | D10: 0 | E10: 0 | F10: =+D10-E10 -> 0 | G10: 0 | H10: 0.137 | I10: =H$1*H10 -> 34250 | J10: 10990.14 | L10: =(J10+K10)*5%+(J10+K10)*5%+(J10+K10)*5%+(J10+K10)*5%+(J10+K10)*5% -> 2747.535 | M10: =H$1*H10 -> 34250 | N10: =J10+K10+L10+M10 -> 47987.675
A11: 6 | B11: PA 1 | C11: POC SERGIO | D11: 0 | E11: 0 | F11: =+D11-E11 -> 0 | G11: 0 | H11: 0.132 | I11: =H$1*H11 -> 33000 | J11: 10589.04 | L11: =(J11+K11)*5%+(J11+K11)*5%+(J11+K11)*5%+(J11+K11)*5%+(J11+K11)*5% -> 2647.26 | M11: =H$1*H11 -> 33000 | N11: =J11+K11+L11+M11 -> 46236.3
A12: 7 | B12: PA 3 | C12: BARBARESI CAROLINA | D12: 0 | E12: 0 | F12: =+D12-E12 -> 0 | G12: 0 | H12: 0.127 | I12: =H$1*H12 -> 31750 | J12: 0 | L12: =(J12+K12)*5%+(J12+K12)*5%+(J12+K12)*5%+(J12+K12)*5%+(J12+K12)*5% -> 0 | M12: =H$1*H12 -> 31750 | N12: =J12+K12+L12+M12 -> 31750
A13: 8 | B13: PA 4 | C13: MANTEIGA LUCAS | D13: 0 | E13: 0 | F13: =+D13-E13 -> 0 | G13: 0 | H13: 0.127 | I13: =H$1*H13 -> 31750 | J13: 0 | L13: =(J13+K13)*5%+(J13+K13)*5%+(J13+K13)*5%+(J13+K13)*5%+(J13+K13)*5% -> 0 | M13: =H$1*H13 -> 31750 | N13: =J13+K13+L13+M13 -> 31750
A14: TOTALES | D14: =SUM(D6:D13) -> 0 | E14: =SUM(E6:E13) -> 0 | F14: =SUM(F6:F13) -> 0 | G14: =SUM(G6:G13) -> 0 | H14: =SUM(H6:H13) -> 1 | I14: =SUM(I6:I13) -> 250000 | J14: =SUM(J6:J13) -> 69630.96 | K14: =SUM(K6:K13) -> 0 | M14: =SUM(M6:M13) -> 250000 | N14: =SUM(N6:N13) -> 337038.7
