Workbook

Sheet RESUMEN
B2: MAIL: consorciogorriti368@gmail.com
B3: CUIT ADMINISTRACION: 27231256879
B4: CBU: 0290034600000502294350 | D4: TELEFONO: 11 5320-2676
A5: LIQUIDACION DE EXPENSAS | B5: ADMINISTRADORA: CAROLINA CANCIANI MP:1148
A6: CUIT DEL EDIFICIO: 30583957819 | B6: PERÍODO: ENERO | D6: HORARIOS DE ATENCION: LUNES A VIERNES
A7: CONSORCIO DE PROPIETARIOS DEL EDIFICIO CALLE GORRITI 368 | D7: 10 A 16HS - EMERGENCIAS 24HS
B9: VTO 13/02
A14: ESTIMADOS PROPIETARIOS E INQUILINOS: POR FAVOR LOS QUE ABONAN EN PRIMER VENCIMIENTO ABONEN EL MONTO DE PRIMER VENCIMIENTO, ASI AGILIZAN LA LIQUIDACION, RESPETEN LOS CENTAVOS CORRESPONDIENTES A LA UNIDAD FUNCIONAL. ES DE CARÁCTER OBLIGATORIO INFORMAR VIA MAIL LAS EXPENSAS. CASO CONTRARIO SE INFORMARA VIA CARTA DOCUMENTO A LA UNIDAD FUNCIONAL QUE CREEMOS QUE CORRESPONDE, CUYO COSTO SERA IMPUTADO A LA UNIDAD FUNCIONAL SOSPECHADA.
A21: GASTOS ORDINARIOS UNIDADES FUNCIONALES:
A22: HABERES ENCARGADOS
A23: Sueldo encargado Colmiero Oscar | D23: 1158217
A26: Retenciones | D26: 0
A28: Neto | D28: =SUM(D23:D27) -> 1158217 | G28: =D28+D37 -> 2218075
A29: Sueldo encargado Balcazza Leonardo | D29: 1059858
A33: SAC
A34: Retenciones SAC
A35: Retenciones | D35: 0
A37: Neto | D37: =SUM(D29:D36) -> 1059858
A38: TOTAL SUELDO | E38: =D28+D37 -> 2218075
A39: HONORARIOS
A40: GUSTAVO PADRON - NO SE COBRAN HONORARIOS HASTA TENER EL CONTROL DE LA CUENTA - SE ADEUDA MES 12/24 Y MES 1/25
A41: HONORARIOS ADMINISTRACION RC - NO SE COBRAN HONORARIOS HASTA TENER EL CONTROL DE LA CUENTA - SE ADEUDA MES 1/25 | D41: 230000
A42: TOTAL | E42: =SUM(D40:D41) -> 230000
A43: SEGUROS
A44: Seguro Integral consorcio San Cristobal - Poliza 01-05-07-30183461 | D44: 120974 | E44: Debito 10/01
A46: TOTAL IMPUESTO | E46: =SUM(D44:D45) -> 120974
A47: APORTES Y CONTRIBUCIONES
A48: ARCA | D48: 2255205.5 | E48: PMC 24/01
A49: ARCA - Empleada que realizo el reemplazo en Noviembre | D49: 66437.69 | E49: PMC 24/01
A50: Sindicatos mes de ENERO | B50: Fatheryh | D50: 328236.93 | E50: Debito 20/01
A51: =A50 -> Sindicatos mes de ENERO | B51: Suther | D51: 209289.75 | E51: =E50 -> Debito 20/01
A52: =A51 -> Sindicatos mes de ENERO | B52: Seracarh | D52: 23254.21 | E52: =E51 -> Debito 20/01
A53: TOTAL Aportes y Contribuciones - Sindicato | E53: =SUM(D48:D52) -> 2882424.1
A54: ABONOS Y SERVICIOS
A55: EDESUR - Cliente nro. 828563 | D55: 835158.74 | E55: PMC 13/01
A56: EDESUR - Cliente nro. 01672309 | D56: 1120.25 | E56: =E55 -> PMC 13/01
A57: EDESUR - Cliente nro. 01672321 | D57: 13712.85 | E57: =E56 -> PMC 13/01
A58: EDESUR - Cliente nro. 01672319 | D58: 6514.33 | E58: =E57 -> PMC 13/01
A59: Metrogas - Cliente nro. 20495697900 | D59: 5186.14 | E59: PMC 17/01
A60: Metrogas - Cliente nro. 20463936100 | B60: No hay factura
...

Sheet PRORRATEO
E2: =RESUMEN!B4 -> CBU: 0290034600000502294350 | M2: Gastos Ordinarios: | P2: 10381819
A4: Piso | B4: Dpto. | D4: UF | E4: Propietario | F4: Inquilinos | G4: (%) | H4: Saldo Ord + EXP DE URGENCIA | I4: Ingreso | J4: Pago por | K4: Deuda o Saldo a favor | L4: Interes 3% | M4: Expensas extraor. | N4: Expensas ord. | O4: Gastos part. | P4: Total 1er Vto | Q4: Total 2do Vto. | R4: Total 2do Vto
P5: =RESUMEN!B9 -> VTO 13/02
A6: PB | C6: LOC | D6: 1 | E6: GEFFNER SILVIA E. | G6: 0.5131 | H6: 50798.02 | I6: =640937-I13-I7-I47-I48-I56-I59-I69-I73+65440 -> 53236.87 | K6: =H6-I6 -> -2438.85 | L6: =IF(K6>0,K6*3%,0) -> 0 | M6: 0 | N6: =P$2*G6% -> 53269.114 | O6: 0 | P6: =ROUND(SUM(K6:O6),0) + S6 -> 50830.01 | Q6: =ROUND(P6*6% + P6,0) + S6 -> 53880.01 | R6: =ROUND(P6*3%,0) + P6 -> 52355.01 | S6: 0.01
A7: 3º | C7: LOC | D7: =D6+1 -> 2 | E7: COVILOZA S. A. | G7: 0.6119 | H7: 60579.04 | I7: =H7 -> 60579.04 | K7: =H7-I7 -> 0 | L7: =IF(K7>0,K7*3%,0) -> 0 | M7: 0 | N7: =P$2*G7% -> 63526.351 | O7: 0 | P7: =ROUND(SUM(K7:O7),0) + S7 -> 63526.02 | Q7: =ROUND(P7*6% + P7,0) + S7 -> 67338.02 | R7: =ROUND(P7*3%,0) + P7 -> 65432.02 | S7: =S6+0.01 -> 0.02
A8: 3º | B8: 1 | D8: =D7+1 -> 3 | E8: ASIST Y TRAB. | G8: 0.6115 | H8: 60540.06 | I8: =H8 -> 60540.06 | K8: =H8-I8 -> 0 | L8: =IF(K8>0,K8*3%,0) -> 0 | M8: 0 | N8: =P$2*G8% -> 63484.824 | O8: 0 | P8: =ROUND(SUM(K8:O8),0) + S8 -> 63485.03 | Q8: =ROUND(P8*6% + P8,0) + S8 -> 67294.03 | R8: =ROUND(P8*3%,0) + P8 -> 65390.03 | S8: =S7+0.01 -> 0.03
A9: 4º | B9: 2 | D9: =D8+1 -> 4 | E9: ASIST Y TRAB. | G9: 0.5033 | H9: 49828.08 | I9: =H9 -> 49828.08 | K9: =H9-I9 -> 0 | L9: =IF(K9>0,K9*3%,0) -> 0 | M9: 0 | N9: =P$2*G9% -> 52251.695 | O9: 0 | P9: =ROUND(SUM(K9:O9),0) + S9 -> 52252.04 | Q9: =ROUND(P9*6% + P9,0) + S9 -> 55387.04 | R9: =ROUND(P9*3%,0) + P9 -> 53820.04 | S9: =S8+0.01 -> 0.04
A10: 4º | B10: 3 | D10: =D9+1 -> 5 | E10: ASIST Y TRAB. | G10: 0.5033 | H10: 49828.1 | I10: =144015-I9-I8 -> 33646.86 | K10: =H10-I10 -> 16181.24 | L10: =IF(K10>0,K10*3%,0) -> 485.4372 | M10: 0 | N10: =P$2*G10% -> 52251.695 | O10: 0 | P10: =ROUND(SUM(K10:O10),0) + S10 -> 68918.05 | Q10: =ROUND(P10*6% + P10,0) + S10 -> 73053.05 | R10: =ROUND(P10*3%,0) + P10 -> 70986.05 | S10: =S9+0.01 -> 0.05
A11: 5º | B11: 4 | D11: =D10+1 -> 6 | E11: BENMAOR D. | F11: Cristian Requelme | G11: 0.7499 | H11: 74242.12 | I11: =66743.06 -> 66743.06 | K11: =H11-I11 -> 7499.06 | L11: =IF(K11>0,K11*3%,0) -> 224.9718 | M11: 0 | N11: =P$2*G11% -> 77853.261 | O11: 0 | P11: =ROUND(SUM(K11:O11),0) + S11 -> 85577.06 | Q11: =ROUND(P11*6% + P11,0) + S11 -> 90712.06 | R11: =ROUND(P11*3%,0) + P11 -> 88144.06 | S11: =S10+0.01 -> 0.06
A12: 5º | B12: 5 | D12: =D11+1 -> 7 | E12: GALANTERNIK A | F12: Miriam Larken | G12: 0.5425 | H12: 53709.14 | I12: =48284.07+5588.07 -> 53872.14 | K12: =H12-I12 -> -163 | L12: =IF(K12>0,K12*3%,0) -> 0 | M12: 0 | N12: =P$2*G12% -> 56321.368 | O12: 0 | P12: =ROUND(SUM(K12:O12),0) + S12 -> 56158.07 | Q12: =ROUND(P12*6% + P12,0) + S12 -> 59528.07 | R12: =ROUND(P12*3%,0) + P12 -> 57843.07 | S12: =S11+0.01 -> 0.07
A13: 6º | B13: 6 | D13: =D12+1 -> 8 | E13: CANDEL JORGE ISAAC | G13: 0.4537 | H13: 44917.16 | I13: =H13 -> 44917.16 | K13: =H13-I13 -> 0 | L13: =IF(K13>0,K13*3%,0) -> 0 | M13: 0 | N13: =P$2*G13% -> 47102.313 | O13: 0 | P13: =ROUND(SUM(K13:O13),0) + S13 -> 47102.08 | Q13: =ROUND(P13*6% + P13,0) + S13 -> 49928.08 | R13: =ROUND(P13*3%,0) + P13 -> 48515.08 | S13: =S12+0.01 -> 0.08
A14: 6º | B14: 7 | D14: =D13+1 -> 9 | E14: BORTZ SERGIO | G14: 0.5244 | H14: 51917.18 | I14: =46673.09 -> 46673.09 | K14: =H14-I14 -> 5244.09 | L14: =IF(K14>0,K14*3%,0) -> 157.3227 | M14: 0 | N14: =P$2*G14% -> 54442.259 | O14: 0 | P14: =ROUND(SUM(K14:O14),0) + S14 -> 59844.09 | Q14: =ROUND(P14*6% + P14,0) + S14 -> 63435.09 | R14: =ROUND(P14*3%,0) + P14 -> 61639.09 | S14: =S13+0.01 -> 0.09 | U14: ESTA ES LA FUNDACION DE MEDICOS
A15: 7º | B15: 8 | D15: =D14+1 -> 10 | E15: BORTZ SERGIO | G15: 0.424 | H15: 41977.2 | I15: =37737.1 -> 37737.1 | K15: =H15-I15 -> 4240.1 | L15: =IF(K15>0,K15*3%,0) -> 127.203 | M15: 0 | N15: =P$2*G15% -> 44018.913 | O15: 0 | P15: =ROUND(SUM(K15:O15),0) + S15 -> 48386.1 | Q15: =ROUND(P15*6% + P15,0) + S15 -> 51289.1 | R15: =ROUND(P15*3%,0) + P15 -> 49838.1 | S15: =S14+0.01 -> 0.1 | U15: ESTA ES LA FUNDACION DE MEDICOS
A16: 7º | B16: 1 | C16: A | D16: =D15+1 -> 11 | E16: KIM SOON LEO | G16: 2.3033 | H16: 1633137.2 | K16: =H16-I16 -> 1633137.2 | L16: =IF(K16>0,K16*3%,0) -> 48994.117 | M16: 0 | N16: =P$2*G16% -> 239124.44 | O16: 0 | P16: =ROUND(SUM(K16:O16),0) + S16 -> 1921256.1 | Q16: =ROUND(P16*6% + P16,0) + S16 -> 2036531.1 | R16: =ROUND(P16*3%,0) + P16 -> 1978894.1 | S16: =S15+0.01 -> 0.11
A17: 8º | B17: 1 | C17: B | D17: =D16+1 -> 12 | E17: CANDEL MARCELO | F17: Florencia Fucci | G17: 2.7493 | H17: 279528.24 | I17: =244694 -> 244694 | K17: =H17-I17 -> 34834.24 | L17: =IF(K17>0,K17*3%,0) -> 1045.0272 | M17: 0 | N17: =P$2*G17% -> 285427.35 | O17: 0 | P17: =ROUND(SUM(K17:O17),0) + S17 -> 321307.12 | Q17: =ROUND(P17*6% + P17,0) + S17 -> 340586.12 | R17: =ROUND(P17*3%,0) + P17 -> 330946.12 | S17: =S16+0.01 -> 0.12
A18: 8º | B18: 2 | C18: A | D18: =D17+1 -> 13 | E18: TRIPODI | F18: Mariela Pricolo | G18: 2.3033 | H18: 228032.26 | I18: =214999.13 -> 214999.13 | K18: =H18-I18 -> 13033.13 | L18: =IF(K18>0,K18*3%,0) -> 390.9939 | M18: 0 | N18: =P$2*G18% -> 239124.44 | O18: 0 | P18: =ROUND(SUM(K18:O18),0) + S18 -> 252549.13 | Q18: =ROUND(P18*6% + P18,0) + S18 -> 267702.13 | R18: =ROUND(P18*3%,0) + P18 -> 260125.13 | S18: =S17+0.01 -> 0.13
A19: 9º | B19: 2 | C19: B | D19: =D18+1 -> 14 | E19: MIRANDA DE GIL | F19: Susana | G19: 2.6368 | H19: 268089.28 | I19: =200000+40000 -> 240000 | K19: =H19-I19 -> 28089.28 | L19: =IF(K19>0,K19*3%,0) -> 842.6784 | M19: 0 | N19: =P$2*G19% -> 273747.81 | O19: 0 | P19: =ROUND(SUM(K19:O19),0) + S19 -> 302680.14 | Q19: =ROUND(P19*6% + P19,0) + S19 -> 320841.14 | R19: =ROUND(P19*3%,0) + P19 -> 311760.14 | S19: =S18+0.01 -> 0.14 | U19: MAXIMO
A20: 9º | B20: 3 | C20: A | D20: =D19+1 -> 15 | E20: FRAGA DORA | G20: 2.3537 | H20: 233021.3 | I20: =209484.15 -> 209484.15 | K20: =H20-I20 -> 23537.15 | L20: =IF(K20>0,K20*3%,0) -> 706.1145 | M20: 0 | N20: =P$2*G20% -> 244356.88 | O20: 0 | P20: =ROUND(SUM(K20:O20),0) + S20 -> 268600.15 | Q20: =ROUND(P20*6% + P20,0) + S20 -> 284716.15 | R20: =ROUND(P20*3%,0) + P20 -> 276658.15 | S20: =S19+0.01 -> 0.15
A21: 10º | B21: 3 | C21: B | D21: =D20+1 -> 16 | E21: SARUBBI MARTIN | F21: Sarubbi Adriana | G21: 2.6477 | H21: 262128.32 | I21: =235651.16+27271.26+RESUMEN!D70+RESUMEN!D69 -> 310902.42 | K21: =H21-I21 -> -48774.1 | L21: =IF(K21>0,K21*3%,0) -> 0 | M21: 0 | N21: =P$2*G21% -> 274879.42 | O21: 0 | P21: =ROUND(SUM(K21:O21),0) + S21 -> 226105.16 | Q21: =ROUND(P21*6% + P21,0) + S21 -> 239671.16 | R21: =ROUND(P21*3%,0) + P21 -> 232888.16 | S21: =S20+0.01 -> 0.16
A22: 10º | B22: 4 | C22: A | D22: =D21+1 -> 17 | E22: LACENTRE | F22: Gabriela Tamara | G22: 2.3235 | H22: 230031.34 | I22: =206796.17 -> 206796.17 | K22: =H22-I22 -> 23235.17 | L22: =IF(K22>0,K22*3%,0) -> 697.0551 | M22: 0 | N22: =P$2*G22% -> 241221.57 | O22: 0 | P22: =ROUND(SUM(K22:O22),0) + S22 -> 265154.17 | Q22: =ROUND(P22*6% + P22,0) + S22 -> 281063.17 | R22: =ROUND(P22*3%,0) + P22 -> 273109.17 | S22: =S21+0.01 -> 0.17
A23: 11º | B23: 4 | C23: B | D23: =D22+1 -> 18 | E23: FERNANDEZ BERTA | F23: KRAVETZ | G23: 2.688 | H23: 160942.36 | I23: =130157 -> 130157 | K23: =H23-I23 -> 30785.36 | L23: =IF(K23>0,K23*3%,0) -> 923.5608 | M23: 0 | N23: =P$2*G23% -> 279063.3 | O23: 0 | P23: =ROUND(SUM(K23:O23),0) + S23 -> 310772.18 | Q23: =ROUND(P23*6% + P23,0) + S23 -> 329419.18 | R23: =ROUND(P23*3%,0) + P23 -> 320095.18 | S23: =S22+0.01 -> 0.18
A24: 11º | B24: 5 | C24: A | D24: =D23+1 -> 19 | E24: VERONES JOSE MARIA | G24: 2.36 | H24: 233645.38 | I24: =210045.19+23600 -> 233645.19 | K24: =H24-I24 -> 0.19 | L24: =IF(K24>0,K24*3%,0) -> 0.0057 | M24: 0 | N24: =P$2*G24% -> 245010.93 | O24: 0 | P24: =ROUND(SUM(K24:O24),0) + S24 -> 245011.19 | Q24: =ROUND(P24*6% + P24,0) + S24 -> 259712.19 | R24: =ROUND(P24*3%,0) + P24 -> 252361.19 | S24: =S23+0.01 -> 0.19
A25: 12º | B25: 5 | C25: B | D25: =D24+1 -> 20 | E25: SRUGO CARLOS | G25: 2.7183 | H25: 276376.4 | I25: =242000 -> 242000 | K25: =H25-I25 -> 34376.4 | L25: =IF(K25>0,K25*3%,0) -> 1031.292 | M25: 0 | N25: =P$2*G25% -> 282208.99 | O25: 0 | P25: =ROUND(SUM(K25:O25),0) + S25 -> 317617.2 | Q25: =ROUND(P25*6% + P25,0) + S25 -> 336674.2 | R25: =ROUND(P25*3%,0) + P25 -> 327146.2 | S25: =S24+0.01 -> 0.2
A26: 13º | B26: 6 | C26: A | D26: =D25+1 -> 21 | E26: DINOTO | G26: 2.3033 | H26: 228032.42 | I26: =204999.21+23724.21 -> 228723.42 | K26: =H26-I26 -> -691 | L26: =IF(K26>0,K26*3%,0) -> 0 | M26: 0 | N26: =P$2*G26% -> 239124.44 | O26: 0 | P26: =ROUND(SUM(K26:O26),0) + S26 -> 238433.21 | Q26: =ROUND(P26*6% + P26,0) + S26 -> 252739.21 | R26: =ROUND(P26*3%,0) + P26 -> 245586.21 | S26: =S25+0.01 -> 0.21
A27: 14º | B27: 6 | C27: B | D27: =D26+1 -> 22 | E27: BORTZ ESTHER | F27: Daniel | G27: 2.636 | H27: 260970.44 | I27: =234610.22 -> 234610.22 | K27: =H27-I27 -> 26360.22 | L27: =IF(K27>0,K27*3%,0) -> 790.8066 | M27: 0 | N27: =P$2*G27% -> 273664.75 | O27: 0 | P27: =ROUND(SUM(K27:O27),0) + S27 -> 300816.22 | Q27: =ROUND(P27*6% + P27,0) + S27 -> 318865.22 | R27: =ROUND(P27*3%,0) + P27 -> 309840.22 | S27: =S26+0.01 -> 0.22 | U27: ESTA ES LA FUNDACION DE MEDICOS
A28: 15º | B28: 7 | C28: A | D28: =D27+1 -> 23 | E28: COUSO MARIA CRISTINA | G28: 2.3033 | H28: 228032.46 | I28: =204999.23+23724.23 -> 228723.46 | K28: =H28-I28 -> -691 | L28: =IF(K28>0,K28*3%,0) -> 0 | M28: 0 | N28: =P$2*G28% -> 239124.44 | O28: 0 | P28: =ROUND(SUM(K28:O28),0) + S28 -> 238433.23 | Q28: =ROUND(P28*6% + P28,0) + S28 -> 252739.23 | R28: =ROUND(P28*3%,0) + P28 -> 245586.23 | S28: =S27+0.01 -> 0.23
A29: COC | B29: 7 | C29: B | D29: =D28+1 -> 24 | E29: POSSENTI JUAN JOSE | G29: 2.6159 | H29: 258980.48 | I29: =232821.24+6159.24 -> 238980.48 | K29: =H29-I29 -> 20000 | L29: =IF(K29>0,K29*3%,0) -> 600 | M29: 0 | N29: =P$2*G29% -> 271578.01 | O29: 0 | P29: =ROUND(SUM(K29:O29),0) + S29 -> 292178.24 | Q29: =ROUND(P29*6% + P29,0) + S29 -> 309709.24 | R29: =ROUND(P29*3%,0) + P29 -> 300943.24 | S29: =S28+0.01 -> 0.24
A30: COC | B30: 8 | C30: A | D30: =D29+1 -> 25 | E30: VANNI KARINA | G30: 2.3537 | H30: 233021.5 | I30: =209484.25+24243.25 -> 233727.5 | K30: =H30-I30 -> -706 | L30: =IF(K30>0,K30*3%,0) -> 0 | M30: 0 | N30: =P$2*G30% -> 244356.88 | O30: 0 | P30: =ROUND(SUM(K30:O30),0) + S30 -> 243651.25 | Q30: =ROUND(P30*6% + P30,0) + S30 -> 258270.25 | R30: =ROUND(P30*3%,0) + P30 -> 250961.25 | S30: =S29+0.01 -> 0.25
A31: COC | B31: 8 | C31: B | D31: =D30+1 -> 26 | E31: CARRIZO RAÚL | F31: Noelia Villarino | G31: 2.6469 | H31: 262049.52 | I31: =235580.26+26469 -> 262049.26 | K31: =H31-I31 -> 0.26 | L31: =IF(K31>0,K31*3%,0) -> 0.0078 | M31: 0 | N31: =P$2*G31% -> 274796.37 | O31: 0 | P31: =ROUND(SUM(K31:O31),0) + S31 -> 274797.26 | Q31: =ROUND(P31*6% + P31,0) + S31 -> 291285.26 | R31: =ROUND(P31*3%,0) + P31 -> 283041.26 | S31: =S30+0.01 -> 0.26
A32: COC | B32: 9 | C32: A | D32: =D31+1 -> 27 | E32: BLANCO | G32: 2.3537 | H32: 233021.54 | I32: =209484.27 -> 209484.27 | K32: =H32-I32 -> 23537.27 | L32: =IF(K32>0,K32*3%,0) -> 706.1181 | M32: 0 | N32: =P$2*G32% -> 244356.88 | O32: 0 | P32: =ROUND(SUM(K32:O32),0) + S32 -> 268600.27 | Q32: =ROUND(P32*6% + P32,0) + S32 -> 284716.27 | R32: =ROUND(P32*3%,0) + P32 -> 276658.27 | S32: =S31+0.01 -> 0.27
A33: COC | B33: 9 | C33: B | D33: =D32+1 -> 28 | E33: GALANTE CELIA | G33: 2.6663 | H33: 263969.56 | I33: =237306.28 -> 237306.28 | K33: =H33-I33 -> 26663.28 | L33: =IF(K33>0,K33*3%,0) -> 799.8984 | M33: 0 | N33: =P$2*G33% -> 276810.44 | O33: 0 | P33: =ROUND(SUM(K33:O33),0) + S33 -> 304274.28 | Q33: =ROUND(P33*6% + P33,0) + S33 -> 322531.28 | R33: =ROUND(P33*3%,0) + P33 -> 313402.28 | S33: =S32+0.01 -> 0.28
A34: COC | B34: 10 | C34: A | D34: =D33+1 -> 29 | E34: LEGUIZAMON PABLO | F34: Carla | G34: 2.4476 | H34: 242318.58 | I34: =217842.29+25210.29 -> 243052.58 | K34: =H34-I34 -> -734 | L34: =IF(K34>0,K34*3%,0) -> 0 | M34: 0 | N34: =P$2*G34% -> 254105.4 | O34: 0 | P34: =ROUND(SUM(K34:O34),0) + S34 -> 253371.29 | Q34: =ROUND(P34*6% + P34,0) + S34 -> 268574.29 | R34: =ROUND(P34*3%,0) + P34 -> 260972.29 | S34: =S33+0.01 -> 0.29
A35: COC | B35: 10 | C35: B | D35: =D34+1 -> 30 | E35: CANDEL E. MARCELO | G35: 2.7183 | H35: 269118.6 | I35: =241935.3 -> 241935.3 | K35: =H35-I35 -> 27183.3 | L35: =IF(K35>0,K35*3%,0) -> 815.499 | M35: 0 | N35: =P$2*G35% -> 282208.99 | O35: 0 | P35: =ROUND(SUM(K35:O35),0) + S35 -> 310208.3 | Q35: =ROUND(P35*6% + P35,0) + S35 -> 328821.3 | R35: =ROUND(P35*3%,0) + P35 -> 319514.3 | S35: =S34+0.01 -> 0.3
A36: COC | B36: 11 | C36: A | D36: =D35+1 -> 31 | E36: DAVICCA MIGUEL | F36: Romina Navarro | G36: 2.3026 | H36: 227962.62 | I36: =209936.31 -> 209936.31 | K36: =H36-I36 -> 18026.31 | L36: =IF(K36>0,K36*3%,0) -> 540.7893 | M36: 0 | N36: =P$2*G36% -> 239051.77 | O36: 0 | P36: =ROUND(SUM(K36:O36),0) + S36 -> 257619.31 | Q36: =ROUND(P36*6% + P36,0) + S36 -> 273076.31 | R36: =ROUND(P36*3%,0) + P36 -> 265348.31 | S36: =S35+0.01 -> 0.31
A37: COC | B37: 11 | C37: B | D37: =D36+1 -> 32 | E37: GUTMAN MARIO | G37: 2.6562 | H37: 358385.64 | I37: =236407.32+26562.32 -> 262969.64 | K37: =H37-I37 -> 95416 | L37: =IF(K37>0,K37*3%,0) -> 2862.48 | M37: 0 | N37: =P$2*G37% -> 275761.88 | O37: 0 | P37: =ROUND(SUM(K37:O37),0) + S37 -> 374040.32 | Q37: =ROUND(P37*6% + P37,0) + S37 -> 396483.32 | R37: =ROUND(P37*3%,0) + P37 -> 385261.32 | S37: =S36+0.01 -> 0.32
A38: COC | B38: 12 | C38: A | D38: =D37+1 -> 33 | E38: PRATOLONGO EDUARDO | G38: 2.3343 | H38: 231101.66 | I38: =207758.33+23343 -> 231101.33 | K38: =H38-I38 -> 0.33 | L38: =IF(K38>0,K38*3%,0) -> 0.0099 | M38: 0 | N38: =P$2*G38% -> 242342.8 | O38: 0 | P38: =ROUND(SUM(K38:O38),0) + S38 -> 242343.33 | Q38: =ROUND(P38*6% + P38,0) + S38 -> 256884.33 | R38: =ROUND(P38*3%,0) + P38 -> 249613.33 | S38: =S37+0.01 -> 0.33
A39: COC | B39: 12 | C39: B | D39: =D38+1 -> 34 | E39: CARTABBIA MARIO | G39: 2.6259 | H39: 259970.68 | I39: =233711.34 -> 233711.34 | K39: =H39-I39 -> 26259.34 | L39: =IF(K39>0,K39*3%,0) -> 787.7802 | M39: 0 | N39: =P$2*G39% -> 272616.19 | O39: 0 | P39: =ROUND(SUM(K39:O39),0) + S39 -> 299663.34 | Q39: =ROUND(P39*6% + P39,0) + S39 -> 317643.34 | R39: =ROUND(P39*3%,0) + P39 -> 308653.34 | S39: =S38+0.01 -> 0.34
A40: COC | B40: 1 | C40: C | D40: =D39+1 -> 35 | E40: NAVA HECTOR | F40: Marcos | G40: 1.007 | H40: 99695.7 | I40: =89625.35 -> 89625.35 | K40: =H40-I40 -> 10070.35 | L40: =IF(K40>0,K40*3%,0) -> 302.1105 | M40: 0 | N40: =P$2*G40% -> 104544.92 | O40: 0 | P40: =ROUND(SUM(K40:O40),0) + S40 -> 114917.35 | Q40: =ROUND(P40*6% + P40,0) + S40 -> 121812.35 | R40: =ROUND(P40*3%,0) + P40 -> 118365.35 | S40: =S39+0.01 -> 0.35
A41: COC | B41: 1 | C41: D | D41: =D40+1 -> 36 | E41: BRATTOLI | F41: Palermo Hernan | G41: 0.7812 | H41: 77340.72 | I41: =H41 -> 77340.72 | K41: =H41-I41 -> 0 | L41: =IF(K41>0,K41*3%,0) -> 0 | M41: 0 | N41: =P$2*G41% -> 81102.771 | O41: 0 | P41: =ROUND(SUM(K41:O41),0) + S41 -> 81103.36 | Q41: =ROUND(P41*6% + P41,0) + S41 -> 85970.36 | R41: =ROUND(P41*3%,0) + P41 -> 83536.36 | S41: =S40+0.01 -> 0.36 | U41: PALERMO
B42: 1 | C42: E | D42: =D41+1 -> 37 | E42: BRATTOLI | F42: Palermo Hernan | G42: 1.2153 | H42: 120317.74 | I42: =178000-I41+20570 -> 121229.28 | K42: =H42-I42 -> -911.54 | L42: =IF(K42>0,K42*3%,0) -> 0 | M42: 0 | N42: =P$2*G42% -> 126170.25 | O42: 0 | P42: =ROUND(SUM(K42:O42),0) + S42 -> 125259.37 | Q42: =ROUND(P42*6% + P42,0) + S42 -> 132775.37 | R42: =ROUND(P42*3%,0) + P42 -> 129017.37 | S42: =S41+0.01 -> 0.37 | U42: PALERMO
...
