Workbook

Sheet RESUMEN
B1: Domicilio: Dr. Melo Nº 2958 - 8vo piso (cita previa) Lanus
B2: MAIL: amancioalcorta146rc@gmail.com
B3: CUIT: 30-60093228-0
B4: CBU: 2850939030007264271000 | C4: ALIAS: EGECUTE.DEHESA.FOCO,
B5: CUENTA CORRIENTE EN PESOS: MACRO SUCURSAL:939 CUENTA BANCARIA NRO. 393900726427100
A6: LIQUIDACION DE EXPENSAS | B6: PERÍODO: NOVIEMBRE | D6: MP:1148
A8: CONSORCIO DE PROPIETARIOS DEL EDIFICIO CALLE AMANCIO ALCORTA 146
A15: VTO 15/12
A28: GASTOS ORDINARIOS UNIDADES FUNCIONALES:
A29: SUELDO
A30: No hay encargado
A33: TOTAL SUELDO | E33: =SUM(D27:D32) -> 0
A37: TOTAL REEMPLAZO | E37: =SUM(D34:D36) -> 0
A38: HONORARIOS
A39: HONORARIOS administracion | B39: Mes de NOVIEMBRE | D39: 133500 | E39: Efectivo | G39: Aumentados en N0v
A40: Traspaso administracion | D40: 202000
A41: TOTAL | E41: =SUM(D39:D40) -> 335500
A42: IMPUESTO
A43: TSG | C43: Cuota 11 | D43: 29900
A45: TOTAL IMPUESTO | E45: =SUM(D43:D44) -> 29900
A46: APORTES Y CONTRIBUCIONES
A48: TOTAL Aportes y Contribuciones - Sindicato | E48: =D47 -> 0
A49: ABONOS Y SERVICIOS
A50: AYSA - Mes de NOVIEMBRE | D50: 496137.83
A51: Mantenimiento ascensores | D51: 81700
A52: Servicio de fumigacion - Sr. Pastorizza | D52: 73000
A53: EDESUR Nro de cliente : 01121994 | D53: 67441.64
A54: EDESUR Nro de cliente : 01121994 | D54: 0
A55: EDESUR Nro de cliente : 01121996 | D55: 7360.06
A56: EDESUR Nro de cliente : 01121995 | D56: 7637.04
A57: EDESUR Nro de cliente : 01121995 | D57: 0
A58: Metrogas NOVIEMBRE | D58: 5136.22
A60: TOTAL ABONOS Y SERVICIOS | E60: =SUM(D50:D59) -> 738412.79
A61: GASTOS GENERALES / MANTENIMIENTO
A62: Mercantil andina - Poliza nro. 001169864 | D62: 51658.31
A63: Fotocopias | D63: 2700
A64: TOTAL | E64: =SUM(D62:D63) -> 54358.31
A65: GASTOS BANCARIOS
A66: GASTOS BANCARIOS | D66: 32623.84
A68: TOTAL | E68: =SUM(D66:D67) -> 32623.84
...

Sheet PRORRATEO
K1: Gastos Ordinarios: | N1: 3800000
K2: Gastos Extraordinarios:
A3: Piso | B3: Dpto. | C3: UF | D3: Propietario | E3: Inquilinos | F3: (%) | G3: Saldo | H3: Ingreso | J3: DEUDA o SALDO A F | K3: Expensas extraor. | L3: Expensas ord | M3: Gasto part. | N3: TOTAL EXPENSAS 1er VTO | O3: TOTAL EXPENSAS 2do VTO
A5: PB | C5: PB | D5: VITAL VANESA | F5: 2.63 | G5: 107830.07 | H5: =175070-G37 -> 107830 | I5: b | J5: =H5-G5 -> -0.071957925 | K5: =N$2*F5% -> 0 | L5: =N$1*F5% -> 99940 | N5: =L5+K5-J5+M5 -> 99940.072 | O5: =N5*6% + N5 -> 105936.48
A6: 3º | C6: 1A | D6: SASSI A. | E6: Hector Gira | F6: 3.33 | G6: 354609.38 | H6: 136530 | I6: b | J6: =H6-G6 -> -218079.38 | K6: =N$2*F6% -> 0 | L6: =N$1*F6% -> 126540 | N6: =L6+K6-J6+M6 -> 344619.38 | O6: =N6*6% + N6 -> 365296.55
A7: 3º | C7: 1B | D7: BOCALANDRO M.E | F7: 3.32 | G7: 136117.55 | H7: =G7+3 -> 136120.55 | I7: b | J7: =H7-G7 -> 3 | K7: =N$2*F7% -> 0 | L7: =N$1*F7% -> 126160 | N7: =L7+K7-J7+M7 -> 126157 | O7: =N7*6% + N7 -> 133726.42
A8: 4º | C8: 1C | D8: ORTIZ MIRAZ | F8: 3.42 | G8: 434149.13 | H8: =180000 -> 180000 | I8: b | J8: =H8-G8 -> -254149.13 | K8: =N$2*F8% -> 0 | L8: =N$1*F8% -> 129960 | N8: =L8+K8-J8+M8 -> 384109.13 | O8: =N8*6% + N8 -> 407155.68
A9: 4º | C9: 1D | D9: PALUMBO ANTONIO | F9: 3.34 | G9: 136940 | H9: =G9 -> 136940 | I9: b | J9: =H9-G9 -> 0 | K9: =N$2*F9% -> 0 | L9: =N$1*F9% -> 126920 | N9: =L9+K9-J9+M9 -> 126920 | O9: =N9*6% + N9 -> 134535.2
A10: 5º | C10: 2A | D10: RAMOS PAMELA | F10: 3.33 | G10: 136530 | H10: =G10 -> 136530 | I10: b | J10: =H10-G10 -> 0 | K10: =N$2*F10% -> 0 | L10: =N$1*F10% -> 126540 | N10: =L10+K10-J10+M10 -> 126540 | O10: =N10*6% + N10 -> 134132.4
A11: 5º | C11: 2B | D11: TEXIDO EMILIO | F11: 3.32 | G11: 136120 | H11: =G11 -> 136120 | I11: b | J11: =H11-G11 -> 0 | K11: =N$2*F11% -> 0 | L11: =N$1*F11% -> 126160 | N11: =L11+K11-J11+M11 -> 126160 | O11: =N11*6% + N11 -> 133729.6
A12: 6º | C12: 2C | D12: FIGUEIRA ALBERTO | F12: 3.33 | G12: 136530 | H12: =G12 -> 136530 | I12: b | J12: =H12-G12 -> 0 | K12: =N$2*F12% -> 0 | L12: =N$1*F12% -> 126540 | N12: =L12+K12-J12+M12 -> 126540 | O12: =N12*6% + N12 -> 134132.4
A13: 6º | C13: 2D | D13: DECIMA SEGUNDO | E13: Barbara | F13: 3.24 | G13: 230305.83 | H13: 165240 | I13: b | J13: =H13-G13 -> -65065.834 | K13: =N$2*F13% -> 0 | L13: =N$1*F13% -> 123120 | N13: =L13+K13-J13+M13 -> 188185.83 | O13: =N13*6% + N13 -> 199476.98 | R13: ESTA ES LARROCA
A14: 7º | C14: 3A | D14: MARQUEZ DELIA | E14: Andrea | F14: 3.33 | G14: 137060 | H14: =137060 -> 137060 | I14: b | J14: =H14-G14 -> 0 | K14: =N$2*F14% -> 0 | L14: =N$1*F14% -> 126540 | M14: 0 | N14: =L14+K14-J14+M14 -> 126540 | O14: =N14*6% + N14 -> 134132.4
A15: 7º | C15: 3B | D15: ROMERO GONZALO | F15: 3.32 | G15: 136120 | H15: =G15 -> 136120 | I15: b | J15: =H15-G15 -> 0 | K15: =N$2*F15% -> 0 | L15: =N$1*F15% -> 126160 | N15: =L15+K15-J15+M15 -> 126160 | O15: =N15*6% + N15 -> 133729.6
A16: 8º | C16: 3C | D16: DEL CASTILLO LAURA | F16: 3.33 | G16: 136066.3 | H16: =G16 -> 136066.3 | I16: b | J16: =H16-G16 -> 0 | K16: =N$2*F16% -> 0 | L16: =N$1*F16% -> 126540 | N16: =L16+K16-J16+M16 -> 126540 | O16: =N16*6% + N16 -> 134132.4
A17: 8º | C17: 3D | D17: MOLINA MATIAS | F17: 3.24 | G17: 132635.35 | H17: =199700-H30 -> 132460 | I17: b | J17: =H17-G17 -> -175.34636 | K17: =N$2*F17% -> 0 | L17: =N$1*F17% -> 123120 | N17: =L17+K17-J17+M17 -> 123295.35 | O17: =N17*6% + N17 -> 130693.07
A18: 9º | C18: 4A | D18: GRECCO CELESTE | E18: Angela | F18: 3.33 | G18: 136104.72 | H18: 135000 | I18: b | J18: =H18-G18 -> -1104.7164 | K18: =N$2*F18% -> 0 | L18: =N$1*F18% -> 126540 | N18: =L18+K18-J18+M18 -> 127644.72 | O18: =N18*6% + N18 -> 135303.4
A19: 9º | C19: 4B | D19: RUSSO L.H | F19: 3.32 | G19: 1540695.5 | I19: B | J19: =H19-G19 -> -1540695.5 | K19: =N$2*F19% -> 0 | L19: =N$1*F19% -> 126160 | N19: =L19+K19-J19+M19 -> 1666855.5 | O19: =N19*6% + N19 -> 1766866.8
A20: 10º | C20: 4C | D20: FERNANDEZ DANIEL | F20: 3.33 | G20: 3081820.7 | I20: B | J20: =H20-G20 -> -3081820.7 | K20: =N$2*F20% -> 0 | L20: =N$1*F20% -> 126540 | N20: =L20+K20-J20+M20 -> 3208360.7 | O20: =N20*6% + N20 -> 3400862.4
A21: 10º | C21: 4D | D21: CORTESE KARINA | E21: Olga | F21: 3.24 | G21: 151319.66 | H21: 142018 | I21: B | J21: =H21-G21 -> -9301.664 | K21: =N$2*F21% -> 0 | L21: =N$1*F21% -> 123120 | N21: =L21+K21-J21+M21 -> 132421.66 | O21: =N21*6% + N21 -> 140366.96
A22: 11º | C22: 5A | D22: SALADINO PABLO | F22: 3.24 | G22: 122080 | H22: 129404 | I22: B | J22: =H22-G22 -> 7324 | K22: =N$2*F22% -> 0 | L22: =N$1*F22% -> 123120 | N22: =L22+K22-J22+M22 -> 115796 | O22: =N22*6% + N22 -> 122743.76
A23: 11º | C23: 5B | D23: VILA LEANDRO | E23: Taller | F23: 3.32 | G23: 136120.48 | H23: =203360*2-H31 -> 339480 | I23: B | J23: =H23-G23 -> 203359.52 | K23: =N$2*F23% -> 0 | L23: =N$1*F23% -> 126160 | N23: =L23+K23-J23+M23 -> -77199.522 | O23: =N23*6% + N23 -> -81831.493
A24: 12º | C24: 5C | D24: MARTINEZ D | E24: Sabrina | F24: 3.33 | G24: 136530 | H24: =G24 -> 136530 | I24: B | J24: =H24-G24 -> 0 | K24: =N$2*F24% -> 0 | L24: =N$1*F24% -> 126540 | N24: =L24+K24-J24+M24 -> 126540 | O24: =N24*6% + N24 -> 134132.4
A25: 13º | C25: 5D | D25: MORINI SERGIO | E25: Cecilia | F25: 3.24 | G25: 132840 | H25: =G25 -> 132840 | I25: B | J25: =H25-G25 -> 0 | K25: =N$2*F25% -> 0 | L25: =N$1*F25% -> 123120 | N25: =L25+K25-J25+M25 -> 123120 | O25: =N25*6% + N25 -> 130507.2
A26: 14º | C26: 6A | D26: MARCHINI MARIO | F26: 3.33 | G26: 136530 | H26: =G26 -> 136530 | I26: B | J26: =H26-G26 -> 0 | K26: =N$2*F26% -> 0 | L26: =N$1*F26% -> 126540 | N26: =L26+K26-J26+M26 -> 126540 | O26: =N26*6% + N26 -> 134132.4
A27: 15º | C27: 6B | D27: AGÜERO CARLOS | E27: Nestor | F27: 3.32 | G27: 134753.77 | H27: 165000 | I27: B | J27: =H27-G27 -> 30246.225 | K27: =N$2*F27% -> 0 | L27: =N$1*F27% -> 126160 | N27: =L27+K27-J27+M27 -> 95913.775 | O27: =N27*6% + N27 -> 101668.6 | Q27: MARIA GARCIA CRISTINA
A28: COC | C28: 6C | D28: PEREZ MARIA | E28: Nelida | F28: 3.33 | G28: 136530 | H28: =G28 -> 136530 | I28: B | J28: =H28-G28 -> 0 | K28: =N$2*F28% -> 0 | L28: =N$1*F28% -> 126540 | N28: =L28+K28-J28+M28 -> 126540 | O28: =N28*6% + N28 -> 134132.4
A29: COC | C29: 6D | D29: R DE FIORE | E29: Fernanda | F29: 3.24 | G29: 132840 | H29: =G29 -> 132840 | I29: B | J29: =H29-G29 -> 0 | K29: =N$2*F29% -> 0 | L29: =N$1*F29% -> 123120 | N29: =L29+K29-J29+M29 -> 123120 | O29: =N29*6% + N29 -> 130507.2
A30: COC | C30: COCH1 | D30: MOLINA MATIAS | F30: 1.64 | G30: 67240 | H30: =G30 -> 67240 | I30: B | J30: =H30-G30 -> 0 | K30: =N$2*F30% -> 0 | L30: =N$1*F30% -> 62320 | N30: =L30+K30-J30+M30 -> 62320 | O30: =N30*6% + N30 -> 66059.2
A31: COC | C31: COCH2 | D31: VILA LEANDRO | F31: 1.64 | G31: 67240 | H31: =G31 -> 67240 | I31: B | J31: =H31-G31 -> 0 | K31: =N$2*F31% -> 0 | L31: =N$1*F31% -> 62320 | N31: =L31+K31-J31+M31 -> 62320 | O31: =N31*6% + N31 -> 66059.2
A32: COC | C32: COCH3 | D32: SASSI A. | F32: 1.64 | G32: 229189.73 | I32: B | J32: =H32-G32 -> -229189.73 | K32: =N$2*F32% -> 0 | L32: =N$1*F32% -> 62320 | N32: =L32+K32-J32+M32 -> 291509.73 | O32: =N32*6% + N32 -> 309000.32
A33: COC | C33: COCH4 | D33: NN | F33: 1.64 | G33: 619906.3 | I33: B | J33: =H33-G33 -> -619906.3 | K33: =N$2*F33% -> 0 | L33: =N$1*F33% -> 62320 | N33: =L33+K33-J33+M33 -> 682226.3 | O33: =N33*6% + N33 -> 723159.88 | Q33: RUSSO
A34: COC | C34: COCH5 | D34: CURRA LETICIA | F34: 1.64 | G34: 67240 | H34: =G34 -> 67240 | I34: B | J34: =H34-G34 -> 0 | K34: =N$2*F34% -> 0 | L34: =N$1*F34% -> 62320 | N34: =L34+K34-J34+M34 -> 62320 | O34: =N34*6% + N34 -> 66059.2
A35: COC | C35: COCH6 | D35: MARCHINI MARIO | F35: 1.64 | G35: 67240 | H35: =G35 -> 67240 | J35: =H35-G35 -> 0 | K35: =N$2*F35% -> 0 | L35: =N$1*F35% -> 62320 | N35: =L35+K35-J35+M35 -> 62320 | O35: =N35*6% + N35 -> 66059.2
A36: COC | C36: COCH7 | D36: FERNANDEZ DANIEL | F36: 1.64 | G36: 1472954.8 | I36: B | J36: =H36-G36 -> -1472954.8 | K36: =N$2*F36% -> 0 | L36: =N$1*F36% -> 62320 | N36: =L36+K36-J36+M36 -> 1535274.8 | O36: =N36*6% + N36 -> 1627391.3
A37: COC | C37: COCH8 | D37: NN VITAL VANESA | F37: 1.64 | G37: 67240 | H37: =G37 -> 67240 | I37: B | J37: =H37-G37 -> 0 | K37: =N$2*F37% -> 0 | L37: =N$1*F37% -> 62320 | N37: =L37+K37-J37+M37 -> 62320 | O37: =N37*6% + N37 -> 66059.2
A38: COC | C38: COCH9 | D38: NN | F38: 1.64 | G38: 67240 | H38: =G38 -> 67240 | I38: B | J38: =H38-G38 -> 0 | K38: =N$2*F38% -> 0 | L38: =N$1*F38% -> 62320 | N38: =L38+K38-J38+M38 -> 62320 | O38: =N38*6% + N38 -> 66059.2
A39: COC | C39: COCH10 | D39: DAVOLA MARTA | F39: 1.64 | G39: 67240 | H39: =G39 -> 67240 | I39: B | J39: =H39-G39 -> 0 | K39: =N$2*F39% -> 0 | L39: =N$1*F39% -> 62320 | N39: =L39+K39-J39+M39 -> 62320 | O39: =N39*6% + N39 -> 66059.2
A40: COC | C40: COCH11 | D40: GUZMAN MIMA | F40: 1.64 | G40: 303388.98 | I40: b | J40: =H40-G40 -> -303388.98 | K40: =N$2*F40% -> 0 | L40: =N$1*F40% -> 62320 | N40: =L40+K40-J40+M40 -> 365708.98 | O40: =N40*6% + N40 -> 387651.52
F41: =SUM(F5:F40) -> 100.09 | G41: =SUM(G5:G40) -> 11425298 | H41: =SUM(H5:H40) -> 3870398.8 | J41: =SUM(J5:J40) -> -7554899.4 | K41: =SUM(K5:K40) -> 0 | L41: =SUM(L5:L40) -> 3803420 | M41: =SUM(M5:M40) -> 0 | N41: =SUM(N5:N40) -> 11358319 | O41: =SUM(O5:O40) -> 12039819
...

Sheet Recibo 
E7: RECIBO DE EXPENSAS
E8: CONSORCIO: ADMINISTRACION DE CONSORCIOS RC
J9: PERIODO: OCTUBRE
E10: Adminstradora: Carolina Canciani | J10: VENCIMIENTO: NOVIEMBRE
E12: EXPENSAS ORDINARIAS
E14: Nombre y apellido: | G14: =PRORRATEO!D10 -> RAMOS PAMELA | I14: Fecha: | J14: 45600 | L14: Sello o firma autoriada:
E15: UF: | F15: =PRORRATEO!C10 -> 2A
E20: Total recibido: | J20: =PRORRATEO!H10 -> 136530
G25: RECIBO DE EXPENSAS
G26: CONSORCIO: ADMINISTRACION DE CONSORCIOS RC
L27: PERIODO: OCTUBRE
G28: Adminstradora: Carolina Canciani | L28: VENCIMIENTO: NOVIEMBRE
G30: EXPENSAS ORDINARIAS
G32: Nombre y apellido: | K32: Fecha: | L32: 45600 | N32: Sello o firma autoriada:
G33: UF: | H33: =PRORRATEO!E28 -> Nelida
G38: Total recibido: | L38: =PRORRATEO!J28 -> 0
