Workbook

Sheet RESUMEN
B2: MAIL: consorciogorriti368@gmail.com
B3: CUIT ADMINISTRACION: 27231256879
B4: CBU: 0290034600000502294350 | D4: TELEFONO: 11 5320-2676
A5: LIQUIDACION DE EXPENSAS | B5: ADMINISTRADORA: CAROLINA CANCIANI MP:1148
A6: CUIT DEL EDIFICIO: 30583957819 | B6: PERÍODO: AGOSTO | D6: HORARIOS DE ATENCION: LUNES A VIERNES
A7: CONSORCIO DE PROPIETARIOS DEL EDIFICIO CALLE GORRITI 368 | D7: 10 A 16HS - EMERGENCIAS 24HS
B9: VTO 15/09
A14: ESTIMADOS PROPIETARIOS E INQUILINOS: POR FAVOR LOS QUE ABONAN EN PRIMER VENCIMIENTO ABONEN EL MONTO DE PRIMER VENCIMIENTO, ASI AGILIZAN LA LIQUIDACION, RESPETEN LOS CENTAVOS CORRESPONDIENTES A LA UNIDAD FUNCIONAL. ES DE CARÁCTER OBLIGATORIO INFORMAR VIA MAIL LAS EXPENSAS. CASO CONTRARIO SE INFORMARA VIA CARTA DOCUMENTO A LA UNIDAD FUNCIONAL QUE CREEMOS QUE CORRESPONDE, CUYO COSTO SERA IMPUTADO A LA UNIDAD FUNCIONAL SOSPECHADA.
A21: GASTOS ORDINARIOS UNIDADES FUNCIONALES:
A22: HABERES ENCARGADOS
A23: Sueldo encargado Colmiero Oscar | D23: 1271490
A26: Retenciones | D26: 0
A28: Neto | D28: =SUM(D23:D27) -> 1271490 | G28: =D28+D30 -> 2313543
A29: Sueldo encargado Balcazza Leonardo | D29: 1042053 | G29: =700000 -> 700000
A30: Neto | D30: =SUM(D29:D29) -> 1042053 | G30: =G28-G29 -> 1613543
A31: Sueldo Alcaraz Gisela - Reemplazo del Sr. Leonardo | D31: 98440 | G31: -500000 | H31: Efectivo
A32: Neto | D32: =SUM(D31) -> 98440 | G32: =G30+G31 -> 1113543
A33: TOTAL SUELDO | E33: =D28+D30+D32 -> 2411983
A34: HONORARIOS
A35: HONORARIOS CONTADOR GUSTAVO PADRON | D35: 90000 | E35: Transf 14/07
A36: HONORARIOS ADMINISTRACION RC - SE ABONA EL MES JULIO - SE DEBE AGOSTO | D36: 249000 | E36: Transf 14/07
A37: TOTAL | E37: =SUM(D35:D36) -> 339000
A38: SEGUROS
A39: Seguro Integral consorcio San Cristobal - Poliza 01-05-07-30183461 | D39: 144149 | E39: Debito 10/07
A41: TOTAL IMPUESTO | E41: =SUM(D39:D40) -> 144149
A42: APORTES Y CONTRIBUCIONES
A43: ARCA | D43: 1843741.1 | E43: PMC 12/08
A44: Sindicatos mes de AGOSTO | B44: Fatheryh | D44: 133047.14 | E44: Debito 14/07
A45: =A44 -> Sindicatos mes de AGOSTO | B45: Suther | D45: 241435.09 | E45: =E44 -> Debito 14/07
A46: =A45 -> Sindicatos mes de AGOSTO | B46: Seracarh | D46: 14783.02 | E46: =E45 -> Debito 14/07
A47: TOTAL Aportes y Contribuciones - Sindicato | E47: =SUM(D43:D46) -> 2233006.4
A48: ABONOS Y SERVICIOS
A49: EDESUR - Cliente nro. 828563 | D49: 1002998.2 | E49: Transf 19/08
A50: EDESUR - Cliente nro. 01672309 | D50: 23385.69 | E50: Transf 11/08
A51: EDESUR - Cliente nro. 01672321 | D51: 14748.22 | E51: =E50 -> Transf 11/08
A52: EDESUR - Cliente nro. 01672319 | D52: 12432.23 | E52: =E51 -> Transf 11/08
A53: Metrogas - Cliente nro. 20463936100 | D53: 5586.39 | E53: Transf 18/08
A54: Metrogas - Cliente nro. 20495697900 | D54: 2046270.6 | E54: Debito 17/07
A55: Personal Flow - Debito automatico | D55: 23728.51 | E55: Debito 21/07
A56: AYSA - Nro de cliente 3888610 | D56: 2168902.4 | E56: Debito 17/07
...

Sheet PRORRATEO
E2: =RESUMEN!B4 -> CBU: 0290034600000502294350 | L2: Gastos ordinarios: | P2: =U2 -> 14485791 | U2: 14485791
A4: Piso | B4: Dpto. | D4: UF | E4: Propietario | F4: Inquilinos | G4: (%) | H4: Saldo Ord | I4: Ingreso | J4: Pago por | K4: Deuda o Saldo a favor | L4: Interes 3% | M4: Expensas extraor. | N4: Expensas ord. | O4: Gastos part. | P4: Total 1er Vto | Q4: Total 2do Vto. | R4: Total 2do Vto
P5: =RESUMEN!B9 -> VTO 15/09
A6: PB | C6: LOC | D6: 1 | E6: GEFFNER SILVIA E. | G6: 0.5131 | H6: 63505.01 | I6: =786304-I13-I7-I47-I48-I59-I69-I73 -> 63505.19 | K6: =H6-I6 -> -0.18 | L6: =IF(K6>0,K6*3%,0) -> 0 | M6: 0 | N6: =P$2*G6% -> 74326.596 | O6: 0 | P6: =ROUND(SUM(K6:O6),0) + S6 -> 74326.01 | Q6: =ROUND(P6*6% + P6,0) + S6 -> 78786.01 | R6: =ROUND(P6*3%,0) + P6 -> 76556.01 | S6: 0.01 | U6: este es el candel que tiene a todas sus demas ufs relacionadas
A7: 3º | C7: LOC | D7: =D6+1 -> 2 | E7: COVILOZA S. A. | G7: 0.6119 | H7: 75734.02 | I7: =H7 -> 75734.02 | K7: =H7-I7 -> 0 | L7: =IF(K7>0,K7*3%,0) -> 0 | M7: 0 | N7: =P$2*G7% -> 88638.558 | O7: 0 | P7: =ROUND(SUM(K7:O7),0) + S7 -> 88639.02 | Q7: =ROUND(P7*6% + P7,0) + S7 -> 93957.02 | R7: =ROUND(P7*3%,0) + P7 -> 91298.02 | S7: =S6+0.01 -> 0.02
A8: 3º | B8: 1 | D8: =D7+1 -> 3 | E8: ASIST Y TRAB. | G8: 0.6115 | H8: 75684.03 | I8: =H8 -> 75684.03 | K8: =H8-I8 -> 0 | L8: =IF(K8>0,K8*3%,0) -> 0 | M8: 0 | N8: =P$2*G8% -> 88580.614 | O8: 0 | P8: =ROUND(SUM(K8:O8),0) + S8 -> 88581.03 | Q8: =ROUND(P8*6% + P8,0) + S8 -> 93896.03 | R8: =ROUND(P8*3%,0) + P8 -> 91238.03 | S8: =S7+0.01 -> 0.03
A9: 4º | B9: 2 | D9: =D8+1 -> 4 | E9: ASIST Y TRAB. | G9: 0.5033 | H9: 62293.04 | I9: =H9 -> 62293.04 | K9: =H9-I9 -> 0 | L9: =IF(K9>0,K9*3%,0) -> 0 | M9: 0 | N9: =P$2*G9% -> 72906.988 | O9: 0 | P9: =ROUND(SUM(K9:O9),0) + S9 -> 72907.04 | Q9: =ROUND(P9*6% + P9,0) + S9 -> 77281.04 | R9: =ROUND(P9*3%,0) + P9 -> 75094.04 | S9: =S8+0.01 -> 0.04
A10: 4º | B10: 3 | D10: =D9+1 -> 5 | E10: ASIST Y TRAB. | G10: 0.5033 | H10: 62293.05 | I10: =H10 -> 62293.05 | K10: =H10-I10 -> 0 | L10: =IF(K10>0,K10*3%,0) -> 0 | M10: 0 | N10: =P$2*G10% -> 72906.988 | O10: 0 | P10: =ROUND(SUM(K10:O10),0) + S10 -> 72907.05 | Q10: =ROUND(P10*6% + P10,0) + S10 -> 77281.05 | R10: =ROUND(P10*3%,0) + P10 -> 75094.05 | S10: =S9+0.01 -> 0.05
A11: 5º | B11: 4 | D11: =D10+1 -> 6 | E11: BENMAOR D. | F11: Cristian Requelme | G11: 0.7499 | H11: 92814.06 | I11: =H11 -> 92814.06 | K11: =H11-I11 -> 0 | L11: =IF(K11>0,K11*3%,0) -> 0 | M11: 0 | N11: =P$2*G11% -> 108628.95 | O11: 0 | P11: =ROUND(SUM(K11:O11),0) + S11 -> 108629.06 | Q11: =ROUND(P11*6% + P11,0) + S11 -> 115147.06 | R11: =ROUND(P11*3%,0) + P11 -> 111888.06 | S11: =S10+0.01 -> 0.06
A12: 5º | B12: 5 | D12: =D11+1 -> 7 | E12: GALANTERNIK A | F12: Miriam Larken | G12: 0.5425 | H12: 67144.07 | I12: =H12 -> 67144.07 | K12: =H12-I12 -> 0 | L12: =IF(K12>0,K12*3%,0) -> 0 | M12: 0 | N12: =P$2*G12% -> 78585.418 | O12: 0 | P12: =ROUND(SUM(K12:O12),0) + S12 -> 78585.07 | Q12: =ROUND(P12*6% + P12,0) + S12 -> 83300.07 | R12: =ROUND(P12*3%,0) + P12 -> 80943.07 | S12: =S11+0.01 -> 0.07
A13: 6º | B13: 6 | D13: =D12+1 -> 8 | E13: CANDEL JORGE ISAAC | G13: 0.4537 | H13: 56154.08 | I13: =H13 -> 56154.08 | K13: =H13-I13 -> 0 | L13: =IF(K13>0,K13*3%,0) -> 0 | M13: 0 | N13: =P$2*G13% -> 65722.036 | O13: 0 | P13: =ROUND(SUM(K13:O13),0) + S13 -> 65722.08 | Q13: =ROUND(P13*6% + P13,0) + S13 -> 69665.08 | R13: =ROUND(P13*3%,0) + P13 -> 67694.08 | S13: =S12+0.01 -> 0.08
A14: 6º | B14: 7 | D14: =D13+1 -> 9 | E14: BORTZ SERGIO | F14: Luciana | G14: 0.5244 | H14: 131755.09 | I14: 200000.09 | K14: =H14-I14 -> -68245 | L14: =IF(K14>0,K14*3%,0) -> 0 | M14: 0 | N14: =P$2*G14% -> 75963.49 | O14: 0 | P14: =ROUND(SUM(K14:O14),0) + S14 -> 7718.09 | Q14: =ROUND(P14*6% + P14,0) + S14 -> 8181.09 | R14: =ROUND(P14*3%,0) + P14 -> 7950.09 | S14: =S13+0.01 -> 0.09 | U14: ESTA ES LA FUNDACION DE MEDICOS
A15: 7º | B15: 8 | D15: =D14+1 -> 10 | E15: BORTZ SERGIO | F15: Luciana | G15: 0.424 | H15: 106530.1 | I15: 200000.1 | K15: =H15-I15 -> -93470 | L15: =IF(K15>0,K15*3%,0) -> 0 | M15: 0 | N15: =P$2*G15% -> 61419.756 | O15: 0 | P15: =ROUND(SUM(K15:O15),0) + S15 -> -32049.9 | Q15: =ROUND(P15*6% + P15,0) + S15 -> -33972.9 | R15: =ROUND(P15*3%,0) + P15 -> -33010.9 | S15: =S14+0.01 -> 0.1 | U15: ESTA ES LA FUNDACION DE MEDICOS
A16: 7º | B16: 1 | C16: A | D16: =D15+1 -> 11 | E16: KIM SOON LEO | G16: 2.3033 | H16: 3639445.1 | K16: =H16-I16 -> 3639445.1 | L16: =IF(K16>0,K16*3%,0) -> 109183.35 | M16: 0 | N16: =P$2*G16% -> 333651.23 | O16: 0 | P16: =ROUND(SUM(K16:O16),0) + S16 -> 4082280.1 | Q16: =ROUND(P16*6% + P16,0) + S16 -> 4327217.1 | R16: =ROUND(P16*3%,0) + P16 -> 4204748.1 | S16: =S15+0.01 -> 0.11
A17: 8º | B17: 1 | C17: B | D17: =D16+1 -> 12 | E17: CANDEL MARCELO | F17: Florencia Fucci | G17: 2.7493 | H17: 350484.12 | I17: =H17 -> 350484.12 | K17: =H17-I17 -> 0 | L17: =IF(K17>0,K17*3%,0) -> 0 | M17: 0 | N17: =P$2*G17% -> 398257.86 | O17: 0 | P17: =ROUND(SUM(K17:O17),0) + S17 -> 398258.12 | Q17: =ROUND(P17*6% + P17,0) + S17 -> 422154.12 | R17: =ROUND(P17*3%,0) + P17 -> 410206.12 | S17: =S16+0.01 -> 0.12
A18: 8º | B18: 2 | C18: A | D18: =D17+1 -> 13 | E18: TRIPODI | F18: Mariela Pricolo | G18: 2.3033 | H18: 285076.13 | I18: =H18 -> 285076.13 | K18: =H18-I18 -> 0 | L18: =IF(K18>0,K18*3%,0) -> 0 | M18: 0 | N18: =P$2*G18% -> 333651.23 | O18: 0 | P18: =ROUND(SUM(K18:O18),0) + S18 -> 333651.13 | Q18: =ROUND(P18*6% + P18,0) + S18 -> 353670.13 | R18: =ROUND(P18*3%,0) + P18 -> 343661.13 | S18: =S17+0.01 -> 0.13
A19: 9º | B19: 2 | C19: B | D19: =D18+1 -> 14 | E19: MIRANDA DE GIL | F19: Susana | G19: 2.6368 | H19: 621056.14 | I19: =40000 -> 40000 | K19: =H19-I19 -> 581056.14 | L19: =IF(K19>0,K19*3%,0) -> 17431.684 | M19: 0 | N19: =P$2*G19% -> 381961.35 | O19: 0 | P19: =ROUND(SUM(K19:O19),0) + S19 -> 980449.14 | Q19: =ROUND(P19*6% + P19,0) + S19 -> 1039276.1 | R19: =ROUND(P19*3%,0) + P19 -> 1009862.1 | S19: =S18+0.01 -> 0.14 | U19: MAXIMO
A20: 9º | B20: 3 | C20: A | D20: =D19+1 -> 15 | E20: FRAGA DORA | G20: 2.3537 | H20: 291313.15 | I20: =H20 -> 291313.15 | K20: =H20-I20 -> 0 | L20: =IF(K20>0,K20*3%,0) -> 0 | M20: 0 | N20: =P$2*G20% -> 340952.07 | O20: 0 | P20: =ROUND(SUM(K20:O20),0) + S20 -> 340952.15 | Q20: =ROUND(P20*6% + P20,0) + S20 -> 361409.15 | R20: =ROUND(P20*3%,0) + P20 -> 351181.15 | S20: =S19+0.01 -> 0.15
A21: 10º | B21: 3 | C21: B | D21: =D20+1 -> 16 | E21: SARUBBI MARTIN | F21: Sarubbi Adriana | G21: 2.6477 | H21: 327701.16 | I21: =H21 -> 327701.16 | K21: =H21-I21 -> 0 | L21: =IF(K21>0,K21*3%,0) -> 0 | M21: 0 | N21: =P$2*G21% -> 383540.3 | O21: 0 | P21: =ROUND(SUM(K21:O21),0) + S21 -> 383540.16 | Q21: =ROUND(P21*6% + P21,0) + S21 -> 406553.16 | R21: =ROUND(P21*3%,0) + P21 -> 395046.16 | S21: =S20+0.01 -> 0.16
A22: 10º | B22: 4 | C22: A | D22: =D21+1 -> 17 | E22: LACENTRE | F22: Gabriela Tamara | G22: 2.3235 | H22: 287576.17 | I22: =H22 -> 287576.17 | K22: =H22-I22 -> 0 | L22: =IF(K22>0,K22*3%,0) -> 0 | M22: 0 | N22: =P$2*G22% -> 336577.36 | O22: 0 | P22: =ROUND(SUM(K22:O22),0) + S22 -> 336577.17 | Q22: =ROUND(P22*6% + P22,0) + S22 -> 356772.17 | R22: =ROUND(P22*3%,0) + P22 -> 346674.17 | S22: =S21+0.01 -> 0.17
A23: 11º | B23: 4 | C23: B | D23: =D22+1 -> 18 | E23: FERNANDEZ BERTA | F23: KRAVETZ | G23: 2.688 | H23: 342670.18 | I23: =H23 -> 342670.18 | K23: =H23-I23 -> 0 | L23: =IF(K23>0,K23*3%,0) -> 0 | M23: 0 | N23: =P$2*G23% -> 389378.07 | O23: 0 | P23: =ROUND(SUM(K23:O23),0) + S23 -> 389378.18 | Q23: =ROUND(P23*6% + P23,0) + S23 -> 412741.18 | R23: =ROUND(P23*3%,0) + P23 -> 401059.18 | S23: =S22+0.01 -> 0.18 | U23: KRAVETZ
A24: 11º | B24: 5 | C24: A | D24: =D23+1 -> 19 | E24: VERONES JOSE MARIA | G24: 2.36 | H24: 292093.19 | I24: =H24+100000 -> 392093.19 | K24: =H24-I24 -> -100000 | L24: =IF(K24>0,K24*3%,0) -> 0 | M24: 0 | N24: =P$2*G24% -> 341864.68 | O24: 0 | P24: =ROUND(SUM(K24:O24),0) + S24 -> 241865.19 | Q24: =ROUND(P24*6% + P24,0) + S24 -> 256377.19 | R24: =ROUND(P24*3%,0) + P24 -> 249121.19 | S24: =S23+0.01 -> 0.19
A25: 12º | B25: 5 | C25: B | D25: =D24+1 -> 20 | E25: SRUGO CARLOS | G25: 2.7183 | H25: 326615.2 | I25: 327000 | K25: =H25-I25 -> -384.8 | L25: =IF(K25>0,K25*3%,0) -> 0 | M25: 0 | N25: =P$2*G25% -> 393767.27 | O25: 0 | P25: =ROUND(SUM(K25:O25),0) + S25 -> 393382.2 | Q25: =ROUND(P25*6% + P25,0) + S25 -> 416985.2 | R25: =ROUND(P25*3%,0) + P25 -> 405183.2 | S25: =S24+0.01 -> 0.2
A26: 13º | B26: 6 | C26: A | D26: =D25+1 -> 21 | E26: DINOTO | G26: 2.3033 | H26: 285076.21 | I26: =H26 -> 285076.21 | K26: =H26-I26 -> 0 | L26: =IF(K26>0,K26*3%,0) -> 0 | M26: 0 | N26: =P$2*G26% -> 333651.23 | O26: 0 | P26: =ROUND(SUM(K26:O26),0) + S26 -> 333651.21 | Q26: =ROUND(P26*6% + P26,0) + S26 -> 353670.21 | R26: =ROUND(P26*3%,0) + P26 -> 343661.21 | S26: =S25+0.01 -> 0.21
A27: 14º | B27: 6 | C27: B | D27: =D26+1 -> 22 | E27: BORTZ ESTHER | F27: Daniel / Luciana | G27: 2.636 | H27: 653120.22 | I27: =885587.22 -> 885587.22 | K27: =H27-I27 -> -232467 | L27: =IF(K27>0,K27*3%,0) -> 0 | M27: 0 | N27: =P$2*G27% -> 381845.46 | O27: 0 | P27: =ROUND(SUM(K27:O27),0) + S27 -> 149378.22 | Q27: =ROUND(P27*6% + P27,0) + S27 -> 158341.22 | R27: =ROUND(P27*3%,0) + P27 -> 153859.22 | S27: =S26+0.01 -> 0.22 | T27: Luciana | U27: ESTA ES LA FUNDACION DE MEDICOS
A28: 15º | B28: 7 | C28: A | D28: =D27+1 -> 23 | E28: COUSO MARIA CRISTINA | G28: 2.3033 | H28: 285076.23 | I28: 290000.23 | K28: =H28-I28 -> -4924 | L28: =IF(K28>0,K28*3%,0) -> 0 | M28: 0 | N28: =P$2*G28% -> 333651.23 | O28: 0 | P28: =ROUND(SUM(K28:O28),0) + S28 -> 328727.23 | Q28: =ROUND(P28*6% + P28,0) + S28 -> 348451.23 | R28: =ROUND(P28*3%,0) + P28 -> 338589.23 | S28: =S27+0.01 -> 0.23
A29: COC | B29: 7 | C29: B | D29: =D28+1 -> 24 | E29: POSSENTI JUAN JOSE | G29: 2.6159 | H29: 323766.24 | I29: =H29 -> 323766.24 | K29: =H29-I29 -> 0 | L29: =IF(K29>0,K29*3%,0) -> 0 | M29: 0 | N29: =P$2*G29% -> 378933.82 | O29: 0 | P29: =ROUND(SUM(K29:O29),0) + S29 -> 378934.24 | Q29: =ROUND(P29*6% + P29,0) + S29 -> 401670.24 | R29: =ROUND(P29*3%,0) + P29 -> 390302.24 | S29: =S28+0.01 -> 0.24
A30: COC | B30: 8 | C30: A | D30: =D29+1 -> 25 | E30: VANNI KARINA | G30: 2.3537 | H30: 291313.25 | I30: =H30 -> 291313.25 | K30: =H30-I30 -> 0 | L30: =IF(K30>0,K30*3%,0) -> 0 | M30: 0 | N30: =P$2*G30% -> 340952.07 | O30: 0 | P30: =ROUND(SUM(K30:O30),0) + S30 -> 340952.25 | Q30: =ROUND(P30*6% + P30,0) + S30 -> 361409.25 | R30: =ROUND(P30*3%,0) + P30 -> 351181.25 | S30: =S29+0.01 -> 0.25
A31: COC | B31: 8 | C31: B | D31: =D30+1 -> 26 | E31: CARRIZO RAÚL | F31: Noelia Villarino | G31: 2.6469 | H31: 327602.26 | I31: =H31 -> 327602.26 | K31: =H31-I31 -> 0 | L31: =IF(K31>0,K31*3%,0) -> 0 | M31: 0 | N31: =P$2*G31% -> 383424.41 | O31: 0 | P31: =ROUND(SUM(K31:O31),0) + S31 -> 383424.26 | Q31: =ROUND(P31*6% + P31,0) + S31 -> 406430.26 | R31: =ROUND(P31*3%,0) + P31 -> 394927.26 | S31: =S30+0.01 -> 0.26
A32: COC | B32: 9 | C32: A | D32: =D31+1 -> 27 | E32: BLANCO | G32: 2.3537 | H32: 291313.27 | I32: 300052.27 | K32: =H32-I32 -> -8739 | L32: =IF(K32>0,K32*3%,0) -> 0 | M32: 0 | N32: =P$2*G32% -> 340952.07 | O32: 0 | P32: =ROUND(SUM(K32:O32),0) + S32 -> 332213.27 | Q32: =ROUND(P32*6% + P32,0) + S32 -> 352146.27 | R32: =ROUND(P32*3%,0) + P32 -> 342179.27 | S32: =S31+0.01 -> 0.27
A33: COC | B33: 9 | C33: B | D33: =D32+1 -> 28 | E33: GALANTE CELIA | G33: 2.6663 | H33: 330003.28 | I33: =H33 -> 330003.28 | K33: =H33-I33 -> 0 | L33: =IF(K33>0,K33*3%,0) -> 0 | M33: 0 | N33: =P$2*G33% -> 386234.66 | O33: 0 | P33: =ROUND(SUM(K33:O33),0) + S33 -> 386235.28 | Q33: =ROUND(P33*6% + P33,0) + S33 -> 409409.28 | R33: =ROUND(P33*3%,0) + P33 -> 397822.28 | S33: =S32+0.01 -> 0.28
A34: COC | B34: 10 | C34: A | D34: =D33+1 -> 29 | E34: LEGUIZAMON PABLO | F34: Carla | G34: 2.4476 | H34: 321435.29 | I34: =H34 -> 321435.29 | K34: =H34-I34 -> 0 | L34: =IF(K34>0,K34*3%,0) -> 0 | M34: 0 | N34: =P$2*G34% -> 354554.23 | O34: 18500 | P34: =ROUND(SUM(K34:O34),0) + S34 -> 373054.29 | Q34: =ROUND(P34*6% + P34,0) + S34 -> 395438.29 | R34: =ROUND(P34*3%,0) + P34 -> 384246.29 | S34: =S33+0.01 -> 0.29
A35: COC | B35: 10 | C35: B | D35: =D34+1 -> 30 | E35: CANDEL E. MARCELO | G35: 2.7183 | H35: 336439.3 | I35: =H35 -> 336439.3 | K35: =H35-I35 -> 0 | L35: =IF(K35>0,K35*3%,0) -> 0 | M35: 0 | N35: =P$2*G35% -> 393767.27 | O35: 0 | P35: =ROUND(SUM(K35:O35),0) + S35 -> 393767.3 | Q35: =ROUND(P35*6% + P35,0) + S35 -> 417393.3 | R35: =ROUND(P35*3%,0) + P35 -> 405580.3 | S35: =S34+0.01 -> 0.3
A36: COC | B36: 11 | C36: A | D36: =D35+1 -> 31 | E36: DAVICCA MIGUEL | F36: Romina Navarro | G36: 2.3026 | H36: 284989.31 | I36: =H36 -> 284989.31 | K36: =H36-I36 -> 0 | L36: =IF(K36>0,K36*3%,0) -> 0 | M36: 0 | N36: =P$2*G36% -> 333549.83 | O36: 0 | P36: =ROUND(SUM(K36:O36),0) + S36 -> 333550.31 | Q36: =ROUND(P36*6% + P36,0) + S36 -> 353563.31 | R36: =ROUND(P36*3%,0) + P36 -> 343557.31 | S36: =S35+0.01 -> 0.31
A37: COC | B37: 11 | C37: B | D37: =D36+1 -> 32 | E37: GUTMAN MARIO | G37: 2.6562 | H37: 456011.32 | I37: 328753.32 | K37: =H37-I37 -> 127258 | L37: =IF(K37>0,K37*3%,0) -> 3817.74 | M37: 0 | N37: =P$2*G37% -> 384771.59 | O37: 0 | P37: =ROUND(SUM(K37:O37),0) + S37 -> 515847.32 | Q37: =ROUND(P37*6% + P37,0) + S37 -> 546798.32 | R37: =ROUND(P37*3%,0) + P37 -> 531322.32 | S37: =S36+0.01 -> 0.32
A38: COC | B38: 12 | C38: A | D38: =D37+1 -> 33 | E38: PRATOLONGO EDUARDO | G38: 2.3343 | H38: 288912.33 | I38: =H38 -> 288912.33 | K38: =H38-I38 -> 0 | L38: =IF(K38>0,K38*3%,0) -> 0 | M38: 0 | N38: =P$2*G38% -> 338141.83 | O38: 0 | P38: =ROUND(SUM(K38:O38),0) + S38 -> 338142.33 | Q38: =ROUND(P38*6% + P38,0) + S38 -> 358431.33 | R38: =ROUND(P38*3%,0) + P38 -> 348286.33 | S38: =S37+0.01 -> 0.33
A39: COC | B39: 12 | C39: B | D39: =D38+1 -> 34 | E39: CARTABBIA MARIO | G39: 2.6259 | H39: 325003.34 | I39: =H39 -> 325003.34 | K39: =H39-I39 -> 0 | L39: =IF(K39>0,K39*3%,0) -> 0 | M39: 0 | N39: =P$2*G39% -> 380382.4 | O39: 0 | P39: =ROUND(SUM(K39:O39),0) + S39 -> 380382.34 | Q39: =ROUND(P39*6% + P39,0) + S39 -> 403205.34 | R39: =ROUND(P39*3%,0) + P39 -> 391793.34 | S39: =S38+0.01 -> 0.34
A40: COC | B40: 1 | C40: C | D40: =D39+1 -> 35 | E40: NAVA HECTOR | F40: Marcos | G40: 1.007 | H40: 128374.35 | I40: =H40 -> 128374.35 | K40: =H40-I40 -> 0 | L40: =IF(K40>0,K40*3%,0) -> 0 | M40: 0 | N40: =P$2*G40% -> 145871.92 | O40: 0 | P40: =ROUND(SUM(K40:O40),0) + S40 -> 145872.35 | Q40: =ROUND(P40*6% + P40,0) + S40 -> 154625.35 | R40: =ROUND(P40*3%,0) + P40 -> 150248.35 | S40: =S39+0.01 -> 0.35
A41: COC | B41: 1 | C41: D | D41: =D40+1 -> 36 | E41: BRATTOLI | F41: Palermo Hernan | G41: 0.7812 | H41: 99589.36 | I41: =H41 -> 99589.36 | K41: =H41-I41 -> 0 | L41: =IF(K41>0,K41*3%,0) -> 0 | M41: 0 | N41: =P$2*G41% -> 113163 | O41: 0 | P41: =ROUND(SUM(K41:O41),0) + S41 -> 113163.36 | Q41: =ROUND(P41*6% + P41,0) + S41 -> 119953.36 | R41: =ROUND(P41*3%,0) + P41 -> 116558.36 | S41: =S40+0.01 -> 0.36 | U41: PALERMO
B42: 1 | C42: E | D42: =D41+1 -> 37 | E42: BRATTOLI | F42: Palermo Hernan | G42: 1.2153 | H42: 154928.37 | I42: =H42 -> 154928.37 | K42: =H42-I42 -> 0 | L42: =IF(K42>0,K42*3%,0) -> 0 | M42: 0 | N42: =P$2*G42% -> 176045.82 | O42: 0 | P42: =ROUND(SUM(K42:O42),0) + S42 -> 176046.37 | Q42: =ROUND(P42*6% + P42,0) + S42 -> 186609.37 | R42: =ROUND(P42*3%,0) + P42 -> 181327.37 | S42: =S41+0.01 -> 0.37 | U42: PALERMO
...

Sheet Hoja1

Sheet PRORRATEO DE PRUEBA  EMERGENCIA
E2: PRESUPUESTO LEMA | L2: PRESUPUESTO LEMA | P2: =16770000+7700000 -> 24470000
A4: Piso | B4: Dpto. | D4: UF | E4: Propietario | F4: Inquilinos | G4: (%) | H4: Saldo Ord | I4: Ingreso | J4: Pago por | K4: Deuda o Saldo a favor | L4: Interes 3% | M4: Expensas extraor. | N4: Presupuesto | P4: Total 1er Vto | Q4: Total 2do Vto. | R4: Total 2do Vto
A6: PB | C6: LOC | D6: 1 | E6: GEFFNER SILVIA E. | G6: 0.5131 | M6: 0 | N6: =P$2*G6% -> 125555.57 | O6: 0 | P6: =ROUND(SUM(K6:O6),0) + S6 -> 125556.01 | Q6: =ROUND(P6*6% + P6,0) + S6 -> 133089.01 | R6: =ROUND(P6*3%,0) + P6 -> 129323.01 | S6: 0.01 | U6: este es el candel que tiene a todas sus demas ufs relacionadas
A7: 3º | C7: LOC | D7: =D6+1 -> 2 | E7: COVILOZA S. A. | G7: 0.6119 | M7: 0 | N7: =P$2*G7% -> 149731.93 | O7: 0 | P7: =ROUND(SUM(K7:O7),0) + S7 -> 149732.02 | Q7: =ROUND(P7*6% + P7,0) + S7 -> 158716.02 | R7: =ROUND(P7*3%,0) + P7 -> 154224.02 | S7: =S6+0.01 -> 0.02
A8: 3º | B8: 1 | D8: =D7+1 -> 3 | E8: ASIST Y TRAB. | G8: 0.6115 | M8: 0 | N8: =P$2*G8% -> 149634.05 | O8: 0 | P8: =ROUND(SUM(K8:O8),0) + S8 -> 149634.03 | Q8: =ROUND(P8*6% + P8,0) + S8 -> 158612.03 | R8: =ROUND(P8*3%,0) + P8 -> 154123.03 | S8: =S7+0.01 -> 0.03
A9: 4º | B9: 2 | D9: =D8+1 -> 4 | E9: ASIST Y TRAB. | G9: 0.5033 | M9: 0 | N9: =P$2*G9% -> 123157.51 | O9: 0 | P9: =ROUND(SUM(K9:O9),0) + S9 -> 123158.04 | Q9: =ROUND(P9*6% + P9,0) + S9 -> 130548.04 | R9: =ROUND(P9*3%,0) + P9 -> 126853.04 | S9: =S8+0.01 -> 0.04
A10: 4º | B10: 3 | D10: =D9+1 -> 5 | E10: ASIST Y TRAB. | G10: 0.5033 | M10: 0 | N10: =P$2*G10% -> 123157.51 | O10: 0 | P10: =ROUND(SUM(K10:O10),0) + S10 -> 123158.05 | Q10: =ROUND(P10*6% + P10,0) + S10 -> 130548.05 | R10: =ROUND(P10*3%,0) + P10 -> 126853.05 | S10: =S9+0.01 -> 0.05
A11: 5º | B11: 4 | D11: =D10+1 -> 6 | E11: BENMAOR D. | F11: Cristian Requelme | G11: 0.7499 | M11: 0 | N11: =P$2*G11% -> 183500.53 | O11: 0 | P11: =ROUND(SUM(K11:O11),0) + S11 -> 183501.06 | Q11: =ROUND(P11*6% + P11,0) + S11 -> 194511.06 | R11: =ROUND(P11*3%,0) + P11 -> 189006.06 | S11: =S10+0.01 -> 0.06
A12: 5º | B12: 5 | D12: =D11+1 -> 7 | E12: GALANTERNIK A | F12: Miriam Larken | G12: 0.5425 | M12: 0 | N12: =P$2*G12% -> 132749.75 | O12: 0 | P12: =ROUND(SUM(K12:O12),0) + S12 -> 132750.07 | Q12: =ROUND(P12*6% + P12,0) + S12 -> 140715.07 | R12: =ROUND(P12*3%,0) + P12 -> 136733.07 | S12: =S11+0.01 -> 0.07
A13: 6º | B13: 6 | D13: =D12+1 -> 8 | E13: CANDEL JORGE ISAAC | G13: 0.4537 | M13: 0 | N13: =P$2*G13% -> 111020.39 | O13: 0 | P13: =ROUND(SUM(K13:O13),0) + S13 -> 111020.08 | Q13: =ROUND(P13*6% + P13,0) + S13 -> 117681.08 | R13: =ROUND(P13*3%,0) + P13 -> 114351.08 | S13: =S12+0.01 -> 0.08
A14: 6º | B14: 7 | D14: =D13+1 -> 9 | E14: BORTZ SERGIO | F14: Luciana | G14: 0.5244 | M14: 0 | N14: =P$2*G14% -> 128320.68 | O14: 0 | P14: =ROUND(SUM(K14:O14),0) + S14 -> 128321.09 | Q14: =ROUND(P14*6% + P14,0) + S14 -> 136020.09 | R14: =ROUND(P14*3%,0) + P14 -> 132171.09 | S14: =S13+0.01 -> 0.09 | U14: ESTA ES LA FUNDACION DE MEDICOS
A15: 7º | B15: 8 | D15: =D14+1 -> 10 | E15: BORTZ SERGIO | F15: Luciana | G15: 0.424 | M15: 0 | N15: =P$2*G15% -> 103752.8 | O15: 0 | P15: =ROUND(SUM(K15:O15),0) + S15 -> 103753.1 | Q15: =ROUND(P15*6% + P15,0) + S15 -> 109978.1 | R15: =ROUND(P15*3%,0) + P15 -> 106866.1 | S15: =S14+0.01 -> 0.1 | U15: ESTA ES LA FUNDACION DE MEDICOS
A16: 7º | B16: 1 | C16: A | D16: =D15+1 -> 11 | E16: KIM SOON LEO | G16: 2.3033 | M16: 0 | N16: =P$2*G16% -> 563617.51 | O16: 0 | P16: =ROUND(SUM(K16:O16),0) + S16 -> 563618.11 | Q16: =ROUND(P16*6% + P16,0) + S16 -> 597435.11 | R16: =ROUND(P16*3%,0) + P16 -> 580527.11 | S16: =S15+0.01 -> 0.11
A17: 8º | B17: 1 | C17: B | D17: =D16+1 -> 12 | E17: CANDEL MARCELO | F17: Florencia Fucci | G17: 2.7493 | M17: 0 | N17: =P$2*G17% -> 672753.71 | O17: 0 | P17: =ROUND(SUM(K17:O17),0) + S17 -> 672754.12 | Q17: =ROUND(P17*6% + P17,0) + S17 -> 713119.12 | R17: =ROUND(P17*3%,0) + P17 -> 692937.12 | S17: =S16+0.01 -> 0.12
A18: 8º | B18: 2 | C18: A | D18: =D17+1 -> 13 | E18: TRIPODI | F18: Mariela Pricolo | G18: 2.3033 | M18: 0 | N18: =P$2*G18% -> 563617.51 | O18: 0 | P18: =ROUND(SUM(K18:O18),0) + S18 -> 563618.13 | Q18: =ROUND(P18*6% + P18,0) + S18 -> 597435.13 | R18: =ROUND(P18*3%,0) + P18 -> 580527.13 | S18: =S17+0.01 -> 0.13
A19: 9º | B19: 2 | C19: B | D19: =D18+1 -> 14 | E19: MIRANDA DE GIL | F19: Susana | G19: 2.6368 | M19: 0 | N19: =P$2*G19% -> 645224.96 | O19: 0 | P19: =ROUND(SUM(K19:O19),0) + S19 -> 645225.14 | Q19: =ROUND(P19*6% + P19,0) + S19 -> 683939.14 | R19: =ROUND(P19*3%,0) + P19 -> 664582.14 | S19: =S18+0.01 -> 0.14 | U19: MAXIMO
A20: 9º | B20: 3 | C20: A | D20: =D19+1 -> 15 | E20: FRAGA DORA | G20: 2.3537 | M20: 0 | N20: =P$2*G20% -> 575950.39 | O20: 0 | P20: =ROUND(SUM(K20:O20),0) + S20 -> 575950.15 | Q20: =ROUND(P20*6% + P20,0) + S20 -> 610507.15 | R20: =ROUND(P20*3%,0) + P20 -> 593229.15 | S20: =S19+0.01 -> 0.15
A21: 10º | B21: 3 | C21: B | D21: =D20+1 -> 16 | E21: SARUBBI MARTIN | F21: Sarubbi Adriana | G21: 2.6477 | M21: 0 | N21: =P$2*G21% -> 647892.19 | O21: 0 | P21: =ROUND(SUM(K21:O21),0) + S21 -> 647892.16 | Q21: =ROUND(P21*6% + P21,0) + S21 -> 686766.16 | R21: =ROUND(P21*3%,0) + P21 -> 667329.16 | S21: =S20+0.01 -> 0.16
A22: 10º | B22: 4 | C22: A | D22: =D21+1 -> 17 | E22: LACENTRE | F22: Gabriela Tamara | G22: 2.3235 | M22: 0 | N22: =P$2*G22% -> 568560.45 | O22: 0 | P22: =ROUND(SUM(K22:O22),0) + S22 -> 568560.17 | Q22: =ROUND(P22*6% + P22,0) + S22 -> 602674.17 | R22: =ROUND(P22*3%,0) + P22 -> 585617.17 | S22: =S21+0.01 -> 0.17
A23: 11º | B23: 4 | C23: B | D23: =D22+1 -> 18 | E23: FERNANDEZ BERTA | F23: KRAVETZ | G23: 2.688 | M23: 0 | N23: =P$2*G23% -> 657753.6 | O23: 0 | P23: =ROUND(SUM(K23:O23),0) + S23 -> 657754.18 | Q23: =ROUND(P23*6% + P23,0) + S23 -> 697219.18 | R23: =ROUND(P23*3%,0) + P23 -> 677487.18 | S23: =S22+0.01 -> 0.18 | U23: KRAVETZ
A24: 11º | B24: 5 | C24: A | D24: =D23+1 -> 19 | E24: VERONES JOSE MARIA | G24: 2.36 | M24: 0 | N24: =P$2*G24% -> 577492 | O24: 0 | P24: =ROUND(SUM(K24:O24),0) + S24 -> 577492.19 | Q24: =ROUND(P24*6% + P24,0) + S24 -> 612142.19 | R24: =ROUND(P24*3%,0) + P24 -> 594817.19 | S24: =S23+0.01 -> 0.19
A25: 12º | B25: 5 | C25: B | D25: =D24+1 -> 20 | E25: SRUGO CARLOS | G25: 2.7183 | M25: 0 | N25: =P$2*G25% -> 665168.01 | O25: 0 | P25: =ROUND(SUM(K25:O25),0) + S25 -> 665168.2 | Q25: =ROUND(P25*6% + P25,0) + S25 -> 705078.2 | R25: =ROUND(P25*3%,0) + P25 -> 685123.2 | S25: =S24+0.01 -> 0.2
A26: 13º | B26: 6 | C26: A | D26: =D25+1 -> 21 | E26: DINOTO | G26: 2.3033 | M26: 0 | N26: =P$2*G26% -> 563617.51 | O26: 0 | P26: =ROUND(SUM(K26:O26),0) + S26 -> 563618.21 | Q26: =ROUND(P26*6% + P26,0) + S26 -> 597435.21 | R26: =ROUND(P26*3%,0) + P26 -> 580527.21 | S26: =S25+0.01 -> 0.21
A27: 14º | B27: 6 | C27: B | D27: =D26+1 -> 22 | E27: BORTZ ESTHER | F27: Daniel / Luciana | G27: 2.636 | M27: 0 | N27: =P$2*G27% -> 645029.2 | O27: 0 | P27: =ROUND(SUM(K27:O27),0) + S27 -> 645029.22 | Q27: =ROUND(P27*6% + P27,0) + S27 -> 683731.22 | R27: =ROUND(P27*3%,0) + P27 -> 664380.22 | S27: =S26+0.01 -> 0.22 | T27: Luciana | U27: ESTA ES LA FUNDACION DE MEDICOS
A28: 15º | B28: 7 | C28: A | D28: =D27+1 -> 23 | E28: COUSO MARIA CRISTINA | G28: 2.3033 | M28: 0 | N28: =P$2*G28% -> 563617.51 | O28: 0 | P28: =ROUND(SUM(K28:O28),0) + S28 -> 563618.23 | Q28: =ROUND(P28*6% + P28,0) + S28 -> 597435.23 | R28: =ROUND(P28*3%,0) + P28 -> 580527.23 | S28: =S27+0.01 -> 0.23
A29: COC | B29: 7 | C29: B | D29: =D28+1 -> 24 | E29: POSSENTI JUAN JOSE | G29: 2.6159 | M29: 0 | N29: =P$2*G29% -> 640110.73 | O29: 0 | P29: =ROUND(SUM(K29:O29),0) + S29 -> 640111.24 | Q29: =ROUND(P29*6% + P29,0) + S29 -> 678518.24 | R29: =ROUND(P29*3%,0) + P29 -> 659314.24 | S29: =S28+0.01 -> 0.24
A30: COC | B30: 8 | C30: A | D30: =D29+1 -> 25 | E30: VANNI KARINA | G30: 2.3537 | M30: 0 | N30: =P$2*G30% -> 575950.39 | O30: 0 | P30: =ROUND(SUM(K30:O30),0) + S30 -> 575950.25 | Q30: =ROUND(P30*6% + P30,0) + S30 -> 610507.25 | R30: =ROUND(P30*3%,0) + P30 -> 593229.25 | S30: =S29+0.01 -> 0.25
A31: COC | B31: 8 | C31: B | D31: =D30+1 -> 26 | E31: CARRIZO RAÚL | F31: Noelia Villarino | G31: 2.6469 | M31: 0 | N31: =P$2*G31% -> 647696.43 | O31: 0 | P31: =ROUND(SUM(K31:O31),0) + S31 -> 647696.26 | Q31: =ROUND(P31*6% + P31,0) + S31 -> 686558.26 | R31: =ROUND(P31*3%,0) + P31 -> 667127.26 | S31: =S30+0.01 -> 0.26
A32: COC | B32: 9 | C32: A | D32: =D31+1 -> 27 | E32: BLANCO | G32: 2.3537 | M32: 0 | N32: =P$2*G32% -> 575950.39 | O32: 0 | P32: =ROUND(SUM(K32:O32),0) + S32 -> 575950.27 | Q32: =ROUND(P32*6% + P32,0) + S32 -> 610507.27 | R32: =ROUND(P32*3%,0) + P32 -> 593229.27 | S32: =S31+0.01 -> 0.27
A33: COC | B33: 9 | C33: B | D33: =D32+1 -> 28 | E33: GALANTE CELIA | G33: 2.6663 | M33: 0 | N33: =P$2*G33% -> 652443.61 | O33: 0 | P33: =ROUND(SUM(K33:O33),0) + S33 -> 652444.28 | Q33: =ROUND(P33*6% + P33,0) + S33 -> 691591.28 | R33: =ROUND(P33*3%,0) + P33 -> 672017.28 | S33: =S32+0.01 -> 0.28
A34: COC | B34: 10 | C34: A | D34: =D33+1 -> 29 | E34: LEGUIZAMON PABLO | F34: Carla | G34: 2.4476 | M34: 0 | N34: =P$2*G34% -> 598927.72 | O34: 18500 | P34: =ROUND(SUM(K34:O34),0) + S34 -> 617428.29 | Q34: =ROUND(P34*6% + P34,0) + S34 -> 654474.29 | R34: =ROUND(P34*3%,0) + P34 -> 635951.29 | S34: =S33+0.01 -> 0.29
A35: COC | B35: 10 | C35: B | D35: =D34+1 -> 30 | E35: CANDEL E. MARCELO | G35: 2.7183 | M35: 0 | N35: =P$2*G35% -> 665168.01 | O35: 0 | P35: =ROUND(SUM(K35:O35),0) + S35 -> 665168.3 | Q35: =ROUND(P35*6% + P35,0) + S35 -> 705078.3 | R35: =ROUND(P35*3%,0) + P35 -> 685123.3 | S35: =S34+0.01 -> 0.3
A36: COC | B36: 11 | C36: A | D36: =D35+1 -> 31 | E36: DAVICCA MIGUEL | F36: Romina Navarro | G36: 2.3026 | M36: 0 | N36: =P$2*G36% -> 563446.22 | O36: 0 | P36: =ROUND(SUM(K36:O36),0) + S36 -> 563446.31 | Q36: =ROUND(P36*6% + P36,0) + S36 -> 597253.31 | R36: =ROUND(P36*3%,0) + P36 -> 580349.31 | S36: =S35+0.01 -> 0.31
A37: COC | B37: 11 | C37: B | D37: =D36+1 -> 32 | E37: GUTMAN MARIO | G37: 2.6562 | M37: 0 | N37: =P$2*G37% -> 649972.14 | O37: 0 | P37: =ROUND(SUM(K37:O37),0) + S37 -> 649972.32 | Q37: =ROUND(P37*6% + P37,0) + S37 -> 688971.32 | R37: =ROUND(P37*3%,0) + P37 -> 669471.32 | S37: =S36+0.01 -> 0.32
A38: COC | B38: 12 | C38: A | D38: =D37+1 -> 33 | E38: PRATOLONGO EDUARDO | G38: 2.3343 | M38: 0 | N38: =P$2*G38% -> 571203.21 | O38: 0 | P38: =ROUND(SUM(K38:O38),0) + S38 -> 571203.33 | Q38: =ROUND(P38*6% + P38,0) + S38 -> 605476.33 | R38: =ROUND(P38*3%,0) + P38 -> 588339.33 | S38: =S37+0.01 -> 0.33
A39: COC | B39: 12 | C39: B | D39: =D38+1 -> 34 | E39: CARTABBIA MARIO | G39: 2.6259 | M39: 0 | N39: =P$2*G39% -> 642557.73 | O39: 0 | P39: =ROUND(SUM(K39:O39),0) + S39 -> 642558.34 | Q39: =ROUND(P39*6% + P39,0) + S39 -> 681112.34 | R39: =ROUND(P39*3%,0) + P39 -> 661835.34 | S39: =S38+0.01 -> 0.34
A40: COC | B40: 1 | C40: C | D40: =D39+1 -> 35 | E40: NAVA HECTOR | F40: Marcos | G40: 1.007 | M40: 0 | N40: =P$2*G40% -> 246412.9 | O40: 0 | P40: =ROUND(SUM(K40:O40),0) + S40 -> 246413.35 | Q40: =ROUND(P40*6% + P40,0) + S40 -> 261198.35 | R40: =ROUND(P40*3%,0) + P40 -> 253805.35 | S40: =S39+0.01 -> 0.35
A41: COC | B41: 1 | C41: D | D41: =D40+1 -> 36 | E41: BRATTOLI | F41: Palermo Hernan | G41: 0.7812 | M41: 0 | N41: =P$2*G41% -> 191159.64 | O41: 0 | P41: =ROUND(SUM(K41:O41),0) + S41 -> 191160.36 | Q41: =ROUND(P41*6% + P41,0) + S41 -> 202630.36 | R41: =ROUND(P41*3%,0) + P41 -> 196895.36 | S41: =S40+0.01 -> 0.36 | U41: PALERMO
B42: 1 | C42: E | D42: =D41+1 -> 37 | E42: BRATTOLI | F42: Palermo Hernan | G42: 1.2153 | M42: 0 | N42: =P$2*G42% -> 297383.91 | O42: 0 | P42: =ROUND(SUM(K42:O42),0) + S42 -> 297384.37 | Q42: =ROUND(P42*6% + P42,0) + S42 -> 315227.37 | R42: =ROUND(P42*3%,0) + P42 -> 306306.37 | S42: =S41+0.01 -> 0.37 | U42: PALERMO
B43: 2 | C43: C | D43: =D42+1 -> 38 | E43: MARIA I. ROTTA | F43: Mabel Rodríguez | G43: 0.9549 | M43: 0 | N43: =P$2*G43% -> 233664.03 | O43: 0 | P43: =ROUND(SUM(K43:O43),0) + S43 -> 233664.38 | Q43: =ROUND(P43*6% + P43,0) + S43 -> 247684.38 | R43: =ROUND(P43*3%,0) + P43 -> 240674.38 | S43: =S42+0.01 -> 0.38
...
