Workbook

Sheet RESUMEN
B1: MAIL: salta1167rc@gmail.com
B2: CUIT ADMINISTRACION: 27231256879
B3: CONSORCIO DE PROPIETARIOS EDIFICIO CALLE SALTA 1167/1169 C DE P SALTA 1167 1169 LANUS CTA CTE $ 039 - 22273/6 CBU: 0720039720000002227368
A4: LIQUIDACION DE EXPENSAS | B4: ADMINISTRADORA: CAROLINA CANCIANI MP:1148
A5: CUIT DEL EDIFICIO: 30-719118061-9 | B5: PERÍODO: JUNIO | D5: HORARIOS DE ATENCION: LUNES A VIERNES
A6: CONSORCIO DE PROPIETARIOS DEL EDIFICIO CALLE SALTA 1167 | D6: 10 A 15HS - EMERGENCIAS 24HS
B8: VTO 17/07
A13: ESTIMADOS PROPIETARIOS E INQUILINOS: POR FAVOR LOS QUE ABONAN EN PRIMER VENCIMIENTO ABONEN EL MONTO DE PRIMER VENCIMIENTO, ASI AGILIZAN LA LIQUIDACION, RESPETEN LOS CENTAVOS CORRESPONDIENTES A LA UNIDAD FUNCIONAL. ES DE CARÁCTER OBLIGATORIO INFORMAR VIA MAIL LAS EXPENSAS. PORFAVOR RESPETAR LOS CENTAVOS AL ABONAR.
A20: GASTOS A - UNIDADES FUNCIONALES:
A21: LIMPIEZA
A22: Full Clean - Servicio de limpieza | D22: 510846.85 | E22: Transf 04/06
A23: Horas extra Sra. Carina | D23: 15000
A24: TOTAL | E24: =SUM(D22:D23) -> 525846.85
A25: SEGUROS
A26: Federacion patronal Seguro obligatorio de consorcio - Poliza nro. 1-2249124-0 | D26: 79864 | E26: Transf 08/06
A27: TOTAL IMPUESTO | E27: =SUM(D26:D26) -> 79864
A28: ABONOS Y SERVICIOS
A29: Edesur | D29: 0
A30: Metrogas | D30: 6403.1 | E30: =E31 -> Transf 02/06
A31: Metrogas | D31: 329815.06 | E31: Transf 02/06
A32: AySa | D32: 640644 | E32: Transf 16/06
A33: Servicio de interet Claro | D33: 26036.19 | E33: Transf 02/06
A34: TOTAL ABONOS Y SERVICIOS | E34: =SUM(D29:D33) -> 1002898.3
A36: Lema - Ascensores - Servicio de mantenimiento - Se abona a mes vencido | D36: 82000 | E36: Transf 05/06
A37: Cambio de caja de piso | D37: 150000 | E37: Transf 05/06
A38: Cambio de cierrapuerta de blindex | D38: 500000 | E38: Transf 05/06
A39: Easy Barracas - Compra de termotanque - Cuota 4 - Restan 2 cuotas de $157.988,29 | D39: 157988.29
A41: TOTAL | E41: =SUM(D36:D40) -> 889988.29
A42: HONORARIOS
A43: Honorario administracion - Mes de JUNIO | D43: 170000 | E43: Transf 30/06
A44: TOTAL | E44: =SUM(D43:D43) -> 170000
A45: GASTOS BANCARIOS
A46: Mantenimiento de cuenta | D46: 69000
A47: Comision cuenta dolares - Reclamo enviado - El banco evaluara una bonificacion | D47: 14770
A48: Gastos bancarios | D48: 56522.84
A49: TOTAL | E49: =SUM(D46:D48) -> 140292.84
A51: PREVISION GASTOS A
A53: TOTAL GASTOS A | E53: =(SUM(E21:E51)) -> 2808890.3
A56: GASTOS B:
E61: =SUM(D57:D60) -> 0
...

Sheet PRORRATEO
E2: Gastos B | G2: 0 | J2: Gastos A | K2: 2400000
A4: Estimados convivientes: Les solicitamos, por favor, que al momento de realizar el pago respeten los centavos que figuran en el monto indicado, ya que estos nos permiten identificar correctamente los pagos y las unidades funcionales, reduciendo así el margen de error. Muchas gracias por su colaboración.
A9: REITERAMOS QUE LOS DATOS DE LA CUENTA EN DONDE DEBEN ABONAR LAS EXPENSAS SON: CONSORCIO DE PROPIETARIOS EDIFICIO CALLE SALTA 1167/1169 - C DE P SALTA 1167 1169 LANUS - CTA CTE $ 039 - 22273/6 CBU: 0720039720000002227368
A10: QUIENES ESTAN EN VIOLETA NO ESTAN RESPETANDO LOS CENTAVOS AL ABONAR.
A11: UF | C11: Propietario | D11: Inquilinos | E11: (%) | F11: Saldo Ord | G11: Ingreso | H11: Deuda o Saldo a favor | I11: Interes 3% | J11: Gastos A | K11: Gastos B | L11: EDESUR | M11: SUM | N11: Total 1er Vto | O11: Total 2do Vto. | P11: Total 2do Vto
N12: =RESUMEN!B8 -> VTO 17/07
A13: 1 | B13: 1 A | C13: MIRAGLIA NORBERTO JOSE | E13: 12 | F13: 288000.01 | G13: =316800.01+396-G29-G30 -> 287999.66 | H13: =F13-G13 -> 0.35 | I13: =IF(H13>0,H13*3%,0) -> 0.0105 | J13: =K$2*E13/100 -> 288000 | K13: =G$2*E13/100 -> 0 | L13: =EDESUR!I5 -> 0 | N13: =ROUND(SUM(H13:M13),0) + Q13 -> 288000.01 | O13: =ROUND(N13*6% + N13,0) + Q13 -> 305280.01 | P13: =ROUND(N13*3%,0) + N13 -> 296640.01 | Q13: 0.01
A14: 2 | B14: 1 C | C14: ADAMO PABLO MARIANO | E14: 6.6 | F14: 189415.02 | G14: 190000 | H14: =F14-G14 -> -584.98 | I14: =IF(H14>0,H14*3%,0) -> 0 | J14: =K$2*E14/100 -> 158400 | K14: =G$2*E14/100 -> 0 | L14: =EDESUR!I6 -> 102901.79 | N14: =ROUND(SUM(H14:M14),0) + Q14 -> 260717.02 | O14: =ROUND(N14*6% + N14,0) + Q14 -> 276360.02 | P14: =ROUND(N14*3%,0) + N14 -> 268539.02 | Q14: =Q13+0.01 -> 0.02
A15: 3 | B15: 1 D | C15: REDONDO | D15: Gilmer | E15: 5.4 | F15: 135021.03 | G15: =F15 -> 135021.03 | H15: =F15-G15 -> 0 | I15: =IF(H15>0,H15*3%,0) -> 0 | J15: =K$2*E15/100 -> 129600 | K15: =G$2*E15/100 -> 0 | L15: =EDESUR!I7 -> 3655.79 | N15: =ROUND(SUM(H15:M15),0) + Q15 -> 133256.03 | O15: =ROUND(N15*6% + N15,0) + Q15 -> 141251.03 | P15: =ROUND(N15*3%,0) + N15 -> 137254.03 | Q15: =Q14+0.01 -> 0.03
A16: 4 | B16: 2 B | C16: CRUZ ADRIANA BEATRIZ | D16: Cristian Rodrigo Centurion | E16: 6.6 | F16: 158400.04 | G16: =178400.24-G32 -> 164000.04 | H16: =F16-G16 -> -5600 | I16: =IF(H16>0,H16*3%,0) -> 0 | J16: =K$2*E16/100 -> 158400 | K16: =G$2*E16/100 -> 0 | L16: =EDESUR!I9 -> 0 | N16: =ROUND(SUM(H16:M16),0) + Q16 -> 152800.04 | O16: =ROUND(N16*6% + N16,0) + Q16 -> 161968.04 | P16: =ROUND(N16*3%,0) + N16 -> 157384.04 | Q16: =Q15+0.01 -> 0.04
A17: 5 | B17: 2 C | C17: D AMURI JOSE LUIS | D17: Martina Belen Carbone | E17: 6.6 | F17: 158400.05 | G17: =F17 -> 158400.05 | H17: =F17-G17 -> 0 | I17: =IF(H17>0,H17*3%,0) -> 0 | J17: =K$2*E17/100 -> 158400 | K17: =G$2*E17/100 -> 0 | L17: =EDESUR!I10 -> 0 | M17: 0 | N17: =ROUND(SUM(H17:M17),0) + Q17 -> 158400.05 | O17: =ROUND(N17*6% + N17,0) + Q17 -> 167904.05 | P17: =ROUND(N17*3%,0) + N17 -> 163152.05 | Q17: =Q16+0.01 -> 0.05 | R17: Alejo Moreno
A18: 6 | B18: 2 D | C18: CAMPOLONGO LUIS | D18: Leandro Gonzalez | E18: 5.4 | F18: 129600.06 | G18: 118800 | H18: =F18-G18 -> 10800.06 | I18: =IF(H18>0,H18*3%,0) -> 324.0018 | J18: =K$2*E18/100 -> 129600 | K18: =G$2*E18/100 -> 0 | L18: =EDESUR!I11 -> 0 | N18: =ROUND(SUM(H18:M18),0) + Q18 -> 140724.06 | O18: =ROUND(N18*6% + N18,0) + Q18 -> 149168.06 | P18: =ROUND(N18*3%,0) + N18 -> 144946.06 | Q18: =Q17+0.01 -> 0.06
A19: 7 | B19: 2 A | C19: PEREZ FERNANDO ARIEL | D19: Gaston Miranda | E19: 5.4 | F19: 129600.07 | H19: =F19-G19 -> 129600.07 | I19: =IF(H19>0,H19*3%,0) -> 3888.0021 | J19: =K$2*E19/100 -> 129600 | K19: =G$2*E19/100 -> 0 | L19: =EDESUR!I12 -> 0 | N19: =ROUND(SUM(H19:M19),0) + Q19 -> 263088.07 | O19: =ROUND(N19*6% + N19,0) + Q19 -> 278873.07 | P19: =ROUND(N19*3%,0) + N19 -> 270981.07 | Q19: =Q18+0.01 -> 0.07
A20: 8 | B20: 3 B | C20: BURGOA CARINA | D20: Alan/Ailen | E20: 6.6 | F20: 225080.08 | G20: =F20 -> 225080.08 | H20: =F20-G20 -> 0 | I20: =IF(H20>0,H20*3%,0) -> 0 | J20: =K$2*E20/100 -> 158400 | K20: =G$2*E20/100 -> 0 | L20: =EDESUR!I13 -> 63231.57 | N20: =ROUND(SUM(H20:M20),0) + Q20 -> 221632.08 | O20: =ROUND(N20*6% + N20,0) + Q20 -> 234930.08 | P20: =ROUND(N20*3%,0) + N20 -> 228281.08 | Q20: =Q19+0.01 -> 0.08
A21: 9 | B21: 3 C | C21: GIL ROSANNA MABEL | D21: Gaston ibarra | E21: 6.6 | F21: 130013.09 | G21: =F21+28387 -> 158400.09 | H21: =F21-G21 -> -28387 | I21: =IF(H21>0,H21*3%,0) -> 0 | J21: =K$2*E21/100 -> 158400 | K21: =G$2*E21/100 -> 0 | L21: =EDESUR!I14 -> 0 | N21: =ROUND(SUM(H21:M21),0) + Q21 -> 130013.09 | O21: =ROUND(N21*6% + N21,0) + Q21 -> 137814.09 | P21: =ROUND(N21*3%,0) + N21 -> 133913.09 | Q21: =Q20+0.01 -> 0.09
A22: 10 | B22: 3 D | C22: FELIX ALBERTO | D22: Jhonatan | E22: 5.4 | F22: -0.9 | G22: =RESUMEN!D39-28387 -> 129601.29 | H22: =F22-G22 -> -129602.19 | I22: =IF(H22>0,H22*3%,0) -> 0 | J22: =K$2*E22/100 -> 129600 | K22: =G$2*E22/100 -> 0 | L22: =EDESUR!I15 -> 0 | N22: =ROUND(SUM(H22:M22),0) + Q22 -> -1.9 | O22: =ROUND(N22*6% + N22,0) + Q22 -> -1.9 | P22: =ROUND(N22*3%,0) + N22 -> -1.9 | Q22: =Q21+0.01 -> 0.1
A23: 11 | B23: 3 A | C23: CAMPANA WALTER CESAR | E23: 5.4 | F23: 129600.11 | G23: =136800-G34 -> 129599.78 | H23: =F23-G23 -> 0.33 | I23: =IF(H23>0,H23*3%,0) -> 0.0099 | J23: =K$2*E23/100 -> 129600 | K23: =G$2*E23/100 -> 0 | L23: =EDESUR!I12 -> 0 | N23: =ROUND(SUM(H23:M23),0) + Q23 -> 129600.11 | O23: =ROUND(N23*6% + N23,0) + Q23 -> 137376.11 | P23: =ROUND(N23*3%,0) + N23 -> 133488.11 | Q23: =Q22+0.01 -> 0.11 | R23: Antonella
A24: 12 | B24: 4 B | C24: PALMA JOSE AGUSTIN | D24: Juan Ignacio / Mariel Cruz | E24: 6.6 | F24: 158400.12 | G24: =F24 -> 158400.12 | H24: =F24-G24 -> 0 | I24: =IF(H24>0,H24*3%,0) -> 0 | J24: =K$2*E24/100 -> 158400 | K24: =G$2*E24/100 -> 0 | L24: =EDESUR!I17 -> 0 | N24: =ROUND(SUM(H24:M24),0) + Q24 -> 158400.12 | O24: =ROUND(N24*6% + N24,0) + Q24 -> 167904.12 | P24: =ROUND(N24*3%,0) + N24 -> 163152.12 | Q24: =Q23+0.01 -> 0.12
A25: 13 | B25: 4 C | C25: BENITEZ EMILIA ISABEL | D25: Daniel Leiva | E25: 6.6 | F25: 154044.13 | G25: 158665.13 | H25: =F25-G25 -> -4621 | I25: =IF(H25>0,H25*3%,0) -> 0 | J25: =K$2*E25/100 -> 158400 | K25: =G$2*E25/100 -> 0 | L25: =EDESUR!I18 -> 0 | N25: =ROUND(SUM(H25:M25),0) + Q25 -> 153779.13 | O25: =ROUND(N25*6% + N25,0) + Q25 -> 163006.13 | P25: =ROUND(N25*3%,0) + N25 -> 158392.13 | Q25: =Q24+0.01 -> 0.13
A26: 14 | B26: 4 D | C26: PUCHETA SANTIAGO / CLARA | E26: 5.4 | F26: 129600.14 | G26: =F26 -> 129600.14 | H26: =F26-G26 -> 0 | I26: =IF(H26>0,H26*3%,0) -> 0 | J26: =K$2*E26/100 -> 129600 | K26: =G$2*E26/100 -> 0 | L26: =EDESUR!I19 -> 0 | N26: =ROUND(SUM(H26:M26),0) + Q26 -> 129600.14 | O26: =ROUND(N26*6% + N26,0) + Q26 -> 137376.14 | P26: =ROUND(N26*3%,0) + N26 -> 133488.14 | Q26: =Q25+0.01 -> 0.14
A27: 15 | B27: 4 A | C27: CAMPANA MIRIAM NOEMI | E27: 5.4 | F27: 129600.15 | G27: =F27 -> 129600.15 | H27: =F27-G27 -> 0 | I27: =IF(H27>0,H27*3%,0) -> 0 | J27: =K$2*E27/100 -> 129600 | K27: =G$2*E27/100 -> 0 | L27: =EDESUR!I16 -> 0 | N27: =ROUND(SUM(H27:M27),0) + Q27 -> 129600.15 | O27: =ROUND(N27*6% + N27,0) + Q27 -> 137376.15 | P27: =ROUND(N27*3%,0) + N27 -> 133488.15 | Q27: =Q26+0.01 -> 0.15
A28: 16 | B28: COC 1 | C28: CAMPOLONGO LUIS | D28: Leandro Gonzalez | E28: 0.7 | F28: 16800.16 | G28: 15400 | H28: =F28-G28 -> 1400.16 | I28: =IF(H28>0,H28*3%,0) -> 42.0048 | J28: =K$2*E28/100 -> 16800 | K28: =G$2*E28/100 -> 0 | L28: =EDESUR!I22 -> 266.88 | N28: =ROUND(SUM(H28:M28),0) + Q28 -> 18509.16 | O28: =ROUND(N28*6% + N28,0) + Q28 -> 19620.16 | P28: =ROUND(N28*3%,0) + N28 -> 19064.16 | Q28: =Q27+0.01 -> 0.16
A29: 17 | B29: COC 2 | C29: MIRAGLIA NORBERTO JOSE | E29: 0.6 | F29: 1200.17 | G29: =F29 -> 1200.17 | H29: =F29-G29 -> 0 | I29: =IF(H29>0,H29*3%,0) -> 0 | J29: =K$2*E29/100 -> 14400 | K29: =G$2*E29/100 -> 0 | L29: =EDESUR!I23 -> 228.75 | N29: =ROUND(SUM(H29:M29),0) + Q29 -> 14629.17 | O29: =ROUND(N29*6% + N29,0) + Q29 -> 15507.17 | P29: =ROUND(N29*3%,0) + N29 -> 15068.17 | Q29: =Q28+0.01 -> 0.17
A30: 18 | B30: COC 3 | C30: MIRAGLIA NORBERTO JOSE | E30: 0.6 | F30: 27996.18 | G30: =F30 -> 27996.18 | H30: =F30-G30 -> 0 | I30: =IF(H30>0,H30*3%,0) -> 0 | J30: =K$2*E30/100 -> 14400 | K30: =G$2*E30/100 -> 0 | L30: =EDESUR!I24 -> 228.75 | N30: =ROUND(SUM(H30:M30),0) + Q30 -> 14629.18 | O30: =ROUND(N30*6% + N30,0) + Q30 -> 15507.18 | P30: =ROUND(N30*3%,0) + N30 -> 15068.18 | Q30: =Q29+0.01 -> 0.18
A31: 19 | B31: COC 4 | C31: PALMA JOSE AGUSTIN | E31: 0.6 | F31: 14400.19 | G31: =F31 -> 14400.19 | H31: =F31-G31 -> 0 | I31: =IF(H31>0,H31*3%,0) -> 0 | J31: =K$2*E31/100 -> 14400 | K31: =G$2*E31/100 -> 0 | L31: =EDESUR!I25 -> 228.75 | N31: =ROUND(SUM(H31:M31),0) + Q31 -> 14629.19 | P31: =ROUND(N31*3%,0) + N31 -> 15068.19 | Q31: =Q30+0.01 -> 0.19
A32: 20 | B32: COC 5 | C32: CRUZ ADRIANA BEATRIZ | D32: Cristian Rodrigo Centurion | E32: 0.6 | F32: 14400.2 | G32: =F32 -> 14400.2 | H32: =F32-G32 -> 0 | I32: =IF(H32>0,H32*3%,0) -> 0 | J32: =K$2*E32/100 -> 14400 | K32: =G$2*E32/100 -> 0 | L32: =EDESUR!I26 -> 228.75 | N32: =ROUND(SUM(H32:M32),0) + Q32 -> 14629.2 | P32: =ROUND(N32*3%,0) + N32 -> 15068.2 | Q32: =Q31+0.01 -> 0.2
A33: 21 | B33: COC 6 | C33: FELIX ALBERTO | D33: Jhonatan | E33: 0.3 | F33: 7002.21 | G33: =F33 -> 7002.21 | H33: =F33-G33 -> 0 | I33: =IF(H33>0,H33*3%,0) -> 0 | J33: =K$2*E33/100 -> 7200 | K33: =G$2*E33/100 -> 0 | L33: =EDESUR!I27 -> 114.38 | N33: =ROUND(SUM(H33:M33),0) + Q33 -> 7314.21 | P33: =ROUND(N33*3%,0) + N33 -> 7533.21 | Q33: =Q32+0.01 -> 0.21
A34: 22 | B34: COC 7 | C34: CAMPANA WALTER CESAR | E34: 0.3 | F34: 7200.22 | G34: =F34 -> 7200.22 | H34: =F34-G34 -> 0 | I34: =IF(H34>0,H34*3%,0) -> 0 | J34: =K$2*E34/100 -> 7200 | K34: =G$2*E34/100 -> 0 | L34: =EDESUR!I28 -> 114.38 | N34: =ROUND(SUM(H34:M34),0) + Q34 -> 7314.22 | P34: =ROUND(N34*3%,0) + N34 -> 7533.22 | Q34: =Q33+0.01 -> 0.22
A35: 23 | B35: COC 8 | C35: REDONDO HECTOR | D35: Gilmer | E35: 0.3 | F35: 7200.23 | G35: =F35 -> 7200.23 | H35: =F35-G35 -> 0 | I35: =IF(H35>0,H35*3%,0) -> 0 | J35: =K$2*E35/100 -> 7200 | K35: =G$2*E35/100 -> 0 | L35: =EDESUR!I29 -> 114.38 | N35: =ROUND(SUM(H35:M35),0) + Q35 -> 7314.23 | P35: =ROUND(N35*3%,0) + N35 -> 7533.23 | Q35: =Q34+0.01 -> 0.23
E36: =SUM(E13:E35) -> 100 | F36: =SUM(F13:F35) -> 2340972.8 | G36: =SUM(G13:G35) -> 2367967 | H36: =SUM(H13:H35) -> -26994.2 | I36: =SUM(I13:I35) -> 4254.0291 | J36: =SUM(J13:J35) -> 2400000 | K36: =SUM(K13:K35) -> 0 | L36: =SUM(L13:L35) -> 171314.17 | N36: =SUM(N13:N35) -> 2548576.8 | O36: =SUM(O13:O35) -> 2647219.7 | P36: =SUM(P13:P35) -> 2625033.8
C39: =RESUMEN!A13 -> ESTIMADOS PROPIETARIOS E INQUILINOS: POR FAVOR LOS QUE ABONAN EN PRIMER VENCIMIENTO ABONEN EL MONTO DE PRIMER VENCIMIENTO, ASI AGILIZAN LA LIQUIDACION, RESPETEN LOS CENTAVOS CORRESPONDIENTES A LA UNIDAD FUNCIONAL. ES DE CARÁCTER OBLIGATORIO INFORMAR VIA MAIL LAS EXPENSAS. PORFAVOR RESPETAR LOS CENTAVOS AL ABONAR.

Sheet EDESUR
B3: Piso | C3: Depto | E3: Total Edesur x Depto | G3: Bonificado x EDESUR | I3: SALDO a PAGAR
B5: 1 | C5: A | E5: 8123.99 | G5: =E5 -> 8123.99 | I5: =E5-G5 -> 0
B6: 1 | C6: C | E6: 102901.79 | G6: 0 | I6: =E6-G6 -> 102901.79
B7: 1 | C7: D | E7: 3655.79 | G7: 0 | I7: =E7-G7 -> 3655.79
B8: 2 | C8: A | E8: 3655.79 | G8: =E8 -> 3655.79 | I8: =E8-G8 -> 0
B9: 2 | C9: B | E9: 4468.19 | G9: =E9 -> 4468.19 | I9: =E9-G9 -> 0
B10: 2 | C10: C | E10: 4468.19 | G10: =E10 -> 4468.19 | I10: =E10-G10 -> 0
B11: 2 | C11: D | E11: 3655.79 | G11: =E11 -> 3655.79 | I11: =E11-G11 -> 0
B12: 3 | C12: A | E12: 3655.79 | G12: =E12 -> 3655.79 | I12: =E12-G12 -> 0
B13: 3 | C13: B | E13: 63231.57 | G13: 0 | I13: =E13-G13 -> 63231.57
B14: 3 | C14: C | E14: =E10 -> 4468.19 | G14: =E14 -> 4468.19 | I14: =E14-G14 -> 0
B15: 3 | C15: D | E15: =E12 -> 3655.79 | G15: =E15 -> 3655.79 | I15: =E15-G15 -> 0
B16: 4 | C16: A | E16: =E15 -> 3655.79 | G16: =E16 -> 3655.79 | I16: =E16-G16 -> 0
B17: 4 | C17: B | E17: =E14 -> 4468.19 | G17: =E17 -> 4468.19 | I17: =E17-G17 -> 0
B18: 4 | C18: C | E18: =E17 -> 4468.19 | G18: =E18 -> 4468.19 | I18: =E18-G18 -> 0
B19: 4 | C19: D | E19: =E16 -> 3655.79 | G19: =E19 -> 3655.79 | I19: =E19-G19 -> 0
B21: Totales | E21: =SUM(E5:E20) -> 222188.83 | G21: =SUM(G5:G20) -> 52399.68 | I21: =E21-G21 -> 169789.15
B22: Cochera | C22: 1 | E22: 473.9 | G22: 207.02 | I22: =E22-G22 -> 266.88
B23: Cochera | C23: 2 | E23: 406.2 | G23: 177.45 | I23: =E23-G23 -> 228.75
B24: Cochera | C24: 3 | E24: =E23 -> 406.2 | G24: 177.45 | I24: =E24-G24 -> 228.75
B25: Cochera | C25: 4 | E25: =E24 -> 406.2 | G25: 177.45 | I25: =E25-G25 -> 228.75
B26: Cochera | C26: 5 | E26: =E25 -> 406.2 | G26: 177.45 | I26: =E26-G26 -> 228.75
B27: Cochera | C27: 6 | E27: 203.1 | G27: 88.72 | I27: =E27-G27 -> 114.38
B28: Cochera | C28: 7 | E28: =E27 -> 203.1 | G28: 88.72 | I28: =E28-G28 -> 114.38
B29: Cochera | C29: 8 | E29: =E28 -> 203.1 | G29: 88.72 | I29: =E29-G29 -> 114.38
B30: Totales | E30: =SUM(E22:E29) -> 2708 | G30: =SUM(G22:G29) -> 1182.98 | I30: =E30-G30 -> 1525.02
I31: =E31-G31 -> 0
E33: =E30+E21 -> 224896.83 | G33: =G21+G30 -> 53582.66 | I33: =E33-G33 -> 171314.17

Sheet Anotaciones
