Workbook

Sheet RESUMEN
B1: Domicilio: Dr. Melo Nº 2958 - 8VO PISO - Con cita previa
B2: consorciobelgrano1640@gmail.com
B3: Santander cuenta 039-010552/1
B4: CBU: 0720039720000001055218
A5: LIQUIDACION DE EXPENSAS | B5: PERÍODO: ENERO | C5: VTO. 13/02
A6: CUIT: 33-71826987-9
A7: CONSORCIO DE PROPIETARIOS DEL EDIFICIO CALLE BELGRANO NUMERO 1640/1646 BANFIELD PARTIDO DE LOMAS DE ZAMORA
B14: Los gastos que se encuentras subrayados son los que corresponden tanto a las unidades funcionales como tambien al local
A21: GASTOS ORDINARIOS UNIDADES FUNCIONALES: | E21: UF 91,91% | F21: LOCAL 8,09%
A22: Sr. Diego Britez (1) | B22: Honorarios ENERO
A23: Haberes | D23: 1014647 | E23: =D23*91.91% -> 932562.02 | F23: =D23*8.09% -> 82084.939
A24: Deducciones | D24: -220685.72 | E24: =D24*91.91% -> -202832.25 | F24: =D24*8.09% -> -17853.475
A25: Redondeo | D25: 0.76 | E25: =D25*91.91% -> 0.698516 | F25: =D25*8.09% -> 0.061484
A30: TOTAL SUELDO | D30: =SUM(D23:D29) -> 793962 | E30: =SUM(E23:E29) -> 729730.47 | F30: =SUM(F23:F29) -> 64231.526 | G30: =E30+F30 -> 793962 | H30: =IF(D30=G30, "", "Error")
A31: SAC | D31: 0 | E31: =D31*91.91% -> 0 | F31: =D31*8.09% -> 0
D32: 0 | E32: =D32*91.91% -> 0 | F32: =D32*8.09% -> 0
A35: TOTAL | D35: =SUM(D31:D33) -> 0 | E35: =SUM(E31:E33) -> 0 | F35: =SUM(F31:F33) -> 0 | G35: =E35+F35 -> 0 | H35: =IF(D35=G35, "", "Error")
A36: SAC | E36: =D36*91.91% -> 0 | F36: =D36*8.09% -> 0
A37: Redondeo | E37: =D37*91.91% -> 0 | F37: =D37*8.09% -> 0
A38: Deducciones | E38: =D38*91.91% -> 0 | F38: =D38*8.09% -> 0
A39: TOTAL SAC | D39: =SUM(D32:D38) -> 0 | E39: =SUM(E32:E38) -> 0 | F39: =E39*8.09% -> 0
A43: TOTAL | E43: =SUM(D40:D42) -> 0 | F43: =(D40)*8.09% -> 0
A45: Piletero Sr Dario - puesta a punto y mantenimiento de pileta | D45: 80000 | E45: =D45 -> 80000
E46: =D46*91.91% -> 0 | F46: =D46*8.09% -> 0
A47: TOTAL REEMPLAZO | D47: =SUM(D45:D46) -> 80000 | E47: =SUM(E45:E46) -> 80000 | F47: =SUM(F45:F46) -> 0 | G47: =E47+F47 -> 80000
A50: APORTES Y CONTRIBUCIONES
A51: SEGURO OBLIGATORIO SR DIEGO BRITEZ FEDERACION PATRONAL DEBITO AUTOMATICO | D51: 5020 | E51: =D51*91.91% -> 4613.882 | F51: =D51*8.09% -> 406.118
A52: SUTERH - FATERYH - SARACAH | B52: Debito 13/01 | D52: =115174.45+7879.26+70913.38 -> 193967.09 | E52: =D52*91.91% -> 178275.15 | F52: =D52*8.09% -> 15691.938
A53: A.F.I.P. | B53: Pago mis cuentas 9/1 | D53: 771433.26 | E53: =D53*91.91% -> 709024.31 | F53: =D53*8.09% -> 62408.951
A54: TOTAL Aportes y Contribuciones - Sindicato | D54: =SUM(D51:D53) -> 970420.35 | E54: =SUM(E51:E53) -> 891913.34 | F54: =SUM(F51:F53) -> 78507.006 | G54: =E54+F54 -> 970420.35 | H54: =IF(D54=G54, "", "Error")
A55: ABONOS Y SERVICIOS
A56: ADS Ascensores del Sur S.A. | B56: DIFERENCIA DE LAS FACTURAS DESCONTANDO EL ARREGLO PERSIANA | D56: 103312 | E56: =D56 -> 103312 | G56: =D56 -> 103312 | H56: =E56+F56 -> 103312 | I56: =IF(G56=H56, "", "Error")
A57: Uniforme encargados - Zapatos - pantalon - Remera | D57: 100130 | E57: =D57*91.91% -> 92029.483 | F57: =D57*8.09% -> 8100.517 | G57: =D57 -> 100130 | H57: =E57+F57 -> 100130 | I57: =IF(G57=H57, "", "Error")
A58: Casa Ruan - Compra reloj digital | D58: 20000 | E58: =D58 -> 20000 | G58: =D58 -> 20000 | H58: =E58+F58 -> 20000
A59: Casa Ruan - Compra de termicas (6) | D59: 111420 | E59: =D59 -> 111420 | G59: =D59 -> 111420 | H59: =E59+F59 -> 111420
A60: Casa Ruan - Compra de 4 TERMICAS | D60: 74280 | E60: =D60 -> 74280 | G60: =D60 -> 74280 | H60: =E60+F60 -> 74280
A61: Servicio Fumigacion | D61: 59500 | E61: =D61 -> 59500 | G61: =D61 -> 59500 | H61: =E61+F61 -> 59500 | I61: =IF(G61=H61, "", "Error")
E62: =D62*91.91% -> 0 | F62: =D62*8.09% -> 0 | G62: =D62 -> 0 | H62: =E62+F62 -> 0 | I62: =IF(G62=H62, "", "Error")
A63: Riesgo Uno | B63: Abono bimestral | D63: 120322.09 | E63: =D63*91.91% -> 110588.03 | F63: =D63*8.09% -> 9734.0571 | G63: =D63 -> 120322.09 | H63: =E63+F63 -> 120322.09 | I63: =IF(G63=H63, "", "Error")
A64: Kromacolor - Compra de recuplas para terraza (2), vendas sinteplas 1x25 (2) | C64: 45685 | D64: 297680.3 | E64: =D64*91.91% -> 273597.96 | F64: =D64*8.09% -> 24082.336 | G64: =D64 -> 297680.3 | H64: =E64+F64 -> 297680.3 | I64: =IF(G64=H64, "", "Error")
...

Sheet PRORRATEO
F1: ESTADO DE CUENTA Y PRORRATEO | K1: SE GASTO: | L1: =RESUMEN!D112 -> 6949271.6 | O1: =L1*8.09% -> 562196.08
K2: SE PRORRATEA EN LAS UF: | M2: =L1+O2+6643*2-1439-128+3800+240+20-200-2+180+15-3617.5-290-29+390+35 -> 7092199.1 | O2: =O1-K7-553-50-86-8 -> 130666.96
A3: =RESUMEN!C5 -> VTO. 13/02 | K3: EXPENSAS EXTRA: | M3: 747146.4
J4: =(J3*8.09%)/44 -> 0 | K4: SE PRORRATEA EN LAS UF: | M4: =747146+80000-13000-1182-59+5 -> 812910
A5: Piso | B5: Dpto. | C5: UF | D5: Propietario | E5: (%) | F5: Saldo | G5: Ingreso | H5: SALDO | I5: Fecha | J5: Expensas extraor. | K5: Expensas ord | L5: SUM/ GASTOS PART | M5: TOTAL EXPENSAS 1er VTO | N5: TOTAL EXPENSAS 2do VTO
A7: PB | C7: 1 | D7: LOCAL 1 - DANIEL VIDAL | E7: 8.09 | F7: 408464.07 | G7: =F7 -> 408464.07 | H7: =F7-G7 -> 0 | I7: 10 | J7: 60444.144 | K7: 430832.11 | L7: 0 | M7: =K7+J7+H7+L7 -> 491276.26 | N7: =M7*6% + M7 -> 520752.83
A8: 3º | C8: 24 | D8: RODRIGUEZ, MARIA ROSA | E8: 2.21 | F8: 135635.43 | G8: 140000 | H8: =F8-G8 -> -4364.569 | I8: 10 | J8: =M$4*E8% -> 17965.311 | K8: =M$2*E8 /100 -> 156737.6 | L8: =J$3*E8%+J$4 -> 0 | M8: =K8+J8+H8+L8 -> 170338.34 | N8: =M8*6% + M8 -> 180558.64
A9: 3º | C9: 25 | D9: RUSSO, JUAN ANTONIO | E9: 4.21 | F9: 259094.8 | G9: =292328-G34 -> 259094.95 | H9: =F9-G9 -> -0.14941938 | I9: 6 | J9: =M$4*E9% -> 34223.511 | K9: =M$2*E9 /100 -> 298581.58 | L9: =J$3*E9%+J$4 -> 0 | M9: =K9+J9+H9+L9 -> 332804.94 | N9: =M9*6% + M9 -> 352773.24
A10: 4º | C10: 26 | D10: SALLABER, MARIA | E10: 2.84 | F10: 174781.25 | G10: =F10 -> 174781.25 | H10: =F10-G10 -> 0 | I10: 14 | J10: =M$4*E10% -> 23086.644 | K10: =M$2*E10 /100 -> 201418.45 | L10: =J$3*E10%+J$4 -> 0 | M10: =K10+J10+H10+L10 -> 224505.1 | N10: =M10*6% + M10 -> 237975.4
A11: 4º | C11: 27 | D11: COLATRELLA, CAROLINA | E11: 3.43 | F11: 211091.44 | G11: =F11 -> 211091.44 | H11: =F11-G11 -> 0 | I11: 3 | J11: =M$4*E11% -> 27882.813 | K11: =M$2*E11 /100 -> 243262.43 | L11: =J$3*E11%+J$4 -> 0 | M11: =K11+J11+H11+L11 -> 271145.24 | N11: =M11*6% + M11 -> 287413.96
A12: 5º | C12: 28 | D12: LUSENSKY, CARLOS | E12: 2.84 | F12: 174781.25 | G12: =F12 -> 174781.25 | H12: =F12-G12 -> 0 | I12: 3 | J12: =M$4*E12% -> 23086.644 | K12: =M$2*E12 /100 -> 201418.45 | L12: =J$3*E12%+J$4 -> 0 | M12: =K12+J12+H12+L12 -> 224505.1 | N12: =M12*6% + M12 -> 237975.4
A13: 5º | C13: 29 | D13: DI TORO, ALEJANDRO | E13: 3.43 | F13: 211090.88 | G13: =247400-G50 -> 211089.81 | H13: =F13-G13 -> 1.0717995 | I13: 6 | J13: =M$4*E13% -> 27882.813 | K13: =M$2*E13 /100 -> 243262.43 | L13: =J$3*E13%+J$4 -> 0 | M13: =K13+J13+H13+L13 -> 271146.31 | N13: =M13*6% + M13 -> 287415.09
A14: 6º | C14: 30 | D14: PERAZA, MARTHA | E14: 2.84 | F14: 184781.25 | G14: =F14 -> 184781.25 | H14: =F14-G14 -> 0 | I14: 14 | J14: =M$4*E14% -> 23086.644 | K14: =M$2*E14 /100 -> 201418.45 | L14: =J$3*E14%+J$4 -> 0 | M14: =K14+J14+H14+L14 -> 224505.1 | N14: =M14*6% + M14 -> 237975.4
A15: 6º | C15: 31 | D15: MARANTE, MAURO | E15: 3.43 | F15: 211091.99 | G15: =241863-G35 -> 211091.65 | H15: =F15-G15 -> 0.33719656 | I15: 9 | J15: =M$4*E15% -> 27882.813 | K15: =M$2*E15 /100 -> 243262.43 | L15: =J$3*E15%+J$4 -> 0 | M15: =K15+J15+H15+L15 -> 271145.58 | N15: =M15*6% + M15 -> 287414.31
A16: 7º | C16: 32 | D16: RUIZ, DIEGO | E16: 2.84 | F16: 543403.54 | G16: =90780+F16-G49 -> 543403.54 | H16: =F16-G16 -> 0 | I16: 3 | J16: =M$4*E16% -> 23086.644 | K16: =M$2*E16 /100 -> 201418.45 | L16: =J$3*E16%+J$4 -> 0 | M16: =K16+J16+H16+L16 -> 224505.1 | N16: =M16*6% + M16 -> 237975.4
A17: 7º | C17: 33 | D17: CAMPANA, NESTOR | E17: 3.43 | F17: 230592.26 | G17: =282019+9501-G47-G48 -> 230592.73 | H17: =F17-G17 -> -0.47168835 | I17: 10 | J17: =M$4*E17% -> 27882.813 | K17: =M$2*E17 /100 -> 243262.43 | L17: 10000 | M17: =K17+J17+H17+L17 -> 281144.77 | N17: =M17*6% + M17 -> 298013.46
A18: 8º | C18: 34 | D18: JARA, CLAUDIO | E18: 2.84 | F18: 170157.06 | G18: =205236-G51 -> 170156.67 | H18: =F18-G18 -> 0.39005285 | I18: 14 | J18: =M$4*E18% -> 23086.644 | K18: =M$2*E18 /100 -> 201418.45 | L18: =J$3*E18%+J$4 -> 0 | M18: =K18+J18+H18+L18 -> 224505.49 | N18: =M18*6% + M18 -> 237975.82
A19: 8º | C19: 35 | D19: MIRAMONTES, HORACIO | E19: 3.43 | F19: 221091.31 | G19: =254324-G41 -> 221090.95 | H19: =F19-G19 -> 0.36352654 | I19: 2 | J19: =M$4*E19% -> 27882.813 | K19: =M$2*E19 /100 -> 243262.43 | L19: =J$3*E19%+J$4 -> 0 | M19: =K19+J19+H19+L19 -> 271145.61 | N19: =M19*6% + M19 -> 287414.34
A20: 9º | C20: 36 | D20: MELINA, ANDRES | E20: 2.84 | F20: 174781.63 | G20: =204938-G38 -> 174782.08 | H20: =F20-G20 -> -0.45469359 | I20: 2 | J20: =M$4*E20% -> 23086.644 | K20: =M$2*E20 /100 -> 201418.45 | L20: =J$3*E20%+J$4 -> 0 | M20: =K20+J20+H20+L20 -> 224504.64 | N20: =M20*6% + M20 -> 237974.92
A21: 9º | C21: 37 | D21: GARCIA, MARIA SOL | E21: 3.43 | F21: 211091.71 | G21: =244325-G45 -> 211091.95 | H21: =F21-G21 -> -0.23414683 | I21: 2 | J21: =M$4*E21% -> 27882.813 | K21: =M$2*E21 /100 -> 243262.43 | L21: =J$3*E21%+J$4 -> 0 | M21: =K21+J21+H21+L21 -> 271145.01 | N21: =M21*6% + M21 -> 287413.71
A22: 10º | C22: 38 | D22: RATON, MARIELA | E22: 2.84 | F22: 174781.25 | G22: =F22 -> 174781.25 | H22: =F22-G22 -> 0 | I22: 6 | J22: =M$4*E22% -> 23086.644 | K22: =M$2*E22 /100 -> 201418.45 | L22: =J$3*E22%+J$4 -> 0 | M22: =K22+J22+H22+L22 -> 224505.1 | N22: =M22*6% + M22 -> 237975.4
A23: 10º | C23: 39 | D23: DAVIN, ALEJANDRO | E23: 3.43 | F23: 229499.45 | G23: =259615-G46 -> 228843.65 | H23: =F23-G23 -> 655.79691 | I23: 13 | J23: =M$4*E23% -> 27882.813 | K23: =M$2*E23 /100 -> 243262.43 | L23: =J$3*E23%+J$4 -> 0 | M23: =K23+J23+H23+L23 -> 271801.04 | N23: =M23*6% + M23 -> 288109.1
A24: 11º | C24: 40 | D24: VROONLAND, DANIEL | E24: 2.84 | F24: 193982.34 | G24: =225000-G37 -> 194844.08 | H24: =F24-G24 -> -861.73713 | I24: 6 | J24: =M$4*E24% -> 23086.644 | K24: =M$2*E24 /100 -> 201418.45 | L24: =J$3*E24%+J$4 -> 0 | M24: =K24+J24+H24+L24 -> 223643.36 | N24: =M24*6% + M24 -> 237061.96
A25: 11º | C25: 41 | D25: SIMONASSI, ALEJO | E25: 3.43 | F25: 211091.44 | G25: =F25 -> 211091.44 | H25: =F25-G25 -> 0 | I25: 9 | J25: =M$4*E25% -> 27882.813 | K25: =M$2*E25 /100 -> 243262.43 | L25: =J$3*E25%+J$4 -> 0 | M25: =K25+J25+H25+L25 -> 271145.24 | N25: =M25*6% + M25 -> 287413.96
A26: 12º | C26: 42 | D26: VELAZ, ATILIO | E26: 6 | F26: 342990.31 | G26: =450000+500000-G30-G31-G36 -> 852147.12 | H26: =F26-G26 -> -509156.81 | I26: 2 | J26: =M$4*E26% -> 48774.6 | K26: =M$2*E26 /100 -> 425531.95 | L26: 0 | M26: =K26+J26+H26+L26 -> -34850.266 | N26: =M26*6% + M26 -> -36941.282
A27: 13º | C27: 43 | D27: AGÜERO, MIRIAM S | E27: 5.89 | F27: 362487.48 | G27: =433876-G39-G40 -> 362486.48 | H27: =F27-G27 -> 1.0021014 | I27: 10 | J27: =M$4*E27% -> 47880.399 | K27: =M$2*E27 /100 -> 417730.53 | L27: =J$3*E27%+J$4 -> 0 | M27: =K27+J27+H27+L27 -> 465611.93 | N27: =M27*6% + M27 -> 493548.64
A28: 14º | C28: 44 | D28: VILLA, JUAN MANUEL | E28: 5.89 | F28: 362411.82 | G28: =206615+221032.66+RESUMEN!D92-G32-G33 -> 506551.29 | H28: =F28-G28 -> -144139.47 | I28: 4 | J28: =M$4*E28% -> 47880.399 | K28: =M$2*E28 /100 -> 417730.53 | L28: =J$3*E28%+J$4 -> 0 | M28: =K28+J28+H28+L28 -> 321471.46 | N28: =M28*6% + M28 -> 340759.75
A29: 15º | C29: 45 | D29: TOLOSA, FABIO | E29: 5.89 | F29: 342104.96 | G29: =468000-G42-G43-G44 -> 368916.26 | H29: =F29-G29 -> -26811.301 | I29: 3 | J29: =M$4*E29% -> 47880.399 | K29: =M$2*E29 /100 -> 417730.53 | L29: 0 | M29: =K29+J29+H29+L29 -> 438799.63 | N29: =M29*6% + M29 -> 465127.6
A30: COC | C30: 1 | D30: VELAZ, ATILIO | E30: 0.54 | F30: 33233.054 | G30: =F30 -> 33233.054 | H30: =F30-G30 -> 0 | J30: =M$4*E30% -> 4389.714 | K30: =M$2*E30 /100 -> 38297.875 | L30: =J$3*E30%+J$4 -> 0 | M30: =K30+J30+H30+L30 -> 42687.589 | N30: =M30*6% + M30 -> 45248.845
A31: COC | C31: 2 | D31: VELAZ, ATILIO | E31: 0.55 | F31: 33848.481 | G31: =F31 -> 33848.481 | H31: =F31-G31 -> 0 | J31: =M$4*E31% -> 4471.005 | K31: =M$2*E31 /100 -> 39007.095 | L31: =J$3*E31%+J$4 -> 0 | M31: =K31+J31+H31+L31 -> 43478.1 | N31: =M31*6% + M31 -> 46086.786
A32: COC | C32: 3 | D32: VILLA, JUAN MANUEL | E32: 0.45 | F32: 27694.212 | G32: =F32 -> 27694.212 | H32: =F32-G32 -> 0 | J32: =M$4*E32% -> 3658.095 | K32: =M$2*E32 /100 -> 31914.896 | L32: =J$3*E32%+J$4 -> 0 | M32: =K32+J32+H32+L32 -> 35572.991 | N32: =M32*6% + M32 -> 37707.37
A33: COC | C33: 4 | D33: VILLA, JUAN MANUEL | E33: 0.61 | F33: 37541.043 | G33: =F33 -> 37541.043 | H33: =F33-G33 -> 0 | J33: =M$4*E33% -> 4958.751 | K33: =M$2*E33 /100 -> 43262.415 | L33: =J$3*E33%+J$4 -> 0 | M33: =K33+J33+H33+L33 -> 48221.166 | N33: =M33*6% + M33 -> 51114.436
A34: COC | C34: 5 | D34: RUSSO, JUAN ANTONIO | E34: 0.54 | F34: 33233.054 | G34: =F34 -> 33233.054 | H34: =F34-G34 -> 0 | J34: =M$4*E34% -> 4389.714 | K34: =M$2*E34 /100 -> 38297.875 | L34: =J$3*E34%+J$4 -> 0 | M34: =K34+J34+H34+L34 -> 42687.589 | N34: =M34*6% + M34 -> 45248.845
A35: COC | C35: 6 | D35: MARANTE, MAURO | E35: 0.5 | F35: 30771.346 | G35: =F35 -> 30771.346 | H35: =F35-G35 -> 0 | J35: =M$4*E35% -> 4064.55 | K35: =M$2*E35 /100 -> 35460.996 | L35: =J$3*E35%+J$4 -> 0 | M35: =K35+J35+H35+L35 -> 39525.546 | N35: =M35*6% + M35 -> 41897.078
A36: COC | C36: 7 | D36: VELAZ, ATILIO | E36: 0.5 | F36: 30771.346 | G36: =F36 -> 30771.346 | H36: =F36-G36 -> 0 | J36: =M$4*E36% -> 4064.55 | K36: =M$2*E36 /100 -> 35460.996 | L36: =J$3*E36%+J$4 -> 0 | M36: =K36+J36+H36+L36 -> 39525.546 | N36: =M36*6% + M36 -> 41897.078
A37: COC | C37: 8 | D37: VROONLAND, DANIEL | E37: 0.49 | F37: 30155.919 | G37: =F37 -> 30155.919 | H37: =F37-G37 -> 0 | J37: =M$4*E37% -> 3983.259 | K37: =M$2*E37 /100 -> 34751.776 | L37: =J$3*E37%+J$4 -> 0 | M37: =K37+J37+H37+L37 -> 38735.035 | N37: =M37*6% + M37 -> 41059.137
A38: COC | C38: 9 | D38: MELINA, ANDRES | E38: 0.49 | F38: 30155.919 | G38: =F38 -> 30155.919 | H38: =F38-G38 -> 0 | J38: =M$4*E38% -> 3983.259 | K38: =M$2*E38 /100 -> 34751.776 | L38: =J$3*E38%+J$4 -> 0 | M38: =K38+J38+H38+L38 -> 38735.035 | N38: =M38*6% + M38 -> 41059.137
A39: COC | C39: 10 | D39: AGÜERO, MIRIAM S | E39: 0.59 | F39: 36310.189 | G39: =F39 -> 36310.189 | H39: =F39-G39 -> 0 | J39: =M$4*E39% -> 4796.169 | K39: =M$2*E39 /100 -> 41843.975 | L39: =J$3*E39%+J$4 -> 0 | M39: =K39+J39+H39+L39 -> 46640.144 | N39: =M39*6% + M39 -> 49438.552
A40: COC | C40: 11 | D40: AGÜERO, MIRIAM S | E40: 0.57 | F40: 35079.335 | G40: =F40 -> 35079.335 | H40: =F40-G40 -> 0 | J40: =M$4*E40% -> 4633.587 | K40: =M$2*E40 /100 -> 40425.535 | L40: =J$3*E40%+J$4 -> 0 | M40: =K40+J40+H40+L40 -> 45059.122 | N40: =M40*6% + M40 -> 47762.669
A41: COC | C41: 12 | D41: MIRAMONTES, HORACIO | E41: 0.54 | F41: 33233.054 | G41: =F41 -> 33233.054 | H41: =F41-G41 -> 0 | J41: =M$4*E41% -> 4389.714 | K41: =M$2*E41 /100 -> 38297.875 | L41: =J$3*E41%+J$4 -> 0 | M41: =K41+J41+H41+L41 -> 42687.589 | N41: =M41*6% + M41 -> 45248.845
...

Sheet COCHERA
D1: ESTADO DE CUENTA Y PRORRATEO | L1: Vencimiento | N1: =RESUMEN!C5 -> VTO. 13/02
D2: BELGRANO Nº 1640
J3: Gastos Ordinario: | L3: 249991.3 | N3: -1891.33
J4: Gastos Extr.: | L4: 0
A5: Cochera | B5: Propietario | C5: Porcentaje | D5: Saldo | E5: Ingreso | F5: DEUDAS | G5: Deuda exp | H5: Intereses | I5: porcentaje | J5: Expensas | K5: Expensas | L5: TOTAL | N5: 1ER Vto. | O5: 2DO Vto.
C6: (%) | D6: Anterior | E6: Exp. Ord. | G6: Extraord | H6: 0.06 | I6: % | J6: Ord. | K6: Extr. | L6: EXPENSAS
A7: 1 | B7: VELAZ, ATILIO | C7: 5.4 | D7: 13967.239 | E7: =D7 -> 13967.239 | F7: 0 | G7: 0 | H7: 0 | I7: 0.54 | J7: 11608.2 | K7: 0 | L7: 11608.2 | N7: 11608.2 | O7: 12304.692
A8: 2 | B8: VELAZ, ATILIO | C8: 5.5 | D8: 14267.901 | E8: =D8 -> 14267.901 | F8: 0 | G8: 0 | H8: 0 | I8: 0.55 | J8: 11858.191 | K8: 0 | L8: 11858.191 | N8: 11858.191 | O8: 12569.683
A9: 3 | B9: VILLA, JUAN MANUEL | C9: 4.5 | D9: 11261.283 | E9: =D9 -> 11261.283 | F9: 0 | G9: 0 | H9: 0 | I9: 0.45 | J9: 9358.2784 | K9: 0 | L9: 9358.2784 | N9: 9358.2784 | O9: 9919.7751
A10: 4 | B10: VILLA, JUAN MANUEL | C10: 6.1 | D10: 16071.872 | E10: =D10 -> 16071.872 | F10: 0 | G10: 0 | H10: 0 | I10: 0.61 | J10: 13358.139 | K10: 0 | L10: 13358.139 | N10: 13358.139 | O10: 14159.628
A11: 5 | B11: RUSSO, JUAN ANTONIO | C11: 5.4 | D11: 13967.239 | E11: =D11 -> 13967.239 | F11: 0 | G11: 0 | H11: 0 | I11: 0.54 | J11: 11608.2 | K11: 0 | L11: 11608.2 | N11: 11608.2 | O11: 12304.692
A12: 6 | B12: MARANTE, MAURO | C12: 5 | D12: 12764.592 | E12: =D12 -> 12764.592 | F12: 0 | G12: 0 | H12: 0 | I12: 0.5 | J12: 10608.235 | K12: 0 | L12: 10608.235 | N12: 10608.235 | O12: 11244.729
A13: 7 | B13: VELAZ, ATILIO | C13: 5 | D13: 12764.592 | E13: =D13 -> 12764.592 | F13: 0 | G13: 0 | H13: 0 | I13: 0.5 | J13: 10608.235 | K13: 0 | L13: 10608.235 | N13: 10608.235 | O13: 11244.729
A14: 8 | B14: VROONLAND, DANIEL | C14: 4.9 | D14: 12463.93 | E14: =D14 -> 12463.93 | F14: 0 | G14: 0 | H14: 0 | I14: 0.49 | J14: 10358.244 | K14: 0 | L14: 10358.244 | N14: 10358.244 | O14: 10979.738
A15: 9 | B15: MELINA, ANDRES | C15: 4.9 | D15: 12463.93 | E15: =D15 -> 12463.93 | F15: 0 | G15: 0 | H15: 0 | I15: 0.49 | J15: 10358.244 | K15: 0 | L15: 10358.244 | N15: 10358.244 | O15: 10979.738
A16: 10 | B16: AGÜERO, MIRIAM S | C16: 5.9 | D16: 15470.549 | E16: =D16 -> 15470.549 | F16: 0 | G16: 0 | H16: 0 | I16: 0.59 | J16: 12858.157 | K16: 0 | L16: 12858.157 | N16: 12858.157 | O16: 13629.646
A17: 11 | B17: AGÜERO, MIRIAM S | C17: 5.7 | D17: 14869.225 | E17: =D17 -> 14869.225 | F17: 0 | G17: 0 | H17: 0 | I17: 0.57 | J17: 12358.174 | K17: 0 | L17: 12358.174 | N17: 12358.174 | O17: 13099.664
A18: 12 | B18: MIRAMONTES, HORACIO | C18: 5.4 | D18: 13967.239 | E18: =D18 -> 13967.239 | F18: 0 | G18: 0 | H18: 0 | I18: 0.54 | J18: 11608.2 | K18: 0 | L18: 11608.2 | N18: 11608.2 | O18: 12304.692
... A28: 22 | B28: JARA, CLAUDIO | C28: 5.7 | D28: 14869.225 | E28: =D28 -> 14869.225 | F28: 0 | G28: 0 | H28: 0 | I28: 0.57 | J28: 12358.174 | K28: 0 | L28: 12358.174 | N28: 12358.174 | O28: 13099.664
C30: 116.6 | D30: 161487.47 | E30: 161487.47 | F30: 0 | G30: 0 | H30: 0 | I30: 11.66 | J30: 249880.59 | K30: 0 | L30: 249880.59 | N30: 249880.59 | O30: 264873.43
