Workbook

Sheet RESUMEN
B1: MAIL: yrigoyen7630@gmail.com
B2: CUIT ADMINISTRACION: 27231256879
B3: CBU: 0440060830000011423569 / ALIAS: OMBU.TECLEO.AMOROSAS / TELEFONO: 11 5320-2676
A4: LIQUIDACION DE EXPENSAS | B4: ADMINISTRADORA: CAROLINA CANCIANI MP:1148
A5: CUIT DEL EDIFICIO: 30-55421584-6 | B5: PERÍODO: SEPTIEMBRE | D5: HORARIOS DE ATENCION: LUNES A VIERNES
A6: CONSORCIO DE PROPIETARIOS DEL EDIFICIO CALLE YRIGOYEN 7630 | D6: 10 A 15HS - EMERGENCIAS 24HS
B8: VTO 16/10
A13: ESTIMADOS PROPIETARIOS E INQUILINOS: POR FAVOR LOS QUE ABONAN EN PRIMER VENCIMIENTO ABONEN EL MONTO DE PRIMER VENCIMIENTO, ASI AGILIZAN LA LIQUIDACION, RESPETEN LOS CENTAVOS CORRESPONDIENTES A LA UNIDAD FUNCIONAL. ES DE CARÁCTER OBLIGATORIO INFORMAR VIA MAIL LAS EXPENSAS. CASO CONTRARIO SE INFORMARA VIA CARTA DOCUMENTO A LA UNIDAD FUNCIONAL QUE CREEMOS QUE CORRESPONDE, CUYO COSTO SERA IMPUTADO A LA UNIDAD FUNCIONAL SOSPECHADA.
A20: GASTOS ORDINARIOS UNIDADES FUNCIONALES:
A21: HABERES ENCARGADOS
A22: Sueldo encargado Walter Fernandez | D22: 890804
A24: Neto | D24: =SUM(D22:D23) -> 890804
A25: Sueldo encargado Balcazza Leonardo
A26: Reemplazo Sr. Walter vacaciones - Sra. Silvana | D26: 0
A27: Seguro Sra. Silvana | D27: 0
A28: SAC
A29: Neto | D29: =SUM(D25:D28) -> 0
A30: TOTAL SUELDO | E30: =D24+D29 -> 890804
A31: HONORARIOS
A32: Gustavo padron - Sr contador honorarios SEPTIEMBRE | D32: 50000
A33: Honorarios administracion - Mes de Agosto - Se adeuda SEPTIEMBRE | D33: 180000 | E33: Transf 16/09 | G33: Subidos en Juni0 a 165000
A34: TOTAL | E34: =SUM(D32:D33) -> 230000
A35: SEGUROS
A36: Federacion patronal - Seguro de vida Poliza nro. 211840604 | D36: =30025+7909 -> 37934 | E36: Debito 02/09
A37: Federacion patronal Seguro obligatorio de consorcio | D37: 69628 | E37: =E36 -> Debito 02/09
A38: TOTAL IMPUESTO | E38: =SUM(D36:D37) -> 107562
A39: APORTES Y CONTRIBUCIONES
A40: ARCA | D40: 619750.26 | E40: Debito 07/09
A41: Plan de pagos ARCA | D41: 10602.27 | E41: Debito 16/09
A42: Plan de pagos ARCA | D42: 75532.29 | E42: =E41 -> Debito 16/09 | F42: =D42+D41 -> 86134.56
A43: Sindicatos mes de SEPTIEMBRE | D43: 5655.57 | E43: Debito 12/08
A44: =A43 -> Sindicatos mes de SEPTIEMBRE | D44: 98687.47 | E44: =E43 -> Debito 12/08
A45: =A44 -> Sindicatos mes de SEPTIEMBRE | D45: 50900.17 | E45: =E44 -> Debito 12/08
A46: TOTAL Aportes y Contribuciones - Sindicato | E46: =SUM(D40:D45) -> 861128.03
A47: ABONOS Y SERVICIOS
A48: EDESUR - Cliente nro. 1481147 | D48: 91685.7 | E48: Transf 28/09
A49: EDESUR - Cliente nro. 1481147 | D49: 254864.2 | E49: Transf 07/09
A50: EDESUR Porteria | D50: 19854.2 | E50: Transf 28/09
A51: Metrogas Porteria | D51: 43083.26 | E51: Transf 09/09
A52: AYSA - Nro de cliente 3477073 | D52: 530549.97 | E52: Debito 07/09
...

Sheet PRORRATEO
D2: Arca plan de pagos: | F2: 86134.56 | J2: Ordinarios | M2: 5580009.4
A4: UF | B4: Propietario | C4: Inquilinos | D4: (%) | E4: Saldo Ord | F4: Ingreso | G4: Deuda o Saldo a favor | H4: Interes 3% | I4: Expensas extraor. | J4: Expensas ord. | K4: Gastos part | L4: Arca plan de pagos | M4: Total 1er Vto | N4: Total 2do Vto. | O4: Total 2do Vto | R4: 4966143.9
M5: =RESUMEN!B8 -> VTO 16/10
A6: 1 | B6: Diaz Joaquin Andres | D6: 6.69 | E6: 379065.01 | F6: =E6 -> 379065.01 | G6: =E6-F6 -> 0 | H6: =IF(G6>0,G6*3%,0) -> 0 | I6: 0 | J6: =M$2*D6/100 -> 373302.63 | L6: =F$2*D6/100 -> 5762.4021 | M6: =ROUND(SUM(G6:L6),0) + P6 -> 379065.01 | N6: =ROUND(M6*6% + M6,0) + P6 -> 401809.01 | O6: =ROUND(M6*3%,0) + M6 -> 390437.01 | P6: 0.01
A7: =A6+1 -> 2 | B7: Marquez, Miguel | D7: 5.88 | E7: 3442518 | G7: =E7-F7 -> 3442518 | H7: =IF(G7>0,G7*3%,0) -> 103275.54 | I7: 0 | J7: =M$2*D7% -> 328104.55 | K7: =24000+99500 -> 123500 | L7: =F$2*D7/100 -> 5064.7121 | M7: =ROUND(SUM(G7:L7),0) + P7 -> 4002463 | N7: =ROUND(M7*6% + M7,0) + P7 -> 4242611 | O7: =ROUND(M7*3%,0) + M7 -> 4122537 | P7: =P6+0.01 -> 0.02
A8: =A7+1 -> 3 | B8: Matheu, Martha F. | D8: 6.65 | E8: 954477.03 | F8: 400000.03 | G8: =E8-F8 -> 554477 | H8: =IF(G8>0,G8*3%,0) -> 16634.31 | I8: 0 | J8: =M$2*D8% -> 371070.62 | L8: =F$2*D8/100 -> 5727.9482 | M8: =ROUND(SUM(G8:L8),0) + P8 -> 947910.03 | N8: =ROUND(M8*6% + M8,0) + P8 -> 1004785 | O8: =ROUND(M8*3%,0) + M8 -> 976347.03 | P8: =P7+0.01 -> 0.03
A9: =A8+1 -> 4 | B9: Hernandez, Susana | D9: 6.73 | E9: 381331.04 | F9: =E9 -> 381331.04 | G9: =E9-F9 -> 0 | H9: =IF(G9>0,G9*3%,0) -> 0 | I9: 0 | J9: =M$2*D9% -> 375534.63 | L9: =F$2*D9/100 -> 5796.8559 | M9: =ROUND(SUM(G9:L9),0) + P9 -> 381331.04 | N9: =ROUND(M9*6% + M9,0) + P9 -> 404211.04 | O9: =ROUND(M9*3%,0) + M9 -> 392771.04 | P9: =P8+0.01 -> 0.04
A10: =A9+1 -> 5 | B10: Rossi, Raul Alfredo | D10: 8.04 | E10: 455558.05 | F10: 0 | G10: =E10-F10 -> 455558.05 | H10: =IF(G10>0,G10*3%,0) -> 13666.741 | I10: 0 | J10: =M$2*D10% -> 448632.75 | L10: =F$2*D10/100 -> 6925.2186 | M10: =ROUND(SUM(G10:L10),0) + P10 -> 924783.05 | N10: =ROUND(M10*6% + M10,0) + P10 -> 980270.05 | O10: =ROUND(M10*3%,0) + M10 -> 952526.05 | P10: =P9+0.01 -> 0.05 | Q10: Silvia lopez
A11: =A10+1 -> 6 | B11: Medaglia, Amadeo Juan | D11: 4.73 | E11: 18009.06 | F11: =E11+RESUMEN!D57 -> 268009.06 | G11: =E11-F11 -> -250000 | H11: =IF(G11>0,G11*3%,0) -> 0 | I11: 0 | J11: =M$2*D11% -> 263934.44 | L11: =F$2*D11/100 -> 4074.1647 | M11: =ROUND(SUM(G11:L11),0) + P11 -> 18009.06 | N11: =ROUND(M11*6% + M11,0) + P11 -> 19090.06 | O11: =ROUND(M11*3%,0) + M11 -> 18549.06 | P11: =P10+0.01 -> 0.06
A12: =A11+1 -> 7 | B12: Solerno, Raul Anibal | D12: 5.67 | E12: 1144136.1 | F12: 0 | G12: =E12-F12 -> 1144136.1 | H12: =IF(G12>0,G12*3%,0) -> 34324.082 | I12: 0 | J12: =M$2*D12% -> 316386.53 | L12: =F$2*D12/100 -> 4883.8296 | M12: =ROUND(SUM(G12:L12),0) + P12 -> 1499731.1 | N12: =ROUND(M12*6% + M12,0) + P12 -> 1589715.1 | O12: =ROUND(M12*3%,0) + M12 -> 1544723.1 | P12: =P11+0.01 -> 0.07
A13: =A12+1 -> 8 | B13: Cavalli, Maria | D13: 5.67 | E13: 321270.08 | F13: 0 | G13: =E13-F13 -> 321270.08 | H13: =IF(G13>0,G13*3%,0) -> 9638.1024 | I13: 0 | J13: =M$2*D13% -> 316386.53 | L13: =F$2*D13/100 -> 4883.8296 | M13: =ROUND(SUM(G13:L13),0) + P13 -> 652179.08 | N13: =ROUND(M13*6% + M13,0) + P13 -> 691310.08 | O13: =ROUND(M13*3%,0) + M13 -> 671744.08 | P13: =P12+0.01 -> 0.08 | R13: CONSTANZA
A14: =A13+1 -> 9 | B14: Lencina, Suzana | D14: 7.67 | E14: 434593.09 | F14: =E14 -> 434593.09 | G14: =E14-F14 -> 0 | H14: =IF(G14>0,G14*3%,0) -> 0 | I14: 0 | J14: =M$2*D14% -> 427986.72 | L14: =F$2*D14/100 -> 6606.5208 | M14: =ROUND(SUM(G14:L14),0) + P14 -> 434593.09 | N14: =ROUND(M14*6% + M14,0) + P14 -> 460669.09 | O14: =ROUND(M14*3%,0) + M14 -> 447631.09 | P14: =P13+0.01 -> 0.09
A15: =A14+1 -> 10 | B15: Castro, Ana Maria | D15: 4.9 | E15: 277641.1 | F15: =E15 -> 277641.1 | G15: =E15-F15 -> 0 | H15: =IF(G15>0,G15*3%,0) -> 0 | I15: 0 | J15: =M$2*D15% -> 273420.46 | L15: =F$2*D15/100 -> 4220.5934 | M15: =ROUND(SUM(G15:L15),0) + P15 -> 277641.1 | N15: =ROUND(M15*6% + M15,0) + P15 -> 294300.1 | O15: =ROUND(M15*3%,0) + M15 -> 285970.1 | P15: =P14+0.01 -> 0.1
A16: =A15+1 -> 11 | B16: Penerbosa, Miguel Angel | D16: 5.63 | E16: 319004.11 | F16: =E16 -> 319004.11 | G16: =E16-F16 -> 0 | H16: =IF(G16>0,G16*3%,0) -> 0 | I16: 0 | J16: =M$2*D16% -> 314154.53 | L16: =F$2*D16/100 -> 4849.3757 | M16: =ROUND(SUM(G16:L16),0) + P16 -> 319004.11 | N16: =ROUND(M16*6% + M16,0) + P16 -> 338144.11 | O16: =ROUND(M16*3%,0) + M16 -> 328574.11 | P16: =P15+0.01 -> 0.11
A17: =A16+1 -> 12 | B17: Smietniansky, Laura | D17: 5.55 | E17: 314471.12 | F17: =E17 -> 314471.12 | G17: =E17-F17 -> 0 | H17: =IF(G17>0,G17*3%,0) -> 0 | I17: 0 | J17: =M$2*D17% -> 309690.52 | L17: =F$2*D17/100 -> 4780.4681 | M17: =ROUND(SUM(G17:L17),0) + P17 -> 314471.12 | N17: =ROUND(M17*6% + M17,0) + P17 -> 333339.12 | O17: =ROUND(M17*3%,0) + M17 -> 323905.12 | P17: =P16+0.01 -> 0.12
A18: =A17+1 -> 13 | B18: Llobera, Fernando | D18: 11.06 | E18: 626676.13 | F18: =E18 -> 626676.13 | G18: =E18-F18 -> 0 | H18: =IF(G18>0,G18*3%,0) -> 0 | I18: 0 | J18: =M$2*D18% -> 617149.04 | L18: =F$2*D18/100 -> 9526.4823 | M18: =ROUND(SUM(G18:L18),0) + P18 -> 626676.13 | N18: =ROUND(M18*6% + M18,0) + P18 -> 664277.13 | O18: =ROUND(M18*3%,0) + M18 -> 645476.13 | P18: =P17+0.01 -> 0.13
A19: =A18+1 -> 14 | B19: Stancati, Victor Dario | D19: 3.3 | E19: 192926.14 | F19: =184140.14+2842.14 -> 186982.28 | G19: =E19-F19 -> 5943.86 | H19: =IF(G19>0,G19*3%,0) -> 178.3158 | I19: 0 | J19: =M$2*D19% -> 184140.31 | L19: =F$2*D19/100 -> 2842.4405 | M19: =ROUND(SUM(G19:L19),0) + P19 -> 193105.14 | N19: =ROUND(M19*6% + M19,0) + P19 -> 204691.14 | O19: =ROUND(M19*3%,0) + M19 -> 198898.14 | P19: =P18+0.01 -> 0.14 | Q19: Ivan Gstavo Almeyda
A20: =A19+1 -> 15 | B20: Russo, Mabel | D20: 1.8 | E20: 101991.15 | F20: =E20 -> 101991.15 | G20: =E20-F20 -> 0 | H20: =IF(G20>0,G20*3%,0) -> 0 | I20: 0 | J20: =M$2*D20% -> 100440.17 | L20: =F$2*D20/100 -> 1550.4221 | M20: =ROUND(SUM(G20:L20),0) + P20 -> 101991.15 | N20: =ROUND(M20*6% + M20,0) + P20 -> 108111.15 | O20: =ROUND(M20*3%,0) + M20 -> 105051.15 | P20: =P19+0.01 -> 0.15 | Q20: cristina - Joatan Fernandez
A21: =A20+1 -> 16 | B21: Gamboa, Ana Cecilia | D21: 3.22 | E21: 182450.16 | F21: =E21 -> 182450.16 | G21: =E21-F21 -> 0 | H21: =IF(G21>0,G21*3%,0) -> 0 | I21: 0 | J21: =M$2*D21% -> 179676.3 | L21: =F$2*D21/100 -> 2773.5328 | M21: =ROUND(SUM(G21:L21),0) + P21 -> 182450.16 | N21: =ROUND(M21*6% + M21,0) + P21 -> 193397.16 | O21: =ROUND(M21*3%,0) + M21 -> 187924.16 | P21: =P20+0.01 -> 0.16
A22: =A21+1 -> 17 | B22: Rodriguez, Stella Maris | D22: 2.61 | E22: 289833.17 | F22: =E22 -> 289833.17 | G22: =E22-F22 -> 0 | H22: =IF(G22>0,G22*3%,0) -> 0 | I22: 0 | J22: =M$2*D22% -> 145638.24 | L22: =F$2*D22/100 -> 2248.112 | M22: =ROUND(SUM(G22:L22),0) + P22 -> 147886.17 | N22: =ROUND(M22*6% + M22,0) + P22 -> 156759.17 | O22: =ROUND(M22*3%,0) + M22 -> 152323.17 | P22: =P21+0.01 -> 0.17 | Q22: Facundo comandatore
A23: =A22+1 -> 18 | B23: Sieira, Leonardo | D23: 4.28 | E23: 182511.18 | F23: =E23+RESUMEN!D58 -> 242511.18 | G23: =E23-F23 -> -60000 | H23: =IF(G23>0,G23*3%,0) -> 0 | I23: 0 | J23: =M$2*D23% -> 238824.4 | L23: =F$2*D23/100 -> 3686.5592 | M23: =ROUND(SUM(G23:L23),0) + P23 -> 182511.18 | N23: =ROUND(M23*6% + M23,0) + P23 -> 193462.18 | O23: =ROUND(M23*3%,0) + M23 -> 187986.18 | P23: =P22+0.01 -> 0.18
P24: =P23+0.01 -> 0.19
D29: =SUM(D6:D28) -> 100.08 | E29: =SUM(E6:E28) -> 10018462 | F29: =SUM(F6:F28) -> 4404558.6 | G29: =SUM(G6:G28) -> 5613903.1 | H29: =SUM(H6:H28) -> 177717.09 | I29: =SUM(I6:I28) -> 0 | J29: =SUM(J6:J28) -> 5584473.4 | L29: =SUM(L6:L28) -> 86203.468 | M29: =SUM(M6:M23) -> 11585801 | N29: =SUM(N6:N28) -> 12280952 | O29: =SUM(O6:O28) -> 11933374
B32: =RESUMEN!A13 -> ESTIMADOS PROPIETARIOS E INQUILINOS: POR FAVOR LOS QUE ABONAN EN PRIMER VENCIMIENTO ABONEN EL MONTO DE PRIMER VENCIMIENTO, ASI AGILIZAN LA LIQUIDACION, RESPETEN LOS CENTAVOS CORRESPONDIENTES A LA UNIDAD FUNCIONAL. ES DE CARÁCTER OBLIGATORIO INFORMAR VIA MAIL LAS EXPENSAS. CASO CONTRARIO SE INFORMARA VIA CARTA DOCUMENTO A LA UNIDAD FUNCIONAL QUE CREEMOS QUE CORRESPONDE, CUYO COSTO SERA IMPUTADO A LA UNIDAD FUNCIONAL SOSPECHADA.

Sheet ANOTACIONES
B2: Anotacion: | C2: 1
B3: Dpto | C3: 5 y 6
B4: El mes pasado el 06 y el 05 pagaron impecable, pero le pusimos pago al 05 lo que iba en el 06 y pago al 06 lo que iba en el 05. El 06 debe abonar $200.896,06 y el 05 $341.480,05
B10: Anotacion: | C10: 1
B11: Dpto | C11: UF 14
B12: El mes pasado abono los $5.028 que le habian quedado como deuda y se nos paso
