Workbook

Sheet RESUMEN
C1: MAIL: elmiradorconsorcios@gmail.com
C2: CUIT ADMINISTRACION: 27231256879
C3: CBU: 0720039720000002171436 | E3: TELEFONO: 11 5320-2676
C4: ADMINISTRADORA: CAROLINA CANCIANI MP:1148
C5: PERÍODO: SEPTIEMBRE | E5: HORARIOS DE ATENCION: LUNES A VIERNES - 10 A 16HS - EMERGENCIAS 24HS
C6: LIQUIDACION DE EXPENSAS
A14: Importante para dueños o inquilinos de departamentos o coheras: Queremos recordarles una cuestión importante respecto a los pagos de expensas que ayuda a evitar errores en la imputación de los mismos. El sistema que utilizamos asigna centavos únicos a cada Unidad Funcional (UF), lo cual nos permite identificar automáticamente a qué unidad corresponde cada transferencia. Es decir, cada UF tiene un número específico de centavos que actúa como "identificador". Por ejemplo, si tu UF es la 45, el importe a abonar debería terminar en $...,45. Si tenés más de una unidad (por ejemplo, un departamento y una cochera), cada una tiene su propio código de centavos. En esos casos, te pedimos por favor que realices una transferencia por cada UF, respetando el importe con sus centavos correspondientes. Sabemos que a veces por comodidad se suele enviar todo junto en una sola transferencia, pero esto puede generar confusión o errores en la imputación automática. Realizar los pagos por separado nos permite asegurar que cada importe se asigne correctamente. Agradecemos muchísimo la colaboración para seguir manteniendo todo ordenado. Saludos cordiales.
A20: VTO 15/10
A24: GASTOS ORDINARIOS UNIDADES FUNCIONALES: | E24: UF 93,20% | F24: LOCAL 1 (1,08%) | G24: LOCAL 2 (1,28%) | H24: LOCAL 3 (1,21%) | I24: LOCAL 4 (1,49%) | J24: LOCAL 5 (1,74%)
A25: Sueldo encargada Sonia Arzamendia Galeano
A26: Haberes | D26: 1008894
A27: Plus pileta | D27: 35211
A28: Plus retiro de basura | D28: =1533.8*80 -> 122704
A29: Plus cochera | D29: 20931
A30: Adicional Viaticos | D30: 58852.2
A31: Adicional remuneracion | D31: 50000
A32: SUBTOTAL | D32: =SUM(D26:D31) -> 1296592.2
A33: Sueldo encargada Miriam
A34: Haberes | D34: 504447
A35: Horas extras
A36: Plus pileta | D36: =D27 -> 35211
A37: Plus retiro de basura | D37: =D28 -> 122704
A38: Plus cochera | D38: =D29 -> 20931
A39: Adicional Viaticos | D39: 58852.2
A40: Adicional remuneracion | D40: 50000
A41: SUBTOTAL | D41: =SUM(D34:D40) -> 792145.2
A42: TOTAL SUELDO | D42: =D32+D41 -> 2088737.4 | E42: =D42*93.2% -> 1946703.3 | F42: =$D42*1.08% -> 22558.364 | G42: =$D42*1.28% -> 26735.839 | H42: =$D42*1.21% -> 25273.723 | I42: =$D42*1.49% -> 31122.187 | J42: =D42*1.74% -> 36344.031 | K42: =E42+J42+F42+G42+H42+I42 -> 2088737.4 | L42: =K42-600000 -> 1488737.4
A43: SAC | D43: 0 | E43: =D43*91.91% -> 0 | J43: =D43*8.09% -> 0
D44: 0 | E44: =D44*91.91% -> 0 | J44: =D44*8.09% -> 0
A47: TOTAL | D47: =SUM(D43:D45) -> 0 | E47: =SUM(E43:E45) -> 0 | J47: =SUM(J43:J45) -> 0 | K47: =E47+J47 -> 0 | L47: =IF(D47=K47, "", "Error")
A48: COMBUSTIBLE PARA GRUPO ELECTROGENO | E48: =D48*91.91% -> 0 | J48: =D48*8.09% -> 0
E49: =D49 -> 0
E50: =D50 -> 0
E51: =D51*91.91% -> 0 | J51: =D51*8.09% -> 0
A52: TOTAL SAC | D52: =SUM(D44:D51) -> 0 | E52: =SUM(E44:E51) -> 0 | K52: =E52+J52+F52+G52+H52+I52 -> 0 | L52: =IF(D52=K52, "", "Error")
A53: IMPUESTOS
A54: ARBA - Impuesto inmobiliario partida 025024270-0 | C54: Mes de descanso
A55: TSG - Partida 197229000 | C55: PMC 08/09 | D55: 643422
A56: TSG - Partida 197227000 | C56: =C55 -> PMC 08/09 | D56: 643422
A57: TOTAL IMPUESTOS | D57: =SUM(D54:D56) -> 1286844 | E57: =D57*93.2% -> 1199338.6 | F57: =$D57*1.08% -> 13897.915 | G57: =$D57*1.28% -> 16471.603 | H57: =$D57*1.21% -> 15570.812 | I57: =$D57*1.49% -> 19173.976 | J57: =D57*1.74% -> 22391.086 | K57: =E57+J57+F57+G57+H57+I57 -> 1286844 | L57: =IF(D57=K57, "", "Error")
...

Sheet PRORRATEO
F1: Banco Santander Rio. | K1: SE GASTO: | L1: =RESUMEN!D107-RESUMEN!D105 -> 10364215
F2: CBU: 0720039720000002171436 | K2: SE PRORRATEA EN LAS UF: | M2: 10000000
A3: =RESUMEN!C5 -> PERÍODO: SEPTIEMBRE | F3: CTA CTE $ 0039 - 21714/3 FIDEICOMISO 25 DE MAYO 837 LAN 30716676737
J4: =(J3*8.09%)/44 -> 0 | P4: =L1-K127 -> 494947.16
A5: Piso | B5: Dpto. | C5: UF | D5: Propietario | E5: Inquilinos | F5: (%) | G5: Saldo | H5: Ingreso | I5: SALDO | J5: Expensas extraor. | K5: Expensas ord | L5: SUM/ GASTOS PART | M5: TOTAL A ABONAR HASTA | N5: TOTAL A ABONAR 2DO VTO - DESDE EL
M7: =RESUMEN!A20 -> VTO 15/10 | N7: =RESUMEN!A20 -> VTO 15/10
A8: conf sup | C8: LOC 1 | D8: Fernandez, Cristian | E8: Gladys ojeda Britez - Exequiel alexis giuliani | F8: 0.0108 | G8: 120107.14 | H8: =G8 -> 120107.14 | I8: =G8-H8 -> 0 | J8: 0 | K8: 90413.071 | L8: =J$3*F8%+J$4 -> 0 | M8: =K8+J8+I8+L8 -> 90413.071 | N8: =M8*6% + M8 -> 95837.855 | Q8: para copias y pegar las expensas ord del local
C9: LOC 2 | D9: Sr propietario | F9: 0.013 | G9: 101816.28 | H9: =117355.87+16429-11268-H99 -> 101816 | I9: =G9-H9 -> 0.278848 | J9: 0 | K9: 107156.23 | L9: =J$3*F9%+J$4 -> 0 | M9: =K9+J9+I9+L9 -> 107156.51 | N9: =M9*6% + M9 -> 113585.9
A10: conf sup | C10: LOC 3 | D10: Schiaffino, Edgardo Angel | F10: 0.0121 | G10: 134565.38 | I10: =G10-H10 -> 134565.38 | J10: 0 | K10: 101296.13 | L10: =J$3*F10%+J$4 -> 0 | M10: =K10+J10+I10+L10 -> 235861.51 | N10: =M10*6% + M10 -> 250013.2 | Q10: LOCAL 1 | R10: =RESUMEN!F107 -> 90413.071
A11: conf sup | C11: LOC 4 | D11: Cordero, Leandro Emanuel - Orona, Victoria | F11: 0.0149 | G11: 165702.97 | I11: =G11-H11 -> 165702.97 | J11: 0 | K11: 124736.55 | L11: =J$3*F11%+J$4 -> 0 | M11: =K11+J11+I11+L11 -> 290439.52 | N11: =M11*6% + M11 -> 307865.9 | Q11: LOCAL 2 | R11: =RESUMEN!G107 -> 107156.23
A12: conf sup | C12: LOC 5 | D12: Orsi, Jose Luis - Fernandez, Cristian Gabriel | F12: 0.0174 | G12: 62115.895 | H12: =G12 -> 62115.895 | I12: =G12-H12 -> 0 | J12: 0 | K12: 145665.5 | L12: =J$3*F12%+J$4 -> 0 | M12: =K12+J12+I12+L12 -> 145665.5 | N12: =M12*6% + M12 -> 154405.43 | Q12: LOCAL 3 | R12: =RESUMEN!H107 -> 101296.13
A13: 3 amb | C13: 2ºA | D13: Franco, Lucas Fabián | F13: 0.0188 | G13: 169200.01 | H13: =G13 -> 169200.01 | I13: =G13-H13 -> 0 | J13: =M$4*F13 -> 0 | K13: =M$2*F13 -> 188000 | L13: =J$3*F13%+J$4 -> 0 | M13: =ROUND((K13+J13+I13+L13),0) + O13 -> 188000.01 | N13: =ROUND((M13*6% + M13 ),0) + O13 -> 199280.01 | O13: 0.01 | Q13: LOCAL 4 | R13: =RESUMEN!I107 -> 124736.55
A14: 1 amb | C14: 2ºB | D14: Martinez, Diego | F14: 0.0084 | G14: 75600.02 | H14: =G14 -> 75600.02 | I14: =G14-H14 -> 0 | J14: =M$4*F14 -> 0 | K14: =M$2*F14 -> 84000 | L14: =J$3*F14%+J$4 -> 0 | M14: =ROUND((K14+J14+I14+L14),0) + O14 -> 84000.02 | N14: =ROUND((M14*6% + M14 ),0) + O14 -> 89040.02 | O14: =O13+0.01 -> 0.02 | Q14: LOCAL 5 | R14: =RESUMEN!J107 -> 145665.5
A15: 3 amb | C15: 2ºC | D15: Rodriguez, Carlos Alberto Miguel | F15: 0.0201 | G15: 180900.03 | H15: =G15 -> 180900.03 | I15: =G15-H15 -> 0 | J15: =M$4*F15 -> 0 | K15: =M$2*F15 -> 201000 | L15: =J$3*F15%+J$4 -> 0 | M15: =ROUND((K15+J15+I15+L15),0) + O15 -> 201000.03 | N15: =ROUND((M15*6% + M15 ),0) + O15 -> 213060.03 | O15: =O14+0.01 -> 0.03
A16: 2 amb | C16: 2ºD | D16: Ferraro, José | E16: Matias Cuevas | F16: 0.0094 | G16: 165172.04 | I16: =G16-H16 -> 165172.04 | J16: =M$4*F16 -> 0 | K16: =M$2*F16 -> 94000 | L16: 0 | M16: =ROUND((K16+J16+I16+L16),0) + O16 -> 259172.04 | N16: =ROUND((M16*6% + M16 ),0) + O16 -> 274722.04 | O16: =O15+0.01 -> 0.04
A17: 2 amb | C17: 2ºE | D17: Dieci, Matias Orlando | E17: Julieta Damiano/Damiani | F17: 0.0087 | G17: 165600.05 | H17: =87300+78300 -> 165600 | I17: =G17-H17 -> 0.05 | J17: =M$4*F17 -> 0 | K17: =M$2*F17 -> 87000 | L17: =J$3*F17%+J$4 -> 0 | M17: =ROUND((K17+J17+I17+L17),0) + O17 -> 87000.05 | N17: =ROUND((M17*6% + M17 ),0) + O17 -> 92220.05 | O17: =O16+0.01 -> 0.05
A18: 2 amb | C18: 2ºF | D18: Ferraro, Jose | E18: Carolina Massa | F18: 0.0095 | G18: 81429.06 | H18: =G18 -> 81429.06 | I18: =G18-H18 -> 0 | J18: =M$4*F18 -> 0 | K18: =M$2*F18 -> 95000 | L18: =J$3*F18%+J$4 -> 0 | M18: =ROUND((K18+J18+I18+L18),0) + O18 -> 95000.06 | N18: =ROUND((M18*6% + M18 ),0) + O18 -> 100700.06 | O18: =O17+0.01 -> 0.06
A19: 3 amb | C19: 3ºA | D19: Ferraro, Jose | E19: Walter | F19: 0.0165 | G19: 307929.07 | H19: 184976.07 | I19: =G19-H19 -> 122953 | J19: =M$4*F19 -> 0 | K19: =M$2*F19 -> 165000 | L19: =J$3*F19%+J$4 -> 0 | M19: =ROUND((K19+J19+I19+L19),0) + O19 -> 287953.07 | N19: =ROUND((M19*6% + M19 ),0) + O19 -> 305230.07 | O19: =O18+0.01 -> 0.07
A20: 1 amb | C20: 3ºB | D20: Balduzzi, Stella Maris | F20: 0.0073 | G20: 65700.08 | H20: =G20 -> 65700.08 | I20: =G20-H20 -> 0 | J20: =M$4*F20 -> 0 | K20: =M$2*F20 -> 73000 | L20: =J$3*F20%+J$4 -> 0 | M20: =ROUND((K20+J20+I20+L20),0) + O20 -> 73000.08 | N20: =ROUND((M20*6% + M20 ),0) + O20 -> 77380.08 | O20: =O19+0.01 -> 0.08
A21: 3 amb | C21: 3ºC | D21: Ferraro, Jose | F21: 0.0178 | G21: 312772.09 | I21: =G21-H21 -> 312772.09 | J21: =M$4*F21 -> 0 | K21: =M$2*F21 -> 178000 | L21: =J$3*F21%+J$4 -> 0 | M21: =ROUND((K21+J21+I21+L21),0) + O21 -> 490772.09 | N21: =ROUND((M21*6% + M21 ),0) + O21 -> 520218.09 | O21: =O20+0.01 -> 0.09
A22: 2 amb | C22: 3ºD | D22: Heredia, Christian | F22: 0.0094 | G22: 169200.1 | I22: =G22-H22 -> 169200.1 | J22: =M$4*F22 -> 0 | K22: =M$2*F22 -> 94000 | L22: =J$3*F22%+J$4 -> 0 | M22: =ROUND((K22+J22+I22+L22),0) + O22 -> 263200.1 | N22: =ROUND((M22*6% + M22 ),0) + O22 -> 278992.1 | O22: =O21+0.01 -> 0.1
A23: 2 amb | C23: 3ºE | D23: Dallorso, Maria Ines - Dallorso, Ana Paula | F23: 0.0087 | G23: 156600.11 | H23: 165996.11 | I23: =G23-H23 -> -9396 | J23: =M$4*F23 -> 0 | K23: =M$2*F23 -> 87000 | L23: =J$3*F23%+J$4 -> 0 | M23: =ROUND((K23+J23+I23+L23),0) + O23 -> 77604.11 | N23: =ROUND((M23*6% + M23 ),0) + O23 -> 82260.11 | O23: =O22+0.01 -> 0.11
A24: 2 amb | C24: 3ºF | D24: Ayala, Roberto Adrian | F24: 0.0095 | G24: 171000.12 | I24: =G24-H24 -> 171000.12 | J24: =M$4*F24 -> 0 | K24: =M$2*F24 -> 95000 | L24: =J$3*F24%+J$4 -> 0 | M24: =ROUND((K24+J24+I24+L24),0) + O24 -> 266000.12 | N24: =ROUND((M24*6% + M24 ),0) + O24 -> 281960.12 | O24: =O23+0.01 -> 0.12
A25: 3 amb | C25: 4ºA | D25: Barral, Carlos Daniel | F25: 0.0164 | G25: 147600.13 | H25: =G25 -> 147600.13 | I25: =G25-H25 -> 0 | J25: =M$4*F25 -> 0 | K25: =M$2*F25 -> 164000 | L25: =J$3*F25%+J$4 -> 0 | M25: =ROUND((K25+J25+I25+L25),0) + O25 -> 164000.13 | N25: =ROUND((M25*6% + M25 ),0) + O25 -> 173840.13 | O25: =O24+0.01 -> 0.13
A26: 1 amb | C26: 4ºB | D26: Sr. Propietario | E26: Liria | F26: 0.0072 | G26: 64800.14 | H26: =G26 -> 64800.14 | I26: =G26-H26 -> 0 | J26: =M$4*F26 -> 0 | K26: =M$2*F26 -> 72000 | L26: =J$3*F26%+J$4 -> 0 | M26: =ROUND((K26+J26+I26+L26),0) + O26 -> 72000.14 | N26: =ROUND((M26*6% + M26 ),0) + O26 -> 76320.14 | O26: =O25+0.01 -> 0.14
A27: 3 amb | C27: 4ºC | D27: Osipowicz, Ariel Marcelo | F27: 0.0173 | G27: 155700.15 | H27: =G27 -> 155700.15 | I27: =G27-H27 -> 0 | J27: =M$4*F27 -> 0 | K27: =M$2*F27 -> 173000 | L27: =J$3*F27%+J$4 -> 0 | M27: =ROUND((K27+J27+I27+L27),0) + O27 -> 173000.15 | N27: =ROUND((M27*6% + M27 ),0) + O27 -> 183380.15 | O27: =O26+0.01 -> 0.15
A28: 2 amb | C28: 4ºD | D28: Ruiz, Juana Del Valle | F28: 0.0094 | G28: 179352.16 | H28: =G28 -> 179352.16 | I28: =G28-H28 -> 0 | J28: =M$4*F28 -> 0 | K28: =M$2*F28 -> 94000 | L28: =J$3*F28%+J$4 -> 0 | M28: =ROUND((K28+J28+I28+L28),0) + O28 -> 94000.16 | N28: =ROUND((M28*6% + M28 ),0) + O28 -> 99640.16 | O28: =O27+0.01 -> 0.16
A29: 2 amb | C29: 4ºE | D29: Ayala, Roberto Adrian | E29: Iara | F29: 0.0087 | G29: 78300.17 | H29: =G29 -> 78300.17 | I29: =G29-H29 -> 0 | J29: =M$4*F29 -> 0 | K29: =M$2*F29 -> 87000 | L29: =K29*0.1 -> 8700 | M29: =ROUND((K29+J29+I29+L29),0) + O29 -> 95700.17 | N29: =ROUND((M29*6% + M29 ),0) + O29 -> 101442.17 | O29: =O28+0.01 -> 0.17
A30: 2 amb | C30: 4ºF | D30: Ayala, Roberto Adrian | F30: 0.0095 | G30: 181260.18 | H30: =G30 -> 181260.18 | I30: =G30-H30 -> 0 | J30: =M$4*F30 -> 0 | K30: =M$2*F30 -> 95000 | L30: =J$3*F30%+J$4 -> 0 | M30: =ROUND((K30+J30+I30+L30),0) + O30 -> 95000.18 | N30: =ROUND((M30*6% + M30 ),0) + O30 -> 100700.18 | O30: =O29+0.01 -> 0.18
A31: 3 amb | C31: 5ºA | D31: Chehab, Gabriel Adrian | E31: Santiago Rodriguez | F31: 0.0164 | G31: 156600.19 | H31: =G31 -> 156600.19 | I31: =G31-H31 -> 0 | J31: =M$4*F31 -> 0 | K31: =M$2*F31 -> 164000 | L31: =J$3*F31%+J$4 -> 0 | M31: =ROUND((K31+J31+I31+L31),0) + O31 -> 164000.19 | N31: =ROUND((M31*6% + M31 ),0) + O31 -> 173840.19 | O31: =O30+0.01 -> 0.19
A32: 1 amb | C32: 5ºB | D32: Mesa, Mariano | F32: 0.0072 | G32: 64800.2 | H32: =G32 -> 64800.2 | I32: =G32-H32 -> 0 | J32: =M$4*F32 -> 0 | K32: =M$2*F32 -> 72000 | L32: =J$3*F32%+J$4 -> 0 | M32: =ROUND((K32+J32+I32+L32),0) + O32 -> 72000.2 | N32: =ROUND((M32*6% + M32 ),0) + O32 -> 76320.2 | O32: =O31+0.01 -> 0.2
A33: 3 amb | C33: 5ºC | D33: Di Mito, Vicente Argentino - Serantes, Mabel | F33: 0.0173 | G33: 434967.21 | I33: =G33-H33 -> 434967.21 | J33: =M$4*F33 -> 0 | K33: =M$2*F33 -> 173000 | L33: =J$3*F33%+J$4 -> 0 | M33: =ROUND((K33+J33+I33+L33),0) + O33 -> 607967.21 | N33: =ROUND((M33*6% + M33 ),0) + O33 -> 644445.21 | O33: =O32+0.01 -> 0.21
A34: 2 amb | C34: 5ºD | D34: Ayala, Agustin | F34: 0.0094 | G34: 179352.22 | H34: =G34 -> 179352.22 | I34: =G34-H34 -> 0 | J34: =M$4*F34 -> 0 | K34: =M$2*F34 -> 94000 | L34: =J$3*F34%+J$4 -> 0 | M34: =ROUND((K34+J34+I34+L34),0) + O34 -> 94000.22 | N34: =ROUND((M34*6% + M34 ),0) + O34 -> 99640.22 | O34: =O33+0.01 -> 0.22
A35: 2 amb | C35: 5ºE | D35: Ayala, Roberto Adrian | F35: 0.0087 | G35: 156600.23 | H35: =G35 -> 156600.23 | I35: =G35-H35 -> 0 | J35: =M$4*F35 -> 0 | K35: =M$2*F35 -> 87000 | L35: =J$3*F35%+J$4 -> 0 | M35: =ROUND((K35+J35+I35+L35),0) + O35 -> 87000.23 | N35: =ROUND((M35*6% + M35 ),0) + O35 -> 92220.23 | O35: =O34+0.01 -> 0.23 | P35: COCHERA 31
A36: 2 amb | C36: 5ºF | D36: Ayala, Agustin | F36: 0.0095 | G36: 181260.24 | H36: =G36 -> 181260.24 | I36: =G36-H36 -> 0 | J36: =M$4*F36 -> 0 | K36: =M$2*F36 -> 95000 | L36: =J$3*F36%+J$4 -> 0 | M36: =ROUND((K36+J36+I36+L36),0) + O36 -> 95000.24 | N36: =ROUND((M36*6% + M36 ),0) + O36 -> 100700.24 | O36: =O35+0.01 -> 0.24
A37: 3 amb | C37: 6ºA | D37: Morandi, Victoria Ayelen | Calvo, Luciano Ezequiel | F37: 0.0164 | G37: 147600.25 | H37: =G37 -> 147600.25 | I37: =G37-H37 -> 0 | J37: =M$4*F37 -> 0 | K37: =M$2*F37 -> 164000 | L37: =J$3*F37%+J$4 -> 0 | M37: =ROUND((K37+J37+I37+L37),0) + O37 -> 164000.25 | N37: =ROUND((M37*6% + M37 ),0) + O37 -> 173840.25 | O37: =O36+0.01 -> 0.25
A38: 1 amb | C38: 6ºB | D38: Grizak Ruben | E38: Christian | F38: 0.0072 | G38: 64800.26 | H38: =G38 -> 64800.26 | I38: =G38-H38 -> 0 | J38: =M$4*F38 -> 0 | K38: =M$2*F38 -> 72000 | L38: =J$3*F38%+J$4 -> 0 | M38: =ROUND((K38+J38+I38+L38),0) + O38 -> 72000.26 | N38: =ROUND((M38*6% + M38 ),0) + O38 -> 76320.26 | O38: =O37+0.01 -> 0.26
A39: 3 amb | C39: 6ºC | D39: Nuñez Leonel - Corrieri Giuliana | F39: 0.0173 | G39: 155700.27 | H39: =G39 -> 155700.27 | I39: =G39-H39 -> 0 | J39: =M$4*F39 -> 0 | K39: =M$2*F39 -> 173000 | L39: =J$3*F39%+J$4 -> 0 | M39: =ROUND((K39+J39+I39+L39),0) + O39 -> 173000.27 | N39: =ROUND((M39*6% + M39 ),0) + O39 -> 183380.27 | O39: =O38+0.01 -> 0.27 | P39: COCHERA 33 | Q39: COCHERA 33
A40: 2 amb | C40: 6ºD | D40: Sr propietario | F40: 0.0094 | G40: 84600.28 | H40: =G40 -> 84600.28 | I40: =G40-H40 -> 0 | J40: =M$4*F40 -> 0 | K40: =M$2*F40 -> 94000 | L40: =J$3*F40%+J$4 -> 0 | M40: =ROUND((K40+J40+I40+L40),0) + O40 -> 94000.28 | N40: =ROUND((M40*6% + M40 ),0) + O40 -> 99640.28 | O40: =O39+0.01 -> 0.28 | Q40: mariano hecimovic
A41: 2 amb | C41: 6ºE | D41: Dieci, Matias Orlando | E41: Gaston Smith | F41: 0.0087 | G41: 82998.29 | H41: =G41 -> 82998.29 | I41: =G41-H41 -> 0 | J41: =M$4*F41 -> 0 | K41: =M$2*F41 -> 87000 | L41: =J$3*F41%+J$4 -> 0 | M41: =ROUND((K41+J41+I41+L41),0) + O41 -> 87000.29 | N41: =ROUND((M41*6% + M41 ),0) + O41 -> 92220.29 | O41: =O40+0.01 -> 0.29
...

Sheet ANOTACIONES

Sheet SUELDOS
C3: =RESUMEN!C5 -> PERÍODO: SEPTIEMBRE | F3: =[1]RESUMEN!A22 -> Sueldo encargada Sonia Arzamendia Galeano
C5: =RESUMEN!A26 -> Haberes | G5: =RESUMEN!D26 -> 1008894 | H5: Firma
C6: =RESUMEN!A27 -> Plus pileta | G6: =RESUMEN!D27 -> 35211 | H6: __________________________________
C7: =RESUMEN!A28 -> Plus retiro de basura | G7: =RESUMEN!D28 -> 122704
C8: =RESUMEN!A29 -> Plus cochera | G8: =RESUMEN!D29 -> 20931
C9: =RESUMEN!A30 -> Adicional Viaticos | G9: =RESUMEN!D30 -> 58852.2 | H9: Aclaracion
C10: =RESUMEN!A31 -> Adicional remuneracion | G10: =RESUMEN!D31 -> 50000 | H10: __________________________________
C12: TOTAL | G12: =SUM(G5:G11) -> 1296592.2
C16: =C3 -> PERÍODO: SEPTIEMBRE | F16: =[1]RESUMEN!A30 -> Sueldo encargada Miriam
H18: Firma
C19: =RESUMEN!A34 -> Haberes | G19: =RESUMEN!D34 -> 504447 | H19: __________________________________
C20: =RESUMEN!A35 -> Horas extras | G20: =RESUMEN!D35 -> 0
C21: =RESUMEN!A36 -> Plus pileta | G21: =RESUMEN!D36 -> 35211
C22: =RESUMEN!A37 -> Plus retiro de basura | G22: =RESUMEN!D37 -> 122704 | H22: Aclaracion
C23: =RESUMEN!A38 -> Plus cochera | G23: =RESUMEN!D38 -> 20931 | H23: __________________________________
C24: =RESUMEN!A39 -> Adicional Viaticos | G24: =RESUMEN!D39 -> 58852.2
C25: =RESUMEN!A40 -> Adicional remuneracion | G25: =RESUMEN!D40 -> 50000
C26: TOTAL | G26: =SUM(G18:G25) -> 792145.2

Sheet Hoja1
C4: AYALA
C5: 52141.08 | D5: 3B
C6: 67140.1 | D6: 3D
C7: 52121.11 | D7: 3E
C8: 67885.12 | D8: 3F
C9: 67140.16 | D9: 4D
C10: 62141.17 | D10: 4E
C11: 67855.18 | D11: 4F
C12: 62141.23 | D12: 5E
C13: 67855.24 | D13: 5F
C14: =SUM(C5:C13) -> 566420.39
