Workbook

Sheet RESUMEN
B1: MAIL: italia2156rc@gmail.com
B2: CUIT ADMINISTRACION: 27-23125687-9
B3: NÚMERO DE CUENTA: Cta. Cte. $ 191-054-034938/2 - BANCO CREDICOP - CBU : 1910054455005403493828
A4: LIQUIDACION DE EXPENSAS | B4: ADMINISTRADORA: CAROLINA CANCIANI MP:1148
A5: CUIT DEL EDIFICIO: 30-56229064-4 | B5: PERÍODO: FEBRERO | D5: HORARIOS DE ATENCION: LUNES A VIERNES
A6: CONS. DE PROP. ITALIA 2156 | D6: 10 A 15HS - EMERGENCIAS 24HS
B8: VTO 13/03
A13: ESTIMADOS PROPIETARIOS E INQUILINOS: POR FAVOR LOS QUE ABONAN EN PRIMER VENCIMIENTO ABONEN EL MONTO DE PRIMER VENCIMIENTO, ASI AGILIZAN LA LIQUIDACION, RESPETEN LOS CENTAVOS CORRESPONDIENTES A LA UNIDAD FUNCIONAL. ES DE CARÁCTER OBLIGATORIO INFORMAR VIA MAIL LAS EXPENSAS. PORFAVOR RESPETAR LOS CENTAVOS AL ABONAR.
A20: GASTOS A - UNIDADES FUNCIONALES:
A21: Cesar Alberto Britez - CUIL 20-23524002-6
A22: Haberes | D22: 1931623
A23: Descuentos | D23: -420128
A24: Redondeo | D24: 0
A25: TOTAL | E25: =SUM(D22:D24) -> 1511495
A26: Sra. Gisela Alcaraz reemplazo Vacaciones Sr. Cesar
A27: Honorarios Sra. Gisela | D27: 148000
A28: Seguro Sra. Gisela | D28: 5842.51 | E28: Efectivo
A29: TOTAL | E29: =D27+D28 -> 153842.51
A30: IMPUESTOS
A31: ARCA - Plan de pago - Cuota 43/60 | D31: 13757.84 | E31: Debito 18/02
A32: ARCA VEP | D32: 1235711 | E32: Debito 10/02
A33: Sindicato - Suther | D33: 225490.24 | E33: Debito 16/02
A34: Sindicato - Seracarh | D34: 98200.71 | E34: =E33 -> Debito 16/02
A35: Sindicato - Fathery | D35: 10911.19 | E35: =E33 -> Debito 16/02
A36: Municipalidad de avellaneda
A37: TOTAL IMPUESTOS | E37: =SUM(D31:D36) -> 1584071
A38: SEGUROS
A39: Allianz Arg. Cía. De Seguros - Seguro Integral del Edificio - Póliza Nro. 230230731426 | D39: 313739 | E39: Debito ROELA 06/02
A40: Federacion Patronal - Poliza 2280633 - Seguro integral para consorcio | D40: 214164 | E40: Debito 27/02
A41: Allianz Arg. Cía. De Seguros - Seguro Combinado Familiar - Póliza Nro. 240150822164 | D41: 5204 | E41: Debito ROELA 06/02
A42: TOTAL IMPUESTO | E42: =SUM(D39:D41) -> 533107
A43: ABONOS Y SERVICIOS
A44: Edesur | B44: Cliente 4873380 | D44: 542686.9 | E44: Debito 23/02
A45: Edesur | B45: Cliente 0304290 | D45: 0
A46: Edesur | B46: Cliente 1295184 | D46: 0
A47: Metrogas | D47: 10111.62 | E47: Debito 04/02
A48: AySa | D48: 4813938.3 | E48: PMC 03/02
A49: Servicio de interet Claro
A50: TOTAL ABONOS Y SERVICIOS | E50: =SUM(D44:D49) -> 5366736.8
A52: Abono ascensor - Lema Ascensores - Mantenimiento | D52: 225000 | E52: Transf 18/02
...

Sheet PRORRATEO
D2: Gastos B | E2: 3000000 | I2: Gastos A | J2: 12074625
A4: ¡IMPORTANTE! Al momento de registrar los pagos de expensas de las distintas Unidades Funcionales, consideramos importante aclarar el siguiente procedimiento, a fin de evitar confusiones en la imputación de los mismos. El sistema que utilizamos asigna centavos únicos a cada Unidad Funcional (UF), los cuales funcionan como un identificador automático para reconocer a qué Unidad Funcional corresponde cada transferencia. Es decir, cada Unidad Funcional tiene asignado un número específico de centavos que debe respetarse al momento de realizar el pago. Ejemplo: Si la Unidad Funcional es la N.º 45, el importe a abonar deberá finalizar en $,45. En caso de poseer más de una Unidad Funcional, cada una contará con su propio código de centavos. En estas situaciones, solicitamos realizar una transferencia individual por cada UF, respetando el importe y los centavos correspondientes a cada una. Entendemos que, por una cuestión de practicidad, a veces se opta por realizar una única transferencia, pero esto puede generar errores o demoras en la imputación automática de los pagos. La separación de los mismos nos permite llevar un control ordenado y preciso. Por lo expuesto, solicitamos encarecidamente que, a partir de ahora, todas las transferencias se realicen respetando los centavos asignados a la Unidad Funcional correspondiente, a fin de asegurar su correcta imputación. Agradecemos desde ya su colaboración y comprensión. Muchas gracias.
A9: LA CUENTA BANCARIA DEL BANCO ROELA HA SIDO CERRADA, TRANSFERENCIAS SOLO AL CREDICOP
A10: QUIENES ESTAN COLOREADOS DE COLOR VIOLETA NO ESTAN RESPETANDO LOS CENTAVOS AL ABONAR
A11: QUIENES ESTAN EN COLOR ROSADO POSEEN UN PLAN DE PAGOS VIGENTE
A12: UF | B12: Propietario | C12: Inquilinos | D12: (%) | E12: Saldo Ord | F12: Ingreso | G12: Deuda o Saldo a favor | H12: Interes 3% | I12: Gastos A | J12: Gastos B | K12: Gasto particular | L12: Total 1er Vto | M12: Total 2do Vto
L13: =RESUMEN!B8 -> VTO 13/03
A14: 1 | B14: PB - A POLICHISO RAMOS | D14: 1.37 | E14: 206522.01 | F14: =E14 -> 206522.01 | G14: =E14-F14 -> 0 | H14: =IF(G14>0,G14*3%,0) -> 0 | I14: =J$2*D14/100 -> 165422.36 | J14: =E$2*D14/100 -> 41100 | L14: =ROUND(SUM(G14:K14),0) + N14 -> 206522.01 | M14: =ROUND(L14*3%,0) + L14 -> 212718.01 | N14: 0.01
A15: 2 | B15: PB - B BATTISTA OMAR R. | D15: 1.18 | E15: 2512429 | F15: 30000 | G15: =E15-F15 -> 2482429 | H15: =IF(G15>0,G15*3%,0) -> 74472.871 | I15: =J$2*D15/100 -> 142480.58 | J15: =E$2*D15/100 -> 35400 | L15: =ROUND(SUM(G15:K15),0) + N15 -> 2734782 | M15: =ROUND(L15*3%,0) + L15 -> 2816825 | N15: =N14+0.01 -> 0.02 | O15: AYALA GASTON
A16: 3 | B16: PB - C DIDIER OLGA | D16: 0.74 | E16: 111552.03 | F16: =E16 -> 111552.03 | G16: =E16-F16 -> 0 | H16: =IF(G16>0,G16*3%,0) -> 0 | I16: =J$2*D16/100 -> 89352.225 | J16: =E$2*D16/100 -> 22200 | L16: =ROUND(SUM(G16:K16),0) + N16 -> 111552.03 | M16: =ROUND(L16*3%,0) + L16 -> 114899.03 | N16: =N15+0.01 -> 0.03
A17: 4 | B17: PB - D XHARDEZ MARIA A. | D17: 1.47 | E17: 214949.04 | F17: =E17 -> 214949.04 | G17: =E17-F17 -> 0 | H17: =IF(G17>0,G17*3%,0) -> 0 | I17: =J$2*D17/100 -> 177496.99 | J17: =E$2*D17/100 -> 44100 | L17: =ROUND(SUM(G17:K17),0) + N17 -> 221597.04 | M17: =ROUND(L17*3%,0) + L17 -> 228245.04 | N17: =N16+0.01 -> 0.04
A18: 5 | B18: PB - E BRANDAN OSVALDO | D18: 1.12 | E18: 163771.05 | F18: 168684.05 | G18: =E18-F18 -> -4913 | H18: =IF(G18>0,G18*3%,0) -> 0 | I18: =J$2*D18/100 -> 135235.8 | J18: =E$2*D18/100 -> 33600 | L18: =ROUND(SUM(G18:K18),0) + N18 -> 163923.05 | M18: =ROUND(L18*3%,0) + L18 -> 168841.05 | N18: =N17+0.01 -> 0.05
A19: 6 | B19: 1 A VEGA RICARDO | D19: 1.35 | E19: 203507.06 | F19: =E19 -> 203507.06 | G19: =E19-F19 -> 0 | H19: =IF(G19>0,G19*3%,0) -> 0 | I19: =J$2*D19/100 -> 163007.44 | J19: =E$2*D19/100 -> 40500 | L19: =ROUND(SUM(G19:K19),0) + N19 -> 203507.06 | M19: =ROUND(L19*3%,0) + L19 -> 209612.06 | N19: =N18+0.01 -> 0.06
A20: 7 | B20: 1 B ASTARITA SUSANA L. | D20: 1.12 | E20: 168836.07 | F20: =E20 -> 168836.07 | G20: =E20-F20 -> 0 | H20: =IF(G20>0,G20*3%,0) -> 0 | I20: =J$2*D20/100 -> 135235.8 | J20: =E$2*D20/100 -> 33600 | L20: =ROUND(SUM(G20:K20),0) + N20 -> 168836.07 | M20: =ROUND(L20*3%,0) + L20 -> 173901.07 | N20: =N19+0.01 -> 0.07
A21: 8 | B21: 1 C GUGLIELMINI ANA M. | D21: 0.82 | E21: 123612.08 | F21: =E21 -> 123612.08 | G21: =E21-F21 -> 0 | H21: =IF(G21>0,G21*3%,0) -> 0 | I21: =J$2*D21/100 -> 99011.925 | J21: =E$2*D21/100 -> 24600 | L21: =ROUND(SUM(G21:K21),0) + N21 -> 123612.08 | M21: =ROUND(L21*3%,0) + L21 -> 127320.08 | N21: =N20+0.01 -> 0.08
A22: 9 | B22: 1 D SCARPATI LORENA P. | D22: 0.82 | E22: 119904.09 | F22: 123501.09 | G22: =E22-F22 -> -3597 | H22: =IF(G22>0,G22*3%,0) -> 0 | I22: =J$2*D22/100 -> 99011.925 | J22: =E$2*D22/100 -> 24600 | L22: =ROUND(SUM(G22:K22),0) + N22 -> 120015.09 | M22: =ROUND(L22*3%,0) + L22 -> 123615.09 | N22: =N21+0.01 -> 0.09
A23: 10 | B23: 1 E BAZAN JOSE | D23: 1.34 | E23: 202000.1 | F23: =E23 -> 202000.1 | G23: =E23-F23 -> 0 | H23: =IF(G23>0,G23*3%,0) -> 0 | I23: =J$2*D23/100 -> 161799.98 | J23: =E$2*D23/100 -> 40200 | L23: =ROUND(SUM(G23:K23),0) + N23 -> 202000.1 | M23: =ROUND(L23*3%,0) + L23 -> 208060.1 | N23: =N22+0.01 -> 0.1
A24: 11 | B24: 1 F KRAJCIR ERNESTO | D24: 1.12 | E24: 168836.11 | F24: =E24 -> 168836.11 | G24: =E24-F24 -> 0 | H24: =IF(G24>0,G24*3%,0) -> 0 | I24: =J$2*D24/100 -> 135235.8 | J24: =E$2*D24/100 -> 33600 | L24: =ROUND(SUM(G24:K24),0) + N24 -> 168836.11 | M24: =ROUND(L24*3%,0) + L24 -> 173901.11 | N24: =N23+0.01 -> 0.11
A25: 12 | B25: 1 G AGOSTINI ALONSO | D25: 1.17 | E25: 3280034.1 | F25: 0 | G25: =E25-F25 -> 3280034.1 | H25: =IF(G25>0,G25*3%,0) -> 98401.024 | I25: =J$2*D25/100 -> 141273.11 | J25: =E$2*D25/100 -> 35100 | L25: =ROUND(SUM(G25:K25),0) + N25 -> 3554808.1 | M25: =ROUND(L25*3%,0) + L25 -> 3661452.1 | N25: =N24+0.01 -> 0.12
A26: 13 | B26: 2 A LORENA ELIZABETH CASSERO | D26: 1.35 | E26: 206752.13 | F26: =E26 -> 206752.13 | G26: =E26-F26 -> 0 | H26: =IF(G26>0,G26*3%,0) -> 0 | I26: =J$2*D26/100 -> 163007.44 | J26: =E$2*D26/100 -> 40500 | L26: =ROUND(SUM(G26:K26),0) + N26 -> 203507.13 | M26: =ROUND(L26*3%,0) + L26 -> 209612.13 | N26: =N25+0.01 -> 0.13
A27: 14 | B27: 2 B BOQUETE ALFREDO | D27: 1.12 | E27: 179275.14 | F27: =E27 -> 179275.14 | G27: =E27-F27 -> 0 | H27: =IF(G27>0,G27*3%,0) -> 0 | I27: =J$2*D27/100 -> 135235.8 | J27: =E$2*D27/100 -> 33600 | L27: =ROUND(SUM(G27:K27),0) + N27 -> 168836.14 | M27: =ROUND(L27*3%,0) + L27 -> 173901.14 | N27: =N26+0.01 -> 0.14
A28: 15 | B28: 2 C DESIMONE ROBERTO | D28: 0.82 | E28: 382072.15 | F28: =123612.15+250932+7528 -> 382072.15 | G28: =E28-F28 -> 0 | H28: =IF(G28>0,G28*3%,0) -> 0 | I28: =J$2*D28/100 -> 99011.925 | J28: =E$2*D28/100 -> 24600 | L28: =ROUND(SUM(G28:K28),0) + N28 -> 123612.15 | M28: =ROUND(L28*3%,0) + L28 -> 127320.15 | N28: =N27+0.01 -> 0.15
A29: 16 | B29: 2 D KERULIS SILVIA | D29: 0.82 | E29: 758530.16 | F29: 400000.16 | G29: =E29-F29 -> 358530 | H29: =IF(G29>0,G29*3%,0) -> 10755.9 | I29: =J$2*D29/100 -> 99011.925 | J29: =E$2*D29/100 -> 24600 | L29: =ROUND(SUM(G29:K29),0) + N29 -> 492898.16 | M29: =ROUND(L29*3%,0) + L29 -> 507685.16 | N29: =N28+0.01 -> 0.16
A30: 17 | B30: 2 E GARCIA SILVIA | D30: 1.34 | E30: 202000.17 | F30: =E30 -> 202000.17 | G30: =E30-F30 -> 0 | H30: =IF(G30>0,G30*3%,0) -> 0 | I30: =J$2*D30/100 -> 161799.98 | J30: =E$2*D30/100 -> 40200 | L30: =ROUND(SUM(G30:K30),0) + N30 -> 202000.17 | M30: =ROUND(L30*3%,0) + L30 -> 208060.17 | N30: =N29+0.01 -> 0.17
A31: 18 | B31: 2 F LOPEZ MERCEDES R. | D31: 1.12 | E31: 168836.18 | F31: 173901.18 | G31: =E31-F31 -> -5065 | H31: =IF(G31>0,G31*3%,0) -> 0 | I31: =J$2*D31/100 -> 135235.8 | J31: =E$2*D31/100 -> 33600 | L31: =ROUND(SUM(G31:K31),0) + N31 -> 163771.18 | M31: =ROUND(L31*3%,0) + L31 -> 168684.18 | N31: =N30+0.01 -> 0.18
A32: 19 | B32: 2 G MENDEZ JORGE O. | D32: 1.17 | E32: 176373.19 | F32: =191448.19-F113 -> 176372.19 | G32: =E32-F32 -> 1 | H32: =IF(G32>0,G32*3%,0) -> 0.03 | I32: =J$2*D32/100 -> 141273.11 | J32: =E$2*D32/100 -> 35100 | L32: =ROUND(SUM(G32:K32),0) + N32 -> 176374.19 | M32: =ROUND(L32*3%,0) + L32 -> 181665.19 | N32: =N31+0.01 -> 0.19 | O32: Tiene la cochera uf 100
A33: 20 | B33: 3 A POLLIO RICARDO | D33: 1.35 | E33: 203507.2 | G33: =E33-F33 -> 203507.2 | H33: =IF(G33>0,G33*3%,0) -> 6105.216 | I33: =J$2*D33/100 -> 163007.44 | J33: =E$2*D33/100 -> 40500 | L33: =ROUND(SUM(G33:K33),0) + N33 -> 413120.2 | M33: =ROUND(L33*3%,0) + L33 -> 425514.2 | N33: =N32+0.01 -> 0.2 | O33: Efectivo
A34: 21 | B34: 3 B WASZNIEWSKI G. | D34: 1.12 | E34: 168836.21 | F34: =E34 -> 168836.21 | G34: =E34-F34 -> 0 | H34: =IF(G34>0,G34*3%,0) -> 0 | I34: =J$2*D34/100 -> 135235.8 | J34: =E$2*D34/100 -> 33600 | L34: =ROUND(SUM(G34:K34),0) + N34 -> 168836.21 | M34: =ROUND(L34*3%,0) + L34 -> 173901.21 | N34: =N33+0.01 -> 0.21
A35: =A34+1 -> 22 | B35: 3 C MAROTTA PABLO | D35: 0.82 | E35: 123612.22 | F35: 127320.22 | G35: =E35-F35 -> -3708 | H35: =IF(G35>0,G35*3%,0) -> 0 | I35: =J$2*D35/100 -> 99011.925 | J35: =E$2*D35/100 -> 24600 | L35: =ROUND(SUM(G35:K35),0) + N35 -> 119904.22 | M35: =ROUND(L35*3%,0) + L35 -> 123501.22 | N35: =N34+0.01 -> 0.22
A36: =A35+1 -> 23 | B36: 3 D GARCIA MANUELA | D36: 0.82 | E36: 119904.23 | F36: =E36 -> 119904.23 | G36: =E36-F36 -> 0 | H36: =IF(G36>0,G36*3%,0) -> 0 | I36: =J$2*D36/100 -> 99011.925 | J36: =E$2*D36/100 -> 24600 | L36: =ROUND(SUM(G36:K36),0) + N36 -> 123612.23 | M36: =ROUND(L36*3%,0) + L36 -> 127320.23 | N36: =N35+0.01 -> 0.23
A37: =A36+1 -> 24 | B37: 3 E LASTIRI DANIELA | D37: 1.34 | E37: 208060.24 | F37: =E37 -> 208060.24 | G37: =E37-F37 -> 0 | H37: =IF(G37>0,G37*3%,0) -> 0 | I37: =J$2*D37/100 -> 161799.98 | J37: =E$2*D37/100 -> 40200 | L37: =ROUND(SUM(G37:K37),0) + N37 -> 202000.24 | M37: =ROUND(L37*3%,0) + L37 -> 208060.24 | N37: =N36+0.01 -> 0.24
A38: =A37+1 -> 25 | B38: 3 F LOPEZ ESTEBAN | D38: 1.12 | E38: 150649.25 | G38: =E38-F38 -> 150649.25 | H38: =IF(G38>0,G38*3%,0) -> 4519.4775 | I38: =J$2*D38/100 -> 135235.8 | J38: =E$2*D38/100 -> 33600 | L38: =ROUND(SUM(G38:K38),0) + N38 -> 324005.25 | M38: =ROUND(L38*3%,0) + L38 -> 333725.25 | N38: =N37+0.01 -> 0.25
A39: =A38+1 -> 26 | B39: 3 G FONDACARO FEDERICO | D39: 1.17 | E39: 375264.26 | F39: =E39 -> 375264.26 | G39: =E39-F39 -> 0 | H39: =IF(G39>0,G39*3%,0) -> 0 | I39: =J$2*D39/100 -> 141273.11 | J39: =E$2*D39/100 -> 35100 | L39: =ROUND(SUM(G39:K39),0) + N39 -> 176373.26 | M39: =ROUND(L39*3%,0) + L39 -> 181664.26 | N39: =N38+0.01 -> 0.26
A40: =A39+1 -> 27 | B40: 4 A FERNANDEZ LUCAS M. | D40: 1.35 | E40: 197402.27 | F40: =E40 -> 197402.27 | G40: =E40-F40 -> 0 | H40: =IF(G40>0,G40*3%,0) -> 0 | I40: =J$2*D40/100 -> 163007.44 | J40: =E$2*D40/100 -> 40500 | L40: =ROUND(SUM(G40:K40),0) + N40 -> 203507.27 | M40: =ROUND(L40*3%,0) + L40 -> 209612.27 | N40: =N39+0.01 -> 0.27
A41: =A40+1 -> 28 | B41: 4 B FRIDMAN J. Y SRA. | D41: 1.12 | E41: 163771.28 | F41: 168684.28 | G41: =E41-F41 -> -4913 | H41: =IF(G41>0,G41*3%,0) -> 0 | I41: =J$2*D41/100 -> 135235.8 | J41: =E$2*D41/100 -> 33600 | L41: =ROUND(SUM(G41:K41),0) + N41 -> 163923.28 | M41: =ROUND(L41*3%,0) + L41 -> 168841.28 | N41: =N40+0.01 -> 0.28
A42: =A41+1 -> 29 | B42: 4 C FERREIRA DE SOUSA | D42: 0.82 | E42: 116843.29 | G42: =E42-F42 -> 116843.29 | H42: =IF(G42>0,G42*3%,0) -> 3505.2987 | I42: =J$2*D42/100 -> 99011.925 | J42: =E$2*D42/100 -> 24600 | L42: =ROUND(SUM(G42:K42),0) + N42 -> 243961.29 | M42: =ROUND(L42*3%,0) + L42 -> 251280.29 | N42: =N41+0.01 -> 0.29 | O42: Silvana Valeria Arredondo
A43: =A42+1 -> 30 | B43: 4 D DIAZ PETRONA A. | D43: 0.82 | E43: 120677.3 | F43: 125000 | G43: =E43-F43 -> -4322.7 | H43: =IF(G43>0,G43*3%,0) -> 0 | I43: =J$2*D43/100 -> 99011.925 | J43: =E$2*D43/100 -> 24600 | L43: =ROUND(SUM(G43:K43),0) + N43 -> 119289.3 | M43: =ROUND(L43*3%,0) + L43 -> 122868.3 | N43: =N42+0.01 -> 0.3
A44: =A43+1 -> 31 | B44: 4 E XHARDEZ MARIA E. | D44: 1.34 | E44: 202000.31 | F44: 208060.31 | G44: =E44-F44 -> -6060 | H44: =IF(G44>0,G44*3%,0) -> 0 | I44: =J$2*D44/100 -> 161799.98 | J44: =E$2*D44/100 -> 40200 | L44: =ROUND(SUM(G44:K44),0) + N44 -> 195940.31 | M44: =ROUND(L44*3%,0) + L44 -> 201818.31 | N44: =N43+0.01 -> 0.31
A45: =A44+1 -> 32 | B45: 4 F WASINGER ADRIANA B. | D45: 1.12 | E45: 158706.32 | G45: =E45-F45 -> 158706.32 | H45: =IF(G45>0,G45*3%,0) -> 4761.1896 | I45: =J$2*D45/100 -> 135235.8 | J45: =E$2*D45/100 -> 33600 | L45: =ROUND(SUM(G45:K45),0) + N45 -> 332303.32 | M45: =ROUND(L45*3%,0) + L45 -> 342272.32 | N45: =N44+0.01 -> 0.32
A46: =A45+1 -> 33 | B46: 4 G OLIVERA LORENZO | D46: 1.17 | E46: 176373.11 | G46: =E46-F46 -> 176373.11 | H46: =IF(G46>0,G46*3%,0) -> 5291.1934 | I46: =J$2*D46/100 -> 141273.11 | J46: =E$2*D46/100 -> 35100 | L46: =ROUND(SUM(G46:K46),0) + N46 -> 358037.33 | M46: =ROUND(L46*3%,0) + L46 -> 368778.33 | N46: =N45+0.01 -> 0.33
...

Sheet ANOTACIONES
C4: Al 7F le hicimos su situacion detallada al pie de la letra debe abonar $371.016,53
C7: Al 7D le debemos poner el deposito no identificado de enero de $110,000 este mes debe abonar $123.612,51
C10: El 3C tiene nuevo propietario, Marotta Pablo, agregarlo a la cadena de mails pabloeze.marotta@gmail.com
C12: 8C deposito $132.520 el 12/03

Sheet 7F SITUACION
C4: En diciembre debia abonar | F4: Abono | H4: Deuda: | J4: Expensas para abonar en enero
C5: 168835.53 | F5: =C5 -> 168835.53 | H5: 0 | J5: =F5 -> 168835.53
M7: Total a abonar en febrero (expensas + deuda) - Descontamos punitorios
C8: En enero debia abonar: | F8: Abono | H8: Deuda: | J8: Expensas para abonar en Febrero
C9: 168836.53 | F9: 0 | H9: =C9-F9 -> 168836.53 | J9: =33600+135235.8 -> 168835.8 | M9: 300737.53
M11: Total a abonar en febrero (expensas + deuda) - Descontamos punitorios
C12: En febrero debia abonar: | F12: Abono | H12: Deuda: | J12: Expensas para abonar en Marzo
C13: =M9 -> 300737.53 | F13: 98556.53 | H13: =C13-F13 -> 202181 | J13: =33600+135235.8 -> 168835.8 | M13: =J13+H13-0.27 -> 371016.53
C15: Todo este problema con los números se origina en el mes de enero, cuando la unidad funcional 7°F no realizó ningún pago. En ese mismo período, otro propietario efectuó un pago con una terminacion de 53 centavos, lo que generó que el sistema de la administración imputara ese pago a la unidad funcional 7°F, cuando en realidad dicha unidad nunca abonó. Debido a que el inconveniente y la confusión se originan a partir de una situación ajena a la unidad funcional 7°F, la administración decidió no aplicar los punitorios correspondientes al momento de rehacer y corregir los cálculos.

Sheet SITUACION 6B
D4: Deuda a Financiar | F4: 843306.42 | G4: En el mes de febrero se abonaron $200.000,42 pesos que correspondieron $132.000 en concepto de honorarios de la Sra. Abogada y el restante ($68.000 en concepto de adelanto)
D5: Ingreso de convenio | F5: -68000
D6: Saldo | F6: =F4+F5 -> 775306.42
D8: Gastos A Febrero | F8: 135235.8
D9: Gastos B Febrero | F9: 33600
D11: Total | F11: =F6+F8+F9 -> 944142.22
D13: El saldo total sera abonado mediante 24 cuotas de $33.000
